Workbook

Sheet DB
F1: =SUBTOTAL(9,F3:F1048576) -> 161912 | G1: =SUBTOTAL(9,G3:G1048576) -> 1209056 | H1: =SUBTOTAL(9,H3:H1048576) -> 1376934 | I1: =SUBTOTAL(9,I3:I1048576) -> 1.3344605e+10 | J1: =SUBTOTAL(9,J3:J1048576) -> 77902494000
A2: 순서 | B2: 0 | C2: 품번색상 | D2: 사이즈 | E2: 분류 | F2: 입고수량 | G2: 미입고수량 | H2: 기획수량 | I2: 원가 | J2: TAG가
A3: 1 | B3: =IF(C2=C3,B2,B2+1) -> 1 | C3: ELSSBE3801BK | D3: FRE | E3: M | F3: 500 | G3: 0 | H3: 500 | I3: 5010000 | J3: 22500000
A4: 2 | B4: =IF(C3=C4,B3,B3+1) -> 2 | C4: ELSSBE3801BL | D4: FRE | E4: M | F4: 500 | G4: 0 | H4: 500 | I4: 5010000 | J4: 22500000
A5: 3 | B5: =IF(C4=C5,B4,B4+1) -> 3 | C5: ELSSBE3802YE | D5: FRE | E5: M | F5: 500 | G5: 0 | H5: 500 | I5: 5010000 | J5: 22500000
A6: 4 | B6: =IF(C5=C6,B5,B5+1) -> 4 | C6: ELSSBE3803PK | D6: FRE | E6: M | F6: 500 | G6: 0 | H6: 500 | I6: 5010000 | J6: 22500000
A7: 5 | B7: =IF(C6=C7,B6,B6+1) -> 5 | F7: 2000 | G7: 0 | H7: 2000 | I7: 20040000 | J7: 90000000
A8: 6 | B8: =IF(C7=C8,B7,B7+1) -> 6 | C8: DAKBEE5301GY | D8: FRE | E8: B | F8: 0 | G8: 360 | H8: 360 | I8: 3436363.6 | J8: 12600000
A9: 7 | B9: =IF(C8=C9,B8,B8+1) -> 7 | C9: DAKBEE5302BK | D9: FRE | E9: B | F9: 0 | G9: 480 | H9: 480 | I9: 3796363.6 | J9: 13920000
A10: 8 | B10: =IF(C9=C10,B9,B9+1) -> 8 | C10: DAKBEE5302GY | D10: FRE | E10: B | F10: 0 | G10: 480 | H10: 480 | I10: 3796363.6 | J10: 13920000
A11: 9 | B11: =IF(C10=C11,B10,B10+1) -> 9 | C11: DAKTPE5303RE | D11: FRE | E11: B | F11: 0 | G11: 240 | H11: 240 | I11: 3861818.2 | J11: 14160000
A12: 10 | B12: =IF(C11=C12,B11,B11+1) -> 10 | C12: DAKBEE5304GY | D12: FRE | E12: B | F12: 0 | G12: 360 | H12: 360 | I12: 2454545.5 | J12: 9000000
A13: 11 | B13: =IF(C12=C13,B12,B12+1) -> 11 | C13: DAKBEE5004MT | D13: FRE | E13: B | F13: 0 | G13: 360 | H13: 360 | I13: 3829090.9 | J13: 14040000
A14: 12 | B14: =IF(C13=C14,B13,B13+1) -> 12 | C14: DAKBEE5004GR | D14: FRE | E14: B | F14: 0 | G14: 240 | H14: 240 | I14: 2552727.3 | J14: 9360000
A15: 13 | B15: =IF(C14=C15,B14,B14+1) -> 13 | C15: DAKEBE5305BK | D15: FRE | E15: B | F15: 0 | G15: 360 | H15: 360 | I15: 3829090.9 | J15: 14040000
A16: 14 | B16: =IF(C15=C16,B15,B15+1) -> 14 | C16: DAKEBE5305BG | D16: FRE | E16: B | F16: 0 | G16: 360 | H16: 360 | I16: 3829090.9 | J16: 14040000
A17: 15 | B17: =IF(C16=C17,B16,B16+1) -> 15 | C17: DAKBEE5306BW | D17: FRE | E17: B | F17: 0 | G17: 480 | H17: 480 | I17: 5105454.5 | J17: 18720000
A18: 16 | B18: =IF(C17=C18,B17,B17+1) -> 16 | C18: DAKBEE5306OR | D18: FRE | E18: B | F18: 0 | G18: 480 | H18: 480 | I18: 5105454.5 | J18: 18720000
A19: 17 | B19: =IF(C18=C19,B18,B18+1) -> 17 | C19: DAKBEE5307BU | D19: FRE | E19: B | F19: 0 | G19: 480 | H19: 480 | I19: 5105454.5 | J19: 18720000
... A24: 22 | B24: =IF(C23=C24,B23,B23+1) -> 22 | C24: DAKEBE5801OR | D24: FRE | E24: B | F24: 0 | G24: 120 | H24: 120 | I24: 1145454.5 | J24: 4200000
A25: 23 | B25: =IF(C24=C25,B24,B24+1) -> 23 | F25: 0 | G25: 5760 | H25: 5760 | I25: 60021818 | J25: 220080000
A26: 24 | B26: =IF(C25=C26,B25,B25+1) -> 24 | C26: ELSEDE5102BK | D26: FRE | E26: M | F26: 0 | G26: 500 | H26: 500 | I26: 4157605 | J26: 19500000
A27: 25 | B27: =IF(C26=C27,B26,B26+1) -> 25 | C27: ELSEDE5103GY | D27: FRE | E27: M | F27: 0 | G27: 500 | H27: 500 | I27: 4157605 | J27: 19500000
A28: 26 | B28: =IF(C27=C28,B27,B27+1) -> 26 | C28: ELSERE5104BK | D28: FRE | E28: M | F28: 0 | G28: 500 | H28: 500 | I28: 2592005 | J28: 14500000
A29: 27 | B29: =IF(C28=C29,B28,B28+1) -> 27 | C29: ELSERE5105GY | D29: FRE | E29: M | F29: 0 | G29: 500 | H29: 500 | I29: 2592005 | J29: 14500000
A30: 28 | B30: =IF(C29=C30,B29,B29+1) -> 28 | C30: ELSTPE5108BU | D30: FRE | E30: M | F30: 0 | G30: 1000 | H30: 1000 | I30: 8795510 | J30: 55000000
A31: 29 | B31: =IF(C30=C31,B30,B30+1) -> 29 | C31: ELSTPE5608BU | D31: FRE | E31: M | F31: 0 | G31: 1000 | H31: 1000 | I31: 8633510 | J31: 49000000
A32: 30 | B32: =IF(C31=C32,B31,B31+1) -> 30 | F32: 0 | G32: 4000 | H32: 4000 | I32: 30928240 | J32: 172000000
A33: 31 | B33: =IF(C32=C33,B32,B32+1) -> 31 | C33: JILBAE5022BG | D33: FRE | E33: M | F33: 0 | G33: 1000 | H33: 1000 | I33: 6186444 | J33: 39000000
A34: 32 | B34: =IF(C33=C34,B33,B33+1) -> 32 | C34: JILBAE5022PP | D34: FRE | E34: M | F34: 0 | G34: 1000 | H34: 1000 | I34: 6186444 | J34: 39000000
A35: 33 | B35: =IF(C34=C35,B34,B34+1) -> 33 | C35: JILEBE5036BK | D35: FRE | E35: M | F35: 0 | G35: 1500 | H35: 1500 | I35: 10197495 | J35: 64500000
A36: 34 | B36: =IF(C35=C36,B35,B35+1) -> 34 | C36: JILEBE5036GY | D36: FRE | E36: M | F36: 0 | G36: 1500 | H36: 1500 | I36: 10197495 | J36: 64500000
A37: 35 | B37: =IF(C36=C37,B36,B36+1) -> 35 | C37: JILEBE5036RE | D37: FRE | E37: M | F37: 0 | G37: 1000 | H37: 1000 | I37: 6798330 | J37: 43000000
A38: 36 | B38: =IF(C37=C38,B37,B37+1) -> 36 | C38: JILFAE5001GY | D38: FRE | E38: M | F38: 0 | G38: 800 | H38: 800 | I38: 6160560 | J38: 31200000
A39: 37 | B39: =IF(C38=C39,B38,B38+1) -> 37 | C39: JILTPE5021BK | D39: FRE | E39: M | F39: 0 | G39: 1000 | H39: 1000 | I39: 6752144 | J39: 65000000
A40: 38 | B40: =IF(C39=C40,B39,B39+1) -> 38 | C40: JILTPE5021RE | D40: FRE | E40: M | F40: 0 | G40: 1000 | H40: 1000 | I40: 6752144 | J40: 65000000
A41: 39 | B41: =IF(C40=C41,B40,B40+1) -> 39 | F41: 0 | G41: 8800 | H41: 8800 | I41: 59231056 | J41: 411200000
A42: 40 | B42: =IF(C41=C42,B41,B41+1) -> 40 | C42: JILBEE5042BK | D42: FRE | E42: M | F42: 0 | G42: 1000 | H42: 1000 | I42: 4783750 | J42: 39000000
A43: 41 | B43: =IF(C42=C43,B42,B42+1) -> 41 | C43: JILBEE5042KH | D43: FRE | E43: M | F43: 0 | G43: 1000 | H43: 1000 | I43: 4783750 | J43: 39000000
A44: 42 | B44: =IF(C43=C44,B43,B43+1) -> 42 | C44: JILBEE5071PK | D44: FRE | E44: M | F44: 0 | G44: 1500 | H44: 1500 | I44: 6710850 | J44: 58500000
...

Sheet P
D3: 데이터
A4: 0 | B4: 품번색상 | C4: 분류 | D4: 기획수량 | E4: TAG가 | F4: 원가 | G4: 배수 | H4: 입고수량 | I4: 미입고수량
A5: 1 | B5: ELSSBE3801BK | C5: M | D5: 500 | E5: 22500000 | F5: 5010000 | G5: 4.0827436 | H5: 500 | I5: 0
A6: 2 | B6: ELSSBE3801BL | C6: M | D6: 500 | E6: 22500000 | F6: 5010000 | G6: 4.0827436 | H6: 500 | I6: 0
A7: 3 | B7: ELSSBE3802YE | C7: M | D7: 500 | E7: 22500000 | F7: 5010000 | G7: 4.0827436 | H7: 500 | I7: 0
A8: 4 | B8: ELSSBE3803PK | C8: M | D8: 500 | E8: 22500000 | F8: 5010000 | G8: 4.0827436 | H8: 500 | I8: 0
A9: 6 | B9: DAKBEE5301GY | C9: B | D9: 360 | E9: 12600000 | F9: 3436363.6 | G9: 3.3333333 | H9: 0 | I9: 360
A10: 7 | B10: DAKBEE5302BK | C10: B | D10: 480 | E10: 13920000 | F10: 3796363.6 | G10: 3.3333333 | H10: 0 | I10: 480
A11: 8 | B11: DAKBEE5302GY | C11: B | D11: 480 | E11: 13920000 | F11: 3796363.6 | G11: 3.3333333 | H11: 0 | I11: 480
A12: 9 | B12: DAKTPE5303RE | C12: B | D12: 240 | E12: 14160000 | F12: 3861818.2 | G12: 3.3333333 | H12: 0 | I12: 240
A13: 10 | B13: DAKBEE5304GY | C13: B | D13: 360 | E13: 9000000 | F13: 2454545.5 | G13: 3.3333333 | H13: 0 | I13: 360
A14: 11 | B14: DAKBEE5004MT | C14: B | D14: 360 | E14: 14040000 | F14: 3829090.9 | G14: 3.3333333 | H14: 0 | I14: 360
A15: 12 | B15: DAKBEE5004GR | C15: B | D15: 240 | E15: 9360000 | F15: 2552727.3 | G15: 3.3333333 | H15: 0 | I15: 240
A16: 13 | B16: DAKEBE5305BK | C16: B | D16: 360 | E16: 14040000 | F16: 3829090.9 | G16: 3.3333333 | H16: 0 | I16: 360
... A905: 1074 | B905: ELSBAE3841RE | C905: M | D905: 1000 | E905: 53000000 | F905: 12045455 | G905: 4 | H905: 0 | I905: 1000
A906: 총합계 | D906: 688467 | E906: 38951247000 | F906: 6.6723024e+09 | G906: 5.3070473 | H906: 80956 | I906: 604528

Sheet DB2
A1: 러닝/신규 | B1: 최초/리오더 | C1: 품번(최초) | D1: 품번수(최초) | E1: 품번(리오더) | F1: 품번수(리오더) | G1: 품번색상(최초) | H1: 색상수(최초) | I1: 품번색상(리오더) | J1: 색상수(리오더) | K1: 년도시즌 | L1: 품목2 | M1: 브랜드 | N1: 품목 | O1: 브랜드품목 | P1: 품번 | Q1: 품번색상 | R1: 분류 | S1: 기획수량 | T1: TAG가 | U1: 원가(-V) | V1: 배수 | W1: 입고수량 | X1: 미입고수량
A2: =IF(OR(MID(Q2,8,1)="3",MID(Q2,8,1)="8"),"신규","러닝") -> 신규 | B2: =IF(COUNTIF(Q$1:Q1,Q2)=0,"최초","리오더") -> 최초 | C2: =IF($B2="리오더","",P2) -> ELSSBE3801 | D2: =IF(C2="",0,1/COUNTIF(C:C,C2)) -> 0.33333333 | E2: =IF($B2="리오더",P2,"") | F2: =IF(E2="",0,1/COUNTIF(E:E,E2)) -> 0 | G2: =IF($B2="리오더","",Q2) -> ELSSBE3801BK | H2: =IF(G2="",0,1/COUNTIF(G:G,G2)) -> 0.5 | I2: =IF($B2="리오더",Q2,"") | J2: =IF(I2="",0,1/COUNTIF(I:I,I2)) -> 0 | K2: =MID(Q2,6,2) -> E3 | L2: =VLOOKUP(N2,CODE!K:P,CODE!$P$1,FALSE) -> 가방 | M2: =VLOOKUP(MID(Q2,1,3),CODE!$B:$G,CODE!D$1,FALSE) -> ELS | N2: =MID(Q2,4,2) -> SB | O2: =IF(ISERROR(IF(VLOOKUP($N2,CODE!$K:$P,CODE!$O$1,FALSE)="",$M2,$M2&"-"&VLOOKUP($N2,CODE!$K:$P,CODE!$O$1,FALSE)))=TRUE,"",IF(VLOOKUP($N2,CODE!$K:$P,CODE!$O$1,FALSE)="",$M2,$M2&"-"&VLOOKUP($N2,CODE!$K:$P,CODE!$O$1,FALSE))) -> ELS-가방 | P2: =MID(Q2,1,10) -> ELSSBE3801 | Q2: ELSSBE3801BK | R2: M | S2: 500 | T2: 22500000 | U2: 5010000 | V2: 4.0827436 | W2: 500 | X2: 0
A3: =IF(OR(MID(Q3,8,1)="3",MID(Q3,8,1)="8"),"신규","러닝") -> 신규 | B3: =IF(COUNTIF(Q$1:Q2,Q3)=0,"최초","리오더") -> 최초 | C3: =IF($B3="리오더","",P3) -> ELSSBE3801 | D3: =IF(C3="",0,1/COUNTIF(C:C,C3)) -> 0.33333333 | E3: =IF($B3="리오더",P3,"") | F3: =IF(E3="",0,1/COUNTIF(E:E,E3)) -> 0 | G3: =IF($B3="리오더","",Q3) -> ELSSBE3801BL | H3: =IF(G3="",0,1/COUNTIF(G:G,G3)) -> 1 | I3: =IF($B3="리오더",Q3,"") | J3: =IF(I3="",0,1/COUNTIF(I:I,I3)) -> 0 | K3: =MID(Q3,6,2) -> E3 | L3: =VLOOKUP(N3,CODE!K:P,CODE!$P$1,FALSE) -> 가방 | M3: =VLOOKUP(MID(Q3,1,3),CODE!$B:$G,CODE!D$1,FALSE) -> ELS | N3: =MID(Q3,4,2) -> SB | O3: =IF(ISERROR(IF(VLOOKUP($N3,CODE!$K:$P,CODE!$O$1,FALSE)="",$M3,$M3&"-"&VLOOKUP($N3,CODE!$K:$P,CODE!$O$1,FALSE)))=TRUE,"",IF(VLOOKUP($N3,CODE!$K:$P,CODE!$O$1,FALSE)="",$M3,$M3&"-"&VLOOKUP($N3,CODE!$K:$P,CODE!$O$1,FALSE))) -> ELS-가방 | P3: =MID(Q3,1,10) -> ELSSBE3801 | Q3: ELSSBE3801BL | R3: M | S3: 500 | T3: 22500000 | U3: 5010000 | V3: 4.0827436 | W3: 500 | X3: 0
A4: =IF(OR(MID(Q4,8,1)="3",MID(Q4,8,1)="8"),"신규","러닝") -> 신규 | B4: =IF(COUNTIF(Q$1:Q3,Q4)=0,"최초","리오더") -> 최초 | C4: =IF($B4="리오더","",P4) -> ELSSBE3802 | D4: =IF(C4="",0,1/COUNTIF(C:C,C4)) -> 1 | E4: =IF($B4="리오더",P4,"") | F4: =IF(E4="",0,1/COUNTIF(E:E,E4)) -> 0 | G4: =IF($B4="리오더","",Q4) -> ELSSBE3802YE | H4: =IF(G4="",0,1/COUNTIF(G:G,G4)) -> 1 | I4: =IF($B4="리오더",Q4,"") | J4: =IF(I4="",0,1/COUNTIF(I:I,I4)) -> 0 | K4: =MID(Q4,6,2) -> E3 | L4: =VLOOKUP(N4,CODE!K:P,CODE!$P$1,FALSE) -> 가방 | M4: =VLOOKUP(MID(Q4,1,3),CODE!$B:$G,CODE!D$1,FALSE) -> ELS | N4: =MID(Q4,4,2) -> SB | O4: =IF(ISERROR(IF(VLOOKUP($N4,CODE!$K:$P,CODE!$O$1,FALSE)="",$M4,$M4&"-"&VLOOKUP($N4,CODE!$K:$P,CODE!$O$1,FALSE)))=TRUE,"",IF(VLOOKUP($N4,CODE!$K:$P,CODE!$O$1,FALSE)="",$M4,$M4&"-"&VLOOKUP($N4,CODE!$K:$P,CODE!$O$1,FALSE))) -> ELS-가방 | P4: =MID(Q4,1,10) -> ELSSBE3802 | Q4: ELSSBE3802YE | R4: M | S4: 500 | T4: 22500000 | U4: 5010000 | V4: 4.0827436 | W4: 500 | X4: 0
A5: =IF(OR(MID(Q5,8,1)="3",MID(Q5,8,1)="8"),"신규","러닝") -> 신규 | B5: =IF(COUNTIF(Q$1:Q4,Q5)=0,"최초","리오더") -> 최초 | C5: =IF($B5="리오더","",P5) -> ELSSBE3803 | D5: =IF(C5="",0,1/COUNTIF(C:C,C5)) -> 1 | E5: =IF($B5="리오더",P5,"") | F5: =IF(E5="",0,1/COUNTIF(E:E,E5)) -> 0 | G5: =IF($B5="리오더","",Q5) -> ELSSBE3803PK | H5: =IF(G5="",0,1/COUNTIF(G:G,G5)) -> 1 | I5: =IF($B5="리오더",Q5,"") | J5: =IF(I5="",0,1/COUNTIF(I:I,I5)) -> 0 | K5: =MID(Q5,6,2) -> E3 | L5: =VLOOKUP(N5,CODE!K:P,CODE!$P$1,FALSE) -> 가방 | M5: =VLOOKUP(MID(Q5,1,3),CODE!$B:$G,CODE!D$1,FALSE) -> ELS | N5: =MID(Q5,4,2) -> SB | O5: =IF(ISERROR(IF(VLOOKUP($N5,CODE!$K:$P,CODE!$O$1,FALSE)="",$M5,$M5&"-"&VLOOKUP($N5,CODE!$K:$P,CODE!$O$1,FALSE)))=TRUE,"",IF(VLOOKUP($N5,CODE!$K:$P,CODE!$O$1,FALSE)="",$M5,$M5&"-"&VLOOKUP($N5,CODE!$K:$P,CODE!$O$1,FALSE))) -> ELS-가방 | P5: =MID(Q5,1,10) -> ELSSBE3803 | Q5: ELSSBE3803PK | R5: M | S5: 500 | T5: 22500000 | U5: 5010000 | V5: 4.0827436 | W5: 500 | X5: 0
A6: =IF(OR(MID(Q6,8,1)="3",MID(Q6,8,1)="8"),"신규","러닝") -> 신규 | B6: =IF(COUNTIF(Q$1:Q5,Q6)=0,"최초","리오더") -> 최초 | C6: =IF($B6="리오더","",P6) -> DAKBEE5301 | D6: =IF(C6="",0,1/COUNTIF(C:C,C6)) -> 1 | E6: =IF($B6="리오더",P6,"") | F6: =IF(E6="",0,1/COUNTIF(E:E,E6)) -> 0 | G6: =IF($B6="리오더","",Q6) -> DAKBEE5301GY | H6: =IF(G6="",0,1/COUNTIF(G:G,G6)) -> 1 | I6: =IF($B6="리오더",Q6,"") | J6: =IF(I6="",0,1/COUNTIF(I:I,I6)) -> 0 | K6: =MID(Q6,6,2) -> E5 | L6: =VLOOKUP(N6,CODE!K:P,CODE!$P$1,FALSE) -> 모자 | M6: =VLOOKUP(MID(Q6,1,3),CODE!$B:$G,CODE!D$1,FALSE) -> DAK | N6: =MID(Q6,4,2) -> BE | O6: =IF(ISERROR(IF(VLOOKUP($N6,CODE!$K:$P,CODE!$O$1,FALSE)="",$M6,$M6&"-"&VLOOKUP($N6,CODE!$K:$P,CODE!$O$1,FALSE)))=TRUE,"",IF(VLOOKUP($N6,CODE!$K:$P,CODE!$O$1,FALSE)="",$M6,$M6&"-"&VLOOKUP($N6,CODE!$K:$P,CODE!$O$1,FALSE))) -> DAK | P6: =MID(Q6,1,10) -> DAKBEE5301 | Q6: DAKBEE5301GY | R6: B | S6: 360 | T6: 12600000 | U6: 3436363.6 | V6: 3.3333333 | W6: 0 | X6: 360
A7: =IF(OR(MID(Q7,8,1)="3",MID(Q7,8,1)="8"),"신규","러닝") -> 신규 | B7: =IF(COUNTIF(Q$1:Q6,Q7)=0,"최초","리오더") -> 최초 | C7: =IF($B7="리오더","",P7) -> DAKBEE5302 | D7: =IF(C7="",0,1/COUNTIF(C:C,C7)) -> 0.5 | E7: =IF($B7="리오더",P7,"") | F7: =IF(E7="",0,1/COUNTIF(E:E,E7)) -> 0 | G7: =IF($B7="리오더","",Q7) -> DAKBEE5302BK | H7: =IF(G7="",0,1/COUNTIF(G:G,G7)) -> 1 | I7: =IF($B7="리오더",Q7,"") | J7: =IF(I7="",0,1/COUNTIF(I:I,I7)) -> 0 | K7: =MID(Q7,6,2) -> E5 | L7: =VLOOKUP(N7,CODE!K:P,CODE!$P$1,FALSE) -> 모자 | M7: =VLOOKUP(MID(Q7,1,3),CODE!$B:$G,CODE!D$1,FALSE) -> DAK | N7: =MID(Q7,4,2) -> BE | O7: =IF(ISERROR(IF(VLOOKUP($N7,CODE!$K:$P,CODE!$O$1,FALSE)="",$M7,$M7&"-"&VLOOKUP($N7,CODE!$K:$P,CODE!$O$1,FALSE)))=TRUE,"",IF(VLOOKUP($N7,CODE!$K:$P,CODE!$O$1,FALSE)="",$M7,$M7&"-"&VLOOKUP($N7,CODE!$K:$P,CODE!$O$1,FALSE))) -> DAK | P7: =MID(Q7,1,10) -> DAKBEE5302 | Q7: DAKBEE5302BK | R7: B | S7: 480 | T7: 13920000 | U7: 3796363.6 | V7: 3.3333333 | W7: 0 | X7: 480
A8: =IF(OR(MID(Q8,8,1)="3",MID(Q8,8,1)="8"),"신규","러닝") -> 신규 | B8: =IF(COUNTIF(Q$1:Q7,Q8)=0,"최초","리오더") -> 최초 | C8: =IF($B8="리오더","",P8) -> DAKBEE5302 | D8: =IF(C8="",0,1/COUNTIF(C:C,C8)) -> 0.5 | E8: =IF($B8="리오더",P8,"") | F8: =IF(E8="",0,1/COUNTIF(E:E,E8)) -> 0 | G8: =IF($B8="리오더","",Q8) -> DAKBEE5302GY | H8: =IF(G8="",0,1/COUNTIF(G:G,G8)) -> 1 | I8: =IF($B8="리오더",Q8,"") | J8: =IF(I8="",0,1/COUNTIF(I:I,I8)) -> 0 | K8: =MID(Q8,6,2) -> E5 | L8: =VLOOKUP(N8,CODE!K:P,CODE!$P$1,FALSE) -> 모자 | M8: =VLOOKUP(MID(Q8,1,3),CODE!$B:$G,CODE!D$1,FALSE) -> DAK | N8: =MID(Q8,4,2) -> BE | O8: =IF(ISERROR(IF(VLOOKUP($N8,CODE!$K:$P,CODE!$O$1,FALSE)="",$M8,$M8&"-"&VLOOKUP($N8,CODE!$K:$P,CODE!$O$1,FALSE)))=TRUE,"",IF(VLOOKUP($N8,CODE!$K:$P,CODE!$O$1,FALSE)="",$M8,$M8&"-"&VLOOKUP($N8,CODE!$K:$P,CODE!$O$1,FALSE))) -> DAK | P8: =MID(Q8,1,10) -> DAKBEE5302 | Q8: DAKBEE5302GY | R8: B | S8: 480 | T8: 13920000 | U8: 3796363.6 | V8: 3.3333333 | W8: 0 | X8: 480
A9: =IF(OR(MID(Q9,8,1)="3",MID(Q9,8,1)="8"),"신규","러닝") -> 신규 | B9: =IF(COUNTIF(Q$1:Q8,Q9)=0,"최초","리오더") -> 최초 | C9: =IF($B9="리오더","",P9) -> DAKTPE5303 | D9: =IF(C9="",0,1/COUNTIF(C:C,C9)) -> 1 | E9: =IF($B9="리오더",P9,"") | F9: =IF(E9="",0,1/COUNTIF(E:E,E9)) -> 0 | G9: =IF($B9="리오더","",Q9) -> DAKTPE5303RE | H9: =IF(G9="",0,1/COUNTIF(G:G,G9)) -> 1 | I9: =IF($B9="리오더",Q9,"") | J9: =IF(I9="",0,1/COUNTIF(I:I,I9)) -> 0 | K9: =MID(Q9,6,2) -> E5 | L9: =VLOOKUP(N9,CODE!K:P,CODE!$P$1,FALSE) -> 모자 | M9: =VLOOKUP(MID(Q9,1,3),CODE!$B:$G,CODE!D$1,FALSE) -> DAK | N9: =MID(Q9,4,2) -> TP | O9: =IF(ISERROR(IF(VLOOKUP($N9,CODE!$K:$P,CODE!$O$1,FALSE)="",$M9,$M9&"-"&VLOOKUP($N9,CODE!$K:$P,CODE!$O$1,FALSE)))=TRUE,"",IF(VLOOKUP($N9,CODE!$K:$P,CODE!$O$1,FALSE)="",$M9,$M9&"-"&VLOOKUP($N9,CODE!$K:$P,CODE!$O$1,FALSE))) -> DAK | P9: =MID(Q9,1,10) -> DAKTPE5303 | Q9: DAKTPE5303RE | R9: B | S9: 240 | T9: 14160000 | U9: 3861818.2 | V9: 3.3333333 | W9: 0 | X9: 240
A10: =IF(OR(MID(Q10,8,1)="3",MID(Q10,8,1)="8"),"신규","러닝") -> 신규 | B10: =IF(COUNTIF(Q$1:Q9,Q10)=0,"최초","리오더") -> 최초 | C10: =IF($B10="리오더","",P10) -> DAKBEE5304 | D10: =IF(C10="",0,1/COUNTIF(C:C,C10)) -> 1 | E10: =IF($B10="리오더",P10,"") | F10: =IF(E10="",0,1/COUNTIF(E:E,E10)) -> 0 | G10: =IF($B10="리오더","",Q10) -> DAKBEE5304GY | H10: =IF(G10="",0,1/COUNTIF(G:G,G10)) -> 1 | I10: =IF($B10="리오더",Q10,"") | J10: =IF(I10="",0,1/COUNTIF(I:I,I10)) -> 0 | K10: =MID(Q10,6,2) -> E5 | L10: =VLOOKUP(N10,CODE!K:P,CODE!$P$1,FALSE) -> 모자 | M10: =VLOOKUP(MID(Q10,1,3),CODE!$B:$G,CODE!D$1,FALSE) -> DAK | N10: =MID(Q10,4,2) -> BE | O10: =IF(ISERROR(IF(VLOOKUP($N10,CODE!$K:$P,CODE!$O$1,FALSE)="",$M10,$M10&"-"&VLOOKUP($N10,CODE!$K:$P,CODE!$O$1,FALSE)))=TRUE,"",IF(VLOOKUP($N10,CODE!$K:$P,CODE!$O$1,FALSE)="",$M10,$M10&"-"&VLOOKUP($N10,CODE!$K:$P,CODE!$O$1,FALSE))) -> DAK | P10: =MID(Q10,1,10) -> DAKBEE5304 | Q10: DAKBEE5304GY | R10: B | S10: 360 | T10: 9000000 | U10: 2454545.5 | V10: 3.3333333 | W10: 0 | X10: 360
A11: =IF(OR(MID(Q11,8,1)="3",MID(Q11,8,1)="8"),"신규","러닝") -> 러닝 | B11: =IF(COUNTIF(Q$1:Q10,Q11)=0,"최초","리오더") -> 최초 | C11: =IF($B11="리오더","",P11) -> DAKBEE5004 | D11: =IF(C11="",0,1/COUNTIF(C:C,C11)) -> 0.5 | E11: =IF($B11="리오더",P11,"") | F11: =IF(E11="",0,1/COUNTIF(E:E,E11)) -> 0 | G11: =IF($B11="리오더","",Q11) -> DAKBEE5004MT | H11: =IF(G11="",0,1/COUNTIF(G:G,G11)) -> 1 | I11: =IF($B11="리오더",Q11,"") | J11: =IF(I11="",0,1/COUNTIF(I:I,I11)) -> 0 | K11: =MID(Q11,6,2) -> E5 | L11: =VLOOKUP(N11,CODE!K:P,CODE!$P$1,FALSE) -> 모자 | M11: =VLOOKUP(MID(Q11,1,3),CODE!$B:$G,CODE!D$1,FALSE) -> DAK | N11: =MID(Q11,4,2) -> BE | O11: =IF(ISERROR(IF(VLOOKUP($N11,CODE!$K:$P,CODE!$O$1,FALSE)="",$M11,$M11&"-"&VLOOKUP($N11,CODE!$K:$P,CODE!$O$1,FALSE)))=TRUE,"",IF(VLOOKUP($N11,CODE!$K:$P,CODE!$O$1,FALSE)="",$M11,$M11&"-"&VLOOKUP($N11,CODE!$K:$P,CODE!$O$1,FALSE))) -> DAK | P11: =MID(Q11,1,10) -> DAKBEE5004 | Q11: DAKBEE5004MT | R11: B | S11: 360 | T11: 14040000 | U11: 3829090.9 | V11: 3.3333333 | W11: 0 | X11: 360
A12: =IF(OR(MID(Q12,8,1)="3",MID(Q12,8,1)="8"),"신규","러닝") -> 러닝 | B12: =IF(COUNTIF(Q$1:Q11,Q12)=0,"최초","리오더") -> 최초 | C12: =IF($B12="리오더","",P12) -> DAKBEE5004 | D12: =IF(C12="",0,1/COUNTIF(C:C,C12)) -> 0.5 | E12: =IF($B12="리오더",P12,"") | F12: =IF(E12="",0,1/COUNTIF(E:E,E12)) -> 0 | G12: =IF($B12="리오더","",Q12) -> DAKBEE5004GR | H12: =IF(G12="",0,1/COUNTIF(G:G,G12)) -> 1 | I12: =IF($B12="리오더",Q12,"") | J12: =IF(I12="",0,1/COUNTIF(I:I,I12)) -> 0 | K12: =MID(Q12,6,2) -> E5 | L12: =VLOOKUP(N12,CODE!K:P,CODE!$P$1,FALSE) -> 모자 | M12: =VLOOKUP(MID(Q12,1,3),CODE!$B:$G,CODE!D$1,FALSE) -> DAK | N12: =MID(Q12,4,2) -> BE | O12: =IF(ISERROR(IF(VLOOKUP($N12,CODE!$K:$P,CODE!$O$1,FALSE)="",$M12,$M12&"-"&VLOOKUP($N12,CODE!$K:$P,CODE!$O$1,FALSE)))=TRUE,"",IF(VLOOKUP($N12,CODE!$K:$P,CODE!$O$1,FALSE)="",$M12,$M12&"-"&VLOOKUP($N12,CODE!$K:$P,CODE!$O$1,FALSE))) -> DAK | P12: =MID(Q12,1,10) -> DAKBEE5004 | Q12: DAKBEE5004GR | R12: B | S12: 240 | T12: 9360000 | U12: 2552727.3 | V12: 3.3333333 | W12: 0 | X12: 240
A13: =IF(OR(MID(Q13,8,1)="3",MID(Q13,8,1)="8"),"신규","러닝") -> 신규 | B13: =IF(COUNTIF(Q$1:Q12,Q13)=0,"최초","리오더") -> 최초 | C13: =IF($B13="리오더","",P13) -> DAKEBE5305 | D13: =IF(C13="",0,1/COUNTIF(C:C,C13)) -> 0.5 | E13: =IF($B13="리오더",P13,"") | F13: =IF(E13="",0,1/COUNTIF(E:E,E13)) -> 0 | G13: =IF($B13="리오더","",Q13) -> DAKEBE5305BK | H13: =IF(G13="",0,1/COUNTIF(G:G,G13)) -> 1 | I13: =IF($B13="리오더",Q13,"") | J13: =IF(I13="",0,1/COUNTIF(I:I,I13)) -> 0 | K13: =MID(Q13,6,2) -> E5 | L13: =VLOOKUP(N13,CODE!K:P,CODE!$P$1,FALSE) -> 모자 | M13: =VLOOKUP(MID(Q13,1,3),CODE!$B:$G,CODE!D$1,FALSE) -> DAK | N13: =MID(Q13,4,2) -> EB | O13: =IF(ISERROR(IF(VLOOKUP($N13,CODE!$K:$P,CODE!$O$1,FALSE)="",$M13,$M13&"-"&VLOOKUP($N13,CODE!$K:$P,CODE!$O$1,FALSE)))=TRUE,"",IF(VLOOKUP($N13,CODE!$K:$P,CODE!$O$1,FALSE)="",$M13,$M13&"-"&VLOOKUP($N13,CODE!$K:$P,CODE!$O$1,FALSE))) -> DAK | P13: =MID(Q13,1,10) -> DAKEBE5305 | Q13: DAKEBE5305BK | R13: B | S13: 360 | T13: 14040000 | U13: 3829090.9 | V13: 3.3333333 | W13: 0 | X13: 360
... A65: =IF(OR(MID(Q65,8,1)="3",MID(Q65,8,1)="8"),"신규","러닝") -> 신규 | B65: =IF(COUNTIF(Q$1:Q64,Q65)=0,"최초","리오더") -> 최초 | C65: =IF($B65="리오더","",P65) -> TRUBAE3303 | D65: =IF(C65="",0,1/COUNTIF(C:C,C65)) -> 0.25 | E65: =IF($B65="리오더",P65,"") | F65: =IF(E65="",0,1/COUNTIF(E:E,E65)) -> 0 | G65: =IF($B65="리오더","",Q65) -> TRUBAE3303PK | H65: =IF(G65="",0,1/COUNTIF(G:G,G65)) -> 1 | I65: =IF($B65="리오더",Q65,"") | J65: =IF(I65="",0,1/COUNTIF(I:I,I65)) -> 0 | K65: =MID(Q65,6,2) -> E3 | L65: =VLOOKUP(N65,CODE!K:P,CODE!$P$1,FALSE) -> 모자 | M65: =VLOOKUP(MID(Q65,1,3),CODE!$B:$G,CODE!D$1,FALSE) -> TRU | N65: =MID(Q65,4,2) -> BA | O65: =IF(ISERROR(IF(VLOOKUP($N65,CODE!$K:$P,CODE!$O$1,FALSE)="",$M65,$M65&"-"&VLOOKUP($N65,CODE!$K:$P,CODE!$O$1,FALSE)))=TRUE,"",IF(VLOOKUP($N65,CODE!$K:$P,CODE!$O$1,FALSE)="",$M65,$M65&"-"&VLOOKUP($N65,CODE!$K:$P,CODE!$O$1,FALSE))) -> TRU | P65: =MID(Q65,1,10) -> TRUBAE3303 | Q65: TRUBAE3303PK | R65: B | S65: 108 | T65: 18252000 | U65: 4802205.1 | V65: 3.4552309 | W65: 0 | X65: 108
A66: =IF(OR(MID(Q66,8,1)="3",MID(Q66,8,1)="8"),"신규","러닝") -> 신규 | B66: 최초 | C66: =IF($B66="리오더","",P66) -> TRUBAE3303 | D66: =IF(C66="",0,1/COUNTIF(C:C,C66)) -> 0.25 | E66: =IF($B66="리오더",P66,"") | F66: =IF(E66="",0,1/COUNTIF(E:E,E66)) -> 0 | G66: =IF($B66="리오더","",Q66) -> TRUBAE3303BL | H66: =IF(G66="",0,1/COUNTIF(G:G,G66)) -> 0.5 | I66: =IF($B66="리오더",Q66,"") | J66: =IF(I66="",0,1/COUNTIF(I:I,I66)) -> 0 | K66: =MID(Q66,6,2) -> E3 | L66: =VLOOKUP(N66,CODE!K:P,CODE!$P$1,FALSE) -> 모자 | M66: =VLOOKUP(MID(Q66,1,3),CODE!$B:$G,CODE!D$1,FALSE) -> TRU | N66: =MID(Q66,4,2) -> BA | O66: =IF(ISERROR(IF(VLOOKUP($N66,CODE!$K:$P,CODE!$O$1,FALSE)="",$M66,$M66&"-"&VLOOKUP($N66,CODE!$K:$P,CODE!$O$1,FALSE)))=TRUE,"",IF(VLOOKUP($N66,CODE!$K:$P,CODE!$O$1,FALSE)="",$M66,$M66&"-"&VLOOKUP($N66,CODE!$K:$P,CODE!$O$1,FALSE))) -> TRU | P66: =MID(Q66,1,10) -> TRUBAE3303 | Q66: TRUBAE3303BL | R66: B | S66: 108 | T66: 18252000 | U66: 4802205.1 | V66: 3.4552309 | W66: 0 | X66: 108
A67: =IF(OR(MID(Q67,8,1)="3",MID(Q67,8,1)="8"),"신규","러닝") -> 신규 | B67: =IF(COUNTIF(Q$1:Q66,Q67)=0,"최초","리오더") -> 최초 | C67: =IF($B67="리오더","",P67) -> TRUBAE3304 | D67: =IF(C67="",0,1/COUNTIF(C:C,C67)) -> 0.33333333 | E67: =IF($B67="리오더",P67,"") | F67: =IF(E67="",0,1/COUNTIF(E:E,E67)) -> 0 | G67: =IF($B67="리오더","",Q67) -> TRUBAE3304CL | H67: =IF(G67="",0,1/COUNTIF(G:G,G67)) -> 1 | I67: =IF($B67="리오더",Q67,"") | J67: =IF(I67="",0,1/COUNTIF(I:I,I67)) -> 0 | K67: =MID(Q67,6,2) -> E3 | L67: =VLOOKUP(N67,CODE!K:P,CODE!$P$1,FALSE) -> 모자 | M67: =VLOOKUP(MID(Q67,1,3),CODE!$B:$G,CODE!D$1,FALSE) -> TRU | N67: =MID(Q67,4,2) -> BA | O67: =IF(ISERROR(IF(VLOOKUP($N67,CODE!$K:$P,CODE!$O$1,FALSE)="",$M67,$M67&"-"&VLOOKUP($N67,CODE!$K:$P,CODE!$O$1,FALSE)))=TRUE,"",IF(VLOOKUP($N67,CODE!$K:$P,CODE!$O$1,FALSE)="",$M67,$M67&"-"&VLOOKUP($N67,CODE!$K:$P,CODE!$O$1,FALSE))) -> TRU | P67: =MID(Q67,1,10) -> TRUBAE3304 | Q67: TRUBAE3304CL | R67: B | S67: 108 | T67: 12420000 | U67: 3286614.1 | V67: 3.4354228 | W67: 0 | X67: 108
A68: =IF(OR(MID(Q68,8,1)="3",MID(Q68,8,1)="8"),"신규","러닝") -> 신규 | B68: =IF(COUNTIF(Q$1:Q67,Q68)=0,"최초","리오더") -> 최초 | C68: =IF($B68="리오더","",P68) -> TRUBAE3304 | D68: =IF(C68="",0,1/COUNTIF(C:C,C68)) -> 0.33333333 | E68: =IF($B68="리오더",P68,"") | F68: =IF(E68="",0,1/COUNTIF(E:E,E68)) -> 0 | G68: =IF($B68="리오더","",Q68) -> TRUBAE3304NY | H68: =IF(G68="",0,1/COUNTIF(G:G,G68)) -> 1 | I68: =IF($B68="리오더",Q68,"") | J68: =IF(I68="",0,1/COUNTIF(I:I,I68)) -> 0 | K68: =MID(Q68,6,2) -> E3 | L68: =VLOOKUP(N68,CODE!K:P,CODE!$P$1,FALSE) -> 모자 | M68: =VLOOKUP(MID(Q68,1,3),CODE!$B:$G,CODE!D$1,FALSE) -> TRU | N68: =MID(Q68,4,2) -> BA | O68: =IF(ISERROR(IF(VLOOKUP($N68,CODE!$K:$P,CODE!$O$1,FALSE)="",$M68,$M68&"-"&VLOOKUP($N68,CODE!$K:$P,CODE!$O$1,FALSE)))=TRUE,"",IF(VLOOKUP($N68,CODE!$K:$P,CODE!$O$1,FALSE)="",$M68,$M68&"-"&VLOOKUP($N68,CODE!$K:$P,CODE!$O$1,FALSE))) -> TRU | P68: =MID(Q68,1,10) -> TRUBAE3304 | Q68: TRUBAE3304NY | R68: B | S68: 144 | T68: 16560000 | U68: 4382152.1 | V68: 3.4354228 | W68: 0 | X68: 144
A69: =IF(OR(MID(Q69,8,1)="3",MID(Q69,8,1)="8"),"신규","러닝") -> 신규 | B69: =IF(COUNTIF(Q$1:Q68,Q69)=0,"최초","리오더") -> 최초 | C69: =IF($B69="리오더","",P69) -> TRUBAE3304 | D69: =IF(C69="",0,1/COUNTIF(C:C,C69)) -> 0.33333333 | E69: =IF($B69="리오더",P69,"") | F69: =IF(E69="",0,1/COUNTIF(E:E,E69)) -> 0 | G69: =IF($B69="리오더","",Q69) -> TRUBAE3304RE | H69: =IF(G69="",0,1/COUNTIF(G:G,G69)) -> 1 | I69: =IF($B69="리오더",Q69,"") | J69: =IF(I69="",0,1/COUNTIF(I:I,I69)) -> 0 | K69: =MID(Q69,6,2) -> E3 | L69: =VLOOKUP(N69,CODE!K:P,CODE!$P$1,FALSE) -> 모자 | M69: =VLOOKUP(MID(Q69,1,3),CODE!$B:$G,CODE!D$1,FALSE) -> TRU | N69: =MID(Q69,4,2) -> BA | O69: =IF(ISERROR(IF(VLOOKUP($N69,CODE!$K:$P,CODE!$O$1,FALSE)="",$M69,$M69&"-"&VLOOKUP($N69,CODE!$K:$P,CODE!$O$1,FALSE)))=TRUE,"",IF(VLOOKUP($N69,CODE!$K:$P,CODE!$O$1,FALSE)="",$M69,$M69&"-"&VLOOKUP($N69,CODE!$K:$P,CODE!$O$1,FALSE))) -> TRU | P69: =MID(Q69,1,10) -> TRUBAE3304 | Q69: TRUBAE3304RE | R69: B | S69: 168 | T69: 19320000 | U69: 5112510.8 | V69: 3.4354228 | W69: 0 | X69: 168
A70: =IF(OR(MID(Q70,8,1)="3",MID(Q70,8,1)="8"),"신규","러닝") -> 신규 | B70: =IF(COUNTIF(Q$1:Q69,Q70)=0,"최초","리오더") -> 최초 | C70: =IF($B70="리오더","",P70) -> TRUFIE3305 | D70: =IF(C70="",0,1/COUNTIF(C:C,C70)) -> 0.25 | E70: =IF($B70="리오더",P70,"") | F70: =IF(E70="",0,1/COUNTIF(E:E,E70)) -> 0 | G70: =IF($B70="리오더","",Q70) -> TRUFIE3305NY | H70: =IF(G70="",0,1/COUNTIF(G:G,G70)) -> 1 | I70: =IF($B70="리오더",Q70,"") | J70: =IF(I70="",0,1/COUNTIF(I:I,I70)) -> 0 | K70: =MID(Q70,6,2) -> E3 | L70: =VLOOKUP(N70,CODE!K:P,CODE!$P$1,FALSE) -> 모자 | M70: =VLOOKUP(MID(Q70,1,3),CODE!$B:$G,CODE!D$1,FALSE) -> TRU | N70: =MID(Q70,4,2) -> FI | O70: =IF(ISERROR(IF(VLOOKUP($N70,CODE!$K:$P,CODE!$O$1,FALSE)="",$M70,$M70&"-"&VLOOKUP($N70,CODE!$K:$P,CODE!$O$1,FALSE)))=TRUE,"",IF(VLOOKUP($N70,CODE!$K:$P,CODE!$O$1,FALSE)="",$M70,$M70&"-"&VLOOKUP($N70,CODE!$K:$P,CODE!$O$1,FALSE))) -> TRU | P70: =MID(Q70,1,10) -> TRUFIE3305 | Q70: TRUFIE3305NY | R70: B | S70: 96 | T70: 9504000 | U70: 2472370.8 | V70: 3.4946215 | W70: 0 | X70: 96
A71: =IF(OR(MID(Q71,8,1)="3",MID(Q71,8,1)="8"),"신규","러닝") -> 신규 | B71: =IF(COUNTIF(Q$1:Q70,Q71)=0,"최초","리오더") -> 최초 | C71: =IF($B71="리오더","",P71) -> TRUFIE3305 | D71: =IF(C71="",0,1/COUNTIF(C:C,C71)) -> 0.25 | E71: =IF($B71="리오더",P71,"") | F71: =IF(E71="",0,1/COUNTIF(E:E,E71)) -> 0 | G71: =IF($B71="리오더","",Q71) -> TRUFIE3305RE | H71: =IF(G71="",0,1/COUNTIF(G:G,G71)) -> 1 | I71: =IF($B71="리오더",Q71,"") | J71: =IF(I71="",0,1/COUNTIF(I:I,I71)) -> 0 | K71: =MID(Q71,6,2) -> E3 | L71: =VLOOKUP(N71,CODE!K:P,CODE!$P$1,FALSE) -> 모자 | M71: =VLOOKUP(MID(Q71,1,3),CODE!$B:$G,CODE!D$1,FALSE) -> TRU | N71: =MID(Q71,4,2) -> FI | O71: =IF(ISERROR(IF(VLOOKUP($N71,CODE!$K:$P,CODE!$O$1,FALSE)="",$M71,$M71&"-"&VLOOKUP($N71,CODE!$K:$P,CODE!$O$1,FALSE)))=TRUE,"",IF(VLOOKUP($N71,CODE!$K:$P,CODE!$O$1,FALSE)="",$M71,$M71&"-"&VLOOKUP($N71,CODE!$K:$P,CODE!$O$1,FALSE))) -> TRU | P71: =MID(Q71,1,10) -> TRUFIE3305 | Q71: TRUFIE3305RE | R71: B | S71: 96 | T71: 9504000 | U71: 2472370.8 | V71: 3.4946215 | W71: 0 | X71: 96
A72: =IF(OR(MID(Q72,8,1)="3",MID(Q72,8,1)="8"),"신규","러닝") -> 신규 | B72: =IF(COUNTIF(Q$1:Q71,Q72)=0,"최초","리오더") -> 최초 | C72: =IF($B72="리오더","",P72) -> TRUFIE3305 | D72: =IF(C72="",0,1/COUNTIF(C:C,C72)) -> 0.25 | E72: =IF($B72="리오더",P72,"") | F72: =IF(E72="",0,1/COUNTIF(E:E,E72)) -> 0 | G72: =IF($B72="리오더","",Q72) -> TRUFIE3305YE | H72: =IF(G72="",0,1/COUNTIF(G:G,G72)) -> 1 | I72: =IF($B72="리오더",Q72,"") | J72: =IF(I72="",0,1/COUNTIF(I:I,I72)) -> 0 | K72: =MID(Q72,6,2) -> E3 | L72: =VLOOKUP(N72,CODE!K:P,CODE!$P$1,FALSE) -> 모자 | M72: =VLOOKUP(MID(Q72,1,3),CODE!$B:$G,CODE!D$1,FALSE) -> TRU | N72: =MID(Q72,4,2) -> FI | O72: =IF(ISERROR(IF(VLOOKUP($N72,CODE!$K:$P,CODE!$O$1,FALSE)="",$M72,$M72&"-"&VLOOKUP($N72,CODE!$K:$P,CODE!$O$1,FALSE)))=TRUE,"",IF(VLOOKUP($N72,CODE!$K:$P,CODE!$O$1,FALSE)="",$M72,$M72&"-"&VLOOKUP($N72,CODE!$K:$P,CODE!$O$1,FALSE))) -> TRU | P72: =MID(Q72,1,10) -> TRUFIE3305 | Q72: TRUFIE3305YE | R72: B | S72: 72 | T72: 7128000 | U72: 1854278.1 | V72: 3.4946215 | W72: 0 | X72: 72
A73: =IF(OR(MID(Q73,8,1)="3",MID(Q73,8,1)="8"),"신규","러닝") -> 신규 | B73: =IF(COUNTIF(Q$1:Q72,Q73)=0,"최초","리오더") -> 최초 | C73: =IF($B73="리오더","",P73) -> TRUFIE3305 | D73: =IF(C73="",0,1/COUNTIF(C:C,C73)) -> 0.25 | E73: =IF($B73="리오더",P73,"") | F73: =IF(E73="",0,1/COUNTIF(E:E,E73)) -> 0 | G73: =IF($B73="리오더","",Q73) -> TRUFIE3305BK | H73: =IF(G73="",0,1/COUNTIF(G:G,G73)) -> 1 | I73: =IF($B73="리오더",Q73,"") | J73: =IF(I73="",0,1/COUNTIF(I:I,I73)) -> 0 | K73: =MID(Q73,6,2) -> E3 | L73: =VLOOKUP(N73,CODE!K:P,CODE!$P$1,FALSE) -> 모자 | M73: =VLOOKUP(MID(Q73,1,3),CODE!$B:$G,CODE!D$1,FALSE) -> TRU | N73: =MID(Q73,4,2) -> FI | O73: =IF(ISERROR(IF(VLOOKUP($N73,CODE!$K:$P,CODE!$O$1,FALSE)="",$M73,$M73&"-"&VLOOKUP($N73,CODE!$K:$P,CODE!$O$1,FALSE)))=TRUE,"",IF(VLOOKUP($N73,CODE!$K:$P,CODE!$O$1,FALSE)="",$M73,$M73&"-"&VLOOKUP($N73,CODE!$K:$P,CODE!$O$1,FALSE))) -> TRU | P73: =MID(Q73,1,10) -> TRUFIE3305 | Q73: TRUFIE3305BK | R73: B | S73: 96 | T73: 9504000 | U73: 2472370.8 | V73: 3.4946215 | W73: 0 | X73: 96
A74: =IF(OR(MID(Q74,8,1)="3",MID(Q74,8,1)="8"),"신규","러닝") -> 신규 | B74: =IF(COUNTIF(Q$1:Q73,Q74)=0,"최초","리오더") -> 최초 | C74: =IF($B74="리오더","",P74) -> TRUFIE3306 | D74: =IF(C74="",0,1/COUNTIF(C:C,C74)) -> 0.33333333 | E74: =IF($B74="리오더",P74,"") | F74: =IF(E74="",0,1/COUNTIF(E:E,E74)) -> 0 | G74: =IF($B74="리오더","",Q74) -> TRUFIE3306NY | H74: =IF(G74="",0,1/COUNTIF(G:G,G74)) -> 1 | I74: =IF($B74="리오더",Q74,"") | J74: =IF(I74="",0,1/COUNTIF(I:I,I74)) -> 0 | K74: =MID(Q74,6,2) -> E3 | L74: =VLOOKUP(N74,CODE!K:P,CODE!$P$1,FALSE) -> 모자 | M74: =VLOOKUP(MID(Q74,1,3),CODE!$B:$G,CODE!D$1,FALSE) -> TRU | N74: =MID(Q74,4,2) -> FI | O74: =IF(ISERROR(IF(VLOOKUP($N74,CODE!$K:$P,CODE!$O$1,FALSE)="",$M74,$M74&"-"&VLOOKUP($N74,CODE!$K:$P,CODE!$O$1,FALSE)))=TRUE,"",IF(VLOOKUP($N74,CODE!$K:$P,CODE!$O$1,FALSE)="",$M74,$M74&"-"&VLOOKUP($N74,CODE!$K:$P,CODE!$O$1,FALSE))) -> TRU | P74: =MID(Q74,1,10) -> TRUFIE3306 | Q74: TRUFIE3306NY | R74: B | S74: 96 | T74: 11040000 | U74: 2921434.8 | V74: 3.4354228 | W74: 0 | X74: 96
A75: =IF(OR(MID(Q75,8,1)="3",MID(Q75,8,1)="8"),"신규","러닝") -> 신규 | B75: =IF(COUNTIF(Q$1:Q74,Q75)=0,"최초","리오더") -> 최초 | C75: =IF($B75="리오더","",P75) -> TRUFIE3306 | D75: =IF(C75="",0,1/COUNTIF(C:C,C75)) -> 0.33333333 | E75: =IF($B75="리오더",P75,"") | F75: =IF(E75="",0,1/COUNTIF(E:E,E75)) -> 0 | G75: =IF($B75="리오더","",Q75) -> TRUFIE3306RE | H75: =IF(G75="",0,1/COUNTIF(G:G,G75)) -> 1 | I75: =IF($B75="리오더",Q75,"") | J75: =IF(I75="",0,1/COUNTIF(I:I,I75)) -> 0 | K75: =MID(Q75,6,2) -> E3 | L75: =VLOOKUP(N75,CODE!K:P,CODE!$P$1,FALSE) -> 모자 | M75: =VLOOKUP(MID(Q75,1,3),CODE!$B:$G,CODE!D$1,FALSE) -> TRU | N75: =MID(Q75,4,2) -> FI | O75: =IF(ISERROR(IF(VLOOKUP($N75,CODE!$K:$P,CODE!$O$1,FALSE)="",$M75,$M75&"-"&VLOOKUP($N75,CODE!$K:$P,CODE!$O$1,FALSE)))=TRUE,"",IF(VLOOKUP($N75,CODE!$K:$P,CODE!$O$1,FALSE)="",$M75,$M75&"-"&VLOOKUP($N75,CODE!$K:$P,CODE!$O$1,FALSE))) -> TRU | P75: =MID(Q75,1,10) -> TRUFIE3306 | Q75: TRUFIE3306RE | R75: B | S75: 96 | T75: 11040000 | U75: 2921434.8 | V75: 3.4354228 | W75: 0 | X75: 96
A76: =IF(OR(MID(Q76,8,1)="3",MID(Q76,8,1)="8"),"신규","러닝") -> 신규 | B76: =IF(COUNTIF(Q$1:Q75,Q76)=0,"최초","리오더") -> 최초 | C76: =IF($B76="리오더","",P76) -> TRUFIE3306 | D76: =IF(C76="",0,1/COUNTIF(C:C,C76)) -> 0.33333333 | E76: =IF($B76="리오더",P76,"") | F76: =IF(E76="",0,1/COUNTIF(E:E,E76)) -> 0 | G76: =IF($B76="리오더","",Q76) -> TRUFIE3306OR | H76: =IF(G76="",0,1/COUNTIF(G:G,G76)) -> 1 | I76: =IF($B76="리오더",Q76,"") | J76: =IF(I76="",0,1/COUNTIF(I:I,I76)) -> 0 | K76: =MID(Q76,6,2) -> E3 | L76: =VLOOKUP(N76,CODE!K:P,CODE!$P$1,FALSE) -> 모자 | M76: =VLOOKUP(MID(Q76,1,3),CODE!$B:$G,CODE!D$1,FALSE) -> TRU | N76: =MID(Q76,4,2) -> FI | O76: =IF(ISERROR(IF(VLOOKUP($N76,CODE!$K:$P,CODE!$O$1,FALSE)="",$M76,$M76&"-"&VLOOKUP($N76,CODE!$K:$P,CODE!$O$1,FALSE)))=TRUE,"",IF(VLOOKUP($N76,CODE!$K:$P,CODE!$O$1,FALSE)="",$M76,$M76&"-"&VLOOKUP($N76,CODE!$K:$P,CODE!$O$1,FALSE))) -> TRU | P76: =MID(Q76,1,10) -> TRUFIE3306 | Q76: TRUFIE3306OR | R76: B | S76: 72 | T76: 8280000 | U76: 2191076.1 | V76: 3.4354228 | W76: 0 | X76: 72
A77: =IF(OR(MID(Q77,8,1)="3",MID(Q77,8,1)="8"),"신규","러닝") -> 신규 | B77: =IF(COUNTIF(Q$1:Q76,Q77)=0,"최초","리오더") -> 최초 | C77: =IF($B77="리오더","",P77) -> JILMIE3301 | D77: =IF(C77="",0,1/COUNTIF(C:C,C77)) -> 1 | E77: =IF($B77="리오더",P77,"") | F77: =IF(E77="",0,1/COUNTIF(E:E,E77)) -> 0 | G77: =IF($B77="리오더","",Q77) -> JILMIE3301BK | H77: =IF(G77="",0,1/COUNTIF(G:G,G77)) -> 1 | I77: =IF($B77="리오더",Q77,"") | J77: =IF(I77="",0,1/COUNTIF(I:I,I77)) -> 0 | K77: =MID(Q77,6,2) -> E3 | L77: =VLOOKUP(N77,CODE!K:P,CODE!$P$1,FALSE) -> 모자 | M77: =VLOOKUP(MID(Q77,1,3),CODE!$B:$G,CODE!D$1,FALSE) -> JIL | N77: =MID(Q77,4,2) -> MI | O77: =IF(ISERROR(IF(VLOOKUP($N77,CODE!$K:$P,CODE!$O$1,FALSE)="",$M77,$M77&"-"&VLOOKUP($N77,CODE!$K:$P,CODE!$O$1,FALSE)))=TRUE,"",IF(VLOOKUP($N77,CODE!$K:$P,CODE!$O$1,FALSE)="",$M77,$M77&"-"&VLOOKUP($N77,CODE!$K:$P,CODE!$O$1,FALSE))) -> JIL | P77: =MID(Q77,1,10) -> JILMIE3301 | Q77: JILMIE3301BK | R77: M | S77: 500 | T77: 24500000 | U77: 3580970 | V77: 6.219747 | W77: 0 | X77: 500
A78: =IF(OR(MID(Q78,8,1)="3",MID(Q78,8,1)="8"),"신규","러닝") -> 신규 | B78: =IF(COUNTIF(Q$1:Q77,Q78)=0,"최초","리오더") -> 최초 | C78: =IF($B78="리오더","",P78) -> JILMIE5303 | D78: =IF(C78="",0,1/COUNTIF(C:C,C78)) -> 0.5 | E78: =IF($B78="리오더",P78,"") | F78: =IF(E78="",0,1/COUNTIF(E:E,E78)) -> 0 | G78: =IF($B78="리오더","",Q78) -> JILMIE5303GY | H78: =IF(G78="",0,1/COUNTIF(G:G,G78)) -> 1 | I78: =IF($B78="리오더",Q78,"") | J78: =IF(I78="",0,1/COUNTIF(I:I,I78)) -> 0 | K78: =MID(Q78,6,2) -> E5 | L78: =VLOOKUP(N78,CODE!K:P,CODE!$P$1,FALSE) -> 모자 | M78: =VLOOKUP(MID(Q78,1,3),CODE!$B:$G,CODE!D$1,FALSE) -> JIL | N78: =MID(Q78,4,2) -> MI | O78: =IF(ISERROR(IF(VLOOKUP($N78,CODE!$K:$P,CODE!$O$1,FALSE)="",$M78,$M78&"-"&VLOOKUP($N78,CODE!$K:$P,CODE!$O$1,FALSE)))=TRUE,"",IF(VLOOKUP($N78,CODE!$K:$P,CODE!$O$1,FALSE)="",$M78,$M78&"-"&VLOOKUP($N78,CODE!$K:$P,CODE!$O$1,FALSE))) -> JIL | P78: =MID(Q78,1,10) -> JILMIE5303 | Q78: JILMIE5303GY | R78: M | S78: 500 | T78: 24500000 | U78: 3205070 | V78: 6.9492171 | W78: 0 | X78: 500
... A343: =IF(OR(MID(Q343,8,1)="3",MID(Q343,8,1)="8"),"신규","러닝") -> 러닝 | B343: =IF(COUNTIF(Q$1:Q342,Q343)=0,"최초","리오더") -> 최초 | C343: =IF($B343="리오더","",P343) -> ELSBPE3613 | D343: =IF(C343="",0,1/COUNTIF(C:C,C343)) -> 1 | E343: =IF($B343="리오더",P343,"") | F343: =IF(E343="",0,1/COUNTIF(E:E,E343)) -> 0 | G343: =IF($B343="리오더","",Q343) -> ELSBPE3613GR | H343: =IF(G343="",0,1/COUNTIF(G:G,G343)) -> 1 | I343: =IF($B343="리오더",Q343,"") | J343: =IF(I343="",0,1/COUNTIF(I:I,I343)) -> 0 | K343: =MID(Q343,6,2) -> E3 | L343: =VLOOKUP(N343,CODE!K:P,CODE!$P$1,FALSE) -> 가방 | M343: =VLOOKUP(MID(Q343,1,3),CODE!$B:$G,CODE!D$1,FALSE) -> ELS | N343: =MID(Q343,4,2) -> BP | O343: =IF(ISERROR(IF(VLOOKUP($N343,CODE!$K:$P,CODE!$O$1,FALSE)="",$M343,$M343&"-"&VLOOKUP($N343,CODE!$K:$P,CODE!$O$1,FALSE)))=TRUE,"",IF(VLOOKUP($N343,CODE!$K:$P,CODE!$O$1,FALSE)="",$M343,$M343&"-"&VLOOKUP($N343,CODE!$K:$P,CODE!$O$1,FALSE))) -> ELS-가방 | P343: =MID(Q343,1,10) -> ELSBPE3613 | Q343: ELSBPE3613GR | R343: M | S343: 500 | T343: 49500000 | U343: 10460000 | V343: 4.3021033 | W343: 500 | X343: 0
A344: =IF(OR(MID(Q344,8,1)="3",MID(Q344,8,1)="8"),"신규","러닝") -> 신규 | B344: 최초 | C344: =IF($B344="리오더","",P344) -> ELSSBE3801 | D344: =IF(C344="",0,1/COUNTIF(C:C,C344)) -> 0.33333333 | E344: =IF($B344="리오더",P344,"") | F344: =IF(E344="",0,1/COUNTIF(E:E,E344)) -> 0 | G344: =IF($B344="리오더","",Q344) -> ELSSBE3801BK | H344: =IF(G344="",0,1/COUNTIF(G:G,G344)) -> 0.5 | I344: =IF($B344="리오더",Q344,"") | J344: =IF(I344="",0,1/COUNTIF(I:I,I344)) -> 0 | K344: =MID(Q344,6,2) -> E3 | L344: =VLOOKUP(N344,CODE!K:P,CODE!$P$1,FALSE) -> 가방 | M344: =VLOOKUP(MID(Q344,1,3),CODE!$B:$G,CODE!D$1,FALSE) -> ELS | N344: =MID(Q344,4,2) -> SB | O344: =IF(ISERROR(IF(VLOOKUP($N344,CODE!$K:$P,CODE!$O$1,FALSE)="",$M344,$M344&"-"&VLOOKUP($N344,CODE!$K:$P,CODE!$O$1,FALSE)))=TRUE,"",IF(VLOOKUP($N344,CODE!$K:$P,CODE!$O$1,FALSE)="",$M344,$M344&"-"&VLOOKUP($N344,CODE!$K:$P,CODE!$O$1,FALSE))) -> ELS-가방 | P344: =MID(Q344,1,10) -> ELSSBE3801 | Q344: ELSSBE3801BK | R344: M | S344: 500 | T344: 22500000 | U344: 5010000 | V344: 4.0827436 | W344: 500 | X344: 0
A345: =IF(OR(MID(Q345,8,1)="3",MID(Q345,8,1)="8"),"신규","러닝") -> 러닝 | B345: =IF(COUNTIF(Q$1:Q344,Q345)=0,"최초","리오더") -> 리오더 | C345: =IF($B345="리오더","",P345) | D345: =IF(C345="",0,1/COUNTIF(C:C,C345)) -> 0 | E345: =IF($B345="리오더",P345,"") -> VBLBAE3216 | F345: =IF(E345="",0,1/COUNTIF(E:E,E345)) -> 0.25 | G345: =IF($B345="리오더","",Q345) | H345: =IF(G345="",0,1/COUNTIF(G:G,G345)) -> 0 | I345: =IF($B345="리오더",Q345,"") -> VBLBAE3216BK | J345: =IF(I345="",0,1/COUNTIF(I:I,I345)) -> 0.5 | K345: =MID(Q345,6,2) -> E3 | L345: =VLOOKUP(N345,CODE!K:P,CODE!$P$1,FALSE) -> 모자 | M345: =VLOOKUP(MID(Q345,1,3),CODE!$B:$G,CODE!D$1,FALSE) -> VBL | N345: =MID(Q345,4,2) -> BA | O345: =IF(ISERROR(IF(VLOOKUP($N345,CODE!$K:$P,CODE!$O$1,FALSE)="",$M345,$M345&"-"&VLOOKUP($N345,CODE!$K:$P,CODE!$O$1,FALSE)))=TRUE,"",IF(VLOOKUP($N345,CODE!$K:$P,CODE!$O$1,FALSE)="",$M345,$M345&"-"&VLOOKUP($N345,CODE!$K:$P,CODE!$O$1,FALSE))) -> VBL | P345: =MID(Q345,1,10) -> VBLBAE3216 | Q345: VBLBAE3216BK | R345: M | S345: 3000 | T345: 147000000 | U345: 25560000 | V345: 5.2283397 | W345: 3000 | X345: 0
A346: =IF(OR(MID(Q346,8,1)="3",MID(Q346,8,1)="8"),"신규","러닝") -> 러닝 | B346: =IF(COUNTIF(Q$1:Q345,Q346)=0,"최초","리오더") -> 최초 | C346: =IF($B346="리오더","",P346) -> BMDBAE3202 | D346: =IF(C346="",0,1/COUNTIF(C:C,C346)) -> 0.25 | E346: =IF($B346="리오더",P346,"") | F346: =IF(E346="",0,1/COUNTIF(E:E,E346)) -> 0 | G346: =IF($B346="리오더","",Q346) -> BMDBAE3202BK | H346: =IF(G346="",0,1/COUNTIF(G:G,G346)) -> 1 | I346: =IF($B346="리오더",Q346,"") | J346: =IF(I346="",0,1/COUNTIF(I:I,I346)) -> 0 | K346: =MID(Q346,6,2) -> E3 | L346: =VLOOKUP(N346,CODE!K:P,CODE!$P$1,FALSE) -> 모자 | M346: =VLOOKUP(MID(Q346,1,3),CODE!$B:$G,CODE!D$1,FALSE) -> BMD | N346: =MID(Q346,4,2) -> BA | O346: =IF(ISERROR(IF(VLOOKUP($N346,CODE!$K:$P,CODE!$O$1,FALSE)="",$M346,$M346&"-"&VLOOKUP($N346,CODE!$K:$P,CODE!$O$1,FALSE)))=TRUE,"",IF(VLOOKUP($N346,CODE!$K:$P,CODE!$O$1,FALSE)="",$M346,$M346&"-"&VLOOKUP($N346,CODE!$K:$P,CODE!$O$1,FALSE))) -> BMD | P346: =MID(Q346,1,10) -> BMDBAE3202 | Q346: BMDBAE3202BK | R346: M | S346: 1000 | T346: 55000000 | U346: 9020000 | V346: 5.5432373 | W346: 497 | X346: 503
A347: =IF(OR(MID(Q347,8,1)="3",MID(Q347,8,1)="8"),"신규","러닝") -> 러닝 | B347: =IF(COUNTIF(Q$1:Q346,Q347)=0,"최초","리오더") -> 최초 | C347: =IF($B347="리오더","",P347) -> BMDBAE3202 | D347: =IF(C347="",0,1/COUNTIF(C:C,C347)) -> 0.25 | E347: =IF($B347="리오더",P347,"") | F347: =IF(E347="",0,1/COUNTIF(E:E,E347)) -> 0 | G347: =IF($B347="리오더","",Q347) -> BMDBAE3202PK | H347: =IF(G347="",0,1/COUNTIF(G:G,G347)) -> 1 | I347: =IF($B347="리오더",Q347,"") | J347: =IF(I347="",0,1/COUNTIF(I:I,I347)) -> 0 | K347: =MID(Q347,6,2) -> E3 | L347: =VLOOKUP(N347,CODE!K:P,CODE!$P$1,FALSE) -> 모자 | M347: =VLOOKUP(MID(Q347,1,3),CODE!$B:$G,CODE!D$1,FALSE) -> BMD | N347: =MID(Q347,4,2) -> BA | O347: =IF(ISERROR(IF(VLOOKUP($N347,CODE!$K:$P,CODE!$O$1,FALSE)="",$M347,$M347&"-"&VLOOKUP($N347,CODE!$K:$P,CODE!$O$1,FALSE)))=TRUE,"",IF(VLOOKUP($N347,CODE!$K:$P,CODE!$O$1,FALSE)="",$M347,$M347&"-"&VLOOKUP($N347,CODE!$K:$P,CODE!$O$1,FALSE))) -> BMD | P347: =MID(Q347,1,10) -> BMDBAE3202 | Q347: BMDBAE3202PK | R347: M | S347: 1000 | T347: 55000000 | U347: 9020000 | V347: 5.5432373 | W347: 499 | X347: 501
A348: =IF(OR(MID(Q348,8,1)="3",MID(Q348,8,1)="8"),"신규","러닝") -> 신규 | B348: =IF(COUNTIF(Q$1:Q347,Q348)=0,"최초","리오더") -> 최초 | C348: =IF($B348="리오더","",P348) -> HCUMIE3304 | D348: =IF(C348="",0,1/COUNTIF(C:C,C348)) -> 1 | E348: =IF($B348="리오더",P348,"") | F348: =IF(E348="",0,1/COUNTIF(E:E,E348)) -> 0 | G348: =IF($B348="리오더","",Q348) -> HCUMIE3304BK | H348: =IF(G348="",0,1/COUNTIF(G:G,G348)) -> 1 | I348: =IF($B348="리오더",Q348,"") | J348: =IF(I348="",0,1/COUNTIF(I:I,I348)) -> 0 | K348: =MID(Q348,6,2) -> E3 | L348: =VLOOKUP(N348,CODE!K:P,CODE!$P$1,FALSE) -> 모자 | M348: =VLOOKUP(MID(Q348,1,3),CODE!$B:$G,CODE!D$1,FALSE) -> HCU | N348: =MID(Q348,4,2) -> MI | O348: =IF(ISERROR(IF(VLOOKUP($N348,CODE!$K:$P,CODE!$O$1,FALSE)="",$M348,$M348&"-"&VLOOKUP($N348,CODE!$K:$P,CODE!$O$1,FALSE)))=TRUE,"",IF(VLOOKUP($N348,CODE!$K:$P,CODE!$O$1,FALSE)="",$M348,$M348&"-"&VLOOKUP($N348,CODE!$K:$P,CODE!$O$1,FALSE))) -> HCU | P348: =MID(Q348,1,10) -> HCUMIE3304 | Q348: HCUMIE3304BK | R348: M | S348: 1000 | T348: 49000000 | U348: 5938470 | V348: 7.5011669 | W348: 0 | X348: 1000
A349: =IF(OR(MID(Q349,8,1)="3",MID(Q349,8,1)="8"),"신규","러닝") -> 신규 | B349: =IF(COUNTIF(Q$1:Q348,Q349)=0,"최초","리오더") -> 최초 | C349: =IF($B349="리오더","",P349) -> HCUMIE3305 | D349: =IF(C349="",0,1/COUNTIF(C:C,C349)) -> 1 | E349: =IF($B349="리오더",P349,"") | F349: =IF(E349="",0,1/COUNTIF(E:E,E349)) -> 0 | G349: =IF($B349="리오더","",Q349) -> HCUMIE3305NY | H349: =IF(G349="",0,1/COUNTIF(G:G,G349)) -> 1 | I349: =IF($B349="리오더",Q349,"") | J349: =IF(I349="",0,1/COUNTIF(I:I,I349)) -> 0 | K349: =MID(Q349,6,2) -> E3 | L349: =VLOOKUP(N349,CODE!K:P,CODE!$P$1,FALSE) -> 모자 | M349: =VLOOKUP(MID(Q349,1,3),CODE!$B:$G,CODE!D$1,FALSE) -> HCU | N349: =MID(Q349,4,2) -> MI | O349: =IF(ISERROR(IF(VLOOKUP($N349,CODE!$K:$P,CODE!$O$1,FALSE)="",$M349,$M349&"-"&VLOOKUP($N349,CODE!$K:$P,CODE!$O$1,FALSE)))=TRUE,"",IF(VLOOKUP($N349,CODE!$K:$P,CODE!$O$1,FALSE)="",$M349,$M349&"-"&VLOOKUP($N349,CODE!$K:$P,CODE!$O$1,FALSE))) -> HCU | P349: =MID(Q349,1,10) -> HCUMIE3305 | Q349: HCUMIE3305NY | R349: M | S349: 800 | T349: 44000000 | U349: 7126060 | V349: 5.6132 | W349: 0 | X349: 800
A350: =IF(OR(MID(Q350,8,1)="3",MID(Q350,8,1)="8"),"신규","러닝") -> 신규 | B350: =IF(COUNTIF(Q$1:Q349,Q350)=0,"최초","리오더") -> 최초 | C350: =IF($B350="리오더","",P350) -> HCUMIE3306 | D350: =IF(C350="",0,1/COUNTIF(C:C,C350)) -> 0.5 | E350: =IF($B350="리오더",P350,"") | F350: =IF(E350="",0,1/COUNTIF(E:E,E350)) -> 0 | G350: =IF($B350="리오더","",Q350) -> HCUMIE3306KH | H350: =IF(G350="",0,1/COUNTIF(G:G,G350)) -> 1 | I350: =IF($B350="리오더",Q350,"") | J350: =IF(I350="",0,1/COUNTIF(I:I,I350)) -> 0 | K350: =MID(Q350,6,2) -> E3 | L350: =VLOOKUP(N350,CODE!K:P,CODE!$P$1,FALSE) -> 모자 | M350: =VLOOKUP(MID(Q350,1,3),CODE!$B:$G,CODE!D$1,FALSE) -> HCU | N350: =MID(Q350,4,2) -> MI | O350: =IF(ISERROR(IF(VLOOKUP($N350,CODE!$K:$P,CODE!$O$1,FALSE)="",$M350,$M350&"-"&VLOOKUP($N350,CODE!$K:$P,CODE!$O$1,FALSE)))=TRUE,"",IF(VLOOKUP($N350,CODE!$K:$P,CODE!$O$1,FALSE)="",$M350,$M350&"-"&VLOOKUP($N350,CODE!$K:$P,CODE!$O$1,FALSE))) -> HCU | P350: =MID(Q350,1,10) -> HCUMIE3306 | Q350: HCUMIE3306KH | R350: M | S350: 800 | T350: 44000000 | U350: 7517256 | V350: 5.3210906 | W350: 0 | X350: 800
A351: =IF(OR(MID(Q351,8,1)="3",MID(Q351,8,1)="8"),"신규","러닝") -> 신규 | B351: =IF(COUNTIF(Q$1:Q350,Q351)=0,"최초","리오더") -> 최초 | C351: =IF($B351="리오더","",P351) -> HCUMIE3306 | D351: =IF(C351="",0,1/COUNTIF(C:C,C351)) -> 0.5 | E351: =IF($B351="리오더",P351,"") | F351: =IF(E351="",0,1/COUNTIF(E:E,E351)) -> 0 | G351: =IF($B351="리오더","",Q351) -> HCUMIE3306BK | H351: =IF(G351="",0,1/COUNTIF(G:G,G351)) -> 1 | I351: =IF($B351="리오더",Q351,"") | J351: =IF(I351="",0,1/COUNTIF(I:I,I351)) -> 0 | K351: =MID(Q351,6,2) -> E3 | L351: =VLOOKUP(N351,CODE!K:P,CODE!$P$1,FALSE) -> 모자 | M351: =VLOOKUP(MID(Q351,1,3),CODE!$B:$G,CODE!D$1,FALSE) -> HCU | N351: =MID(Q351,4,2) -> MI | O351: =IF(ISERROR(IF(VLOOKUP($N351,CODE!$K:$P,CODE!$O$1,FALSE)="",$M351,$M351&"-"&VLOOKUP($N351,CODE!$K:$P,CODE!$O$1,FALSE)))=TRUE,"",IF(VLOOKUP($N351,CODE!$K:$P,CODE!$O$1,FALSE)="",$M351,$M351&"-"&VLOOKUP($N351,CODE!$K:$P,CODE!$O$1,FALSE))) -> HCU | P351: =MID(Q351,1,10) -> HCUMIE3306 | Q351: HCUMIE3306BK | R351: M | S351: 800 | T351: 44000000 | U351: 7517256 | V351: 5.3210906 | W351: 0 | X351: 800
A352: =IF(OR(MID(Q352,8,1)="3",MID(Q352,8,1)="8"),"신규","러닝") -> 신규 | B352: =IF(COUNTIF(Q$1:Q351,Q352)=0,"최초","리오더") -> 최초 | C352: =IF($B352="리오더","",P352) -> HCUMIE3307 | D352: =IF(C352="",0,1/COUNTIF(C:C,C352)) -> 1 | E352: =IF($B352="리오더",P352,"") | F352: =IF(E352="",0,1/COUNTIF(E:E,E352)) -> 0 | G352: =IF($B352="리오더","",Q352) -> HCUMIE3307GY | H352: =IF(G352="",0,1/COUNTIF(G:G,G352)) -> 1 | I352: =IF($B352="리오더",Q352,"") | J352: =IF(I352="",0,1/COUNTIF(I:I,I352)) -> 0 | K352: =MID(Q352,6,2) -> E3 | L352: =VLOOKUP(N352,CODE!K:P,CODE!$P$1,FALSE) -> 모자 | M352: =VLOOKUP(MID(Q352,1,3),CODE!$B:$G,CODE!D$1,FALSE) -> HCU | N352: =MID(Q352,4,2) -> MI | O352: =IF(ISERROR(IF(VLOOKUP($N352,CODE!$K:$P,CODE!$O$1,FALSE)="",$M352,$M352&"-"&VLOOKUP($N352,CODE!$K:$P,CODE!$O$1,FALSE)))=TRUE,"",IF(VLOOKUP($N352,CODE!$K:$P,CODE!$O$1,FALSE)="",$M352,$M352&"-"&VLOOKUP($N352,CODE!$K:$P,CODE!$O$1,FALSE))) -> HCU | P352: =MID(Q352,1,10) -> HCUMIE3307 | Q352: HCUMIE3307GY | R352: M | S352: 800 | T352: 44000000 | U352: 7236176 | V352: 5.5277815 | W352: 0 | X352: 800
A353: =IF(OR(MID(Q353,8,1)="3",MID(Q353,8,1)="8"),"신규","러닝") -> 신규 | B353: =IF(COUNTIF(Q$1:Q352,Q353)=0,"최초","리오더") -> 최초 | C353: =IF($B353="리오더","",P353) -> HCUERE5308 | D353: =IF(C353="",0,1/COUNTIF(C:C,C353)) -> 0.5 | E353: =IF($B353="리오더",P353,"") | F353: =IF(E353="",0,1/COUNTIF(E:E,E353)) -> 0 | G353: =IF($B353="리오더","",Q353) -> HCUERE5308KH | H353: =IF(G353="",0,1/COUNTIF(G:G,G353)) -> 1 | I353: =IF($B353="리오더",Q353,"") | J353: =IF(I353="",0,1/COUNTIF(I:I,I353)) -> 0 | K353: =MID(Q353,6,2) -> E5 | L353: =VLOOKUP(N353,CODE!K:P,CODE!$P$1,FALSE) -> 모자 | M353: =VLOOKUP(MID(Q353,1,3),CODE!$B:$G,CODE!D$1,FALSE) -> HCU | N353: =MID(Q353,4,2) -> ER | O353: =IF(ISERROR(IF(VLOOKUP($N353,CODE!$K:$P,CODE!$O$1,FALSE)="",$M353,$M353&"-"&VLOOKUP($N353,CODE!$K:$P,CODE!$O$1,FALSE)))=TRUE,"",IF(VLOOKUP($N353,CODE!$K:$P,CODE!$O$1,FALSE)="",$M353,$M353&"-"&VLOOKUP($N353,CODE!$K:$P,CODE!$O$1,FALSE))) -> HCU | P353: =MID(Q353,1,10) -> HCUERE5308 | Q353: HCUERE5308KH | R353: M | S353: 800 | T353: 47200000 | U353: 6631792 | V353: 6.4702106 | W353: 0 | X353: 800
A354: =IF(OR(MID(Q354,8,1)="3",MID(Q354,8,1)="8"),"신규","러닝") -> 신규 | B354: =IF(COUNTIF(Q$1:Q353,Q354)=0,"최초","리오더") -> 최초 | C354: =IF($B354="리오더","",P354) -> HCUERE5308 | D354: =IF(C354="",0,1/COUNTIF(C:C,C354)) -> 0.5 | E354: =IF($B354="리오더",P354,"") | F354: =IF(E354="",0,1/COUNTIF(E:E,E354)) -> 0 | G354: =IF($B354="리오더","",Q354) -> HCUERE5308BK | H354: =IF(G354="",0,1/COUNTIF(G:G,G354)) -> 1 | I354: =IF($B354="리오더",Q354,"") | J354: =IF(I354="",0,1/COUNTIF(I:I,I354)) -> 0 | K354: =MID(Q354,6,2) -> E5 | L354: =VLOOKUP(N354,CODE!K:P,CODE!$P$1,FALSE) -> 모자 | M354: =VLOOKUP(MID(Q354,1,3),CODE!$B:$G,CODE!D$1,FALSE) -> HCU | N354: =MID(Q354,4,2) -> ER | O354: =IF(ISERROR(IF(VLOOKUP($N354,CODE!$K:$P,CODE!$O$1,FALSE)="",$M354,$M354&"-"&VLOOKUP($N354,CODE!$K:$P,CODE!$O$1,FALSE)))=TRUE,"",IF(VLOOKUP($N354,CODE!$K:$P,CODE!$O$1,FALSE)="",$M354,$M354&"-"&VLOOKUP($N354,CODE!$K:$P,CODE!$O$1,FALSE))) -> HCU | P354: =MID(Q354,1,10) -> HCUERE5308 | Q354: HCUERE5308BK | R354: M | S354: 800 | T354: 47200000 | U354: 6813792 | V354: 6.2973878 | W354: 0 | X354: 800
A355: =IF(OR(MID(Q355,8,1)="3",MID(Q355,8,1)="8"),"신규","러닝") -> 신규 | B355: =IF(COUNTIF(Q$1:Q354,Q355)=0,"최초","리오더") -> 최초 | C355: =IF($B355="리오더","",P355) -> PLAUME3301 | D355: =IF(C355="",0,1/COUNTIF(C:C,C355)) -> 1 | E355: =IF($B355="리오더",P355,"") | F355: =IF(E355="",0,1/COUNTIF(E:E,E355)) -> 0 | G355: =IF($B355="리오더","",Q355) -> PLAUME3301BL | H355: =IF(G355="",0,1/COUNTIF(G:G,G355)) -> 1 | I355: =IF($B355="리오더",Q355,"") | J355: =IF(I355="",0,1/COUNTIF(I:I,I355)) -> 0 | K355: =MID(Q355,6,2) -> E3 | L355: =VLOOKUP(N355,CODE!K:P,CODE!$P$1,FALSE) -> 모자 | M355: =VLOOKUP(MID(Q355,1,3),CODE!$B:$G,CODE!D$1,FALSE) -> PLA | N355: =MID(Q355,4,2) -> UM | O355: =IF(ISERROR(IF(VLOOKUP($N355,CODE!$K:$P,CODE!$O$1,FALSE)="",$M355,$M355&"-"&VLOOKUP($N355,CODE!$K:$P,CODE!$O$1,FALSE)))=TRUE,"",IF(VLOOKUP($N355,CODE!$K:$P,CODE!$O$1,FALSE)="",$M355,$M355&"-"&VLOOKUP($N355,CODE!$K:$P,CODE!$O$1,FALSE))) -> PLA | P355: =MID(Q355,1,10) -> PLAUME3301 | Q355: PLAUME3301BL | R355: M | S355: 700 | T355: 45500000 | U355: 6112260 | V355: 6.7673228 | W355: 0 | X355: 700
...

Sheet P (2)
B1: 2013 FW 기획진행현황 (HATS ON) 2
P2: 41470
B3: 분류 | C3: 브랜드품목 | D3: 러닝/신규 | E3: 최초/리오더 | F3: 품번수 | G3: 품번수(리오더) | H3: 색상수 | I3: 색상수(리오더) | J3: 기획수량 | K3: LOT | L3: TAG가 | M3: 원가(-V) | N3: 배수 | O3: 입고수량 | P3: 미입고수량
F6: 데이터
B7: 분류 | C7: 브랜드품목 | D7: 러닝/신규 | E7: 최초/리오더 | F7: 품번수 | G7: 품번수(리오더) | H7: 색상수 | I7: 색상수(리오더) | J7: 기획수량 | K7: LOT | L7: TAG가 | M7: 원가(-V) | N7: 배수 | O7: 입고수량 | P7: 미입고수량
B8: M | C8: ELS | D8: 신규 | E8: 최초 | F8: 63 | G8: 0 | H8: 84 | I8: 0 | J8: 66800 | K8: 795.2381 | L8: 3149920000 | M8: 5.3018883e+08 | N8: 5.401026 | O8: 0 | P8: 66800
D9: 러닝 | E9: 최초 | F9: 37 | G9: 0 | H9: 47 | I9: 0 | J9: 80800 | K9: 1719.1489 | L9: 4096800000 | M9: 5.4282717e+08 | N9: 6.8610487 | O9: 4000 | P9: 76500
E10: 리오더 | F10: 0 | G10: 2 | H10: 0 | I10: 2 | J10: 3200 | K10: 1600 | L10: 164000000 | M10: 20373280 | N10: 7.317963 | O10: 0 | P10: 3200
C11: ELS-가방 | D11: 신규 | E11: 최초 | F11: 6 | G11: 0 | H11: 7 | I11: 0 | J11: 4000 | K11: 571.42857 | L11: 271000000 | M11: 58830000 | N11: 4.1877212 | O11: 2500 | P11: 1500
E12: 리오더 | F12: 0 | G12: 2 | H12: 0 | I12: 2 | J12: 1000 | K12: 500 | L12: 45000000 | M12: 10020000 | N12: 4.0827436 | O12: 0 | P12: 1000
D13: 러닝 | E13: 최초 | F13: 10 | G13: 0 | H13: 14 | I13: 0 | J13: 8000 | K13: 571.42857 | L13: 877000000 | M13: 181110000 | N13: 4.4021464 | O13: 3500 | P13: 4500
E14: 리오더 | F14: 0 | G14: 2 | H14: 0 | I14: 2 | J14: 1700 | K14: 850 | L14: 185300000 | M14: 38964000 | N14: 4.3233381 | O14: 0 | P14: 1700
C15: ELS-의류 | D15: 신규 | E15: 최초 | F15: 51 | G15: 0 | H15: 65 | I15: 0 | J15: 77100 | K15: 1186.1538 | L15: 7748900000 | M15: 1.677303e+09 | N15: 4.1998701 | O15: 0 | P15: 77100
C16: SMB | D16: 신규 | E16: 최초 | F16: 42 | G16: 0 | H16: 43 | I16: 0 | J16: 30600 | K16: 711.62791 | L16: 1464400000 | M16: 2.115326e+08 | N16: 6.2934636 | O16: 0 | P16: 30600
D17: 러닝 | E17: 최초 | F17: 33 | G17: 0 | H17: 34 | I17: 0 | J17: 32100 | K17: 944.11765 | L17: 1528900000 | M17: 2.1537471e+08 | N17: 6.4534461 | O17: 5399 | P17: 26700
E18: 리오더 | F18: 0 | G18: 6 | H18: 0 | I18: 6 | J18: 12300 | K18: 2050 | L18: 662700000 | M18: 86064935 | N18: 7 | O18: 0 | P18: 12300
C19: NAA | D19: 신규 | E19: 최초 | F19: 18 | G19: 0 | H19: 18 | I19: 0 | J19: 11600 | K19: 644.44444 | L19: 538600000 | M19: 82074300 | N19: 5.9657696 | O19: 0 | P19: 11600
C20: NOV | D20: 신규 | E20: 최초 | F20: 27 | G20: 0 | H20: 34 | I20: 0 | J20: 17400 | K20: 511.76471 | L20: 953600000 | M20: 117210570 | N20: 7.3961682 | O20: 4445 | P20: 12900
D21: 러닝 | E21: 최초 | F21: 5 | G21: 0 | H21: 7 | I21: 0 | J21: 5100 | K21: 728.57143 | L21: 257900000 | M21: 33221489 | N21: 7.057316 | O21: 0 | P21: 5100
C22: VBL | D22: 신규 | E22: 최초 | F22: 22 | G22: 0 | H22: 22 | I22: 0 | J22: 14850 | K22: 675 | L22: 812350000 | M22: 1.0393502e+08 | N22: 7.1054011 | O22: 0 | P22: 14850
D23: 러닝 | E23: 최초 | F23: 8 | G23: 0 | H23: 13 | I23: 0 | J23: 20200 | K23: 1553.8462 | L23: 1044600000 | M23: 156693295 | N23: 6.0604786 | O23: 15343 | P23: 4500
E24: 리오더 | F24: 0 | G24: 4 | H24: 0 | I24: 7 | J24: 20700 | K24: 2957.1429 | L24: 1052100000 | M24: 1.5622644e+08 | N24: 6.1222321 | O24: 3700 | P24: 17000
C25: PLA | D25: 신규 | E25: 최초 | F25: 6 | G25: 0 | H25: 7 | I25: 0 | J25: 5100 | K25: 728.57143 | L25: 309300000 | M25: 40839876 | N25: 6.8849822 | O25: 0 | P25: 5100
D26: 러닝 | E26: 최초 | F26: 5 | G26: 0 | H26: 5 | I26: 0 | J26: 4700 | K26: 940 | L26: 277300000 | M26: 36611190 | N26: 6.8856246 | O26: 2200 | P26: 2500
E27: 리오더 | F27: 0 | G27: 1 | H27: 0 | I27: 1 | J27: 3000 | K27: 3000 | L27: 177000000 | M27: 24324300 | N27: 6.6151581 | O27: 0 | P27: 3000
C28: JIL | D28: 신규 | E28: 최초 | F28: 73 | G28: 0 | H28: 118 | I28: 0 | J28: 94400 | K28: 800 | L28: 3814000000 | M28: 5.3899017e+08 | N28: 6.4329053 | O28: 19078 | P28: 75400
E29: 리오더 | F29: 0 | G29: 3 | H29: 0 | I29: 4 | J29: 14500 | K29: 3625 | L29: 420500000 | M29: 75032701 | N29: 5.0947483 | O29: 0 | P29: 14500
D30: 러닝 | E30: 최초 | F30: 18 | G30: 0 | H30: 28 | I30: 0 | J30: 32100 | K30: 1146.4286 | L30: 1400700000 | M30: 189346650 | N30: 6.7250392 | O30: 2000 | P30: 30100
C31: HCU | D31: 신규 | E31: 최초 | F31: 8 | G31: 0 | H31: 13 | I31: 0 | J31: 19800 | K31: 1523.0769 | L31: 859400000 | M31: 144054432 | N31: 5.423455 | O31: 11697 | P31: 5800
E32: 리오더 | F32: 0 | G32: 1 | H32: 0 | I32: 1 | J32: 2000 | K32: 2000 | L32: 70000000 | M32: 10606061 | N32: 6 | O32: 0 | P32: 2000
D33: 러닝 | E33: 최초 | F33: 6 | G33: 0 | H33: 7 | I33: 0 | J33: 6500 | K33: 928.57143 | L33: 319700000 | M33: 50390431 | N33: 5.7676896 | O33: 0 | P33: 6500
C34: BRO | D34: 러닝 | E34: 최초 | F34: 5 | G34: 0 | H34: 5 | I34: 0 | J34: 2800 | K34: 560 | L34: 163200000 | M34: 26673954 | N34: 5.5621164 | O34: 0 | P34: 2800
C35: BMD | D35: 신규 | E35: 최초 | F35: 3 | G35: 0 | H35: 9 | I35: 0 | J35: 5700 | K35: 633.33333 | L35: 320900000 | M35: 54958652 | N35: 5.3081228 | O35: 0 | P35: 5700
D36: 러닝 | E36: 최초 | F36: 2 | G36: 0 | H36: 6 | I36: 0 | J36: 4500 | K36: 750 | L36: 241500000 | M36: 41390000 | N36: 5.3043115 | O36: 996 | P36: 3504
E37: 리오더 | F37: 0 | G37: 1 | H37: 0 | I37: 3 | J37: 4000 | K37: 1333.3333 | L37: 220000000 | M37: 36000000 | N37: 5.5555556 | O37: 0 | P37: 4000
C38: WTR | D38: 신규 | E38: 최초 | F38: 12 | G38: 0 | H38: 12 | I38: 0 | J38: 6900 | K38: 575 | L38: 424700000 | M38: 81895064 | N38: 4.7144588 | O38: 0 | P38: 6900
D39: 러닝 | E39: 최초 | F39: 5 | G39: 0 | H39: 5 | I39: 0 | J39: 2800 | K39: 560 | L39: 166600000 | M39: 35896077 | N39: 4.2192506 | O39: 0 | P39: 2800
C40: JOI | D40: 신규 | E40: 최초 | F40: 15 | G40: 0 | H40: 17 | I40: 0 | J40: 7300 | K40: 429.41176 | L40: 409100000 | M40: 66711087 | N40: 5.5749217 | O40: 0 | P40: 7300
D41: 러닝 | E41: 최초 | F41: 4 | G41: 0 | H41: 4 | I41: 0 | J41: 2000 | K41: 500 | L41: 110000000 | M41: 16167325 | N41: 6.1853151 | O41: 0 | P41: 2000
C42: ELS-ACC | D42: 신규 | E42: 최초 | F42: 2 | G42: 0 | H42: 2 | I42: 0 | J42: 1000 | K42: 500 | L42: 43000000 | M42: 8003360 | N42: 4.8843122 | O42: 0 | P42: 1000
...

Sheet CODE
C1: 2 | D1: 3 | E1: 4 | F1: 5 | G1: 6 | L1: 2 | M1: 3 | N1: 4 | O1: 5 | P1: 6 | S1: 2 | T1: 3 | X1: 2 | Y1: 3 | AE1: 2 | AF1: 3 | AJ1: 2 | AK1: 3 | AL1: 4 | AO1: 2 | AP1: 3 | AS1: 2 | AT1: 3 | AW1: 2 | AX1: 3
A2: BRAND (3자리) | I2: ITEM (2자리) | R2: YEAR (2자리) | V2: SEASON (1자리) | AA2: STNO (3자리) | AC2: COLOR (2자리) | AH2: SIZE (3자리) | AN2: 분류 | AR2: 성별 | AV2: 원산지
A3: 구코드 | B3: 코드 | C3: 코드명 | D3: 그룹 | E3: 코드 | F3: 구분 | G3: B/M/C | I3: 구코드 | J3: 구코드명 | K3: 코드 | L3: 코드명 | M3: 코드 | N3: 구분 | O3: 구분 | P3: 구분 | R3: 코드 | S3: 코드명 | T3: 코드 | V3: 구코드 | W3: 코드 | X3: 코드명 | Y3: 코드 | AA3: 코드 | AC3: 구코드 | AD3: 코드 | AE3: 코드명 | AF3: 코드 | AH3: 구코드 | AI3: 코드 | AJ3: 코드명 | AK3: TYPE | AL3: 코드 | AN3: 코드 | AO3: 코드명 | AP3: 코드 | AR3: 코드 | AS3: 코드명 | AT3: 코드 | AV3: 코드 | AW3: 코드명 | AX3: 코드
A4: BZ | C4: COP CARDINALS | D4: =B4 -> 0 | E4: =B4 -> 0 | F4: SPORTS | G4: B | I4: CA | J4: BASIC CAP (핀치히터) | K4: BA | L4: BASIC CAP | M4: =K4 -> BA | N4: 의류외 | P4: 모자 | R4: A | S4: 2009 | T4: =R4 -> A | V4: 0 | W4: 0 | X4: SS | Y4: =W4 -> 0 | AA4: 001 | AC4: B0 | AD4: BK | AE4: Black | AF4: =AD4 -> BK | AH4: A | AI4: FRE | AJ4: OSFA(ADJUST CAP) | AK4: 1 | AL4: =AI4 -> FRE | AN4: B | AO4: 사입 | AP4: =AN4 -> B | AR4: M | AS4: 남자 | AT4: =AR4 -> M | AV4: CN | AW4: 중국 | AX4: =AV4 -> CN
A5: BH | C5: COP INDIANS | D5: =B5 -> 0 | E5: =B5 -> 0 | F5: SPORTS | G5: B | I5: CS | J5: VISOR CAP | K5: BA | L5: BASIC CAP | M5: =K5 -> BA | N5: 의류외 | P5: 모자 | R5: B | S5: 2010 | T5: =R5 -> B | V5: 1 | W5: 0 | X5: SS | Y5: =W5 -> 0 | AA5: 002 | AC5: B1 | AE5: Black Camo | AF5: =AD5 -> 0 | AH5: N | AI5: OXS | AJ5: XS | AK5: 1 | AL5: =AI5 -> OXS | AN5: C | AO5: 위탁 | AP5: =AN5 -> C | AR5: W | AS5: 여자 | AT5: =AR5 -> W | AV5: JP | AW5: 일본 | AX5: =AV5 -> JP
A6: BR | C6: COP METS | D6: =B6 -> 0 | E6: =B6 -> 0 | F6: SPORTS | G6: B | I6: CC | J6: FLEX CAP (3930) | K6: FL | L6: FLEX CAP | M6: =K6 -> FL | N6: 의류외 | P6: 모자 | R6: C | S6: 2011 | T6: =R6 -> C | V6: 2 | W6: 0 | X6: SS | Y6: =W6 -> 0 | AA6: 003 | AC6: B2 | AE6: Black Leopard | AF6: =AD6 -> 0 | AI6: OSS | AJ6: S | AK6: 1 | AL6: =AI6 -> OSS | AN6: M | AO6: 제조 | AP6: =AN6 -> M | AR6: U | AS6: UNISEX | AT6: =AR6 -> U | AV6: KR | AW6: 한국 | AX6: =AV6 -> KR
A7: BC | C7: COP ORIOLES | D7: =B7 -> 0 | E7: =B7 -> 0 | F7: SPORTS | G7: B | I7: CD | J7: NORMAL FITTED CAP (커브) | K7: FL | L7: FLEX CAP | M7: =K7 -> FL | N7: 의류외 | P7: 모자 | R7: D | S7: 2012 | T7: =R7 -> D | V7: 3 | W7: 0 | X7: SS | Y7: =W7 -> 0 | AA7: 004 | AC7: B3 | AE7: Black/White | AF7: =AD7 -> 0 | AI7: OMM | AJ7: M | AK7: 1 | AL7: =AI7 -> OMM | AR7: K | AS7: KIDS | AT7: =AR7 -> K | AV7: US | AW7: 미국 | AX7: =AV7 -> US
A8: BJ | C8: COP TIGERS | D8: =B8 -> 0 | E8: =B8 -> 0 | F8: SPORTS | G8: B | I8: CE | J8: FLAT BILL FITTED CAP(5950) | K8: FI | L8: FITTED CAP | M8: =K8 -> FI | N8: 의류외 | P8: 모자 | R8: E | S8: 2013 | T8: =R8 -> E | V8: 4 | W8: 0 | X8: SS | Y8: =W8 -> 0 | AA8: 005 | AC8: B4 | AE8: Black/Flann | AF8: =AD8 -> 0 | AI8: OLL | AJ8: L | AK8: 1 | AL8: =AI8 -> OLL | AR8: N | AS8: NEWERA | AT8: =AR8 -> N | AV8: IN | AW8: 인도네시아 | AX8: =AV8 -> IN
A9: KC | B9: KDO | C9: DOOSAN BEARS | D9: KBO | E9: =B9 -> KDO | F9: SPORTS | G9: B | I9: CU | J9: FLAT BILL FLEX CAP(일자) | K9: FI | L9: FITTED CAP | M9: =K9 -> FI | N9: 의류외 | P9: 모자 | R9: F | S9: 2014 | T9: =R9 -> F | V9: 5 | W9: 3 | X9: FW | Y9: =W9 -> 3 | AA9: 006 | AC9: B5 | AE9: Dark Flann | AF9: =AD9 -> 0 | AI9: OXL | AJ9: XL | AK9: 1 | AL9: =AI9 -> OXL | AR9: A | AS9: AUTHENTIC | AT9: =AR9 -> A | AV9: BG | AW9: 방글라데시 | AX9: =AV9 -> BG
A10: CD | B10: ZCD | C10: EUR BARCELONA | D10: =B10 -> ZCD | E10: =B10 -> ZCD | F10: SPORTS | G10: B | I10: DA | J10: FLAT BILL FITTED BASIC (BLANK 5950) | K10: FI | L10: FITTED CAP | M10: =K10 -> FI | N10: 의류외 | P10: 모자 | R10: G | S10: 2015 | T10: =R10 -> G | V10: 6 | W10: 3 | X10: FW | Y10: =W10 -> 3 | AA10: 007 | AC10: B6 | AE10: Loden | AF10: =AD10 -> 0 | AH10: O | AI10: OSM | AJ10: S~M | AK10: 1 | AL10: =AI10 -> OSM | AV10: DE | AW10: 독일 | AX10: =AV10 -> DE
A11: CA | B11: ZCA | C11: EUR MUCHESTER | D11: =B11 -> ZCA | E11: =B11 -> ZCA | F11: SPORTS | G11: B | I11: CB | J11: WASHED CAP (워싱캡) | K11: WC | L11: WASHED CAP | M11: =K11 -> WC | N11: 의류외 | P11: 모자 | R11: H | S11: 2016 | T11: =R11 -> H | V11: 7 | W11: 3 | X11: FW | Y11: =W11 -> 3 | AA11: 008 | AC11: B7 | AE11: Pine X | AF11: =AD11 -> 0 | AH11: P | AI11: OML | AJ11: M~L | AK11: 1 | AL11: =AI11 -> OML | AV11: AT | AW11: 오스트리아 | AX11: =AV11 -> AT
A12: KH | B12: KHA | C12: HANWHA EAGLES | D12: KBO | E12: =B12 -> KHA | F12: SPORTS | G12: B | I12: CF | J12: TRUCKER CAP | K12: TR | L12: TRUCKER CAP | M12: =K12 -> TR | N12: 의류외 | P12: 모자 | R12: I | S12: 2017 | T12: =R12 -> I | V12: 8 | W12: 3 | X12: FW | Y12: =W12 -> 3 | AA12: 009 | AC12: B8 | AE12: Block | AF12: =AD12 -> 0 | AH12: Q | AI12: LXL | AJ12: L~XL | AK12: 1 | AL12: =AI12 -> LXL | AV12: BE | AW12: 벨기에 | AX12: =AV12 -> BE
A13: KA | B13: KKI | C13: KIA TIGERS | D13: KBO | E13: =B13 -> KKI | F13: SPORTS | G13: B | I13: CV | J13: MESH CAP(커브) | K13: TR | L13: TRUCKER CAP | M13: =K13 -> TR | N13: 의류외 | P13: 모자 | R13: J | S13: 2018 | T13: =R13 -> J | V13: 9 | W13: 3 | X13: FW | Y13: =W13 -> 3 | AA13: 010 | AC13: B9 | AD13: BU | AE13: Burgundy | AF13: =AD13 -> BU | AV13: CH | AW13: 스위스 | AX13: =AV13 -> CH
A14: KG | B14: KLG | C14: LG TWINS | D14: KBO | E14: =B14 -> KLG | F14: SPORTS | G14: B | I14: CW | J14: FLAT BILL MESH CAP(일자) | K14: TR | L14: TRUCKER CAP | M14: =K14 -> TR | N14: 의류외 | P14: 모자 | AC14: BA | AE14: PLAID BLACK | AF14: =AD14 -> 0 | AH14: E | AI14: 700 | AJ14: 7(56CM) | AK14: 2 | AL14: =AI14 -> 700 | AV14: ES | AW14: 스페인 | AX14: =AV14 -> ES
A15: KD | B15: KLO | C15: LOTTE GIANTS | D15: KBO | E15: =B15 -> KLO | F15: SPORTS | G15: B | I15: DB | J15: FLAT BILL TRUCKER CAP | K15: TR | L15: TRUCKER CAP | M15: =K15 -> TR | N15: 의류외 | P15: 모자 | AC15: BB | AE15: Black/Red | AF15: =AD15 -> 0 | AH15: F | AI15: 718 | AJ15: 71/8(57CM) | AK15: 2 | AL15: =AI15 -> 718 | AV15: FR | AW15: 프랑스 | AX15: =AV15 -> FR
A16: AO | B16: NAN | C16: MLB ANGELS | D16: MLB | E16: =B16 -> NAN | F16: SPORTS | G16: B | I16: CZ | J16: UMPIRE | K16: UM | L16: UMPIRE | M16: =K16 -> UM | N16: 의류외 | P16: 모자 | AC16: C1 | AD16: BG | AE16: Beige | AF16: =AD16 -> BG | AH16: G | AI16: 714 | AJ16: 71/4(58CM) | AK16: 2 | AL16: =AI16 -> 714 | AV16: GR | AW16: 영국 | AX16: =AV16 -> GR
A17: AU | B17: NAS | C17: MLB A'S | D17: MLB | E17: =B17 -> NAS | F17: SPORTS | G17: B | I17: CG | J17: PERFORMANCE CAP(기능성) | K17: PE | L17: PERFORMANCE CAP | M17: =K17 -> PE | N17: 의류외 | P17: 모자 | AC17: C2 | AE17: Putty | AF17: =AD17 -> 0 | AH17: H | AI17: 738 | AJ17: 73/8(59CM) | AK17: 2 | AL17: =AI17 -> 738 | AV17: IT | AW17: 이탈리아 | AX17: =AV17 -> IT
