Workbook

Sheet 14FW판매DB
A1: 이월 판매 | B1: 러닝 판매 | C1: 판매/입고예정 | D1: 입고예정
A2: 13FW | B2: 14SS | C2: 14FW | D2: 15SS
A3: 러닝품번색상 오름차순 | C3: 2 | D3: =C3+1 -> 3 | E3: =D3+1 -> 4 | F3: =E3+1 -> 5 | G3: =F3+1 -> 6 | H3: =G3+1 -> 7 | I3: =H3+1 -> 8 | J3: =I3+1 -> 9 | K3: =J3+1 -> 10 | ... AF3: =AE3+1 -> 31
A4: 42463 | AD4: =SUBTOTAL(9,AD6:AD1048576) -> 98
A5: 브랜드품목 | B5: 품번색상 | C5: 러닝품번색상 | D5: 년도시즌 | E5: 품번 | F5: 품번명 | G5: 색상 | H5: 사이즈 | I5: 원가 | J5: TAG가 | K5: 판매가 | L5: 발주 | M5: 최초입고일 | N5: 입고수량 | O5: 입고금액 | P5: 최초출고일 | Q5: 매장출고 | R5: 타계정 | S5: 출고금액 | T5: 최초판매일 | U5: 판매수량 | V5: 판매금액 | W5: 판매율(입,수) | X5: 판매율(입,금) | Y5: 판매율(출,수) | Z5: 판매율(출,금) | AA5: 창고재고수량 | AB5: 매장재고수량 | AC5: 주간판매수량 | AD5: 기간판매수량 | AE5: 기간판매금액 | AF5: 기간판매금액비
A6: =IF(VLOOKUP(MID($B6,4,2),CODE!K:P,CODE!$O$1,FALSE)="",VLOOKUP(MID($B6,1,3),CODE!$B:$G,CODE!$D$1,FALSE),VLOOKUP(MID($B6,1,3),CODE!$B:$G,CODE!$D$1,FALSE)&"-"&VLOOKUP(MID($B6,4,2),CODE!K:P,CODE!$O$1,FALSE)) -> BLH | B6: =IF(ISERROR(VLOOKUP(E6&G6,품번정리!$D:$E,2,FALSE))=TRUE,E6&G6,VLOOKUP(E6&G6,품번정리!$D:$E,2,FALSE)) -> BLHFEF5003BK | C6: =IF(ISERROR(VLOOKUP(MID(B6,1,5)&MID(B6,8,5),품번정리!$A:$B,2,FALSE))=TRUE,MID(B6,1,5)&MID(B6,8,5),VLOOKUP(MID(B6,1,5)&MID(B6,8,5),품번정리!$A:$B,2,FALSE)) -> BLHFE003BK | D6: =MID(E6,6,2) -> F5 | E6: BLHFEF5003 | F6: BLLFEF5003BKFRE | G6: BK | I6: 8358 | J6: 69000 | K6: 69000 | L6: 5 | M6: 2014-12-02 | P6: 2014-12-02
A7: =IF(VLOOKUP(MID($B7,4,2),CODE!K:P,CODE!$O$1,FALSE)="",VLOOKUP(MID($B7,1,3),CODE!$B:$G,CODE!$D$1,FALSE),VLOOKUP(MID($B7,1,3),CODE!$B:$G,CODE!$D$1,FALSE)&"-"&VLOOKUP(MID($B7,4,2),CODE!K:P,CODE!$O$1,FALSE)) -> BRH | B7: =IF(ISERROR(VLOOKUP(E7&G7,품번정리!$D:$E,2,FALSE))=TRUE,E7&G7,VLOOKUP(E7&G7,품번정리!$D:$E,2,FALSE)) -> BRHERF5504WH | C7: =IF(ISERROR(VLOOKUP(MID(B7,1,5)&MID(B7,8,5),품번정리!$A:$B,2,FALSE))=TRUE,MID(B7,1,5)&MID(B7,8,5),VLOOKUP(MID(B7,1,5)&MID(B7,8,5),품번정리!$A:$B,2,FALSE)) -> BRHER504WH | D7: =MID(E7,6,2) -> F5 | E7: BRHERF5504 | F7: BROERF5504WHOSM | G7: WH | I7: 8833 | J7: 55000 | K7: 29000 | L7: 250 | M7: 2014-12-02 | N7: 190 | O7: 10450000 | P7: 2014-12-03 | Q7: 187 | S7: 10285000 | T7: 2014-12-05 | U7: 164 | V7: 5438500 | W7: 86.3 | X7: 52 | Y7: 87.7 | Z7: 52.9 | AA7: 3 | AB7: 23
A8: =IF(VLOOKUP(MID($B8,4,2),CODE!K:P,CODE!$O$1,FALSE)="",VLOOKUP(MID($B8,1,3),CODE!$B:$G,CODE!$D$1,FALSE),VLOOKUP(MID($B8,1,3),CODE!$B:$G,CODE!$D$1,FALSE)&"-"&VLOOKUP(MID($B8,4,2),CODE!K:P,CODE!$O$1,FALSE)) -> BRK | B8: =IF(ISERROR(VLOOKUP(E8&G8,품번정리!$D:$E,2,FALSE))=TRUE,E8&G8,VLOOKUP(E8&G8,품번정리!$D:$E,2,FALSE)) -> BRKBAF5501GY | C8: =IF(ISERROR(VLOOKUP(MID(B8,1,5)&MID(B8,8,5),품번정리!$A:$B,2,FALSE))=TRUE,MID(B8,1,5)&MID(B8,8,5),VLOOKUP(MID(B8,1,5)&MID(B8,8,5),품번정리!$A:$B,2,FALSE)) -> BRKBA501GY | D8: =MID(E8,6,2) -> F5 | E8: BRKBAF5501 | F8: 14FW BROWN_SQURE_CAP-01-GY_KIDS | G8: GY | I8: 7449 | J8: 45000 | K8: 25000 | L8: 640 | M8: 2014-08-08 | N8: 560 | O8: 25200000 | P8: 2014-08-14 | Q8: 192 | S8: 8640000 | T8: 2014-08-23 | U8: 75 | V8: 2927500 | W8: 13.4 | X8: 11.6 | Y8: 39.1 | Z8: 33.9 | AA8: 368 | AB8: 117
A9: =IF(VLOOKUP(MID($B9,4,2),CODE!K:P,CODE!$O$1,FALSE)="",VLOOKUP(MID($B9,1,3),CODE!$B:$G,CODE!$D$1,FALSE),VLOOKUP(MID($B9,1,3),CODE!$B:$G,CODE!$D$1,FALSE)&"-"&VLOOKUP(MID($B9,4,2),CODE!K:P,CODE!$O$1,FALSE)) -> BRK | B9: =IF(ISERROR(VLOOKUP(E9&G9,품번정리!$D:$E,2,FALSE))=TRUE,E9&G9,VLOOKUP(E9&G9,품번정리!$D:$E,2,FALSE)) -> BRKBAF5501PK | C9: =IF(ISERROR(VLOOKUP(MID(B9,1,5)&MID(B9,8,5),품번정리!$A:$B,2,FALSE))=TRUE,MID(B9,1,5)&MID(B9,8,5),VLOOKUP(MID(B9,1,5)&MID(B9,8,5),품번정리!$A:$B,2,FALSE)) -> BRKBA501PK | D9: =MID(E9,6,2) -> F5 | E9: BRKBAF5501 | F9: 14FW BROWN_SQURE_CAP-01-GY_KIDS | G9: PK | I9: 7449 | J9: 45000 | K9: 25000 | L9: 623 | M9: 2014-08-08 | N9: 562 | O9: 25290000 | P9: 2014-08-14 | Q9: 177 | S9: 7965000 | T9: 2014-08-20 | U9: 87 | V9: 3562500 | W9: 15.5 | X9: 14.1 | Y9: 49.2 | Z9: 44.7 | AA9: 385 | AB9: 90
A10: =IF(VLOOKUP(MID($B10,4,2),CODE!K:P,CODE!$O$1,FALSE)="",VLOOKUP(MID($B10,1,3),CODE!$B:$G,CODE!$D$1,FALSE),VLOOKUP(MID($B10,1,3),CODE!$B:$G,CODE!$D$1,FALSE)&"-"&VLOOKUP(MID($B10,4,2),CODE!K:P,CODE!$O$1,FALSE)) -> BRK | B10: =IF(ISERROR(VLOOKUP(E10&G10,품번정리!$D:$E,2,FALSE))=TRUE,E10&G10,VLOOKUP(E10&G10,품번정리!$D:$E,2,FALSE)) -> BRKERF5504WH | C10: =IF(ISERROR(VLOOKUP(MID(B10,1,5)&MID(B10,8,5),품번정리!$A:$B,2,FALSE))=TRUE,MID(B10,1,5)&MID(B10,8,5),VLOOKUP(MID(B10,1,5)&MID(B10,8,5),품번정리!$A:$B,2,FALSE)) -> BRKER504WH | D10: =MID(E10,6,2) -> F5 | E10: BRKERF5504 | F10: 14FW BROWN_SQURE_CAP-06-WH_KIDS | G10: WH | I10: 8691 | J10: 55000 | K10: 29000 | L10: 445 | M10: 2014-09-30 | N10: 355 | O10: 19525000 | P10: 2014-09-30 | Q10: 289 | R10: 2 | S10: 15895000 | T10: 2014-10-02 | U10: 217 | V10: 10643000 | W10: 61.1 | X10: 54.5 | Y10: 75.1 | Z10: 67 | AA10: 64 | AB10: 72
A11: =IF(VLOOKUP(MID($B11,4,2),CODE!K:P,CODE!$O$1,FALSE)="",VLOOKUP(MID($B11,1,3),CODE!$B:$G,CODE!$D$1,FALSE),VLOOKUP(MID($B11,1,3),CODE!$B:$G,CODE!$D$1,FALSE)&"-"&VLOOKUP(MID($B11,4,2),CODE!K:P,CODE!$O$1,FALSE)) -> BRK | B11: =IF(ISERROR(VLOOKUP(E11&G11,품번정리!$D:$E,2,FALSE))=TRUE,E11&G11,VLOOKUP(E11&G11,품번정리!$D:$E,2,FALSE)) -> BRKERF5505RE | C11: =IF(ISERROR(VLOOKUP(MID(B11,1,5)&MID(B11,8,5),품번정리!$A:$B,2,FALSE))=TRUE,MID(B11,1,5)&MID(B11,8,5),VLOOKUP(MID(B11,1,5)&MID(B11,8,5),품번정리!$A:$B,2,FALSE)) -> BRKER505RE | D11: =MID(E11,6,2) -> F5 | E11: BRKERF5505 | F11: 14FW BROWN_SQURE_CAP-08-RD_KIDS | G11: RE | I11: 8092 | J11: 55000 | K11: 29000 | L11: 387 | M11: 2014-09-05 | N11: 385 | O11: 21175000 | P11: 2014-09-12 | Q11: 317 | S11: 17435000 | T11: 2014-10-01 | U11: 238 | V11: 8282000 | W11: 61.8 | X11: 39.1 | Y11: 75.1 | Z11: 47.5 | AA11: 68 | AB11: 79
A12: =IF(VLOOKUP(MID($B12,4,2),CODE!K:P,CODE!$O$1,FALSE)="",VLOOKUP(MID($B12,1,3),CODE!$B:$G,CODE!$D$1,FALSE),VLOOKUP(MID($B12,1,3),CODE!$B:$G,CODE!$D$1,FALSE)&"-"&VLOOKUP(MID($B12,4,2),CODE!K:P,CODE!$O$1,FALSE)) -> BRK | B12: =IF(ISERROR(VLOOKUP(E12&G12,품번정리!$D:$E,2,FALSE))=TRUE,E12&G12,VLOOKUP(E12&G12,품번정리!$D:$E,2,FALSE)) -> BRKERF5506BK | C12: =IF(ISERROR(VLOOKUP(MID(B12,1,5)&MID(B12,8,5),품번정리!$A:$B,2,FALSE))=TRUE,MID(B12,1,5)&MID(B12,8,5),VLOOKUP(MID(B12,1,5)&MID(B12,8,5),품번정리!$A:$B,2,FALSE)) -> BRKER506BK | D12: =MID(E12,6,2) -> F5 | E12: BRKERF5506 | F12: 14FW BROWN_SQURE_CAP-09-BK_KIDS | G12: BK | I12: 8627 | J12: 55000 | K12: 29000 | L12: 278 | M12: 2014-09-05 | N12: 357 | O12: 19635000 | P12: 2014-09-12 | Q12: 338 | S12: 18590000 | T12: 2014-09-25 | U12: 242 | V12: 9690500 | W12: 67.8 | X12: 49.4 | Y12: 71.6 | Z12: 52.1 | AA12: 19 | AB12: 96
A13: =IF(VLOOKUP(MID($B13,4,2),CODE!K:P,CODE!$O$1,FALSE)="",VLOOKUP(MID($B13,1,3),CODE!$B:$G,CODE!$D$1,FALSE),VLOOKUP(MID($B13,1,3),CODE!$B:$G,CODE!$D$1,FALSE)&"-"&VLOOKUP(MID($B13,4,2),CODE!K:P,CODE!$O$1,FALSE)) -> DPH | B13: =IF(ISERROR(VLOOKUP(E13&G13,품번정리!$D:$E,2,FALSE))=TRUE,E13&G13,VLOOKUP(E13&G13,품번정리!$D:$E,2,FALSE)) -> DPHEBF5508PK | C13: =IF(ISERROR(VLOOKUP(MID(B13,1,5)&MID(B13,8,5),품번정리!$A:$B,2,FALSE))=TRUE,MID(B13,1,5)&MID(B13,8,5),VLOOKUP(MID(B13,1,5)&MID(B13,8,5),품번정리!$A:$B,2,FALSE)) -> DPHEB508PK | D13: =MID(E13,6,2) -> F5 | E13: DPHEBF5508 | F13: 14FW DPS 04_SNAP_PK_KIDS | G13: PK | I13: 6750 | J13: 49000 | K13: 25000 | L13: 250 | M13: 2015-09-09 | N13: 150 | O13: 7350000 | P13: 2015-10-13 | Q13: 84 | S13: 4116000 | T13: 2015-10-17 | U13: 19 | V13: 475000 | W13: 12.7 | X13: 6.5 | Y13: 22.6 | Z13: 11.5 | AA13: 66 | AB13: 65
A14: =IF(VLOOKUP(MID($B14,4,2),CODE!K:P,CODE!$O$1,FALSE)="",VLOOKUP(MID($B14,1,3),CODE!$B:$G,CODE!$D$1,FALSE),VLOOKUP(MID($B14,1,3),CODE!$B:$G,CODE!$D$1,FALSE)&"-"&VLOOKUP(MID($B14,4,2),CODE!K:P,CODE!$O$1,FALSE)) -> DPH | B14: =IF(ISERROR(VLOOKUP(E14&G14,품번정리!$D:$E,2,FALSE))=TRUE,E14&G14,VLOOKUP(E14&G14,품번정리!$D:$E,2,FALSE)) -> DPHERF5509PK | C14: =IF(ISERROR(VLOOKUP(MID(B14,1,5)&MID(B14,8,5),품번정리!$A:$B,2,FALSE))=TRUE,MID(B14,1,5)&MID(B14,8,5),VLOOKUP(MID(B14,1,5)&MID(B14,8,5),품번정리!$A:$B,2,FALSE)) -> DPHER509PK | D14: =MID(E14,6,2) -> F5 | E14: DPHERF5509 | F14: 14FW DPS SNAP_03_PK_KIDS | G14: PK | I14: 5579 | J14: 49000 | K14: 25000 | L14: 300 | M14: 2015-09-09 | N14: 200 | O14: 9800000 | P14: 2015-10-13 | Q14: 161 | S14: 7889000 | T14: 2015-10-16 | U14: 83 | V14: 2075000 | W14: 41.5 | X14: 21.2 | Y14: 51.6 | Z14: 26.3 | AA14: 39 | AB14: 78
A15: =IF(VLOOKUP(MID($B15,4,2),CODE!K:P,CODE!$O$1,FALSE)="",VLOOKUP(MID($B15,1,3),CODE!$B:$G,CODE!$D$1,FALSE),VLOOKUP(MID($B15,1,3),CODE!$B:$G,CODE!$D$1,FALSE)&"-"&VLOOKUP(MID($B15,4,2),CODE!K:P,CODE!$O$1,FALSE)) -> DPH | B15: =IF(ISERROR(VLOOKUP(E15&G15,품번정리!$D:$E,2,FALSE))=TRUE,E15&G15,VLOOKUP(E15&G15,품번정리!$D:$E,2,FALSE)) -> DPHSNF3501PK | C15: =IF(ISERROR(VLOOKUP(MID(B15,1,5)&MID(B15,8,5),품번정리!$A:$B,2,FALSE))=TRUE,MID(B15,1,5)&MID(B15,8,5),VLOOKUP(MID(B15,1,5)&MID(B15,8,5),품번정리!$A:$B,2,FALSE)) -> DPHSN501PK | D15: =MID(E15,6,2) -> F3 | E15: DPHSNF3501 | F15: DPSSNF3501PKOSM | G15: PK | I15: 11700 | J15: 45000 | K15: 45000 | L15: 170 | M15: 2014-09-02 | N15: 172 | O15: 7740000 | P15: 2014-09-04 | Q15: 117 | R15: 3 | S15: 5265000 | T15: 2014-09-05 | U15: 67 | V15: 3015000 | W15: 39 | X15: 39 | Y15: 57.3 | Z15: 57.3 | AA15: 52 | AB15: 50
A16: =IF(VLOOKUP(MID($B16,4,2),CODE!K:P,CODE!$O$1,FALSE)="",VLOOKUP(MID($B16,1,3),CODE!$B:$G,CODE!$D$1,FALSE),VLOOKUP(MID($B16,1,3),CODE!$B:$G,CODE!$D$1,FALSE)&"-"&VLOOKUP(MID($B16,4,2),CODE!K:P,CODE!$O$1,FALSE)) -> DPK-가방 | B16: =IF(ISERROR(VLOOKUP(E16&G16,품번정리!$D:$E,2,FALSE))=TRUE,E16&G16,VLOOKUP(E16&G16,품번정리!$D:$E,2,FALSE)) -> DPKBPF3501PK | C16: =IF(ISERROR(VLOOKUP(MID(B16,1,5)&MID(B16,8,5),품번정리!$A:$B,2,FALSE))=TRUE,MID(B16,1,5)&MID(B16,8,5),VLOOKUP(MID(B16,1,5)&MID(B16,8,5),품번정리!$A:$B,2,FALSE)) -> DPKBP501PK | D16: =MID(E16,6,2) -> F3 | E16: DPKBPF3501 | F16: 14FW DISNEY_BP_07_PK_KIDS | G16: PK | I16: 34000 | J16: 129000 | K16: 69000 | L16: 100 | M16: 2014-08-28 | N16: 100 | O16: 12900000 | P16: 2014-08-28 | Q16: 91 | S16: 11739000 | T16: 2014-09-04 | U16: 52 | V16: 5670000 | W16: 52 | X16: 44 | Y16: 57.1 | Z16: 48.3 | AA16: 9 | AB16: 39
A17: =IF(VLOOKUP(MID($B17,4,2),CODE!K:P,CODE!$O$1,FALSE)="",VLOOKUP(MID($B17,1,3),CODE!$B:$G,CODE!$D$1,FALSE),VLOOKUP(MID($B17,1,3),CODE!$B:$G,CODE!$D$1,FALSE)&"-"&VLOOKUP(MID($B17,4,2),CODE!K:P,CODE!$O$1,FALSE)) -> DPK-가방 | B17: =IF(ISERROR(VLOOKUP(E17&G17,품번정리!$D:$E,2,FALSE))=TRUE,E17&G17,VLOOKUP(E17&G17,품번정리!$D:$E,2,FALSE)) -> DPKBPF3502PK | C17: =IF(ISERROR(VLOOKUP(MID(B17,1,5)&MID(B17,8,5),품번정리!$A:$B,2,FALSE))=TRUE,MID(B17,1,5)&MID(B17,8,5),VLOOKUP(MID(B17,1,5)&MID(B17,8,5),품번정리!$A:$B,2,FALSE)) -> DPKBP502PK | D17: =MID(E17,6,2) -> F3 | E17: DPKBPF3502 | F17: 14FW DISNEY_BP_08_PK_KIDS | G17: PK | I17: 34500 | J17: 129000 | K17: 69000 | L17: 100 | M17: 2014-08-28 | N17: 100 | O17: 12900000 | P17: 2014-08-28 | Q17: 86 | S17: 11094000 | T17: 2014-09-03 | U17: 40 | V17: 4255500 | W17: 40 | X17: 33 | Y17: 46.5 | Z17: 38.4 | AA17: 14 | AB17: 46 | AC17: 1 | AD17: 1 | AE17: 69000 | AF17: 1
A18: =IF(VLOOKUP(MID($B18,4,2),CODE!K:P,CODE!$O$1,FALSE)="",VLOOKUP(MID($B18,1,3),CODE!$B:$G,CODE!$D$1,FALSE),VLOOKUP(MID($B18,1,3),CODE!$B:$G,CODE!$D$1,FALSE)&"-"&VLOOKUP(MID($B18,4,2),CODE!K:P,CODE!$O$1,FALSE)) -> DPK-가방 | B18: =IF(ISERROR(VLOOKUP(E18&G18,품번정리!$D:$E,2,FALSE))=TRUE,E18&G18,VLOOKUP(E18&G18,품번정리!$D:$E,2,FALSE)) -> DPKBPF3503NY | C18: =IF(ISERROR(VLOOKUP(MID(B18,1,5)&MID(B18,8,5),품번정리!$A:$B,2,FALSE))=TRUE,MID(B18,1,5)&MID(B18,8,5),VLOOKUP(MID(B18,1,5)&MID(B18,8,5),품번정리!$A:$B,2,FALSE)) -> DPKBP503NY | D18: =MID(E18,6,2) -> F3 | E18: DPKBPF3503 | F18: 14FW DISNEY_BP_09_NV_KIDS | G18: NY | I18: 34000 | J18: 129000 | K18: 69000 | L18: 100 | M18: 2014-08-28 | N18: 100 | O18: 12900000 | P18: 2014-08-28 | Q18: 95 | S18: 12255000 | T18: 2014-09-03 | U18: 67 | V18: 7974000 | W18: 67 | X18: 61.8 | Y18: 70.5 | Z18: 65.1 | AA18: 5 | AB18: 28
A19: =IF(VLOOKUP(MID($B19,4,2),CODE!K:P,CODE!$O$1,FALSE)="",VLOOKUP(MID($B19,1,3),CODE!$B:$G,CODE!$D$1,FALSE),VLOOKUP(MID($B19,1,3),CODE!$B:$G,CODE!$D$1,FALSE)&"-"&VLOOKUP(MID($B19,4,2),CODE!K:P,CODE!$O$1,FALSE)) -> DPK | B19: =IF(ISERROR(VLOOKUP(E19&G19,품번정리!$D:$E,2,FALSE))=TRUE,E19&G19,VLOOKUP(E19&G19,품번정리!$D:$E,2,FALSE)) -> DPKEBF5508PK | C19: =IF(ISERROR(VLOOKUP(MID(B19,1,5)&MID(B19,8,5),품번정리!$A:$B,2,FALSE))=TRUE,MID(B19,1,5)&MID(B19,8,5),VLOOKUP(MID(B19,1,5)&MID(B19,8,5),품번정리!$A:$B,2,FALSE)) -> DPKEB508PK | D19: =MID(E19,6,2) -> F5 | E19: DPKEBF5508 | F19: 14FW DISNEY 04_SNAP_PK_KIDS | G19: PK | I19: 6744 | J19: 49000 | K19: 25000 | L19: 120 | M19: 2014-09-24 | N19: 120 | O19: 5880000 | P19: 2014-10-08 | Q19: 38 | S19: 1862000 | T19: 2014-10-10 | U19: 37 | V19: 1813000 | W19: 30.8 | X19: 30.8 | Y19: 97.4 | Z19: 97.4 | AA19: 82 | AB19: 1
A20: =IF(VLOOKUP(MID($B20,4,2),CODE!K:P,CODE!$O$1,FALSE)="",VLOOKUP(MID($B20,1,3),CODE!$B:$G,CODE!$D$1,FALSE),VLOOKUP(MID($B20,1,3),CODE!$B:$G,CODE!$D$1,FALSE)&"-"&VLOOKUP(MID($B20,4,2),CODE!K:P,CODE!$O$1,FALSE)) -> DPK | B20: =IF(ISERROR(VLOOKUP(E20&G20,품번정리!$D:$E,2,FALSE))=TRUE,E20&G20,VLOOKUP(E20&G20,품번정리!$D:$E,2,FALSE)) -> DPKERF5509PK | C20: =IF(ISERROR(VLOOKUP(MID(B20,1,5)&MID(B20,8,5),품번정리!$A:$B,2,FALSE))=TRUE,MID(B20,1,5)&MID(B20,8,5),VLOOKUP(MID(B20,1,5)&MID(B20,8,5),품번정리!$A:$B,2,FALSE)) -> DPKER509PK | D20: =MID(E20,6,2) -> F5 | E20: DPKERF5509 | F20: 14FW FROZEN SNAP_03_PK_KIDS | G20: PK | I20: 5556 | J20: 49000 | K20: 25000 | L20: 200 | M20: 2014-11-13 | N20: 200 | O20: 9800000 | P20: 2014-11-13 | Q20: 49 | R20: -1 | S20: 2401000 | T20: 2014-11-15 | U20: 47 | V20: 2156000 | W20: 23.5 | X20: 22 | Y20: 95.9 | Z20: 89.8 | AA20: 152 | AB20: 2
A21: =IF(VLOOKUP(MID($B21,4,2),CODE!K:P,CODE!$O$1,FALSE)="",VLOOKUP(MID($B21,1,3),CODE!$B:$G,CODE!$D$1,FALSE),VLOOKUP(MID($B21,1,3),CODE!$B:$G,CODE!$D$1,FALSE)&"-"&VLOOKUP(MID($B21,4,2),CODE!K:P,CODE!$O$1,FALSE)) -> DPK | B21: =IF(ISERROR(VLOOKUP(E21&G21,품번정리!$D:$E,2,FALSE))=TRUE,E21&G21,VLOOKUP(E21&G21,품번정리!$D:$E,2,FALSE)) -> DPKSNF3501PK | C21: =IF(ISERROR(VLOOKUP(MID(B21,1,5)&MID(B21,8,5),품번정리!$A:$B,2,FALSE))=TRUE,MID(B21,1,5)&MID(B21,8,5),VLOOKUP(MID(B21,1,5)&MID(B21,8,5),품번정리!$A:$B,2,FALSE)) -> DPKSN501PK | D21: =MID(E21,6,2) -> F3 | E21: DPKSNF3501 | F21: 14SS FROZEN SNAP_01_PK_KIDS | G21: PK | I21: 11700 | J21: 45000 | K21: 19000 | L21: 120 | M21: 2014-05-16 | N21: 118 | O21: 5310000 | P21: 2014-05-16 | Q21: 87 | R21: -4 | S21: 3915000 | T21: 2014-05-18 | U21: 87 | V21: 3767300 | W21: 73.7 | X21: 70.9 | Y21: 100 | Z21: 96.2 | AA21: 35
A22: =IF(VLOOKUP(MID($B22,4,2),CODE!K:P,CODE!$O$1,FALSE)="",VLOOKUP(MID($B22,1,3),CODE!$B:$G,CODE!$D$1,FALSE),VLOOKUP(MID($B22,1,3),CODE!$B:$G,CODE!$D$1,FALSE)&"-"&VLOOKUP(MID($B22,4,2),CODE!K:P,CODE!$O$1,FALSE)) -> DPK | B22: =IF(ISERROR(VLOOKUP(E22&G22,품번정리!$D:$E,2,FALSE))=TRUE,E22&G22,VLOOKUP(E22&G22,품번정리!$D:$E,2,FALSE)) -> DPKSNF3502BL | C22: =IF(ISERROR(VLOOKUP(MID(B22,1,5)&MID(B22,8,5),품번정리!$A:$B,2,FALSE))=TRUE,MID(B22,1,5)&MID(B22,8,5),VLOOKUP(MID(B22,1,5)&MID(B22,8,5),품번정리!$A:$B,2,FALSE)) -> DPKSN502BL | D22: =MID(E22,6,2) -> F3 | E22: DPKSNF3502 | F22: 14SS FROZEN SNAP_02_BL_KIDS | G22: BL | I22: 12500 | J22: 45000 | K22: 19000 | L22: 120 | M22: 2014-05-16 | N22: 119 | O22: 5355000 | P22: 2014-05-16 | Q22: 64 | S22: 2880000 | T22: 2014-05-20 | U22: 64 | V22: 2848300 | W22: 53.8 | X22: 53.2 | Y22: 100 | Z22: 98.9 | AA22: 55 | AC22: -1
A23: =IF(VLOOKUP(MID($B23,4,2),CODE!K:P,CODE!$O$1,FALSE)="",VLOOKUP(MID($B23,1,3),CODE!$B:$G,CODE!$D$1,FALSE),VLOOKUP(MID($B23,1,3),CODE!$B:$G,CODE!$D$1,FALSE)&"-"&VLOOKUP(MID($B23,4,2),CODE!K:P,CODE!$O$1,FALSE)) -> DPK | B23: =IF(ISERROR(VLOOKUP(E23&G23,품번정리!$D:$E,2,FALSE))=TRUE,E23&G23,VLOOKUP(E23&G23,품번정리!$D:$E,2,FALSE)) -> DPKSNF3503PP | C23: =IF(ISERROR(VLOOKUP(MID(B23,1,5)&MID(B23,8,5),품번정리!$A:$B,2,FALSE))=TRUE,MID(B23,1,5)&MID(B23,8,5),VLOOKUP(MID(B23,1,5)&MID(B23,8,5),품번정리!$A:$B,2,FALSE)) -> DPKSN503PP | D23: =MID(E23,6,2) -> F3 | E23: DPKSNF3503 | F23: 14SS FROZEN SNAP_04_PP_KIDS | G23: PP | I23: 10600 | J23: 43000 | K23: 19000 | L23: 120 | M23: 2014-06-19 | N23: 120 | O23: 5160000 | P23: 2014-06-20 | Q23: 63 | S23: 2709000 | T23: 2014-07-02 | U23: 63 | V23: 2591500 | W23: 52.5 | X23: 50.2 | Y23: 100 | Z23: 95.7 | AA23: 57
A24: =IF(VLOOKUP(MID($B24,4,2),CODE!K:P,CODE!$O$1,FALSE)="",VLOOKUP(MID($B24,1,3),CODE!$B:$G,CODE!$D$1,FALSE),VLOOKUP(MID($B24,1,3),CODE!$B:$G,CODE!$D$1,FALSE)&"-"&VLOOKUP(MID($B24,4,2),CODE!K:P,CODE!$O$1,FALSE)) -> DPK | B24: =IF(ISERROR(VLOOKUP(E24&G24,품번정리!$D:$E,2,FALSE))=TRUE,E24&G24,VLOOKUP(E24&G24,품번정리!$D:$E,2,FALSE)) -> DPKSNF3504MT | C24: =IF(ISERROR(VLOOKUP(MID(B24,1,5)&MID(B24,8,5),품번정리!$A:$B,2,FALSE))=TRUE,MID(B24,1,5)&MID(B24,8,5),VLOOKUP(MID(B24,1,5)&MID(B24,8,5),품번정리!$A:$B,2,FALSE)) -> DPKSN504MT | D24: =MID(E24,6,2) -> F3 | E24: DPKSNF3504 | F24: 14SS FROZEN SNAP_05_MT_KIDS | G24: MT | I24: 7543 | J24: 43000 | K24: 29000 | L24: 240 | M24: 2014-06-19 | N24: 240 | O24: 10320000 | P24: 2014-06-20 | Q24: 223 | R24: 1 | S24: 9589000 | T24: 2014-06-21 | U24: 223 | V24: 9517000 | W24: 92.9 | X24: 92.2 | Y24: 100 | Z24: 99.2 | AA24: 16
A25: =IF(VLOOKUP(MID($B25,4,2),CODE!K:P,CODE!$O$1,FALSE)="",VLOOKUP(MID($B25,1,3),CODE!$B:$G,CODE!$D$1,FALSE),VLOOKUP(MID($B25,1,3),CODE!$B:$G,CODE!$D$1,FALSE)&"-"&VLOOKUP(MID($B25,4,2),CODE!K:P,CODE!$O$1,FALSE)) -> ELH | B25: =IF(ISERROR(VLOOKUP(E25&G25,품번정리!$D:$E,2,FALSE))=TRUE,E25&G25,VLOOKUP(E25&G25,품번정리!$D:$E,2,FALSE)) -> ELHBAF3649KH | C25: =IF(ISERROR(VLOOKUP(MID(B25,1,5)&MID(B25,8,5),품번정리!$A:$B,2,FALSE))=TRUE,MID(B25,1,5)&MID(B25,8,5),VLOOKUP(MID(B25,1,5)&MID(B25,8,5),품번정리!$A:$B,2,FALSE)) -> ELHBA649KH | D25: =MID(E25,6,2) -> F3 | E25: ELHBAF3649 | F25: ELSBAD3649KHFRE | G25: KH | I25: 6313 | J25: 43000 | K25: 25000 | L25: 676 | M25: 2014-08-11 | N25: 117 | O25: 5031000 | P25: 2014-08-14 | Q25: 113 | S25: 4859000 | T25: 2014-08-16 | U25: 87 | V25: 2022640 | W25: 74.4 | X25: 40.2 | Y25: 77 | Z25: 41.6 | AA25: 4 | AB25: 26
A26: =IF(VLOOKUP(MID($B26,4,2),CODE!K:P,CODE!$O$1,FALSE)="",VLOOKUP(MID($B26,1,3),CODE!$B:$G,CODE!$D$1,FALSE),VLOOKUP(MID($B26,1,3),CODE!$B:$G,CODE!$D$1,FALSE)&"-"&VLOOKUP(MID($B26,4,2),CODE!K:P,CODE!$O$1,FALSE)) -> ELH | B26: =IF(ISERROR(VLOOKUP(E26&G26,품번정리!$D:$E,2,FALSE))=TRUE,E26&G26,VLOOKUP(E26&G26,품번정리!$D:$E,2,FALSE)) -> ELHBAF3649PK | C26: =IF(ISERROR(VLOOKUP(MID(B26,1,5)&MID(B26,8,5),품번정리!$A:$B,2,FALSE))=TRUE,MID(B26,1,5)&MID(B26,8,5),VLOOKUP(MID(B26,1,5)&MID(B26,8,5),품번정리!$A:$B,2,FALSE)) -> ELHBA649PK | D26: =MID(E26,6,2) -> F3 | E26: ELHBAF3649 | F26: ELSBAD3649KHFRE | G26: PK | I26: 6313 | J26: 43000 | K26: 25000 | L26: 1888 | M26: 2014-08-11 | N26: 499 | O26: 21457000 | P26: 2014-08-14 | Q26: 300 | S26: 12900000 | T26: 2014-08-16 | U26: 110 | V26: 2229840 | W26: 22 | X26: 10.4 | Y26: 36.7 | Z26: 17.3 | AA26: 199 | AB26: 190 | AC26: -2 | AD26: -2 | AE26: -50000 | AF26: -0.4
A27: =IF(VLOOKUP(MID($B27,4,2),CODE!K:P,CODE!$O$1,FALSE)="",VLOOKUP(MID($B27,1,3),CODE!$B:$G,CODE!$D$1,FALSE),VLOOKUP(MID($B27,1,3),CODE!$B:$G,CODE!$D$1,FALSE)&"-"&VLOOKUP(MID($B27,4,2),CODE!K:P,CODE!$O$1,FALSE)) -> ELH | B27: =IF(ISERROR(VLOOKUP(E27&G27,품번정리!$D:$E,2,FALSE))=TRUE,E27&G27,VLOOKUP(E27&G27,품번정리!$D:$E,2,FALSE)) -> ELHBAF3811LI | C27: =IF(ISERROR(VLOOKUP(MID(B27,1,5)&MID(B27,8,5),품번정리!$A:$B,2,FALSE))=TRUE,MID(B27,1,5)&MID(B27,8,5),VLOOKUP(MID(B27,1,5)&MID(B27,8,5),품번정리!$A:$B,2,FALSE)) -> ELHBA811LI | D27: =MID(E27,6,2) -> F3 | E27: ELHBAF3811 | F27: ELSBAE3811LIFRE | G27: LI | I27: 7787 | J27: 43000 | K27: 15000 | L27: 670 | M27: 2014-08-11 | N27: 300 | O27: 12900000 | P27: 2014-08-14 | Q27: 284 | S27: 12212000 | T27: 2014-08-15 | U27: 237 | V27: 5320000 | W27: 79 | X27: 41.2 | Y27: 83.5 | Z27: 43.6 | AA27: 16 | AB27: 47
A28: =IF(VLOOKUP(MID($B28,4,2),CODE!K:P,CODE!$O$1,FALSE)="",VLOOKUP(MID($B28,1,3),CODE!$B:$G,CODE!$D$1,FALSE),VLOOKUP(MID($B28,1,3),CODE!$B:$G,CODE!$D$1,FALSE)&"-"&VLOOKUP(MID($B28,4,2),CODE!K:P,CODE!$O$1,FALSE)) -> ELH | B28: =IF(ISERROR(VLOOKUP(E28&G28,품번정리!$D:$E,2,FALSE))=TRUE,E28&G28,VLOOKUP(E28&G28,품번정리!$D:$E,2,FALSE)) -> ELHBAF3811PK | C28: =IF(ISERROR(VLOOKUP(MID(B28,1,5)&MID(B28,8,5),품번정리!$A:$B,2,FALSE))=TRUE,MID(B28,1,5)&MID(B28,8,5),VLOOKUP(MID(B28,1,5)&MID(B28,8,5),품번정리!$A:$B,2,FALSE)) -> ELHBA811PK | D28: =MID(E28,6,2) -> F3 | E28: ELHBAF3811 | F28: ELSBAE3811LIFRE | G28: PK | I28: 7787 | J28: 43000 | K28: 15000 | L28: 1876 | M28: 2014-08-11 | N28: 500 | O28: 21500000 | P28: 2014-08-14 | Q28: 481 | S28: 20683000 | T28: 2014-08-15 | U28: 466 | V28: 10624000 | W28: 93.2 | X28: 49.4 | Y28: 96.9 | Z28: 51.4 | AA28: 19 | AB28: 15 | AC28: 8 | AD28: 10 | AE28: 150000 | AF28: 2
A29: =IF(VLOOKUP(MID($B29,4,2),CODE!K:P,CODE!$O$1,FALSE)="",VLOOKUP(MID($B29,1,3),CODE!$B:$G,CODE!$D$1,FALSE),VLOOKUP(MID($B29,1,3),CODE!$B:$G,CODE!$D$1,FALSE)&"-"&VLOOKUP(MID($B29,4,2),CODE!K:P,CODE!$O$1,FALSE)) -> ELH | B29: =IF(ISERROR(VLOOKUP(E29&G29,품번정리!$D:$E,2,FALSE))=TRUE,E29&G29,VLOOKUP(E29&G29,품번정리!$D:$E,2,FALSE)) -> ELHBAF3812NY | C29: =IF(ISERROR(VLOOKUP(MID(B29,1,5)&MID(B29,8,5),품번정리!$A:$B,2,FALSE))=TRUE,MID(B29,1,5)&MID(B29,8,5),VLOOKUP(MID(B29,1,5)&MID(B29,8,5),품번정리!$A:$B,2,FALSE)) -> ELHBA812NY | D29: =MID(E29,6,2) -> F3 | E29: ELHBAF3812 | F29: ELSBAE3812NYFRE | G29: NY | I29: 7287 | J29: 43000 | K29: 15000 | L29: 788 | M29: 2014-08-11 | N29: 300 | O29: 12900000 | P29: 2014-08-14 | Q29: 298 | S29: 12814000 | T29: 2014-08-15 | U29: 238 | V29: 5493000 | W29: 79.3 | X29: 42.6 | Y29: 79.9 | Z29: 42.9 | AA29: 2 | AB29: 60
A30: =IF(VLOOKUP(MID($B30,4,2),CODE!K:P,CODE!$O$1,FALSE)="",VLOOKUP(MID($B30,1,3),CODE!$B:$G,CODE!$D$1,FALSE),VLOOKUP(MID($B30,1,3),CODE!$B:$G,CODE!$D$1,FALSE)&"-"&VLOOKUP(MID($B30,4,2),CODE!K:P,CODE!$O$1,FALSE)) -> ELH | B30: =IF(ISERROR(VLOOKUP(E30&G30,품번정리!$D:$E,2,FALSE))=TRUE,E30&G30,VLOOKUP(E30&G30,품번정리!$D:$E,2,FALSE)) -> ELHBAF5506GR | C30: =IF(ISERROR(VLOOKUP(MID(B30,1,5)&MID(B30,8,5),품번정리!$A:$B,2,FALSE))=TRUE,MID(B30,1,5)&MID(B30,8,5),VLOOKUP(MID(B30,1,5)&MID(B30,8,5),품번정리!$A:$B,2,FALSE)) -> ELHBA506GR | D30: =MID(E30,6,2) -> F5 | E30: ELHBAF5506 | F30: 14FW ELS_53_SNAP_GR_KIDS | G30: GR | I30: 6792 | J30: 45000 | K30: 25000 | L30: 582 | M30: 2015-09-09 | N30: 372 | O30: 16740000 | P30: 2015-10-13 | Q30: 267 | S30: 12015000 | T30: 2015-10-14 | U30: 172 | V30: 4307500 | W30: 46.2 | X30: 25.7 | Y30: 64.4 | Z30: 35.9 | AA30: 105 | AB30: 95 | AC30: 2 | AD30: 2 | AE30: 50000 | AF30: 0.5
A31: =IF(VLOOKUP(MID($B31,4,2),CODE!K:P,CODE!$O$1,FALSE)="",VLOOKUP(MID($B31,1,3),CODE!$B:$G,CODE!$D$1,FALSE),VLOOKUP(MID($B31,1,3),CODE!$B:$G,CODE!$D$1,FALSE)&"-"&VLOOKUP(MID($B31,4,2),CODE!K:P,CODE!$O$1,FALSE)) -> ELH | B31: =IF(ISERROR(VLOOKUP(E31&G31,품번정리!$D:$E,2,FALSE))=TRUE,E31&G31,VLOOKUP(E31&G31,품번정리!$D:$E,2,FALSE)) -> ELHBAF5507RE | C31: =IF(ISERROR(VLOOKUP(MID(B31,1,5)&MID(B31,8,5),품번정리!$A:$B,2,FALSE))=TRUE,MID(B31,1,5)&MID(B31,8,5),VLOOKUP(MID(B31,1,5)&MID(B31,8,5),품번정리!$A:$B,2,FALSE)) -> ELHBA507RE | D31: =MID(E31,6,2) -> F5 | E31: ELHBAF5507 | F31: 14FW ELS_52_SNAP_RD_KIDS | G31: RE | I31: 6939 | J31: 45000 | K31: 25000 | L31: 450 | M31: 2015-09-09 | N31: 450 | O31: 20250000 | P31: 2015-10-06 | Q31: 145 | S31: 6525000 | T31: 2015-10-24 | U31: 51 | V31: 1275000 | W31: 11.3 | X31: 6.3 | Y31: 35.2 | Z31: 19.5 | AA31: 305 | AB31: 94 | AC31: -2 | AD31: -2 | AE31: -50000 | AF31: -0.4
A32: =IF(VLOOKUP(MID($B32,4,2),CODE!K:P,CODE!$O$1,FALSE)="",VLOOKUP(MID($B32,1,3),CODE!$B:$G,CODE!$D$1,FALSE),VLOOKUP(MID($B32,1,3),CODE!$B:$G,CODE!$D$1,FALSE)&"-"&VLOOKUP(MID($B32,4,2),CODE!K:P,CODE!$O$1,FALSE)) -> ELH | B32: =IF(ISERROR(VLOOKUP(E32&G32,품번정리!$D:$E,2,FALSE))=TRUE,E32&G32,VLOOKUP(E32&G32,품번정리!$D:$E,2,FALSE)) -> ELHBAF5508PK | C32: =IF(ISERROR(VLOOKUP(MID(B32,1,5)&MID(B32,8,5),품번정리!$A:$B,2,FALSE))=TRUE,MID(B32,1,5)&MID(B32,8,5),VLOOKUP(MID(B32,1,5)&MID(B32,8,5),품번정리!$A:$B,2,FALSE)) -> ELHBA508PK | D32: =MID(E32,6,2) -> F5 | E32: ELHBAF5508 | F32: 14FW ELS_52_SNAP_PK_KIDS | G32: PK | I32: 6731 | J32: 45000 | K32: 25000 | L32: 500 | M32: 2015-09-09 | N32: 390 | O32: 17550000 | P32: 2015-10-06 | Q32: 87 | S32: 3915000 | T32: 2015-10-15 | U32: 20 | V32: 500000 | W32: 5.1 | X32: 2.8 | Y32: 23 | Z32: 12.8 | AA32: 303 | AB32: 67 | AC32: 2 | AD32: 2 | AE32: 50000 | AF32: 0.5
A33: =IF(VLOOKUP(MID($B33,4,2),CODE!K:P,CODE!$O$1,FALSE)="",VLOOKUP(MID($B33,1,3),CODE!$B:$G,CODE!$D$1,FALSE),VLOOKUP(MID($B33,1,3),CODE!$B:$G,CODE!$D$1,FALSE)&"-"&VLOOKUP(MID($B33,4,2),CODE!K:P,CODE!$O$1,FALSE)) -> ELH | B33: =IF(ISERROR(VLOOKUP(E33&G33,품번정리!$D:$E,2,FALSE))=TRUE,E33&G33,VLOOKUP(E33&G33,품번정리!$D:$E,2,FALSE)) -> ELHBAF5518PP | C33: =IF(ISERROR(VLOOKUP(MID(B33,1,5)&MID(B33,8,5),품번정리!$A:$B,2,FALSE))=TRUE,MID(B33,1,5)&MID(B33,8,5),VLOOKUP(MID(B33,1,5)&MID(B33,8,5),품번정리!$A:$B,2,FALSE)) -> ELHBA518PP | D33: =MID(E33,6,2) -> F5 | E33: ELHBAF5518 | F33: 14FW ELS_47_SNAP_PP_KIDS | G33: PP | I33: 9482 | J33: 55000 | K33: 29000 | L33: 420 | M33: 2015-09-09 | N33: 68 | O33: 3740000 | P33: 2015-10-16 | Q33: 62 | S33: 3410000 | T33: 2015-11-21 | U33: 7 | V33: 203000 | W33: 10.3 | X33: 5.4 | Y33: 11.3 | Z33: 6 | AA33: 6 | AB33: 55
A34: =IF(VLOOKUP(MID($B34,4,2),CODE!K:P,CODE!$O$1,FALSE)="",VLOOKUP(MID($B34,1,3),CODE!$B:$G,CODE!$D$1,FALSE),VLOOKUP(MID($B34,1,3),CODE!$B:$G,CODE!$D$1,FALSE)&"-"&VLOOKUP(MID($B34,4,2),CODE!K:P,CODE!$O$1,FALSE)) -> ELH | B34: =IF(ISERROR(VLOOKUP(E34&G34,품번정리!$D:$E,2,FALSE))=TRUE,E34&G34,VLOOKUP(E34&G34,품번정리!$D:$E,2,FALSE)) -> ELHBEF5802GR | C34: =IF(ISERROR(VLOOKUP(MID(B34,1,5)&MID(B34,8,5),품번정리!$A:$B,2,FALSE))=TRUE,MID(B34,1,5)&MID(B34,8,5),VLOOKUP(MID(B34,1,5)&MID(B34,8,5),품번정리!$A:$B,2,FALSE)) -> ELHBE802GR | D34: =MID(E34,6,2) -> F5 | E34: ELHBEF5802 | F34: ELSBEE5802GRFRE | G34: GR | I34: 5786 | J34: 45000 | K34: 15000 | L34: 368 | M34: 2014-10-10 | N34: 368 | O34: 16560000 | P34: 2014-10-14 | Q34: 357 | R34: 7 | S34: 16065000 | T34: 2014-11-05 | U34: 286 | V34: 4511500 | W34: 77.7 | X34: 27.2 | Y34: 80.1 | Z34: 28.1 | AA34: 4 | AB34: 71
A35: =IF(VLOOKUP(MID($B35,4,2),CODE!K:P,CODE!$O$1,FALSE)="",VLOOKUP(MID($B35,1,3),CODE!$B:$G,CODE!$D$1,FALSE),VLOOKUP(MID($B35,1,3),CODE!$B:$G,CODE!$D$1,FALSE)&"-"&VLOOKUP(MID($B35,4,2),CODE!K:P,CODE!$O$1,FALSE)) -> ELH | B35: =IF(ISERROR(VLOOKUP(E35&G35,품번정리!$D:$E,2,FALSE))=TRUE,E35&G35,VLOOKUP(E35&G35,품번정리!$D:$E,2,FALSE)) -> ELHBEF5803BL | C35: =IF(ISERROR(VLOOKUP(MID(B35,1,5)&MID(B35,8,5),품번정리!$A:$B,2,FALSE))=TRUE,MID(B35,1,5)&MID(B35,8,5),VLOOKUP(MID(B35,1,5)&MID(B35,8,5),품번정리!$A:$B,2,FALSE)) -> ELHBE803BL | D35: =MID(E35,6,2) -> F5 | E35: ELHBEF5803 | F35: ELSBEE5803BLFRE | G35: BL | I35: 5808 | J35: 45000 | K35: 15000 | L35: 414 | M35: 2014-10-10 | N35: 413 | O35: 18585000 | P35: 2014-10-14 | Q35: 349 | R35: -3 | S35: 15705000 | T35: 2014-10-20 | U35: 293 | V35: 4880000 | W35: 70.9 | X35: 26.3 | Y35: 84 | Z35: 31.1 | AA35: 67 | AB35: 56
A36: =IF(VLOOKUP(MID($B36,4,2),CODE!K:P,CODE!$O$1,FALSE)="",VLOOKUP(MID($B36,1,3),CODE!$B:$G,CODE!$D$1,FALSE),VLOOKUP(MID($B36,1,3),CODE!$B:$G,CODE!$D$1,FALSE)&"-"&VLOOKUP(MID($B36,4,2),CODE!K:P,CODE!$O$1,FALSE)) -> ELH | B36: =IF(ISERROR(VLOOKUP(E36&G36,품번정리!$D:$E,2,FALSE))=TRUE,E36&G36,VLOOKUP(E36&G36,품번정리!$D:$E,2,FALSE)) -> ELHBEF5804BK | C36: =IF(ISERROR(VLOOKUP(MID(B36,1,5)&MID(B36,8,5),품번정리!$A:$B,2,FALSE))=TRUE,MID(B36,1,5)&MID(B36,8,5),VLOOKUP(MID(B36,1,5)&MID(B36,8,5),품번정리!$A:$B,2,FALSE)) -> ELHBE804BK | D36: =MID(E36,6,2) -> F5 | E36: ELHBEF5804 | F36: ELSBEE5804BKFRE | G36: BK | I36: 6081 | J36: 35000 | K36: 15000 | L36: 358 | M36: 2014-10-10 | N36: 358 | O36: 12530000 | P36: 2014-10-14 | Q36: 332 | R36: 7 | S36: 11620000 | T36: 2014-10-17 | U36: 299 | V36: 4960500 | W36: 83.5 | X36: 39.6 | Y36: 90.1 | Z36: 42.7 | AA36: 19 | AB36: 33
A37: =IF(VLOOKUP(MID($B37,4,2),CODE!K:P,CODE!$O$1,FALSE)="",VLOOKUP(MID($B37,1,3),CODE!$B:$G,CODE!$D$1,FALSE),VLOOKUP(MID($B37,1,3),CODE!$B:$G,CODE!$D$1,FALSE)&"-"&VLOOKUP(MID($B37,4,2),CODE!K:P,CODE!$O$1,FALSE)) -> ELH | B37: =IF(ISERROR(VLOOKUP(E37&G37,품번정리!$D:$E,2,FALSE))=TRUE,E37&G37,VLOOKUP(E37&G37,품번정리!$D:$E,2,FALSE)) -> ELHBEF5804GR | C37: =IF(ISERROR(VLOOKUP(MID(B37,1,5)&MID(B37,8,5),품번정리!$A:$B,2,FALSE))=TRUE,MID(B37,1,5)&MID(B37,8,5),VLOOKUP(MID(B37,1,5)&MID(B37,8,5),품번정리!$A:$B,2,FALSE)) -> ELHBE804GR | D37: =MID(E37,6,2) -> F5 | E37: ELHBEF5804 | F37: ELSBEE5804BKFRE | G37: GR | I37: 6081 | J37: 35000 | K37: 15000 | L37: 406 | M37: 2014-10-10 | N37: 406 | O37: 14210000 | P37: 2014-10-14 | Q37: 218 | R37: 2 | S37: 7630000 | T37: 2014-10-17 | U37: 120 | V37: 1971000 | W37: 29.6 | X37: 13.9 | Y37: 55 | Z37: 25.8 | AA37: 186 | AB37: 98 | AC37: -1 | AD37: -1 | AE37: -15000 | AF37: -0.2
A38: =IF(VLOOKUP(MID($B38,4,2),CODE!K:P,CODE!$O$1,FALSE)="",VLOOKUP(MID($B38,1,3),CODE!$B:$G,CODE!$D$1,FALSE),VLOOKUP(MID($B38,1,3),CODE!$B:$G,CODE!$D$1,FALSE)&"-"&VLOOKUP(MID($B38,4,2),CODE!K:P,CODE!$O$1,FALSE)) -> ELH | B38: =IF(ISERROR(VLOOKUP(E38&G38,품번정리!$D:$E,2,FALSE))=TRUE,E38&G38,VLOOKUP(E38&G38,품번정리!$D:$E,2,FALSE)) -> ELHBEF5804PK | C38: =IF(ISERROR(VLOOKUP(MID(B38,1,5)&MID(B38,8,5),품번정리!$A:$B,2,FALSE))=TRUE,MID(B38,1,5)&MID(B38,8,5),VLOOKUP(MID(B38,1,5)&MID(B38,8,5),품번정리!$A:$B,2,FALSE)) -> ELHBE804PK | D38: =MID(E38,6,2) -> F5 | E38: ELHBEF5804 | F38: ELSBEE5804BKFRE | G38: PK | I38: 6081 | J38: 35000 | K38: 15000 | L38: 361 | M38: 2014-10-10 | N38: 361 | O38: 12635000 | P38: 2014-10-14 | Q38: 259 | R38: 1 | S38: 9065000 | T38: 2014-11-05 | U38: 200 | V38: 3276000 | W38: 55.4 | X38: 25.9 | Y38: 77.2 | Z38: 36.1 | AA38: 101 | AB38: 59
A39: =IF(VLOOKUP(MID($B39,4,2),CODE!K:P,CODE!$O$1,FALSE)="",VLOOKUP(MID($B39,1,3),CODE!$B:$G,CODE!$D$1,FALSE),VLOOKUP(MID($B39,1,3),CODE!$B:$G,CODE!$D$1,FALSE)&"-"&VLOOKUP(MID($B39,4,2),CODE!K:P,CODE!$O$1,FALSE)) -> ELH | B39: =IF(ISERROR(VLOOKUP(E39&G39,품번정리!$D:$E,2,FALSE))=TRUE,E39&G39,VLOOKUP(E39&G39,품번정리!$D:$E,2,FALSE)) -> ELHBEF5838MT | C39: =IF(ISERROR(VLOOKUP(MID(B39,1,5)&MID(B39,8,5),품번정리!$A:$B,2,FALSE))=TRUE,MID(B39,1,5)&MID(B39,8,5),VLOOKUP(MID(B39,1,5)&MID(B39,8,5),품번정리!$A:$B,2,FALSE)) -> ELHBE838MT | D39: =MID(E39,6,2) -> F5 | E39: ELHBEF5838 | F39: ELSBEE5838MTFRE | G39: MT | I39: 6558 | J39: 45000 | K39: 15000 | L39: 414 | M39: 2014-10-10 | N39: 414 | O39: 18630000 | P39: 2014-10-14 | Q39: 414 | S39: 18630000 | T39: 2014-10-21 | U39: 408 | V39: 7865500 | W39: 98.6 | X39: 42.2 | Y39: 98.6 | Z39: 42.2 | AB39: 6
A40: =IF(VLOOKUP(MID($B40,4,2),CODE!K:P,CODE!$O$1,FALSE)="",VLOOKUP(MID($B40,1,3),CODE!$B:$G,CODE!$D$1,FALSE),VLOOKUP(MID($B40,1,3),CODE!$B:$G,CODE!$D$1,FALSE)&"-"&VLOOKUP(MID($B40,4,2),CODE!K:P,CODE!$O$1,FALSE)) -> ELH | B40: =IF(ISERROR(VLOOKUP(E40&G40,품번정리!$D:$E,2,FALSE))=TRUE,E40&G40,VLOOKUP(E40&G40,품번정리!$D:$E,2,FALSE)) -> ELHBEF5839BL | C40: =IF(ISERROR(VLOOKUP(MID(B40,1,5)&MID(B40,8,5),품번정리!$A:$B,2,FALSE))=TRUE,MID(B40,1,5)&MID(B40,8,5),VLOOKUP(MID(B40,1,5)&MID(B40,8,5),품번정리!$A:$B,2,FALSE)) -> ELHBE839BL | D40: =MID(E40,6,2) -> F5 | E40: ELHBEF5839 | F40: ELSBEE5839BLFRE | G40: BL | I40: 6436 | J40: 45000 | K40: 15000 | L40: 415 | M40: 2014-10-10 | N40: 415 | O40: 18675000 | P40: 2014-11-04 | Q40: 284 | R40: 3 | S40: 12780000 | T40: 2014-11-05 | U40: 233 | V40: 3995000 | W40: 56.1 | X40: 21.4 | Y40: 82 | Z40: 31.3 | AA40: 128 | AB40: 51 | AC40: 1 | AD40: 1 | AE40: 15000 | AF40: 0.2
...

Sheet 입고예정DB
B1: 이월 판매 | C1: 러닝 판매 | D1: 판매/입고예정 | E1: 입고예정
A2: 14SS | B2: 13SS | C2: 14SS | D2: 14SS | E2: 14FW
A3: 14FW | B3: 13FW | C3: 14FW | D3: 14FW | E3: 15SS
A4: 기획현황/입고현황 내역 붙여넣기
A5: 품번색상 | B5: 러닝품번색상 | C5: 품번색상2 | D5: 차기입고일 | E5: 미입고
A6: =IF(D6=0,"",C6) | B6: =IF(ISERROR(VLOOKUP(MID(A6,1,5)&MID(A6,8,5),품번정리!$A:$B,2,FALSE))=TRUE,MID(A6,1,5)&MID(A6,8,5),VLOOKUP(MID(A6,1,5)&MID(A6,8,5),품번정리!$A:$B,2,FALSE)) | C6: URKTRG2609RE
A7: =IF(D7=0,"",C7) | B7: =IF(ISERROR(VLOOKUP(MID(A7,1,5)&MID(A7,8,5),품번정리!$A:$B,2,FALSE))=TRUE,MID(A7,1,5)&MID(A7,8,5),VLOOKUP(MID(A7,1,5)&MID(A7,8,5),품번정리!$A:$B,2,FALSE)) | C7: URKSNG0601GY
A8: =IF(D8=0,"",C8) | B8: =IF(ISERROR(VLOOKUP(MID(A8,1,5)&MID(A8,8,5),품번정리!$A:$B,2,FALSE))=TRUE,MID(A8,1,5)&MID(A8,8,5),VLOOKUP(MID(A8,1,5)&MID(A8,8,5),품번정리!$A:$B,2,FALSE)) | C8: URKSNG0602BK
A9: =IF(D9=0,"",C9) | B9: =IF(ISERROR(VLOOKUP(MID(A9,1,5)&MID(A9,8,5),품번정리!$A:$B,2,FALSE))=TRUE,MID(A9,1,5)&MID(A9,8,5),VLOOKUP(MID(A9,1,5)&MID(A9,8,5),품번정리!$A:$B,2,FALSE)) | C9: URKSNG0603WH
A10: =IF(D10=0,"",C10) | B10: =IF(ISERROR(VLOOKUP(MID(A10,1,5)&MID(A10,8,5),품번정리!$A:$B,2,FALSE))=TRUE,MID(A10,1,5)&MID(A10,8,5),VLOOKUP(MID(A10,1,5)&MID(A10,8,5),품번정리!$A:$B,2,FALSE)) | C10: URKSNG0615RE
A11: =IF(D11=0,"",C11) | B11: =IF(ISERROR(VLOOKUP(MID(A11,1,5)&MID(A11,8,5),품번정리!$A:$B,2,FALSE))=TRUE,MID(A11,1,5)&MID(A11,8,5),VLOOKUP(MID(A11,1,5)&MID(A11,8,5),품번정리!$A:$B,2,FALSE)) | C11: JOKBEG0607PK
A12: =IF(D12=0,"",C12) | B12: =IF(ISERROR(VLOOKUP(MID(A12,1,5)&MID(A12,8,5),품번정리!$A:$B,2,FALSE))=TRUE,MID(A12,1,5)&MID(A12,8,5),VLOOKUP(MID(A12,1,5)&MID(A12,8,5),품번정리!$A:$B,2,FALSE)) | C12: JOKBEG0608BL
A13: =IF(D13=0,"",C13) | B13: =IF(ISERROR(VLOOKUP(MID(A13,1,5)&MID(A13,8,5),품번정리!$A:$B,2,FALSE))=TRUE,MID(A13,1,5)&MID(A13,8,5),VLOOKUP(MID(A13,1,5)&MID(A13,8,5),품번정리!$A:$B,2,FALSE)) | C13: URKSNG0509BK
A14: =IF(D14=0,"",C14) | B14: =IF(ISERROR(VLOOKUP(MID(A14,1,5)&MID(A14,8,5),품번정리!$A:$B,2,FALSE))=TRUE,MID(A14,1,5)&MID(A14,8,5),VLOOKUP(MID(A14,1,5)&MID(A14,8,5),품번정리!$A:$B,2,FALSE)) | C14: SWKSNG0958PK
A15: =IF(D15=0,"",C15) | B15: =IF(ISERROR(VLOOKUP(MID(A15,1,5)&MID(A15,8,5),품번정리!$A:$B,2,FALSE))=TRUE,MID(A15,1,5)&MID(A15,8,5),VLOOKUP(MID(A15,1,5)&MID(A15,8,5),품번정리!$A:$B,2,FALSE)) | C15: SMHSNG0402BK
A16: =IF(D16=0,"",C16) | B16: =IF(ISERROR(VLOOKUP(MID(A16,1,5)&MID(A16,8,5),품번정리!$A:$B,2,FALSE))=TRUE,MID(A16,1,5)&MID(A16,8,5),VLOOKUP(MID(A16,1,5)&MID(A16,8,5),품번정리!$A:$B,2,FALSE)) | C16: SMHSNG0426BK
A17: =IF(D17=0,"",C17) | B17: =IF(ISERROR(VLOOKUP(MID(A17,1,5)&MID(A17,8,5),품번정리!$A:$B,2,FALSE))=TRUE,MID(A17,1,5)&MID(A17,8,5),VLOOKUP(MID(A17,1,5)&MID(A17,8,5),품번정리!$A:$B,2,FALSE)) | C17: URHSNG0009BK
... A273: =IF(D273=0,"",C273) | B273: =IF(ISERROR(VLOOKUP(MID(A273,1,5)&MID(A273,8,5),품번정리!$A:$B,2,FALSE))=TRUE,MID(A273,1,5)&MID(A273,8,5),VLOOKUP(MID(A273,1,5)&MID(A273,8,5),품번정리!$A:$B,2,FALSE)) | C273: HKKSNG0602PK
A274: =IF(D274=0,"",C274) | B274: =IF(ISERROR(VLOOKUP(MID(A274,1,5)&MID(A274,8,5),품번정리!$A:$B,2,FALSE))=TRUE,MID(A274,1,5)&MID(A274,8,5),VLOOKUP(MID(A274,1,5)&MID(A274,8,5),품번정리!$A:$B,2,FALSE))
A275: =IF(D275=0,"",C275) | B275: =IF(ISERROR(VLOOKUP(MID(A275,1,5)&MID(A275,8,5),품번정리!$A:$B,2,FALSE))=TRUE,MID(A275,1,5)&MID(A275,8,5),VLOOKUP(MID(A275,1,5)&MID(A275,8,5),품번정리!$A:$B,2,FALSE))
A276: =IF(D276=0,"",C276) | B276: =IF(ISERROR(VLOOKUP(MID(A276,1,5)&MID(A276,8,5),품번정리!$A:$B,2,FALSE))=TRUE,MID(A276,1,5)&MID(A276,8,5),VLOOKUP(MID(A276,1,5)&MID(A276,8,5),품번정리!$A:$B,2,FALSE))
A277: =IF(D277=0,"",C277) | B277: =IF(ISERROR(VLOOKUP(MID(A277,1,5)&MID(A277,8,5),품번정리!$A:$B,2,FALSE))=TRUE,MID(A277,1,5)&MID(A277,8,5),VLOOKUP(MID(A277,1,5)&MID(A277,8,5),품번정리!$A:$B,2,FALSE))
A278: =IF(D278=0,"",C278) | B278: =IF(ISERROR(VLOOKUP(MID(A278,1,5)&MID(A278,8,5),품번정리!$A:$B,2,FALSE))=TRUE,MID(A278,1,5)&MID(A278,8,5),VLOOKUP(MID(A278,1,5)&MID(A278,8,5),품번정리!$A:$B,2,FALSE))
A279: =IF(D279=0,"",C279) | B279: =IF(ISERROR(VLOOKUP(MID(A279,1,5)&MID(A279,8,5),품번정리!$A:$B,2,FALSE))=TRUE,MID(A279,1,5)&MID(A279,8,5),VLOOKUP(MID(A279,1,5)&MID(A279,8,5),품번정리!$A:$B,2,FALSE))
A280: =IF(D280=0,"",C280) | B280: =IF(ISERROR(VLOOKUP(MID(A280,1,5)&MID(A280,8,5),품번정리!$A:$B,2,FALSE))=TRUE,MID(A280,1,5)&MID(A280,8,5),VLOOKUP(MID(A280,1,5)&MID(A280,8,5),품번정리!$A:$B,2,FALSE))
A281: =IF(D281=0,"",C281) | B281: =IF(ISERROR(VLOOKUP(MID(A281,1,5)&MID(A281,8,5),품번정리!$A:$B,2,FALSE))=TRUE,MID(A281,1,5)&MID(A281,8,5),VLOOKUP(MID(A281,1,5)&MID(A281,8,5),품번정리!$A:$B,2,FALSE))
A282: =IF(D282=0,"",C282) | B282: =IF(ISERROR(VLOOKUP(MID(A282,1,5)&MID(A282,8,5),품번정리!$A:$B,2,FALSE))=TRUE,MID(A282,1,5)&MID(A282,8,5),VLOOKUP(MID(A282,1,5)&MID(A282,8,5),품번정리!$A:$B,2,FALSE))
A283: =IF(D283=0,"",C283) | B283: =IF(ISERROR(VLOOKUP(MID(A283,1,5)&MID(A283,8,5),품번정리!$A:$B,2,FALSE))=TRUE,MID(A283,1,5)&MID(A283,8,5),VLOOKUP(MID(A283,1,5)&MID(A283,8,5),품번정리!$A:$B,2,FALSE))
A284: =IF(D284=0,"",C284) | B284: =IF(ISERROR(VLOOKUP(MID(A284,1,5)&MID(A284,8,5),품번정리!$A:$B,2,FALSE))=TRUE,MID(A284,1,5)&MID(A284,8,5),VLOOKUP(MID(A284,1,5)&MID(A284,8,5),품번정리!$A:$B,2,FALSE))
A285: =IF(D285=0,"",C285) | B285: =IF(ISERROR(VLOOKUP(MID(A285,1,5)&MID(A285,8,5),품번정리!$A:$B,2,FALSE))=TRUE,MID(A285,1,5)&MID(A285,8,5),VLOOKUP(MID(A285,1,5)&MID(A285,8,5),품번정리!$A:$B,2,FALSE))
... A2143: =IF(D2143=0,"",C2143) | B2143: =IF(ISERROR(VLOOKUP(MID(A2143,1,5)&MID(A2143,8,5),품번정리!$A:$B,2,FALSE))=TRUE,MID(A2143,1,5)&MID(A2143,8,5),VLOOKUP(MID(A2143,1,5)&MID(A2143,8,5),품번정리!$A:$B,2,FALSE))

Sheet 발주DB
N1: 14FW HATS ON KIDS
A2: 러닝품번색상 | B2: 품번색상 | C2: 업체명 | D2: 발주일 | E2: 정렬=발주일내림 | G2: 러닝품번색상 | H2: 품번색상 | I2: 업체명 | J2: 발주일 | K2: 품번색상 | L2: 업체명 | M2: 발주일 | N2: 품번색상 | O2: 업체명 | P2: 발주일 | Q2: 오더차수 | R2: 차기입고일 | S2: 입고수량 | T2: 미입고수량 | V2: 러닝품번색상 | W2: 품번색상 | X2: 업체명 | Y2: 발주일 | Z2: 품번색상 | AA2: 업체명 | AB2: 발주일
G3: =IF(ISERROR(VLOOKUP(MID(H3,1,5)&MID(H3,8,5),품번정리!$A:$B,2,FALSE))=TRUE,MID(H3,1,5)&MID(H3,8,5),VLOOKUP(MID(H3,1,5)&MID(H3,8,5),품번정리!$A:$B,2,FALSE)) | H3: =IF($R3="","",K3) | I3: =IF($R3="","",L3) | J3: =IF($R3="","",M3) | K3: =IF(N3="",K2,N3) -> SMKFIF3634RE | L3: =IF(O3="",L2,O3) -> 성진 | M3: =IF(P3="",M2,P3) -> 41711 | N3: SMKFIF3634RE | O3: 성진 | P3: 41711 | Q3: R1 | S3: 250 | T3: 0 | V3: =IF(ISERROR(VLOOKUP(MID(W3,1,5)&MID(W3,8,5),품번정리!$A:$B,2,FALSE))=TRUE,MID(W3,1,5)&MID(W3,8,5),VLOOKUP(MID(W3,1,5)&MID(W3,8,5),품번정리!$A:$B,2,FALSE)) | W3: =IF($AG3="","",Z3) | X3: =IF($AG3="","",AA3) | Y3: =IF($AG3="","",AB3) | Z3: =IF(AC3="",Z2,AC3) -> 품번색상 | AA3: =IF(AD3="",AA2,AD3) -> 업체명 | AB3: =IF(AE3="",AB2,AE3) -> 발주일
G4: =IF(ISERROR(VLOOKUP(MID(H4,1,5)&MID(H4,8,5),품번정리!$A:$B,2,FALSE))=TRUE,MID(H4,1,5)&MID(H4,8,5),VLOOKUP(MID(H4,1,5)&MID(H4,8,5),품번정리!$A:$B,2,FALSE)) | H4: =IF($R4="","",K4) | I4: =IF($R4="","",L4) | J4: =IF($R4="","",M4) | K4: =IF(N4="",K3,N4) -> ELKTPF5821MT | L4: =IF(O4="",L3,O4) -> FOREMOST | M4: =IF(P4="",M3,P4) -> 41711 | N4: ELKTPF5821MT | O4: FOREMOST | P4: 41711 | Q4: R1 | S4: 250 | T4: 0 | V4: =IF(ISERROR(VLOOKUP(MID(W4,1,5)&MID(W4,8,5),품번정리!$A:$B,2,FALSE))=TRUE,MID(W4,1,5)&MID(W4,8,5),VLOOKUP(MID(W4,1,5)&MID(W4,8,5),품번정리!$A:$B,2,FALSE)) | W4: =IF($AG4="","",Z4) | X4: =IF($AG4="","",AA4) | Y4: =IF($AG4="","",AB4) | Z4: =IF(AC4="",Z3,AC4) -> 품번색상 | AA4: =IF(AD4="",AA3,AD4) -> 업체명 | AB4: =IF(AE4="",AB3,AE4) -> 발주일
G5: =IF(ISERROR(VLOOKUP(MID(H5,1,5)&MID(H5,8,5),품번정리!$A:$B,2,FALSE))=TRUE,MID(H5,1,5)&MID(H5,8,5),VLOOKUP(MID(H5,1,5)&MID(H5,8,5),품번정리!$A:$B,2,FALSE)) | H5: =IF($R5="","",K5) | I5: =IF($R5="","",L5) | J5: =IF($R5="","",M5) | K5: =IF(N5="",K4,N5) -> ELKTPF5801NY | L5: =IF(O5="",L4,O5) -> FOREMOST | M5: =IF(P5="",M4,P5) -> 41711 | N5: ELKTPF5801NY | O5: FOREMOST | P5: 41711 | Q5: R1 | S5: 250 | T5: 0 | V5: =IF(ISERROR(VLOOKUP(MID(W5,1,5)&MID(W5,8,5),품번정리!$A:$B,2,FALSE))=TRUE,MID(W5,1,5)&MID(W5,8,5),VLOOKUP(MID(W5,1,5)&MID(W5,8,5),품번정리!$A:$B,2,FALSE)) | W5: =IF($AG5="","",Z5) | X5: =IF($AG5="","",AA5) | Y5: =IF($AG5="","",AB5) | Z5: =IF(AC5="",Z4,AC5) -> 품번색상 | AA5: =IF(AD5="",AA4,AD5) -> 업체명 | AB5: =IF(AE5="",AB4,AE5) -> 발주일
G6: =IF(ISERROR(VLOOKUP(MID(H6,1,5)&MID(H6,8,5),품번정리!$A:$B,2,FALSE))=TRUE,MID(H6,1,5)&MID(H6,8,5),VLOOKUP(MID(H6,1,5)&MID(H6,8,5),품번정리!$A:$B,2,FALSE)) | H6: =IF($R6="","",K6) | I6: =IF($R6="","",L6) | J6: =IF($R6="","",M6) | K6: =IF(N6="",K5,N6) -> JOKEBF5803BL | L6: =IF(O6="",L5,O6) -> FOREMOST | M6: =IF(P6="",M5,P6) -> 41711 | N6: JOKEBF5803BL | O6: FOREMOST | P6: 41711 | Q6: R1 | S6: 250 | T6: 0 | V6: =IF(ISERROR(VLOOKUP(MID(W6,1,5)&MID(W6,8,5),품번정리!$A:$B,2,FALSE))=TRUE,MID(W6,1,5)&MID(W6,8,5),VLOOKUP(MID(W6,1,5)&MID(W6,8,5),품번정리!$A:$B,2,FALSE)) | W6: =IF($AG6="","",Z6) | X6: =IF($AG6="","",AA6) | Y6: =IF($AG6="","",AB6) | Z6: =IF(AC6="",Z5,AC6) -> 품번색상 | AA6: =IF(AD6="",AA5,AD6) -> 업체명 | AB6: =IF(AE6="",AB5,AE6) -> 발주일
G7: =IF(ISERROR(VLOOKUP(MID(H7,1,5)&MID(H7,8,5),품번정리!$A:$B,2,FALSE))=TRUE,MID(H7,1,5)&MID(H7,8,5),VLOOKUP(MID(H7,1,5)&MID(H7,8,5),품번정리!$A:$B,2,FALSE)) | H7: =IF($R7="","",K7) | I7: =IF($R7="","",L7) | J7: =IF($R7="","",M7) | K7: =IF(N7="",K6,N7) -> JOKEBF5804RE | L7: =IF(O7="",L6,O7) -> FOREMOST | M7: =IF(P7="",M6,P7) -> 41711 | N7: JOKEBF5804RE | O7: FOREMOST | P7: 41711 | Q7: R1 | S7: 250 | T7: 0 | V7: =IF(ISERROR(VLOOKUP(MID(W7,1,5)&MID(W7,8,5),품번정리!$A:$B,2,FALSE))=TRUE,MID(W7,1,5)&MID(W7,8,5),VLOOKUP(MID(W7,1,5)&MID(W7,8,5),품번정리!$A:$B,2,FALSE)) | W7: =IF($AG7="","",Z7) | X7: =IF($AG7="","",AA7) | Y7: =IF($AG7="","",AB7) | Z7: =IF(AC7="",Z6,AC7) -> 품번색상 | AA7: =IF(AD7="",AA6,AD7) -> 업체명 | AB7: =IF(AE7="",AB6,AE7) -> 발주일
G8: =IF(ISERROR(VLOOKUP(MID(H8,1,5)&MID(H8,8,5),품번정리!$A:$B,2,FALSE))=TRUE,MID(H8,1,5)&MID(H8,8,5),VLOOKUP(MID(H8,1,5)&MID(H8,8,5),품번정리!$A:$B,2,FALSE)) | H8: =IF($R8="","",K8) | I8: =IF($R8="","",L8) | J8: =IF($R8="","",M8) | K8: =IF(N8="",K7,N8) -> JOKVBF5806NY | L8: =IF(O8="",L7,O8) -> FOREMOST | M8: =IF(P8="",M7,P8) -> 41711 | N8: JOKVBF5806NY | O8: FOREMOST | P8: 41711 | Q8: R1 | S8: 250 | T8: 0 | V8: =IF(ISERROR(VLOOKUP(MID(W8,1,5)&MID(W8,8,5),품번정리!$A:$B,2,FALSE))=TRUE,MID(W8,1,5)&MID(W8,8,5),VLOOKUP(MID(W8,1,5)&MID(W8,8,5),품번정리!$A:$B,2,FALSE)) | W8: =IF($AG8="","",Z8) | X8: =IF($AG8="","",AA8) | Y8: =IF($AG8="","",AB8) | Z8: =IF(AC8="",Z7,AC8) -> 품번색상 | AA8: =IF(AD8="",AA7,AD8) -> 업체명 | AB8: =IF(AE8="",AB7,AE8) -> 발주일
G9: =IF(ISERROR(VLOOKUP(MID(H9,1,5)&MID(H9,8,5),품번정리!$A:$B,2,FALSE))=TRUE,MID(H9,1,5)&MID(H9,8,5),VLOOKUP(MID(H9,1,5)&MID(H9,8,5),품번정리!$A:$B,2,FALSE)) | H9: =IF($R9="","",K9) | I9: =IF($R9="","",L9) | J9: =IF($R9="","",M9) | K9: =IF(N9="",K8,N9) -> JOKVBF5806PK | L9: =IF(O9="",L8,O9) -> FOREMOST | M9: =IF(P9="",M8,P9) -> 41711 | N9: JOKVBF5806PK | O9: FOREMOST | P9: 41711 | Q9: R1 | S9: 249 | T9: 0 | V9: =IF(ISERROR(VLOOKUP(MID(W9,1,5)&MID(W9,8,5),품번정리!$A:$B,2,FALSE))=TRUE,MID(W9,1,5)&MID(W9,8,5),VLOOKUP(MID(W9,1,5)&MID(W9,8,5),품번정리!$A:$B,2,FALSE)) | W9: =IF($AG9="","",Z9) | X9: =IF($AG9="","",AA9) | Y9: =IF($AG9="","",AB9) | Z9: =IF(AC9="",Z8,AC9) -> 품번색상 | AA9: =IF(AD9="",AA8,AD9) -> 업체명 | AB9: =IF(AE9="",AB8,AE9) -> 발주일
G10: =IF(ISERROR(VLOOKUP(MID(H10,1,5)&MID(H10,8,5),품번정리!$A:$B,2,FALSE))=TRUE,MID(H10,1,5)&MID(H10,8,5),VLOOKUP(MID(H10,1,5)&MID(H10,8,5),품번정리!$A:$B,2,FALSE)) | H10: =IF($R10="","",K10) | I10: =IF($R10="","",L10) | J10: =IF($R10="","",M10) | K10: =IF(N10="",K9,N10) -> PNKUMF5501RE | L10: =IF(O10="",L9,O10) -> 성진 | M10: =IF(P10="",M9,P10) -> 41732 | N10: PNKUMF5501RE | O10: 성진 | P10: 41732 | S10: 400 | T10: 0 | V10: =IF(ISERROR(VLOOKUP(MID(W10,1,5)&MID(W10,8,5),품번정리!$A:$B,2,FALSE))=TRUE,MID(W10,1,5)&MID(W10,8,5),VLOOKUP(MID(W10,1,5)&MID(W10,8,5),품번정리!$A:$B,2,FALSE)) | W10: =IF($AG10="","",Z10) | X10: =IF($AG10="","",AA10) | Y10: =IF($AG10="","",AB10) | Z10: =IF(AC10="",Z9,AC10) -> 품번색상 | AA10: =IF(AD10="",AA9,AD10) -> 업체명 | AB10: =IF(AE10="",AB9,AE10) -> 발주일
G11: =IF(ISERROR(VLOOKUP(MID(H11,1,5)&MID(H11,8,5),품번정리!$A:$B,2,FALSE))=TRUE,MID(H11,1,5)&MID(H11,8,5),VLOOKUP(MID(H11,1,5)&MID(H11,8,5),품번정리!$A:$B,2,FALSE)) | H11: =IF($R11="","",K11) | I11: =IF($R11="","",L11) | J11: =IF($R11="","",M11) | K11: =IF(N11="",K10,N11) -> PNKUMF5501PK | L11: =IF(O11="",L10,O11) -> 성진 | M11: =IF(P11="",M10,P11) -> 41732 | N11: PNKUMF5501PK | O11: 성진 | P11: 41732 | S11: 600 | T11: 0 | V11: =IF(ISERROR(VLOOKUP(MID(W11,1,5)&MID(W11,8,5),품번정리!$A:$B,2,FALSE))=TRUE,MID(W11,1,5)&MID(W11,8,5),VLOOKUP(MID(W11,1,5)&MID(W11,8,5),품번정리!$A:$B,2,FALSE)) | W11: =IF($AG11="","",Z11) | X11: =IF($AG11="","",AA11) | Y11: =IF($AG11="","",AB11) | Z11: =IF(AC11="",Z10,AC11) -> 품번색상 | AA11: =IF(AD11="",AA10,AD11) -> 업체명 | AB11: =IF(AE11="",AB10,AE11) -> 발주일
G12: =IF(ISERROR(VLOOKUP(MID(H12,1,5)&MID(H12,8,5),품번정리!$A:$B,2,FALSE))=TRUE,MID(H12,1,5)&MID(H12,8,5),VLOOKUP(MID(H12,1,5)&MID(H12,8,5),품번정리!$A:$B,2,FALSE)) | H12: =IF($R12="","",K12) | I12: =IF($R12="","",L12) | J12: =IF($R12="","",M12) | K12: =IF(N12="",K11,N12) -> PNKERF5503NY | L12: =IF(O12="",L11,O12) -> 동일모자 | M12: =IF(P12="",M11,P12) -> 41732 | N12: PNKERF5503NY | O12: 동일모자 | P12: 41732 | S12: 250 | T12: 0 | V12: =IF(ISERROR(VLOOKUP(MID(W12,1,5)&MID(W12,8,5),품번정리!$A:$B,2,FALSE))=TRUE,MID(W12,1,5)&MID(W12,8,5),VLOOKUP(MID(W12,1,5)&MID(W12,8,5),품번정리!$A:$B,2,FALSE)) | W12: =IF($AG12="","",Z12) | X12: =IF($AG12="","",AA12) | Y12: =IF($AG12="","",AB12) | Z12: =IF(AC12="",Z11,AC12) -> 품번색상 | AA12: =IF(AD12="",AA11,AD12) -> 업체명 | AB12: =IF(AE12="",AB11,AE12) -> 발주일
G13: =IF(ISERROR(VLOOKUP(MID(H13,1,5)&MID(H13,8,5),품번정리!$A:$B,2,FALSE))=TRUE,MID(H13,1,5)&MID(H13,8,5),VLOOKUP(MID(H13,1,5)&MID(H13,8,5),품번정리!$A:$B,2,FALSE)) | H13: =IF($R13="","",K13) | I13: =IF($R13="","",L13) | J13: =IF($R13="","",M13) | K13: =IF(N13="",K12,N13) -> PNKERF5503PK | L13: =IF(O13="",L12,O13) -> 동일모자 | M13: =IF(P13="",M12,P13) -> 41732 | N13: PNKERF5503PK | O13: 동일모자 | P13: 41732 | S13: 250 | T13: 0 | V13: =IF(ISERROR(VLOOKUP(MID(W13,1,5)&MID(W13,8,5),품번정리!$A:$B,2,FALSE))=TRUE,MID(W13,1,5)&MID(W13,8,5),VLOOKUP(MID(W13,1,5)&MID(W13,8,5),품번정리!$A:$B,2,FALSE)) | W13: =IF($AG13="","",Z13) | X13: =IF($AG13="","",AA13) | Y13: =IF($AG13="","",AB13) | Z13: =IF(AC13="",Z12,AC13) -> 품번색상 | AA13: =IF(AD13="",AA12,AD13) -> 업체명 | AB13: =IF(AE13="",AB12,AE13) -> 발주일
G14: =IF(ISERROR(VLOOKUP(MID(H14,1,5)&MID(H14,8,5),품번정리!$A:$B,2,FALSE))=TRUE,MID(H14,1,5)&MID(H14,8,5),VLOOKUP(MID(H14,1,5)&MID(H14,8,5),품번정리!$A:$B,2,FALSE)) | H14: =IF($R14="","",K14) | I14: =IF($R14="","",L14) | J14: =IF($R14="","",M14) | K14: =IF(N14="",K13,N14) -> SMKFLF3501BK | L14: =IF(O14="",L13,O14) -> 성진 | M14: =IF(P14="",M13,P14) -> 41733 | N14: SMKFLF3501BK | O14: 성진 | P14: 41733 | S14: 280 | T14: 0 | V14: =IF(ISERROR(VLOOKUP(MID(W14,1,5)&MID(W14,8,5),품번정리!$A:$B,2,FALSE))=TRUE,MID(W14,1,5)&MID(W14,8,5),VLOOKUP(MID(W14,1,5)&MID(W14,8,5),품번정리!$A:$B,2,FALSE)) | W14: =IF($AG14="","",Z14) | X14: =IF($AG14="","",AA14) | Y14: =IF($AG14="","",AB14) | Z14: =IF(AC14="",Z13,AC14) -> 품번색상 | AA14: =IF(AD14="",AA13,AD14) -> 업체명 | AB14: =IF(AE14="",AB13,AE14) -> 발주일
G15: =IF(ISERROR(VLOOKUP(MID(H15,1,5)&MID(H15,8,5),품번정리!$A:$B,2,FALSE))=TRUE,MID(H15,1,5)&MID(H15,8,5),VLOOKUP(MID(H15,1,5)&MID(H15,8,5),품번정리!$A:$B,2,FALSE)) | H15: =IF($R15="","",K15) | I15: =IF($R15="","",L15) | J15: =IF($R15="","",M15) | K15: =IF(N15="",K14,N15) -> SMKBAF3503GR | L15: =IF(O15="",L14,O15) -> 동일모자 | M15: =IF(P15="",M14,P15) -> 41733 | N15: SMKBAF3503GR | O15: 동일모자 | P15: 41733 | S15: 355 | T15: 0 | V15: =IF(ISERROR(VLOOKUP(MID(W15,1,5)&MID(W15,8,5),품번정리!$A:$B,2,FALSE))=TRUE,MID(W15,1,5)&MID(W15,8,5),VLOOKUP(MID(W15,1,5)&MID(W15,8,5),품번정리!$A:$B,2,FALSE)) | W15: =IF($AG15="","",Z15) | X15: =IF($AG15="","",AA15) | Y15: =IF($AG15="","",AB15) | Z15: =IF(AC15="",Z14,AC15) -> 품번색상 | AA15: =IF(AD15="",AA14,AD15) -> 업체명 | AB15: =IF(AE15="",AB14,AE15) -> 발주일
G16: =IF(ISERROR(VLOOKUP(MID(H16,1,5)&MID(H16,8,5),품번정리!$A:$B,2,FALSE))=TRUE,MID(H16,1,5)&MID(H16,8,5),VLOOKUP(MID(H16,1,5)&MID(H16,8,5),품번정리!$A:$B,2,FALSE)) | H16: =IF($R16="","",K16) | I16: =IF($R16="","",L16) | J16: =IF($R16="","",M16) | K16: =IF(N16="",K15,N16) -> SMKBAF3503OR | L16: =IF(O16="",L15,O16) -> 동일모자 | M16: =IF(P16="",M15,P16) -> 41733 | N16: SMKBAF3503OR | O16: 동일모자 | P16: 41733 | S16: 299 | T16: 0 | V16: =IF(ISERROR(VLOOKUP(MID(W16,1,5)&MID(W16,8,5),품번정리!$A:$B,2,FALSE))=TRUE,MID(W16,1,5)&MID(W16,8,5),VLOOKUP(MID(W16,1,5)&MID(W16,8,5),품번정리!$A:$B,2,FALSE)) | W16: =IF($AG16="","",Z16) | X16: =IF($AG16="","",AA16) | Y16: =IF($AG16="","",AB16) | Z16: =IF(AC16="",Z15,AC16) -> 품번색상 | AA16: =IF(AD16="",AA15,AD16) -> 업체명 | AB16: =IF(AE16="",AB15,AE16) -> 발주일
G17: =IF(ISERROR(VLOOKUP(MID(H17,1,5)&MID(H17,8,5),품번정리!$A:$B,2,FALSE))=TRUE,MID(H17,1,5)&MID(H17,8,5),VLOOKUP(MID(H17,1,5)&MID(H17,8,5),품번정리!$A:$B,2,FALSE)) | H17: =IF($R17="","",K17) | I17: =IF($R17="","",L17) | J17: =IF($R17="","",M17) | K17: =IF(N17="",K16,N17) -> SMKSNF3502BL | L17: =IF(O17="",L16,O17) -> QF | M17: =IF(P17="",M16,P17) -> 41733 | N17: SMKSNF3502BL | O17: QF | P17: 41733 | S17: 80 | T17: 0 | V17: =IF(ISERROR(VLOOKUP(MID(W17,1,5)&MID(W17,8,5),품번정리!$A:$B,2,FALSE))=TRUE,MID(W17,1,5)&MID(W17,8,5),VLOOKUP(MID(W17,1,5)&MID(W17,8,5),품번정리!$A:$B,2,FALSE)) | W17: =IF($AG17="","",Z17) | X17: =IF($AG17="","",AA17) | Y17: =IF($AG17="","",AB17) | Z17: =IF(AC17="",Z16,AC17) -> 품번색상 | AA17: =IF(AD17="",AA16,AD17) -> 업체명 | AB17: =IF(AE17="",AB16,AE17) -> 발주일
G18: =IF(ISERROR(VLOOKUP(MID(H18,1,5)&MID(H18,8,5),품번정리!$A:$B,2,FALSE))=TRUE,MID(H18,1,5)&MID(H18,8,5),VLOOKUP(MID(H18,1,5)&MID(H18,8,5),품번정리!$A:$B,2,FALSE)) | H18: =IF($R18="","",K18) | I18: =IF($R18="","",L18) | J18: =IF($R18="","",M18) | K18: =IF(N18="",K17,N18) -> SWKSNF3503PP | L18: =IF(O18="",L17,O18) -> QF | M18: =IF(P18="",M17,P18) -> 41733 | N18: SWKSNF3503PP | O18: QF | P18: 41733 | S18: 400 | T18: 0 | V18: =IF(ISERROR(VLOOKUP(MID(W18,1,5)&MID(W18,8,5),품번정리!$A:$B,2,FALSE))=TRUE,MID(W18,1,5)&MID(W18,8,5),VLOOKUP(MID(W18,1,5)&MID(W18,8,5),품번정리!$A:$B,2,FALSE)) | W18: =IF($AG18="","",Z18) | X18: =IF($AG18="","",AA18) | Y18: =IF($AG18="","",AB18) | Z18: =IF(AC18="",Z17,AC18) -> 품번색상 | AA18: =IF(AD18="",AA17,AD18) -> 업체명 | AB18: =IF(AE18="",AB17,AE18) -> 발주일
G19: =IF(ISERROR(VLOOKUP(MID(H19,1,5)&MID(H19,8,5),품번정리!$A:$B,2,FALSE))=TRUE,MID(H19,1,5)&MID(H19,8,5),VLOOKUP(MID(H19,1,5)&MID(H19,8,5),품번정리!$A:$B,2,FALSE)) | H19: =IF($R19="","",K19) | I19: =IF($R19="","",L19) | J19: =IF($R19="","",M19) | K19: =IF(N19="",K18,N19) -> SWKSNF3503PK | L19: =IF(O19="",L18,O19) -> QF | M19: =IF(P19="",M18,P19) -> 41733 | N19: SWKSNF3503PK | O19: QF | P19: 41733 | S19: 399 | T19: 0 | V19: =IF(ISERROR(VLOOKUP(MID(W19,1,5)&MID(W19,8,5),품번정리!$A:$B,2,FALSE))=TRUE,MID(W19,1,5)&MID(W19,8,5),VLOOKUP(MID(W19,1,5)&MID(W19,8,5),품번정리!$A:$B,2,FALSE)) | W19: =IF($AG19="","",Z19) | X19: =IF($AG19="","",AA19) | Y19: =IF($AG19="","",AB19) | Z19: =IF(AC19="",Z18,AC19) -> 품번색상 | AA19: =IF(AD19="",AA18,AD19) -> 업체명 | AB19: =IF(AE19="",AB18,AE19) -> 발주일
G20: =IF(ISERROR(VLOOKUP(MID(H20,1,5)&MID(H20,8,5),품번정리!$A:$B,2,FALSE))=TRUE,MID(H20,1,5)&MID(H20,8,5),VLOOKUP(MID(H20,1,5)&MID(H20,8,5),품번정리!$A:$B,2,FALSE)) | H20: =IF($R20="","",K20) | I20: =IF($R20="","",L20) | J20: =IF($R20="","",M20) | K20: =IF(N20="",K19,N20) -> SMKERF5505NY | L20: =IF(O20="",L19,O20) -> 캡보이2 | M20: =IF(P20="",M19,P20) -> 41733 | N20: SMKERF5505NY | O20: 캡보이2 | P20: 41733 | S20: 300 | T20: 0 | V20: =IF(ISERROR(VLOOKUP(MID(W20,1,5)&MID(W20,8,5),품번정리!$A:$B,2,FALSE))=TRUE,MID(W20,1,5)&MID(W20,8,5),VLOOKUP(MID(W20,1,5)&MID(W20,8,5),품번정리!$A:$B,2,FALSE)) | W20: =IF($AG20="","",Z20) | X20: =IF($AG20="","",AA20) | Y20: =IF($AG20="","",AB20) | Z20: =IF(AC20="",Z19,AC20) -> 품번색상 | AA20: =IF(AD20="",AA19,AD20) -> 업체명 | AB20: =IF(AE20="",AB19,AE20) -> 발주일
G21: =IF(ISERROR(VLOOKUP(MID(H21,1,5)&MID(H21,8,5),품번정리!$A:$B,2,FALSE))=TRUE,MID(H21,1,5)&MID(H21,8,5),VLOOKUP(MID(H21,1,5)&MID(H21,8,5),품번정리!$A:$B,2,FALSE)) | H21: =IF($R21="","",K21) | I21: =IF($R21="","",L21) | J21: =IF($R21="","",M21) | K21: =IF(N21="",K20,N21) -> SMKERF5506NY | L21: =IF(O21="",L20,O21) -> 동일모자 | M21: =IF(P21="",M20,P21) -> 41733 | N21: SMKERF5506NY | O21: 동일모자 | P21: 41733 | S21: 298 | T21: 0 | V21: =IF(ISERROR(VLOOKUP(MID(W21,1,5)&MID(W21,8,5),품번정리!$A:$B,2,FALSE))=TRUE,MID(W21,1,5)&MID(W21,8,5),VLOOKUP(MID(W21,1,5)&MID(W21,8,5),품번정리!$A:$B,2,FALSE)) | W21: =IF($AG21="","",Z21) | X21: =IF($AG21="","",AA21) | Y21: =IF($AG21="","",AB21) | Z21: =IF(AC21="",Z20,AC21) -> 품번색상 | AA21: =IF(AD21="",AA20,AD21) -> 업체명 | AB21: =IF(AE21="",AB20,AE21) -> 발주일
... G39: =IF(ISERROR(VLOOKUP(MID(H39,1,5)&MID(H39,8,5),품번정리!$A:$B,2,FALSE))=TRUE,MID(H39,1,5)&MID(H39,8,5),VLOOKUP(MID(H39,1,5)&MID(H39,8,5),품번정리!$A:$B,2,FALSE)) | H39: =IF($R39="","",K39) | I39: =IF($R39="","",L39) | J39: =IF($R39="","",M39) | K39: =IF(N39="",K38,N39) -> DPKSNF3504MT | L39: =IF(O39="",L38,O39) -> 캡보이 | M39: =IF(P39="",M38,P39) -> 41736 | N39: DPKSNF3504MT | O39: 캡보이 | P39: 41736 | S39: 120 | T39: 0 | V39: =IF(ISERROR(VLOOKUP(MID(W39,1,5)&MID(W39,8,5),품번정리!$A:$B,2,FALSE))=TRUE,MID(W39,1,5)&MID(W39,8,5),VLOOKUP(MID(W39,1,5)&MID(W39,8,5),품번정리!$A:$B,2,FALSE)) | W39: =IF($AG39="","",Z39) | X39: =IF($AG39="","",AA39) | Y39: =IF($AG39="","",AB39) | Z39: =IF(AC39="",Z38,AC39) -> 품번색상 | AA39: =IF(AD39="",AA38,AD39) -> 업체명 | AB39: =IF(AE39="",AB38,AE39) -> 발주일
G40: =IF(ISERROR(VLOOKUP(MID(H40,1,5)&MID(H40,8,5),품번정리!$A:$B,2,FALSE))=TRUE,MID(H40,1,5)&MID(H40,8,5),VLOOKUP(MID(H40,1,5)&MID(H40,8,5),품번정리!$A:$B,2,FALSE)) | H40: =IF($R40="","",K40) | I40: =IF($R40="","",L40) | J40: =IF($R40="","",M40) | K40: =IF(N40="",K39,N40) -> DPKSNF3504MT | L40: =IF(O40="",L39,O40) -> QF | M40: =IF(P40="",M39,P40) -> 41856 | O40: QF | P40: 41856 | Q40: R1 | S40: 120 | T40: 0 | V40: =IF(ISERROR(VLOOKUP(MID(W40,1,5)&MID(W40,8,5),품번정리!$A:$B,2,FALSE))=TRUE,MID(W40,1,5)&MID(W40,8,5),VLOOKUP(MID(W40,1,5)&MID(W40,8,5),품번정리!$A:$B,2,FALSE)) | W40: =IF($AG40="","",Z40) | X40: =IF($AG40="","",AA40) | Y40: =IF($AG40="","",AB40) | Z40: =IF(AC40="",Z39,AC40) -> 품번색상 | AA40: =IF(AD40="",AA39,AD40) -> 업체명 | AB40: =IF(AE40="",AB39,AE40) -> 발주일
G41: =IF(ISERROR(VLOOKUP(MID(H41,1,5)&MID(H41,8,5),품번정리!$A:$B,2,FALSE))=TRUE,MID(H41,1,5)&MID(H41,8,5),VLOOKUP(MID(H41,1,5)&MID(H41,8,5),품번정리!$A:$B,2,FALSE)) | H41: =IF($R41="","",K41) | I41: =IF($R41="","",L41) | J41: =IF($R41="","",M41) | K41: =IF(N41="",K40,N41) -> ELKSNF5503RE | L41: =IF(O41="",L40,O41) -> 성진 | M41: =IF(P41="",M40,P41) -> 41736 | N41: ELKSNF5503RE | O41: 성진 | P41: 41736 | S41: 600 | T41: 0 | V41: =IF(ISERROR(VLOOKUP(MID(W41,1,5)&MID(W41,8,5),품번정리!$A:$B,2,FALSE))=TRUE,MID(W41,1,5)&MID(W41,8,5),VLOOKUP(MID(W41,1,5)&MID(W41,8,5),품번정리!$A:$B,2,FALSE)) | W41: =IF($AG41="","",Z41) | X41: =IF($AG41="","",AA41) | Y41: =IF($AG41="","",AB41) | Z41: =IF(AC41="",Z40,AC41) -> 품번색상 | AA41: =IF(AD41="",AA40,AD41) -> 업체명 | AB41: =IF(AE41="",AB40,AE41) -> 발주일
G42: =IF(ISERROR(VLOOKUP(MID(H42,1,5)&MID(H42,8,5),품번정리!$A:$B,2,FALSE))=TRUE,MID(H42,1,5)&MID(H42,8,5),VLOOKUP(MID(H42,1,5)&MID(H42,8,5),품번정리!$A:$B,2,FALSE)) | H42: =IF($R42="","",K42) | I42: =IF($R42="","",L42) | J42: =IF($R42="","",M42) | K42: =IF(N42="",K41,N42) -> ELKBAF5506GR | L42: =IF(O42="",L41,O42) -> 동일모자 | M42: =IF(P42="",M41,P42) -> 41736 | N42: ELKBAF5506GR | O42: 동일모자 | P42: 41736 | S42: 141 | T42: 0 | V42: =IF(ISERROR(VLOOKUP(MID(W42,1,5)&MID(W42,8,5),품번정리!$A:$B,2,FALSE))=TRUE,MID(W42,1,5)&MID(W42,8,5),VLOOKUP(MID(W42,1,5)&MID(W42,8,5),품번정리!$A:$B,2,FALSE)) | W42: =IF($AG42="","",Z42) | X42: =IF($AG42="","",AA42) | Y42: =IF($AG42="","",AB42) | Z42: =IF(AC42="",Z41,AC42) -> 품번색상 | AA42: =IF(AD42="",AA41,AD42) -> 업체명 | AB42: =IF(AE42="",AB41,AE42) -> 발주일
G43: =IF(ISERROR(VLOOKUP(MID(H43,1,5)&MID(H43,8,5),품번정리!$A:$B,2,FALSE))=TRUE,MID(H43,1,5)&MID(H43,8,5),VLOOKUP(MID(H43,1,5)&MID(H43,8,5),품번정리!$A:$B,2,FALSE)) | H43: =IF($R43="","",K43) | I43: =IF($R43="","",L43) | J43: =IF($R43="","",M43) | K43: =IF(N43="",K42,N43) -> ELKBAF5507RE | L43: =IF(O43="",L42,O43) -> 동일모자 | M43: =IF(P43="",M42,P43) -> 41736 | N43: ELKBAF5507RE | O43: 동일모자 | P43: 41736 | S43: 541 | T43: 0 | V43: =IF(ISERROR(VLOOKUP(MID(W43,1,5)&MID(W43,8,5),품번정리!$A:$B,2,FALSE))=TRUE,MID(W43,1,5)&MID(W43,8,5),VLOOKUP(MID(W43,1,5)&MID(W43,8,5),품번정리!$A:$B,2,FALSE)) | W43: =IF($AG43="","",Z43) | X43: =IF($AG43="","",AA43) | Y43: =IF($AG43="","",AB43) | Z43: =IF(AC43="",Z42,AC43) -> 품번색상 | AA43: =IF(AD43="",AA42,AD43) -> 업체명 | AB43: =IF(AE43="",AB42,AE43) -> 발주일
G44: =IF(ISERROR(VLOOKUP(MID(H44,1,5)&MID(H44,8,5),품번정리!$A:$B,2,FALSE))=TRUE,MID(H44,1,5)&MID(H44,8,5),VLOOKUP(MID(H44,1,5)&MID(H44,8,5),품번정리!$A:$B,2,FALSE)) | H44: =IF($R44="","",K44) | I44: =IF($R44="","",L44) | J44: =IF($R44="","",M44) | K44: =IF(N44="",K43,N44) -> ELKBAF5508PK | L44: =IF(O44="",L43,O44) -> 동일모자 | M44: =IF(P44="",M43,P44) -> 41736 | N44: ELKBAF5508PK | O44: 동일모자 | P44: 41736 | S44: 519 | T44: 0 | V44: =IF(ISERROR(VLOOKUP(MID(W44,1,5)&MID(W44,8,5),품번정리!$A:$B,2,FALSE))=TRUE,MID(W44,1,5)&MID(W44,8,5),VLOOKUP(MID(W44,1,5)&MID(W44,8,5),품번정리!$A:$B,2,FALSE)) | W44: =IF($AG44="","",Z44) | X44: =IF($AG44="","",AA44) | Y44: =IF($AG44="","",AB44) | Z44: =IF(AC44="",Z43,AC44) -> 품번색상 | AA44: =IF(AD44="",AA43,AD44) -> 업체명 | AB44: =IF(AE44="",AB43,AE44) -> 발주일
G45: =IF(ISERROR(VLOOKUP(MID(H45,1,5)&MID(H45,8,5),품번정리!$A:$B,2,FALSE))=TRUE,MID(H45,1,5)&MID(H45,8,5),VLOOKUP(MID(H45,1,5)&MID(H45,8,5),품번정리!$A:$B,2,FALSE)) | H45: =IF($R45="","",K45) | I45: =IF($R45="","",L45) | J45: =IF($R45="","",M45) | K45: =IF(N45="",K44,N45) -> ELKERF5511GR | L45: =IF(O45="",L44,O45) -> 동일모자 | M45: =IF(P45="",M44,P45) -> 41736 | N45: ELKERF5511GR | O45: 동일모자 | P45: 41736 | S45: 145 | T45: 0 | V45: =IF(ISERROR(VLOOKUP(MID(W45,1,5)&MID(W45,8,5),품번정리!$A:$B,2,FALSE))=TRUE,MID(W45,1,5)&MID(W45,8,5),VLOOKUP(MID(W45,1,5)&MID(W45,8,5),품번정리!$A:$B,2,FALSE)) | W45: =IF($AG45="","",Z45) | X45: =IF($AG45="","",AA45) | Y45: =IF($AG45="","",AB45) | Z45: =IF(AC45="",Z44,AC45) -> 품번색상 | AA45: =IF(AD45="",AA44,AD45) -> 업체명 | AB45: =IF(AE45="",AB44,AE45) -> 발주일
G46: =IF(ISERROR(VLOOKUP(MID(H46,1,5)&MID(H46,8,5),품번정리!$A:$B,2,FALSE))=TRUE,MID(H46,1,5)&MID(H46,8,5),VLOOKUP(MID(H46,1,5)&MID(H46,8,5),품번정리!$A:$B,2,FALSE)) | H46: =IF($R46="","",K46) | I46: =IF($R46="","",L46) | J46: =IF($R46="","",M46) | K46: =IF(N46="",K45,N46) -> ELKERF5512RE | L46: =IF(O46="",L45,O46) -> 동일모자 | M46: =IF(P46="",M45,P46) -> 41736 | N46: ELKERF5512RE | O46: 동일모자 | P46: 41736 | S46: 125 | T46: 0 | V46: =IF(ISERROR(VLOOKUP(MID(W46,1,5)&MID(W46,8,5),품번정리!$A:$B,2,FALSE))=TRUE,MID(W46,1,5)&MID(W46,8,5),VLOOKUP(MID(W46,1,5)&MID(W46,8,5),품번정리!$A:$B,2,FALSE)) | W46: =IF($AG46="","",Z46) | X46: =IF($AG46="","",AA46) | Y46: =IF($AG46="","",AB46) | Z46: =IF(AC46="",Z45,AC46) -> 품번색상 | AA46: =IF(AD46="",AA45,AD46) -> 업체명 | AB46: =IF(AE46="",AB45,AE46) -> 발주일
G47: =IF(ISERROR(VLOOKUP(MID(H47,1,5)&MID(H47,8,5),품번정리!$A:$B,2,FALSE))=TRUE,MID(H47,1,5)&MID(H47,8,5),VLOOKUP(MID(H47,1,5)&MID(H47,8,5),품번정리!$A:$B,2,FALSE)) | H47: =IF($R47="","",K47) | I47: =IF($R47="","",L47) | J47: =IF($R47="","",M47) | K47: =IF(N47="",K46,N47) -> ELKERF5513PK | L47: =IF(O47="",L46,O47) -> 동일모자 | M47: =IF(P47="",M46,P47) -> 41736 | N47: ELKERF5513PK | O47: 동일모자 | P47: 41736 | S47: 163 | T47: 0 | V47: =IF(ISERROR(VLOOKUP(MID(W47,1,5)&MID(W47,8,5),품번정리!$A:$B,2,FALSE))=TRUE,MID(W47,1,5)&MID(W47,8,5),VLOOKUP(MID(W47,1,5)&MID(W47,8,5),품번정리!$A:$B,2,FALSE)) | W47: =IF($AG47="","",Z47) | X47: =IF($AG47="","",AA47) | Y47: =IF($AG47="","",AB47) | Z47: =IF(AC47="",Z46,AC47) -> 품번색상 | AA47: =IF(AD47="",AA46,AD47) -> 업체명 | AB47: =IF(AE47="",AB46,AE47) -> 발주일
G48: =IF(ISERROR(VLOOKUP(MID(H48,1,5)&MID(H48,8,5),품번정리!$A:$B,2,FALSE))=TRUE,MID(H48,1,5)&MID(H48,8,5),VLOOKUP(MID(H48,1,5)&MID(H48,8,5),품번정리!$A:$B,2,FALSE)) | H48: =IF($R48="","",K48) | I48: =IF($R48="","",L48) | J48: =IF($R48="","",M48) | K48: =IF(N48="",K47,N48) -> VBKTLF4503NY | L48: =IF(O48="",L47,O48) -> EVERGREEN | M48: =IF(P48="",M47,P48) -> 41737 | N48: VBKTLF4503NY | O48: EVERGREEN | P48: 41737 | S48: 528 | T48: 0 | V48: =IF(ISERROR(VLOOKUP(MID(W48,1,5)&MID(W48,8,5),품번정리!$A:$B,2,FALSE))=TRUE,MID(W48,1,5)&MID(W48,8,5),VLOOKUP(MID(W48,1,5)&MID(W48,8,5),품번정리!$A:$B,2,FALSE)) | W48: =IF($AG48="","",Z48) | X48: =IF($AG48="","",AA48) | Y48: =IF($AG48="","",AB48) | Z48: =IF(AC48="",Z47,AC48) -> 품번색상 | AA48: =IF(AD48="",AA47,AD48) -> 업체명 | AB48: =IF(AE48="",AB47,AE48) -> 발주일
G49: =IF(ISERROR(VLOOKUP(MID(H49,1,5)&MID(H49,8,5),품번정리!$A:$B,2,FALSE))=TRUE,MID(H49,1,5)&MID(H49,8,5),VLOOKUP(MID(H49,1,5)&MID(H49,8,5),품번정리!$A:$B,2,FALSE)) | H49: =IF($R49="","",K49) | I49: =IF($R49="","",L49) | J49: =IF($R49="","",M49) | K49: =IF(N49="",K48,N49) -> VBKTLF4503BU | L49: =IF(O49="",L48,O49) -> EVERGREEN | M49: =IF(P49="",M48,P49) -> 41737 | N49: VBKTLF4503BU | O49: EVERGREEN | P49: 41737 | S49: 512 | T49: 0 | V49: =IF(ISERROR(VLOOKUP(MID(W49,1,5)&MID(W49,8,5),품번정리!$A:$B,2,FALSE))=TRUE,MID(W49,1,5)&MID(W49,8,5),VLOOKUP(MID(W49,1,5)&MID(W49,8,5),품번정리!$A:$B,2,FALSE)) | W49: =IF($AG49="","",Z49) | X49: =IF($AG49="","",AA49) | Y49: =IF($AG49="","",AB49) | Z49: =IF(AC49="",Z48,AC49) -> 품번색상 | AA49: =IF(AD49="",AA48,AD49) -> 업체명 | AB49: =IF(AE49="",AB48,AE49) -> 발주일
