Workbook

Sheet 순점검
A1: 업체차수점검 | K1: 품번순서
K3: 브랜드 | N3: 사용가
E4: 데이터 | K4: SMB | N4: 사용불가
A5: 업체명 | B5: 차수 | C5: 발주일 | D5: 브랜드 | E5: 품번수 | F5: 색상수 | G5: 수량 | H5: 원가금액 | I5: TAG가금액 | K5: 의류외
A6: 성진 | B6: 2 | C6: 41374 | D6: SMB | E6: 5.5 | F6: 6 | G6: 3100 | H6: 21180000 | I6: 142300000
B7: 12 | C7: 41401 | D7: SMB | E7: 5 | F7: 5 | G7: 6000 | H7: 41458500 | I7: 264000000 | K7: REORDER | N7: MAIN (U,M,W) | Q7: MAIN (K)
B8: 23 | C8: 41435 | D8: SMB | E8: 7.5 | F8: 8 | G8: 8700 | H8: 52506494 | I8: 404300000 | K8: 품번순서 | N8: 품번순서 | Q8: 품번순서
B9: 26 | C9: 41443 | D9: SMB | E9: 3 | F9: 3 | G9: 8200 | H9: 63694150 | I9: 441800000 | K9: 1 | L9: =IF(ISERROR(VLOOKUP($K$4&$K$5&$K9,기획현황!$H:$H,1,FALSE))=TRUE,"",VLOOKUP($K$4&$K$5&$K9,기획현황!$H:$H,1,FALSE)) | N9: 1 | O9: =IF(ISERROR(VLOOKUP($K$4&$K$5&$N9,기획현황!$H:$H,1,FALSE))=TRUE,"",VLOOKUP($K$4&$K$5&$N9,기획현황!$H:$H,1,FALSE)) | Q9: =N9+500 -> 501 | R9: =IF(ISERROR(VLOOKUP($K$4&$K$5&$Q9,기획현황!$H:$H,1,FALSE))=TRUE,"",VLOOKUP($K$4&$K$5&$Q9,기획현황!$H:$H,1,FALSE))
B10: 28 | C10: 41443 | D10: SMB | E10: 3 | F10: 3 | G10: 12300 | H10: 86064935 | I10: 662700000 | K10: =K9+1 -> 2 | L10: =IF(ISERROR(VLOOKUP($K$4&$K$5&$K10,기획현황!$H:$H,1,FALSE))=TRUE,"",VLOOKUP($K$4&$K$5&$K10,기획현황!$H:$H,1,FALSE)) | N10: =N9+1 -> 2 | O10: =IF(ISERROR(VLOOKUP($K$4&$K$5&$N10,기획현황!$H:$H,1,FALSE))=TRUE,"",VLOOKUP($K$4&$K$5&$N10,기획현황!$H:$H,1,FALSE)) | Q10: =Q9+1 -> 502 | R10: =IF(ISERROR(VLOOKUP($K$4&$K$5&$Q10,기획현황!$H:$H,1,FALSE))=TRUE,"",VLOOKUP($K$4&$K$5&$Q10,기획현황!$H:$H,1,FALSE))
A11: 캡보이 | B11: 1 | C11: 41365 | D11: VBL | E11: 1 | F11: 1 | G11: 1200 | H11: 18974000 | I11: 68800000 | K11: =K10+1 -> 3 | L11: =IF(ISERROR(VLOOKUP($K$4&$K$5&$K11,기획현황!$H:$H,1,FALSE))=TRUE,"",VLOOKUP($K$4&$K$5&$K11,기획현황!$H:$H,1,FALSE)) | N11: =N10+1 -> 3 | O11: =IF(ISERROR(VLOOKUP($K$4&$K$5&$N11,기획현황!$H:$H,1,FALSE))=TRUE,"",VLOOKUP($K$4&$K$5&$N11,기획현황!$H:$H,1,FALSE)) | Q11: =Q10+1 -> 503 | R11: =IF(ISERROR(VLOOKUP($K$4&$K$5&$Q11,기획현황!$H:$H,1,FALSE))=TRUE,"",VLOOKUP($K$4&$K$5&$Q11,기획현황!$H:$H,1,FALSE))
B12: 2 | C12: 41373 | D12: VBL | E12: 0.66666667 | F12: 1 | G12: 3700 | H12: 36724000 | I12: 177100000 | K12: =K11+1 -> 4 | L12: =IF(ISERROR(VLOOKUP($K$4&$K$5&$K12,기획현황!$H:$H,1,FALSE))=TRUE,"",VLOOKUP($K$4&$K$5&$K12,기획현황!$H:$H,1,FALSE)) | N12: =N11+1 -> 4 | O12: =IF(ISERROR(VLOOKUP($K$4&$K$5&$N12,기획현황!$H:$H,1,FALSE))=TRUE,"",VLOOKUP($K$4&$K$5&$N12,기획현황!$H:$H,1,FALSE)) | Q12: =Q11+1 -> 504 | R12: =IF(ISERROR(VLOOKUP($K$4&$K$5&$Q12,기획현황!$H:$H,1,FALSE))=TRUE,"",VLOOKUP($K$4&$K$5&$Q12,기획현황!$H:$H,1,FALSE))
B13: 3 | C13: 41374 | D13: WTR | E13: 3 | F13: 3 | G13: 1300 | H13: 15326000 | I13: 69100000 | K13: =K12+1 -> 5 | L13: =IF(ISERROR(VLOOKUP($K$4&$K$5&$K13,기획현황!$H:$H,1,FALSE))=TRUE,"",VLOOKUP($K$4&$K$5&$K13,기획현황!$H:$H,1,FALSE)) | N13: =N12+1 -> 5 | O13: =IF(ISERROR(VLOOKUP($K$4&$K$5&$N13,기획현황!$H:$H,1,FALSE))=TRUE,"",VLOOKUP($K$4&$K$5&$N13,기획현황!$H:$H,1,FALSE)) | Q13: =Q12+1 -> 505 | R13: =IF(ISERROR(VLOOKUP($K$4&$K$5&$Q13,기획현황!$H:$H,1,FALSE))=TRUE,"",VLOOKUP($K$4&$K$5&$Q13,기획현황!$H:$H,1,FALSE))
B14: 4 | C14: 41380 | D14: WTR | E14: 7 | F14: 7 | G14: 3500 | H14: 54920000 | I14: 228100000 | K14: =K13+1 -> 6 | L14: =IF(ISERROR(VLOOKUP($K$4&$K$5&$K14,기획현황!$H:$H,1,FALSE))=TRUE,"",VLOOKUP($K$4&$K$5&$K14,기획현황!$H:$H,1,FALSE)) | N14: =N13+1 -> 6 | O14: =IF(ISERROR(VLOOKUP($K$4&$K$5&$N14,기획현황!$H:$H,1,FALSE))=TRUE,"",VLOOKUP($K$4&$K$5&$N14,기획현황!$H:$H,1,FALSE)) | Q14: =Q13+1 -> 506 | R14: =IF(ISERROR(VLOOKUP($K$4&$K$5&$Q14,기획현황!$H:$H,1,FALSE))=TRUE,"",VLOOKUP($K$4&$K$5&$Q14,기획현황!$H:$H,1,FALSE))
B15: 5 | C15: 41387 | D15: VBL | E15: 0.5 | F15: 0.5 | G15: 2000 | H15: 20440000 | I15: 90000000 | K15: =K14+1 -> 7 | L15: =IF(ISERROR(VLOOKUP($K$4&$K$5&$K15,기획현황!$H:$H,1,FALSE))=TRUE,"",VLOOKUP($K$4&$K$5&$K15,기획현황!$H:$H,1,FALSE)) | N15: =N14+1 -> 7 | O15: =IF(ISERROR(VLOOKUP($K$4&$K$5&$N15,기획현황!$H:$H,1,FALSE))=TRUE,"",VLOOKUP($K$4&$K$5&$N15,기획현황!$H:$H,1,FALSE)) | Q15: =Q14+1 -> 507 | R15: =IF(ISERROR(VLOOKUP($K$4&$K$5&$Q15,기획현황!$H:$H,1,FALSE))=TRUE,"",VLOOKUP($K$4&$K$5&$Q15,기획현황!$H:$H,1,FALSE))
B16: 6 | C16: 41390 | D16: VBL | E16: 0.66666667 | F16: 4 | G16: 4000 | H16: 40080000 | I16: 196000000 | K16: =K15+1 -> 8 | L16: =IF(ISERROR(VLOOKUP($K$4&$K$5&$K16,기획현황!$H:$H,1,FALSE))=TRUE,"",VLOOKUP($K$4&$K$5&$K16,기획현황!$H:$H,1,FALSE)) | N16: =N15+1 -> 8 | O16: =IF(ISERROR(VLOOKUP($K$4&$K$5&$N16,기획현황!$H:$H,1,FALSE))=TRUE,"",VLOOKUP($K$4&$K$5&$N16,기획현황!$H:$H,1,FALSE)) | Q16: =Q15+1 -> 508 | R16: =IF(ISERROR(VLOOKUP($K$4&$K$5&$Q16,기획현황!$H:$H,1,FALSE))=TRUE,"",VLOOKUP($K$4&$K$5&$Q16,기획현황!$H:$H,1,FALSE))
B17: 10 | C17: 41408 | D17: VBL | E17: 0.16666667 | F17: 0.5 | G17: 3000 | H17: 25560000 | I17: 147000000 | K17: =K16+1 -> 9 | L17: =IF(ISERROR(VLOOKUP($K$4&$K$5&$K17,기획현황!$H:$H,1,FALSE))=TRUE,"",VLOOKUP($K$4&$K$5&$K17,기획현황!$H:$H,1,FALSE)) | N17: =N16+1 -> 9 | O17: =IF(ISERROR(VLOOKUP($K$4&$K$5&$N17,기획현황!$H:$H,1,FALSE))=TRUE,"",VLOOKUP($K$4&$K$5&$N17,기획현황!$H:$H,1,FALSE)) | Q17: =Q16+1 -> 509 | R17: =IF(ISERROR(VLOOKUP($K$4&$K$5&$Q17,기획현황!$H:$H,1,FALSE))=TRUE,"",VLOOKUP($K$4&$K$5&$Q17,기획현황!$H:$H,1,FALSE))
B18: 12 | C18: 41416 | D18: VBL | E18: 0.5 | F18: 0.5 | G18: 700 | H18: 6664000 | I18: 30100000 | K18: =K17+1 -> 10 | L18: =IF(ISERROR(VLOOKUP($K$4&$K$5&$K18,기획현황!$H:$H,1,FALSE))=TRUE,"",VLOOKUP($K$4&$K$5&$K18,기획현황!$H:$H,1,FALSE)) | N18: =N17+1 -> 10 | O18: =IF(ISERROR(VLOOKUP($K$4&$K$5&$N18,기획현황!$H:$H,1,FALSE))=TRUE,"",VLOOKUP($K$4&$K$5&$N18,기획현황!$H:$H,1,FALSE)) | Q18: =Q17+1 -> 510 | R18: =IF(ISERROR(VLOOKUP($K$4&$K$5&$Q18,기획현황!$H:$H,1,FALSE))=TRUE,"",VLOOKUP($K$4&$K$5&$Q18,기획현황!$H:$H,1,FALSE))
B19: 14 | C19: 41418 | D19: VBL | E19: 2 | F19: 2 | G19: 2000 | H19: 23540000 | I19: 114000000 | K19: =K18+1 -> 11 | L19: =IF(ISERROR(VLOOKUP($K$4&$K$5&$K19,기획현황!$H:$H,1,FALSE))=TRUE,"",VLOOKUP($K$4&$K$5&$K19,기획현황!$H:$H,1,FALSE)) | N19: =N18+1 -> 11 | O19: =IF(ISERROR(VLOOKUP($K$4&$K$5&$N19,기획현황!$H:$H,1,FALSE))=TRUE,"",VLOOKUP($K$4&$K$5&$N19,기획현황!$H:$H,1,FALSE)) | Q19: =Q18+1 -> 511 | R19: =IF(ISERROR(VLOOKUP($K$4&$K$5&$Q19,기획현황!$H:$H,1,FALSE))=TRUE,"",VLOOKUP($K$4&$K$5&$Q19,기획현황!$H:$H,1,FALSE))
B20: 15 | C20: 41428 | D20: VBL | E20: 1 | F20: 1 | G20: 500 | H20: 6522727.3 | I20: 28700000 | K20: =K19+1 -> 12 | L20: =IF(ISERROR(VLOOKUP($K$4&$K$5&$K20,기획현황!$H:$H,1,FALSE))=TRUE,"",VLOOKUP($K$4&$K$5&$K20,기획현황!$H:$H,1,FALSE)) | N20: =N19+1 -> 12 | O20: =IF(ISERROR(VLOOKUP($K$4&$K$5&$N20,기획현황!$H:$H,1,FALSE))=TRUE,"",VLOOKUP($K$4&$K$5&$N20,기획현황!$H:$H,1,FALSE)) | Q20: =Q19+1 -> 512 | R20: =IF(ISERROR(VLOOKUP($K$4&$K$5&$Q20,기획현황!$H:$H,1,FALSE))=TRUE,"",VLOOKUP($K$4&$K$5&$Q20,기획현황!$H:$H,1,FALSE))
B21: 16 | C21: 41435 | D21: WTR | E21: 1 | F21: 1 | G21: 700 | H21: 7795454.5 | I21: 34300000 | K21: =K20+1 -> 13 | L21: =IF(ISERROR(VLOOKUP($K$4&$K$5&$K21,기획현황!$H:$H,1,FALSE))=TRUE,"",VLOOKUP($K$4&$K$5&$K21,기획현황!$H:$H,1,FALSE)) | N21: =N20+1 -> 13 | O21: =IF(ISERROR(VLOOKUP($K$4&$K$5&$N21,기획현황!$H:$H,1,FALSE))=TRUE,"",VLOOKUP($K$4&$K$5&$N21,기획현황!$H:$H,1,FALSE)) | Q21: =Q20+1 -> 513 | R21: =IF(ISERROR(VLOOKUP($K$4&$K$5&$Q21,기획현황!$H:$H,1,FALSE))=TRUE,"",VLOOKUP($K$4&$K$5&$Q21,기획현황!$H:$H,1,FALSE))
B22: 17 | C22: 41435 | D22: VBL | E22: 1 | F22: 1 | G22: 1000 | H22: 13409091 | I22: 59000000 | K22: =K21+1 -> 14 | L22: =IF(ISERROR(VLOOKUP($K$4&$K$5&$K22,기획현황!$H:$H,1,FALSE))=TRUE,"",VLOOKUP($K$4&$K$5&$K22,기획현황!$H:$H,1,FALSE)) | N22: =N21+1 -> 14 | O22: =IF(ISERROR(VLOOKUP($K$4&$K$5&$N22,기획현황!$H:$H,1,FALSE))=TRUE,"",VLOOKUP($K$4&$K$5&$N22,기획현황!$H:$H,1,FALSE)) | Q22: =Q21+1 -> 514 | R22: =IF(ISERROR(VLOOKUP($K$4&$K$5&$Q22,기획현황!$H:$H,1,FALSE))=TRUE,"",VLOOKUP($K$4&$K$5&$Q22,기획현황!$H:$H,1,FALSE))
B23: 21 | C23: 41443 | D23: VBL | E23: 0.5 | F23: 0.5 | G23: 3000 | H23: 30681818 | I23: 135000000 | K23: =K22+1 -> 15 | L23: =IF(ISERROR(VLOOKUP($K$4&$K$5&$K23,기획현황!$H:$H,1,FALSE))=TRUE,"",VLOOKUP($K$4&$K$5&$K23,기획현황!$H:$H,1,FALSE)) | N23: =N22+1 -> 15 | O23: =IF(ISERROR(VLOOKUP($K$4&$K$5&$N23,기획현황!$H:$H,1,FALSE))=TRUE,"",VLOOKUP($K$4&$K$5&$N23,기획현황!$H:$H,1,FALSE)) | Q23: =Q22+1 -> 515 | R23: =IF(ISERROR(VLOOKUP($K$4&$K$5&$Q23,기획현황!$H:$H,1,FALSE))=TRUE,"",VLOOKUP($K$4&$K$5&$Q23,기획현황!$H:$H,1,FALSE))
A24: FOREMOST | B24: 4 | C24: 41360 | D24: WTR | E24: 1 | F24: 1 | G24: 800 | H24: 12774622 | I24: 63200000 | K24: =K23+1 -> 16 | L24: =IF(ISERROR(VLOOKUP($K$4&$K$5&$K24,기획현황!$H:$H,1,FALSE))=TRUE,"",VLOOKUP($K$4&$K$5&$K24,기획현황!$H:$H,1,FALSE)) | N24: =N23+1 -> 16 | O24: =IF(ISERROR(VLOOKUP($K$4&$K$5&$N24,기획현황!$H:$H,1,FALSE))=TRUE,"",VLOOKUP($K$4&$K$5&$N24,기획현황!$H:$H,1,FALSE)) | Q24: =Q23+1 -> 516 | R24: =IF(ISERROR(VLOOKUP($K$4&$K$5&$Q24,기획현황!$H:$H,1,FALSE))=TRUE,"",VLOOKUP($K$4&$K$5&$Q24,기획현황!$H:$H,1,FALSE))
B25: 6 | C25: 41365 | D25: VBL | E25: 4 | F25: 4 | G25: 2300 | H25: 10769858 | I25: 123500000 | K25: =K24+1 -> 17 | L25: =IF(ISERROR(VLOOKUP($K$4&$K$5&$K25,기획현황!$H:$H,1,FALSE))=TRUE,"",VLOOKUP($K$4&$K$5&$K25,기획현황!$H:$H,1,FALSE)) | N25: =N24+1 -> 17 | O25: =IF(ISERROR(VLOOKUP($K$4&$K$5&$N25,기획현황!$H:$H,1,FALSE))=TRUE,"",VLOOKUP($K$4&$K$5&$N25,기획현황!$H:$H,1,FALSE)) | Q25: =Q24+1 -> 517 | R25: =IF(ISERROR(VLOOKUP($K$4&$K$5&$Q25,기획현황!$H:$H,1,FALSE))=TRUE,"",VLOOKUP($K$4&$K$5&$Q25,기획현황!$H:$H,1,FALSE))
B26: 10 | C26: 41380 | D26: WTR | E26: 4 | F26: 4 | G26: 3000 | H26: 21026784 | I26: 165000000 | K26: =K25+1 -> 18 | L26: =IF(ISERROR(VLOOKUP($K$4&$K$5&$K26,기획현황!$H:$H,1,FALSE))=TRUE,"",VLOOKUP($K$4&$K$5&$K26,기획현황!$H:$H,1,FALSE)) | N26: =N25+1 -> 18 | O26: =IF(ISERROR(VLOOKUP($K$4&$K$5&$N26,기획현황!$H:$H,1,FALSE))=TRUE,"",VLOOKUP($K$4&$K$5&$N26,기획현황!$H:$H,1,FALSE)) | Q26: =Q25+1 -> 518 | R26: =IF(ISERROR(VLOOKUP($K$4&$K$5&$Q26,기획현황!$H:$H,1,FALSE))=TRUE,"",VLOOKUP($K$4&$K$5&$Q26,기획현황!$H:$H,1,FALSE))
B27: 11 | C27: 41380 | D27: WTR | E27: 1 | F27: 1 | G27: 400 | H27: 5948280 | I27: 31600000 | K27: =K26+1 -> 19 | L27: =IF(ISERROR(VLOOKUP($K$4&$K$5&$K27,기획현황!$H:$H,1,FALSE))=TRUE,"",VLOOKUP($K$4&$K$5&$K27,기획현황!$H:$H,1,FALSE)) | N27: =N26+1 -> 19 | O27: =IF(ISERROR(VLOOKUP($K$4&$K$5&$N27,기획현황!$H:$H,1,FALSE))=TRUE,"",VLOOKUP($K$4&$K$5&$N27,기획현황!$H:$H,1,FALSE)) | Q27: =Q26+1 -> 519 | R27: =IF(ISERROR(VLOOKUP($K$4&$K$5&$Q27,기획현황!$H:$H,1,FALSE))=TRUE,"",VLOOKUP($K$4&$K$5&$Q27,기획현황!$H:$H,1,FALSE))
B28: 12 | C28: 41387 | D28: VBL | E28: 0.5 | F28: 1 | G28: 6000 | H28: 26534980 | I28: 330000000 | K28: =K27+1 -> 20 | L28: =IF(ISERROR(VLOOKUP($K$4&$K$5&$K28,기획현황!$H:$H,1,FALSE))=TRUE,"",VLOOKUP($K$4&$K$5&$K28,기획현황!$H:$H,1,FALSE)) | N28: =N27+1 -> 20 | O28: =IF(ISERROR(VLOOKUP($K$4&$K$5&$N28,기획현황!$H:$H,1,FALSE))=TRUE,"",VLOOKUP($K$4&$K$5&$N28,기획현황!$H:$H,1,FALSE)) | Q28: =Q27+1 -> 520 | R28: =IF(ISERROR(VLOOKUP($K$4&$K$5&$Q28,기획현황!$H:$H,1,FALSE))=TRUE,"",VLOOKUP($K$4&$K$5&$Q28,기획현황!$H:$H,1,FALSE))
B29: 19 | C29: 41402 | D29: VBL | E29: 8 | F29: 8 | G29: 5300 | H29: 26331574 | I29: 273900000 | K29: =K28+1 -> 21 | L29: =IF(ISERROR(VLOOKUP($K$4&$K$5&$K29,기획현황!$H:$H,1,FALSE))=TRUE,"",VLOOKUP($K$4&$K$5&$K29,기획현황!$H:$H,1,FALSE)) | N29: =N28+1 -> 21 | O29: =IF(ISERROR(VLOOKUP($K$4&$K$5&$N29,기획현황!$H:$H,1,FALSE))=TRUE,"",VLOOKUP($K$4&$K$5&$N29,기획현황!$H:$H,1,FALSE)) | Q29: =Q28+1 -> 521 | R29: =IF(ISERROR(VLOOKUP($K$4&$K$5&$Q29,기획현황!$H:$H,1,FALSE))=TRUE,"",VLOOKUP($K$4&$K$5&$Q29,기획현황!$H:$H,1,FALSE))
B30: 23 | C30: 41402 | D30: VBL | E30: 3 | F30: 3 | G30: 1900 | H30: 9638362 | I30: 101500000 | K30: =K29+1 -> 22 | L30: =IF(ISERROR(VLOOKUP($K$4&$K$5&$K30,기획현황!$H:$H,1,FALSE))=TRUE,"",VLOOKUP($K$4&$K$5&$K30,기획현황!$H:$H,1,FALSE)) | N30: =N29+1 -> 22 | O30: =IF(ISERROR(VLOOKUP($K$4&$K$5&$N30,기획현황!$H:$H,1,FALSE))=TRUE,"",VLOOKUP($K$4&$K$5&$N30,기획현황!$H:$H,1,FALSE)) | Q30: =Q29+1 -> 522 | R30: =IF(ISERROR(VLOOKUP($K$4&$K$5&$Q30,기획현황!$H:$H,1,FALSE))=TRUE,"",VLOOKUP($K$4&$K$5&$Q30,기획현황!$H:$H,1,FALSE))
B31: 24 | C31: 41402 | D31: VBL | E31: 2.5 | F31: 2.5 | G31: 1550 | H31: 8759104 | I31: 94050000 | K31: =K30+1 -> 23 | L31: =IF(ISERROR(VLOOKUP($K$4&$K$5&$K31,기획현황!$H:$H,1,FALSE))=TRUE,"",VLOOKUP($K$4&$K$5&$K31,기획현황!$H:$H,1,FALSE)) | N31: =N30+1 -> 23 | O31: =IF(ISERROR(VLOOKUP($K$4&$K$5&$N31,기획현황!$H:$H,1,FALSE))=TRUE,"",VLOOKUP($K$4&$K$5&$N31,기획현황!$H:$H,1,FALSE)) | Q31: =Q30+1 -> 523 | R31: =IF(ISERROR(VLOOKUP($K$4&$K$5&$Q31,기획현황!$H:$H,1,FALSE))=TRUE,"",VLOOKUP($K$4&$K$5&$Q31,기획현황!$H:$H,1,FALSE))
B32: 27 | C32: 41409 | D32: VBL | E32: 2 | F32: 2 | G32: 2500 | H32: 9374315 | I32: 137500000 | K32: =K31+1 -> 24 | L32: =IF(ISERROR(VLOOKUP($K$4&$K$5&$K32,기획현황!$H:$H,1,FALSE))=TRUE,"",VLOOKUP($K$4&$K$5&$K32,기획현황!$H:$H,1,FALSE)) | N32: =N31+1 -> 24 | O32: =IF(ISERROR(VLOOKUP($K$4&$K$5&$N32,기획현황!$H:$H,1,FALSE))=TRUE,"",VLOOKUP($K$4&$K$5&$N32,기획현황!$H:$H,1,FALSE)) | Q32: =Q31+1 -> 524 | R32: =IF(ISERROR(VLOOKUP($K$4&$K$5&$Q32,기획현황!$H:$H,1,FALSE))=TRUE,"",VLOOKUP($K$4&$K$5&$Q32,기획현황!$H:$H,1,FALSE))
B33: 40 | C33: 41428 | D33: VBL | E33: 1.5 | F33: 1.5 | G33: 1100 | H33: 9530303 | I33: 62900000 | K33: =K32+1 -> 25 | L33: =IF(ISERROR(VLOOKUP($K$4&$K$5&$K33,기획현황!$H:$H,1,FALSE))=TRUE,"",VLOOKUP($K$4&$K$5&$K33,기획현황!$H:$H,1,FALSE)) | N33: =N32+1 -> 25 | O33: =IF(ISERROR(VLOOKUP($K$4&$K$5&$N33,기획현황!$H:$H,1,FALSE))=TRUE,"",VLOOKUP($K$4&$K$5&$N33,기획현황!$H:$H,1,FALSE)) | Q33: =Q32+1 -> 525 | R33: =IF(ISERROR(VLOOKUP($K$4&$K$5&$Q33,기획현황!$H:$H,1,FALSE))=TRUE,"",VLOOKUP($K$4&$K$5&$Q33,기획현황!$H:$H,1,FALSE))
B34: 48 | C34: 41443 | D34: VBL | E34: 0.5 | F34: 1 | G34: 9000 | H34: 75000000 | I34: 495000000 | K34: =K33+1 -> 26 | L34: =IF(ISERROR(VLOOKUP($K$4&$K$5&$K34,기획현황!$H:$H,1,FALSE))=TRUE,"",VLOOKUP($K$4&$K$5&$K34,기획현황!$H:$H,1,FALSE)) | N34: =N33+1 -> 26 | O34: =IF(ISERROR(VLOOKUP($K$4&$K$5&$N34,기획현황!$H:$H,1,FALSE))=TRUE,"",VLOOKUP($K$4&$K$5&$N34,기획현황!$H:$H,1,FALSE)) | Q34: =Q33+1 -> 526 | R34: =IF(ISERROR(VLOOKUP($K$4&$K$5&$Q34,기획현황!$H:$H,1,FALSE))=TRUE,"",VLOOKUP($K$4&$K$5&$Q34,기획현황!$H:$H,1,FALSE))
B35: 49 | C35: 0 | D35: SMB | E35: 1 | F35: 2 | G35: 1400 | H35: 0 | I35: 0 | K35: =K34+1 -> 27 | L35: =IF(ISERROR(VLOOKUP($K$4&$K$5&$K35,기획현황!$H:$H,1,FALSE))=TRUE,"",VLOOKUP($K$4&$K$5&$K35,기획현황!$H:$H,1,FALSE)) | N35: =N34+1 -> 27 | O35: =IF(ISERROR(VLOOKUP($K$4&$K$5&$N35,기획현황!$H:$H,1,FALSE))=TRUE,"",VLOOKUP($K$4&$K$5&$N35,기획현황!$H:$H,1,FALSE)) | Q35: =Q34+1 -> 527 | R35: =IF(ISERROR(VLOOKUP($K$4&$K$5&$Q35,기획현황!$H:$H,1,FALSE))=TRUE,"",VLOOKUP($K$4&$K$5&$Q35,기획현황!$H:$H,1,FALSE))
A36: 총합계 | E36: 72 | F36: 79 | G36: 100150 | H36: 7.8122935e+08 | I36: 5170450000 | K36: =K35+1 -> 28 | L36: =IF(ISERROR(VLOOKUP($K$4&$K$5&$K36,기획현황!$H:$H,1,FALSE))=TRUE,"",VLOOKUP($K$4&$K$5&$K36,기획현황!$H:$H,1,FALSE)) | N36: =N35+1 -> 28 | O36: =IF(ISERROR(VLOOKUP($K$4&$K$5&$N36,기획현황!$H:$H,1,FALSE))=TRUE,"",VLOOKUP($K$4&$K$5&$N36,기획현황!$H:$H,1,FALSE)) | Q36: =Q35+1 -> 528 | R36: =IF(ISERROR(VLOOKUP($K$4&$K$5&$Q36,기획현황!$H:$H,1,FALSE))=TRUE,"",VLOOKUP($K$4&$K$5&$Q36,기획현황!$H:$H,1,FALSE))
K37: =K36+1 -> 29 | L37: =IF(ISERROR(VLOOKUP($K$4&$K$5&$K37,기획현황!$H:$H,1,FALSE))=TRUE,"",VLOOKUP($K$4&$K$5&$K37,기획현황!$H:$H,1,FALSE)) | N37: =N36+1 -> 29 | O37: =IF(ISERROR(VLOOKUP($K$4&$K$5&$N37,기획현황!$H:$H,1,FALSE))=TRUE,"",VLOOKUP($K$4&$K$5&$N37,기획현황!$H:$H,1,FALSE)) | Q37: =Q36+1 -> 529 | R37: =IF(ISERROR(VLOOKUP($K$4&$K$5&$Q37,기획현황!$H:$H,1,FALSE))=TRUE,"",VLOOKUP($K$4&$K$5&$Q37,기획현황!$H:$H,1,FALSE))
K38: =K37+1 -> 30 | L38: =IF(ISERROR(VLOOKUP($K$4&$K$5&$K38,기획현황!$H:$H,1,FALSE))=TRUE,"",VLOOKUP($K$4&$K$5&$K38,기획현황!$H:$H,1,FALSE)) | N38: =N37+1 -> 30 | O38: =IF(ISERROR(VLOOKUP($K$4&$K$5&$N38,기획현황!$H:$H,1,FALSE))=TRUE,"",VLOOKUP($K$4&$K$5&$N38,기획현황!$H:$H,1,FALSE)) | Q38: =Q37+1 -> 530 | R38: =IF(ISERROR(VLOOKUP($K$4&$K$5&$Q38,기획현황!$H:$H,1,FALSE))=TRUE,"",VLOOKUP($K$4&$K$5&$Q38,기획현황!$H:$H,1,FALSE))
K39: =K38+1 -> 31 | L39: =IF(ISERROR(VLOOKUP($K$4&$K$5&$K39,기획현황!$H:$H,1,FALSE))=TRUE,"",VLOOKUP($K$4&$K$5&$K39,기획현황!$H:$H,1,FALSE)) | N39: =N38+1 -> 31 | O39: =IF(ISERROR(VLOOKUP($K$4&$K$5&$N39,기획현황!$H:$H,1,FALSE))=TRUE,"",VLOOKUP($K$4&$K$5&$N39,기획현황!$H:$H,1,FALSE)) | Q39: =Q38+1 -> 531 | R39: =IF(ISERROR(VLOOKUP($K$4&$K$5&$Q39,기획현황!$H:$H,1,FALSE))=TRUE,"",VLOOKUP($K$4&$K$5&$Q39,기획현황!$H:$H,1,FALSE))
K40: =K39+1 -> 32 | L40: =IF(ISERROR(VLOOKUP($K$4&$K$5&$K40,기획현황!$H:$H,1,FALSE))=TRUE,"",VLOOKUP($K$4&$K$5&$K40,기획현황!$H:$H,1,FALSE)) | N40: =N39+1 -> 32 | O40: =IF(ISERROR(VLOOKUP($K$4&$K$5&$N40,기획현황!$H:$H,1,FALSE))=TRUE,"",VLOOKUP($K$4&$K$5&$N40,기획현황!$H:$H,1,FALSE)) | Q40: =Q39+1 -> 532 | R40: =IF(ISERROR(VLOOKUP($K$4&$K$5&$Q40,기획현황!$H:$H,1,FALSE))=TRUE,"",VLOOKUP($K$4&$K$5&$Q40,기획현황!$H:$H,1,FALSE))
K41: =K40+1 -> 33 | L41: =IF(ISERROR(VLOOKUP($K$4&$K$5&$K41,기획현황!$H:$H,1,FALSE))=TRUE,"",VLOOKUP($K$4&$K$5&$K41,기획현황!$H:$H,1,FALSE)) | N41: =N40+1 -> 33 | O41: =IF(ISERROR(VLOOKUP($K$4&$K$5&$N41,기획현황!$H:$H,1,FALSE))=TRUE,"",VLOOKUP($K$4&$K$5&$N41,기획현황!$H:$H,1,FALSE)) | Q41: =Q40+1 -> 533 | R41: =IF(ISERROR(VLOOKUP($K$4&$K$5&$Q41,기획현황!$H:$H,1,FALSE))=TRUE,"",VLOOKUP($K$4&$K$5&$Q41,기획현황!$H:$H,1,FALSE))
...

Sheet 기획현황
C1: PO ISSUE | F1: 1 | G1: =F1+1 -> 2 | H1: =G1+1 -> 3 | I1: =H1+1 -> 4 | J1: =I1+1 -> 5 | K1: =J1+1 -> 6 | L1: =K1+1 -> 7 | M1: =L1+1 -> 8 | N1: =M1+1 -> 9 | ... BR1: =BQ1+1 -> 65
K2: 2014 | L2: FW | M2: 기획현황 (유란) | AT2: 180 | AU2: 20 | BX2: DATA UPLOAD FOR E-BIZ | CS2: TAG ISSUE | DG2: **PRODUCTION SCHEDULE | EL2: ** 결재 및 가격사정
AO3: 환율 | AS3: 관세 | AW3: 제비용 | AX3: *인도네시아, 방글라데시 무관세 적용
AO4: KRW | AP4: EUR | AQ4: USD | AR4: JPY | AS4: 모자 | AT4: 의류 | AU4: 가방 | AV4: ACC | AW4: 0.05 | BN4: SHORTAGE | DV4: =TODAY() -> 42520
AO5: 1 | AP5: 1500 | AQ5: 1100 | AR5: 13 | AS5: 0.08 | AT5: 0.13 | AU5: 0.056 | AV5: 0.08 | BB5: =TODAY() -> 42520 | BG5: 건별계약서내용과 동일
K6: * 업체,업체차수,브랜드 정렬 | AZ6: 월,수요일 | BN6: 0.1
BX7: 컬렉션 | BY7: 시즌 | BZ7: 소재 | CA7: 품목 | CB7: 성별 | CC7: 국가 | CD7: 원산지 코드 | CE7: STYLE | CF7: 순번 | CG7: STYLE명 | CH7: COL | CI7: S_TYPE | CJ7: SIZE | CK7: 수량 | CL7: FOB | CM7: TAG가 | CN7: 원가 | CO7: 자재원가 | CP7: 구분
K8: 이미지 | L8: 브랜드 | M8: 브랜드명 | N8: 년도 | O8: 시즌 | P8: 품목 | Q8: 품목명 | R8: 성별 | S8: 순번 | T8: 순번 | U8: 품번 | V8: 품번수 | W8: 품명(=샘플명) | X8: 색상 | Y8: 색상명 | Z8: 품번색상 | AA8: 품번오더차수 | AB8: 색상수 | AC8: 원자재 혼용율 | AD8: 사이즈타입 | AE8: 사이즈 | AF8: 수량 | AG8: 업체 | AM8: TAG가 | AO8: 원가(-VAT) | AX8: 일정 | BG8: 원가 확정여부 | BH8: 입고일 확정여부 | BI8: 입고수량점검 | BO8: TOTAL | BX8: 브랜드 | BY8: 시즌 | BZ8: 분류 | CA8: 품목 | CB8: 성별 | CC8: 국가 | CD8: 샘플명 | CE8: 품번 | CF8: 순번 | CG8: 품번명 | CH8: 색상 | CI8: 사이즈타입 | CJ8: 사이즈 | CK8: 수량 | CL8: FOB($) | CM8: TAG가(\) | CN8: 원가(\,-VAT) | CO8: 자재원가(\,-VAT) | CP8: 수입1, 내수2 | CQ8: 발주번호 | CS8: NO. | CT8: 품번 (HAT'S ON CODE) | CU8: 명칭(상단) | CV8: 명칭(하단) | CW8: 명칭 (색상/사이즈) | CX8: 브랜드 | CY8: 순번 | CZ8: 수량 | DA8: TAG가(\) | DB8: 색상 | DC8: 사이즈 | DD8: 자율안전인증번호 | DE8: 최초순번 | DG8: PRODUCTION SCHEDULE | DZ8: 비고 | EF8: 순번 | EW8: 비고
AG9: 업체명 | AH9: 차수 | AI9: 차수 | AJ9: 분류 | AK9: 국가 | AL9: 수입/내수 | AN9: 확정일 | AO9: 목표 | AP9: 조정 | AQ9: 차이 | AR9: 공급자재 | AV9: 해외(FOB, USD, JPY) | AW9: 국내(KRW) | AX9: 발주일 | AY9: 선적일 | AZ9: 납기일 | BO9: 수량 | BP9: 원가금액 (-VAT,백만원) | BQ9: TAG가금액 (백만원) | BR9: MU | DG9: PO 발송일 | DH9: 메인작지 수령 목표일 | DI9: 메인작지 수령일 | DJ9: 메인작지 발송일 | DK9: 건별계약서 작성(원가, 납기) | DL9: 중국원단사용유무 | DN9: 원자재 발주일 | DO9: 부자재 발주일 | DP9: 원부자재 발송 목표일 | DQ9: 원자재 발송일 | DR9: 부자재 발송일 | DS9: 최초상품대금 결재상신일 | DT9: PPS 수령일 | DU9: PPS 컨펌일 | DV9: 가격택 발송일 | DW9: INSPECTION일 | DX9: SPS 수령일 | DY9: 입고 완료여부 | EF9: 0 | EL9: 선급금 요청 | EM9: 선급금 실송금일 | EN9: 선급금 실송금액 | EO9: 중도금 요청 | EP9: 중도금 실송금일 | EQ9: 중도금 실송금액 | ER9: 잔금 요청 | ES9: 잔금 실송금일 | ET9: 잔금 실송금액 | EU9: 물류수량 확정일 | EV9: 가격사정
AR10: 원자재 | AS10: 부자재 | AT10: 기타 | AU10: 계 | AZ10: 목표 | BA10: 계약 | BB10: 1차입고 | BC10: 2차입고 | BD10: 3차입고 | BE10: 4차입고 | BF10: 5차입고 | BI10: 1차입고 | BJ10: 2차입고 | BK10: 3차입고 | BL10: 4차입고 | BM10: 5차입고 | BN10: 미입고수량 | DE10: 최초순번 | DL10: 총가지수 | DM10: 중국가지수 | EF10: 5 | EI10: 품번수계산
V11: =SUM(V$13:V62542)-SUMIF($I:$I,"TTL",V:V) -> 52 | AB11: =SUM(AB$13:AB62542)-SUMIF($I:$I,"TTL",AB:AB) -> 58 | AF11: =SUM(AF$13:AF62542)-SUMIF($I:$I,"TTL",AF:AF) -> 16910 | BI11: =SUM(BI$13:BI62546)-SUMIF($I:$I,"TTL",BI:BI) -> 14954 | BJ11: =SUM(BJ$13:BJ62546)-SUMIF($I:$I,"TTL",BJ:BJ) -> 1675 | BK11: =SUM(BK$13:BK62546)-SUMIF($I:$I,"TTL",BK:BK) -> 108 | BL11: =SUM(BL$13:BL62546)-SUMIF($I:$I,"TTL",BL:BL) -> 0 | BM11: =SUM(BM$13:BM62546)-SUMIF($I:$I,"TTL",BM:BM) -> 0 | BN11: =SUM(BN$13:BN62546)-SUMIF($I:$I,"TTL",BN:BN) -> 0 | BO11: =SUM(BO$13:BO62542)-SUMIF($I:$I,"TTL",BO:BO) -> 16910 | BP11: =SUM(BP$13:BP62542)-SUMIF($I:$I,"TTL",BP:BP) -> 1.5070177e+08 | BQ11: =SUM(BQ$13:BQ62542)-SUMIF($I:$I,"TTL",BQ:BQ) -> 833390000 | BR11: =IF(ISERROR($BQ11/($BP11*1.1))=TRUE,0,$BQ11/($BP11*1.1)) -> 5.0273284 | BV11: 품번/색상/사이즈/수량/업체/차수/국가 | DH11: 90 | DL11: 숫자로 표기 | DM11: 숫자로 표기 | DN11: '없음'표기 | DO11: '없음'표기 | DP11: 60 | DQ11: 최종일표기 | DR11: 최종일표기 | EC11: 품번색상/발주일 | ED11: 품번색상사이즈 | EE11: 리오더(NEW) | EF11: 리오더(RUNNING) | EG11: 품번차수 | EI11: 품번 | EJ11: 품번색상
A12: 구분 | B12: 브랜드품목 | C12: 브랜드/업체/차수 | D12: 브랜드/업체/차수/품번색상 | E12: 순서 | F12: 브랜드/업체/차수/순서 | G12: 브랜드/업체/차수/순서/품번색상/사이즈 | H12: 브랜드/순번 | I12: 브랜드 | J12: 공란 | K12: 이미지 | L12: 브랜드 | M12: 브랜드명 | N12: 년도 | O12: 시즌 | P12: 품목 | Q12: 품목명 | R12: 성별 | S12: 순번 | T12: 순번2 | U12: 품번 | V12: 품번수 | W12: 품명(=샘플명) | X12: 색상 | Y12: 색상명 | Z12: 품번색상 | AA12: 오더차수 | AB12: 색상수 | AC12: 혼용율 | AD12: 사이즈타입 | AE12: 사이즈 | AF12: 수량 | AG12: 업체명 | AH12: 차수 | AI12: 차수2 | AJ12: 분류 | AK12: 국가 | AL12: 수입/내수 | AM12: TAG가목표 | AN12: TAG가조정 | AO12: 원가목표 | AP12: 원가조정 | AQ12: 원가차이 | AR12: 공급원자재 | AS12: 공급부자재 | AT12: 공급기타 | AU12: 공급계 | AV12: 해외(FOB, USD, JPY) | AW12: 국내(KRW) | AX12: 발주일 | AY12: 선적일 | AZ12: 목표납기일 | BA12: 계약납기일 | BB12: 1차입고일 | BC12: 2차입고일 | BD12: 3차입고일 | BE12: 4차입고일 | BF12: 5차입고일 | BG12: 확정여부 | BH12: 확정여부 | BI12: 1차입고수량 | BJ12: 2차입고수량 | BK12: 3차입고수량 | BL12: 3차입고수량 | BM12: 3차입고수량 | BN12: 차이수량 | BO12: TOTAL수량 | BP12: TOTAL원가금액 | BQ12: TOTALTAG가금액 | BR12: MU
A13: =IF(OR($I13="TTL",$I13=""),"",IF(ISERROR(VLOOKUP($B13,CODE!$D:$G,CODE!$F$1-2,FALSE))=TRUE,"전략",VLOOKUP($B13,CODE!$D:$G,CODE!$F$1-2,FALSE))) -> F-HAT | B13: =IF(OR($I13="TTL",$I13=""),"",IF(VLOOKUP($P13,CODE!$K:$O,CODE!$O$1,FALSE)="",$I13,$I13&"-"&VLOOKUP($P13,CODE!$K:$O,CODE!$O$1,FALSE))) -> JOK | C13: =IF($I13="TTL","",I13&"-"&$AG13&"-"&$AI13) -> JOK-FOREMOST-02 | D13: =$C13&$Z13 -> JOK-FOREMOST-02JOKEBF5803BL | E13: =IF($I13="TTL",0,IF(ISERROR(IF($Z12=$Z13,$E12,$E12+1))=TRUE,1,IF($Z12=$Z13,$E12,$E12+1))) -> 1 | F13: =$C13&$E13 -> JOK-FOREMOST-021 | G13: =$F13&"-"&$U13&$Y13&$AE13 -> JOK-FOREMOST-021-JOKEBF5803BLUEFRE | H13: =IF(ISERROR(I13&VLOOKUP(P13,CODE!$K:$N,CODE!$N$1,FALSE)&S13)=TRUE,0,I13&VLOOKUP(P13,CODE!$K:$N,CODE!$N$1,FALSE)&S13) -> JOK의류외803 | I13: =IF(ISERROR(SEARCH("TTL",$K13))=TRUE,IF($L13="","",VLOOKUP($L13,CODE!$B:$G,CODE!$D$1,FALSE)),"TTL") -> JOK | J13: =MID(W13,1,6) -> 13FW J | L13: JOK | M13: =IF(OR($I13="TTL",$L13=""),"",VLOOKUP($L13,CODE!$B:$D,CODE!$C$1,FALSE)) -> JOIE BETE KIDS | N13: =IF(OR($I13="TTL",$L13=""),"",VLOOKUP($K$2,CODE!$S:$T,CODE!$T$1-1,FALSE)) -> F | O13: 5 | P13: EB | Q13: =IF(OR($I13="TTL",$P13=""),"",VLOOKUP($P13,CODE!$K:$M,CODE!$L$1,FALSE)) -> EARFLAP BEANIE | R13: K | S13: 803 | T13: =IF(OR($I13="TTL",$S13=""),"",IF($S13<10,"00"&$S13,IF($S13<100,"0"&$S13,$S13))) -> 803 | U13: =IF($I13="TTL","",$L13&$P13&$N13&$O13&$T13) -> JOKEBF5803 | V13: =IF($I13="TTL",SUMIF($C:$C,MID($K13,1,SEARCH("TTL",$K13)-2),$V:$V),IF($EI13="",0,1/COUNTIF($EI:$EI,$EI13))) -> 1 | W13: 13FW JOIE BETE_03_BL_KIDS | X13: =IF($Y13="","",VLOOKUP($Y13,CODE!$AE:$AF,CODE!$AF$1-1,FALSE)) -> BL | Y13: BLUE | Z13: =$U13&$X13 -> JOKEBF5803BL | AA13: =VLOOKUP($Z13&$AX13,$EC:$EG,5,FALSE) -> R1 | AB13: =IF($I13="TTL",SUMIF($C:$C,MID($K13,1,SEARCH("TTL",$K13)-2),$AB:$AB),IF($EJ13="",0,1/COUNTIF($EJ:$EJ,$EJ13))) -> 1 | AC13: 0 | AD13: 1 | AE13: FRE | AF13: 250 | AG13: FOREMOST | AH13: 2 | AI13: =IF($AH13=0,"",IF($AH13<10,"0"&$AH13,$AH13)) -> 02 | AJ13: M | AK13: CN | AL13: =IF($AK13=0,"",IF($AK13="KR",2,1)) -> 1 | AM13: =IF(ISERROR(VLOOKUP($F13,[1]기획현황취합!$A$1:$E$64926,[1]기획현황취합!$B$1,FALSE))=TRUE,0,VLOOKUP($F13,[1]기획현황취합!$A$1:$E$64926,[1]기획현황취합!$B$1,FALSE)) -> 55000 | AN13: =IF(ISERROR(VLOOKUP($F13,[1]기획현황취합!$A$1:$E$64926,[1]기획현황취합!$C$1,FALSE))=TRUE,0,VLOOKUP($F13,[1]기획현황취합!$A$1:$E$64926,[1]기획현황취합!$C$1,FALSE)) -> 41710 | AO13: =IF(ISERROR(($AM13/1.1)/VLOOKUP($AG13,'TARGET MU'!$A:$D,'TARGET MU'!$D$1,FALSE))=TRUE,0,($AM13/1.1)/VLOOKUP($AG13,'TARGET MU'!$A:$D,'TARGET MU'!$D$1,FALSE)) -> 8333.3333 | AP13: =IF(OR(AF13=0,AND(AV13=0,AW13=0)),0,IF(AG13="캡보이2",AV13*$AQ$5+AU13,IF(OR(AK13="IN",AK13="BG",AK13="VT",AK13="CB"),$AU13+(($AV13*(1+$AW$4))*(HLOOKUP(VLOOKUP(AG13,'TARGET MU'!$A:$P,'TARGET MU'!$J$1,FALSE),$AO$4:$AR$5,2,FALSE)))+$AW13,$AU13+((($AV13*(1+$AW$4))*(1+HLOOKUP(VLOOKUP($P13,CODE!$K:$P,CODE!$P$1,FALSE),$AS$4:$AV$5,2,FALSE)))*(HLOOKUP(VLOOKUP(AG13,'TARGET MU'!$A:$P,'TARGET MU'!$J$1,FALSE),$AO$4:$AR$5,2,FALSE)))+$AW13))) -> 8989.43 | AQ13: =AP13-AO13 -> 656.09667 | AS13: 300 | AT13: 20 | AU13: =SUM(AR13:AT13) -> 320 | AV13: 6.95 | AX13: =IF(ISERROR(VLOOKUP($F13,[1]기획현황취합!$A$1:$E$64926,[1]기획현황취합!$D$1,FALSE))=TRUE,0,VLOOKUP($F13,[1]기획현황취합!$A$1:$E$64926,[1]기획현황취합!$D$1,FALSE)) -> 41711 | AZ13: =IF(ISERROR(VLOOKUP($F13,[1]기획현황취합!$A$1:$E$64926,[1]기획현황취합!$E$1,FALSE))=TRUE,0,VLOOKUP($F13,[1]기획현황취합!$A$1:$E$64926,[1]기획현황취합!$E$1,FALSE)) -> 41858 | BA13: 41858 | BB13: 41887 | BG13: 확정 | BH13: 확정 | BI13: =IF($I13="TTL",SUMIF($C:$C,MID($K13,1,SEARCH("TTL",$K13)-2),$BI:$BI),SUMIF(실입고현황!$A:$A,BB13&VLOOKUP($AG13,'TARGET MU'!$A:$D,'TARGET MU'!$B$1,FALSE)&$Z13&" "&$AE13,실입고현황!$C:$C)) -> 250 | BJ13: =IF($I13="TTL",SUMIF($C:$C,MID($K13,1,SEARCH("TTL",$K13)-2),$BJ:$BJ),SUMIF(실입고현황!$A:$A,BC13&VLOOKUP($AG13,'TARGET MU'!$A:$D,'TARGET MU'!$B$1,FALSE)&$Z13&" "&$AE13,실입고현황!$C:$C)) -> 0 | BK13: =IF($I13="TTL",SUMIF($C:$C,MID($K13,1,SEARCH("TTL",$K13)-2),$BK:$BK),SUMIF(실입고현황!$A:$A,BD13&VLOOKUP($AG13,'TARGET MU'!$A:$D,'TARGET MU'!$B$1,FALSE)&$Z13&" "&$AE13,실입고현황!$C:$C)) -> 0 | BL13: =IF($I13="TTL",SUMIF($C:$C,MID($K13,1,SEARCH("TTL",$K13)-2),$BL:$BL),SUMIF(실입고현황!$A:$A,BE13&VLOOKUP($AG13,'TARGET MU'!$A:$D,'TARGET MU'!$B$1,FALSE)&$Z13&" "&$AE13,실입고현황!$C:$C)) -> 0 | BM13: =IF($I13="TTL",SUMIF($C:$C,MID($K13,1,SEARCH("TTL",$K13)-2),$BM:$BM),SUMIF(실입고현황!$A:$A,BF13&VLOOKUP($AG13,'TARGET MU'!$A:$D,'TARGET MU'!$B$1,FALSE)&$Z13&" "&$AE13,실입고현황!$C:$C)) -> 0 | BN13: =IF($I13="TTL",SUMIF($C:$C,MID($K13,1,SEARCH("TTL",$K13)-2),$BN:$BN),IF(($BO13-SUM($BI13,$BJ13,$BK13,BL13,BM13))<$BO13*$BN$6,0,$BO13-SUM($BI13,$BJ13,$BK13,BL13,BM13))) -> 0 | BO13: =IF($I13="TTL",SUMIF($C:$C,MID($K13,1,SEARCH("TTL",$K13)-2),$BO:$BO),$AF13) -> 250 | BP13: =IF($I13="TTL",SUMIF($C:$C,MID($K13,1,SEARCH("TTL",$K13)-2),$BP:$BP),IF($AO13=0,0,IF($AP13=0,$AO13*$AF13,$AP13*$AF13))) -> 2247357.5 | BQ13: =IF($I13="TTL",SUMIF($C:$C,MID($K13,1,SEARCH("TTL",$K13)-2),$BQ:$BQ),$AM13*$AF13) -> 13750000 | BR13: =IF(ISERROR($BQ13/($BP13*1.1))=TRUE,0,$BQ13/($BP13*1.1)) -> 5.5620879 | BT13: =IF(ISERROR(Z13&VLOOKUP($AG13,'TARGET MU'!$A:$D,'TARGET MU'!$B$1,FALSE))=TRUE,"",Z13&VLOOKUP($AG13,'TARGET MU'!$A:$D,'TARGET MU'!$B$1,FALSE)) -> JOKEBF5803BL포모스트 | BU13: =AP13 -> 8989.43 | BV13: =Z13&AE13&AF13&AM13&AG13&AI13&AK13 -> JOKEBF5803BLFRE25055000FOREMOST02CN | BX13: =IF($I13="TTL","",$L13) -> JOK | BY13: =$O13 -> 5 | BZ13: =$AJ13 -> M | CA13: =$P13 -> EB | CB13: =$R13 -> K | CC13: =$AK13 -> CN | CD13: =$W13 -> 13FW JOIE BETE_03_BL_KIDS | CE13: =$U13 -> JOKEBF5803 | CF13: =$T13 -> 803 | CG13: =$W13 -> 13FW JOIE BETE_03_BL_KIDS | CH13: =$X13 -> BL | CI13: =$AD13 -> 1 | CJ13: =$AE13 -> FRE | CK13: =IF($I13="TTL",SUMIF($C:$C,MID($K13,1,SEARCH("TTL",$K13)-2),$BO:$BO),$AF13) -> 250 | CL13: =$AV13 -> 6.95 | CM13: =$AM13 -> 55000 | CN13: =$AP13-$AU13 -> 8669.43 | CO13: =$AU13 -> 320 | CP13: =$AL13 -> 1 | CQ13: 853 | CT13: =IF($I13="TTL",$K13,$Z13&$AE13) -> JOKEBF5803BLFRE | CU13: =$M13 -> JOIE BETE KIDS | CV13: =IF($I13="TTL","",IF($CX13="","",$Q13&"_"&$T13&IF(N13="K","_KIDS",IF(N13="I","_INFANT","")))) -> EARFLAP BEANIE_803 | CW13: =IF($I13="TTL","",IF($CT13="","",$Y13&"_"&$AE13)) -> BLUE_FRE | CX13: =$L13 -> JOK | CY13: =$T13 -> 803 | CZ13: =IF($I13="TTL",SUMIF($C:$C,MID($K13,1,SEARCH("TTL",$K13)-2),$CZ:$CZ),$AF13) -> 250 | DA13: =$AM13 -> 55000 | DB13: =$Y13 -> BLUE | DC13: =$AE13 -> FRE | DG13: 41712 | DH13: =IF(OR($I13="TTL",$I13=""),"",AZ13-$DH$11) -> 41768 | DI13: 41715 | DJ13: 41715 | DK13: 41779 | DL13: 6 | DM13: 6 | DN13: x | DO13: 41723 | DP13: =IF(OR($DN13="없음",$I13="TTL",$I13=""),"",AZ13-$DP$11) -> 41798 | DQ13: x | DR13: 41732 | DS13: 41771 | DT13: 41757 | DU13: 41768 | DV13: 41771 | DW13: x | DX13: 41869 | DY13: 입고완료 | DZ13: 가격사정완료 | EC13: =IF(OR(Z12&AX12=Z13&AX12,Z13&AX13=""),"",Z13&AX13) -> JOKEBF5803BL41711 | ED13: =IF(OR(Z12&AE12=Z13&AE13,Z13=""),"",Z13&AE13) -> JOKEBF5803BLFRE | EE13: =IF(ED13="",0,IF(COUNTIF(ED$12:ED12,ED13)=0,0,COUNTIF(ED$12:ED12,ED13))) -> 0 | EF13: =IF(OR($AJ13="B",$ED13="",MID($U13,8,1)=$EF$9,MID($U13,8,1)=$EF$10),0,1) -> 1 | EG13: =IF(EE13+EF13=0,"","R"&(EE13+EF13)) -> R1 | EI13: =IF($ED13="","",IF($EE13=0,U13,"")) -> JOKEBF5803 | EJ13: =IF($ED13="","",IF($EE13=0,Z13,"")) -> JOKEBF5803BL | EL13: 41771 | EM13: 41800 | EN13: 2935.2 | EO13: X | EP13: X | EQ13: X
A14: =IF(OR($I14="TTL",$I14=""),"",IF(ISERROR(VLOOKUP($B14,CODE!$D:$G,CODE!$F$1-2,FALSE))=TRUE,"전략",VLOOKUP($B14,CODE!$D:$G,CODE!$F$1-2,FALSE))) -> F-HAT | B14: =IF(OR($I14="TTL",$I14=""),"",IF(VLOOKUP($P14,CODE!$K:$O,CODE!$O$1,FALSE)="",$I14,$I14&"-"&VLOOKUP($P14,CODE!$K:$O,CODE!$O$1,FALSE))) -> JOK | C14: =IF($I14="TTL","",I14&"-"&$AG14&"-"&$AI14) -> JOK-FOREMOST-02 | D14: =$C14&$Z14 -> JOK-FOREMOST-02JOKEBF5804RE | E14: =IF($I14="TTL",0,IF(ISERROR(IF($Z13=$Z14,$E13,$E13+1))=TRUE,1,IF($Z13=$Z14,$E13,$E13+1))) -> 2 | F14: =$C14&$E14 -> JOK-FOREMOST-022 | G14: =$F14&"-"&$U14&$Y14&$AE14 -> JOK-FOREMOST-022-JOKEBF5804REDFRE | H14: =IF(ISERROR(I14&VLOOKUP(P14,CODE!$K:$N,CODE!$N$1,FALSE)&S14)=TRUE,0,I14&VLOOKUP(P14,CODE!$K:$N,CODE!$N$1,FALSE)&S14) -> JOK의류외804 | I14: =IF(ISERROR(SEARCH("TTL",$K14))=TRUE,IF($L14="","",VLOOKUP($L14,CODE!$B:$G,CODE!$D$1,FALSE)),"TTL") -> JOK | J14: =MID(W14,1,6) -> 13FW J | L14: JOK | M14: =IF(OR($I14="TTL",$L14=""),"",VLOOKUP($L14,CODE!$B:$D,CODE!$C$1,FALSE)) -> JOIE BETE KIDS | N14: =IF(OR($I14="TTL",$L14=""),"",VLOOKUP($K$2,CODE!$S:$T,CODE!$T$1-1,FALSE)) -> F | O14: 5 | P14: EB | Q14: =IF(OR($I14="TTL",$P14=""),"",VLOOKUP($P14,CODE!$K:$M,CODE!$L$1,FALSE)) -> EARFLAP BEANIE | R14: K | S14: 804 | T14: =IF(OR($I14="TTL",$S14=""),"",IF($S14<10,"00"&$S14,IF($S14<100,"0"&$S14,$S14))) -> 804 | U14: =IF($I14="TTL","",$L14&$P14&$N14&$O14&$T14) -> JOKEBF5804 | V14: =IF($I14="TTL",SUMIF($C:$C,MID($K14,1,SEARCH("TTL",$K14)-2),$V:$V),IF($EI14="",0,1/COUNTIF($EI:$EI,$EI14))) -> 1 | W14: 13FW JOIE BETE_03_RD_KIDS | X14: =IF($Y14="","",VLOOKUP($Y14,CODE!$AE:$AF,CODE!$AF$1-1,FALSE)) -> RE | Y14: RED | Z14: =$U14&$X14 -> JOKEBF5804RE | AA14: =VLOOKUP($Z14&$AX14,$EC:$EG,5,FALSE) -> R1 | AB14: =IF($I14="TTL",SUMIF($C:$C,MID($K14,1,SEARCH("TTL",$K14)-2),$AB:$AB),IF($EJ14="",0,1/COUNTIF($EJ:$EJ,$EJ14))) -> 1 | AC14: 0 | AD14: 1 | AE14: FRE | AF14: 250 | AG14: FOREMOST | AH14: 2 | AI14: =IF($AH14=0,"",IF($AH14<10,"0"&$AH14,$AH14)) -> 02 | AJ14: M | AK14: CN | AL14: =IF($AK14=0,"",IF($AK14="KR",2,1)) -> 1 | AM14: =IF(ISERROR(VLOOKUP($F14,[1]기획현황취합!$A$1:$E$64926,[1]기획현황취합!$B$1,FALSE))=TRUE,0,VLOOKUP($F14,[1]기획현황취합!$A$1:$E$64926,[1]기획현황취합!$B$1,FALSE)) -> 55000 | AN14: =IF(ISERROR(VLOOKUP($F14,[1]기획현황취합!$A$1:$E$64926,[1]기획현황취합!$C$1,FALSE))=TRUE,0,VLOOKUP($F14,[1]기획현황취합!$A$1:$E$64926,[1]기획현황취합!$C$1,FALSE)) -> 41710 | AO14: =IF(ISERROR(($AM14/1.1)/VLOOKUP($AG14,'TARGET MU'!$A:$D,'TARGET MU'!$D$1,FALSE))=TRUE,0,($AM14/1.1)/VLOOKUP($AG14,'TARGET MU'!$A:$D,'TARGET MU'!$D$1,FALSE)) -> 8333.3333 | AP14: =IF(OR(AF14=0,AND(AV14=0,AW14=0)),0,IF(AG14="캡보이2",AV14*$AQ$5+AU14,IF(OR(AK14="IN",AK14="BG",AK14="VT",AK14="CB"),$AU14+(($AV14*(1+$AW$4))*(HLOOKUP(VLOOKUP(AG14,'TARGET MU'!$A:$P,'TARGET MU'!$J$1,FALSE),$AO$4:$AR$5,2,FALSE)))+$AW14,$AU14+((($AV14*(1+$AW$4))*(1+HLOOKUP(VLOOKUP($P14,CODE!$K:$P,CODE!$P$1,FALSE),$AS$4:$AV$5,2,FALSE)))*(HLOOKUP(VLOOKUP(AG14,'TARGET MU'!$A:$P,'TARGET MU'!$J$1,FALSE),$AO$4:$AR$5,2,FALSE)))+$AW14))) -> 8802.32 | AQ14: =AP14-AO14 -> 468.98667 | AR14: 0 | AS14: 300 | AT14: 20 | AU14: =SUM(AR14:AT14) -> 320 | AV14: 6.8 | AW14: 0 | AX14: =IF(ISERROR(VLOOKUP($F14,[1]기획현황취합!$A$1:$E$64926,[1]기획현황취합!$D$1,FALSE))=TRUE,0,VLOOKUP($F14,[1]기획현황취합!$A$1:$E$64926,[1]기획현황취합!$D$1,FALSE)) -> 41711 | AZ14: =IF(ISERROR(VLOOKUP($F14,[1]기획현황취합!$A$1:$E$64926,[1]기획현황취합!$E$1,FALSE))=TRUE,0,VLOOKUP($F14,[1]기획현황취합!$A$1:$E$64926,[1]기획현황취합!$E$1,FALSE)) -> 41858 | BA14: 41858 | BB14: 41887 | BC14: 0 | BD14: 0 | BE14: 0 | BF14: 0 | BG14: 확정 | BH14: 확정 | BI14: =IF($I14="TTL",SUMIF($C:$C,MID($K14,1,SEARCH("TTL",$K14)-2),$BI:$BI),SUMIF(실입고현황!$A:$A,BB14&VLOOKUP($AG14,'TARGET MU'!$A:$D,'TARGET MU'!$B$1,FALSE)&$Z14&" "&$AE14,실입고현황!$C:$C)) -> 250 | BJ14: =IF($I14="TTL",SUMIF($C:$C,MID($K14,1,SEARCH("TTL",$K14)-2),$BJ:$BJ),SUMIF(실입고현황!$A:$A,BC14&VLOOKUP($AG14,'TARGET MU'!$A:$D,'TARGET MU'!$B$1,FALSE)&$Z14&" "&$AE14,실입고현황!$C:$C)) -> 0 | BK14: =IF($I14="TTL",SUMIF($C:$C,MID($K14,1,SEARCH("TTL",$K14)-2),$BK:$BK),SUMIF(실입고현황!$A:$A,BD14&VLOOKUP($AG14,'TARGET MU'!$A:$D,'TARGET MU'!$B$1,FALSE)&$Z14&" "&$AE14,실입고현황!$C:$C)) -> 0 | BL14: =IF($I14="TTL",SUMIF($C:$C,MID($K14,1,SEARCH("TTL",$K14)-2),$BL:$BL),SUMIF(실입고현황!$A:$A,BE14&VLOOKUP($AG14,'TARGET MU'!$A:$D,'TARGET MU'!$B$1,FALSE)&$Z14&" "&$AE14,실입고현황!$C:$C)) -> 0 | BM14: =IF($I14="TTL",SUMIF($C:$C,MID($K14,1,SEARCH("TTL",$K14)-2),$BM:$BM),SUMIF(실입고현황!$A:$A,BF14&VLOOKUP($AG14,'TARGET MU'!$A:$D,'TARGET MU'!$B$1,FALSE)&$Z14&" "&$AE14,실입고현황!$C:$C)) -> 0 | BN14: =IF($I14="TTL",SUMIF($C:$C,MID($K14,1,SEARCH("TTL",$K14)-2),$BN:$BN),IF(($BO14-SUM($BI14,$BJ14,$BK14,BL14,BM14))<$BO14*$BN$6,0,$BO14-SUM($BI14,$BJ14,$BK14,BL14,BM14))) -> 0 | BO14: =IF($I14="TTL",SUMIF($C:$C,MID($K14,1,SEARCH("TTL",$K14)-2),$BO:$BO),$AF14) -> 250 | BP14: =IF($I14="TTL",SUMIF($C:$C,MID($K14,1,SEARCH("TTL",$K14)-2),$BP:$BP),IF($AO14=0,0,IF($AP14=0,$AO14*$AF14,$AP14*$AF14))) -> 2200580 | BQ14: =IF($I14="TTL",SUMIF($C:$C,MID($K14,1,SEARCH("TTL",$K14)-2),$BQ:$BQ),$AM14*$AF14) -> 13750000 | BR14: =IF(ISERROR($BQ14/($BP14*1.1))=TRUE,0,$BQ14/($BP14*1.1)) -> 5.6803206 | BT14: =IF(ISERROR(Z14&VLOOKUP($AG14,'TARGET MU'!$A:$D,'TARGET MU'!$B$1,FALSE))=TRUE,"",Z14&VLOOKUP($AG14,'TARGET MU'!$A:$D,'TARGET MU'!$B$1,FALSE)) -> JOKEBF5804RE포모스트 | BU14: =AP14 -> 8802.32 | BV14: =Z14&AE14&AF14&AM14&AG14&AI14&AK14 -> JOKEBF5804REFRE25055000FOREMOST02CN | BX14: =IF($I14="TTL","",$L14) -> JOK | BY14: =$O14 -> 5 | BZ14: =$AJ14 -> M | CA14: =$P14 -> EB | CB14: =$R14 -> K | CC14: =$AK14 -> CN | CD14: =$W14 -> 13FW JOIE BETE_03_RD_KIDS | CE14: =$U14 -> JOKEBF5804 | CF14: =$T14 -> 804 | CG14: =$W14 -> 13FW JOIE BETE_03_RD_KIDS | CH14: =$X14 -> RE | CI14: =$AD14 -> 1 | CJ14: =$AE14 -> FRE | CK14: =IF($I14="TTL",SUMIF($C:$C,MID($K14,1,SEARCH("TTL",$K14)-2),$BO:$BO),$AF14) -> 250 | CL14: =$AV14 -> 6.8 | CM14: =$AM14 -> 55000 | CN14: =$AP14-$AU14 -> 8482.32 | CO14: =$AU14 -> 320 | CP14: =$AL14 -> 1 | CQ14: 853 | CT14: =IF($I14="TTL",$K14,$Z14&$AE14) -> JOKEBF5804REFRE | CU14: =$M14 -> JOIE BETE KIDS | CV14: =IF($I14="TTL","",IF($CX14="","",$Q14&"_"&$T14&IF(N14="K","_KIDS",IF(N14="I","_INFANT","")))) -> EARFLAP BEANIE_804 | CW14: =IF($I14="TTL","",IF($CT14="","",$Y14&"_"&$AE14)) -> RED_FRE | CX14: =$L14 -> JOK | CY14: =$T14 -> 804 | CZ14: =IF($I14="TTL",SUMIF($C:$C,MID($K14,1,SEARCH("TTL",$K14)-2),$CZ:$CZ),$AF14) -> 250 | DA14: =$AM14 -> 55000 | DB14: =$Y14 -> RED | DC14: =$AE14 -> FRE | DG14: 41712 | DH14: =IF(OR($I14="TTL",$I14=""),"",AZ14-$DH$11) -> 41768 | DI14: 41715 | DJ14: 41715 | DK14: 41779 | DL14: 6 | DM14: 6 | DN14: x | DO14: 41723 | DP14: =IF(OR($DN14="없음",$I14="TTL",$I14=""),"",AZ14-$DP$11) -> 41798 | DQ14: x | DR14: 41732 | DS14: 41771 | DT14: 41757 | DU14: 41757 | DV14: 41771 | DW14: x | DX14: 41869 | DY14: 입고완료 | DZ14: 가격사정완료 | EC14: =IF(OR(Z13&AX13=Z14&AX13,Z14&AX14=""),"",Z14&AX14) -> JOKEBF5804RE41711 | ED14: =IF(OR(Z13&AE13=Z14&AE14,Z14=""),"",Z14&AE14) -> JOKEBF5804REFRE | EE14: =IF(ED14="",0,IF(COUNTIF(ED$12:ED13,ED14)=0,0,COUNTIF(ED$12:ED13,ED14))) -> 0 | EF14: =IF(OR($AJ14="B",$ED14="",MID($U14,8,1)=$EF$9,MID($U14,8,1)=$EF$10),0,1) -> 1 | EG14: =IF(EE14+EF14=0,"","R"&(EE14+EF14)) -> R1 | EI14: =IF($ED14="","",IF($EE14=0,U14,"")) -> JOKEBF5804 | EJ14: =IF($ED14="","",IF($EE14=0,Z14,"")) -> JOKEBF5804RE | EL14: 41771 | EM14: 41800 | EN14: X | EO14: X | EP14: X | EQ14: X
A15: =IF(OR($I15="TTL",$I15=""),"",IF(ISERROR(VLOOKUP($B15,CODE!$D:$G,CODE!$F$1-2,FALSE))=TRUE,"전략",VLOOKUP($B15,CODE!$D:$G,CODE!$F$1-2,FALSE))) -> F-HAT | B15: =IF(OR($I15="TTL",$I15=""),"",IF(VLOOKUP($P15,CODE!$K:$O,CODE!$O$1,FALSE)="",$I15,$I15&"-"&VLOOKUP($P15,CODE!$K:$O,CODE!$O$1,FALSE))) -> JOK | C15: =IF($I15="TTL","",I15&"-"&$AG15&"-"&$AI15) -> JOK-FOREMOST-02 | D15: =$C15&$Z15 -> JOK-FOREMOST-02JOKVBF5806NY | E15: =IF($I15="TTL",0,IF(ISERROR(IF($Z14=$Z15,$E14,$E14+1))=TRUE,1,IF($Z14=$Z15,$E14,$E14+1))) -> 3 | F15: =$C15&$E15 -> JOK-FOREMOST-023 | G15: =$F15&"-"&$U15&$Y15&$AE15 -> JOK-FOREMOST-023-JOKVBF5806NAVYFRE | H15: =IF(ISERROR(I15&VLOOKUP(P15,CODE!$K:$N,CODE!$N$1,FALSE)&S15)=TRUE,0,I15&VLOOKUP(P15,CODE!$K:$N,CODE!$N$1,FALSE)&S15) -> JOK의류외806 | I15: =IF(ISERROR(SEARCH("TTL",$K15))=TRUE,IF($L15="","",VLOOKUP($L15,CODE!$B:$G,CODE!$D$1,FALSE)),"TTL") -> JOK | J15: =MID(W15,1,6) -> 13FW J | L15: JOK | M15: =IF(OR($I15="TTL",$L15=""),"",VLOOKUP($L15,CODE!$B:$D,CODE!$C$1,FALSE)) -> JOIE BETE KIDS | N15: =IF(OR($I15="TTL",$L15=""),"",VLOOKUP($K$2,CODE!$S:$T,CODE!$T$1-1,FALSE)) -> F | O15: 5 | P15: VB | Q15: =IF(OR($I15="TTL",$P15=""),"",VLOOKUP($P15,CODE!$K:$M,CODE!$L$1,FALSE)) -> VISOR BEANIE | R15: K | S15: 806 | T15: =IF(OR($I15="TTL",$S15=""),"",IF($S15<10,"00"&$S15,IF($S15<100,"0"&$S15,$S15))) -> 806 | U15: =IF($I15="TTL","",$L15&$P15&$N15&$O15&$T15) -> JOKVBF5806 | V15: =IF($I15="TTL",SUMIF($C:$C,MID($K15,1,SEARCH("TTL",$K15)-2),$V:$V),IF($EI15="",0,1/COUNTIF($EI:$EI,$EI15))) -> 0.5 | W15: 13FW JOIE BETE_09_NY_KIDS | X15: =IF($Y15="","",VLOOKUP($Y15,CODE!$AE:$AF,CODE!$AF$1-1,FALSE)) -> NY | Y15: NAVY | Z15: =$U15&$X15 -> JOKVBF5806NY | AA15: =VLOOKUP($Z15&$AX15,$EC:$EG,5,FALSE) -> R1 | AB15: =IF($I15="TTL",SUMIF($C:$C,MID($K15,1,SEARCH("TTL",$K15)-2),$AB:$AB),IF($EJ15="",0,1/COUNTIF($EJ:$EJ,$EJ15))) -> 1 | AC15: 0 | AD15: 1 | AE15: FRE | AF15: 250 | AG15: FOREMOST | AH15: 2 | AI15: =IF($AH15=0,"",IF($AH15<10,"0"&$AH15,$AH15)) -> 02 | AJ15: M | AK15: CN | AL15: =IF($AK15=0,"",IF($AK15="KR",2,1)) -> 1 | AM15: =IF(ISERROR(VLOOKUP($F15,[1]기획현황취합!$A$1:$E$64926,[1]기획현황취합!$B$1,FALSE))=TRUE,0,VLOOKUP($F15,[1]기획현황취합!$A$1:$E$64926,[1]기획현황취합!$B$1,FALSE)) -> 55000 | AN15: =IF(ISERROR(VLOOKUP($F15,[1]기획현황취합!$A$1:$E$64926,[1]기획현황취합!$C$1,FALSE))=TRUE,0,VLOOKUP($F15,[1]기획현황취합!$A$1:$E$64926,[1]기획현황취합!$C$1,FALSE)) -> 41710 | AO15: =IF(ISERROR(($AM15/1.1)/VLOOKUP($AG15,'TARGET MU'!$A:$D,'TARGET MU'!$D$1,FALSE))=TRUE,0,($AM15/1.1)/VLOOKUP($AG15,'TARGET MU'!$A:$D,'TARGET MU'!$D$1,FALSE)) -> 8333.3333 | AP15: =IF(OR(AF15=0,AND(AV15=0,AW15=0)),0,IF(AG15="캡보이2",AV15*$AQ$5+AU15,IF(OR(AK15="IN",AK15="BG",AK15="VT",AK15="CB"),$AU15+(($AV15*(1+$AW$4))*(HLOOKUP(VLOOKUP(AG15,'TARGET MU'!$A:$P,'TARGET MU'!$J$1,FALSE),$AO$4:$AR$5,2,FALSE)))+$AW15,$AU15+((($AV15*(1+$AW$4))*(1+HLOOKUP(VLOOKUP($P15,CODE!$K:$P,CODE!$P$1,FALSE),$AS$4:$AV$5,2,FALSE)))*(HLOOKUP(VLOOKUP(AG15,'TARGET MU'!$A:$P,'TARGET MU'!$J$1,FALSE),$AO$4:$AR$5,2,FALSE)))+$AW15))) -> 10049.72 | AQ15: =AP15-AO15 -> 1716.3867 | AR15: 0 | AS15: 300 | AT15: 20 | AU15: =SUM(AR15:AT15) -> 320 | AV15: 7.8 | AW15: 0 | AX15: =IF(ISERROR(VLOOKUP($F15,[1]기획현황취합!$A$1:$E$64926,[1]기획현황취합!$D$1,FALSE))=TRUE,0,VLOOKUP($F15,[1]기획현황취합!$A$1:$E$64926,[1]기획현황취합!$D$1,FALSE)) -> 41711 | AZ15: =IF(ISERROR(VLOOKUP($F15,[1]기획현황취합!$A$1:$E$64926,[1]기획현황취합!$E$1,FALSE))=TRUE,0,VLOOKUP($F15,[1]기획현황취합!$A$1:$E$64926,[1]기획현황취합!$E$1,FALSE)) -> 41858 | BA15: 41858 | BB15: 41887 | BC15: 0 | BD15: 0 | BE15: 0 | BF15: 0 | BG15: 확정 | BH15: 확정 | BI15: =IF($I15="TTL",SUMIF($C:$C,MID($K15,1,SEARCH("TTL",$K15)-2),$BI:$BI),SUMIF(실입고현황!$A:$A,BB15&VLOOKUP($AG15,'TARGET MU'!$A:$D,'TARGET MU'!$B$1,FALSE)&$Z15&" "&$AE15,실입고현황!$C:$C)) -> 250 | BJ15: =IF($I15="TTL",SUMIF($C:$C,MID($K15,1,SEARCH("TTL",$K15)-2),$BJ:$BJ),SUMIF(실입고현황!$A:$A,BC15&VLOOKUP($AG15,'TARGET MU'!$A:$D,'TARGET MU'!$B$1,FALSE)&$Z15&" "&$AE15,실입고현황!$C:$C)) -> 0 | BK15: =IF($I15="TTL",SUMIF($C:$C,MID($K15,1,SEARCH("TTL",$K15)-2),$BK:$BK),SUMIF(실입고현황!$A:$A,BD15&VLOOKUP($AG15,'TARGET MU'!$A:$D,'TARGET MU'!$B$1,FALSE)&$Z15&" "&$AE15,실입고현황!$C:$C)) -> 0 | BL15: =IF($I15="TTL",SUMIF($C:$C,MID($K15,1,SEARCH("TTL",$K15)-2),$BL:$BL),SUMIF(실입고현황!$A:$A,BE15&VLOOKUP($AG15,'TARGET MU'!$A:$D,'TARGET MU'!$B$1,FALSE)&$Z15&" "&$AE15,실입고현황!$C:$C)) -> 0 | BM15: =IF($I15="TTL",SUMIF($C:$C,MID($K15,1,SEARCH("TTL",$K15)-2),$BM:$BM),SUMIF(실입고현황!$A:$A,BF15&VLOOKUP($AG15,'TARGET MU'!$A:$D,'TARGET MU'!$B$1,FALSE)&$Z15&" "&$AE15,실입고현황!$C:$C)) -> 0 | BN15: =IF($I15="TTL",SUMIF($C:$C,MID($K15,1,SEARCH("TTL",$K15)-2),$BN:$BN),IF(($BO15-SUM($BI15,$BJ15,$BK15,BL15,BM15))<$BO15*$BN$6,0,$BO15-SUM($BI15,$BJ15,$BK15,BL15,BM15))) -> 0 | BO15: =IF($I15="TTL",SUMIF($C:$C,MID($K15,1,SEARCH("TTL",$K15)-2),$BO:$BO),$AF15) -> 250 | BP15: =IF($I15="TTL",SUMIF($C:$C,MID($K15,1,SEARCH("TTL",$K15)-2),$BP:$BP),IF($AO15=0,0,IF($AP15=0,$AO15*$AF15,$AP15*$AF15))) -> 2512430 | BQ15: =IF($I15="TTL",SUMIF($C:$C,MID($K15,1,SEARCH("TTL",$K15)-2),$BQ:$BQ),$AM15*$AF15) -> 13750000 | BR15: =IF(ISERROR($BQ15/($BP15*1.1))=TRUE,0,$BQ15/($BP15*1.1)) -> 4.975263 | BT15: =IF(ISERROR(Z15&VLOOKUP($AG15,'TARGET MU'!$A:$D,'TARGET MU'!$B$1,FALSE))=TRUE,"",Z15&VLOOKUP($AG15,'TARGET MU'!$A:$D,'TARGET MU'!$B$1,FALSE)) -> JOKVBF5806NY포모스트 | BU15: =AP15 -> 10049.72 | BV15: =Z15&AE15&AF15&AM15&AG15&AI15&AK15 -> JOKVBF5806NYFRE25055000FOREMOST02CN | BX15: =IF($I15="TTL","",$L15) -> JOK | BY15: =$O15 -> 5 | BZ15: =$AJ15 -> M | CA15: =$P15 -> VB | CB15: =$R15 -> K | CC15: =$AK15 -> CN | CD15: =$W15 -> 13FW JOIE BETE_09_NY_KIDS | CE15: =$U15 -> JOKVBF5806 | CF15: =$T15 -> 806 | CG15: =$W15 -> 13FW JOIE BETE_09_NY_KIDS | CH15: =$X15 -> NY | CI15: =$AD15 -> 1 | CJ15: =$AE15 -> FRE | CK15: =IF($I15="TTL",SUMIF($C:$C,MID($K15,1,SEARCH("TTL",$K15)-2),$BO:$BO),$AF15) -> 250 | CL15: =$AV15 -> 7.8 | CM15: =$AM15 -> 55000 | CN15: =$AP15-$AU15 -> 9729.72 | CO15: =$AU15 -> 320 | CP15: =$AL15 -> 1 | CQ15: 853 | CT15: =IF($I15="TTL",$K15,$Z15&$AE15) -> JOKVBF5806NYFRE | CU15: =$M15 -> JOIE BETE KIDS | CV15: =IF($I15="TTL","",IF($CX15="","",$Q15&"_"&$T15&IF(N15="K","_KIDS",IF(N15="I","_INFANT","")))) -> VISOR BEANIE_806 | CW15: =IF($I15="TTL","",IF($CT15="","",$Y15&"_"&$AE15)) -> NAVY_FRE | CX15: =$L15 -> JOK | CY15: =$T15 -> 806 | CZ15: =IF($I15="TTL",SUMIF($C:$C,MID($K15,1,SEARCH("TTL",$K15)-2),$CZ:$CZ),$AF15) -> 250 | DA15: =$AM15 -> 55000 | DB15: =$Y15 -> NAVY | DC15: =$AE15 -> FRE | DG15: 41712 | DH15: =IF(OR($I15="TTL",$I15=""),"",AZ15-$DH$11) -> 41768 | DI15: 41715 | DJ15: 41715 | DK15: 41779 | DL15: 8 | DM15: 8 | DN15: x | DO15: 41723 | DP15: =IF(OR($DN15="없음",$I15="TTL",$I15=""),"",AZ15-$DP$11) -> 41798 | DQ15: x | DR15: 41732 | DS15: 41771 | DT15: 41757 | DU15: 41758 | DV15: 41771 | DW15: x | DX15: 41869 | DY15: 입고완료 | DZ15: 가격사정완료 | EC15: =IF(OR(Z14&AX14=Z15&AX14,Z15&AX15=""),"",Z15&AX15) -> JOKVBF5806NY41711 | ED15: =IF(OR(Z14&AE14=Z15&AE15,Z15=""),"",Z15&AE15) -> JOKVBF5806NYFRE | EE15: =IF(ED15="",0,IF(COUNTIF(ED$12:ED14,ED15)=0,0,COUNTIF(ED$12:ED14,ED15))) -> 0 | EF15: =IF(OR($AJ15="B",$ED15="",MID($U15,8,1)=$EF$9,MID($U15,8,1)=$EF$10),0,1) -> 1 | EG15: =IF(EE15+EF15=0,"","R"&(EE15+EF15)) -> R1 | EI15: =IF($ED15="","",IF($EE15=0,U15,"")) -> JOKVBF5806 | EJ15: =IF($ED15="","",IF($EE15=0,Z15,"")) -> JOKVBF5806NY | EL15: 41771 | EM15: 41800 | EN15: X | EO15: X | EP15: X | EQ15: X
A16: =IF(OR($I16="TTL",$I16=""),"",IF(ISERROR(VLOOKUP($B16,CODE!$D:$G,CODE!$F$1-2,FALSE))=TRUE,"전략",VLOOKUP($B16,CODE!$D:$G,CODE!$F$1-2,FALSE))) -> F-HAT | B16: =IF(OR($I16="TTL",$I16=""),"",IF(VLOOKUP($P16,CODE!$K:$O,CODE!$O$1,FALSE)="",$I16,$I16&"-"&VLOOKUP($P16,CODE!$K:$O,CODE!$O$1,FALSE))) -> JOK | C16: =IF($I16="TTL","",I16&"-"&$AG16&"-"&$AI16) -> JOK-FOREMOST-02 | D16: =$C16&$Z16 -> JOK-FOREMOST-02JOKVBF5806PK | E16: =IF($I16="TTL",0,IF(ISERROR(IF($Z15=$Z16,$E15,$E15+1))=TRUE,1,IF($Z15=$Z16,$E15,$E15+1))) -> 4 | F16: =$C16&$E16 -> JOK-FOREMOST-024 | G16: =$F16&"-"&$U16&$Y16&$AE16 -> JOK-FOREMOST-024-JOKVBF5806PINKFRE | H16: =IF(ISERROR(I16&VLOOKUP(P16,CODE!$K:$N,CODE!$N$1,FALSE)&S16)=TRUE,0,I16&VLOOKUP(P16,CODE!$K:$N,CODE!$N$1,FALSE)&S16) -> JOK의류외806 | I16: =IF(ISERROR(SEARCH("TTL",$K16))=TRUE,IF($L16="","",VLOOKUP($L16,CODE!$B:$G,CODE!$D$1,FALSE)),"TTL") -> JOK | J16: =MID(W16,1,6) -> 13FW J | L16: JOK | M16: =IF(OR($I16="TTL",$L16=""),"",VLOOKUP($L16,CODE!$B:$D,CODE!$C$1,FALSE)) -> JOIE BETE KIDS | N16: =IF(OR($I16="TTL",$L16=""),"",VLOOKUP($K$2,CODE!$S:$T,CODE!$T$1-1,FALSE)) -> F | O16: 5 | P16: VB | Q16: =IF(OR($I16="TTL",$P16=""),"",VLOOKUP($P16,CODE!$K:$M,CODE!$L$1,FALSE)) -> VISOR BEANIE | R16: K | S16: 806 | T16: =IF(OR($I16="TTL",$S16=""),"",IF($S16<10,"00"&$S16,IF($S16<100,"0"&$S16,$S16))) -> 806 | U16: =IF($I16="TTL","",$L16&$P16&$N16&$O16&$T16) -> JOKVBF5806 | V16: =IF($I16="TTL",SUMIF($C:$C,MID($K16,1,SEARCH("TTL",$K16)-2),$V:$V),IF($EI16="",0,1/COUNTIF($EI:$EI,$EI16))) -> 0.5 | W16: 13FW JOIE BETE_09_PK_KIDS | X16: =IF($Y16="","",VLOOKUP($Y16,CODE!$AE:$AF,CODE!$AF$1-1,FALSE)) -> PK | Y16: PINK | Z16: =$U16&$X16 -> JOKVBF5806PK | AA16: =VLOOKUP($Z16&$AX16,$EC:$EG,5,FALSE) -> R1 | AB16: =IF($I16="TTL",SUMIF($C:$C,MID($K16,1,SEARCH("TTL",$K16)-2),$AB:$AB),IF($EJ16="",0,1/COUNTIF($EJ:$EJ,$EJ16))) -> 1 | AC16: 0 | AD16: 1 | AE16: FRE | AF16: 250 | AG16: FOREMOST | AH16: 2 | AI16: =IF($AH16=0,"",IF($AH16<10,"0"&$AH16,$AH16)) -> 02 | AJ16: M | AK16: CN | AL16: =IF($AK16=0,"",IF($AK16="KR",2,1)) -> 1 | AM16: =IF(ISERROR(VLOOKUP($F16,[1]기획현황취합!$A$1:$E$64926,[1]기획현황취합!$B$1,FALSE))=TRUE,0,VLOOKUP($F16,[1]기획현황취합!$A$1:$E$64926,[1]기획현황취합!$B$1,FALSE)) -> 55000 | AN16: =IF(ISERROR(VLOOKUP($F16,[1]기획현황취합!$A$1:$E$64926,[1]기획현황취합!$C$1,FALSE))=TRUE,0,VLOOKUP($F16,[1]기획현황취합!$A$1:$E$64926,[1]기획현황취합!$C$1,FALSE)) -> 41710 | AO16: =IF(ISERROR(($AM16/1.1)/VLOOKUP($AG16,'TARGET MU'!$A:$D,'TARGET MU'!$D$1,FALSE))=TRUE,0,($AM16/1.1)/VLOOKUP($AG16,'TARGET MU'!$A:$D,'TARGET MU'!$D$1,FALSE)) -> 8333.3333 | AP16: =IF(OR(AF16=0,AND(AV16=0,AW16=0)),0,IF(AG16="캡보이2",AV16*$AQ$5+AU16,IF(OR(AK16="IN",AK16="BG",AK16="VT",AK16="CB"),$AU16+(($AV16*(1+$AW$4))*(HLOOKUP(VLOOKUP(AG16,'TARGET MU'!$A:$P,'TARGET MU'!$J$1,FALSE),$AO$4:$AR$5,2,FALSE)))+$AW16,$AU16+((($AV16*(1+$AW$4))*(1+HLOOKUP(VLOOKUP($P16,CODE!$K:$P,CODE!$P$1,FALSE),$AS$4:$AV$5,2,FALSE)))*(HLOOKUP(VLOOKUP(AG16,'TARGET MU'!$A:$P,'TARGET MU'!$J$1,FALSE),$AO$4:$AR$5,2,FALSE)))+$AW16))) -> 10049.72 | AQ16: =AP16-AO16 -> 1716.3867 | AR16: 0 | AS16: 300 | AT16: 20 | AU16: =SUM(AR16:AT16) -> 320 | AV16: 7.8 | AW16: 0 | AX16: =IF(ISERROR(VLOOKUP($F16,[1]기획현황취합!$A$1:$E$64926,[1]기획현황취합!$D$1,FALSE))=TRUE,0,VLOOKUP($F16,[1]기획현황취합!$A$1:$E$64926,[1]기획현황취합!$D$1,FALSE)) -> 41711 | AZ16: =IF(ISERROR(VLOOKUP($F16,[1]기획현황취합!$A$1:$E$64926,[1]기획현황취합!$E$1,FALSE))=TRUE,0,VLOOKUP($F16,[1]기획현황취합!$A$1:$E$64926,[1]기획현황취합!$E$1,FALSE)) -> 41858 | BA16: 41858 | BB16: 41887 | BC16: 0 | BD16: 0 | BE16: 0 | BF16: 0 | BG16: 확정 | BH16: 확정 | BI16: =IF($I16="TTL",SUMIF($C:$C,MID($K16,1,SEARCH("TTL",$K16)-2),$BI:$BI),SUMIF(실입고현황!$A:$A,BB16&VLOOKUP($AG16,'TARGET MU'!$A:$D,'TARGET MU'!$B$1,FALSE)&$Z16&" "&$AE16,실입고현황!$C:$C)) -> 249 | BJ16: =IF($I16="TTL",SUMIF($C:$C,MID($K16,1,SEARCH("TTL",$K16)-2),$BJ:$BJ),SUMIF(실입고현황!$A:$A,BC16&VLOOKUP($AG16,'TARGET MU'!$A:$D,'TARGET MU'!$B$1,FALSE)&$Z16&" "&$AE16,실입고현황!$C:$C)) -> 0 | BK16: =IF($I16="TTL",SUMIF($C:$C,MID($K16,1,SEARCH("TTL",$K16)-2),$BK:$BK),SUMIF(실입고현황!$A:$A,BD16&VLOOKUP($AG16,'TARGET MU'!$A:$D,'TARGET MU'!$B$1,FALSE)&$Z16&" "&$AE16,실입고현황!$C:$C)) -> 0 | BL16: =IF($I16="TTL",SUMIF($C:$C,MID($K16,1,SEARCH("TTL",$K16)-2),$BL:$BL),SUMIF(실입고현황!$A:$A,BE16&VLOOKUP($AG16,'TARGET MU'!$A:$D,'TARGET MU'!$B$1,FALSE)&$Z16&" "&$AE16,실입고현황!$C:$C)) -> 0 | BM16: =IF($I16="TTL",SUMIF($C:$C,MID($K16,1,SEARCH("TTL",$K16)-2),$BM:$BM),SUMIF(실입고현황!$A:$A,BF16&VLOOKUP($AG16,'TARGET MU'!$A:$D,'TARGET MU'!$B$1,FALSE)&$Z16&" "&$AE16,실입고현황!$C:$C)) -> 0 | BN16: =IF($I16="TTL",SUMIF($C:$C,MID($K16,1,SEARCH("TTL",$K16)-2),$BN:$BN),IF(($BO16-SUM($BI16,$BJ16,$BK16,BL16,BM16))<$BO16*$BN$6,0,$BO16-SUM($BI16,$BJ16,$BK16,BL16,BM16))) -> 0 | BO16: =IF($I16="TTL",SUMIF($C:$C,MID($K16,1,SEARCH("TTL",$K16)-2),$BO:$BO),$AF16) -> 250 | BP16: =IF($I16="TTL",SUMIF($C:$C,MID($K16,1,SEARCH("TTL",$K16)-2),$BP:$BP),IF($AO16=0,0,IF($AP16=0,$AO16*$AF16,$AP16*$AF16))) -> 2512430 | BQ16: =IF($I16="TTL",SUMIF($C:$C,MID($K16,1,SEARCH("TTL",$K16)-2),$BQ:$BQ),$AM16*$AF16) -> 13750000 | BR16: =IF(ISERROR($BQ16/($BP16*1.1))=TRUE,0,$BQ16/($BP16*1.1)) -> 4.975263 | BT16: =IF(ISERROR(Z16&VLOOKUP($AG16,'TARGET MU'!$A:$D,'TARGET MU'!$B$1,FALSE))=TRUE,"",Z16&VLOOKUP($AG16,'TARGET MU'!$A:$D,'TARGET MU'!$B$1,FALSE)) -> JOKVBF5806PK포모스트 | BU16: =AP16 -> 10049.72 | BV16: =Z16&AE16&AF16&AM16&AG16&AI16&AK16 -> JOKVBF5806PKFRE25055000FOREMOST02CN | BX16: =IF($I16="TTL","",$L16) -> JOK | BY16: =$O16 -> 5 | BZ16: =$AJ16 -> M | CA16: =$P16 -> VB | CB16: =$R16 -> K | CC16: =$AK16 -> CN | CD16: =$W16 -> 13FW JOIE BETE_09_PK_KIDS | CE16: =$U16 -> JOKVBF5806 | CF16: =$T16 -> 806 | CG16: =$W16 -> 13FW JOIE BETE_09_PK_KIDS | CH16: =$X16 -> PK | CI16: =$AD16 -> 1 | CJ16: =$AE16 -> FRE | CK16: =IF($I16="TTL",SUMIF($C:$C,MID($K16,1,SEARCH("TTL",$K16)-2),$BO:$BO),$AF16) -> 250 | CL16: =$AV16 -> 7.8 | CM16: =$AM16 -> 55000 | CN16: =$AP16-$AU16 -> 9729.72 | CO16: =$AU16 -> 320 | CP16: =$AL16 -> 1 | CQ16: 853 | CT16: =IF($I16="TTL",$K16,$Z16&$AE16) -> JOKVBF5806PKFRE | CU16: =$M16 -> JOIE BETE KIDS | CV16: =IF($I16="TTL","",IF($CX16="","",$Q16&"_"&$T16&IF(N16="K","_KIDS",IF(N16="I","_INFANT","")))) -> VISOR BEANIE_806 | CW16: =IF($I16="TTL","",IF($CT16="","",$Y16&"_"&$AE16)) -> PINK_FRE | CX16: =$L16 -> JOK | CY16: =$T16 -> 806 | CZ16: =IF($I16="TTL",SUMIF($C:$C,MID($K16,1,SEARCH("TTL",$K16)-2),$CZ:$CZ),$AF16) -> 250 | DA16: =$AM16 -> 55000 | DB16: =$Y16 -> PINK | DC16: =$AE16 -> FRE | DG16: 41712 | DH16: =IF(OR($I16="TTL",$I16=""),"",AZ16-$DH$11) -> 41768 | DI16: 41715 | DJ16: 41715 | DK16: 41779 | DL16: 7 | DM16: 7 | DN16: x | DO16: 41723 | DP16: =IF(OR($DN16="없음",$I16="TTL",$I16=""),"",AZ16-$DP$11) -> 41798 | DQ16: x | DR16: 41732 | DS16: 41771 | DT16: 41757 | DU16: 41768 | DV16: 41771 | DW16: x | DX16: 41869 | DY16: 입고완료 | DZ16: 가격사정완료 | EC16: =IF(OR(Z15&AX15=Z16&AX15,Z16&AX16=""),"",Z16&AX16) -> JOKVBF5806PK41711 | ED16: =IF(OR(Z15&AE15=Z16&AE16,Z16=""),"",Z16&AE16) -> JOKVBF5806PKFRE | EE16: =IF(ED16="",0,IF(COUNTIF(ED$12:ED15,ED16)=0,0,COUNTIF(ED$12:ED15,ED16))) -> 0 | EF16: =IF(OR($AJ16="B",$ED16="",MID($U16,8,1)=$EF$9,MID($U16,8,1)=$EF$10),0,1) -> 1 | EG16: =IF(EE16+EF16=0,"","R"&(EE16+EF16)) -> R1 | EI16: =IF($ED16="","",IF($EE16=0,U16,"")) -> JOKVBF5806 | EJ16: =IF($ED16="","",IF($EE16=0,Z16,"")) -> JOKVBF5806PK | EL16: 41771 | EM16: 41800 | EN16: X | EO16: X | EP16: X | EQ16: X
A17: =IF(OR($I17="TTL",$I17=""),"",IF(ISERROR(VLOOKUP($B17,CODE!$D:$G,CODE!$F$1-2,FALSE))=TRUE,"전략",VLOOKUP($B17,CODE!$D:$G,CODE!$F$1-2,FALSE))) | B17: =IF(OR($I17="TTL",$I17=""),"",IF(VLOOKUP($P17,CODE!$K:$O,CODE!$O$1,FALSE)="",$I17,$I17&"-"&VLOOKUP($P17,CODE!$K:$O,CODE!$O$1,FALSE))) | C17: =IF($I17="TTL","",I17&"-"&$AG17&"-"&$AI17) | D17: =$C17&$Z17 | E17: =IF($I17="TTL",0,IF(ISERROR(IF($Z16=$Z17,$E16,$E16+1))=TRUE,1,IF($Z16=$Z17,$E16,$E16+1))) -> 0 | F17: =$C17&$E17 -> 0 | G17: =$F17&"-"&$U17&$Y17&$AE17 -> 0- | H17: =IF(ISERROR(I17&VLOOKUP(P17,CODE!$K:$N,CODE!$N$1,FALSE)&S17)=TRUE,0,I17&VLOOKUP(P17,CODE!$K:$N,CODE!$N$1,FALSE)&S17) -> 0 | I17: =IF(ISERROR(SEARCH("TTL",$K17))=TRUE,IF($L17="","",VLOOKUP($L17,CODE!$B:$G,CODE!$D$1,FALSE)),"TTL") -> TTL | J17: =MID(W17,1,6) | K17: =C16&" TTL" -> JOK-FOREMOST-02 TTL | M17: =IF(OR($I17="TTL",$L17=""),"",VLOOKUP($L17,CODE!$B:$D,CODE!$C$1,FALSE)) | N17: =IF(OR($I17="TTL",$L17=""),"",VLOOKUP($K$2,CODE!$S:$T,CODE!$T$1-1,FALSE)) | O17: =IF(OR($I17="TTL",$L17=""),"",VLOOKUP($L$2,CODE!$X:$Y,CODE!$Y$1-1,FALSE)) | Q17: =IF(OR($I17="TTL",$P17=""),"",VLOOKUP($P17,CODE!$K:$M,CODE!$L$1,FALSE)) | T17: =IF(OR($I17="TTL",$S17=""),"",IF($S17<10,"00"&$S17,IF($S17<100,"0"&$S17,$S17))) | U17: =IF($I17="TTL","",$L17&$P17&$N17&$O17&$T17) | V17: =IF($I17="TTL",SUMIF($C:$C,MID($K17,1,SEARCH("TTL",$K17)-2),$V:$V),IF($EI17="",0,1/COUNTIF($EI:$EI,$EI17))) -> 3 | X17: =IF($Y17="","",VLOOKUP($Y17,CODE!$AE:$AF,CODE!$AF$1-1,FALSE)) | Z17: =$U17&$X17 | AA17: =VLOOKUP($Z17&$AX17,$EC:$EG,5,FALSE) | AB17: =IF($I17="TTL",SUMIF($C:$C,MID($K17,1,SEARCH("TTL",$K17)-2),$AB:$AB),IF($EJ17="",0,1/COUNTIF($EJ:$EJ,$EJ17))) -> 4 | AC17: 0 | AD17: 1 | AI17: =IF($AH17=0,"",IF($AH17<10,"0"&$AH17,$AH17)) | AL17: =IF($AK17=0,"",IF($AK17="KR",2,1)) | AM17: =IF(ISERROR(VLOOKUP($F17,[1]기획현황취합!$A$1:$E$64926,[1]기획현황취합!$B$1,FALSE))=TRUE,0,VLOOKUP($F17,[1]기획현황취합!$A$1:$E$64926,[1]기획현황취합!$B$1,FALSE)) -> 0 | AN17: =IF(ISERROR(VLOOKUP($F17,[1]기획현황취합!$A$1:$E$64926,[1]기획현황취합!$C$1,FALSE))=TRUE,0,VLOOKUP($F17,[1]기획현황취합!$A$1:$E$64926,[1]기획현황취합!$C$1,FALSE)) -> 0 | AO17: =IF(ISERROR(($AM17/1.1)/VLOOKUP($AG17,'TARGET MU'!$A:$D,'TARGET MU'!$D$1,FALSE))=TRUE,0,($AM17/1.1)/VLOOKUP($AG17,'TARGET MU'!$A:$D,'TARGET MU'!$D$1,FALSE)) -> 0 | AP17: =IF(OR(AF17=0,AND(AV17=0,AW17=0)),0,IF(AG17="캡보이2",AV17*$AQ$5+AU17,IF(OR(AK17="IN",AK17="BG",AK17="VT",AK17="CB"),$AU17+(($AV17*(1+$AW$4))*(HLOOKUP(VLOOKUP(AG17,'TARGET MU'!$A:$P,'TARGET MU'!$J$1,FALSE),$AO$4:$AR$5,2,FALSE)))+$AW17,$AU17+((($AV17*(1+$AW$4))*(1+HLOOKUP(VLOOKUP($P17,CODE!$K:$P,CODE!$P$1,FALSE),$AS$4:$AV$5,2,FALSE)))*(HLOOKUP(VLOOKUP(AG17,'TARGET MU'!$A:$P,'TARGET MU'!$J$1,FALSE),$AO$4:$AR$5,2,FALSE)))+$AW17))) -> 0 | AQ17: =AP17-AO17 -> 0 | AR17: 0 | AS17: 0 | AU17: =SUM(AR17:AT17) -> 0 | AV17: 0 | AW17: 0 | AX17: =IF(ISERROR(VLOOKUP($F17,[1]기획현황취합!$A$1:$E$64926,[1]기획현황취합!$D$1,FALSE))=TRUE,0,VLOOKUP($F17,[1]기획현황취합!$A$1:$E$64926,[1]기획현황취합!$D$1,FALSE)) -> 0 | AY17: 0 | AZ17: =IF(ISERROR(VLOOKUP($F17,[1]기획현황취합!$A$1:$E$64926,[1]기획현황취합!$E$1,FALSE))=TRUE,0,VLOOKUP($F17,[1]기획현황취합!$A$1:$E$64926,[1]기획현황취합!$E$1,FALSE)) -> 0 | BA17: 0 | BB17: 0 | BC17: 0 | BD17: 0 | BE17: 0 | BF17: 0 | BG17: 0 | BH17: 0 | BI17: =IF($I17="TTL",SUMIF($C:$C,MID($K17,1,SEARCH("TTL",$K17)-2),$BI:$BI),SUMIF(실입고현황!$A:$A,BB17&VLOOKUP($AG17,'TARGET MU'!$A:$D,'TARGET MU'!$B$1,FALSE)&$Z17&" "&$AE17,실입고현황!$C:$C)) -> 999 | BJ17: =IF($I17="TTL",SUMIF($C:$C,MID($K17,1,SEARCH("TTL",$K17)-2),$BJ:$BJ),SUMIF(실입고현황!$A:$A,BC17&VLOOKUP($AG17,'TARGET MU'!$A:$D,'TARGET MU'!$B$1,FALSE)&$Z17&" "&$AE17,실입고현황!$C:$C)) -> 0 | BK17: =IF($I17="TTL",SUMIF($C:$C,MID($K17,1,SEARCH("TTL",$K17)-2),$BK:$BK),SUMIF(실입고현황!$A:$A,BD17&VLOOKUP($AG17,'TARGET MU'!$A:$D,'TARGET MU'!$B$1,FALSE)&$Z17&" "&$AE17,실입고현황!$C:$C)) -> 0 | BL17: =IF($I17="TTL",SUMIF($C:$C,MID($K17,1,SEARCH("TTL",$K17)-2),$BL:$BL),SUMIF(실입고현황!$A:$A,BE17&VLOOKUP($AG17,'TARGET MU'!$A:$D,'TARGET MU'!$B$1,FALSE)&$Z17&" "&$AE17,실입고현황!$C:$C)) -> 0 | BM17: =IF($I17="TTL",SUMIF($C:$C,MID($K17,1,SEARCH("TTL",$K17)-2),$BM:$BM),SUMIF(실입고현황!$A:$A,BF17&VLOOKUP($AG17,'TARGET MU'!$A:$D,'TARGET MU'!$B$1,FALSE)&$Z17&" "&$AE17,실입고현황!$C:$C)) -> 0 | BN17: =IF($I17="TTL",SUMIF($C:$C,MID($K17,1,SEARCH("TTL",$K17)-2),$BN:$BN),IF(($BO17-SUM($BI17,$BJ17,$BK17,BL17,BM17))<$BO17*$BN$6,0,$BO17-SUM($BI17,$BJ17,$BK17,BL17,BM17))) -> 0 | BO17: =IF($I17="TTL",SUMIF($C:$C,MID($K17,1,SEARCH("TTL",$K17)-2),$BO:$BO),$AF17) -> 1000 | BP17: =IF($I17="TTL",SUMIF($C:$C,MID($K17,1,SEARCH("TTL",$K17)-2),$BP:$BP),IF($AO17=0,0,IF($AP17=0,$AO17*$AF17,$AP17*$AF17))) -> 9472797.5 | BQ17: =IF($I17="TTL",SUMIF($C:$C,MID($K17,1,SEARCH("TTL",$K17)-2),$BQ:$BQ),$AM17*$AF17) -> 55000000 | BR17: =IF(ISERROR($BQ17/($BP17*1.1))=TRUE,0,$BQ17/($BP17*1.1)) -> 5.2782718 | BT17: =IF(ISERROR(Z17&VLOOKUP($AG17,'TARGET MU'!$A:$D,'TARGET MU'!$B$1,FALSE))=TRUE,"",Z17&VLOOKUP($AG17,'TARGET MU'!$A:$D,'TARGET MU'!$B$1,FALSE)) | BU17: =AP17 -> 0 | BV17: =Z17&AE17&AF17&AM17&AG17&AI17&AK17 -> 0 | BX17: =IF($I17="TTL","",$L17) | BY17: =$O17 | BZ17: =$AJ17 -> 0 | CA17: =$P17 -> 0 | CB17: =$R17 -> 0 | CC17: =$AK17 -> 0 | CD17: =$W17 -> 0 | CE17: =$U17 | CF17: =$T17 | CG17: =$W17 -> 0 | CH17: =$X17 | CI17: =$AD17 -> 1 | CJ17: =$AE17 -> 0 | CK17: =IF($I17="TTL",SUMIF($C:$C,MID($K17,1,SEARCH("TTL",$K17)-2),$BO:$BO),$AF17) -> 1000 | CL17: =$AV17 -> 0 | CM17: =$AM17 -> 0 | CN17: =$AP17-$AU17 -> 0 | CO17: =$AU17 -> 0 | CP17: =$AL17 | CT17: =IF($I17="TTL",$K17,$Z17&$AE17) -> JOK-FOREMOST-02 TTL | CU17: =$M17 | CV17: =IF($I17="TTL","",IF($CX17="","",$Q17&"_"&$T17&IF(N17="K","_KIDS",IF(N17="I","_INFANT","")))) | CW17: =IF($I17="TTL","",IF($CT17="","",$Y17&"_"&$AE17)) | CX17: =$L17 -> 0 | CY17: =$T17 | CZ17: =IF($I17="TTL",SUMIF($C:$C,MID($K17,1,SEARCH("TTL",$K17)-2),$CZ:$CZ),$AF17) -> 1000 | DA17: =$AM17 -> 0 | DB17: =$Y17 -> 0 | DC17: =$AE17 -> 0 | DH17: =IF(OR($I17="TTL",$I17=""),"",AZ17-$DH$11) | DP17: =IF(OR($DN17="없음",$I17="TTL",$I17=""),"",AZ17-$DP$11) | EC17: =IF(OR(Z16&AX16=Z17&AX16,Z17&AX17=""),"",Z17&AX17) -> 0 | ED17: =IF(OR(Z16&AE16=Z17&AE17,Z17=""),"",Z17&AE17) | EE17: =IF(ED17="",0,IF(COUNTIF(ED$12:ED16,ED17)=0,0,COUNTIF(ED$12:ED16,ED17))) -> 0 | EF17: =IF(OR($AJ17="B",$ED17="",MID($U17,8,1)=$EF$9,MID($U17,8,1)=$EF$10),0,1) -> 0 | EG17: =IF(EE17+EF17=0,"","R"&(EE17+EF17)) | EI17: =IF($ED17="","",IF($EE17=0,U17,"")) | EJ17: =IF($ED17="","",IF($EE17=0,Z17,""))
