Workbook

Sheet DB
F1: =SUBTOTAL(9,F3:F1048576) -> 1555100 | G1: =SUBTOTAL(9,G3:G1048576) -> 0 | H1: =SUBTOTAL(9,H3:H1048576) -> 1560808 | I1: =SUBTOTAL(9,I3:I1048576) -> 1.5275375e+10 | J1: =SUBTOTAL(9,J3:J1048576) -> 87189840000
A2: 순서 | B2: 0 | C2: 품번색상 | D2: 사이즈 | E2: 분류 | F2: 입고수량 | G2: 미입고수량 | H2: 기획수량 | I2: 원가 | J2: TAG가
A3: 1 | B3: =IF(C2=C3,B2,B2+1) -> 1 | C3: NHLSNF3001BK | D3: FRE | E3: B | F3: 792 | G3: 0 | H3: 792 | I3: 8990261.3 | J3: 34056000
A4: 2 | B4: =IF(C3=C4,B3,B3+1) -> 2 | C4: NHLSNF3002BK | D4: FRE | E4: B | F4: 792 | G4: 0 | H4: 792 | I4: 8990261.3 | J4: 34056000
A5: 3 | B5: =IF(C4=C5,B4,B4+1) -> 3 | C5: NHLSNF3003BK | D5: FRE | E5: B | F5: 792 | G5: 0 | H5: 792 | I5: 8990261.3 | J5: 34056000
A6: 4 | B6: =IF(C5=C6,B5,B5+1) -> 4 | C6: NHLSNF3004RE | D6: FRE | E6: B | F6: 600 | G6: 0 | H6: 600 | I6: 8180449.2 | J6: 28200000
A7: 5 | B7: =IF(C6=C7,B6,B6+1) -> 5 | C7: NHLSNF3005BK | D7: FRE | E7: B | F7: 996 | G7: 0 | H7: 996 | I7: 12337135 | J7: 44820000
A8: 6 | B8: =IF(C7=C8,B7,B7+1) -> 6 | C8: NHLSNF3006NY | D8: FRE | E8: B | F8: 600 | G8: 0 | H8: 600 | I8: 7432009.2 | J8: 27000000
A9: 7 | B9: =IF(C8=C9,B8,B8+1) -> 7 | C9: NHLSNF3007RE | D9: FRE | E9: B | F9: 600 | G9: 0 | H9: 600 | I9: 7432009.2 | J9: 27000000
A10: 8 | B10: =IF(C9=C10,B9,B9+1) -> 8 | C10: NHLSNF3008WH | D10: FRE | E10: B | F10: 600 | G10: 0 | H10: 600 | I10: 7432009.2 | J10: 27000000
A11: 9 | B11: =IF(C10=C11,B10,B10+1) -> 9 | C11: NHLFIF3009BK | D11: 714 | E11: B | F11: 120 | G11: 0 | H11: 120 | I11: 1486401.8 | J11: 5400000
A12: 10 | B12: =IF(C11=C12,B11,B11+1) -> 9 | C12: NHLFIF3009BK | D12: 738 | E12: B | F12: 192 | G12: 0 | H12: 192 | I12: 2378242.9 | J12: 8640000
A13: 11 | B13: =IF(C12=C13,B12,B12+1) -> 9 | C13: NHLFIF3009BK | D13: 712 | E13: B | F13: 192 | G13: 0 | H13: 192 | I13: 2378242.9 | J13: 8640000
A14: 12 | B14: =IF(C13=C14,B13,B13+1) -> 9 | C14: NHLFIF3009BK | D14: 758 | E14: B | F14: 108 | G14: 0 | H14: 108 | I14: 1337761.7 | J14: 4860000
A15: 13 | B15: =IF(C14=C15,B14,B14+1) -> 9 | C15: NHLFIF3009BK | D15: 734 | E15: B | F15: 96 | G15: 0 | H15: 96 | I15: 1189121.5 | J15: 4320000
A16: 14 | B16: =IF(C15=C16,B15,B15+1) -> 9 | C16: NHLFIF3009BK | D16: 778 | E16: B | F16: 84 | G16: 0 | H16: 84 | I16: 1040481.3 | J16: 3780000
A17: 15 | B17: =IF(C16=C17,B16,B16+1) -> 10 | C17: NHLFIF3010BK | D17: 714 | E17: B | F17: 120 | G17: 0 | H17: 120 | I17: 1486401.8 | J17: 5400000
A18: 16 | B18: =IF(C17=C18,B17,B17+1) -> 10 | C18: NHLFIF3010BK | D18: 738 | E18: B | F18: 192 | G18: 0 | H18: 192 | I18: 2378242.9 | J18: 8640000
A19: 17 | B19: =IF(C18=C19,B18,B18+1) -> 10 | C19: NHLFIF3010BK | D19: 712 | E19: B | F19: 192 | G19: 0 | H19: 192 | I19: 2378242.9 | J19: 8640000
A20: 18 | B20: =IF(C19=C20,B19,B19+1) -> 10 | C20: NHLFIF3010BK | D20: 758 | E20: B | F20: 108 | G20: 0 | H20: 108 | I20: 1337761.7 | J20: 4860000
A21: 19 | B21: =IF(C20=C21,B20,B20+1) -> 10 | C21: NHLFIF3010BK | D21: 734 | E21: B | F21: 96 | G21: 0 | H21: 96 | I21: 1189121.5 | J21: 4320000
A22: 20 | B22: =IF(C21=C22,B21,B21+1) -> 10 | C22: NHLFIF3010BK | D22: 778 | E22: B | F22: 84 | G22: 0 | H22: 84 | I22: 1040481.3 | J22: 3780000
A23: 21 | B23: =IF(C22=C23,B22,B22+1) -> 11 | C23: NHLSNF3011BK | D23: FRE | E23: B | F23: 780 | G23: 0 | H23: 792 | I23: 9810252.1 | J23: 35640000
A24: 22 | B24: =IF(C23=C24,B23,B23+1) -> 12 | C24: NHLSNF3012RE | D24: FRE | E24: B | F24: 792 | G24: 0 | H24: 792 | I24: 9810252.1 | J24: 35640000
A25: 23 | B25: =IF(C24=C25,B24,B24+1) -> 13 | C25: NHLSNF3013BK | D25: FRE | E25: B | F25: 996 | G25: 0 | H25: 996 | I25: 13219247 | J25: 46812000
A26: 24 | B26: =IF(C25=C26,B25,B25+1) -> 14 | C26: NHLSNF3014BK | D26: FRE | E26: B | F26: 996 | G26: 0 | H26: 996 | I26: 13219247 | J26: 46812000
A27: 25 | B27: =IF(C26=C27,B26,B26+1) -> 15 | C27: NHLSNF3015BK | D27: FRE | E27: B | F27: 996 | G27: 0 | H27: 996 | I27: 11492296 | J27: 42828000
A28: 26 | B28: =IF(C27=C28,B27,B27+1) -> 16 | C28: NHLSNF3016BK | D28: FRE | E28: B | F28: 996 | G28: 0 | H28: 996 | I28: 11492296 | J28: 42828000
A29: 27 | B29: =IF(C28=C29,B28,B28+1) -> 17 | C29: NHLFIF3017PP | D29: 714 | E29: B | F29: 120 | G29: 0 | H29: 120 | I29: 1486401.8 | J29: 5400000
A30: 28 | B30: =IF(C29=C30,B29,B29+1) -> 17 | C30: NHLFIF3017PP | D30: 738 | E30: B | F30: 192 | G30: 0 | H30: 192 | I30: 2378242.9 | J30: 8640000
A31: 29 | B31: =IF(C30=C31,B30,B30+1) -> 17 | C31: NHLFIF3017PP | D31: 712 | E31: B | F31: 192 | G31: 0 | H31: 192 | I31: 2378242.9 | J31: 8640000
A32: 30 | B32: =IF(C31=C32,B31,B31+1) -> 17 | C32: NHLFIF3017PP | D32: 758 | E32: B | F32: 96 | G32: 0 | H32: 96 | I32: 1189121.5 | J32: 4320000
A33: 31 | B33: =IF(C32=C33,B32,B32+1) -> 18 | C33: NHLFIF3018BU | D33: 714 | E33: B | F33: 120 | G33: 0 | H33: 120 | I33: 1486401.8 | J33: 5400000
A34: 32 | B34: =IF(C33=C34,B33,B33+1) -> 18 | C34: NHLFIF3018BU | D34: 738 | E34: B | F34: 192 | G34: 0 | H34: 192 | I34: 2378242.9 | J34: 8640000
A35: 33 | B35: =IF(C34=C35,B34,B34+1) -> 18 | C35: NHLFIF3018BU | D35: 712 | E35: B | F35: 192 | G35: 0 | H35: 192 | I35: 2378242.9 | J35: 8640000
A36: 34 | B36: =IF(C35=C36,B35,B35+1) -> 18 | C36: NHLFIF3018BU | D36: 758 | E36: B | F36: 96 | G36: 0 | H36: 96 | I36: 1189121.5 | J36: 4320000
A37: 35 | B37: =IF(C36=C37,B36,B36+1) -> 19 | F37: 14112 | G37: 0 | H37: 14124 | I37: 1.7331251e+08 | J37: 632028000
A38: 36 | B38: =IF(C37=C38,B37,B37+1) -> 20 | C38: NHLSNF3019BK | D38: FRE | E38: B | F38: 996 | G38: 0 | H38: 996 | I38: 11492296 | J38: 42828000
A39: 37 | B39: =IF(C38=C39,B38,B38+1) -> 21 | C39: NHLSNF3019GY | D39: FRE | E39: B | F39: 996 | G39: 0 | H39: 996 | I39: 11492296 | J39: 42828000
A40: 38 | B40: =IF(C39=C40,B39,B39+1) -> 22 | C40: NHLSNF3019PP | D40: FRE | E40: B | F40: 792 | G40: 0 | H40: 792 | I40: 9138452.4 | J40: 34056000
...

Sheet P
D3: 데이터
A4: 0 | B4: 품번색상 | C4: 분류 | D4: 기획수량 | E4: TAG가 | F4: 원가 | G4: 배수 | H4: 입고수량 | I4: 미입고수량
A5: 1 | B5: NHLSNF3001BK | C5: B | D5: 792 | E5: 34056000 | F5: 8990261.3 | G5: 3.4437264 | H5: 792 | I5: 0
A6: 2 | B6: NHLSNF3002BK | C6: B | D6: 792 | E6: 34056000 | F6: 8990261.3 | G6: 3.4437264 | H6: 792 | I6: 0
A7: 3 | B7: NHLSNF3003BK | C7: B | D7: 792 | E7: 34056000 | F7: 8990261.3 | G7: 3.4437264 | H7: 792 | I7: 0
A8: 4 | B8: NHLSNF3004RE | C8: B | D8: 600 | E8: 28200000 | F8: 8180449.2 | G8: 3.1338577 | H8: 600 | I8: 0
A9: 5 | B9: NHLSNF3005BK | C9: B | D9: 996 | E9: 44820000 | F9: 12337135 | G9: 3.3026674 | H9: 996 | I9: 0
A10: 6 | B10: NHLSNF3006NY | C10: B | D10: 600 | E10: 27000000 | F10: 7432009.2 | G10: 3.3026674 | H10: 600 | I10: 0
A11: 7 | B11: NHLSNF3007RE | C11: B | D11: 600 | E11: 27000000 | F11: 7432009.2 | G11: 3.3026674 | H11: 600 | I11: 0
A12: 8 | B12: NHLSNF3008WH | C12: B | D12: 600 | E12: 27000000 | F12: 7432009.2 | G12: 3.3026674 | H12: 600 | I12: 0
A13: 9 | B13: NHLFIF3009BK | C13: B | D13: 792 | E13: 35640000 | F13: 9810252.1 | G13: 3.3026674 | H13: 792 | I13: 0
A14: 10 | B14: NHLFIF3010BK | C14: B | D14: 792 | E14: 35640000 | F14: 9810252.1 | G14: 3.3026674 | H14: 792 | I14: 0
A15: 11 | B15: NHLSNF3011BK | C15: B | D15: 792 | E15: 35640000 | F15: 9810252.1 | G15: 3.3026674 | H15: 780 | I15: 0
A16: 12 | B16: NHLSNF3012RE | C16: B | D16: 792 | E16: 35640000 | F16: 9810252.1 | G16: 3.3026674 | H16: 792 | I16: 0
... A834: 1053 | B834: SHLFAF5005BK | C834: B | D834: 5 | E834: 295000 | F834: 120781.82 | G834: 2.2203824 | H834: 5 | I834: 0
A835: 총합계 | D835: 781404 | E835: 43708920000 | F835: 7.6630327e+09 | G835: 5.1853337 | H835: 778550 | I835: 0

Sheet DB2
A1: 러닝/신규 | B1: 최초/리오더 | C1: 품번(최초) | D1: 품번수(최초) | E1: 품번(리오더) | F1: 품번수(리오더) | G1: 품번색상(최초) | H1: 색상수(최초) | I1: 품번색상(리오더) | J1: 색상수(리오더) | K1: 년도시즌 | L1: 품목2 | M1: 브랜드 | N1: 품목 | O1: 브랜드품목 | P1: 성별 | Q1: 품번 | R1: 품번색상 | S1: 분류 | T1: 기획수량 | U1: TAG가 | V1: 원가(-V) | W1: 배수 | X1: 입고수량 | Y1: 미입고수량
A2: =IF(OR(MID(R2,8,1)="0",MID(R2,8,1)="5"),"신규","러닝") -> 신규 | B2: =IF(COUNTIF(R$1:R1,R2)=0,"최초","리오더") -> 최초 | C2: =IF($B2="리오더","",Q2) -> NHLSNF3001 | D2: =IF(C2="",0,1/COUNTIF(C:C,C2)) -> 1 | E2: =IF($B2="리오더",Q2,"") | F2: =IF(E2="",0,1/COUNTIF(E:E,E2)) -> 0 | G2: =IF($B2="리오더","",R2) -> NHLSNF3001BK | H2: =IF(G2="",0,1/COUNTIF(G:G,G2)) -> 1 | I2: =IF($B2="리오더",R2,"") | J2: =IF(I2="",0,1/COUNTIF(I:I,I2)) -> 0 | K2: =MID(R2,6,2) -> F3 | L2: =VLOOKUP(N2,CODE!K:P,CODE!$P$1,FALSE) -> 모자 | M2: =VLOOKUP(MID(R2,1,3),CODE!$B:$G,CODE!D$1,FALSE) -> NHL | N2: =MID(R2,4,2) -> SN | O2: =IF(ISERROR(IF(VLOOKUP($N2,CODE!$K:$P,CODE!$O$1,FALSE)="",$M2,$M2&"-"&VLOOKUP($N2,CODE!$K:$P,CODE!$O$1,FALSE)))=TRUE,"",IF(VLOOKUP($N2,CODE!$K:$P,CODE!$O$1,FALSE)="",$M2,$M2&"-"&VLOOKUP($N2,CODE!$K:$P,CODE!$O$1,FALSE))) -> NHL | P2: =IF(OR(MID(R2,8,1)="0",MID(R2,8,1)="1",MID(R2,8,1)="2",MID(R2,8,1)="3",MID(R2,8,1)="4"),"성인","키즈") -> 성인 | Q2: =MID(R2,1,10) -> NHLSNF3001 | R2: NHLSNF3001BK | S2: B | T2: 792 | U2: 34056000 | V2: 8990261.3 | W2: 3.4437264 | X2: 792 | Y2: 0
A3: =IF(OR(MID(R3,8,1)="0",MID(R3,8,1)="5"),"신규","러닝") -> 신규 | B3: =IF(COUNTIF(R$1:R2,R3)=0,"최초","리오더") -> 최초 | C3: =IF($B3="리오더","",Q3) -> NHLSNF3002 | D3: =IF(C3="",0,1/COUNTIF(C:C,C3)) -> 1 | E3: =IF($B3="리오더",Q3,"") | F3: =IF(E3="",0,1/COUNTIF(E:E,E3)) -> 0 | G3: =IF($B3="리오더","",R3) -> NHLSNF3002BK | H3: =IF(G3="",0,1/COUNTIF(G:G,G3)) -> 1 | I3: =IF($B3="리오더",R3,"") | J3: =IF(I3="",0,1/COUNTIF(I:I,I3)) -> 0 | K3: =MID(R3,6,2) -> F3 | L3: =VLOOKUP(N3,CODE!K:P,CODE!$P$1,FALSE) -> 모자 | M3: =VLOOKUP(MID(R3,1,3),CODE!$B:$G,CODE!D$1,FALSE) -> NHL | N3: =MID(R3,4,2) -> SN | O3: =IF(ISERROR(IF(VLOOKUP($N3,CODE!$K:$P,CODE!$O$1,FALSE)="",$M3,$M3&"-"&VLOOKUP($N3,CODE!$K:$P,CODE!$O$1,FALSE)))=TRUE,"",IF(VLOOKUP($N3,CODE!$K:$P,CODE!$O$1,FALSE)="",$M3,$M3&"-"&VLOOKUP($N3,CODE!$K:$P,CODE!$O$1,FALSE))) -> NHL | P3: =IF(OR(MID(R3,8,1)="0",MID(R3,8,1)="1",MID(R3,8,1)="2",MID(R3,8,1)="3",MID(R3,8,1)="4"),"성인","키즈") -> 성인 | Q3: =MID(R3,1,10) -> NHLSNF3002 | R3: NHLSNF3002BK | S3: B | T3: 792 | U3: 34056000 | V3: 8990261.3 | W3: 3.4437264 | X3: 792 | Y3: 0
A4: =IF(OR(MID(R4,8,1)="0",MID(R4,8,1)="5"),"신규","러닝") -> 신규 | B4: =IF(COUNTIF(R$1:R3,R4)=0,"최초","리오더") -> 최초 | C4: =IF($B4="리오더","",Q4) -> NHLSNF3003 | D4: =IF(C4="",0,1/COUNTIF(C:C,C4)) -> 1 | E4: =IF($B4="리오더",Q4,"") | F4: =IF(E4="",0,1/COUNTIF(E:E,E4)) -> 0 | G4: =IF($B4="리오더","",R4) -> NHLSNF3003BK | H4: =IF(G4="",0,1/COUNTIF(G:G,G4)) -> 1 | I4: =IF($B4="리오더",R4,"") | J4: =IF(I4="",0,1/COUNTIF(I:I,I4)) -> 0 | K4: =MID(R4,6,2) -> F3 | L4: =VLOOKUP(N4,CODE!K:P,CODE!$P$1,FALSE) -> 모자 | M4: =VLOOKUP(MID(R4,1,3),CODE!$B:$G,CODE!D$1,FALSE) -> NHL | N4: =MID(R4,4,2) -> SN | O4: =IF(ISERROR(IF(VLOOKUP($N4,CODE!$K:$P,CODE!$O$1,FALSE)="",$M4,$M4&"-"&VLOOKUP($N4,CODE!$K:$P,CODE!$O$1,FALSE)))=TRUE,"",IF(VLOOKUP($N4,CODE!$K:$P,CODE!$O$1,FALSE)="",$M4,$M4&"-"&VLOOKUP($N4,CODE!$K:$P,CODE!$O$1,FALSE))) -> NHL | P4: =IF(OR(MID(R4,8,1)="0",MID(R4,8,1)="1",MID(R4,8,1)="2",MID(R4,8,1)="3",MID(R4,8,1)="4"),"성인","키즈") -> 성인 | Q4: =MID(R4,1,10) -> NHLSNF3003 | R4: NHLSNF3003BK | S4: B | T4: 792 | U4: 34056000 | V4: 8990261.3 | W4: 3.4437264 | X4: 792 | Y4: 0
A5: =IF(OR(MID(R5,8,1)="0",MID(R5,8,1)="5"),"신규","러닝") -> 신규 | B5: =IF(COUNTIF(R$1:R4,R5)=0,"최초","리오더") -> 최초 | C5: =IF($B5="리오더","",Q5) -> NHLSNF3004 | D5: =IF(C5="",0,1/COUNTIF(C:C,C5)) -> 1 | E5: =IF($B5="리오더",Q5,"") | F5: =IF(E5="",0,1/COUNTIF(E:E,E5)) -> 0 | G5: =IF($B5="리오더","",R5) -> NHLSNF3004RE | H5: =IF(G5="",0,1/COUNTIF(G:G,G5)) -> 1 | I5: =IF($B5="리오더",R5,"") | J5: =IF(I5="",0,1/COUNTIF(I:I,I5)) -> 0 | K5: =MID(R5,6,2) -> F3 | L5: =VLOOKUP(N5,CODE!K:P,CODE!$P$1,FALSE) -> 모자 | M5: =VLOOKUP(MID(R5,1,3),CODE!$B:$G,CODE!D$1,FALSE) -> NHL | N5: =MID(R5,4,2) -> SN | O5: =IF(ISERROR(IF(VLOOKUP($N5,CODE!$K:$P,CODE!$O$1,FALSE)="",$M5,$M5&"-"&VLOOKUP($N5,CODE!$K:$P,CODE!$O$1,FALSE)))=TRUE,"",IF(VLOOKUP($N5,CODE!$K:$P,CODE!$O$1,FALSE)="",$M5,$M5&"-"&VLOOKUP($N5,CODE!$K:$P,CODE!$O$1,FALSE))) -> NHL | P5: =IF(OR(MID(R5,8,1)="0",MID(R5,8,1)="1",MID(R5,8,1)="2",MID(R5,8,1)="3",MID(R5,8,1)="4"),"성인","키즈") -> 성인 | Q5: =MID(R5,1,10) -> NHLSNF3004 | R5: NHLSNF3004RE | S5: B | T5: 600 | U5: 28200000 | V5: 8180449.2 | W5: 3.1338577 | X5: 600 | Y5: 0
A6: =IF(OR(MID(R6,8,1)="0",MID(R6,8,1)="5"),"신규","러닝") -> 신규 | B6: =IF(COUNTIF(R$1:R5,R6)=0,"최초","리오더") -> 최초 | C6: =IF($B6="리오더","",Q6) -> NHLSNF3005 | D6: =IF(C6="",0,1/COUNTIF(C:C,C6)) -> 1 | E6: =IF($B6="리오더",Q6,"") | F6: =IF(E6="",0,1/COUNTIF(E:E,E6)) -> 0 | G6: =IF($B6="리오더","",R6) -> NHLSNF3005BK | H6: =IF(G6="",0,1/COUNTIF(G:G,G6)) -> 1 | I6: =IF($B6="리오더",R6,"") | J6: =IF(I6="",0,1/COUNTIF(I:I,I6)) -> 0 | K6: =MID(R6,6,2) -> F3 | L6: =VLOOKUP(N6,CODE!K:P,CODE!$P$1,FALSE) -> 모자 | M6: =VLOOKUP(MID(R6,1,3),CODE!$B:$G,CODE!D$1,FALSE) -> NHL | N6: =MID(R6,4,2) -> SN | O6: =IF(ISERROR(IF(VLOOKUP($N6,CODE!$K:$P,CODE!$O$1,FALSE)="",$M6,$M6&"-"&VLOOKUP($N6,CODE!$K:$P,CODE!$O$1,FALSE)))=TRUE,"",IF(VLOOKUP($N6,CODE!$K:$P,CODE!$O$1,FALSE)="",$M6,$M6&"-"&VLOOKUP($N6,CODE!$K:$P,CODE!$O$1,FALSE))) -> NHL | P6: =IF(OR(MID(R6,8,1)="0",MID(R6,8,1)="1",MID(R6,8,1)="2",MID(R6,8,1)="3",MID(R6,8,1)="4"),"성인","키즈") -> 성인 | Q6: =MID(R6,1,10) -> NHLSNF3005 | R6: NHLSNF3005BK | S6: B | T6: 996 | U6: 44820000 | V6: 12337135 | W6: 3.3026674 | X6: 996 | Y6: 0
A7: =IF(OR(MID(R7,8,1)="0",MID(R7,8,1)="5"),"신규","러닝") -> 신규 | B7: =IF(COUNTIF(R$1:R6,R7)=0,"최초","리오더") -> 최초 | C7: =IF($B7="리오더","",Q7) -> NHLSNF3006 | D7: =IF(C7="",0,1/COUNTIF(C:C,C7)) -> 1 | E7: =IF($B7="리오더",Q7,"") | F7: =IF(E7="",0,1/COUNTIF(E:E,E7)) -> 0 | G7: =IF($B7="리오더","",R7) -> NHLSNF3006NY | H7: =IF(G7="",0,1/COUNTIF(G:G,G7)) -> 1 | I7: =IF($B7="리오더",R7,"") | J7: =IF(I7="",0,1/COUNTIF(I:I,I7)) -> 0 | K7: =MID(R7,6,2) -> F3 | L7: =VLOOKUP(N7,CODE!K:P,CODE!$P$1,FALSE) -> 모자 | M7: =VLOOKUP(MID(R7,1,3),CODE!$B:$G,CODE!D$1,FALSE) -> NHL | N7: =MID(R7,4,2) -> SN | O7: =IF(ISERROR(IF(VLOOKUP($N7,CODE!$K:$P,CODE!$O$1,FALSE)="",$M7,$M7&"-"&VLOOKUP($N7,CODE!$K:$P,CODE!$O$1,FALSE)))=TRUE,"",IF(VLOOKUP($N7,CODE!$K:$P,CODE!$O$1,FALSE)="",$M7,$M7&"-"&VLOOKUP($N7,CODE!$K:$P,CODE!$O$1,FALSE))) -> NHL | P7: =IF(OR(MID(R7,8,1)="0",MID(R7,8,1)="1",MID(R7,8,1)="2",MID(R7,8,1)="3",MID(R7,8,1)="4"),"성인","키즈") -> 성인 | Q7: =MID(R7,1,10) -> NHLSNF3006 | R7: NHLSNF3006NY | S7: B | T7: 600 | U7: 27000000 | V7: 7432009.2 | W7: 3.3026674 | X7: 600 | Y7: 0
A8: =IF(OR(MID(R8,8,1)="0",MID(R8,8,1)="5"),"신규","러닝") -> 신규 | B8: =IF(COUNTIF(R$1:R7,R8)=0,"최초","리오더") -> 최초 | C8: =IF($B8="리오더","",Q8) -> NHLSNF3007 | D8: =IF(C8="",0,1/COUNTIF(C:C,C8)) -> 1 | E8: =IF($B8="리오더",Q8,"") | F8: =IF(E8="",0,1/COUNTIF(E:E,E8)) -> 0 | G8: =IF($B8="리오더","",R8) -> NHLSNF3007RE | H8: =IF(G8="",0,1/COUNTIF(G:G,G8)) -> 1 | I8: =IF($B8="리오더",R8,"") | J8: =IF(I8="",0,1/COUNTIF(I:I,I8)) -> 0 | K8: =MID(R8,6,2) -> F3 | L8: =VLOOKUP(N8,CODE!K:P,CODE!$P$1,FALSE) -> 모자 | M8: =VLOOKUP(MID(R8,1,3),CODE!$B:$G,CODE!D$1,FALSE) -> NHL | N8: =MID(R8,4,2) -> SN | O8: =IF(ISERROR(IF(VLOOKUP($N8,CODE!$K:$P,CODE!$O$1,FALSE)="",$M8,$M8&"-"&VLOOKUP($N8,CODE!$K:$P,CODE!$O$1,FALSE)))=TRUE,"",IF(VLOOKUP($N8,CODE!$K:$P,CODE!$O$1,FALSE)="",$M8,$M8&"-"&VLOOKUP($N8,CODE!$K:$P,CODE!$O$1,FALSE))) -> NHL | P8: =IF(OR(MID(R8,8,1)="0",MID(R8,8,1)="1",MID(R8,8,1)="2",MID(R8,8,1)="3",MID(R8,8,1)="4"),"성인","키즈") -> 성인 | Q8: =MID(R8,1,10) -> NHLSNF3007 | R8: NHLSNF3007RE | S8: B | T8: 600 | U8: 27000000 | V8: 7432009.2 | W8: 3.3026674 | X8: 600 | Y8: 0
A9: =IF(OR(MID(R9,8,1)="0",MID(R9,8,1)="5"),"신규","러닝") -> 신규 | B9: =IF(COUNTIF(R$1:R8,R9)=0,"최초","리오더") -> 최초 | C9: =IF($B9="리오더","",Q9) -> NHLSNF3008 | D9: =IF(C9="",0,1/COUNTIF(C:C,C9)) -> 1 | E9: =IF($B9="리오더",Q9,"") | F9: =IF(E9="",0,1/COUNTIF(E:E,E9)) -> 0 | G9: =IF($B9="리오더","",R9) -> NHLSNF3008WH | H9: =IF(G9="",0,1/COUNTIF(G:G,G9)) -> 1 | I9: =IF($B9="리오더",R9,"") | J9: =IF(I9="",0,1/COUNTIF(I:I,I9)) -> 0 | K9: =MID(R9,6,2) -> F3 | L9: =VLOOKUP(N9,CODE!K:P,CODE!$P$1,FALSE) -> 모자 | M9: =VLOOKUP(MID(R9,1,3),CODE!$B:$G,CODE!D$1,FALSE) -> NHL | N9: =MID(R9,4,2) -> SN | O9: =IF(ISERROR(IF(VLOOKUP($N9,CODE!$K:$P,CODE!$O$1,FALSE)="",$M9,$M9&"-"&VLOOKUP($N9,CODE!$K:$P,CODE!$O$1,FALSE)))=TRUE,"",IF(VLOOKUP($N9,CODE!$K:$P,CODE!$O$1,FALSE)="",$M9,$M9&"-"&VLOOKUP($N9,CODE!$K:$P,CODE!$O$1,FALSE))) -> NHL | P9: =IF(OR(MID(R9,8,1)="0",MID(R9,8,1)="1",MID(R9,8,1)="2",MID(R9,8,1)="3",MID(R9,8,1)="4"),"성인","키즈") -> 성인 | Q9: =MID(R9,1,10) -> NHLSNF3008 | R9: NHLSNF3008WH | S9: B | T9: 600 | U9: 27000000 | V9: 7432009.2 | W9: 3.3026674 | X9: 600 | Y9: 0
A10: =IF(OR(MID(R10,8,1)="0",MID(R10,8,1)="5"),"신규","러닝") -> 신규 | B10: =IF(COUNTIF(R$1:R9,R10)=0,"최초","리오더") -> 최초 | C10: =IF($B10="리오더","",Q10) -> NHLFIF3009 | D10: =IF(C10="",0,1/COUNTIF(C:C,C10)) -> 1 | E10: =IF($B10="리오더",Q10,"") | F10: =IF(E10="",0,1/COUNTIF(E:E,E10)) -> 0 | G10: =IF($B10="리오더","",R10) -> NHLFIF3009BK | H10: =IF(G10="",0,1/COUNTIF(G:G,G10)) -> 1 | I10: =IF($B10="리오더",R10,"") | J10: =IF(I10="",0,1/COUNTIF(I:I,I10)) -> 0 | K10: =MID(R10,6,2) -> F3 | L10: =VLOOKUP(N10,CODE!K:P,CODE!$P$1,FALSE) -> 모자 | M10: =VLOOKUP(MID(R10,1,3),CODE!$B:$G,CODE!D$1,FALSE) -> NHL | N10: =MID(R10,4,2) -> FI | O10: =IF(ISERROR(IF(VLOOKUP($N10,CODE!$K:$P,CODE!$O$1,FALSE)="",$M10,$M10&"-"&VLOOKUP($N10,CODE!$K:$P,CODE!$O$1,FALSE)))=TRUE,"",IF(VLOOKUP($N10,CODE!$K:$P,CODE!$O$1,FALSE)="",$M10,$M10&"-"&VLOOKUP($N10,CODE!$K:$P,CODE!$O$1,FALSE))) -> NHL | P10: =IF(OR(MID(R10,8,1)="0",MID(R10,8,1)="1",MID(R10,8,1)="2",MID(R10,8,1)="3",MID(R10,8,1)="4"),"성인","키즈") -> 성인 | Q10: =MID(R10,1,10) -> NHLFIF3009 | R10: NHLFIF3009BK | S10: B | T10: 792 | U10: 35640000 | V10: 9810252.1 | W10: 3.3026674 | X10: 792 | Y10: 0
A11: =IF(OR(MID(R11,8,1)="0",MID(R11,8,1)="5"),"신규","러닝") -> 신규 | B11: =IF(COUNTIF(R$1:R10,R11)=0,"최초","리오더") -> 최초 | C11: =IF($B11="리오더","",Q11) -> NHLFIF3010 | D11: =IF(C11="",0,1/COUNTIF(C:C,C11)) -> 1 | E11: =IF($B11="리오더",Q11,"") | F11: =IF(E11="",0,1/COUNTIF(E:E,E11)) -> 0 | G11: =IF($B11="리오더","",R11) -> NHLFIF3010BK | H11: =IF(G11="",0,1/COUNTIF(G:G,G11)) -> 1 | I11: =IF($B11="리오더",R11,"") | J11: =IF(I11="",0,1/COUNTIF(I:I,I11)) -> 0 | K11: =MID(R11,6,2) -> F3 | L11: =VLOOKUP(N11,CODE!K:P,CODE!$P$1,FALSE) -> 모자 | M11: =VLOOKUP(MID(R11,1,3),CODE!$B:$G,CODE!D$1,FALSE) -> NHL | N11: =MID(R11,4,2) -> FI | O11: =IF(ISERROR(IF(VLOOKUP($N11,CODE!$K:$P,CODE!$O$1,FALSE)="",$M11,$M11&"-"&VLOOKUP($N11,CODE!$K:$P,CODE!$O$1,FALSE)))=TRUE,"",IF(VLOOKUP($N11,CODE!$K:$P,CODE!$O$1,FALSE)="",$M11,$M11&"-"&VLOOKUP($N11,CODE!$K:$P,CODE!$O$1,FALSE))) -> NHL | P11: =IF(OR(MID(R11,8,1)="0",MID(R11,8,1)="1",MID(R11,8,1)="2",MID(R11,8,1)="3",MID(R11,8,1)="4"),"성인","키즈") -> 성인 | Q11: =MID(R11,1,10) -> NHLFIF3010 | R11: NHLFIF3010BK | S11: B | T11: 792 | U11: 35640000 | V11: 9810252.1 | W11: 3.3026674 | X11: 792 | Y11: 0
A12: =IF(OR(MID(R12,8,1)="0",MID(R12,8,1)="5"),"신규","러닝") -> 신규 | B12: =IF(COUNTIF(R$1:R11,R12)=0,"최초","리오더") -> 최초 | C12: =IF($B12="리오더","",Q12) -> NHLSNF3011 | D12: =IF(C12="",0,1/COUNTIF(C:C,C12)) -> 1 | E12: =IF($B12="리오더",Q12,"") | F12: =IF(E12="",0,1/COUNTIF(E:E,E12)) -> 0 | G12: =IF($B12="리오더","",R12) -> NHLSNF3011BK | H12: =IF(G12="",0,1/COUNTIF(G:G,G12)) -> 1 | I12: =IF($B12="리오더",R12,"") | J12: =IF(I12="",0,1/COUNTIF(I:I,I12)) -> 0 | K12: =MID(R12,6,2) -> F3 | L12: =VLOOKUP(N12,CODE!K:P,CODE!$P$1,FALSE) -> 모자 | M12: =VLOOKUP(MID(R12,1,3),CODE!$B:$G,CODE!D$1,FALSE) -> NHL | N12: =MID(R12,4,2) -> SN | O12: =IF(ISERROR(IF(VLOOKUP($N12,CODE!$K:$P,CODE!$O$1,FALSE)="",$M12,$M12&"-"&VLOOKUP($N12,CODE!$K:$P,CODE!$O$1,FALSE)))=TRUE,"",IF(VLOOKUP($N12,CODE!$K:$P,CODE!$O$1,FALSE)="",$M12,$M12&"-"&VLOOKUP($N12,CODE!$K:$P,CODE!$O$1,FALSE))) -> NHL | P12: =IF(OR(MID(R12,8,1)="0",MID(R12,8,1)="1",MID(R12,8,1)="2",MID(R12,8,1)="3",MID(R12,8,1)="4"),"성인","키즈") -> 성인 | Q12: =MID(R12,1,10) -> NHLSNF3011 | R12: NHLSNF3011BK | S12: B | T12: 792 | U12: 35640000 | V12: 9810252.1 | W12: 3.3026674 | X12: 780 | Y12: 0
A13: =IF(OR(MID(R13,8,1)="0",MID(R13,8,1)="5"),"신규","러닝") -> 신규 | B13: =IF(COUNTIF(R$1:R12,R13)=0,"최초","리오더") -> 최초 | C13: =IF($B13="리오더","",Q13) -> NHLSNF3012 | D13: =IF(C13="",0,1/COUNTIF(C:C,C13)) -> 1 | E13: =IF($B13="리오더",Q13,"") | F13: =IF(E13="",0,1/COUNTIF(E:E,E13)) -> 0 | G13: =IF($B13="리오더","",R13) -> NHLSNF3012RE | H13: =IF(G13="",0,1/COUNTIF(G:G,G13)) -> 1 | I13: =IF($B13="리오더",R13,"") | J13: =IF(I13="",0,1/COUNTIF(I:I,I13)) -> 0 | K13: =MID(R13,6,2) -> F3 | L13: =VLOOKUP(N13,CODE!K:P,CODE!$P$1,FALSE) -> 모자 | M13: =VLOOKUP(MID(R13,1,3),CODE!$B:$G,CODE!D$1,FALSE) -> NHL | N13: =MID(R13,4,2) -> SN | O13: =IF(ISERROR(IF(VLOOKUP($N13,CODE!$K:$P,CODE!$O$1,FALSE)="",$M13,$M13&"-"&VLOOKUP($N13,CODE!$K:$P,CODE!$O$1,FALSE)))=TRUE,"",IF(VLOOKUP($N13,CODE!$K:$P,CODE!$O$1,FALSE)="",$M13,$M13&"-"&VLOOKUP($N13,CODE!$K:$P,CODE!$O$1,FALSE))) -> NHL | P13: =IF(OR(MID(R13,8,1)="0",MID(R13,8,1)="1",MID(R13,8,1)="2",MID(R13,8,1)="3",MID(R13,8,1)="4"),"성인","키즈") -> 성인 | Q13: =MID(R13,1,10) -> NHLSNF3012 | R13: NHLSNF3012RE | S13: B | T13: 792 | U13: 35640000 | V13: 9810252.1 | W13: 3.3026674 | X13: 792 | Y13: 0
... A65: =IF(OR(MID(R65,8,1)="0",MID(R65,8,1)="5"),"신규","러닝") -> 신규 | B65: =IF(COUNTIF(R$1:R64,R65)=0,"최초","리오더") -> 최초 | C65: =IF($B65="리오더","",Q65) -> MGMSNF3003 | D65: =IF(C65="",0,1/COUNTIF(C:C,C65)) -> 1 | E65: =IF($B65="리오더",Q65,"") | F65: =IF(E65="",0,1/COUNTIF(E:E,E65)) -> 0 | G65: =IF($B65="리오더","",R65) -> MGMSNF3003WH | H65: =IF(G65="",0,1/COUNTIF(G:G,G65)) -> 1 | I65: =IF($B65="리오더",R65,"") | J65: =IF(I65="",0,1/COUNTIF(I:I,I65)) -> 0 | K65: =MID(R65,6,2) -> F3 | L65: =VLOOKUP(N65,CODE!K:P,CODE!$P$1,FALSE) -> 모자 | M65: =VLOOKUP(MID(R65,1,3),CODE!$B:$G,CODE!D$1,FALSE) -> MGM | N65: =MID(R65,4,2) -> SN | O65: =IF(ISERROR(IF(VLOOKUP($N65,CODE!$K:$P,CODE!$O$1,FALSE)="",$M65,$M65&"-"&VLOOKUP($N65,CODE!$K:$P,CODE!$O$1,FALSE)))=TRUE,"",IF(VLOOKUP($N65,CODE!$K:$P,CODE!$O$1,FALSE)="",$M65,$M65&"-"&VLOOKUP($N65,CODE!$K:$P,CODE!$O$1,FALSE))) -> MGM | P65: =IF(OR(MID(R65,8,1)="0",MID(R65,8,1)="1",MID(R65,8,1)="2",MID(R65,8,1)="3",MID(R65,8,1)="4"),"성인","키즈") -> 성인 | Q65: =MID(R65,1,10) -> MGMSNF3003 | R65: MGMSNF3003WH | S65: M | T65: 1000 | U65: 45000000 | V65: 7095000 | W65: 5.7659043 | X65: 1001 | Y65: 0
A66: =IF(OR(MID(R66,8,1)="0",MID(R66,8,1)="5"),"신규","러닝") -> 신규 | B66: 최초 | C66: =IF($B66="리오더","",Q66) -> MGMSNF3004 | D66: =IF(C66="",0,1/COUNTIF(C:C,C66)) -> 1 | E66: =IF($B66="리오더",Q66,"") | F66: =IF(E66="",0,1/COUNTIF(E:E,E66)) -> 0 | G66: =IF($B66="리오더","",R66) -> MGMSNF3004GY | H66: =IF(G66="",0,1/COUNTIF(G:G,G66)) -> 1 | I66: =IF($B66="리오더",R66,"") | J66: =IF(I66="",0,1/COUNTIF(I:I,I66)) -> 0 | K66: =MID(R66,6,2) -> F3 | L66: =VLOOKUP(N66,CODE!K:P,CODE!$P$1,FALSE) -> 모자 | M66: =VLOOKUP(MID(R66,1,3),CODE!$B:$G,CODE!D$1,FALSE) -> MGM | N66: =MID(R66,4,2) -> SN | O66: =IF(ISERROR(IF(VLOOKUP($N66,CODE!$K:$P,CODE!$O$1,FALSE)="",$M66,$M66&"-"&VLOOKUP($N66,CODE!$K:$P,CODE!$O$1,FALSE)))=TRUE,"",IF(VLOOKUP($N66,CODE!$K:$P,CODE!$O$1,FALSE)="",$M66,$M66&"-"&VLOOKUP($N66,CODE!$K:$P,CODE!$O$1,FALSE))) -> MGM | P66: =IF(OR(MID(R66,8,1)="0",MID(R66,8,1)="1",MID(R66,8,1)="2",MID(R66,8,1)="3",MID(R66,8,1)="4"),"성인","키즈") -> 성인 | Q66: =MID(R66,1,10) -> MGMSNF3004 | R66: MGMSNF3004GY | S66: M | T66: 1200 | U66: 54000000 | V66: 8514000 | W66: 5.7659043 | X66: 1188 | Y66: 0
A67: =IF(OR(MID(R67,8,1)="0",MID(R67,8,1)="5"),"신규","러닝") -> 신규 | B67: =IF(COUNTIF(R$1:R66,R67)=0,"최초","리오더") -> 최초 | C67: =IF($B67="리오더","",Q67) -> MGMSNF3005 | D67: =IF(C67="",0,1/COUNTIF(C:C,C67)) -> 1 | E67: =IF($B67="리오더",Q67,"") | F67: =IF(E67="",0,1/COUNTIF(E:E,E67)) -> 0 | G67: =IF($B67="리오더","",R67) -> MGMSNF3005BG | H67: =IF(G67="",0,1/COUNTIF(G:G,G67)) -> 1 | I67: =IF($B67="리오더",R67,"") | J67: =IF(I67="",0,1/COUNTIF(I:I,I67)) -> 0 | K67: =MID(R67,6,2) -> F3 | L67: =VLOOKUP(N67,CODE!K:P,CODE!$P$1,FALSE) -> 모자 | M67: =VLOOKUP(MID(R67,1,3),CODE!$B:$G,CODE!D$1,FALSE) -> MGM | N67: =MID(R67,4,2) -> SN | O67: =IF(ISERROR(IF(VLOOKUP($N67,CODE!$K:$P,CODE!$O$1,FALSE)="",$M67,$M67&"-"&VLOOKUP($N67,CODE!$K:$P,CODE!$O$1,FALSE)))=TRUE,"",IF(VLOOKUP($N67,CODE!$K:$P,CODE!$O$1,FALSE)="",$M67,$M67&"-"&VLOOKUP($N67,CODE!$K:$P,CODE!$O$1,FALSE))) -> MGM | P67: =IF(OR(MID(R67,8,1)="0",MID(R67,8,1)="1",MID(R67,8,1)="2",MID(R67,8,1)="3",MID(R67,8,1)="4"),"성인","키즈") -> 성인 | Q67: =MID(R67,1,10) -> MGMSNF3005 | R67: MGMSNF3005BG | S67: M | T67: 1000 | U67: 45000000 | V67: 7645000 | W67: 5.351091 | X67: 1003 | Y67: 0
A68: =IF(OR(MID(R68,8,1)="0",MID(R68,8,1)="5"),"신규","러닝") -> 신규 | B68: =IF(COUNTIF(R$1:R67,R68)=0,"최초","리오더") -> 최초 | C68: =IF($B68="리오더","",Q68) -> MGMSNF3006 | D68: =IF(C68="",0,1/COUNTIF(C:C,C68)) -> 1 | E68: =IF($B68="리오더",Q68,"") | F68: =IF(E68="",0,1/COUNTIF(E:E,E68)) -> 0 | G68: =IF($B68="리오더","",R68) -> MGMSNF3006GY | H68: =IF(G68="",0,1/COUNTIF(G:G,G68)) -> 1 | I68: =IF($B68="리오더",R68,"") | J68: =IF(I68="",0,1/COUNTIF(I:I,I68)) -> 0 | K68: =MID(R68,6,2) -> F3 | L68: =VLOOKUP(N68,CODE!K:P,CODE!$P$1,FALSE) -> 모자 | M68: =VLOOKUP(MID(R68,1,3),CODE!$B:$G,CODE!D$1,FALSE) -> MGM | N68: =MID(R68,4,2) -> SN | O68: =IF(ISERROR(IF(VLOOKUP($N68,CODE!$K:$P,CODE!$O$1,FALSE)="",$M68,$M68&"-"&VLOOKUP($N68,CODE!$K:$P,CODE!$O$1,FALSE)))=TRUE,"",IF(VLOOKUP($N68,CODE!$K:$P,CODE!$O$1,FALSE)="",$M68,$M68&"-"&VLOOKUP($N68,CODE!$K:$P,CODE!$O$1,FALSE))) -> MGM | P68: =IF(OR(MID(R68,8,1)="0",MID(R68,8,1)="1",MID(R68,8,1)="2",MID(R68,8,1)="3",MID(R68,8,1)="4"),"성인","키즈") -> 성인 | Q68: =MID(R68,1,10) -> MGMSNF3006 | R68: MGMSNF3006GY | S68: M | T68: 1000 | U68: 45000000 | V68: 7920000 | W68: 5.1652893 | X68: 977 | Y68: 0
A69: =IF(OR(MID(R69,8,1)="0",MID(R69,8,1)="5"),"신규","러닝") -> 신규 | B69: =IF(COUNTIF(R$1:R68,R69)=0,"최초","리오더") -> 최초 | C69: =IF($B69="리오더","",Q69) -> MGMSNF3007 | D69: =IF(C69="",0,1/COUNTIF(C:C,C69)) -> 1 | E69: =IF($B69="리오더",Q69,"") | F69: =IF(E69="",0,1/COUNTIF(E:E,E69)) -> 0 | G69: =IF($B69="리오더","",R69) -> MGMSNF3007BL | H69: =IF(G69="",0,1/COUNTIF(G:G,G69)) -> 1 | I69: =IF($B69="리오더",R69,"") | J69: =IF(I69="",0,1/COUNTIF(I:I,I69)) -> 0 | K69: =MID(R69,6,2) -> F3 | L69: =VLOOKUP(N69,CODE!K:P,CODE!$P$1,FALSE) -> 모자 | M69: =VLOOKUP(MID(R69,1,3),CODE!$B:$G,CODE!D$1,FALSE) -> MGM | N69: =MID(R69,4,2) -> SN | O69: =IF(ISERROR(IF(VLOOKUP($N69,CODE!$K:$P,CODE!$O$1,FALSE)="",$M69,$M69&"-"&VLOOKUP($N69,CODE!$K:$P,CODE!$O$1,FALSE)))=TRUE,"",IF(VLOOKUP($N69,CODE!$K:$P,CODE!$O$1,FALSE)="",$M69,$M69&"-"&VLOOKUP($N69,CODE!$K:$P,CODE!$O$1,FALSE))) -> MGM | P69: =IF(OR(MID(R69,8,1)="0",MID(R69,8,1)="1",MID(R69,8,1)="2",MID(R69,8,1)="3",MID(R69,8,1)="4"),"성인","키즈") -> 성인 | Q69: =MID(R69,1,10) -> MGMSNF3007 | R69: MGMSNF3007BL | S69: M | T69: 1200 | U69: 54000000 | V69: 7870272 | W69: 6.2375111 | X69: 1176 | Y69: 0
A70: =IF(OR(MID(R70,8,1)="0",MID(R70,8,1)="5"),"신규","러닝") -> 신규 | B70: =IF(COUNTIF(R$1:R69,R70)=0,"최초","리오더") -> 최초 | C70: =IF($B70="리오더","",Q70) -> MGMSNF3008 | D70: =IF(C70="",0,1/COUNTIF(C:C,C70)) -> 1 | E70: =IF($B70="리오더",Q70,"") | F70: =IF(E70="",0,1/COUNTIF(E:E,E70)) -> 0 | G70: =IF($B70="리오더","",R70) -> MGMSNF3008BK | H70: =IF(G70="",0,1/COUNTIF(G:G,G70)) -> 1 | I70: =IF($B70="리오더",R70,"") | J70: =IF(I70="",0,1/COUNTIF(I:I,I70)) -> 0 | K70: =MID(R70,6,2) -> F3 | L70: =VLOOKUP(N70,CODE!K:P,CODE!$P$1,FALSE) -> 모자 | M70: =VLOOKUP(MID(R70,1,3),CODE!$B:$G,CODE!D$1,FALSE) -> MGM | N70: =MID(R70,4,2) -> SN | O70: =IF(ISERROR(IF(VLOOKUP($N70,CODE!$K:$P,CODE!$O$1,FALSE)="",$M70,$M70&"-"&VLOOKUP($N70,CODE!$K:$P,CODE!$O$1,FALSE)))=TRUE,"",IF(VLOOKUP($N70,CODE!$K:$P,CODE!$O$1,FALSE)="",$M70,$M70&"-"&VLOOKUP($N70,CODE!$K:$P,CODE!$O$1,FALSE))) -> MGM | P70: =IF(OR(MID(R70,8,1)="0",MID(R70,8,1)="1",MID(R70,8,1)="2",MID(R70,8,1)="3",MID(R70,8,1)="4"),"성인","키즈") -> 성인 | Q70: =MID(R70,1,10) -> MGMSNF3008 | R70: MGMSNF3008BK | S70: M | T70: 1200 | U70: 54000000 | V70: 7952130 | W70: 6.1733031 | X70: 1199 | Y70: 0
A71: =IF(OR(MID(R71,8,1)="0",MID(R71,8,1)="5"),"신규","러닝") -> 신규 | B71: =IF(COUNTIF(R$1:R70,R71)=0,"최초","리오더") -> 최초 | C71: =IF($B71="리오더","",Q71) -> MGMSNF3009 | D71: =IF(C71="",0,1/COUNTIF(C:C,C71)) -> 1 | E71: =IF($B71="리오더",Q71,"") | F71: =IF(E71="",0,1/COUNTIF(E:E,E71)) -> 0 | G71: =IF($B71="리오더","",R71) -> MGMSNF3009GY | H71: =IF(G71="",0,1/COUNTIF(G:G,G71)) -> 1 | I71: =IF($B71="리오더",R71,"") | J71: =IF(I71="",0,1/COUNTIF(I:I,I71)) -> 0 | K71: =MID(R71,6,2) -> F3 | L71: =VLOOKUP(N71,CODE!K:P,CODE!$P$1,FALSE) -> 모자 | M71: =VLOOKUP(MID(R71,1,3),CODE!$B:$G,CODE!D$1,FALSE) -> MGM | N71: =MID(R71,4,2) -> SN | O71: =IF(ISERROR(IF(VLOOKUP($N71,CODE!$K:$P,CODE!$O$1,FALSE)="",$M71,$M71&"-"&VLOOKUP($N71,CODE!$K:$P,CODE!$O$1,FALSE)))=TRUE,"",IF(VLOOKUP($N71,CODE!$K:$P,CODE!$O$1,FALSE)="",$M71,$M71&"-"&VLOOKUP($N71,CODE!$K:$P,CODE!$O$1,FALSE))) -> MGM | P71: =IF(OR(MID(R71,8,1)="0",MID(R71,8,1)="1",MID(R71,8,1)="2",MID(R71,8,1)="3",MID(R71,8,1)="4"),"성인","키즈") -> 성인 | Q71: =MID(R71,1,10) -> MGMSNF3009 | R71: MGMSNF3009GY | S71: M | T71: 1000 | U71: 45000000 | V71: 6780940 | W71: 6.0329528 | X71: 963 | Y71: 0
A72: =IF(OR(MID(R72,8,1)="0",MID(R72,8,1)="5"),"신규","러닝") -> 신규 | B72: =IF(COUNTIF(R$1:R71,R72)=0,"최초","리오더") -> 최초 | C72: =IF($B72="리오더","",Q72) -> MGMSNF3010 | D72: =IF(C72="",0,1/COUNTIF(C:C,C72)) -> 1 | E72: =IF($B72="리오더",Q72,"") | F72: =IF(E72="",0,1/COUNTIF(E:E,E72)) -> 0 | G72: =IF($B72="리오더","",R72) -> MGMSNF3010KH | H72: =IF(G72="",0,1/COUNTIF(G:G,G72)) -> 1 | I72: =IF($B72="리오더",R72,"") | J72: =IF(I72="",0,1/COUNTIF(I:I,I72)) -> 0 | K72: =MID(R72,6,2) -> F3 | L72: =VLOOKUP(N72,CODE!K:P,CODE!$P$1,FALSE) -> 모자 | M72: =VLOOKUP(MID(R72,1,3),CODE!$B:$G,CODE!D$1,FALSE) -> MGM | N72: =MID(R72,4,2) -> SN | O72: =IF(ISERROR(IF(VLOOKUP($N72,CODE!$K:$P,CODE!$O$1,FALSE)="",$M72,$M72&"-"&VLOOKUP($N72,CODE!$K:$P,CODE!$O$1,FALSE)))=TRUE,"",IF(VLOOKUP($N72,CODE!$K:$P,CODE!$O$1,FALSE)="",$M72,$M72&"-"&VLOOKUP($N72,CODE!$K:$P,CODE!$O$1,FALSE))) -> MGM | P72: =IF(OR(MID(R72,8,1)="0",MID(R72,8,1)="1",MID(R72,8,1)="2",MID(R72,8,1)="3",MID(R72,8,1)="4"),"성인","키즈") -> 성인 | Q72: =MID(R72,1,10) -> MGMSNF3010 | R72: MGMSNF3010KH | S72: M | T72: 1000 | U72: 45000000 | V72: 6727590 | W72: 6.0807943 | X72: 931 | Y72: 0
A73: =IF(OR(MID(R73,8,1)="0",MID(R73,8,1)="5"),"신규","러닝") -> 신규 | B73: =IF(COUNTIF(R$1:R72,R73)=0,"최초","리오더") -> 최초 | C73: =IF($B73="리오더","",Q73) -> MGMSNF3011 | D73: =IF(C73="",0,1/COUNTIF(C:C,C73)) -> 1 | E73: =IF($B73="리오더",Q73,"") | F73: =IF(E73="",0,1/COUNTIF(E:E,E73)) -> 0 | G73: =IF($B73="리오더","",R73) -> MGMSNF3011NY | H73: =IF(G73="",0,1/COUNTIF(G:G,G73)) -> 1 | I73: =IF($B73="리오더",R73,"") | J73: =IF(I73="",0,1/COUNTIF(I:I,I73)) -> 0 | K73: =MID(R73,6,2) -> F3 | L73: =VLOOKUP(N73,CODE!K:P,CODE!$P$1,FALSE) -> 모자 | M73: =VLOOKUP(MID(R73,1,3),CODE!$B:$G,CODE!D$1,FALSE) -> MGM | N73: =MID(R73,4,2) -> SN | O73: =IF(ISERROR(IF(VLOOKUP($N73,CODE!$K:$P,CODE!$O$1,FALSE)="",$M73,$M73&"-"&VLOOKUP($N73,CODE!$K:$P,CODE!$O$1,FALSE)))=TRUE,"",IF(VLOOKUP($N73,CODE!$K:$P,CODE!$O$1,FALSE)="",$M73,$M73&"-"&VLOOKUP($N73,CODE!$K:$P,CODE!$O$1,FALSE))) -> MGM | P73: =IF(OR(MID(R73,8,1)="0",MID(R73,8,1)="1",MID(R73,8,1)="2",MID(R73,8,1)="3",MID(R73,8,1)="4"),"성인","키즈") -> 성인 | Q73: =MID(R73,1,10) -> MGMSNF3011 | R73: MGMSNF3011NY | S73: M | T73: 1000 | U73: 45000000 | V73: 3668240 | W73: 11.152239 | X73: 971 | Y73: 0
A74: =IF(OR(MID(R74,8,1)="0",MID(R74,8,1)="5"),"신규","러닝") -> 신규 | B74: =IF(COUNTIF(R$1:R73,R74)=0,"최초","리오더") -> 최초 | C74: =IF($B74="리오더","",Q74) -> MGMSNF3012 | D74: =IF(C74="",0,1/COUNTIF(C:C,C74)) -> 1 | E74: =IF($B74="리오더",Q74,"") | F74: =IF(E74="",0,1/COUNTIF(E:E,E74)) -> 0 | G74: =IF($B74="리오더","",R74) -> MGMSNF3012BK | H74: =IF(G74="",0,1/COUNTIF(G:G,G74)) -> 1 | I74: =IF($B74="리오더",R74,"") | J74: =IF(I74="",0,1/COUNTIF(I:I,I74)) -> 0 | K74: =MID(R74,6,2) -> F3 | L74: =VLOOKUP(N74,CODE!K:P,CODE!$P$1,FALSE) -> 모자 | M74: =VLOOKUP(MID(R74,1,3),CODE!$B:$G,CODE!D$1,FALSE) -> MGM | N74: =MID(R74,4,2) -> SN | O74: =IF(ISERROR(IF(VLOOKUP($N74,CODE!$K:$P,CODE!$O$1,FALSE)="",$M74,$M74&"-"&VLOOKUP($N74,CODE!$K:$P,CODE!$O$1,FALSE)))=TRUE,"",IF(VLOOKUP($N74,CODE!$K:$P,CODE!$O$1,FALSE)="",$M74,$M74&"-"&VLOOKUP($N74,CODE!$K:$P,CODE!$O$1,FALSE))) -> MGM | P74: =IF(OR(MID(R74,8,1)="0",MID(R74,8,1)="1",MID(R74,8,1)="2",MID(R74,8,1)="3",MID(R74,8,1)="4"),"성인","키즈") -> 성인 | Q74: =MID(R74,1,10) -> MGMSNF3012 | R74: MGMSNF3012BK | S74: M | T74: 1000 | U74: 45000000 | V74: 4102540 | W74: 9.9716495 | X74: 950 | Y74: 0
A75: =IF(OR(MID(R75,8,1)="0",MID(R75,8,1)="5"),"신규","러닝") -> 신규 | B75: =IF(COUNTIF(R$1:R74,R75)=0,"최초","리오더") -> 최초 | C75: =IF($B75="리오더","",Q75) -> URBFIF3001 | D75: =IF(C75="",0,1/COUNTIF(C:C,C75)) -> 1 | E75: =IF($B75="리오더",Q75,"") | F75: =IF(E75="",0,1/COUNTIF(E:E,E75)) -> 0 | G75: =IF($B75="리오더","",R75) -> URBFIF3001BW | H75: =IF(G75="",0,1/COUNTIF(G:G,G75)) -> 1 | I75: =IF($B75="리오더",R75,"") | J75: =IF(I75="",0,1/COUNTIF(I:I,I75)) -> 0 | K75: =MID(R75,6,2) -> F3 | L75: =VLOOKUP(N75,CODE!K:P,CODE!$P$1,FALSE) -> 모자 | M75: =VLOOKUP(MID(R75,1,3),CODE!$B:$G,CODE!D$1,FALSE) -> URB | N75: =MID(R75,4,2) -> FI | O75: =IF(ISERROR(IF(VLOOKUP($N75,CODE!$K:$P,CODE!$O$1,FALSE)="",$M75,$M75&"-"&VLOOKUP($N75,CODE!$K:$P,CODE!$O$1,FALSE)))=TRUE,"",IF(VLOOKUP($N75,CODE!$K:$P,CODE!$O$1,FALSE)="",$M75,$M75&"-"&VLOOKUP($N75,CODE!$K:$P,CODE!$O$1,FALSE))) -> URB | P75: =IF(OR(MID(R75,8,1)="0",MID(R75,8,1)="1",MID(R75,8,1)="2",MID(R75,8,1)="3",MID(R75,8,1)="4"),"성인","키즈") -> 성인 | Q75: =MID(R75,1,10) -> URBFIF3001 | R75: URBFIF3001BW | S75: M | T75: 800 | U75: 42400000 | V75: 5984000 | W75: 6.4414195 | X75: 800 | Y75: 0
A76: =IF(OR(MID(R76,8,1)="0",MID(R76,8,1)="5"),"신규","러닝") -> 신규 | B76: =IF(COUNTIF(R$1:R75,R76)=0,"최초","리오더") -> 최초 | C76: =IF($B76="리오더","",Q76) -> URBFIF3002 | D76: =IF(C76="",0,1/COUNTIF(C:C,C76)) -> 1 | E76: =IF($B76="리오더",Q76,"") | F76: =IF(E76="",0,1/COUNTIF(E:E,E76)) -> 0 | G76: =IF($B76="리오더","",R76) -> URBFIF3002BK | H76: =IF(G76="",0,1/COUNTIF(G:G,G76)) -> 1 | I76: =IF($B76="리오더",R76,"") | J76: =IF(I76="",0,1/COUNTIF(I:I,I76)) -> 0 | K76: =MID(R76,6,2) -> F3 | L76: =VLOOKUP(N76,CODE!K:P,CODE!$P$1,FALSE) -> 모자 | M76: =VLOOKUP(MID(R76,1,3),CODE!$B:$G,CODE!D$1,FALSE) -> URB | N76: =MID(R76,4,2) -> FI | O76: =IF(ISERROR(IF(VLOOKUP($N76,CODE!$K:$P,CODE!$O$1,FALSE)="",$M76,$M76&"-"&VLOOKUP($N76,CODE!$K:$P,CODE!$O$1,FALSE)))=TRUE,"",IF(VLOOKUP($N76,CODE!$K:$P,CODE!$O$1,FALSE)="",$M76,$M76&"-"&VLOOKUP($N76,CODE!$K:$P,CODE!$O$1,FALSE))) -> URB | P76: =IF(OR(MID(R76,8,1)="0",MID(R76,8,1)="1",MID(R76,8,1)="2",MID(R76,8,1)="3",MID(R76,8,1)="4"),"성인","키즈") -> 성인 | Q76: =MID(R76,1,10) -> URBFIF3002 | R76: URBFIF3002BK | S76: M | T76: 800 | U76: 42400000 | V76: 5984000 | W76: 6.4414195 | X76: 800 | Y76: 0
A77: =IF(OR(MID(R77,8,1)="0",MID(R77,8,1)="5"),"신규","러닝") -> 신규 | B77: =IF(COUNTIF(R$1:R76,R77)=0,"최초","리오더") -> 최초 | C77: =IF($B77="리오더","",Q77) -> PLAUMF5001 | D77: =IF(C77="",0,1/COUNTIF(C:C,C77)) -> 0.25 | E77: =IF($B77="리오더",Q77,"") | F77: =IF(E77="",0,1/COUNTIF(E:E,E77)) -> 0 | G77: =IF($B77="리오더","",R77) -> PLAUMF5001RE | H77: =IF(G77="",0,1/COUNTIF(G:G,G77)) -> 1 | I77: =IF($B77="리오더",R77,"") | J77: =IF(I77="",0,1/COUNTIF(I:I,I77)) -> 0 | K77: =MID(R77,6,2) -> F5 | L77: =VLOOKUP(N77,CODE!K:P,CODE!$P$1,FALSE) -> 모자 | M77: =VLOOKUP(MID(R77,1,3),CODE!$B:$G,CODE!D$1,FALSE) -> PLA | N77: =MID(R77,4,2) -> UM | O77: =IF(ISERROR(IF(VLOOKUP($N77,CODE!$K:$P,CODE!$O$1,FALSE)="",$M77,$M77&"-"&VLOOKUP($N77,CODE!$K:$P,CODE!$O$1,FALSE)))=TRUE,"",IF(VLOOKUP($N77,CODE!$K:$P,CODE!$O$1,FALSE)="",$M77,$M77&"-"&VLOOKUP($N77,CODE!$K:$P,CODE!$O$1,FALSE))) -> PLA | P77: =IF(OR(MID(R77,8,1)="0",MID(R77,8,1)="1",MID(R77,8,1)="2",MID(R77,8,1)="3",MID(R77,8,1)="4"),"성인","키즈") -> 성인 | Q77: =MID(R77,1,10) -> PLAUMF5001 | R77: PLAUMF5001RE | S77: M | T77: 1200 | U77: 66000000 | V77: 8382528 | W77: 7.1577453 | X77: 1200 | Y77: 0
A78: =IF(OR(MID(R78,8,1)="0",MID(R78,8,1)="5"),"신규","러닝") -> 신규 | B78: =IF(COUNTIF(R$1:R77,R78)=0,"최초","리오더") -> 최초 | C78: =IF($B78="리오더","",Q78) -> PLAUMF5001 | D78: =IF(C78="",0,1/COUNTIF(C:C,C78)) -> 0.25 | E78: =IF($B78="리오더",Q78,"") | F78: =IF(E78="",0,1/COUNTIF(E:E,E78)) -> 0 | G78: =IF($B78="리오더","",R78) -> PLAUMF5001GY | H78: =IF(G78="",0,1/COUNTIF(G:G,G78)) -> 1 | I78: =IF($B78="리오더",R78,"") | J78: =IF(I78="",0,1/COUNTIF(I:I,I78)) -> 0 | K78: =MID(R78,6,2) -> F5 | L78: =VLOOKUP(N78,CODE!K:P,CODE!$P$1,FALSE) -> 모자 | M78: =VLOOKUP(MID(R78,1,3),CODE!$B:$G,CODE!D$1,FALSE) -> PLA | N78: =MID(R78,4,2) -> UM | O78: =IF(ISERROR(IF(VLOOKUP($N78,CODE!$K:$P,CODE!$O$1,FALSE)="",$M78,$M78&"-"&VLOOKUP($N78,CODE!$K:$P,CODE!$O$1,FALSE)))=TRUE,"",IF(VLOOKUP($N78,CODE!$K:$P,CODE!$O$1,FALSE)="",$M78,$M78&"-"&VLOOKUP($N78,CODE!$K:$P,CODE!$O$1,FALSE))) -> PLA | P78: =IF(OR(MID(R78,8,1)="0",MID(R78,8,1)="1",MID(R78,8,1)="2",MID(R78,8,1)="3",MID(R78,8,1)="4"),"성인","키즈") -> 성인 | Q78: =MID(R78,1,10) -> PLAUMF5001 | R78: PLAUMF5001GY | S78: M | T78: 1000 | U78: 55000000 | V78: 7234920 | W78: 6.9109265 | X78: 1000 | Y78: 0
... A343: =IF(OR(MID(R343,8,1)="0",MID(R343,8,1)="5"),"신규","러닝") -> 신규 | B343: =IF(COUNTIF(R$1:R342,R343)=0,"최초","리오더") -> 최초 | C343: =IF($B343="리오더","",Q343) -> JOIEBF5505 | D343: =IF(C343="",0,1/COUNTIF(C:C,C343)) -> 1 | E343: =IF($B343="리오더",Q343,"") | F343: =IF(E343="",0,1/COUNTIF(E:E,E343)) -> 0 | G343: =IF($B343="리오더","",R343) -> JOIEBF5505BL | H343: =IF(G343="",0,1/COUNTIF(G:G,G343)) -> 1 | I343: =IF($B343="리오더",R343,"") | J343: =IF(I343="",0,1/COUNTIF(I:I,I343)) -> 0 | K343: =MID(R343,6,2) -> F5 | L343: =VLOOKUP(N343,CODE!K:P,CODE!$P$1,FALSE) -> 모자 | M343: =VLOOKUP(MID(R343,1,3),CODE!$B:$G,CODE!D$1,FALSE) -> JOI | N343: =MID(R343,4,2) -> EB | O343: =IF(ISERROR(IF(VLOOKUP($N343,CODE!$K:$P,CODE!$O$1,FALSE)="",$M343,$M343&"-"&VLOOKUP($N343,CODE!$K:$P,CODE!$O$1,FALSE)))=TRUE,"",IF(VLOOKUP($N343,CODE!$K:$P,CODE!$O$1,FALSE)="",$M343,$M343&"-"&VLOOKUP($N343,CODE!$K:$P,CODE!$O$1,FALSE))) -> JOI | P343: =IF(OR(MID(R343,8,1)="0",MID(R343,8,1)="1",MID(R343,8,1)="2",MID(R343,8,1)="3",MID(R343,8,1)="4"),"성인","키즈") -> 키즈 | Q343: =MID(R343,1,10) -> JOIEBF5505 | R343: JOIEBF5505BL | S343: M | T343: 1200 | U343: 58800000 | V343: 9597012 | W343: 5.5699155 | X343: 1200 | Y343: 0
A344: =IF(OR(MID(R344,8,1)="0",MID(R344,8,1)="5"),"신규","러닝") -> 신규 | B344: 최초 | C344: =IF($B344="리오더","",Q344) -> JOIMUF5506 | D344: =IF(C344="",0,1/COUNTIF(C:C,C344)) -> 1 | E344: =IF($B344="리오더",Q344,"") | F344: =IF(E344="",0,1/COUNTIF(E:E,E344)) -> 0 | G344: =IF($B344="리오더","",R344) -> JOIMUF5506BL | H344: =IF(G344="",0,1/COUNTIF(G:G,G344)) -> 1 | I344: =IF($B344="리오더",R344,"") | J344: =IF(I344="",0,1/COUNTIF(I:I,I344)) -> 0 | K344: =MID(R344,6,2) -> F5 | L344: =VLOOKUP(N344,CODE!K:P,CODE!$P$1,FALSE) -> ACC | M344: =VLOOKUP(MID(R344,1,3),CODE!$B:$G,CODE!D$1,FALSE) -> JOI | N344: =MID(R344,4,2) -> MU | O344: =IF(ISERROR(IF(VLOOKUP($N344,CODE!$K:$P,CODE!$O$1,FALSE)="",$M344,$M344&"-"&VLOOKUP($N344,CODE!$K:$P,CODE!$O$1,FALSE)))=TRUE,"",IF(VLOOKUP($N344,CODE!$K:$P,CODE!$O$1,FALSE)="",$M344,$M344&"-"&VLOOKUP($N344,CODE!$K:$P,CODE!$O$1,FALSE))) -> JOI-ACC | P344: =IF(OR(MID(R344,8,1)="0",MID(R344,8,1)="1",MID(R344,8,1)="2",MID(R344,8,1)="3",MID(R344,8,1)="4"),"성인","키즈") -> 키즈 | Q344: =MID(R344,1,10) -> JOIMUF5506 | R344: JOIMUF5506BL | S344: M | T344: 800 | U344: 36000000 | V344: 4895828.8 | W344: 6.6847257 | X344: 800 | Y344: 0
A345: =IF(OR(MID(R345,8,1)="0",MID(R345,8,1)="5"),"신규","러닝") -> 신규 | B345: =IF(COUNTIF(R$1:R344,R345)=0,"최초","리오더") -> 최초 | C345: =IF($B345="리오더","",Q345) -> JOIEDF5507 | D345: =IF(C345="",0,1/COUNTIF(C:C,C345)) -> 1 | E345: =IF($B345="리오더",Q345,"") | F345: =IF(E345="",0,1/COUNTIF(E:E,E345)) -> 0 | G345: =IF($B345="리오더","",R345) -> JOIEDF5507BL | H345: =IF(G345="",0,1/COUNTIF(G:G,G345)) -> 1 | I345: =IF($B345="리오더",R345,"") | J345: =IF(I345="",0,1/COUNTIF(I:I,I345)) -> 0 | K345: =MID(R345,6,2) -> F5 | L345: =VLOOKUP(N345,CODE!K:P,CODE!$P$1,FALSE) -> ACC | M345: =VLOOKUP(MID(R345,1,3),CODE!$B:$G,CODE!D$1,FALSE) -> JOI | N345: =MID(R345,4,2) -> ED | O345: =IF(ISERROR(IF(VLOOKUP($N345,CODE!$K:$P,CODE!$O$1,FALSE)="",$M345,$M345&"-"&VLOOKUP($N345,CODE!$K:$P,CODE!$O$1,FALSE)))=TRUE,"",IF(VLOOKUP($N345,CODE!$K:$P,CODE!$O$1,FALSE)="",$M345,$M345&"-"&VLOOKUP($N345,CODE!$K:$P,CODE!$O$1,FALSE))) -> JOI-ACC | P345: =IF(OR(MID(R345,8,1)="0",MID(R345,8,1)="1",MID(R345,8,1)="2",MID(R345,8,1)="3",MID(R345,8,1)="4"),"성인","키즈") -> 키즈 | Q345: =MID(R345,1,10) -> JOIEDF5507 | R345: JOIEDF5507BL | S345: M | T345: 800 | U345: 23200000 | V345: 3508720 | W345: 6.0109981 | X345: 799 | Y345: 0
A346: =IF(OR(MID(R346,8,1)="0",MID(R346,8,1)="5"),"신규","러닝") -> 신규 | B346: =IF(COUNTIF(R$1:R345,R346)=0,"최초","리오더") -> 최초 | C346: =IF($B346="리오더","",Q346) -> JOIEBF5508 | D346: =IF(C346="",0,1/COUNTIF(C:C,C346)) -> 1 | E346: =IF($B346="리오더",Q346,"") | F346: =IF(E346="",0,1/COUNTIF(E:E,E346)) -> 0 | G346: =IF($B346="리오더","",R346) -> JOIEBF5508IV | H346: =IF(G346="",0,1/COUNTIF(G:G,G346)) -> 1 | I346: =IF($B346="리오더",R346,"") | J346: =IF(I346="",0,1/COUNTIF(I:I,I346)) -> 0 | K346: =MID(R346,6,2) -> F5 | L346: =VLOOKUP(N346,CODE!K:P,CODE!$P$1,FALSE) -> 모자 | M346: =VLOOKUP(MID(R346,1,3),CODE!$B:$G,CODE!D$1,FALSE) -> JOI | N346: =MID(R346,4,2) -> EB | O346: =IF(ISERROR(IF(VLOOKUP($N346,CODE!$K:$P,CODE!$O$1,FALSE)="",$M346,$M346&"-"&VLOOKUP($N346,CODE!$K:$P,CODE!$O$1,FALSE)))=TRUE,"",IF(VLOOKUP($N346,CODE!$K:$P,CODE!$O$1,FALSE)="",$M346,$M346&"-"&VLOOKUP($N346,CODE!$K:$P,CODE!$O$1,FALSE))) -> JOI | P346: =IF(OR(MID(R346,8,1)="0",MID(R346,8,1)="1",MID(R346,8,1)="2",MID(R346,8,1)="3",MID(R346,8,1)="4"),"성인","키즈") -> 키즈 | Q346: =MID(R346,1,10) -> JOIEBF5508 | R346: JOIEBF5508IV | S346: M | T346: 1200 | U346: 58800000 | V346: 7732812 | W346: 6.9126917 | X346: 1201 | Y346: 0
A347: =IF(OR(MID(R347,8,1)="0",MID(R347,8,1)="5"),"신규","러닝") -> 신규 | B347: =IF(COUNTIF(R$1:R346,R347)=0,"최초","리오더") -> 최초 | C347: =IF($B347="리오더","",Q347) -> URBTHF5003 | D347: =IF(C347="",0,1/COUNTIF(C:C,C347)) -> 1 | E347: =IF($B347="리오더",Q347,"") | F347: =IF(E347="",0,1/COUNTIF(E:E,E347)) -> 0 | G347: =IF($B347="리오더","",R347) -> URBTHF5003BK | H347: =IF(G347="",0,1/COUNTIF(G:G,G347)) -> 1 | I347: =IF($B347="리오더",R347,"") | J347: =IF(I347="",0,1/COUNTIF(I:I,I347)) -> 0 | K347: =MID(R347,6,2) -> F5 | L347: =VLOOKUP(N347,CODE!K:P,CODE!$P$1,FALSE) -> 의류 | M347: =VLOOKUP(MID(R347,1,3),CODE!$B:$G,CODE!D$1,FALSE) -> URB | N347: =MID(R347,4,2) -> TH | O347: =IF(ISERROR(IF(VLOOKUP($N347,CODE!$K:$P,CODE!$O$1,FALSE)="",$M347,$M347&"-"&VLOOKUP($N347,CODE!$K:$P,CODE!$O$1,FALSE)))=TRUE,"",IF(VLOOKUP($N347,CODE!$K:$P,CODE!$O$1,FALSE)="",$M347,$M347&"-"&VLOOKUP($N347,CODE!$K:$P,CODE!$O$1,FALSE))) -> URB-의류 | P347: =IF(OR(MID(R347,8,1)="0",MID(R347,8,1)="1",MID(R347,8,1)="2",MID(R347,8,1)="3",MID(R347,8,1)="4"),"성인","키즈") -> 성인 | Q347: =MID(R347,1,10) -> URBTHF5003 | R347: URBTHF5003BK | S347: M | T347: 1200 | U347: 106800000 | V347: 24279000 | W347: 3.9989666 | X347: 1266 | Y347: 0
A348: =IF(OR(MID(R348,8,1)="0",MID(R348,8,1)="5"),"신규","러닝") -> 신규 | B348: =IF(COUNTIF(R$1:R347,R348)=0,"최초","리오더") -> 최초 | C348: =IF($B348="리오더","",Q348) -> URBHPF5004 | D348: =IF(C348="",0,1/COUNTIF(C:C,C348)) -> 1 | E348: =IF($B348="리오더",Q348,"") | F348: =IF(E348="",0,1/COUNTIF(E:E,E348)) -> 0 | G348: =IF($B348="리오더","",R348) -> URBHPF5004BK | H348: =IF(G348="",0,1/COUNTIF(G:G,G348)) -> 1 | I348: =IF($B348="리오더",R348,"") | J348: =IF(I348="",0,1/COUNTIF(I:I,I348)) -> 0 | K348: =MID(R348,6,2) -> F5 | L348: =VLOOKUP(N348,CODE!K:P,CODE!$P$1,FALSE) -> 의류 | M348: =VLOOKUP(MID(R348,1,3),CODE!$B:$G,CODE!D$1,FALSE) -> URB | N348: =MID(R348,4,2) -> HP | O348: =IF(ISERROR(IF(VLOOKUP($N348,CODE!$K:$P,CODE!$O$1,FALSE)="",$M348,$M348&"-"&VLOOKUP($N348,CODE!$K:$P,CODE!$O$1,FALSE)))=TRUE,"",IF(VLOOKUP($N348,CODE!$K:$P,CODE!$O$1,FALSE)="",$M348,$M348&"-"&VLOOKUP($N348,CODE!$K:$P,CODE!$O$1,FALSE))) -> URB-의류 | P348: =IF(OR(MID(R348,8,1)="0",MID(R348,8,1)="1",MID(R348,8,1)="2",MID(R348,8,1)="3",MID(R348,8,1)="4"),"성인","키즈") -> 성인 | Q348: =MID(R348,1,10) -> URBHPF5004 | R348: URBHPF5004BK | S348: M | T348: 1200 | U348: 142800000 | V348: 35782800 | W348: 3.6279492 | X348: 1242 | Y348: 0
A349: =IF(OR(MID(R349,8,1)="0",MID(R349,8,1)="5"),"신규","러닝") -> 신규 | B349: =IF(COUNTIF(R$1:R348,R349)=0,"최초","리오더") -> 최초 | C349: =IF($B349="리오더","",Q349) -> URBJPF5005 | D349: =IF(C349="",0,1/COUNTIF(C:C,C349)) -> 1 | E349: =IF($B349="리오더",Q349,"") | F349: =IF(E349="",0,1/COUNTIF(E:E,E349)) -> 0 | G349: =IF($B349="리오더","",R349) -> URBJPF5005BK | H349: =IF(G349="",0,1/COUNTIF(G:G,G349)) -> 1 | I349: =IF($B349="리오더",R349,"") | J349: =IF(I349="",0,1/COUNTIF(I:I,I349)) -> 0 | K349: =MID(R349,6,2) -> F5 | L349: =VLOOKUP(N349,CODE!K:P,CODE!$P$1,FALSE) -> 의류 | M349: =VLOOKUP(MID(R349,1,3),CODE!$B:$G,CODE!D$1,FALSE) -> URB | N349: =MID(R349,4,2) -> JP | O349: =IF(ISERROR(IF(VLOOKUP($N349,CODE!$K:$P,CODE!$O$1,FALSE)="",$M349,$M349&"-"&VLOOKUP($N349,CODE!$K:$P,CODE!$O$1,FALSE)))=TRUE,"",IF(VLOOKUP($N349,CODE!$K:$P,CODE!$O$1,FALSE)="",$M349,$M349&"-"&VLOOKUP($N349,CODE!$K:$P,CODE!$O$1,FALSE))) -> URB-의류 | P349: =IF(OR(MID(R349,8,1)="0",MID(R349,8,1)="1",MID(R349,8,1)="2",MID(R349,8,1)="3",MID(R349,8,1)="4"),"성인","키즈") -> 성인 | Q349: =MID(R349,1,10) -> URBJPF5005 | R349: URBJPF5005BK | S349: M | T349: 1000 | U349: 158000000 | V349: 37557500 | W349: 3.8244389 | X349: 1073 | Y349: 0
A350: =IF(OR(MID(R350,8,1)="0",MID(R350,8,1)="5"),"신규","러닝") -> 신규 | B350: =IF(COUNTIF(R$1:R349,R350)=0,"최초","리오더") -> 최초 | C350: =IF($B350="리오더","",Q350) -> URBJPF5007 | D350: =IF(C350="",0,1/COUNTIF(C:C,C350)) -> 0.5 | E350: =IF($B350="리오더",Q350,"") | F350: =IF(E350="",0,1/COUNTIF(E:E,E350)) -> 0 | G350: =IF($B350="리오더","",R350) -> URBJPF5007BK | H350: =IF(G350="",0,1/COUNTIF(G:G,G350)) -> 1 | I350: =IF($B350="리오더",R350,"") | J350: =IF(I350="",0,1/COUNTIF(I:I,I350)) -> 0 | K350: =MID(R350,6,2) -> F5 | L350: =VLOOKUP(N350,CODE!K:P,CODE!$P$1,FALSE) -> 의류 | M350: =VLOOKUP(MID(R350,1,3),CODE!$B:$G,CODE!D$1,FALSE) -> URB | N350: =MID(R350,4,2) -> JP | O350: =IF(ISERROR(IF(VLOOKUP($N350,CODE!$K:$P,CODE!$O$1,FALSE)="",$M350,$M350&"-"&VLOOKUP($N350,CODE!$K:$P,CODE!$O$1,FALSE)))=TRUE,"",IF(VLOOKUP($N350,CODE!$K:$P,CODE!$O$1,FALSE)="",$M350,$M350&"-"&VLOOKUP($N350,CODE!$K:$P,CODE!$O$1,FALSE))) -> URB-의류 | P350: =IF(OR(MID(R350,8,1)="0",MID(R350,8,1)="1",MID(R350,8,1)="2",MID(R350,8,1)="3",MID(R350,8,1)="4"),"성인","키즈") -> 성인 | Q350: =MID(R350,1,10) -> URBJPF5007 | R350: URBJPF5007BK | S350: M | T350: 1500 | U350: 417000000 | V350: 100948125 | W350: 3.7553041 | X350: 1640 | Y350: 0
A351: =IF(OR(MID(R351,8,1)="0",MID(R351,8,1)="5"),"신규","러닝") -> 신규 | B351: =IF(COUNTIF(R$1:R350,R351)=0,"최초","리오더") -> 최초 | C351: =IF($B351="리오더","",Q351) -> URBJPF5007 | D351: =IF(C351="",0,1/COUNTIF(C:C,C351)) -> 0.5 | E351: =IF($B351="리오더",Q351,"") | F351: =IF(E351="",0,1/COUNTIF(E:E,E351)) -> 0 | G351: =IF($B351="리오더","",R351) -> URBJPF5007RE | H351: =IF(G351="",0,1/COUNTIF(G:G,G351)) -> 1 | I351: =IF($B351="리오더",R351,"") | J351: =IF(I351="",0,1/COUNTIF(I:I,I351)) -> 0 | K351: =MID(R351,6,2) -> F5 | L351: =VLOOKUP(N351,CODE!K:P,CODE!$P$1,FALSE) -> 의류 | M351: =VLOOKUP(MID(R351,1,3),CODE!$B:$G,CODE!D$1,FALSE) -> URB | N351: =MID(R351,4,2) -> JP | O351: =IF(ISERROR(IF(VLOOKUP($N351,CODE!$K:$P,CODE!$O$1,FALSE)="",$M351,$M351&"-"&VLOOKUP($N351,CODE!$K:$P,CODE!$O$1,FALSE)))=TRUE,"",IF(VLOOKUP($N351,CODE!$K:$P,CODE!$O$1,FALSE)="",$M351,$M351&"-"&VLOOKUP($N351,CODE!$K:$P,CODE!$O$1,FALSE))) -> URB-의류 | P351: =IF(OR(MID(R351,8,1)="0",MID(R351,8,1)="1",MID(R351,8,1)="2",MID(R351,8,1)="3",MID(R351,8,1)="4"),"성인","키즈") -> 성인 | Q351: =MID(R351,1,10) -> URBJPF5007 | R351: URBJPF5007RE | S351: M | T351: 1500 | U351: 417000000 | V351: 100948125 | W351: 3.7553041 | X351: 1653 | Y351: 0
A352: =IF(OR(MID(R352,8,1)="0",MID(R352,8,1)="5"),"신규","러닝") -> 신규 | B352: =IF(COUNTIF(R$1:R351,R352)=0,"최초","리오더") -> 최초 | C352: =IF($B352="리오더","",Q352) -> URBJPF5008 | D352: =IF(C352="",0,1/COUNTIF(C:C,C352)) -> 1 | E352: =IF($B352="리오더",Q352,"") | F352: =IF(E352="",0,1/COUNTIF(E:E,E352)) -> 0 | G352: =IF($B352="리오더","",R352) -> URBJPF5008GY | H352: =IF(G352="",0,1/COUNTIF(G:G,G352)) -> 1 | I352: =IF($B352="리오더",R352,"") | J352: =IF(I352="",0,1/COUNTIF(I:I,I352)) -> 0 | K352: =MID(R352,6,2) -> F5 | L352: =VLOOKUP(N352,CODE!K:P,CODE!$P$1,FALSE) -> 의류 | M352: =VLOOKUP(MID(R352,1,3),CODE!$B:$G,CODE!D$1,FALSE) -> URB | N352: =MID(R352,4,2) -> JP | O352: =IF(ISERROR(IF(VLOOKUP($N352,CODE!$K:$P,CODE!$O$1,FALSE)="",$M352,$M352&"-"&VLOOKUP($N352,CODE!$K:$P,CODE!$O$1,FALSE)))=TRUE,"",IF(VLOOKUP($N352,CODE!$K:$P,CODE!$O$1,FALSE)="",$M352,$M352&"-"&VLOOKUP($N352,CODE!$K:$P,CODE!$O$1,FALSE))) -> URB-의류 | P352: =IF(OR(MID(R352,8,1)="0",MID(R352,8,1)="1",MID(R352,8,1)="2",MID(R352,8,1)="3",MID(R352,8,1)="4"),"성인","키즈") -> 성인 | Q352: =MID(R352,1,10) -> URBJPF5008 | R352: URBJPF5008GY | S352: M | T352: 1500 | U352: 387000000 | V352: 88041000 | W352: 3.9960721 | X352: 1618 | Y352: 0
A353: =IF(OR(MID(R353,8,1)="0",MID(R353,8,1)="5"),"신규","러닝") -> 신규 | B353: =IF(COUNTIF(R$1:R352,R353)=0,"최초","리오더") -> 최초 | C353: =IF($B353="리오더","",Q353) -> WTRTPF5001 | D353: =IF(C353="",0,1/COUNTIF(C:C,C353)) -> 1 | E353: =IF($B353="리오더",Q353,"") | F353: =IF(E353="",0,1/COUNTIF(E:E,E353)) -> 0 | G353: =IF($B353="리오더","",R353) -> WTRTPF5001BU | H353: =IF(G353="",0,1/COUNTIF(G:G,G353)) -> 1 | I353: =IF($B353="리오더",R353,"") | J353: =IF(I353="",0,1/COUNTIF(I:I,I353)) -> 0 | K353: =MID(R353,6,2) -> F5 | L353: =VLOOKUP(N353,CODE!K:P,CODE!$P$1,FALSE) -> 모자 | M353: =VLOOKUP(MID(R353,1,3),CODE!$B:$G,CODE!D$1,FALSE) -> WTR | N353: =MID(R353,4,2) -> TP | O353: =IF(ISERROR(IF(VLOOKUP($N353,CODE!$K:$P,CODE!$O$1,FALSE)="",$M353,$M353&"-"&VLOOKUP($N353,CODE!$K:$P,CODE!$O$1,FALSE)))=TRUE,"",IF(VLOOKUP($N353,CODE!$K:$P,CODE!$O$1,FALSE)="",$M353,$M353&"-"&VLOOKUP($N353,CODE!$K:$P,CODE!$O$1,FALSE))) -> WTR | P353: =IF(OR(MID(R353,8,1)="0",MID(R353,8,1)="1",MID(R353,8,1)="2",MID(R353,8,1)="3",MID(R353,8,1)="4"),"성인","키즈") -> 성인 | Q353: =MID(R353,1,10) -> WTRTPF5001 | R353: WTRTPF5001BU | S353: M | T353: 800 | U353: 55200000 | V353: 10205912 | W353: 4.9169362 | X353: 798 | Y353: 0
A354: =IF(OR(MID(R354,8,1)="0",MID(R354,8,1)="5"),"신규","러닝") -> 신규 | B354: =IF(COUNTIF(R$1:R353,R354)=0,"최초","리오더") -> 최초 | C354: =IF($B354="리오더","",Q354) -> WTRTPF5002 | D354: =IF(C354="",0,1/COUNTIF(C:C,C354)) -> 1 | E354: =IF($B354="리오더",Q354,"") | F354: =IF(E354="",0,1/COUNTIF(E:E,E354)) -> 0 | G354: =IF($B354="리오더","",R354) -> WTRTPF5002BK | H354: =IF(G354="",0,1/COUNTIF(G:G,G354)) -> 1 | I354: =IF($B354="리오더",R354,"") | J354: =IF(I354="",0,1/COUNTIF(I:I,I354)) -> 0 | K354: =MID(R354,6,2) -> F5 | L354: =VLOOKUP(N354,CODE!K:P,CODE!$P$1,FALSE) -> 모자 | M354: =VLOOKUP(MID(R354,1,3),CODE!$B:$G,CODE!D$1,FALSE) -> WTR | N354: =MID(R354,4,2) -> TP | O354: =IF(ISERROR(IF(VLOOKUP($N354,CODE!$K:$P,CODE!$O$1,FALSE)="",$M354,$M354&"-"&VLOOKUP($N354,CODE!$K:$P,CODE!$O$1,FALSE)))=TRUE,"",IF(VLOOKUP($N354,CODE!$K:$P,CODE!$O$1,FALSE)="",$M354,$M354&"-"&VLOOKUP($N354,CODE!$K:$P,CODE!$O$1,FALSE))) -> WTR | P354: =IF(OR(MID(R354,8,1)="0",MID(R354,8,1)="1",MID(R354,8,1)="2",MID(R354,8,1)="3",MID(R354,8,1)="4"),"성인","키즈") -> 성인 | Q354: =MID(R354,1,10) -> WTRTPF5002 | R354: WTRTPF5002BK | S354: M | T354: 1000 | U354: 75000000 | V354: 14065760 | W354: 4.8473611 | X354: 1000 | Y354: 0
A355: =IF(OR(MID(R355,8,1)="0",MID(R355,8,1)="5"),"신규","러닝") -> 신규 | B355: =IF(COUNTIF(R$1:R354,R355)=0,"최초","리오더") -> 최초 | C355: =IF($B355="리오더","",Q355) -> SBRMIF3001 | D355: =IF(C355="",0,1/COUNTIF(C:C,C355)) -> 0.5 | E355: =IF($B355="리오더",Q355,"") | F355: =IF(E355="",0,1/COUNTIF(E:E,E355)) -> 0 | G355: =IF($B355="리오더","",R355) -> SBRMIF3001BK | H355: =IF(G355="",0,1/COUNTIF(G:G,G355)) -> 1 | I355: =IF($B355="리오더",R355,"") | J355: =IF(I355="",0,1/COUNTIF(I:I,I355)) -> 0 | K355: =MID(R355,6,2) -> F3 | L355: =VLOOKUP(N355,CODE!K:P,CODE!$P$1,FALSE) -> 모자 | M355: =VLOOKUP(MID(R355,1,3),CODE!$B:$G,CODE!D$1,FALSE) -> SBR | N355: =MID(R355,4,2) -> MI | O355: =IF(ISERROR(IF(VLOOKUP($N355,CODE!$K:$P,CODE!$O$1,FALSE)="",$M355,$M355&"-"&VLOOKUP($N355,CODE!$K:$P,CODE!$O$1,FALSE)))=TRUE,"",IF(VLOOKUP($N355,CODE!$K:$P,CODE!$O$1,FALSE)="",$M355,$M355&"-"&VLOOKUP($N355,CODE!$K:$P,CODE!$O$1,FALSE))) -> SBR | P355: =IF(OR(MID(R355,8,1)="0",MID(R355,8,1)="1",MID(R355,8,1)="2",MID(R355,8,1)="3",MID(R355,8,1)="4"),"성인","키즈") -> 성인 | Q355: =MID(R355,1,10) -> SBRMIF3001 | R355: SBRMIF3001BK | S355: M | T355: 4000 | U355: 180000000 | V355: 24898104 | W355: 6.572242 | X355: 3996 | Y355: 0
...

Sheet P (2)
B1: 2014 FW 기획진행현황 (HATS ON) 2
P2: =TODAY() -> 42157
B3: 분류 | C3: 브랜드품목 | D3: 러닝/신규 | E3: 최초/리오더 | F3: 품번수 | G3: 품번수(리오더) | H3: 색상수 | I3: 색상수(리오더) | J3: 기획수량 | K3: LOT | L3: TAG가 | M3: 원가(-V) | N3: 배수 | O3: 입고수량 | P3: 미입고수량
F6: 데이터
B7: 분류 | C7: 브랜드품목 | D7: 러닝/신규 | E7: 최초/리오더 | F7: 품번수 | G7: 품번수(리오더) | H7: 색상수 | I7: 색상수(리오더) | J7: 기획수량 | K7: LOT | L7: TAG가 | M7: 원가(-V) | N7: 배수 | O7: 입고수량 | P7: 미입고수량
B8: M | C8: ELS | D8: 신규 | E8: 최초 | F8: 34 | G8: 0 | H8: 35 | I8: 0 | J8: 42730 | K8: 1220.8571 | L8: 2144950000 | M8: 336824540 | N8: 5.7892294 | O8: 42828 | P8: 0
E9: 리오더 | F9: 0 | G9: 4 | H9: 0 | I9: 4 | J9: 5000 | K9: 1250 | L9: 235000000 | M9: 33865430 | N9: 6.3083907 | O9: 4962 | P9: 0
D10: 러닝 | E10: 최초 | F10: 5 | G10: 0 | H10: 6 | I10: 0 | J10: 15000 | K10: 2500 | L10: 791000000 | M10: 110115780 | N10: 6.5303166 | O10: 14972 | P10: 0
C11: ELS-가방 | D11: 신규 | E11: 최초 | F11: 5 | G11: 0 | H11: 5 | I11: 0 | J11: 3800 | K11: 760 | L11: 382200000 | M11: 86426000 | N11: 4.0202548 | O11: 3800 | P11: 0
D12: 러닝 | E12: 최초 | F12: 1 | G12: 0 | H12: 1 | I12: 0 | J12: 1000 | K12: 1000 | L12: 45000000 | M12: 9820000 | N12: 4.1658952 | O12: 1000 | P12: 0
C13: ELS-의류 | D13: 신규 | E13: 최초 | F13: 31 | G13: 0 | H13: 42 | I13: 0 | J13: 48600 | K13: 1157.1429 | L13: 6098800000 | M13: 1404577814 | N13: 3.9473524 | O13: 49246 | P13: 0
C14: SMB | D14: 신규 | E14: 최초 | F14: 40 | G14: 0 | H14: 53 | I14: 0 | J14: 57000 | K14: 1075.4717 | L14: 2457800000 | M14: 338604881 | N14: 6.5987343 | O14: 56568 | P14: 0
E15: 리오더 | F15: 0 | G15: 3 | H15: 0 | I15: 4 | J15: 1700 | K15: 425 | L15: 68100000 | M15: 8901592 | N15: 6.9548336 | O15: 1700 | P15: 0
D16: 러닝 | E16: 최초 | F16: 5 | G16: 0 | H16: 5 | I16: 0 | J16: 12500 | K16: 2500 | L16: 561500000 | M16: 76003238 | N16: 6.716221 | O16: 12498 | P16: 0
C17: NAA | D17: 신규 | E17: 최초 | F17: 3 | G17: 0 | H17: 3 | I17: 0 | J17: 2400 | K17: 800 | L17: 93600000 | M17: 14322000 | N17: 5.9412728 | O17: 2395 | P17: 0
C18: NOV | D18: 신규 | E18: 최초 | F18: 9 | G18: 0 | H18: 14 | I18: 0 | J18: 11400 | K18: 814.28571 | L18: 837800000 | M18: 146642468 | N18: 5.1938321 | O18: 11368 | P18: 0
E19: 리오더 | F19: 0 | G19: 1 | H19: 0 | I19: 3 | J19: 2100 | K19: 700 | L19: 165900000 | M19: 24360063 | N19: 6.1912066 | O19: 2108 | P19: 0
C20: VBL | D20: 신규 | E20: 최초 | F20: 9 | G20: 0 | H20: 9 | I20: 0 | J20: 10000 | K20: 1111.1111 | L20: 535600000 | M20: 68710292 | N20: 7.086407 | O20: 9792 | P20: 0
D21: 러닝 | E21: 최초 | F21: 5 | G21: 0 | H21: 5 | I21: 0 | J21: 9100 | K21: 1820 | L21: 491300000 | M21: 42189678 | N21: 10.586389 | O21: 9091 | P21: 0
C22: PLA | D22: 신규 | E22: 최초 | F22: 4 | G22: 0 | H22: 9 | I22: 0 | J22: 9400 | K22: 1044.4444 | L22: 533000000 | M22: 71206272 | N22: 6.8048143 | O22: 9331 | P22: 0
D23: 러닝 | E23: 최초 | F23: 3 | G23: 0 | H23: 3 | I23: 0 | J23: 5000 | K23: 1666.6667 | L23: 295000000 | M23: 38388735 | N23: 6.9859509 | O23: 4999 | P23: 0
E24: 리오더 | F24: 0 | G24: 1 | H24: 0 | I24: 1 | J24: 2000 | K24: 2000 | L24: 118000000 | M24: 13846140 | N24: 7.7474825 | O24: 2000 | P24: 0
C25: HCU | D25: 신규 | E25: 최초 | F25: 10 | G25: 0 | H25: 15 | I25: 0 | J25: 19100 | K25: 1273.3333 | L25: 947500000 | M25: 145850102 | N25: 5.9058144 | O25: 19111 | P25: 0
D26: 러닝 | E26: 최초 | F26: 6 | G26: 0 | H26: 7 | I26: 0 | J26: 10500 | K26: 1500 | L26: 527500000 | M26: 69627740 | N26: 6.8872759 | O26: 10512 | P26: 0
C27: BRO | D27: 신규 | E27: 최초 | F27: 7 | G27: 0 | H27: 8 | I27: 0 | J27: 8000 | K27: 1000 | L27: 428000000 | M27: 68141450 | N27: 5.7100474 | O27: 7871 | P27: 0
C28: BMD | D28: 신규 | E28: 최초 | F28: 2 | G28: 0 | H28: 2 | I28: 0 | J28: 2000 | K28: 1000 | L28: 104000000 | M28: 15833020 | N28: 5.97141 | O28: 1992 | P28: 0
D29: 러닝 | E29: 최초 | F29: 2 | G29: 0 | H29: 2 | I29: 0 | J29: 2000 | K29: 1000 | L29: 108000000 | M29: 13387180 | N29: 7.3340179 | O29: 1891 | P29: 0
C30: WTR | D30: 신규 | E30: 최초 | F30: 12 | G30: 0 | H30: 12 | I30: 0 | J30: 10200 | K30: 850 | L30: 602600000 | M30: 94766000 | N30: 5.7807461 | O30: 10184 | P30: 0
D31: 러닝 | E31: 최초 | F31: 3 | G31: 0 | H31: 3 | I31: 0 | J31: 4000 | K31: 1333.3333 | L31: 226000000 | M31: 39526080 | N31: 5.1979489 | O31: 3961 | P31: 0
C32: JOI | D32: 신규 | E32: 최초 | F32: 12 | G32: 0 | H32: 13 | I32: 0 | J32: 15100 | K32: 1161.5385 | L32: 738900000 | M32: 122478171 | N32: 5.4844652 | O32: 14963 | P32: 0
D33: 러닝 | E33: 최초 | F33: 3 | G33: 0 | H33: 4 | I33: 0 | J33: 6000 | K33: 1500 | L33: 330000000 | M33: 56836785 | N33: 5.2782718 | O33: 5981 | P33: 0
C34: FFT | D34: 신규 | E34: 최초 | F34: 8 | G34: 0 | H34: 8 | I34: 0 | J34: 144 | K34: 18 | L34: 6024000 | M34: 2464363.6 | N34: 2.2222222 | O34: 144 | P34: 0
C35: ELS-ACC | D35: 신규 | E35: 최초 | F35: 3 | G35: 0 | H35: 3 | I35: 0 | J35: 2400 | K35: 800 | L35: 108000000 | M35: 21866272 | N35: 4.4901032 | O35: 2344 | P35: 0
C36: JOI-ACC | D36: 신규 | E36: 최초 | F36: 4 | G36: 0 | H36: 4 | I36: 0 | J36: 3200 | K36: 800 | L36: 118400000 | M36: 16809098 | N36: 6.4034588 | O36: 3197 | P36: 0
C37: PLA-가방 | D37: 신규 | E37: 최초 | F37: 1 | G37: 0 | H37: 1 | I37: 0 | J37: 600 | K37: 600 | L37: 89400000 | M37: 23160000 | N37: 3.5091851 | O37: 600 | P37: 0
E38: 리오더 | F38: 0 | G38: 1 | H38: 0 | I38: 1 | J38: 900 | K38: 900 | L38: 134100000 | M38: 31266000 | N38: 3.8990946 | O38: 900 | P38: 0
D39: 러닝 | E39: 최초 | F39: 1 | G39: 0 | H39: 1 | I39: 0 | J39: 800 | K39: 800 | L39: 100000000 | M39: 22400000 | N39: 4.0584416 | O39: 800 | P39: 0
E40: 리오더 | F40: 0 | G40: 1 | H40: 0 | I40: 1 | J40: 300 | K40: 300 | L40: 37500000 | M40: 7560000 | N40: 4.5093795 | O40: 300 | P40: 0
C41: URB | D41: 신규 | E41: 최초 | F41: 44 | G41: 0 | H41: 52 | I41: 0 | J41: 60150 | K41: 1156.7308 | L41: 2814850000 | M41: 3.7990847e+08 | N41: 6.7357133 | O41: 60079 | P41: 0
E42: 리오더 | F42: 0 | G42: 1 | H42: 0 | I42: 1 | J42: 2000 | K42: 2000 | L42: 98000000 | M42: 9898920 | N42: 9.0000636 | O42: 1811 | P42: 0
...

Sheet CODE
C1: 2 | D1: 3 | E1: 4 | F1: 5 | G1: 6 | L1: 2 | M1: 3 | N1: 4 | O1: 5 | P1: 6 | S1: 2 | T1: 3 | X1: 2 | Y1: 3 | AE1: 2 | AF1: 3 | AJ1: 2 | AK1: 3 | AL1: 4 | AO1: 2 | AP1: 3 | AS1: 2 | AT1: 3 | AW1: 2 | AX1: 3
A2: BRAND (3자리) | I2: ITEM (2자리) | R2: YEAR (2자리) | V2: SEASON (1자리) | AA2: STNO (3자리) | AC2: COLOR (2자리) | AH2: SIZE (3자리) | AN2: 분류 | AR2: 성별 | AV2: 원산지
A3: 구코드 | B3: 코드 | C3: 코드명 | D3: 그룹 | E3: 코드 | F3: 구분 | G3: B/M/C | I3: 구코드 | J3: 구코드명 | K3: 코드 | L3: 코드명 | M3: 코드 | N3: 구분 | O3: 구분 | P3: 구분 | R3: 코드 | S3: 코드명 | T3: 코드 | V3: 구코드 | W3: 코드 | X3: 코드명 | Y3: 코드 | AA3: 코드 | AC3: 구코드 | AD3: 코드 | AE3: 코드명 | AF3: 코드 | AH3: 구코드 | AI3: 코드 | AJ3: 코드명 | AK3: TYPE | AL3: 코드 | AN3: 코드 | AO3: 코드명 | AP3: 코드 | AR3: 코드 | AS3: 코드명 | AT3: 코드 | AV3: 코드 | AW3: 코드명 | AX3: 코드
A4: BZ | C4: COP CARDINALS | D4: =B4 -> 0 | E4: =B4 -> 0 | F4: SPORTS | G4: B | I4: CA | J4: BASIC CAP (핀치히터) | K4: BA | L4: BASIC CAP | M4: =K4 -> BA | N4: 의류외 | P4: 모자 | R4: A | S4: 2009 | T4: =R4 -> A | V4: 0 | W4: 0 | X4: SS | Y4: =W4 -> 0 | AA4: 001 | AC4: B0 | AD4: BK | AE4: Black | AF4: =AD4 -> BK | AH4: A | AI4: FRE | AJ4: OSFA(ADJUST CAP) | AK4: 1 | AL4: =AI4 -> FRE | AN4: B | AO4: 사입 | AP4: =AN4 -> B | AR4: M | AS4: 남자 | AT4: =AR4 -> M | AV4: CN | AW4: 중국 | AX4: =AV4 -> CN
A5: BH | C5: COP INDIANS | D5: =B5 -> 0 | E5: =B5 -> 0 | F5: SPORTS | G5: B | I5: CS | J5: VISOR CAP | K5: BA | L5: BASIC CAP | M5: =K5 -> BA | N5: 의류외 | P5: 모자 | R5: B | S5: 2010 | T5: =R5 -> B | V5: 1 | W5: 0 | X5: SS | Y5: =W5 -> 0 | AA5: 002 | AC5: B1 | AE5: Black Camo | AF5: =AD5 -> 0 | AI5: XXS | AJ5: XXS | AK5: 1 | AL5: XXS | AN5: C | AO5: 위탁 | AP5: =AN5 -> C | AR5: W | AS5: 여자 | AT5: =AR5 -> W | AV5: JP | AW5: 일본 | AX5: =AV5 -> JP
A6: BR | C6: COP METS | D6: =B6 -> 0 | E6: =B6 -> 0 | F6: SPORTS | G6: B | I6: CC | J6: FLEX CAP (3930) | K6: FL | L6: FLEX CAP | M6: =K6 -> FL | N6: 의류외 | P6: 모자 | R6: C | S6: 2011 | T6: =R6 -> C | V6: 2 | W6: 0 | X6: SS | Y6: =W6 -> 0 | AA6: 003 | AC6: B2 | AE6: Black Leopard | AF6: =AD6 -> 0 | AH6: N | AI6: OXS | AJ6: XS | AK6: 1 | AL6: =AI6 -> OXS | AN6: M | AO6: 제조 | AP6: =AN6 -> M | AR6: U | AS6: UNISEX | AT6: =AR6 -> U | AV6: KR | AW6: 한국 | AX6: =AV6 -> KR
