Workbook

Sheet 순점검
A1: 업체차수점검 | K1: 품번순서
K3: 브랜드 | N3: 사용가
E4: 데이터 | K4: SBR | N4: 사용불가
A5: 업체명 | B5: 차수 | C5: 발주일 | D5: 브랜드 | E5: 품번수 | F5: 색상수 | G5: 수량 | H5: 원가금액 | I5: TAG가금액 | K5: 의류외
A6: 동일모자 | B6: 3 | C6: 41549 | D6: JIL | E6: 1 | F6: 1 | G6: 4000 | H6: 25255440 | I6: 116000000
A7: 성진 | B7: 23 | C7: 41565 | D7: JIL | E7: 8 | F7: 8 | G7: 8000 | H7: 58663060 | I7: 354000000 | K7: REORDER | N7: MAIN (U,M,W) | Q7: MAIN (K)
A8: FOREMOST | B8: 1 | C8: 41513 | D8: JIL | E8: 8 | F8: 15 | G8: 17700 | H8: 97414461 | I8: 642700000 | K8: 품번순서 | N8: 품번순서 | Q8: 품번순서
B9: 4 | C9: 41543 | D9: JIL | E9: 8 | F9: 8 | G9: 7800 | H9: 34472160 | I9: 312200000 | K9: 1 | L9: =IF(ISERROR(VLOOKUP($K$4&$K$5&$K9,기획현황!$H:$H,1,FALSE))=TRUE,"",VLOOKUP($K$4&$K$5&$K9,기획현황!$H:$H,1,FALSE)) -> SBR의류외1 | N9: 201 | O9: =IF(ISERROR(VLOOKUP($K$4&$K$5&$N9,기획현황!$H:$H,1,FALSE))=TRUE,"",VLOOKUP($K$4&$K$5&$N9,기획현황!$H:$H,1,FALSE)) | Q9: =N9+500 -> 701 | R9: =IF(ISERROR(VLOOKUP($K$4&$K$5&$Q9,기획현황!$H:$H,1,FALSE))=TRUE,"",VLOOKUP($K$4&$K$5&$Q9,기획현황!$H:$H,1,FALSE))
B10: 6 | C10: 41549 | D10: JIL | E10: 1 | F10: 1 | G10: 2400 | H10: 14986862 | I10: 108000000 | K10: =K9+1 -> 2 | L10: =IF(ISERROR(VLOOKUP($K$4&$K$5&$K10,기획현황!$H:$H,1,FALSE))=TRUE,"",VLOOKUP($K$4&$K$5&$K10,기획현황!$H:$H,1,FALSE)) -> SBR의류외2 | N10: =N9+1 -> 202 | O10: =IF(ISERROR(VLOOKUP($K$4&$K$5&$N10,기획현황!$H:$H,1,FALSE))=TRUE,"",VLOOKUP($K$4&$K$5&$N10,기획현황!$H:$H,1,FALSE)) | Q10: =Q9+1 -> 702 | R10: =IF(ISERROR(VLOOKUP($K$4&$K$5&$Q10,기획현황!$H:$H,1,FALSE))=TRUE,"",VLOOKUP($K$4&$K$5&$Q10,기획현황!$H:$H,1,FALSE))
B11: 8 | E11: 3 | F11: 5 | G11: 4600 | H11: 28852502 | I11: 185800000 | K11: =K10+1 -> 3 | L11: =IF(ISERROR(VLOOKUP($K$4&$K$5&$K11,기획현황!$H:$H,1,FALSE))=TRUE,"",VLOOKUP($K$4&$K$5&$K11,기획현황!$H:$H,1,FALSE)) -> SBR의류외3 | N11: =N10+1 -> 203 | O11: =IF(ISERROR(VLOOKUP($K$4&$K$5&$N11,기획현황!$H:$H,1,FALSE))=TRUE,"",VLOOKUP($K$4&$K$5&$N11,기획현황!$H:$H,1,FALSE)) | Q11: =Q10+1 -> 703 | R11: =IF(ISERROR(VLOOKUP($K$4&$K$5&$Q11,기획현황!$H:$H,1,FALSE))=TRUE,"",VLOOKUP($K$4&$K$5&$Q11,기획현황!$H:$H,1,FALSE))
B12: 16 | C12: 41565 | D12: JIL | E12: 1 | F12: 2 | G12: 3500 | H12: 22990975 | I12: 150500000 | K12: =K11+1 -> 4 | L12: =IF(ISERROR(VLOOKUP($K$4&$K$5&$K12,기획현황!$H:$H,1,FALSE))=TRUE,"",VLOOKUP($K$4&$K$5&$K12,기획현황!$H:$H,1,FALSE)) -> SBR의류외4 | N12: =N11+1 -> 204 | O12: =IF(ISERROR(VLOOKUP($K$4&$K$5&$N12,기획현황!$H:$H,1,FALSE))=TRUE,"",VLOOKUP($K$4&$K$5&$N12,기획현황!$H:$H,1,FALSE)) | Q12: =Q11+1 -> 704 | R12: =IF(ISERROR(VLOOKUP($K$4&$K$5&$Q12,기획현황!$H:$H,1,FALSE))=TRUE,"",VLOOKUP($K$4&$K$5&$Q12,기획현황!$H:$H,1,FALSE))
B13: 18 | C13: 41568 | D13: JIL | E13: 2 | F13: 3 | G13: 6000 | H13: 29328778 | I13: 174000000 | K13: =K12+1 -> 5 | L13: =IF(ISERROR(VLOOKUP($K$4&$K$5&$K13,기획현황!$H:$H,1,FALSE))=TRUE,"",VLOOKUP($K$4&$K$5&$K13,기획현황!$H:$H,1,FALSE)) -> SBR의류외5 | N13: =N12+1 -> 205 | O13: =IF(ISERROR(VLOOKUP($K$4&$K$5&$N13,기획현황!$H:$H,1,FALSE))=TRUE,"",VLOOKUP($K$4&$K$5&$N13,기획현황!$H:$H,1,FALSE)) | Q13: =Q12+1 -> 705 | R13: =IF(ISERROR(VLOOKUP($K$4&$K$5&$Q13,기획현황!$H:$H,1,FALSE))=TRUE,"",VLOOKUP($K$4&$K$5&$Q13,기획현황!$H:$H,1,FALSE))
B14: 19 | C14: 41568 | D14: JIL | E14: 8 | F14: 10 | G14: 10600 | H14: 53962466 | I14: 475800000 | K14: =K13+1 -> 6 | L14: =IF(ISERROR(VLOOKUP($K$4&$K$5&$K14,기획현황!$H:$H,1,FALSE))=TRUE,"",VLOOKUP($K$4&$K$5&$K14,기획현황!$H:$H,1,FALSE)) -> SBR의류외6 | N14: =N13+1 -> 206 | O14: =IF(ISERROR(VLOOKUP($K$4&$K$5&$N14,기획현황!$H:$H,1,FALSE))=TRUE,"",VLOOKUP($K$4&$K$5&$N14,기획현황!$H:$H,1,FALSE)) | Q14: =Q13+1 -> 706 | R14: =IF(ISERROR(VLOOKUP($K$4&$K$5&$Q14,기획현황!$H:$H,1,FALSE))=TRUE,"",VLOOKUP($K$4&$K$5&$Q14,기획현황!$H:$H,1,FALSE))
B15: 20 | C15: 41570 | D15: JIL | E15: 5 | F15: 5 | G15: 2800 | H15: 16602761 | I15: 130400000 | K15: =K14+1 -> 7 | L15: =IF(ISERROR(VLOOKUP($K$4&$K$5&$K15,기획현황!$H:$H,1,FALSE))=TRUE,"",VLOOKUP($K$4&$K$5&$K15,기획현황!$H:$H,1,FALSE)) -> SBR의류외7 | N15: =N14+1 -> 207 | O15: =IF(ISERROR(VLOOKUP($K$4&$K$5&$N15,기획현황!$H:$H,1,FALSE))=TRUE,"",VLOOKUP($K$4&$K$5&$N15,기획현황!$H:$H,1,FALSE)) | Q15: =Q14+1 -> 707 | R15: =IF(ISERROR(VLOOKUP($K$4&$K$5&$Q15,기획현황!$H:$H,1,FALSE))=TRUE,"",VLOOKUP($K$4&$K$5&$Q15,기획현황!$H:$H,1,FALSE))
B16: 28 | C16: 41598 | D16: JIL | E16: 9 | F16: 12 | G16: 7300 | H16: 57227273 | I16: 377700000 | K16: =K15+1 -> 8 | L16: =IF(ISERROR(VLOOKUP($K$4&$K$5&$K16,기획현황!$H:$H,1,FALSE))=TRUE,"",VLOOKUP($K$4&$K$5&$K16,기획현황!$H:$H,1,FALSE)) -> SBR의류외8 | N16: =N15+1 -> 208 | O16: =IF(ISERROR(VLOOKUP($K$4&$K$5&$N16,기획현황!$H:$H,1,FALSE))=TRUE,"",VLOOKUP($K$4&$K$5&$N16,기획현황!$H:$H,1,FALSE)) | Q16: =Q15+1 -> 708 | R16: =IF(ISERROR(VLOOKUP($K$4&$K$5&$Q16,기획현황!$H:$H,1,FALSE))=TRUE,"",VLOOKUP($K$4&$K$5&$Q16,기획현황!$H:$H,1,FALSE))
A17: HMA | B17: 2 | C17: 41598 | D17: JIL | E17: 1 | F17: 1 | G17: 500 | H17: 3831168.8 | I17: 29500000 | K17: =K16+1 -> 9 | L17: =IF(ISERROR(VLOOKUP($K$4&$K$5&$K17,기획현황!$H:$H,1,FALSE))=TRUE,"",VLOOKUP($K$4&$K$5&$K17,기획현황!$H:$H,1,FALSE)) -> SBR의류외9 | N17: =N16+1 -> 209 | O17: =IF(ISERROR(VLOOKUP($K$4&$K$5&$N17,기획현황!$H:$H,1,FALSE))=TRUE,"",VLOOKUP($K$4&$K$5&$N17,기획현황!$H:$H,1,FALSE)) | Q17: =Q16+1 -> 709 | R17: =IF(ISERROR(VLOOKUP($K$4&$K$5&$Q17,기획현황!$H:$H,1,FALSE))=TRUE,"",VLOOKUP($K$4&$K$5&$Q17,기획현황!$H:$H,1,FALSE))
A18: QF | B18: 8 | E18: 7 | F18: 7 | G18: 5600 | H18: 21586848 | I18: 231200000 | K18: =K17+1 -> 10 | L18: =IF(ISERROR(VLOOKUP($K$4&$K$5&$K18,기획현황!$H:$H,1,FALSE))=TRUE,"",VLOOKUP($K$4&$K$5&$K18,기획현황!$H:$H,1,FALSE)) -> SBR의류외10 | N18: =N17+1 -> 210 | O18: =IF(ISERROR(VLOOKUP($K$4&$K$5&$N18,기획현황!$H:$H,1,FALSE))=TRUE,"",VLOOKUP($K$4&$K$5&$N18,기획현황!$H:$H,1,FALSE)) | Q18: =Q17+1 -> 710 | R18: =IF(ISERROR(VLOOKUP($K$4&$K$5&$Q18,기획현황!$H:$H,1,FALSE))=TRUE,"",VLOOKUP($K$4&$K$5&$Q18,기획현황!$H:$H,1,FALSE))
A19: TS | B19: 1 | C19: 41591 | D19: JIL | E19: 1 | F19: 2 | G19: 1800 | H19: 14040000 | I19: 81000000 | K19: =K18+1 -> 11 | L19: =IF(ISERROR(VLOOKUP($K$4&$K$5&$K19,기획현황!$H:$H,1,FALSE))=TRUE,"",VLOOKUP($K$4&$K$5&$K19,기획현황!$H:$H,1,FALSE)) -> SBR의류외11 | N19: =N18+1 -> 211 | O19: =IF(ISERROR(VLOOKUP($K$4&$K$5&$N19,기획현황!$H:$H,1,FALSE))=TRUE,"",VLOOKUP($K$4&$K$5&$N19,기획현황!$H:$H,1,FALSE)) | Q19: =Q18+1 -> 711 | R19: =IF(ISERROR(VLOOKUP($K$4&$K$5&$Q19,기획현황!$H:$H,1,FALSE))=TRUE,"",VLOOKUP($K$4&$K$5&$Q19,기획현황!$H:$H,1,FALSE))
A20: YITIAN | B20: 1 | C20: 41568 | D20: JIL | E20: 1 | F20: 1 | G20: 600 | H20: 3365742 | I20: 27000000 | K20: =K19+1 -> 12 | L20: =IF(ISERROR(VLOOKUP($K$4&$K$5&$K20,기획현황!$H:$H,1,FALSE))=TRUE,"",VLOOKUP($K$4&$K$5&$K20,기획현황!$H:$H,1,FALSE)) -> SBR의류외12 | N20: =N19+1 -> 212 | O20: =IF(ISERROR(VLOOKUP($K$4&$K$5&$N20,기획현황!$H:$H,1,FALSE))=TRUE,"",VLOOKUP($K$4&$K$5&$N20,기획현황!$H:$H,1,FALSE)) | Q20: =Q19+1 -> 712 | R20: =IF(ISERROR(VLOOKUP($K$4&$K$5&$Q20,기획현황!$H:$H,1,FALSE))=TRUE,"",VLOOKUP($K$4&$K$5&$Q20,기획현황!$H:$H,1,FALSE))
A21: 총합계 | E21: 64 | F21: 81 | G21: 83200 | H21: 4.825805e+08 | I21: 3395800000 | K21: =K20+1 -> 13 | L21: =IF(ISERROR(VLOOKUP($K$4&$K$5&$K21,기획현황!$H:$H,1,FALSE))=TRUE,"",VLOOKUP($K$4&$K$5&$K21,기획현황!$H:$H,1,FALSE)) -> SBR의류외13 | N21: =N20+1 -> 213 | O21: =IF(ISERROR(VLOOKUP($K$4&$K$5&$N21,기획현황!$H:$H,1,FALSE))=TRUE,"",VLOOKUP($K$4&$K$5&$N21,기획현황!$H:$H,1,FALSE)) | Q21: =Q20+1 -> 713 | R21: =IF(ISERROR(VLOOKUP($K$4&$K$5&$Q21,기획현황!$H:$H,1,FALSE))=TRUE,"",VLOOKUP($K$4&$K$5&$Q21,기획현황!$H:$H,1,FALSE))
K22: =K21+1 -> 14 | L22: =IF(ISERROR(VLOOKUP($K$4&$K$5&$K22,기획현황!$H:$H,1,FALSE))=TRUE,"",VLOOKUP($K$4&$K$5&$K22,기획현황!$H:$H,1,FALSE)) -> SBR의류외14 | N22: =N21+1 -> 214 | O22: =IF(ISERROR(VLOOKUP($K$4&$K$5&$N22,기획현황!$H:$H,1,FALSE))=TRUE,"",VLOOKUP($K$4&$K$5&$N22,기획현황!$H:$H,1,FALSE)) | Q22: =Q21+1 -> 714 | R22: =IF(ISERROR(VLOOKUP($K$4&$K$5&$Q22,기획현황!$H:$H,1,FALSE))=TRUE,"",VLOOKUP($K$4&$K$5&$Q22,기획현황!$H:$H,1,FALSE))
K23: =K22+1 -> 15 | L23: =IF(ISERROR(VLOOKUP($K$4&$K$5&$K23,기획현황!$H:$H,1,FALSE))=TRUE,"",VLOOKUP($K$4&$K$5&$K23,기획현황!$H:$H,1,FALSE)) -> SBR의류외15 | N23: =N22+1 -> 215 | O23: =IF(ISERROR(VLOOKUP($K$4&$K$5&$N23,기획현황!$H:$H,1,FALSE))=TRUE,"",VLOOKUP($K$4&$K$5&$N23,기획현황!$H:$H,1,FALSE)) | Q23: =Q22+1 -> 715 | R23: =IF(ISERROR(VLOOKUP($K$4&$K$5&$Q23,기획현황!$H:$H,1,FALSE))=TRUE,"",VLOOKUP($K$4&$K$5&$Q23,기획현황!$H:$H,1,FALSE))
K24: =K23+1 -> 16 | L24: =IF(ISERROR(VLOOKUP($K$4&$K$5&$K24,기획현황!$H:$H,1,FALSE))=TRUE,"",VLOOKUP($K$4&$K$5&$K24,기획현황!$H:$H,1,FALSE)) -> SBR의류외16 | N24: =N23+1 -> 216 | O24: =IF(ISERROR(VLOOKUP($K$4&$K$5&$N24,기획현황!$H:$H,1,FALSE))=TRUE,"",VLOOKUP($K$4&$K$5&$N24,기획현황!$H:$H,1,FALSE)) | Q24: =Q23+1 -> 716 | R24: =IF(ISERROR(VLOOKUP($K$4&$K$5&$Q24,기획현황!$H:$H,1,FALSE))=TRUE,"",VLOOKUP($K$4&$K$5&$Q24,기획현황!$H:$H,1,FALSE))
K25: =K24+1 -> 17 | L25: =IF(ISERROR(VLOOKUP($K$4&$K$5&$K25,기획현황!$H:$H,1,FALSE))=TRUE,"",VLOOKUP($K$4&$K$5&$K25,기획현황!$H:$H,1,FALSE)) -> SBR의류외17 | N25: =N24+1 -> 217 | O25: =IF(ISERROR(VLOOKUP($K$4&$K$5&$N25,기획현황!$H:$H,1,FALSE))=TRUE,"",VLOOKUP($K$4&$K$5&$N25,기획현황!$H:$H,1,FALSE)) | Q25: =Q24+1 -> 717 | R25: =IF(ISERROR(VLOOKUP($K$4&$K$5&$Q25,기획현황!$H:$H,1,FALSE))=TRUE,"",VLOOKUP($K$4&$K$5&$Q25,기획현황!$H:$H,1,FALSE))
K26: =K25+1 -> 18 | L26: =IF(ISERROR(VLOOKUP($K$4&$K$5&$K26,기획현황!$H:$H,1,FALSE))=TRUE,"",VLOOKUP($K$4&$K$5&$K26,기획현황!$H:$H,1,FALSE)) -> SBR의류외18 | N26: =N25+1 -> 218 | O26: =IF(ISERROR(VLOOKUP($K$4&$K$5&$N26,기획현황!$H:$H,1,FALSE))=TRUE,"",VLOOKUP($K$4&$K$5&$N26,기획현황!$H:$H,1,FALSE)) | Q26: =Q25+1 -> 718 | R26: =IF(ISERROR(VLOOKUP($K$4&$K$5&$Q26,기획현황!$H:$H,1,FALSE))=TRUE,"",VLOOKUP($K$4&$K$5&$Q26,기획현황!$H:$H,1,FALSE))
K27: =K26+1 -> 19 | L27: =IF(ISERROR(VLOOKUP($K$4&$K$5&$K27,기획현황!$H:$H,1,FALSE))=TRUE,"",VLOOKUP($K$4&$K$5&$K27,기획현황!$H:$H,1,FALSE)) -> SBR의류외19 | N27: =N26+1 -> 219 | O27: =IF(ISERROR(VLOOKUP($K$4&$K$5&$N27,기획현황!$H:$H,1,FALSE))=TRUE,"",VLOOKUP($K$4&$K$5&$N27,기획현황!$H:$H,1,FALSE)) | Q27: =Q26+1 -> 719 | R27: =IF(ISERROR(VLOOKUP($K$4&$K$5&$Q27,기획현황!$H:$H,1,FALSE))=TRUE,"",VLOOKUP($K$4&$K$5&$Q27,기획현황!$H:$H,1,FALSE))
K28: =K27+1 -> 20 | L28: =IF(ISERROR(VLOOKUP($K$4&$K$5&$K28,기획현황!$H:$H,1,FALSE))=TRUE,"",VLOOKUP($K$4&$K$5&$K28,기획현황!$H:$H,1,FALSE)) -> SBR의류외20 | N28: =N27+1 -> 220 | O28: =IF(ISERROR(VLOOKUP($K$4&$K$5&$N28,기획현황!$H:$H,1,FALSE))=TRUE,"",VLOOKUP($K$4&$K$5&$N28,기획현황!$H:$H,1,FALSE)) | Q28: =Q27+1 -> 720 | R28: =IF(ISERROR(VLOOKUP($K$4&$K$5&$Q28,기획현황!$H:$H,1,FALSE))=TRUE,"",VLOOKUP($K$4&$K$5&$Q28,기획현황!$H:$H,1,FALSE))
K29: =K28+1 -> 21 | L29: =IF(ISERROR(VLOOKUP($K$4&$K$5&$K29,기획현황!$H:$H,1,FALSE))=TRUE,"",VLOOKUP($K$4&$K$5&$K29,기획현황!$H:$H,1,FALSE)) -> SBR의류외21 | N29: =N28+1 -> 221 | O29: =IF(ISERROR(VLOOKUP($K$4&$K$5&$N29,기획현황!$H:$H,1,FALSE))=TRUE,"",VLOOKUP($K$4&$K$5&$N29,기획현황!$H:$H,1,FALSE)) | Q29: =Q28+1 -> 721 | R29: =IF(ISERROR(VLOOKUP($K$4&$K$5&$Q29,기획현황!$H:$H,1,FALSE))=TRUE,"",VLOOKUP($K$4&$K$5&$Q29,기획현황!$H:$H,1,FALSE))
K30: =K29+1 -> 22 | L30: =IF(ISERROR(VLOOKUP($K$4&$K$5&$K30,기획현황!$H:$H,1,FALSE))=TRUE,"",VLOOKUP($K$4&$K$5&$K30,기획현황!$H:$H,1,FALSE)) -> SBR의류외22 | N30: =N29+1 -> 222 | O30: =IF(ISERROR(VLOOKUP($K$4&$K$5&$N30,기획현황!$H:$H,1,FALSE))=TRUE,"",VLOOKUP($K$4&$K$5&$N30,기획현황!$H:$H,1,FALSE)) | Q30: =Q29+1 -> 722 | R30: =IF(ISERROR(VLOOKUP($K$4&$K$5&$Q30,기획현황!$H:$H,1,FALSE))=TRUE,"",VLOOKUP($K$4&$K$5&$Q30,기획현황!$H:$H,1,FALSE))
K31: =K30+1 -> 23 | L31: =IF(ISERROR(VLOOKUP($K$4&$K$5&$K31,기획현황!$H:$H,1,FALSE))=TRUE,"",VLOOKUP($K$4&$K$5&$K31,기획현황!$H:$H,1,FALSE)) -> SBR의류외23 | N31: =N30+1 -> 223 | O31: =IF(ISERROR(VLOOKUP($K$4&$K$5&$N31,기획현황!$H:$H,1,FALSE))=TRUE,"",VLOOKUP($K$4&$K$5&$N31,기획현황!$H:$H,1,FALSE)) | Q31: =Q30+1 -> 723 | R31: =IF(ISERROR(VLOOKUP($K$4&$K$5&$Q31,기획현황!$H:$H,1,FALSE))=TRUE,"",VLOOKUP($K$4&$K$5&$Q31,기획현황!$H:$H,1,FALSE))
K32: =K31+1 -> 24 | L32: =IF(ISERROR(VLOOKUP($K$4&$K$5&$K32,기획현황!$H:$H,1,FALSE))=TRUE,"",VLOOKUP($K$4&$K$5&$K32,기획현황!$H:$H,1,FALSE)) -> SBR의류외24 | N32: =N31+1 -> 224 | O32: =IF(ISERROR(VLOOKUP($K$4&$K$5&$N32,기획현황!$H:$H,1,FALSE))=TRUE,"",VLOOKUP($K$4&$K$5&$N32,기획현황!$H:$H,1,FALSE)) | Q32: =Q31+1 -> 724 | R32: =IF(ISERROR(VLOOKUP($K$4&$K$5&$Q32,기획현황!$H:$H,1,FALSE))=TRUE,"",VLOOKUP($K$4&$K$5&$Q32,기획현황!$H:$H,1,FALSE))
K33: =K32+1 -> 25 | L33: =IF(ISERROR(VLOOKUP($K$4&$K$5&$K33,기획현황!$H:$H,1,FALSE))=TRUE,"",VLOOKUP($K$4&$K$5&$K33,기획현황!$H:$H,1,FALSE)) -> SBR의류외25 | N33: =N32+1 -> 225 | O33: =IF(ISERROR(VLOOKUP($K$4&$K$5&$N33,기획현황!$H:$H,1,FALSE))=TRUE,"",VLOOKUP($K$4&$K$5&$N33,기획현황!$H:$H,1,FALSE)) | Q33: =Q32+1 -> 725 | R33: =IF(ISERROR(VLOOKUP($K$4&$K$5&$Q33,기획현황!$H:$H,1,FALSE))=TRUE,"",VLOOKUP($K$4&$K$5&$Q33,기획현황!$H:$H,1,FALSE))
... K107: =K106+1 -> 99 | L107: =IF(ISERROR(VLOOKUP($K$4&$K$5&$K107,기획현황!$H:$H,1,FALSE))=TRUE,"",VLOOKUP($K$4&$K$5&$K107,기획현황!$H:$H,1,FALSE)) | N107: =N106+1 -> 299 | O107: =IF(ISERROR(VLOOKUP($K$4&$K$5&$N107,기획현황!$H:$H,1,FALSE))=TRUE,"",VLOOKUP($K$4&$K$5&$N107,기획현황!$H:$H,1,FALSE)) | Q107: =Q106+1 -> 799 | R107: =IF(ISERROR(VLOOKUP($K$4&$K$5&$Q107,기획현황!$H:$H,1,FALSE))=TRUE,"",VLOOKUP($K$4&$K$5&$Q107,기획현황!$H:$H,1,FALSE))
K108: =K107+1 -> 100 | L108: =IF(ISERROR(VLOOKUP($K$4&$K$5&$K108,기획현황!$H:$H,1,FALSE))=TRUE,"",VLOOKUP($K$4&$K$5&$K108,기획현황!$H:$H,1,FALSE))
K109: =K108+1 -> 101 | L109: =IF(ISERROR(VLOOKUP($K$4&$K$5&$K109,기획현황!$H:$H,1,FALSE))=TRUE,"",VLOOKUP($K$4&$K$5&$K109,기획현황!$H:$H,1,FALSE))
K110: =K109+1 -> 102 | L110: =IF(ISERROR(VLOOKUP($K$4&$K$5&$K110,기획현황!$H:$H,1,FALSE))=TRUE,"",VLOOKUP($K$4&$K$5&$K110,기획현황!$H:$H,1,FALSE))
K111: =K110+1 -> 103 | L111: =IF(ISERROR(VLOOKUP($K$4&$K$5&$K111,기획현황!$H:$H,1,FALSE))=TRUE,"",VLOOKUP($K$4&$K$5&$K111,기획현황!$H:$H,1,FALSE))
K112: =K111+1 -> 104 | L112: =IF(ISERROR(VLOOKUP($K$4&$K$5&$K112,기획현황!$H:$H,1,FALSE))=TRUE,"",VLOOKUP($K$4&$K$5&$K112,기획현황!$H:$H,1,FALSE))
K113: =K112+1 -> 105 | L113: =IF(ISERROR(VLOOKUP($K$4&$K$5&$K113,기획현황!$H:$H,1,FALSE))=TRUE,"",VLOOKUP($K$4&$K$5&$K113,기획현황!$H:$H,1,FALSE))
K114: =K113+1 -> 106 | L114: =IF(ISERROR(VLOOKUP($K$4&$K$5&$K114,기획현황!$H:$H,1,FALSE))=TRUE,"",VLOOKUP($K$4&$K$5&$K114,기획현황!$H:$H,1,FALSE))
...

Sheet 기획현황
C1: PO ISSUE | F1: 1 | G1: =F1+1 -> 2 | H1: =G1+1 -> 3 | I1: =H1+1 -> 4 | J1: =I1+1 -> 5 | K1: =J1+1 -> 6 | L1: =K1+1 -> 7 | M1: =L1+1 -> 8 | N1: =M1+1 -> 9 | ... BR1: =BQ1+1 -> 65
K2: 2014 | L2: FW | M2: 기획현황 (♥문솔♥) | BX2: DATA UPLOAD FOR E-BIZ | CS2: TAG ISSUE | DG2: **PRODUCTION SCHEDULE
AO3: 환율 | AS3: 관세 | AW3: 제비용 | AX3: *인도네시아, 방글라데시 무관세 적용
AO4: KRW | AP4: EUR | AQ4: USD | AR4: JPY | AS4: 모자 | AT4: 의류 | AU4: 가방 | AV4: ACC | AW4: 0.05 | BN4: SHORTAGE | DV4: =TODAY() -> 42191
AO5: 1 | AP5: 1500 | AQ5: 1100 | AR5: 13 | AS5: 0.08 | AT5: 0.13 | AU5: 0.056 | AV5: 0.08 | BB5: =TODAY() -> 42191 | BG5: 건별계약서내용과 동일
K6: * 업체,업체차수,브랜드 정렬 | AZ6: 월,수요일 | BN6: 0.1
BX7: 컬렉션 | BY7: 시즌 | BZ7: 소재 | CA7: 품목 | CB7: 성별 | CC7: 국가 | CD7: 원산지 코드 | CE7: STYLE | CF7: 순번 | CG7: STYLE명 | CH7: COL | CI7: S_TYPE | CJ7: SIZE | CK7: 수량 | CL7: FOB | CM7: TAG가 | CN7: 원가 | CO7: 자재원가 | CP7: 구분
K8: 이미지 | L8: 브랜드 | M8: 브랜드명 | N8: 년도 | O8: 시즌 | P8: 품목 | Q8: 품목명 | R8: 성별 | S8: 순번 | T8: 순번 | U8: 품번 | V8: 품번수 | W8: 품명(=샘플명) | X8: 색상 | Y8: 색상명 | Z8: 품번색상 | AA8: 품번오더차수 | AB8: 색상수 | AC8: 원자재 혼용율 | AD8: 사이즈타입 | AE8: 사이즈 | AF8: 수량 | AG8: 업체 | AM8: TAG가 | AO8: 원가(-VAT) | AX8: 일정 | BG8: 원가 확정여부 | BH8: 입고일 확정여부 | BI8: 입고수량점검 | BO8: TOTAL | BX8: 브랜드 | BY8: 시즌 | BZ8: 분류 | CA8: 품목 | CB8: 성별 | CC8: 국가 | CD8: 샘플명 | CE8: 품번 | CF8: 순번 | CG8: 품번명 | CH8: 색상 | CI8: 사이즈타입 | CJ8: 사이즈 | CK8: 수량 | CL8: FOB($) | CM8: TAG가(\) | CN8: 원가(\,-VAT) | CO8: 자재원가(\,-VAT) | CP8: 수입1, 내수2 | CQ8: 발주번호 | CS8: NO. | CT8: 품번 (HAT'S ON CODE) | CU8: 명칭(상단) | CV8: 명칭(하단) | CW8: 명칭 (색상/사이즈) | CX8: 브랜드 | CY8: 순번 | CZ8: 수량 | DA8: TAG가(\) | DB8: 색상 | DC8: 사이즈 | DD8: 자율안전인증번호 | DE8: 최초순번 | DG8: PRODUCTION SCHEDULE | DZ8: 비고 | EF8: 순번 | EL8: 가격사정여부
AG9: 업체명 | AH9: 차수 | AI9: 차수 | AJ9: 분류 | AK9: 국가 | AL9: 수입/내수 | AN9: 확정일 | AO9: 목표 | AP9: 조정 | AQ9: 차이 | AR9: 공급자재 | AV9: 해외(FOB, USD, JPY) | AW9: 국내(KRW) | AX9: 발주일 | AY9: 선적일 | AZ9: 납기일 | BO9: 수량 | BP9: 원가금액 (-VAT,백만원) | BQ9: TAG가금액 (백만원) | BR9: MU | DG9: PO 발송일 | DH9: 메인작지 수령 목표일 | DI9: 메인작지 수령일 | DJ9: 메인작지 발송일 | DK9: 건별계약서 작성(원가, 납기) | DL9: 중국원단사용유무 | DN9: 원자재 발주일 | DO9: 부자재 발주일 | DP9: 원부자재 발송 목표일 | DQ9: 원자재 발송일 | DR9: 부자재 발송일 | DS9: 최초상품대금 결재상신일 | DT9: PPS 수령일 | DU9: PPS 컨펌일 | DV9: 가격택 발송일 | DW9: INSPECTION일 | DX9: SPS 수령일 | DY9: 입고 완료여부 | EF9: 0
AR10: 원자재 | AS10: 부자재 | AT10: 기타 | AU10: 계 | AZ10: 목표 | BA10: 계약 | BB10: 1차입고 | BC10: 2차입고 | BD10: 3차입고 | BE10: 4차입고 | BF10: 5차입고 | BI10: 1차입고 | BJ10: 2차입고 | BK10: 3차입고 | BL10: 4차입고 | BM10: 5차입고 | BN10: 미입고수량 | DE10: 최초순번 | DL10: 총가지수 | DM10: 중국가지수 | EF10: 5 | EI10: 품번수계산
V11: =SUM(V$13:V62617)-SUMIF($I:$I,"TTL",V:V) -> 95 | AB11: =SUM(AB$13:AB62617)-SUMIF($I:$I,"TTL",AB:AB) -> 156 | AF11: =SUM(AF$13:AF62617)-SUMIF($I:$I,"TTL",AF:AF) -> 165290 | BI11: =SUM(BI$13:BI62621)-SUMIF($I:$I,"TTL",BI:BI) -> 136505 | BJ11: =SUM(BJ$13:BJ62621)-SUMIF($I:$I,"TTL",BJ:BJ) -> 24000 | BK11: =SUM(BK$13:BK62621)-SUMIF($I:$I,"TTL",BK:BK) -> 4081 | BL11: =SUM(BL$13:BL62621)-SUMIF($I:$I,"TTL",BL:BL) -> 0 | BM11: =SUM(BM$13:BM62621)-SUMIF($I:$I,"TTL",BM:BM) -> 0 | BN11: =SUM(BN$13:BN62621)-SUMIF($I:$I,"TTL",BN:BN) -> 0 | BO11: =SUM(BO$13:BO62617)-SUMIF($I:$I,"TTL",BO:BO) -> 165290 | BP11: =SUM(BP$13:BP62617)-SUMIF($I:$I,"TTL",BP:BP) -> 1.1077518e+09 | BQ11: =SUM(BQ$13:BQ62617)-SUMIF($I:$I,"TTL",BQ:BQ) -> 7042910000 | BR11: =IF(ISERROR($BQ11/($BP11*1.1))=TRUE,0,$BQ11/($BP11*1.1)) -> 5.7798556 | BV11: 품번/색상/사이즈/수량/업체/차수/국가 | DH11: 90 | DL11: 숫자로 표기 | DM11: 숫자로 표기 | DN11: '없음'표기 | DO11: '없음'표기 | DP11: 60 | DQ11: 최종일표기 | DR11: 최종일표기 | EC11: 품번색상/발주일 | ED11: 품번색상사이즈 | EE11: 리오더(NEW) | EF11: 리오더(RUNNING) | EG11: 품번차수 | EI11: 품번 | EJ11: 품번색상
A12: 구분 | B12: 브랜드품목 | C12: 브랜드/업체/차수 | D12: 브랜드/업체/차수/품번색상 | E12: 순서 | F12: 브랜드/업체/차수/순서 | G12: 브랜드/업체/차수/순서/품번색상/사이즈 | H12: 브랜드/순번 | I12: 브랜드 | J12: 공란 | K12: 이미지 | L12: 브랜드 | M12: 브랜드명 | N12: 년도 | O12: 시즌 | P12: 품목 | Q12: 품목명 | R12: 성별 | S12: 순번 | T12: 순번2 | U12: 품번 | V12: 품번수 | W12: 품명(=샘플명) | X12: 색상 | Y12: 색상명 | Z12: 품번색상 | AA12: 오더차수 | AB12: 색상수 | AC12: 혼용율 | AD12: 사이즈타입 | AE12: 사이즈 | AF12: 수량 | AG12: 업체명 | AH12: 차수 | AI12: 차수2 | AJ12: 분류 | AK12: 국가 | AL12: 수입/내수 | AM12: TAG가목표 | AN12: TAG가조정 | AO12: 원가목표 | AP12: 원가조정 | AQ12: 원가차이 | AR12: 공급원자재 | AS12: 공급부자재 | AT12: 공급기타 | AU12: 공급계 | AV12: 해외(FOB, USD, JPY) | AW12: 국내(KRW) | AX12: 발주일 | AY12: 선적일 | AZ12: 목표납기일 | BA12: 계약납기일 | BB12: 1차입고일 | BC12: 2차입고일 | BD12: 3차입고일 | BE12: 4차입고일 | BF12: 5차입고일 | BG12: 확정여부 | BH12: 확정여부 | BI12: 1차입고수량 | BJ12: 2차입고수량 | BK12: 3차입고수량 | BL12: 3차입고수량 | BM12: 3차입고수량 | BN12: 차이수량 | BO12: TOTAL수량 | BP12: TOTAL원가금액 | BQ12: TOTALTAG가금액 | BR12: MU
A13: =IF(OR($I13="TTL",$I13=""),"",IF(ISERROR(VLOOKUP($B13,CODE!$D:$G,CODE!$F$1-2,FALSE))=TRUE,"전략",VLOOKUP($B13,CODE!$D:$G,CODE!$F$1-2,FALSE))) -> F-CAP | B13: =IF(OR($I13="TTL",$I13=""),"",IF(VLOOKUP($P13,CODE!$K:$O,CODE!$O$1,FALSE)="",$I13,$I13&"-"&VLOOKUP($P13,CODE!$K:$O,CODE!$O$1,FALSE))) -> DPS | C13: =IF($I13="TTL","",I13&"-"&$AG13&"-"&$AI13) -> DPS-캡보이-02 | D13: =$C13&$Z13 -> DPS-캡보이-02DPSSNF3501PK | E13: =IF($I13="TTL",0,IF(ISERROR(IF($Z12=$Z13,$E12,$E12+1))=TRUE,1,IF($Z12=$Z13,$E12,$E12+1))) -> 1 | F13: =$C13&$E13 -> DPS-캡보이-021 | G13: =$F13&"-"&$U13&$Y13&$AE13 -> DPS-캡보이-021-DPSSNF3501PINKOSM | H13: =IF(ISERROR(I13&VLOOKUP(P13,CODE!$K:$N,CODE!$N$1,FALSE)&S13)=TRUE,0,I13&VLOOKUP(P13,CODE!$K:$N,CODE!$N$1,FALSE)&S13) -> DPS의류외501 | I13: =IF(ISERROR(SEARCH("TTL",$K13))=TRUE,IF($L13="","",VLOOKUP($L13,CODE!$B:$G,CODE!$D$1,FALSE)),"TTL") -> DPS | J13: =MID(W13,1,6) -> 14SS F | L13: DPS | M13: =IF(OR($I13="TTL",$L13=""),"",VLOOKUP($L13,CODE!$B:$D,CODE!$C$1,FALSE)) -> DISNEY PRINCESS | N13: =IF(OR($I13="TTL",$L13=""),"",VLOOKUP($K$2,CODE!$S:$T,CODE!$T$1-1,FALSE)) -> F | O13: =IF(OR($I13="TTL",$L13=""),"",VLOOKUP($L$2,CODE!$X:$Y,CODE!$Y$1-1,FALSE)) -> 3 | P13: SN | Q13: =IF(OR($I13="TTL",$P13=""),"",VLOOKUP($P13,CODE!$K:$M,CODE!$L$1,FALSE)) -> SNAPBACK | R13: K | S13: 501 | T13: =IF(OR($I13="TTL",$S13=""),"",IF($S13<10,"00"&$S13,IF($S13<100,"0"&$S13,$S13))) -> 501 | U13: =IF($I13="TTL","",$L13&$P13&$N13&$O13&$T13) -> DPSSNF3501 | V13: =IF($I13="TTL",SUMIF($C:$C,MID($K13,1,SEARCH("TTL",$K13)-2),$V:$V),IF($EI13="",0,1/COUNTIF($EI:$EI,$EI13))) -> 0.5 | W13: 14SS FROZEN SNAP_01_PK_KIDS | X13: =IF($Y13="","",VLOOKUP($Y13,CODE!$AE:$AF,CODE!$AF$1-1,FALSE)) -> PK | Y13: PINK | Z13: =$U13&$X13 -> DPSSNF3501PK | AA13: =VLOOKUP($Z13&$AX13,$EC:$EG,5,FALSE) | AB13: =IF($I13="TTL",SUMIF($C:$C,MID($K13,1,SEARCH("TTL",$K13)-2),$AB:$AB),IF($EJ13="",0,1/COUNTIF($EJ:$EJ,$EJ13))) -> 0.5 | AC13: 0 | AD13: 1 | AE13: OSM | AF13: 600 | AG13: 캡보이 | AH13: 2 | AI13: =IF($AH13=0,"",IF($AH13<10,"0"&$AH13,$AH13)) -> 02 | AJ13: M | AK13: KR | AL13: =IF($AK13=0,"",IF($AK13="KR",2,1)) -> 2 | AM13: =IF(ISERROR(VLOOKUP($F13,[1]기획현황취합!$A$1:$E$65485,[1]기획현황취합!$B$1,FALSE))=TRUE,0,VLOOKUP($F13,[1]기획현황취합!$A$1:$E$65485,[1]기획현황취합!$B$1,FALSE)) -> 45000 | AN13: =IF(ISERROR(VLOOKUP($F13,[1]기획현황취합!$A$1:$E$65485,[1]기획현황취합!$C$1,FALSE))=TRUE,0,VLOOKUP($F13,[1]기획현황취합!$A$1:$E$65485,[1]기획현황취합!$C$1,FALSE)) -> 41752 | AO13: =IF(ISERROR(($AM13/1.1)/VLOOKUP($AG13,'TARGET MU'!$A:$D,'TARGET MU'!$D$1,FALSE))=TRUE,0,($AM13/1.1)/VLOOKUP($AG13,'TARGET MU'!$A:$D,'TARGET MU'!$D$1,FALSE)) -> 10227.273 | AP13: =IF(OR(AF13=0,AND(AV13=0,AW13=0)),0,IF(AG13="캡보이2",AV13*$AQ$5+AU13,IF(OR(AK13="IN",AK13="BG",AK13="VT",AK13="CB"),$AU13+(($AV13*(1+$AW$4))*(HLOOKUP(VLOOKUP(AG13,'TARGET MU'!$A:$P,'TARGET MU'!$J$1,FALSE),$AO$4:$AR$5,2,FALSE)))+$AW13,$AU13+((($AV13*(1+$AW$4))*(1+HLOOKUP(VLOOKUP($P13,CODE!$K:$P,CODE!$P$1,FALSE),$AS$4:$AV$5,2,FALSE)))*(HLOOKUP(VLOOKUP(AG13,'TARGET MU'!$A:$P,'TARGET MU'!$J$1,FALSE),$AO$4:$AR$5,2,FALSE)))+$AW13))) -> 11700 | AQ13: =AP13-AO13 -> 1472.7273 | AU13: =SUM(AR13:AT13) -> 0 | AW13: 11700 | AX13: =IF(ISERROR(VLOOKUP($F13,[1]기획현황취합!$A$1:$E$65485,[1]기획현황취합!$D$1,FALSE))=TRUE,0,VLOOKUP($F13,[1]기획현황취합!$A$1:$E$65485,[1]기획현황취합!$D$1,FALSE)) -> 41736 | AY13: 0 | AZ13: =IF(ISERROR(VLOOKUP($F13,[1]기획현황취합!$A$1:$E$65485,[1]기획현황취합!$E$1,FALSE))=TRUE,0,VLOOKUP($F13,[1]기획현황취합!$A$1:$E$65485,[1]기획현황취합!$E$1,FALSE)) -> 41774 | BA13: 0 | BB13: 41761 | BC13: 41768 | BF13: 0 | BG13: 확정 | BH13: 확정 | BI13: =IF($I13="TTL",SUMIF($C:$C,MID($K13,1,SEARCH("TTL",$K13)-2),$BI:$BI),SUMIF(실입고현황!$A:$A,BB13&VLOOKUP($AG13,'TARGET MU'!$A:$D,'TARGET MU'!$B$1,FALSE)&$Z13&" "&$AE13,실입고현황!$C:$C)) -> 150 | BJ13: =IF($I13="TTL",SUMIF($C:$C,MID($K13,1,SEARCH("TTL",$K13)-2),$BJ:$BJ),SUMIF(실입고현황!$A:$A,BC13&VLOOKUP($AG13,'TARGET MU'!$A:$D,'TARGET MU'!$B$1,FALSE)&$Z13&" "&$AE13,실입고현황!$C:$C)) -> 450 | BK13: =IF($I13="TTL",SUMIF($C:$C,MID($K13,1,SEARCH("TTL",$K13)-2),$BK:$BK),SUMIF(실입고현황!$A:$A,BD13&VLOOKUP($AG13,'TARGET MU'!$A:$D,'TARGET MU'!$B$1,FALSE)&$Z13&" "&$AE13,실입고현황!$C:$C)) -> 0 | BL13: =IF($I13="TTL",SUMIF($C:$C,MID($K13,1,SEARCH("TTL",$K13)-2),$BL:$BL),SUMIF(실입고현황!$A:$A,BE13&VLOOKUP($AG13,'TARGET MU'!$A:$D,'TARGET MU'!$B$1,FALSE)&$Z13&" "&$AE13,실입고현황!$C:$C)) -> 0 | BM13: =IF($I13="TTL",SUMIF($C:$C,MID($K13,1,SEARCH("TTL",$K13)-2),$BM:$BM),SUMIF(실입고현황!$A:$A,BF13&VLOOKUP($AG13,'TARGET MU'!$A:$D,'TARGET MU'!$B$1,FALSE)&$Z13&" "&$AE13,실입고현황!$C:$C)) -> 0 | BN13: =IF($I13="TTL",SUMIF($C:$C,MID($K13,1,SEARCH("TTL",$K13)-2),$BN:$BN),IF(($BO13-SUM($BI13,$BJ13,$BK13,BL13,BM13))<$BO13*$BN$6,0,$BO13-SUM($BI13,$BJ13,$BK13,BL13,BM13))) -> 0 | BO13: =IF($I13="TTL",SUMIF($C:$C,MID($K13,1,SEARCH("TTL",$K13)-2),$BO:$BO),$AF13) -> 600 | BP13: =IF($I13="TTL",SUMIF($C:$C,MID($K13,1,SEARCH("TTL",$K13)-2),$BP:$BP),IF(AO13=0,0,IF($AP13=0,$AO13*$AF13,$AP13*$AF13))) -> 7020000 | BQ13: =IF($I13="TTL",SUMIF($C:$C,MID($K13,1,SEARCH("TTL",$K13)-2),$BQ:$BQ),$AM13*$AF13) -> 27000000 | BR13: =IF(ISERROR($BQ13/($BP13*1.1))=TRUE,0,$BQ13/($BP13*1.1)) -> 3.4965035 | BT13: =IF(ISERROR(Z13&VLOOKUP($AG13,'TARGET MU'!$A:$D,'TARGET MU'!$B$1,FALSE))=TRUE,"",Z13&VLOOKUP($AG13,'TARGET MU'!$A:$D,'TARGET MU'!$B$1,FALSE)) -> DPSSNF3501PK캡보이 | BU13: =AP13 -> 11700 | BV13: =Z13&AE13&AF13&AM13&AG13&AI13&AK13 -> DPSSNF3501PKOSM60045000캡보이02KR | BX13: =IF($I13="TTL","",$L13) -> DPS | BY13: =$O13 -> 3 | BZ13: =$AJ13 -> M | CA13: =$P13 -> SN | CB13: =$R13 -> K | CC13: =$AK13 -> KR | CD13: =$W13 -> 14SS FROZEN SNAP_01_PK_KIDS | CE13: =$U13 -> DPSSNF3501 | CF13: =$T13 -> 501 | CG13: =$W13 -> 14SS FROZEN SNAP_01_PK_KIDS | CH13: =$X13 -> PK | CI13: =$AD13 -> 1 | CJ13: =$AE13 -> OSM | CK13: =IF($I13="TTL",SUMIF($C:$C,MID($K13,1,SEARCH("TTL",$K13)-2),$BO:$BO),$AF13) -> 600 | CL13: =$AV13 -> 0 | CM13: =$AM13 -> 45000 | CN13: =$AP13-$AU13 -> 11700 | CO13: =$AU13 -> 0 | CP13: =$AL13 -> 2 | CQ13: 514530 | CT13: =IF($I13="TTL",$K13,$Z13&$AE13) -> DPSSNF3501PKOSM | CU13: =$M13 -> DISNEY PRINCESS | CV13: =IF($I13="TTL","",IF($CT13="","",$Q13&"_"&$T13&IF(R13="K","_KIDS",""))) -> SNAPBACK_501_KIDS | CW13: =IF($I13="TTL","",IF($CT13="","",$Y13&"_"&$AE13)) -> PINK_OSM | CX13: =$L13 -> DPS | CY13: =$T13 -> 501 | CZ13: =IF($I13="TTL",SUMIF($C:$C,MID($K13,1,SEARCH("TTL",$K13)-2),$CZ:$CZ),$AF13) -> 600 | DA13: =$AM13 -> 45000 | DB13: =$Y13 -> PINK | DC13: =$AE13 -> OSM | DG13: 41736 | DH13: =IF(OR($I13="TTL",$I13=""),"",AZ13-$DH$11) -> 41684 | DI13: 41736 | DJ13: 41736 | DK13: 없음 | DL13: 3 | DM13: 0 | DN13: 없음 | DO13: 없음 | DP13: =IF(OR($DN13="없음",$I13="TTL",$I13=""),"",AZ13-$DP$11) | DQ13: 없음 | DR13: 없음 | DS13: 없음 | DT13: 없음 | DU13: 없음 | DV13: 41759 | DW13: 없음 | DX13: 없음 | DY13: 완료 | EC13: =IF(OR($Z12&$AX12=$Z13&$AX12,$Z13&$AX13=""),"",$Z13&$AX13) -> DPSSNF3501PK41736 | ED13: =IF(OR(Z12&AE12=Z13&AE13,Z13=""),"",Z13&AE13) -> DPSSNF3501PKOSM | EE13: =IF($ED13="",0,IF(COUNTIF(ED$12:ED12,ED13)=0,0,COUNTIF(ED$12:ED12,ED13))) -> 0 | EF13: =IF(OR($AJ13="B",$ED13="",MID($U13,8,1)=$EF$9,MID($U13,8,1)=$EF$10),0,1) -> 0 | EG13: =IF(EE13+EF13=0,"","R"&(EE13+EF13)) | EI13: =IF($ED13="","",IF($EE13=0,U13,"")) -> DPSSNF3501 | EJ13: =IF($ED13="","",IF($EE13=0,Z13,"")) -> DPSSNF3501PK | EL13: 없음
A14: =IF(OR($I14="TTL",$I14=""),"",IF(ISERROR(VLOOKUP($B14,CODE!$D:$G,CODE!$F$1-2,FALSE))=TRUE,"전략",VLOOKUP($B14,CODE!$D:$G,CODE!$F$1-2,FALSE))) -> F-CAP | B14: =IF(OR($I14="TTL",$I14=""),"",IF(VLOOKUP($P14,CODE!$K:$O,CODE!$O$1,FALSE)="",$I14,$I14&"-"&VLOOKUP($P14,CODE!$K:$O,CODE!$O$1,FALSE))) -> DPS | C14: =IF($I14="TTL","",I14&"-"&$AG14&"-"&$AI14) -> DPS-캡보이-02 | D14: =$C14&$Z14 -> DPS-캡보이-02DPSSNF3501PK | E14: =IF($I14="TTL",0,IF(ISERROR(IF($Z13=$Z14,$E13,$E13+1))=TRUE,1,IF($Z13=$Z14,$E13,$E13+1))) -> 1 | F14: =$C14&$E14 -> DPS-캡보이-021 | G14: =$F14&"-"&$U14&$Y14&$AE14 -> DPS-캡보이-021-DPSSNF3501PINKOML | H14: =IF(ISERROR(I14&VLOOKUP(P14,CODE!$K:$N,CODE!$N$1,FALSE)&S14)=TRUE,0,I14&VLOOKUP(P14,CODE!$K:$N,CODE!$N$1,FALSE)&S14) -> DPS의류외501 | I14: =IF(ISERROR(SEARCH("TTL",$K14))=TRUE,IF($L14="","",VLOOKUP($L14,CODE!$B:$G,CODE!$D$1,FALSE)),"TTL") -> DPS | J14: =MID(W14,1,6) -> 14SS F | L14: DPS | M14: =IF(OR($I14="TTL",$L14=""),"",VLOOKUP($L14,CODE!$B:$D,CODE!$C$1,FALSE)) -> DISNEY PRINCESS | N14: =IF(OR($I14="TTL",$L14=""),"",VLOOKUP($K$2,CODE!$S:$T,CODE!$T$1-1,FALSE)) -> F | O14: =IF(OR($I14="TTL",$L14=""),"",VLOOKUP($L$2,CODE!$X:$Y,CODE!$Y$1-1,FALSE)) -> 3 | P14: SN | Q14: =IF(OR($I14="TTL",$P14=""),"",VLOOKUP($P14,CODE!$K:$M,CODE!$L$1,FALSE)) -> SNAPBACK | R14: K | S14: 501 | T14: =IF(OR($I14="TTL",$S14=""),"",IF($S14<10,"00"&$S14,IF($S14<100,"0"&$S14,$S14))) -> 501 | U14: =IF($I14="TTL","",$L14&$P14&$N14&$O14&$T14) -> DPSSNF3501 | V14: =IF($I14="TTL",SUMIF($C:$C,MID($K14,1,SEARCH("TTL",$K14)-2),$V:$V),IF($EI14="",0,1/COUNTIF($EI:$EI,$EI14))) -> 0.5 | W14: 14SS FROZEN SNAP_01_PK_KIDS | X14: =IF($Y14="","",VLOOKUP($Y14,CODE!$AE:$AF,CODE!$AF$1-1,FALSE)) -> PK | Y14: PINK | Z14: =$U14&$X14 -> DPSSNF3501PK | AA14: =VLOOKUP($Z14&$AX14,$EC:$EG,5,FALSE) | AB14: =IF($I14="TTL",SUMIF($C:$C,MID($K14,1,SEARCH("TTL",$K14)-2),$AB:$AB),IF($EJ14="",0,1/COUNTIF($EJ:$EJ,$EJ14))) -> 0.5 | AC14: 0 | AD14: 1 | AE14: OML | AF14: 400 | AG14: 캡보이 | AH14: 2 | AI14: =IF($AH14=0,"",IF($AH14<10,"0"&$AH14,$AH14)) -> 02 | AJ14: M | AK14: KR | AL14: =IF($AK14=0,"",IF($AK14="KR",2,1)) -> 2 | AM14: =IF(ISERROR(VLOOKUP($F14,[1]기획현황취합!$A$1:$E$65485,[1]기획현황취합!$B$1,FALSE))=TRUE,0,VLOOKUP($F14,[1]기획현황취합!$A$1:$E$65485,[1]기획현황취합!$B$1,FALSE)) -> 45000 | AN14: =IF(ISERROR(VLOOKUP($F14,[1]기획현황취합!$A$1:$E$65485,[1]기획현황취합!$C$1,FALSE))=TRUE,0,VLOOKUP($F14,[1]기획현황취합!$A$1:$E$65485,[1]기획현황취합!$C$1,FALSE)) -> 41752 | AO14: =IF(ISERROR(($AM14/1.1)/VLOOKUP($AG14,'TARGET MU'!$A:$D,'TARGET MU'!$D$1,FALSE))=TRUE,0,($AM14/1.1)/VLOOKUP($AG14,'TARGET MU'!$A:$D,'TARGET MU'!$D$1,FALSE)) -> 10227.273 | AP14: =IF(OR(AF14=0,AND(AV14=0,AW14=0)),0,IF(AG14="캡보이2",AV14*$AQ$5+AU14,IF(OR(AK14="IN",AK14="BG",AK14="VT",AK14="CB"),$AU14+(($AV14*(1+$AW$4))*(HLOOKUP(VLOOKUP(AG14,'TARGET MU'!$A:$P,'TARGET MU'!$J$1,FALSE),$AO$4:$AR$5,2,FALSE)))+$AW14,$AU14+((($AV14*(1+$AW$4))*(1+HLOOKUP(VLOOKUP($P14,CODE!$K:$P,CODE!$P$1,FALSE),$AS$4:$AV$5,2,FALSE)))*(HLOOKUP(VLOOKUP(AG14,'TARGET MU'!$A:$P,'TARGET MU'!$J$1,FALSE),$AO$4:$AR$5,2,FALSE)))+$AW14))) -> 11700 | AQ14: =AP14-AO14 -> 1472.7273 | AR14: 0 | AS14: 0 | AU14: =SUM(AR14:AT14) -> 0 | AV14: 0 | AW14: 11700 | AX14: =IF(ISERROR(VLOOKUP($F14,[1]기획현황취합!$A$1:$E$65485,[1]기획현황취합!$D$1,FALSE))=TRUE,0,VLOOKUP($F14,[1]기획현황취합!$A$1:$E$65485,[1]기획현황취합!$D$1,FALSE)) -> 41736 | AY14: 0 | AZ14: =IF(ISERROR(VLOOKUP($F14,[1]기획현황취합!$A$1:$E$65485,[1]기획현황취합!$E$1,FALSE))=TRUE,0,VLOOKUP($F14,[1]기획현황취합!$A$1:$E$65485,[1]기획현황취합!$E$1,FALSE)) -> 41774 | BA14: 0 | BB14: 41761 | BC14: 41768 | BF14: 0 | BG14: 확정 | BH14: 확정 | BI14: =IF($I14="TTL",SUMIF($C:$C,MID($K14,1,SEARCH("TTL",$K14)-2),$BI:$BI),SUMIF(실입고현황!$A:$A,BB14&VLOOKUP($AG14,'TARGET MU'!$A:$D,'TARGET MU'!$B$1,FALSE)&$Z14&" "&$AE14,실입고현황!$C:$C)) -> 145 | BJ14: =IF($I14="TTL",SUMIF($C:$C,MID($K14,1,SEARCH("TTL",$K14)-2),$BJ:$BJ),SUMIF(실입고현황!$A:$A,BC14&VLOOKUP($AG14,'TARGET MU'!$A:$D,'TARGET MU'!$B$1,FALSE)&$Z14&" "&$AE14,실입고현황!$C:$C)) -> 255 | BK14: =IF($I14="TTL",SUMIF($C:$C,MID($K14,1,SEARCH("TTL",$K14)-2),$BK:$BK),SUMIF(실입고현황!$A:$A,BD14&VLOOKUP($AG14,'TARGET MU'!$A:$D,'TARGET MU'!$B$1,FALSE)&$Z14&" "&$AE14,실입고현황!$C:$C)) -> 0 | BL14: =IF($I14="TTL",SUMIF($C:$C,MID($K14,1,SEARCH("TTL",$K14)-2),$BL:$BL),SUMIF(실입고현황!$A:$A,BE14&VLOOKUP($AG14,'TARGET MU'!$A:$D,'TARGET MU'!$B$1,FALSE)&$Z14&" "&$AE14,실입고현황!$C:$C)) -> 0 | BM14: =IF($I14="TTL",SUMIF($C:$C,MID($K14,1,SEARCH("TTL",$K14)-2),$BM:$BM),SUMIF(실입고현황!$A:$A,BF14&VLOOKUP($AG14,'TARGET MU'!$A:$D,'TARGET MU'!$B$1,FALSE)&$Z14&" "&$AE14,실입고현황!$C:$C)) -> 0 | BN14: =IF($I14="TTL",SUMIF($C:$C,MID($K14,1,SEARCH("TTL",$K14)-2),$BN:$BN),IF(($BO14-SUM($BI14,$BJ14,$BK14,BL14,BM14))<$BO14*$BN$6,0,$BO14-SUM($BI14,$BJ14,$BK14,BL14,BM14))) -> 0 | BO14: =IF($I14="TTL",SUMIF($C:$C,MID($K14,1,SEARCH("TTL",$K14)-2),$BO:$BO),$AF14) -> 400 | BP14: =IF($I14="TTL",SUMIF($C:$C,MID($K14,1,SEARCH("TTL",$K14)-2),$BP:$BP),IF(AO14=0,0,IF($AP14=0,$AO14*$AF14,$AP14*$AF14))) -> 4680000 | BQ14: =IF($I14="TTL",SUMIF($C:$C,MID($K14,1,SEARCH("TTL",$K14)-2),$BQ:$BQ),$AM14*$AF14) -> 18000000 | BR14: =IF(ISERROR($BQ14/($BP14*1.1))=TRUE,0,$BQ14/($BP14*1.1)) -> 3.4965035 | BT14: =IF(ISERROR(Z14&VLOOKUP($AG14,'TARGET MU'!$A:$D,'TARGET MU'!$B$1,FALSE))=TRUE,"",Z14&VLOOKUP($AG14,'TARGET MU'!$A:$D,'TARGET MU'!$B$1,FALSE)) -> DPSSNF3501PK캡보이 | BU14: =AP14 -> 11700 | BV14: =Z14&AE14&AF14&AM14&AG14&AI14&AK14 -> DPSSNF3501PKOML40045000캡보이02KR | BX14: =IF($I14="TTL","",$L14) -> DPS | BY14: =$O14 -> 3 | BZ14: =$AJ14 -> M | CA14: =$P14 -> SN | CB14: =$R14 -> K | CC14: =$AK14 -> KR | CD14: =$W14 -> 14SS FROZEN SNAP_01_PK_KIDS | CE14: =$U14 -> DPSSNF3501 | CF14: =$T14 -> 501 | CG14: =$W14 -> 14SS FROZEN SNAP_01_PK_KIDS | CH14: =$X14 -> PK | CI14: =$AD14 -> 1 | CJ14: =$AE14 -> OML | CK14: =IF($I14="TTL",SUMIF($C:$C,MID($K14,1,SEARCH("TTL",$K14)-2),$BO:$BO),$AF14) -> 400 | CL14: =$AV14 -> 0 | CM14: =$AM14 -> 45000 | CN14: =$AP14-$AU14 -> 11700 | CO14: =$AU14 -> 0 | CP14: =$AL14 -> 2 | CQ14: 514530 | CT14: =IF($I14="TTL",$K14,$Z14&$AE14) -> DPSSNF3501PKOML | CU14: =$M14 -> DISNEY PRINCESS | CV14: =IF($I14="TTL","",IF($CT14="","",$Q14&"_"&$T14&IF(R14="K","_KIDS",""))) -> SNAPBACK_501_KIDS | CW14: =IF($I14="TTL","",IF($CT14="","",$Y14&"_"&$AE14)) -> PINK_OML | CX14: =$L14 -> DPS | CY14: =$T14 -> 501 | CZ14: =IF($I14="TTL",SUMIF($C:$C,MID($K14,1,SEARCH("TTL",$K14)-2),$CZ:$CZ),$AF14) -> 400 | DA14: =$AM14 -> 45000 | DB14: =$Y14 -> PINK | DC14: =$AE14 -> OML | DG14: 41736 | DH14: =IF(OR($I14="TTL",$I14=""),"",AZ14-$DH$11) -> 41684 | DI14: 41736 | DJ14: 41736 | DK14: 없음 | DL14: 3 | DM14: 0 | DN14: 없음 | DO14: 없음 | DP14: =IF(OR($DN14="없음",$I14="TTL",$I14=""),"",AZ14-$DP$11) | DQ14: 없음 | DR14: 없음 | DS14: 없음 | DT14: 없음 | DU14: 없음 | DV14: 41759 | DW14: 없음 | DX14: 없음 | DY14: 완료 | EC14: =IF(OR($Z13&$AX13=$Z14&$AX13,$Z14&$AX14=""),"",$Z14&$AX14) | ED14: =IF(OR(Z13&AE13=Z14&AE14,Z14=""),"",Z14&AE14) -> DPSSNF3501PKOML | EE14: =IF($ED14="",0,IF(COUNTIF(ED$12:ED13,ED14)=0,0,COUNTIF(ED$12:ED13,ED14))) -> 0 | EF14: =IF(OR($AJ14="B",$ED14="",MID($U14,8,1)=$EF$9,MID($U14,8,1)=$EF$10),0,1) -> 0 | EG14: =IF(EE14+EF14=0,"","R"&(EE14+EF14)) | EI14: =IF($ED14="","",IF($EE14=0,U14,"")) -> DPSSNF3501 | EJ14: =IF($ED14="","",IF($EE14=0,Z14,"")) -> DPSSNF3501PK | EL14: 없음
A15: =IF(OR($I15="TTL",$I15=""),"",IF(ISERROR(VLOOKUP($B15,CODE!$D:$G,CODE!$F$1-2,FALSE))=TRUE,"전략",VLOOKUP($B15,CODE!$D:$G,CODE!$F$1-2,FALSE))) -> F-CAP | B15: =IF(OR($I15="TTL",$I15=""),"",IF(VLOOKUP($P15,CODE!$K:$O,CODE!$O$1,FALSE)="",$I15,$I15&"-"&VLOOKUP($P15,CODE!$K:$O,CODE!$O$1,FALSE))) -> DPS | C15: =IF($I15="TTL","",I15&"-"&$AG15&"-"&$AI15) -> DPS-캡보이-02 | D15: =$C15&$Z15 -> DPS-캡보이-02DPSSNF3502BL | E15: =IF($I15="TTL",0,IF(ISERROR(IF($Z14=$Z15,$E14,$E14+1))=TRUE,1,IF($Z14=$Z15,$E14,$E14+1))) -> 2 | F15: =$C15&$E15 -> DPS-캡보이-022 | G15: =$F15&"-"&$U15&$Y15&$AE15 -> DPS-캡보이-022-DPSSNF3502BLUEOSM | H15: =IF(ISERROR(I15&VLOOKUP(P15,CODE!$K:$N,CODE!$N$1,FALSE)&S15)=TRUE,0,I15&VLOOKUP(P15,CODE!$K:$N,CODE!$N$1,FALSE)&S15) -> DPS의류외502 | I15: =IF(ISERROR(SEARCH("TTL",$K15))=TRUE,IF($L15="","",VLOOKUP($L15,CODE!$B:$G,CODE!$D$1,FALSE)),"TTL") -> DPS | J15: =MID(W15,1,6) -> 14SS F | L15: DPS | M15: =IF(OR($I15="TTL",$L15=""),"",VLOOKUP($L15,CODE!$B:$D,CODE!$C$1,FALSE)) -> DISNEY PRINCESS | N15: =IF(OR($I15="TTL",$L15=""),"",VLOOKUP($K$2,CODE!$S:$T,CODE!$T$1-1,FALSE)) -> F | O15: =IF(OR($I15="TTL",$L15=""),"",VLOOKUP($L$2,CODE!$X:$Y,CODE!$Y$1-1,FALSE)) -> 3 | P15: SN | Q15: =IF(OR($I15="TTL",$P15=""),"",VLOOKUP($P15,CODE!$K:$M,CODE!$L$1,FALSE)) -> SNAPBACK | R15: K | S15: 502 | T15: =IF(OR($I15="TTL",$S15=""),"",IF($S15<10,"00"&$S15,IF($S15<100,"0"&$S15,$S15))) -> 502 | U15: =IF($I15="TTL","",$L15&$P15&$N15&$O15&$T15) -> DPSSNF3502 | V15: =IF($I15="TTL",SUMIF($C:$C,MID($K15,1,SEARCH("TTL",$K15)-2),$V:$V),IF($EI15="",0,1/COUNTIF($EI:$EI,$EI15))) -> 0.5 | W15: 14SS FROZEN SNAP_02_BL_KIDS | X15: =IF($Y15="","",VLOOKUP($Y15,CODE!$AE:$AF,CODE!$AF$1-1,FALSE)) -> BL | Y15: BLUE | Z15: =$U15&$X15 -> DPSSNF3502BL | AA15: =VLOOKUP($Z15&$AX15,$EC:$EG,5,FALSE) | AB15: =IF($I15="TTL",SUMIF($C:$C,MID($K15,1,SEARCH("TTL",$K15)-2),$AB:$AB),IF($EJ15="",0,1/COUNTIF($EJ:$EJ,$EJ15))) -> 0.5 | AC15: 0 | AD15: 1 | AE15: OSM | AF15: 600 | AG15: 캡보이 | AH15: 2 | AI15: =IF($AH15=0,"",IF($AH15<10,"0"&$AH15,$AH15)) -> 02 | AJ15: M | AK15: KR | AL15: =IF($AK15=0,"",IF($AK15="KR",2,1)) -> 2 | AM15: =IF(ISERROR(VLOOKUP($F15,[1]기획현황취합!$A$1:$E$65485,[1]기획현황취합!$B$1,FALSE))=TRUE,0,VLOOKUP($F15,[1]기획현황취합!$A$1:$E$65485,[1]기획현황취합!$B$1,FALSE)) -> 45000 | AN15: =IF(ISERROR(VLOOKUP($F15,[1]기획현황취합!$A$1:$E$65485,[1]기획현황취합!$C$1,FALSE))=TRUE,0,VLOOKUP($F15,[1]기획현황취합!$A$1:$E$65485,[1]기획현황취합!$C$1,FALSE)) -> 41752 | AO15: =IF(ISERROR(($AM15/1.1)/VLOOKUP($AG15,'TARGET MU'!$A:$D,'TARGET MU'!$D$1,FALSE))=TRUE,0,($AM15/1.1)/VLOOKUP($AG15,'TARGET MU'!$A:$D,'TARGET MU'!$D$1,FALSE)) -> 10227.273 | AP15: =IF(OR(AF15=0,AND(AV15=0,AW15=0)),0,IF(AG15="캡보이2",AV15*$AQ$5+AU15,IF(OR(AK15="IN",AK15="BG",AK15="VT",AK15="CB"),$AU15+(($AV15*(1+$AW$4))*(HLOOKUP(VLOOKUP(AG15,'TARGET MU'!$A:$P,'TARGET MU'!$J$1,FALSE),$AO$4:$AR$5,2,FALSE)))+$AW15,$AU15+((($AV15*(1+$AW$4))*(1+HLOOKUP(VLOOKUP($P15,CODE!$K:$P,CODE!$P$1,FALSE),$AS$4:$AV$5,2,FALSE)))*(HLOOKUP(VLOOKUP(AG15,'TARGET MU'!$A:$P,'TARGET MU'!$J$1,FALSE),$AO$4:$AR$5,2,FALSE)))+$AW15))) -> 12500 | AQ15: =AP15-AO15 -> 2272.7273 | AR15: 0 | AS15: 0 | AU15: =SUM(AR15:AT15) -> 0 | AV15: 0 | AW15: 12500 | AX15: =IF(ISERROR(VLOOKUP($F15,[1]기획현황취합!$A$1:$E$65485,[1]기획현황취합!$D$1,FALSE))=TRUE,0,VLOOKUP($F15,[1]기획현황취합!$A$1:$E$65485,[1]기획현황취합!$D$1,FALSE)) -> 41736 | AY15: 0 | AZ15: =IF(ISERROR(VLOOKUP($F15,[1]기획현황취합!$A$1:$E$65485,[1]기획현황취합!$E$1,FALSE))=TRUE,0,VLOOKUP($F15,[1]기획현황취합!$A$1:$E$65485,[1]기획현황취합!$E$1,FALSE)) -> 41774 | BA15: 0 | BB15: 41761 | BC15: 41768 | BD15: 41775 | BF15: 0 | BG15: 확정 | BH15: 확정 | BI15: =IF($I15="TTL",SUMIF($C:$C,MID($K15,1,SEARCH("TTL",$K15)-2),$BI:$BI),SUMIF(실입고현황!$A:$A,BB15&VLOOKUP($AG15,'TARGET MU'!$A:$D,'TARGET MU'!$B$1,FALSE)&$Z15&" "&$AE15,실입고현황!$C:$C)) -> 150 | BJ15: =IF($I15="TTL",SUMIF($C:$C,MID($K15,1,SEARCH("TTL",$K15)-2),$BJ:$BJ),SUMIF(실입고현황!$A:$A,BC15&VLOOKUP($AG15,'TARGET MU'!$A:$D,'TARGET MU'!$B$1,FALSE)&$Z15&" "&$AE15,실입고현황!$C:$C)) -> 0 | BK15: =IF($I15="TTL",SUMIF($C:$C,MID($K15,1,SEARCH("TTL",$K15)-2),$BK:$BK),SUMIF(실입고현황!$A:$A,BD15&VLOOKUP($AG15,'TARGET MU'!$A:$D,'TARGET MU'!$B$1,FALSE)&$Z15&" "&$AE15,실입고현황!$C:$C)) -> 450 | BL15: =IF($I15="TTL",SUMIF($C:$C,MID($K15,1,SEARCH("TTL",$K15)-2),$BL:$BL),SUMIF(실입고현황!$A:$A,BE15&VLOOKUP($AG15,'TARGET MU'!$A:$D,'TARGET MU'!$B$1,FALSE)&$Z15&" "&$AE15,실입고현황!$C:$C)) -> 0 | BM15: =IF($I15="TTL",SUMIF($C:$C,MID($K15,1,SEARCH("TTL",$K15)-2),$BM:$BM),SUMIF(실입고현황!$A:$A,BF15&VLOOKUP($AG15,'TARGET MU'!$A:$D,'TARGET MU'!$B$1,FALSE)&$Z15&" "&$AE15,실입고현황!$C:$C)) -> 0 | BN15: =IF($I15="TTL",SUMIF($C:$C,MID($K15,1,SEARCH("TTL",$K15)-2),$BN:$BN),IF(($BO15-SUM($BI15,$BJ15,$BK15,BL15,BM15))<$BO15*$BN$6,0,$BO15-SUM($BI15,$BJ15,$BK15,BL15,BM15))) -> 0 | BO15: =IF($I15="TTL",SUMIF($C:$C,MID($K15,1,SEARCH("TTL",$K15)-2),$BO:$BO),$AF15) -> 600 | BP15: =IF($I15="TTL",SUMIF($C:$C,MID($K15,1,SEARCH("TTL",$K15)-2),$BP:$BP),IF(AO15=0,0,IF($AP15=0,$AO15*$AF15,$AP15*$AF15))) -> 7500000 | BQ15: =IF($I15="TTL",SUMIF($C:$C,MID($K15,1,SEARCH("TTL",$K15)-2),$BQ:$BQ),$AM15*$AF15) -> 27000000 | BR15: =IF(ISERROR($BQ15/($BP15*1.1))=TRUE,0,$BQ15/($BP15*1.1)) -> 3.2727273 | BT15: =IF(ISERROR(Z15&VLOOKUP($AG15,'TARGET MU'!$A:$D,'TARGET MU'!$B$1,FALSE))=TRUE,"",Z15&VLOOKUP($AG15,'TARGET MU'!$A:$D,'TARGET MU'!$B$1,FALSE)) -> DPSSNF3502BL캡보이 | BU15: =AP15 -> 12500 | BV15: =Z15&AE15&AF15&AM15&AG15&AI15&AK15 -> DPSSNF3502BLOSM60045000캡보이02KR | BX15: =IF($I15="TTL","",$L15) -> DPS | BY15: =$O15 -> 3 | BZ15: =$AJ15 -> M | CA15: =$P15 -> SN | CB15: =$R15 -> K | CC15: =$AK15 -> KR | CD15: =$W15 -> 14SS FROZEN SNAP_02_BL_KIDS | CE15: =$U15 -> DPSSNF3502 | CF15: =$T15 -> 502 | CG15: =$W15 -> 14SS FROZEN SNAP_02_BL_KIDS | CH15: =$X15 -> BL | CI15: =$AD15 -> 1 | CJ15: =$AE15 -> OSM | CK15: =IF($I15="TTL",SUMIF($C:$C,MID($K15,1,SEARCH("TTL",$K15)-2),$BO:$BO),$AF15) -> 600 | CL15: =$AV15 -> 0 | CM15: =$AM15 -> 45000 | CN15: =$AP15-$AU15 -> 12500 | CO15: =$AU15 -> 0 | CP15: =$AL15 -> 2 | CQ15: 514 | CT15: =IF($I15="TTL",$K15,$Z15&$AE15) -> DPSSNF3502BLOSM | CU15: =$M15 -> DISNEY PRINCESS | CV15: =IF($I15="TTL","",IF($CT15="","",$Q15&"_"&$T15&IF(R15="K","_KIDS",""))) -> SNAPBACK_502_KIDS | CW15: =IF($I15="TTL","",IF($CT15="","",$Y15&"_"&$AE15)) -> BLUE_OSM | CX15: =$L15 -> DPS | CY15: =$T15 -> 502 | CZ15: =IF($I15="TTL",SUMIF($C:$C,MID($K15,1,SEARCH("TTL",$K15)-2),$CZ:$CZ),$AF15) -> 600 | DA15: =$AM15 -> 45000 | DB15: =$Y15 -> BLUE | DC15: =$AE15 -> OSM | DG15: 41736 | DH15: =IF(OR($I15="TTL",$I15=""),"",AZ15-$DH$11) -> 41684 | DI15: 41736 | DJ15: 41736 | DK15: 없음 | DL15: 3 | DM15: 0 | DN15: 없음 | DO15: 없음 | DP15: =IF(OR($DN15="없음",$I15="TTL",$I15=""),"",AZ15-$DP$11) | DQ15: 없음 | DR15: 없음 | DS15: 없음 | DT15: 없음 | DU15: 없음 | DV15: 41759 | DW15: 없음 | DX15: 없음 | DY15: 완료 | EC15: =IF(OR($Z14&$AX14=$Z15&$AX14,$Z15&$AX15=""),"",$Z15&$AX15) -> DPSSNF3502BL41736 | ED15: =IF(OR(Z14&AE14=Z15&AE15,Z15=""),"",Z15&AE15) -> DPSSNF3502BLOSM | EE15: =IF($ED15="",0,IF(COUNTIF(ED$12:ED14,ED15)=0,0,COUNTIF(ED$12:ED14,ED15))) -> 0 | EF15: =IF(OR($AJ15="B",$ED15="",MID($U15,8,1)=$EF$9,MID($U15,8,1)=$EF$10),0,1) -> 0 | EG15: =IF(EE15+EF15=0,"","R"&(EE15+EF15)) | EI15: =IF($ED15="","",IF($EE15=0,U15,"")) -> DPSSNF3502 | EJ15: =IF($ED15="","",IF($EE15=0,Z15,"")) -> DPSSNF3502BL | EL15: 없음
A16: =IF(OR($I16="TTL",$I16=""),"",IF(ISERROR(VLOOKUP($B16,CODE!$D:$G,CODE!$F$1-2,FALSE))=TRUE,"전략",VLOOKUP($B16,CODE!$D:$G,CODE!$F$1-2,FALSE))) -> F-CAP | B16: =IF(OR($I16="TTL",$I16=""),"",IF(VLOOKUP($P16,CODE!$K:$O,CODE!$O$1,FALSE)="",$I16,$I16&"-"&VLOOKUP($P16,CODE!$K:$O,CODE!$O$1,FALSE))) -> DPS | C16: =IF($I16="TTL","",I16&"-"&$AG16&"-"&$AI16) -> DPS-캡보이-02 | D16: =$C16&$Z16 -> DPS-캡보이-02DPSSNF3502BL | E16: =IF($I16="TTL",0,IF(ISERROR(IF($Z15=$Z16,$E15,$E15+1))=TRUE,1,IF($Z15=$Z16,$E15,$E15+1))) -> 2 | F16: =$C16&$E16 -> DPS-캡보이-022 | G16: =$F16&"-"&$U16&$Y16&$AE16 -> DPS-캡보이-022-DPSSNF3502BLUEOML | H16: =IF(ISERROR(I16&VLOOKUP(P16,CODE!$K:$N,CODE!$N$1,FALSE)&S16)=TRUE,0,I16&VLOOKUP(P16,CODE!$K:$N,CODE!$N$1,FALSE)&S16) -> DPS의류외502 | I16: =IF(ISERROR(SEARCH("TTL",$K16))=TRUE,IF($L16="","",VLOOKUP($L16,CODE!$B:$G,CODE!$D$1,FALSE)),"TTL") -> DPS | J16: =MID(W16,1,6) -> 14SS F | L16: DPS | M16: =IF(OR($I16="TTL",$L16=""),"",VLOOKUP($L16,CODE!$B:$D,CODE!$C$1,FALSE)) -> DISNEY PRINCESS | N16: =IF(OR($I16="TTL",$L16=""),"",VLOOKUP($K$2,CODE!$S:$T,CODE!$T$1-1,FALSE)) -> F | O16: =IF(OR($I16="TTL",$L16=""),"",VLOOKUP($L$2,CODE!$X:$Y,CODE!$Y$1-1,FALSE)) -> 3 | P16: SN | Q16: =IF(OR($I16="TTL",$P16=""),"",VLOOKUP($P16,CODE!$K:$M,CODE!$L$1,FALSE)) -> SNAPBACK | R16: K | S16: 502 | T16: =IF(OR($I16="TTL",$S16=""),"",IF($S16<10,"00"&$S16,IF($S16<100,"0"&$S16,$S16))) -> 502 | U16: =IF($I16="TTL","",$L16&$P16&$N16&$O16&$T16) -> DPSSNF3502 | V16: =IF($I16="TTL",SUMIF($C:$C,MID($K16,1,SEARCH("TTL",$K16)-2),$V:$V),IF($EI16="",0,1/COUNTIF($EI:$EI,$EI16))) -> 0.5 | W16: 14SS FROZEN SNAP_02_BL_KIDS | X16: =IF($Y16="","",VLOOKUP($Y16,CODE!$AE:$AF,CODE!$AF$1-1,FALSE)) -> BL | Y16: BLUE | Z16: =$U16&$X16 -> DPSSNF3502BL | AA16: =VLOOKUP($Z16&$AX16,$EC:$EG,5,FALSE) | AB16: =IF($I16="TTL",SUMIF($C:$C,MID($K16,1,SEARCH("TTL",$K16)-2),$AB:$AB),IF($EJ16="",0,1/COUNTIF($EJ:$EJ,$EJ16))) -> 0.5 | AC16: 0 | AD16: 1 | AE16: OML | AF16: 400 | AG16: 캡보이 | AH16: 2 | AI16: =IF($AH16=0,"",IF($AH16<10,"0"&$AH16,$AH16)) -> 02 | AJ16: M | AK16: KR | AL16: =IF($AK16=0,"",IF($AK16="KR",2,1)) -> 2 | AM16: =IF(ISERROR(VLOOKUP($F16,[1]기획현황취합!$A$1:$E$65485,[1]기획현황취합!$B$1,FALSE))=TRUE,0,VLOOKUP($F16,[1]기획현황취합!$A$1:$E$65485,[1]기획현황취합!$B$1,FALSE)) -> 45000 | AN16: =IF(ISERROR(VLOOKUP($F16,[1]기획현황취합!$A$1:$E$65485,[1]기획현황취합!$C$1,FALSE))=TRUE,0,VLOOKUP($F16,[1]기획현황취합!$A$1:$E$65485,[1]기획현황취합!$C$1,FALSE)) -> 41752 | AO16: =IF(ISERROR(($AM16/1.1)/VLOOKUP($AG16,'TARGET MU'!$A:$D,'TARGET MU'!$D$1,FALSE))=TRUE,0,($AM16/1.1)/VLOOKUP($AG16,'TARGET MU'!$A:$D,'TARGET MU'!$D$1,FALSE)) -> 10227.273 | AP16: =IF(OR(AF16=0,AND(AV16=0,AW16=0)),0,IF(AG16="캡보이2",AV16*$AQ$5+AU16,IF(OR(AK16="IN",AK16="BG",AK16="VT",AK16="CB"),$AU16+(($AV16*(1+$AW$4))*(HLOOKUP(VLOOKUP(AG16,'TARGET MU'!$A:$P,'TARGET MU'!$J$1,FALSE),$AO$4:$AR$5,2,FALSE)))+$AW16,$AU16+((($AV16*(1+$AW$4))*(1+HLOOKUP(VLOOKUP($P16,CODE!$K:$P,CODE!$P$1,FALSE),$AS$4:$AV$5,2,FALSE)))*(HLOOKUP(VLOOKUP(AG16,'TARGET MU'!$A:$P,'TARGET MU'!$J$1,FALSE),$AO$4:$AR$5,2,FALSE)))+$AW16))) -> 12500 | AQ16: =AP16-AO16 -> 2272.7273 | AR16: 0 | AS16: 0 | AU16: =SUM(AR16:AT16) -> 0 | AV16: 0 | AW16: 12500 | AX16: =IF(ISERROR(VLOOKUP($F16,[1]기획현황취합!$A$1:$E$65485,[1]기획현황취합!$D$1,FALSE))=TRUE,0,VLOOKUP($F16,[1]기획현황취합!$A$1:$E$65485,[1]기획현황취합!$D$1,FALSE)) -> 41736 | AY16: 0 | AZ16: =IF(ISERROR(VLOOKUP($F16,[1]기획현황취합!$A$1:$E$65485,[1]기획현황취합!$E$1,FALSE))=TRUE,0,VLOOKUP($F16,[1]기획현황취합!$A$1:$E$65485,[1]기획현황취합!$E$1,FALSE)) -> 41774 | BA16: 0 | BB16: 41761 | BC16: 41768 | BD16: 41775 | BF16: 0 | BG16: 확정 | BH16: 확정 | BI16: =IF($I16="TTL",SUMIF($C:$C,MID($K16,1,SEARCH("TTL",$K16)-2),$BI:$BI),SUMIF(실입고현황!$A:$A,BB16&VLOOKUP($AG16,'TARGET MU'!$A:$D,'TARGET MU'!$B$1,FALSE)&$Z16&" "&$AE16,실입고현황!$C:$C)) -> 150 | BJ16: =IF($I16="TTL",SUMIF($C:$C,MID($K16,1,SEARCH("TTL",$K16)-2),$BJ:$BJ),SUMIF(실입고현황!$A:$A,BC16&VLOOKUP($AG16,'TARGET MU'!$A:$D,'TARGET MU'!$B$1,FALSE)&$Z16&" "&$AE16,실입고현황!$C:$C)) -> 258 | BK16: =IF($I16="TTL",SUMIF($C:$C,MID($K16,1,SEARCH("TTL",$K16)-2),$BK:$BK),SUMIF(실입고현황!$A:$A,BD16&VLOOKUP($AG16,'TARGET MU'!$A:$D,'TARGET MU'!$B$1,FALSE)&$Z16&" "&$AE16,실입고현황!$C:$C)) -> 0 | BL16: =IF($I16="TTL",SUMIF($C:$C,MID($K16,1,SEARCH("TTL",$K16)-2),$BL:$BL),SUMIF(실입고현황!$A:$A,BE16&VLOOKUP($AG16,'TARGET MU'!$A:$D,'TARGET MU'!$B$1,FALSE)&$Z16&" "&$AE16,실입고현황!$C:$C)) -> 0 | BM16: =IF($I16="TTL",SUMIF($C:$C,MID($K16,1,SEARCH("TTL",$K16)-2),$BM:$BM),SUMIF(실입고현황!$A:$A,BF16&VLOOKUP($AG16,'TARGET MU'!$A:$D,'TARGET MU'!$B$1,FALSE)&$Z16&" "&$AE16,실입고현황!$C:$C)) -> 0 | BN16: =IF($I16="TTL",SUMIF($C:$C,MID($K16,1,SEARCH("TTL",$K16)-2),$BN:$BN),IF(($BO16-SUM($BI16,$BJ16,$BK16,BL16,BM16))<$BO16*$BN$6,0,$BO16-SUM($BI16,$BJ16,$BK16,BL16,BM16))) -> 0 | BO16: =IF($I16="TTL",SUMIF($C:$C,MID($K16,1,SEARCH("TTL",$K16)-2),$BO:$BO),$AF16) -> 400 | BP16: =IF($I16="TTL",SUMIF($C:$C,MID($K16,1,SEARCH("TTL",$K16)-2),$BP:$BP),IF(AO16=0,0,IF($AP16=0,$AO16*$AF16,$AP16*$AF16))) -> 5000000 | BQ16: =IF($I16="TTL",SUMIF($C:$C,MID($K16,1,SEARCH("TTL",$K16)-2),$BQ:$BQ),$AM16*$AF16) -> 18000000 | BR16: =IF(ISERROR($BQ16/($BP16*1.1))=TRUE,0,$BQ16/($BP16*1.1)) -> 3.2727273 | BT16: =IF(ISERROR(Z16&VLOOKUP($AG16,'TARGET MU'!$A:$D,'TARGET MU'!$B$1,FALSE))=TRUE,"",Z16&VLOOKUP($AG16,'TARGET MU'!$A:$D,'TARGET MU'!$B$1,FALSE)) -> DPSSNF3502BL캡보이 | BU16: =AP16 -> 12500 | BV16: =Z16&AE16&AF16&AM16&AG16&AI16&AK16 -> DPSSNF3502BLOML40045000캡보이02KR | BX16: =IF($I16="TTL","",$L16) -> DPS | BY16: =$O16 -> 3 | BZ16: =$AJ16 -> M | CA16: =$P16 -> SN | CB16: =$R16 -> K | CC16: =$AK16 -> KR | CD16: =$W16 -> 14SS FROZEN SNAP_02_BL_KIDS | CE16: =$U16 -> DPSSNF3502 | CF16: =$T16 -> 502 | CG16: =$W16 -> 14SS FROZEN SNAP_02_BL_KIDS | CH16: =$X16 -> BL | CI16: =$AD16 -> 1 | CJ16: =$AE16 -> OML | CK16: =IF($I16="TTL",SUMIF($C:$C,MID($K16,1,SEARCH("TTL",$K16)-2),$BO:$BO),$AF16) -> 400 | CL16: =$AV16 -> 0 | CM16: =$AM16 -> 45000 | CN16: =$AP16-$AU16 -> 12500 | CO16: =$AU16 -> 0 | CP16: =$AL16 -> 2 | CQ16: 514530 | CT16: =IF($I16="TTL",$K16,$Z16&$AE16) -> DPSSNF3502BLOML | CU16: =$M16 -> DISNEY PRINCESS | CV16: =IF($I16="TTL","",IF($CT16="","",$Q16&"_"&$T16&IF(R16="K","_KIDS",""))) -> SNAPBACK_502_KIDS | CW16: =IF($I16="TTL","",IF($CT16="","",$Y16&"_"&$AE16)) -> BLUE_OML | CX16: =$L16 -> DPS | CY16: =$T16 -> 502 | CZ16: =IF($I16="TTL",SUMIF($C:$C,MID($K16,1,SEARCH("TTL",$K16)-2),$CZ:$CZ),$AF16) -> 400 | DA16: =$AM16 -> 45000 | DB16: =$Y16 -> BLUE | DC16: =$AE16 -> OML | DG16: 41736 | DH16: =IF(OR($I16="TTL",$I16=""),"",AZ16-$DH$11) -> 41684 | DI16: 41736 | DJ16: 41736 | DK16: 없음 | DL16: 3 | DM16: 0 | DN16: 없음 | DO16: 없음 | DP16: =IF(OR($DN16="없음",$I16="TTL",$I16=""),"",AZ16-$DP$11) | DQ16: 없음 | DR16: 없음 | DS16: 없음 | DT16: 없음 | DU16: 없음 | DV16: 41759 | DW16: 없음 | DX16: 없음 | DY16: 완료 | EC16: =IF(OR($Z15&$AX15=$Z16&$AX15,$Z16&$AX16=""),"",$Z16&$AX16) | ED16: =IF(OR(Z15&AE15=Z16&AE16,Z16=""),"",Z16&AE16) -> DPSSNF3502BLOML | EE16: =IF($ED16="",0,IF(COUNTIF(ED$12:ED15,ED16)=0,0,COUNTIF(ED$12:ED15,ED16))) -> 0 | EF16: =IF(OR($AJ16="B",$ED16="",MID($U16,8,1)=$EF$9,MID($U16,8,1)=$EF$10),0,1) -> 0 | EG16: =IF(EE16+EF16=0,"","R"&(EE16+EF16)) | EI16: =IF($ED16="","",IF($EE16=0,U16,"")) -> DPSSNF3502 | EJ16: =IF($ED16="","",IF($EE16=0,Z16,"")) -> DPSSNF3502BL | EL16: 없음
A17: =IF(OR($I17="TTL",$I17=""),"",IF(ISERROR(VLOOKUP($B17,CODE!$D:$G,CODE!$F$1-2,FALSE))=TRUE,"전략",VLOOKUP($B17,CODE!$D:$G,CODE!$F$1-2,FALSE))) -> F-CAP | B17: =IF(OR($I17="TTL",$I17=""),"",IF(VLOOKUP($P17,CODE!$K:$O,CODE!$O$1,FALSE)="",$I17,$I17&"-"&VLOOKUP($P17,CODE!$K:$O,CODE!$O$1,FALSE))) -> DPS | C17: =IF($I17="TTL","",I17&"-"&$AG17&"-"&$AI17) -> DPS-캡보이-02 | D17: =$C17&$Z17 -> DPS-캡보이-02DPSSNF3003PP | E17: =IF($I17="TTL",0,IF(ISERROR(IF($Z16=$Z17,$E16,$E16+1))=TRUE,1,IF($Z16=$Z17,$E16,$E16+1))) -> 3 | F17: =$C17&$E17 -> DPS-캡보이-023 | G17: =$F17&"-"&$U17&$Y17&$AE17 -> DPS-캡보이-023-DPSSNF3003PURPLEFRE | H17: =IF(ISERROR(I17&VLOOKUP(P17,CODE!$K:$N,CODE!$N$1,FALSE)&S17)=TRUE,0,I17&VLOOKUP(P17,CODE!$K:$N,CODE!$N$1,FALSE)&S17) -> DPS의류외3 | I17: =IF(ISERROR(SEARCH("TTL",$K17))=TRUE,IF($L17="","",VLOOKUP($L17,CODE!$B:$G,CODE!$D$1,FALSE)),"TTL") -> DPS | J17: =MID(W17,1,6) -> 14SS F | L17: DPS | M17: =IF(OR($I17="TTL",$L17=""),"",VLOOKUP($L17,CODE!$B:$D,CODE!$C$1,FALSE)) -> DISNEY PRINCESS | N17: =IF(OR($I17="TTL",$L17=""),"",VLOOKUP($K$2,CODE!$S:$T,CODE!$T$1-1,FALSE)) -> F | O17: =IF(OR($I17="TTL",$L17=""),"",VLOOKUP($L$2,CODE!$X:$Y,CODE!$Y$1-1,FALSE)) -> 3 | P17: SN | Q17: =IF(OR($I17="TTL",$P17=""),"",VLOOKUP($P17,CODE!$K:$M,CODE!$L$1,FALSE)) -> SNAPBACK | R17: U | S17: 3 | T17: =IF(OR($I17="TTL",$S17=""),"",IF($S17<10,"00"&$S17,IF($S17<100,"0"&$S17,$S17))) -> 003 | U17: =IF($I17="TTL","",$L17&$P17&$N17&$O17&$T17) -> DPSSNF3003 | V17: =IF($I17="TTL",SUMIF($C:$C,MID($K17,1,SEARCH("TTL",$K17)-2),$V:$V),IF($EI17="",0,1/COUNTIF($EI:$EI,$EI17))) -> 1 | W17: 14SS FROZEN SNAP_04_PP | X17: =IF($Y17="","",VLOOKUP($Y17,CODE!$AE:$AF,CODE!$AF$1-1,FALSE)) -> PP | Y17: PURPLE | Z17: =$U17&$X17 -> DPSSNF3003PP | AA17: =VLOOKUP($Z17&$AX17,$EC:$EG,5,FALSE) | AB17: =IF($I17="TTL",SUMIF($C:$C,MID($K17,1,SEARCH("TTL",$K17)-2),$AB:$AB),IF($EJ17="",0,1/COUNTIF($EJ:$EJ,$EJ17))) -> 1 | AC17: 0 | AD17: 1 | AE17: FRE | AF17: 1000 | AG17: 캡보이 | AH17: 2 | AI17: =IF($AH17=0,"",IF($AH17<10,"0"&$AH17,$AH17)) -> 02 | AJ17: M | AK17: KR | AL17: =IF($AK17=0,"",IF($AK17="KR",2,1)) -> 2 | AM17: =IF(ISERROR(VLOOKUP($F17,[1]기획현황취합!$A$1:$E$65485,[1]기획현황취합!$B$1,FALSE))=TRUE,0,VLOOKUP($F17,[1]기획현황취합!$A$1:$E$65485,[1]기획현황취합!$B$1,FALSE)) -> 47000 | AN17: =IF(ISERROR(VLOOKUP($F17,[1]기획현황취합!$A$1:$E$65485,[1]기획현황취합!$C$1,FALSE))=TRUE,0,VLOOKUP($F17,[1]기획현황취합!$A$1:$E$65485,[1]기획현황취합!$C$1,FALSE)) -> 41752 | AO17: =IF(ISERROR(($AM17/1.1)/VLOOKUP($AG17,'TARGET MU'!$A:$D,'TARGET MU'!$D$1,FALSE))=TRUE,0,($AM17/1.1)/VLOOKUP($AG17,'TARGET MU'!$A:$D,'TARGET MU'!$D$1,FALSE)) -> 10681.818 | AP17: =IF(OR(AF17=0,AND(AV17=0,AW17=0)),0,IF(AG17="캡보이2",AV17*$AQ$5+AU17,IF(OR(AK17="IN",AK17="BG",AK17="VT",AK17="CB"),$AU17+(($AV17*(1+$AW$4))*(HLOOKUP(VLOOKUP(AG17,'TARGET MU'!$A:$P,'TARGET MU'!$J$1,FALSE),$AO$4:$AR$5,2,FALSE)))+$AW17,$AU17+((($AV17*(1+$AW$4))*(1+HLOOKUP(VLOOKUP($P17,CODE!$K:$P,CODE!$P$1,FALSE),$AS$4:$AV$5,2,FALSE)))*(HLOOKUP(VLOOKUP(AG17,'TARGET MU'!$A:$P,'TARGET MU'!$J$1,FALSE),$AO$4:$AR$5,2,FALSE)))+$AW17))) -> 11300 | AQ17: =AP17-AO17 -> 618.18182 | AR17: 0 | AS17: 700 | AU17: =SUM(AR17:AT17) -> 700 | AV17: 0 | AW17: 10600 | AX17: =IF(ISERROR(VLOOKUP($F17,[1]기획현황취합!$A$1:$E$65485,[1]기획현황취합!$D$1,FALSE))=TRUE,0,VLOOKUP($F17,[1]기획현황취합!$A$1:$E$65485,[1]기획현황취합!$D$1,FALSE)) -> 41736 | AY17: 0 | AZ17: =IF(ISERROR(VLOOKUP($F17,[1]기획현황취합!$A$1:$E$65485,[1]기획현황취합!$E$1,FALSE))=TRUE,0,VLOOKUP($F17,[1]기획현황취합!$A$1:$E$65485,[1]기획현황취합!$E$1,FALSE)) -> 41774 | BA17: 0 | BB17: 41761 | BC17: 41782 | BD17: 41802 | BF17: 0 | BG17: 확정 | BH17: 확정 | BI17: =IF($I17="TTL",SUMIF($C:$C,MID($K17,1,SEARCH("TTL",$K17)-2),$BI:$BI),SUMIF(실입고현황!$A:$A,BB17&VLOOKUP($AG17,'TARGET MU'!$A:$D,'TARGET MU'!$B$1,FALSE)&$Z17&" "&$AE17,실입고현황!$C:$C)) -> 200 | BJ17: =IF($I17="TTL",SUMIF($C:$C,MID($K17,1,SEARCH("TTL",$K17)-2),$BJ:$BJ),SUMIF(실입고현황!$A:$A,BC17&VLOOKUP($AG17,'TARGET MU'!$A:$D,'TARGET MU'!$B$1,FALSE)&$Z17&" "&$AE17,실입고현황!$C:$C)) -> 300 | BK17: =IF($I17="TTL",SUMIF($C:$C,MID($K17,1,SEARCH("TTL",$K17)-2),$BK:$BK),SUMIF(실입고현황!$A:$A,BD17&VLOOKUP($AG17,'TARGET MU'!$A:$D,'TARGET MU'!$B$1,FALSE)&$Z17&" "&$AE17,실입고현황!$C:$C)) -> 514 | BL17: =IF($I17="TTL",SUMIF($C:$C,MID($K17,1,SEARCH("TTL",$K17)-2),$BL:$BL),SUMIF(실입고현황!$A:$A,BE17&VLOOKUP($AG17,'TARGET MU'!$A:$D,'TARGET MU'!$B$1,FALSE)&$Z17&" "&$AE17,실입고현황!$C:$C)) -> 0 | BM17: =IF($I17="TTL",SUMIF($C:$C,MID($K17,1,SEARCH("TTL",$K17)-2),$BM:$BM),SUMIF(실입고현황!$A:$A,BF17&VLOOKUP($AG17,'TARGET MU'!$A:$D,'TARGET MU'!$B$1,FALSE)&$Z17&" "&$AE17,실입고현황!$C:$C)) -> 0 | BN17: =IF($I17="TTL",SUMIF($C:$C,MID($K17,1,SEARCH("TTL",$K17)-2),$BN:$BN),IF(($BO17-SUM($BI17,$BJ17,$BK17,BL17,BM17))<$BO17*$BN$6,0,$BO17-SUM($BI17,$BJ17,$BK17,BL17,BM17))) -> 0 | BO17: =IF($I17="TTL",SUMIF($C:$C,MID($K17,1,SEARCH("TTL",$K17)-2),$BO:$BO),$AF17) -> 1000 | BP17: =IF($I17="TTL",SUMIF($C:$C,MID($K17,1,SEARCH("TTL",$K17)-2),$BP:$BP),IF(AO17=0,0,IF($AP17=0,$AO17*$AF17,$AP17*$AF17))) -> 11300000 | BQ17: =IF($I17="TTL",SUMIF($C:$C,MID($K17,1,SEARCH("TTL",$K17)-2),$BQ:$BQ),$AM17*$AF17) -> 47000000 | BR17: =IF(ISERROR($BQ17/($BP17*1.1))=TRUE,0,$BQ17/($BP17*1.1)) -> 3.7811746 | BT17: =IF(ISERROR(Z17&VLOOKUP($AG17,'TARGET MU'!$A:$D,'TARGET MU'!$B$1,FALSE))=TRUE,"",Z17&VLOOKUP($AG17,'TARGET MU'!$A:$D,'TARGET MU'!$B$1,FALSE)) -> DPSSNF3003PP캡보이 | BU17: =AP17 -> 11300 | BV17: =Z17&AE17&AF17&AM17&AG17&AI17&AK17 -> DPSSNF3003PPFRE100047000캡보이02KR | BX17: =IF($I17="TTL","",$L17) -> DPS | BY17: =$O17 -> 3 | BZ17: =$AJ17 -> M | CA17: =$P17 -> SN | CB17: =$R17 -> U | CC17: =$AK17 -> KR | CD17: =$W17 -> 14SS FROZEN SNAP_04_PP | CE17: =$U17 -> DPSSNF3003 | CF17: =$T17 -> 003 | CG17: =$W17 -> 14SS FROZEN SNAP_04_PP | CH17: =$X17 -> PP | CI17: =$AD17 -> 1 | CJ17: =$AE17 -> FRE | CK17: =IF($I17="TTL",SUMIF($C:$C,MID($K17,1,SEARCH("TTL",$K17)-2),$BO:$BO),$AF17) -> 1000 | CL17: =$AV17 -> 0 | CM17: =$AM17 -> 47000 | CN17: =$AP17-$AU17 -> 10600 | CO17: =$AU17 -> 700 | CP17: =$AL17 -> 2 | CQ17: 514573628 | CT17: =IF($I17="TTL",$K17,$Z17&$AE17) -> DPSSNF3003PPFRE | CU17: =$M17 -> DISNEY PRINCESS | CV17: =IF($I17="TTL","",IF($CT17="","",$Q17&"_"&$T17&IF(R17="K","_KIDS",""))) -> SNAPBACK_003 | CW17: =IF($I17="TTL","",IF($CT17="","",$Y17&"_"&$AE17)) -> PURPLE_FRE | CX17: =$L17 -> DPS | CY17: =$T17 -> 003 | CZ17: =IF($I17="TTL",SUMIF($C:$C,MID($K17,1,SEARCH("TTL",$K17)-2),$CZ:$CZ),$AF17) -> 1000 | DA17: =$AM17 -> 47000 | DB17: =$Y17 -> PURPLE | DC17: =$AE17 -> FRE | DG17: 41736 | DH17: =IF(OR($I17="TTL",$I17=""),"",AZ17-$DH$11) -> 41684 | DI17: 41736 | DJ17: 41736 | DK17: 없음 | DL17: 2 | DM17: 0 | DN17: 없음 | DO17: 없음 | DP17: =IF(OR($DN17="없음",$I17="TTL",$I17=""),"",AZ17-$DP$11) | DQ17: 없음 | DR17: 없음 | DS17: 없음 | DT17: 없음 | DU17: 없음 | DV17: 41759 | DW17: 없음 | DX17: 없음 | DY17: 완료 | EC17: =IF(OR($Z16&$AX16=$Z17&$AX16,$Z17&$AX17=""),"",$Z17&$AX17) -> DPSSNF3003PP41736 | ED17: =IF(OR(Z16&AE16=Z17&AE17,Z17=""),"",Z17&AE17) -> DPSSNF3003PPFRE | EE17: =IF($ED17="",0,IF(COUNTIF(ED$12:ED16,ED17)=0,0,COUNTIF(ED$12:ED16,ED17))) -> 0 | EF17: =IF(OR($AJ17="B",$ED17="",MID($U17,8,1)=$EF$9,MID($U17,8,1)=$EF$10),0,1) -> 0 | EG17: =IF(EE17+EF17=0,"","R"&(EE17+EF17)) | EI17: =IF($ED17="","",IF($EE17=0,U17,"")) -> DPSSNF3003 | EJ17: =IF($ED17="","",IF($EE17=0,Z17,"")) -> DPSSNF3003PP | EL17: 없음
