Workbook

Sheet 순점검
A1: 업체차수점검 | K1: 품번순서
K3: 브랜드 | N3: 사용가
E4: 데이터 | K4: SMB | N4: 사용불가
A5: 업체명 | B5: 차수 | C5: 발주일 | D5: 브랜드 | E5: 품번수 | F5: 색상수 | G5: 수량 | H5: 원가금액 | I5: TAG가금액 | K5: 의류외
A6: 대경 | B6: 1 | C6: 41547 | D6: ELS | E6: 25 | F6: 26 | G6: 26500 | H6: 0 | I6: 0
B7: 2 | C7: 41547 | D7: ELS | E7: 8 | F7: 9 | G7: 10550 | H7: 0 | I7: 0 | K7: REORDER | N7: MAIN (U,M,W) | Q7: MAIN (K)
B8: 3 | C8: 41564 | D8: ELS | E8: 16 | F8: 16 | G8: 20500 | H8: 1.8583636e+08 | I8: 1022100000 | K8: 품번순서 | N8: 품번순서 | Q8: 품번순서
A9: 아트인드림 | B9: 3 | C9: 41547 | D9: ELS | E9: 8 | F9: 8 | G9: 11600 | H9: 101696600 | I9: 0 | K9: 1 | L9: =IF(ISERROR(VLOOKUP($K$4&$K$5&$K9,기획현황!$H:$H,1,FALSE))=TRUE,"",VLOOKUP($K$4&$K$5&$K9,기획현황!$H:$H,1,FALSE)) | N9: 1 | O9: =IF(ISERROR(VLOOKUP($K$4&$K$5&$N9,기획현황!$H:$H,1,FALSE))=TRUE,"",VLOOKUP($K$4&$K$5&$N9,기획현황!$H:$H,1,FALSE)) | Q9: =N9+500 -> 501 | R9: =IF(ISERROR(VLOOKUP($K$4&$K$5&$Q9,기획현황!$H:$H,1,FALSE))=TRUE,"",VLOOKUP($K$4&$K$5&$Q9,기획현황!$H:$H,1,FALSE))
B10: 5 | C10: 41564 | D10: ELS | E10: 4 | F10: 4 | G10: 4800 | H10: 92160000 | I10: 321600000 | K10: =K9+1 -> 2 | L10: =IF(ISERROR(VLOOKUP($K$4&$K$5&$K10,기획현황!$H:$H,1,FALSE))=TRUE,"",VLOOKUP($K$4&$K$5&$K10,기획현황!$H:$H,1,FALSE)) | N10: =N9+1 -> 2 | O10: =IF(ISERROR(VLOOKUP($K$4&$K$5&$N10,기획현황!$H:$H,1,FALSE))=TRUE,"",VLOOKUP($K$4&$K$5&$N10,기획현황!$H:$H,1,FALSE)) | Q10: =Q9+1 -> 502 | R10: =IF(ISERROR(VLOOKUP($K$4&$K$5&$Q10,기획현황!$H:$H,1,FALSE))=TRUE,"",VLOOKUP($K$4&$K$5&$Q10,기획현황!$H:$H,1,FALSE))
B11: 6 | C11: 41564 | D11: ELS | E11: 11 | F11: 17 | G11: 29000 | H11: 349120000 | I11: 1310600000 | K11: =K10+1 -> 3 | L11: =IF(ISERROR(VLOOKUP($K$4&$K$5&$K11,기획현황!$H:$H,1,FALSE))=TRUE,"",VLOOKUP($K$4&$K$5&$K11,기획현황!$H:$H,1,FALSE)) | N11: =N10+1 -> 3 | O11: =IF(ISERROR(VLOOKUP($K$4&$K$5&$N11,기획현황!$H:$H,1,FALSE))=TRUE,"",VLOOKUP($K$4&$K$5&$N11,기획현황!$H:$H,1,FALSE)) | Q11: =Q10+1 -> 503 | R11: =IF(ISERROR(VLOOKUP($K$4&$K$5&$Q11,기획현황!$H:$H,1,FALSE))=TRUE,"",VLOOKUP($K$4&$K$5&$Q11,기획현황!$H:$H,1,FALSE))
B12: 7 | C12: 41564 | D12: ELS | E12: 2 | F12: 2 | G12: 4000 | H12: 46740000 | I12: 176000000 | K12: =K11+1 -> 4 | L12: =IF(ISERROR(VLOOKUP($K$4&$K$5&$K12,기획현황!$H:$H,1,FALSE))=TRUE,"",VLOOKUP($K$4&$K$5&$K12,기획현황!$H:$H,1,FALSE)) | N12: =N11+1 -> 4 | O12: =IF(ISERROR(VLOOKUP($K$4&$K$5&$N12,기획현황!$H:$H,1,FALSE))=TRUE,"",VLOOKUP($K$4&$K$5&$N12,기획현황!$H:$H,1,FALSE)) | Q12: =Q11+1 -> 504 | R12: =IF(ISERROR(VLOOKUP($K$4&$K$5&$Q12,기획현황!$H:$H,1,FALSE))=TRUE,"",VLOOKUP($K$4&$K$5&$Q12,기획현황!$H:$H,1,FALSE))
A13: 한림 | B13: 1 | C13: 41564 | D13: ELS | E13: 6 | F13: 6 | G13: 8700 | H13: 68563636 | I13: 377100000 | K13: =K12+1 -> 5 | L13: =IF(ISERROR(VLOOKUP($K$4&$K$5&$K13,기획현황!$H:$H,1,FALSE))=TRUE,"",VLOOKUP($K$4&$K$5&$K13,기획현황!$H:$H,1,FALSE)) | N13: =N12+1 -> 5 | O13: =IF(ISERROR(VLOOKUP($K$4&$K$5&$N13,기획현황!$H:$H,1,FALSE))=TRUE,"",VLOOKUP($K$4&$K$5&$N13,기획현황!$H:$H,1,FALSE)) | Q13: =Q12+1 -> 505 | R13: =IF(ISERROR(VLOOKUP($K$4&$K$5&$Q13,기획현황!$H:$H,1,FALSE))=TRUE,"",VLOOKUP($K$4&$K$5&$Q13,기획현황!$H:$H,1,FALSE))
A14: EVERGREEN | B14: 1 | C14: 41533 | D14: ELS | E14: 8 | F14: 13 | G14: 15600 | H14: 1.1169697e+08 | I14: 737200000 | K14: =K13+1 -> 6 | L14: =IF(ISERROR(VLOOKUP($K$4&$K$5&$K14,기획현황!$H:$H,1,FALSE))=TRUE,"",VLOOKUP($K$4&$K$5&$K14,기획현황!$H:$H,1,FALSE)) | N14: =N13+1 -> 6 | O14: =IF(ISERROR(VLOOKUP($K$4&$K$5&$N14,기획현황!$H:$H,1,FALSE))=TRUE,"",VLOOKUP($K$4&$K$5&$N14,기획현황!$H:$H,1,FALSE)) | Q14: =Q13+1 -> 506 | R14: =IF(ISERROR(VLOOKUP($K$4&$K$5&$Q14,기획현황!$H:$H,1,FALSE))=TRUE,"",VLOOKUP($K$4&$K$5&$Q14,기획현황!$H:$H,1,FALSE))
B15: 2 | C15: 41547 | D15: ELS | E15: 5 | F15: 6 | G15: 6400 | H15: 0 | I15: 0 | K15: =K14+1 -> 7 | L15: =IF(ISERROR(VLOOKUP($K$4&$K$5&$K15,기획현황!$H:$H,1,FALSE))=TRUE,"",VLOOKUP($K$4&$K$5&$K15,기획현황!$H:$H,1,FALSE)) | N15: =N14+1 -> 7 | O15: =IF(ISERROR(VLOOKUP($K$4&$K$5&$N15,기획현황!$H:$H,1,FALSE))=TRUE,"",VLOOKUP($K$4&$K$5&$N15,기획현황!$H:$H,1,FALSE)) | Q15: =Q14+1 -> 507 | R15: =IF(ISERROR(VLOOKUP($K$4&$K$5&$Q15,기획현황!$H:$H,1,FALSE))=TRUE,"",VLOOKUP($K$4&$K$5&$Q15,기획현황!$H:$H,1,FALSE))
B16: 3 | C16: 41564 | D16: ELS | E16: 5 | F16: 9 | G16: 11400 | H16: 76636364 | I16: 505800000 | K16: =K15+1 -> 8 | L16: =IF(ISERROR(VLOOKUP($K$4&$K$5&$K16,기획현황!$H:$H,1,FALSE))=TRUE,"",VLOOKUP($K$4&$K$5&$K16,기획현황!$H:$H,1,FALSE)) | N16: =N15+1 -> 8 | O16: =IF(ISERROR(VLOOKUP($K$4&$K$5&$N16,기획현황!$H:$H,1,FALSE))=TRUE,"",VLOOKUP($K$4&$K$5&$N16,기획현황!$H:$H,1,FALSE)) | Q16: =Q15+1 -> 508 | R16: =IF(ISERROR(VLOOKUP($K$4&$K$5&$Q16,기획현황!$H:$H,1,FALSE))=TRUE,"",VLOOKUP($K$4&$K$5&$Q16,기획현황!$H:$H,1,FALSE))
A17: PIAFIELD | B17: 1 | C17: 41564 | D17: ELS | E17: 4 | F17: 8 | G17: 12000 | H17: 1.1127273e+08 | I17: 612000000 | K17: =K16+1 -> 9 | L17: =IF(ISERROR(VLOOKUP($K$4&$K$5&$K17,기획현황!$H:$H,1,FALSE))=TRUE,"",VLOOKUP($K$4&$K$5&$K17,기획현황!$H:$H,1,FALSE)) | N17: =N16+1 -> 9 | O17: =IF(ISERROR(VLOOKUP($K$4&$K$5&$N17,기획현황!$H:$H,1,FALSE))=TRUE,"",VLOOKUP($K$4&$K$5&$N17,기획현황!$H:$H,1,FALSE)) | Q17: =Q16+1 -> 509 | R17: =IF(ISERROR(VLOOKUP($K$4&$K$5&$Q17,기획현황!$H:$H,1,FALSE))=TRUE,"",VLOOKUP($K$4&$K$5&$Q17,기획현황!$H:$H,1,FALSE))
A18: YANGYUAN | B18: 1 | C18: 41513 | D18: ELS | E18: 3 | F18: 3 | G18: 2880 | H18: 34349371 | I18: 179520000 | K18: =K17+1 -> 10 | L18: =IF(ISERROR(VLOOKUP($K$4&$K$5&$K18,기획현황!$H:$H,1,FALSE))=TRUE,"",VLOOKUP($K$4&$K$5&$K18,기획현황!$H:$H,1,FALSE)) | N18: =N17+1 -> 10 | O18: =IF(ISERROR(VLOOKUP($K$4&$K$5&$N18,기획현황!$H:$H,1,FALSE))=TRUE,"",VLOOKUP($K$4&$K$5&$N18,기획현황!$H:$H,1,FALSE)) | Q18: =Q17+1 -> 510 | R18: =IF(ISERROR(VLOOKUP($K$4&$K$5&$Q18,기획현황!$H:$H,1,FALSE))=TRUE,"",VLOOKUP($K$4&$K$5&$Q18,기획현황!$H:$H,1,FALSE))
A19: 총합계 | E19: 105 | F19: 127 | G19: 163930 | H19: 1.178072e+09 | I19: 5241920000 | K19: =K18+1 -> 11 | L19: =IF(ISERROR(VLOOKUP($K$4&$K$5&$K19,기획현황!$H:$H,1,FALSE))=TRUE,"",VLOOKUP($K$4&$K$5&$K19,기획현황!$H:$H,1,FALSE)) | N19: =N18+1 -> 11 | O19: =IF(ISERROR(VLOOKUP($K$4&$K$5&$N19,기획현황!$H:$H,1,FALSE))=TRUE,"",VLOOKUP($K$4&$K$5&$N19,기획현황!$H:$H,1,FALSE)) | Q19: =Q18+1 -> 511 | R19: =IF(ISERROR(VLOOKUP($K$4&$K$5&$Q19,기획현황!$H:$H,1,FALSE))=TRUE,"",VLOOKUP($K$4&$K$5&$Q19,기획현황!$H:$H,1,FALSE))
K20: =K19+1 -> 12 | L20: =IF(ISERROR(VLOOKUP($K$4&$K$5&$K20,기획현황!$H:$H,1,FALSE))=TRUE,"",VLOOKUP($K$4&$K$5&$K20,기획현황!$H:$H,1,FALSE)) | N20: =N19+1 -> 12 | O20: =IF(ISERROR(VLOOKUP($K$4&$K$5&$N20,기획현황!$H:$H,1,FALSE))=TRUE,"",VLOOKUP($K$4&$K$5&$N20,기획현황!$H:$H,1,FALSE)) | Q20: =Q19+1 -> 512 | R20: =IF(ISERROR(VLOOKUP($K$4&$K$5&$Q20,기획현황!$H:$H,1,FALSE))=TRUE,"",VLOOKUP($K$4&$K$5&$Q20,기획현황!$H:$H,1,FALSE))
K21: =K20+1 -> 13 | L21: =IF(ISERROR(VLOOKUP($K$4&$K$5&$K21,기획현황!$H:$H,1,FALSE))=TRUE,"",VLOOKUP($K$4&$K$5&$K21,기획현황!$H:$H,1,FALSE)) | N21: =N20+1 -> 13 | O21: =IF(ISERROR(VLOOKUP($K$4&$K$5&$N21,기획현황!$H:$H,1,FALSE))=TRUE,"",VLOOKUP($K$4&$K$5&$N21,기획현황!$H:$H,1,FALSE)) | Q21: =Q20+1 -> 513 | R21: =IF(ISERROR(VLOOKUP($K$4&$K$5&$Q21,기획현황!$H:$H,1,FALSE))=TRUE,"",VLOOKUP($K$4&$K$5&$Q21,기획현황!$H:$H,1,FALSE))
K22: =K21+1 -> 14 | L22: =IF(ISERROR(VLOOKUP($K$4&$K$5&$K22,기획현황!$H:$H,1,FALSE))=TRUE,"",VLOOKUP($K$4&$K$5&$K22,기획현황!$H:$H,1,FALSE)) | N22: =N21+1 -> 14 | O22: =IF(ISERROR(VLOOKUP($K$4&$K$5&$N22,기획현황!$H:$H,1,FALSE))=TRUE,"",VLOOKUP($K$4&$K$5&$N22,기획현황!$H:$H,1,FALSE)) | Q22: =Q21+1 -> 514 | R22: =IF(ISERROR(VLOOKUP($K$4&$K$5&$Q22,기획현황!$H:$H,1,FALSE))=TRUE,"",VLOOKUP($K$4&$K$5&$Q22,기획현황!$H:$H,1,FALSE))
K23: =K22+1 -> 15 | L23: =IF(ISERROR(VLOOKUP($K$4&$K$5&$K23,기획현황!$H:$H,1,FALSE))=TRUE,"",VLOOKUP($K$4&$K$5&$K23,기획현황!$H:$H,1,FALSE)) | N23: =N22+1 -> 15 | O23: =IF(ISERROR(VLOOKUP($K$4&$K$5&$N23,기획현황!$H:$H,1,FALSE))=TRUE,"",VLOOKUP($K$4&$K$5&$N23,기획현황!$H:$H,1,FALSE)) | Q23: =Q22+1 -> 515 | R23: =IF(ISERROR(VLOOKUP($K$4&$K$5&$Q23,기획현황!$H:$H,1,FALSE))=TRUE,"",VLOOKUP($K$4&$K$5&$Q23,기획현황!$H:$H,1,FALSE))
K24: =K23+1 -> 16 | L24: =IF(ISERROR(VLOOKUP($K$4&$K$5&$K24,기획현황!$H:$H,1,FALSE))=TRUE,"",VLOOKUP($K$4&$K$5&$K24,기획현황!$H:$H,1,FALSE)) | N24: =N23+1 -> 16 | O24: =IF(ISERROR(VLOOKUP($K$4&$K$5&$N24,기획현황!$H:$H,1,FALSE))=TRUE,"",VLOOKUP($K$4&$K$5&$N24,기획현황!$H:$H,1,FALSE)) | Q24: =Q23+1 -> 516 | R24: =IF(ISERROR(VLOOKUP($K$4&$K$5&$Q24,기획현황!$H:$H,1,FALSE))=TRUE,"",VLOOKUP($K$4&$K$5&$Q24,기획현황!$H:$H,1,FALSE))
K25: =K24+1 -> 17 | L25: =IF(ISERROR(VLOOKUP($K$4&$K$5&$K25,기획현황!$H:$H,1,FALSE))=TRUE,"",VLOOKUP($K$4&$K$5&$K25,기획현황!$H:$H,1,FALSE)) | N25: =N24+1 -> 17 | O25: =IF(ISERROR(VLOOKUP($K$4&$K$5&$N25,기획현황!$H:$H,1,FALSE))=TRUE,"",VLOOKUP($K$4&$K$5&$N25,기획현황!$H:$H,1,FALSE)) | Q25: =Q24+1 -> 517 | R25: =IF(ISERROR(VLOOKUP($K$4&$K$5&$Q25,기획현황!$H:$H,1,FALSE))=TRUE,"",VLOOKUP($K$4&$K$5&$Q25,기획현황!$H:$H,1,FALSE))
K26: =K25+1 -> 18 | L26: =IF(ISERROR(VLOOKUP($K$4&$K$5&$K26,기획현황!$H:$H,1,FALSE))=TRUE,"",VLOOKUP($K$4&$K$5&$K26,기획현황!$H:$H,1,FALSE)) | N26: =N25+1 -> 18 | O26: =IF(ISERROR(VLOOKUP($K$4&$K$5&$N26,기획현황!$H:$H,1,FALSE))=TRUE,"",VLOOKUP($K$4&$K$5&$N26,기획현황!$H:$H,1,FALSE)) | Q26: =Q25+1 -> 518 | R26: =IF(ISERROR(VLOOKUP($K$4&$K$5&$Q26,기획현황!$H:$H,1,FALSE))=TRUE,"",VLOOKUP($K$4&$K$5&$Q26,기획현황!$H:$H,1,FALSE))
K27: =K26+1 -> 19 | L27: =IF(ISERROR(VLOOKUP($K$4&$K$5&$K27,기획현황!$H:$H,1,FALSE))=TRUE,"",VLOOKUP($K$4&$K$5&$K27,기획현황!$H:$H,1,FALSE)) | N27: =N26+1 -> 19 | O27: =IF(ISERROR(VLOOKUP($K$4&$K$5&$N27,기획현황!$H:$H,1,FALSE))=TRUE,"",VLOOKUP($K$4&$K$5&$N27,기획현황!$H:$H,1,FALSE)) | Q27: =Q26+1 -> 519 | R27: =IF(ISERROR(VLOOKUP($K$4&$K$5&$Q27,기획현황!$H:$H,1,FALSE))=TRUE,"",VLOOKUP($K$4&$K$5&$Q27,기획현황!$H:$H,1,FALSE))
K28: =K27+1 -> 20 | L28: =IF(ISERROR(VLOOKUP($K$4&$K$5&$K28,기획현황!$H:$H,1,FALSE))=TRUE,"",VLOOKUP($K$4&$K$5&$K28,기획현황!$H:$H,1,FALSE)) | N28: =N27+1 -> 20 | O28: =IF(ISERROR(VLOOKUP($K$4&$K$5&$N28,기획현황!$H:$H,1,FALSE))=TRUE,"",VLOOKUP($K$4&$K$5&$N28,기획현황!$H:$H,1,FALSE)) | Q28: =Q27+1 -> 520 | R28: =IF(ISERROR(VLOOKUP($K$4&$K$5&$Q28,기획현황!$H:$H,1,FALSE))=TRUE,"",VLOOKUP($K$4&$K$5&$Q28,기획현황!$H:$H,1,FALSE))
K29: =K28+1 -> 21 | L29: =IF(ISERROR(VLOOKUP($K$4&$K$5&$K29,기획현황!$H:$H,1,FALSE))=TRUE,"",VLOOKUP($K$4&$K$5&$K29,기획현황!$H:$H,1,FALSE)) | N29: =N28+1 -> 21 | O29: =IF(ISERROR(VLOOKUP($K$4&$K$5&$N29,기획현황!$H:$H,1,FALSE))=TRUE,"",VLOOKUP($K$4&$K$5&$N29,기획현황!$H:$H,1,FALSE)) | Q29: =Q28+1 -> 521 | R29: =IF(ISERROR(VLOOKUP($K$4&$K$5&$Q29,기획현황!$H:$H,1,FALSE))=TRUE,"",VLOOKUP($K$4&$K$5&$Q29,기획현황!$H:$H,1,FALSE))
K30: =K29+1 -> 22 | L30: =IF(ISERROR(VLOOKUP($K$4&$K$5&$K30,기획현황!$H:$H,1,FALSE))=TRUE,"",VLOOKUP($K$4&$K$5&$K30,기획현황!$H:$H,1,FALSE)) | N30: =N29+1 -> 22 | O30: =IF(ISERROR(VLOOKUP($K$4&$K$5&$N30,기획현황!$H:$H,1,FALSE))=TRUE,"",VLOOKUP($K$4&$K$5&$N30,기획현황!$H:$H,1,FALSE)) | Q30: =Q29+1 -> 522 | R30: =IF(ISERROR(VLOOKUP($K$4&$K$5&$Q30,기획현황!$H:$H,1,FALSE))=TRUE,"",VLOOKUP($K$4&$K$5&$Q30,기획현황!$H:$H,1,FALSE))
K31: =K30+1 -> 23 | L31: =IF(ISERROR(VLOOKUP($K$4&$K$5&$K31,기획현황!$H:$H,1,FALSE))=TRUE,"",VLOOKUP($K$4&$K$5&$K31,기획현황!$H:$H,1,FALSE)) | N31: =N30+1 -> 23 | O31: =IF(ISERROR(VLOOKUP($K$4&$K$5&$N31,기획현황!$H:$H,1,FALSE))=TRUE,"",VLOOKUP($K$4&$K$5&$N31,기획현황!$H:$H,1,FALSE)) | Q31: =Q30+1 -> 523 | R31: =IF(ISERROR(VLOOKUP($K$4&$K$5&$Q31,기획현황!$H:$H,1,FALSE))=TRUE,"",VLOOKUP($K$4&$K$5&$Q31,기획현황!$H:$H,1,FALSE))
... K107: =K106+1 -> 99 | L107: =IF(ISERROR(VLOOKUP($K$4&$K$5&$K107,기획현황!$H:$H,1,FALSE))=TRUE,"",VLOOKUP($K$4&$K$5&$K107,기획현황!$H:$H,1,FALSE)) | N107: =N106+1 -> 99 | O107: =IF(ISERROR(VLOOKUP($K$4&$K$5&$N107,기획현황!$H:$H,1,FALSE))=TRUE,"",VLOOKUP($K$4&$K$5&$N107,기획현황!$H:$H,1,FALSE)) | Q107: =Q106+1 -> 599 | R107: =IF(ISERROR(VLOOKUP($K$4&$K$5&$Q107,기획현황!$H:$H,1,FALSE))=TRUE,"",VLOOKUP($K$4&$K$5&$Q107,기획현황!$H:$H,1,FALSE))
K108: =K107+1 -> 100 | L108: =IF(ISERROR(VLOOKUP($K$4&$K$5&$K108,기획현황!$H:$H,1,FALSE))=TRUE,"",VLOOKUP($K$4&$K$5&$K108,기획현황!$H:$H,1,FALSE))
K109: =K108+1 -> 101 | L109: =IF(ISERROR(VLOOKUP($K$4&$K$5&$K109,기획현황!$H:$H,1,FALSE))=TRUE,"",VLOOKUP($K$4&$K$5&$K109,기획현황!$H:$H,1,FALSE))
K110: =K109+1 -> 102 | L110: =IF(ISERROR(VLOOKUP($K$4&$K$5&$K110,기획현황!$H:$H,1,FALSE))=TRUE,"",VLOOKUP($K$4&$K$5&$K110,기획현황!$H:$H,1,FALSE))
K111: =K110+1 -> 103 | L111: =IF(ISERROR(VLOOKUP($K$4&$K$5&$K111,기획현황!$H:$H,1,FALSE))=TRUE,"",VLOOKUP($K$4&$K$5&$K111,기획현황!$H:$H,1,FALSE))
K112: =K111+1 -> 104 | L112: =IF(ISERROR(VLOOKUP($K$4&$K$5&$K112,기획현황!$H:$H,1,FALSE))=TRUE,"",VLOOKUP($K$4&$K$5&$K112,기획현황!$H:$H,1,FALSE))
K113: =K112+1 -> 105 | L113: =IF(ISERROR(VLOOKUP($K$4&$K$5&$K113,기획현황!$H:$H,1,FALSE))=TRUE,"",VLOOKUP($K$4&$K$5&$K113,기획현황!$H:$H,1,FALSE))
K114: =K113+1 -> 106 | L114: =IF(ISERROR(VLOOKUP($K$4&$K$5&$K114,기획현황!$H:$H,1,FALSE))=TRUE,"",VLOOKUP($K$4&$K$5&$K114,기획현황!$H:$H,1,FALSE))
K115: =K114+1 -> 107 | L115: =IF(ISERROR(VLOOKUP($K$4&$K$5&$K115,기획현황!$H:$H,1,FALSE))=TRUE,"",VLOOKUP($K$4&$K$5&$K115,기획현황!$H:$H,1,FALSE))
K116: =K115+1 -> 108 | L116: =IF(ISERROR(VLOOKUP($K$4&$K$5&$K116,기획현황!$H:$H,1,FALSE))=TRUE,"",VLOOKUP($K$4&$K$5&$K116,기획현황!$H:$H,1,FALSE))
...

Sheet 기획현황
C1: PO ISSUE | F1: 1 | G1: =F1+1 -> 2 | H1: =G1+1 -> 3 | I1: =H1+1 -> 4 | J1: =I1+1 -> 5 | K1: =J1+1 -> 6 | L1: =K1+1 -> 7 | M1: =L1+1 -> 8 | N1: =M1+1 -> 9 | ... BR1: =BQ1+1 -> 65
K2: 2014 | L2: FW | M2: 기획현황 (이경진) | AT2: 180 | AU2: 20 | BX2: DATA UPLOAD FOR E-BIZ | CS2: TAG ISSUE | DG2: **PRODUCTION SCHEDULE
AO3: 환율 | AS3: 관세 | AW3: 제비용 | AX3: *인도네시아, 방글라데시 무관세 적용
AO4: KRW | AP4: EUR | AQ4: USD | AR4: JPY | AS4: 모자 | AT4: 의류 | AU4: 가방 | AV4: ACC | AW4: 0.05 | BN4: SHORTAGE | DV4: =TODAY() -> 42157
AO5: 1 | AP5: 1500 | AQ5: 1100 | AR5: 13 | AS5: 0.08 | AT5: 0.13 | AU5: 0.056 | AV5: 0.08 | BB5: =TODAY() -> 42157 | BG5: 건별계약서내용과 동일
K6: * 업체,업체차수,브랜드 정렬 | AZ6: 월,수요일 | BN6: 0.1
BX7: 컬렉션 | BY7: 시즌 | BZ7: 소재 | CA7: 품목 | CB7: 성별 | CC7: 국가 | CD7: 원산지 코드 | CE7: STYLE | CF7: 순번 | CG7: STYLE명 | CH7: COL | CI7: S_TYPE | CJ7: SIZE | CK7: 수량 | CL7: FOB | CM7: TAG가 | CN7: 원가 | CO7: 자재원가 | CP7: 구분
K8: 이미지 | L8: 브랜드 | M8: 브랜드명 | N8: 년도 | O8: 시즌 | P8: 품목 | Q8: 품목명 | R8: 성별 | S8: 순번 | T8: 순번 | U8: 품번 | V8: 품번수 | W8: 품명(=샘플명) | X8: 색상 | Y8: 색상명 | Z8: 품번색상 | AA8: 품번오더차수 | AB8: 색상수 | AC8: 원자재 혼용율 | AD8: 사이즈타입 | AE8: 사이즈 | AF8: 수량 | AG8: 업체 | AM8: TAG가 | AO8: 원가(-VAT) | AX8: 일정 | BG8: 원가 확정여부 | BH8: 입고일 확정여부 | BI8: 입고수량점검 | BO8: TOTAL | BX8: 브랜드 | BY8: 시즌 | BZ8: 분류 | CA8: 품목 | CB8: 성별 | CC8: 국가 | CD8: 샘플명 | CE8: 품번 | CF8: 순번 | CG8: 품번명 | CH8: 색상 | CI8: 사이즈타입 | CJ8: 사이즈 | CK8: 수량 | CL8: FOB($) | CM8: TAG가(\) | CN8: 원가(\,-VAT) | CO8: 자재원가(\,-VAT) | CP8: 수입1, 내수2 | CQ8: 발주번호 | CS8: NO. | CT8: 품번 (HAT'S ON CODE) | CU8: 명칭(상단) | CV8: 명칭(하단) | CW8: 명칭 (색상/사이즈) | CX8: 브랜드 | CY8: 순번 | CZ8: 수량 | DA8: TAG가(\) | DB8: 색상 | DC8: 사이즈 | DD8: 자율안전인증번호 | DE8: 최초순번 | DG8: PRODUCTION SCHEDULE | DZ8: 비고 | EF8: 순번
AG9: 업체명 | AH9: 차수 | AI9: 차수 | AJ9: 분류 | AK9: 국가 | AL9: 수입/내수 | AN9: 확정일 | AO9: 목표 | AP9: 조정 | AQ9: 차이 | AR9: 공급자재 | AV9: 해외(FOB, USD, JPY) | AW9: 국내(KRW) | AX9: 발주일 | AY9: 선적일 | AZ9: 납기일 | BO9: 수량 | BP9: 원가금액 (-VAT,백만원) | BQ9: TAG가금액 (백만원) | BR9: MU | DG9: PO 발송일 | DH9: 메인작지 수령 목표일 | DI9: 메인작지 수령일 | DJ9: 메인작지 발송일 | DK9: 건별계약서 작성(원가, 납기) | DL9: 중국원단사용유무 | DN9: 원자재 발주일 | DO9: 부자재 발주일 | DP9: 원부자재 발송 목표일 | DQ9: 원자재 발송일 | DR9: 부자재 발송일 | DS9: 최초상품대금 결재상신일 | DT9: PPS 수령일 | DU9: PPS 컨펌일 | DV9: 가격택 발송일 | DW9: INSPECTION일 | DX9: SPS 수령일 | DY9: 입고 완료여부 | EF9: 0
AR10: 원자재 | AS10: 부자재 | AT10: 기타 | AU10: 계 | AZ10: 목표 | BA10: 계약 | BB10: 1차입고 | BC10: 2차입고 | BD10: 3차입고 | BE10: 4차입고 | BF10: 5차입고 | BI10: 1차입고 | BJ10: 2차입고 | BK10: 3차입고 | BL10: 4차입고 | BM10: 5차입고 | BN10: 미입고수량 | DE10: 최초순번 | DL10: 총가지수 | DM10: 중국가지수 | EF10: 5 | EI10: 품번수계산
V11: =SUM(V$13:V61997)-SUMIF($I:$I,"TTL",V:V) -> 53 | AB11: =SUM(AB$13:AB61997)-SUMIF($I:$I,"TTL",AB:AB) -> 69 | AF11: =SUM(AF$13:AF61997)-SUMIF($I:$I,"TTL",AF:AF) -> 79800 | BI11: =SUM(BI$13:BI62001)-SUMIF($I:$I,"TTL",BI:BI) -> 76866 | BJ11: =SUM(BJ$13:BJ62001)-SUMIF($I:$I,"TTL",BJ:BJ) -> 4593 | BK11: =SUM(BK$13:BK62001)-SUMIF($I:$I,"TTL",BK:BK) -> 0 | BL11: =SUM(BL$13:BL62001)-SUMIF($I:$I,"TTL",BL:BL) -> 0 | BM11: =SUM(BM$13:BM62001)-SUMIF($I:$I,"TTL",BM:BM) -> 0 | BN11: =SUM(BN$13:BN62001)-SUMIF($I:$I,"TTL",BN:BN) -> 699 | BO11: =SUM(BO$13:BO61997)-SUMIF($I:$I,"TTL",BO:BO) -> 79800 | BP11: =SUM(BP$13:BP61997)-SUMIF($I:$I,"TTL",BP:BP) -> 2253846160 | BQ11: =SUM(BQ$13:BQ61997)-SUMIF($I:$I,"TTL",BQ:BQ) -> 9868500000 | BR11: =IF(ISERROR($BQ11/($BP11*1.1))=TRUE,0,$BQ11/($BP11*1.1)) -> 3.9804685 | BV11: 품번/색상/사이즈/수량/업체/차수/국가 | DH11: 90 | DL11: 숫자로 표기 | DM11: 숫자로 표기 | DN11: '없음'표기 | DO11: '없음'표기 | DP11: 60 | DQ11: 최종일표기 | DR11: 최종일표기 | EC11: 품번색상/발주일 | ED11: 품번색상사이즈 | EE11: 리오더(NEW) | EF11: 리오더(RUNNING) | EG11: 품번차수 | EI11: 품번 | EJ11: 품번색상
A12: 구분 | B12: 브랜드품목 | C12: 브랜드/업체/차수 | D12: 브랜드/업체/차수/품번색상 | E12: 순서 | F12: 브랜드/업체/차수/순서 | G12: 브랜드/업체/차수/순서/품번색상/사이즈 | H12: 브랜드/순번 | I12: 브랜드 | J12: 공란 | K12: 이미지 | L12: 브랜드 | M12: 브랜드명 | N12: 년도 | O12: 시즌 | P12: 품목 | Q12: 품목명 | R12: 성별 | S12: 순번 | T12: 순번2 | U12: 품번 | V12: 품번수 | W12: 품명(=샘플명) | X12: 색상 | Y12: 색상명 | Z12: 품번색상 | AA12: 오더차수 | AB12: 색상수 | AC12: 혼용율 | AD12: 사이즈타입 | AE12: 사이즈 | AF12: 수량 | AG12: 업체명 | AH12: 차수 | AI12: 차수2 | AJ12: 분류 | AK12: 국가 | AL12: 수입/내수 | AM12: TAG가목표 | AN12: TAG가조정 | AO12: 원가목표 | AP12: 원가조정 | AQ12: 원가차이 | AR12: 공급원자재 | AS12: 공급부자재 | AT12: 공급기타 | AU12: 공급계 | AV12: 해외(FOB, USD, JPY) | AW12: 국내(KRW) | AX12: 발주일 | AY12: 선적일 | AZ12: 목표납기일 | BA12: 계약납기일 | BB12: 1차입고일 | BC12: 2차입고일 | BD12: 3차입고일 | BE12: 4차입고일 | BF12: 5차입고일 | BG12: 확정여부 | BH12: 확정여부 | BI12: 1차입고수량 | BJ12: 2차입고수량 | BK12: 3차입고수량 | BL12: 3차입고수량 | BM12: 3차입고수량 | BN12: 차이수량 | BO12: TOTAL수량 | BP12: TOTAL원가금액 | BQ12: TOTALTAG가금액 | BR12: MU
A13: =IF(OR($I13="TTL",$I13=""),"",IF(ISERROR(VLOOKUP($B13,CODE!$D:$G,CODE!$F$1-2,FALSE))=TRUE,"전략",VLOOKUP($B13,CODE!$D:$G,CODE!$F$1-2,FALSE))) -> 전략 | B13: =IF(OR($I13="TTL",$I13=""),"",IF(VLOOKUP($P13,CODE!$K:$O,CODE!$O$1,FALSE)="",$I13,$I13&"-"&VLOOKUP($P13,CODE!$K:$O,CODE!$O$1,FALSE))) -> VBL-의류 | C13: =IF($I13="TTL","",I13&"-"&$AG13&"-"&$AI13) -> VBL-아트인드림-01 | D13: =$C13&$Z13 -> VBL-아트인드림-01VBLTLF4001BK | E13: =IF($I13="TTL",0,IF(ISERROR(IF($Z12=$Z13,$E12,$E12+1))=TRUE,1,IF($Z12=$Z13,$E12,$E12+1))) -> 1 | F13: =$C13&$E13 -> VBL-아트인드림-011 | G13: =$F13&"-"&$U13&$Y13&$AE13 -> VBL-아트인드림-011-VBLTLF4001BLACKOSS | H13: =IF(ISERROR(I13&VLOOKUP(P13,CODE!$K:$N,CODE!$N$1,FALSE)&S13)=TRUE,0,I13&VLOOKUP(P13,CODE!$K:$N,CODE!$N$1,FALSE)&S13) -> VBL의류1 | I13: =IF(ISERROR(SEARCH("TTL",$K13))=TRUE,IF($L13="","",VLOOKUP($L13,CODE!$B:$G,CODE!$D$1,FALSE)),"TTL") -> VBL | J13: =MID(W13,1,6) -> 14FW V | L13: VBL | M13: =IF(OR($I13="TTL",$L13=""),"",VLOOKUP($L13,CODE!$B:$D,CODE!$C$1,FALSE)) -> VITAL BLUE | N13: =IF(OR($I13="TTL",$L13=""),"",VLOOKUP($K$2,CODE!$S:$T,CODE!$T$1-1,FALSE)) -> F | O13: 4 | P13: TL | Q13: =IF(OR($I13="TTL",$P13=""),"",VLOOKUP($P13,CODE!$K:$M,CODE!$L$1,FALSE)) -> LONG SLEEVES | R13: U | S13: 1 | T13: =IF(OR($I13="TTL",$S13=""),"",IF($S13<10,"00"&$S13,IF($S13<100,"0"&$S13,$S13))) -> 001 | U13: =IF($I13="TTL","",$L13&$P13&$N13&$O13&$T13) -> VBLTLF4001 | V13: =IF($I13="TTL",SUMIF($C:$C,MID($K13,1,SEARCH("TTL",$K13)-2),$V:$V),IF($EI13="",0,1/COUNTIF($EI:$EI,$EI13))) -> 0.25 | W13: 14FW VB_MTM_01_BK | X13: =IF($Y13="","",VLOOKUP($Y13,CODE!$AE:$AF,CODE!$AF$1-1,FALSE)) -> BK | Y13: BLACK | Z13: =$U13&$X13 -> VBLTLF4001BK | AA13: =VLOOKUP($Z13&$AX13,$EC:$EG,5,FALSE) | AB13: =IF($I13="TTL",SUMIF($C:$C,MID($K13,1,SEARCH("TTL",$K13)-2),$AB:$AB),IF($EJ13="",0,1/COUNTIF($EJ:$EJ,$EJ13))) -> 0.25 | AC13: 0 | AD13: 1 | AE13: OSS | AF13: 250 | AG13: 아트인드림 | AH13: 1 | AI13: =IF($AH13=0,"",IF($AH13<10,"0"&$AH13,$AH13)) -> 01 | AJ13: M | AK13: KR | AL13: =IF($AK13=0,"",IF($AK13="KR",2,1)) -> 2 | AM13: =IF(ISERROR(VLOOKUP($F13,[1]기획현황취합!$A$1:$E$65440,[1]기획현황취합!$B$1,FALSE))=TRUE,0,VLOOKUP($F13,[1]기획현황취합!$A$1:$E$65440,[1]기획현황취합!$B$1,FALSE)) -> 79000 | AN13: =IF(ISERROR(VLOOKUP($F13,[1]기획현황취합!$A$1:$E$65440,[1]기획현황취합!$C$1,FALSE))=TRUE,0,VLOOKUP($F13,[1]기획현황취합!$A$1:$E$65440,[1]기획현황취합!$C$1,FALSE)) -> 41803 | AO13: =IF(ISERROR(($AM13/1.1)/VLOOKUP($AG13,'TARGET MU'!$A:$D,'TARGET MU'!$D$1,FALSE))=TRUE,0,($AM13/1.1)/VLOOKUP($AG13,'TARGET MU'!$A:$D,'TARGET MU'!$D$1,FALSE)) -> 19949.495 | AP13: =IF(OR(AF13=0,AND(AV13=0,AW13=0)),0,IF(AG13="캡보이2",AV13*$AQ$5+AU13,IF(OR(AK13="IN",AK13="BG",AK13="VT",AK13="CB"),$AU13+(($AV13*(1+$AW$4))*(HLOOKUP(VLOOKUP(AG13,'TARGET MU'!$A:$P,'TARGET MU'!$J$1,FALSE),$AO$4:$AR$5,2,FALSE)))+$AW13,$AU13+((($AV13*(1+$AW$4))*(1+HLOOKUP(VLOOKUP($P13,CODE!$K:$P,CODE!$P$1,FALSE),$AS$4:$AV$5,2,FALSE)))*(HLOOKUP(VLOOKUP(AG13,'TARGET MU'!$A:$P,'TARGET MU'!$J$1,FALSE),$AO$4:$AR$5,2,FALSE)))+$AW13))) -> 16500 | AQ13: =AP13-AO13 -> -3449.4949 | AR13: 0 | AS13: 20 | AU13: =SUM(AR13:AT13) -> 20 | AW13: 16480 | AX13: =IF(ISERROR(VLOOKUP($F13,[1]기획현황취합!$A$1:$E$65440,[1]기획현황취합!$D$1,FALSE))=TRUE,0,VLOOKUP($F13,[1]기획현황취합!$A$1:$E$65440,[1]기획현황취합!$D$1,FALSE)) -> 41737 | AZ13: =IF(ISERROR(VLOOKUP($F13,[1]기획현황취합!$A$1:$E$65440,[1]기획현황취합!$E$1,FALSE))=TRUE,0,VLOOKUP($F13,[1]기획현황취합!$A$1:$E$65440,[1]기획현황취합!$E$1,FALSE)) -> 41823 | BA13: 41864 | BB13: 41885 | BC13: 41901 | BD13: 0 | BE13: 0 | BF13: 0 | BG13: 확정 | BH13: 0 | BI13: =IF($I13="TTL",SUMIF($C:$C,MID($K13,1,SEARCH("TTL",$K13)-2),$BI:$BI),SUMIF(실입고현황!$A:$A,BB13&VLOOKUP($AG13,'TARGET MU'!$A:$D,'TARGET MU'!$B$1,FALSE)&$Z13&" "&$AE13,실입고현황!$C:$C)) -> 228 | BJ13: =IF($I13="TTL",SUMIF($C:$C,MID($K13,1,SEARCH("TTL",$K13)-2),$BJ:$BJ),SUMIF(실입고현황!$A:$A,BC13&VLOOKUP($AG13,'TARGET MU'!$A:$D,'TARGET MU'!$B$1,FALSE)&$Z13&" "&$AE13,실입고현황!$C:$C)) -> 13 | BK13: =IF($I13="TTL",SUMIF($C:$C,MID($K13,1,SEARCH("TTL",$K13)-2),$BK:$BK),SUMIF(실입고현황!$A:$A,BD13&VLOOKUP($AG13,'TARGET MU'!$A:$D,'TARGET MU'!$B$1,FALSE)&$Z13&" "&$AE13,실입고현황!$C:$C)) -> 0 | BL13: =IF($I13="TTL",SUMIF($C:$C,MID($K13,1,SEARCH("TTL",$K13)-2),$BL:$BL),SUMIF(실입고현황!$A:$A,BE13&VLOOKUP($AG13,'TARGET MU'!$A:$D,'TARGET MU'!$B$1,FALSE)&$Z13&" "&$AE13,실입고현황!$C:$C)) -> 0 | BM13: =IF($I13="TTL",SUMIF($C:$C,MID($K13,1,SEARCH("TTL",$K13)-2),$BM:$BM),SUMIF(실입고현황!$A:$A,BF13&VLOOKUP($AG13,'TARGET MU'!$A:$D,'TARGET MU'!$B$1,FALSE)&$Z13&" "&$AE13,실입고현황!$C:$C)) -> 0 | BN13: =IF($I13="TTL",SUMIF($C:$C,MID($K13,1,SEARCH("TTL",$K13)-2),$BN:$BN),IF(($BO13-SUM($BI13,$BJ13,$BK13,BL13,BM13))<$BO13*$BN$6,0,$BO13-SUM($BI13,$BJ13,$BK13,BL13,BM13))) -> 0 | BO13: =IF($I13="TTL",SUMIF($C:$C,MID($K13,1,SEARCH("TTL",$K13)-2),$BO:$BO),$AF13) -> 250 | BP13: =IF($I13="TTL",SUMIF($C:$C,MID($K13,1,SEARCH("TTL",$K13)-2),$BP:$BP),IF($AP13=0,$AO13*$AF13,$AP13*$AF13)) -> 4125000 | BQ13: =IF($I13="TTL",SUMIF($C:$C,MID($K13,1,SEARCH("TTL",$K13)-2),$BQ:$BQ),$AM13*$AF13) -> 19750000 | BR13: =IF(ISERROR($BQ13/($BP13*1.1))=TRUE,0,$BQ13/($BP13*1.1)) -> 4.3526171 | BT13: =IF(ISERROR(Z13&VLOOKUP($AG13,'TARGET MU'!$A:$D,'TARGET MU'!$B$1,FALSE))=TRUE,"",Z13&VLOOKUP($AG13,'TARGET MU'!$A:$D,'TARGET MU'!$B$1,FALSE)) -> VBLTLF4001BK아트인드림 | BU13: =AP13 -> 16500 | BV13: =Z13&AE13&AF13&AM13&AG13&AI13&AK13 -> VBLTLF4001BKOSS25079000아트인드림01KR | BX13: =IF($I13="TTL","",$L13) -> VBL | BY13: =$O13 -> 4 | BZ13: =$AJ13 -> M | CA13: =$P13 -> TL | CB13: =$R13 -> U | CC13: =$AK13 -> KR | CD13: =$W13 -> 14FW VB_MTM_01_BK | CE13: =$U13 -> VBLTLF4001 | CF13: =$T13 -> 001 | CG13: =$W13 -> 14FW VB_MTM_01_BK | CH13: =$X13 -> BK | CI13: =$AD13 -> 1 | CJ13: =$AE13 -> OSS | CK13: =IF($I13="TTL",SUMIF($C:$C,MID($K13,1,SEARCH("TTL",$K13)-2),$BO:$BO),$AF13) -> 250 | CL13: =$AV13 -> 0 | CM13: =$AM13 -> 79000 | CN13: =$AP13-$AU13 -> 16480 | CO13: =$AU13 -> 20 | CP13: =$AL13 -> 2 | CT13: =IF($I13="TTL",$K13,$Z13&$AE13) -> VBLTLF4001BKOSS | CU13: =$M13 -> VITAL BLUE | CV13: =IF($I13="TTL","",IF($CT13="","",$Q13&"_"&$T13&IF(R13="K","_KIDS",""))) -> LONG SLEEVES_001 | CW13: =IF($I13="TTL","",IF($CT13="","",$Y13&"_"&$AE13)) -> BLACK_OSS | CX13: =$L13 -> VBL | CY13: =$T13 -> 001 | CZ13: =IF($I13="TTL",SUMIF($C:$C,MID($K13,1,SEARCH("TTL",$K13)-2),$CZ:$CZ),$AF13) -> 250 | DA13: =$AM13 -> 79000 | DB13: =$Y13 -> BLACK | DC13: =$AE13 -> OSS | DG13: 41778 | DH13: =IF(OR($I13="TTL",$I13=""),"",AZ13-$DH$11) -> 41733 | DI13: 41737 | DJ13: 41737 | DK13: 41829 | DP13: =IF(OR($DN13="없음",$I13="TTL",$I13=""),"",AZ13-$DP$11) -> 41763 | DV13: 41838 | EC13: =IF(OR($Z12&$AX12=$Z13&$AX12,$Z13&$AX13=""),"",$Z13&$AX13) -> VBLTLF4001BK41737 | ED13: =IF(OR(Z12&AE12=Z13&AE13,Z13=""),"",Z13&AE13) -> VBLTLF4001BKOSS | EE13: =IF($ED13="",0,IF(COUNTIF(ED$12:ED12,ED13)=0,0,COUNTIF(ED$12:ED12,ED13))) -> 0 | EF13: =IF(OR($AJ13="B",$ED13="",MID($U13,8,1)=$EF$9,MID($U13,8,1)=$EF$10),0,1) -> 0 | EG13: =IF(EE13+EF13=0,"","R"&(EE13+EF13)) | EI13: =IF($ED13="","",IF($EE13=0,U13,"")) -> VBLTLF4001 | EJ13: =IF($ED13="","",IF($EE13=0,Z13,"")) -> VBLTLF4001BK
A14: =IF(OR($I14="TTL",$I14=""),"",IF(ISERROR(VLOOKUP($B14,CODE!$D:$G,CODE!$F$1-2,FALSE))=TRUE,"전략",VLOOKUP($B14,CODE!$D:$G,CODE!$F$1-2,FALSE))) -> 전략 | B14: =IF(OR($I14="TTL",$I14=""),"",IF(VLOOKUP($P14,CODE!$K:$O,CODE!$O$1,FALSE)="",$I14,$I14&"-"&VLOOKUP($P14,CODE!$K:$O,CODE!$O$1,FALSE))) -> VBL-의류 | C14: =IF($I14="TTL","",I14&"-"&$AG14&"-"&$AI14) -> VBL-아트인드림-01 | D14: =$C14&$Z14 -> VBL-아트인드림-01VBLTLF4001BK | E14: =IF($I14="TTL",0,IF(ISERROR(IF($Z13=$Z14,$E13,$E13+1))=TRUE,1,IF($Z13=$Z14,$E13,$E13+1))) -> 1 | F14: =$C14&$E14 -> VBL-아트인드림-011 | G14: =$F14&"-"&$U14&$Y14&$AE14 -> VBL-아트인드림-011-VBLTLF4001BLACKOMM | H14: =IF(ISERROR(I14&VLOOKUP(P14,CODE!$K:$N,CODE!$N$1,FALSE)&S14)=TRUE,0,I14&VLOOKUP(P14,CODE!$K:$N,CODE!$N$1,FALSE)&S14) -> VBL의류1 | I14: =IF(ISERROR(SEARCH("TTL",$K14))=TRUE,IF($L14="","",VLOOKUP($L14,CODE!$B:$G,CODE!$D$1,FALSE)),"TTL") -> VBL | J14: =MID(W14,1,6) -> 14FW V | L14: VBL | M14: =IF(OR($I14="TTL",$L14=""),"",VLOOKUP($L14,CODE!$B:$D,CODE!$C$1,FALSE)) -> VITAL BLUE | N14: =IF(OR($I14="TTL",$L14=""),"",VLOOKUP($K$2,CODE!$S:$T,CODE!$T$1-1,FALSE)) -> F | O14: 4 | P14: TL | Q14: =IF(OR($I14="TTL",$P14=""),"",VLOOKUP($P14,CODE!$K:$M,CODE!$L$1,FALSE)) -> LONG SLEEVES | R14: U | S14: 1 | T14: =IF(OR($I14="TTL",$S14=""),"",IF($S14<10,"00"&$S14,IF($S14<100,"0"&$S14,$S14))) -> 001 | U14: =IF($I14="TTL","",$L14&$P14&$N14&$O14&$T14) -> VBLTLF4001 | V14: =IF($I14="TTL",SUMIF($C:$C,MID($K14,1,SEARCH("TTL",$K14)-2),$V:$V),IF($EI14="",0,1/COUNTIF($EI:$EI,$EI14))) -> 0.25 | W14: 14FW VB_MTM_01_BK | X14: =IF($Y14="","",VLOOKUP($Y14,CODE!$AE:$AF,CODE!$AF$1-1,FALSE)) -> BK | Y14: BLACK | Z14: =$U14&$X14 -> VBLTLF4001BK | AA14: =VLOOKUP($Z14&$AX14,$EC:$EG,5,FALSE) | AB14: =IF($I14="TTL",SUMIF($C:$C,MID($K14,1,SEARCH("TTL",$K14)-2),$AB:$AB),IF($EJ14="",0,1/COUNTIF($EJ:$EJ,$EJ14))) -> 0.25 | AC14: 0 | AD14: 1 | AE14: OMM | AF14: 350 | AG14: 아트인드림 | AH14: 1 | AI14: =IF($AH14=0,"",IF($AH14<10,"0"&$AH14,$AH14)) -> 01 | AJ14: M | AK14: KR | AL14: =IF($AK14=0,"",IF($AK14="KR",2,1)) -> 2 | AM14: =IF(ISERROR(VLOOKUP($F14,[1]기획현황취합!$A$1:$E$65440,[1]기획현황취합!$B$1,FALSE))=TRUE,0,VLOOKUP($F14,[1]기획현황취합!$A$1:$E$65440,[1]기획현황취합!$B$1,FALSE)) -> 79000 | AN14: =IF(ISERROR(VLOOKUP($F14,[1]기획현황취합!$A$1:$E$65440,[1]기획현황취합!$C$1,FALSE))=TRUE,0,VLOOKUP($F14,[1]기획현황취합!$A$1:$E$65440,[1]기획현황취합!$C$1,FALSE)) -> 41803 | AO14: =IF(ISERROR(($AM14/1.1)/VLOOKUP($AG14,'TARGET MU'!$A:$D,'TARGET MU'!$D$1,FALSE))=TRUE,0,($AM14/1.1)/VLOOKUP($AG14,'TARGET MU'!$A:$D,'TARGET MU'!$D$1,FALSE)) -> 19949.495 | AP14: =IF(OR(AF14=0,AND(AV14=0,AW14=0)),0,IF(AG14="캡보이2",AV14*$AQ$5+AU14,IF(OR(AK14="IN",AK14="BG",AK14="VT",AK14="CB"),$AU14+(($AV14*(1+$AW$4))*(HLOOKUP(VLOOKUP(AG14,'TARGET MU'!$A:$P,'TARGET MU'!$J$1,FALSE),$AO$4:$AR$5,2,FALSE)))+$AW14,$AU14+((($AV14*(1+$AW$4))*(1+HLOOKUP(VLOOKUP($P14,CODE!$K:$P,CODE!$P$1,FALSE),$AS$4:$AV$5,2,FALSE)))*(HLOOKUP(VLOOKUP(AG14,'TARGET MU'!$A:$P,'TARGET MU'!$J$1,FALSE),$AO$4:$AR$5,2,FALSE)))+$AW14))) -> 16500 | AQ14: =AP14-AO14 -> -3449.4949 | AR14: 0 | AS14: 20 | AU14: =SUM(AR14:AT14) -> 20 | AV14: 0 | AW14: 16480 | AX14: =IF(ISERROR(VLOOKUP($F14,[1]기획현황취합!$A$1:$E$65440,[1]기획현황취합!$D$1,FALSE))=TRUE,0,VLOOKUP($F14,[1]기획현황취합!$A$1:$E$65440,[1]기획현황취합!$D$1,FALSE)) -> 41737 | AY14: 0 | AZ14: =IF(ISERROR(VLOOKUP($F14,[1]기획현황취합!$A$1:$E$65440,[1]기획현황취합!$E$1,FALSE))=TRUE,0,VLOOKUP($F14,[1]기획현황취합!$A$1:$E$65440,[1]기획현황취합!$E$1,FALSE)) -> 41823 | BA14: 41864 | BB14: 41885 | BC14: 41901 | BD14: 0 | BE14: 0 | BF14: 0 | BG14: 확정 | BH14: 0 | BI14: =IF($I14="TTL",SUMIF($C:$C,MID($K14,1,SEARCH("TTL",$K14)-2),$BI:$BI),SUMIF(실입고현황!$A:$A,BB14&VLOOKUP($AG14,'TARGET MU'!$A:$D,'TARGET MU'!$B$1,FALSE)&$Z14&" "&$AE14,실입고현황!$C:$C)) -> 295 | BJ14: =IF($I14="TTL",SUMIF($C:$C,MID($K14,1,SEARCH("TTL",$K14)-2),$BJ:$BJ),SUMIF(실입고현황!$A:$A,BC14&VLOOKUP($AG14,'TARGET MU'!$A:$D,'TARGET MU'!$B$1,FALSE)&$Z14&" "&$AE14,실입고현황!$C:$C)) -> 74 | BK14: =IF($I14="TTL",SUMIF($C:$C,MID($K14,1,SEARCH("TTL",$K14)-2),$BK:$BK),SUMIF(실입고현황!$A:$A,BD14&VLOOKUP($AG14,'TARGET MU'!$A:$D,'TARGET MU'!$B$1,FALSE)&$Z14&" "&$AE14,실입고현황!$C:$C)) -> 0 | BL14: =IF($I14="TTL",SUMIF($C:$C,MID($K14,1,SEARCH("TTL",$K14)-2),$BL:$BL),SUMIF(실입고현황!$A:$A,BE14&VLOOKUP($AG14,'TARGET MU'!$A:$D,'TARGET MU'!$B$1,FALSE)&$Z14&" "&$AE14,실입고현황!$C:$C)) -> 0 | BM14: =IF($I14="TTL",SUMIF($C:$C,MID($K14,1,SEARCH("TTL",$K14)-2),$BM:$BM),SUMIF(실입고현황!$A:$A,BF14&VLOOKUP($AG14,'TARGET MU'!$A:$D,'TARGET MU'!$B$1,FALSE)&$Z14&" "&$AE14,실입고현황!$C:$C)) -> 0 | BN14: =IF($I14="TTL",SUMIF($C:$C,MID($K14,1,SEARCH("TTL",$K14)-2),$BN:$BN),IF(($BO14-SUM($BI14,$BJ14,$BK14,BL14,BM14))<$BO14*$BN$6,0,$BO14-SUM($BI14,$BJ14,$BK14,BL14,BM14))) -> 0 | BO14: =IF($I14="TTL",SUMIF($C:$C,MID($K14,1,SEARCH("TTL",$K14)-2),$BO:$BO),$AF14) -> 350 | BP14: =IF($I14="TTL",SUMIF($C:$C,MID($K14,1,SEARCH("TTL",$K14)-2),$BP:$BP),IF($AP14=0,$AO14*$AF14,$AP14*$AF14)) -> 5775000 | BQ14: =IF($I14="TTL",SUMIF($C:$C,MID($K14,1,SEARCH("TTL",$K14)-2),$BQ:$BQ),$AM14*$AF14) -> 27650000 | BR14: =IF(ISERROR($BQ14/($BP14*1.1))=TRUE,0,$BQ14/($BP14*1.1)) -> 4.3526171 | BT14: =IF(ISERROR(Z14&VLOOKUP($AG14,'TARGET MU'!$A:$D,'TARGET MU'!$B$1,FALSE))=TRUE,"",Z14&VLOOKUP($AG14,'TARGET MU'!$A:$D,'TARGET MU'!$B$1,FALSE)) -> VBLTLF4001BK아트인드림 | BU14: =AP14 -> 16500 | BV14: =Z14&AE14&AF14&AM14&AG14&AI14&AK14 -> VBLTLF4001BKOMM35079000아트인드림01KR | BX14: =IF($I14="TTL","",$L14) -> VBL | BY14: =$O14 -> 4 | BZ14: =$AJ14 -> M | CA14: =$P14 -> TL | CB14: =$R14 -> U | CC14: =$AK14 -> KR | CD14: =$W14 -> 14FW VB_MTM_01_BK | CE14: =$U14 -> VBLTLF4001 | CF14: =$T14 -> 001 | CG14: =$W14 -> 14FW VB_MTM_01_BK | CH14: =$X14 -> BK | CI14: =$AD14 -> 1 | CJ14: =$AE14 -> OMM | CK14: =IF($I14="TTL",SUMIF($C:$C,MID($K14,1,SEARCH("TTL",$K14)-2),$BO:$BO),$AF14) -> 350 | CL14: =$AV14 -> 0 | CM14: =$AM14 -> 79000 | CN14: =$AP14-$AU14 -> 16480 | CO14: =$AU14 -> 20 | CP14: =$AL14 -> 2 | CT14: =IF($I14="TTL",$K14,$Z14&$AE14) -> VBLTLF4001BKOMM | CU14: =$M14 -> VITAL BLUE | CV14: =IF($I14="TTL","",IF($CT14="","",$Q14&"_"&$T14&IF(R14="K","_KIDS",""))) -> LONG SLEEVES_001 | CW14: =IF($I14="TTL","",IF($CT14="","",$Y14&"_"&$AE14)) -> BLACK_OMM | CX14: =$L14 -> VBL | CY14: =$T14 -> 001 | CZ14: =IF($I14="TTL",SUMIF($C:$C,MID($K14,1,SEARCH("TTL",$K14)-2),$CZ:$CZ),$AF14) -> 350 | DA14: =$AM14 -> 79000 | DB14: =$Y14 -> BLACK | DC14: =$AE14 -> OMM | DG14: 41778 | DH14: =IF(OR($I14="TTL",$I14=""),"",AZ14-$DH$11) -> 41733 | DI14: 41737 | DJ14: 41737 | DK14: 41829 | DP14: =IF(OR($DN14="없음",$I14="TTL",$I14=""),"",AZ14-$DP$11) -> 41763 | DV14: 41838 | EC14: =IF(OR($Z13&$AX13=$Z14&$AX13,$Z14&$AX14=""),"",$Z14&$AX14) | ED14: =IF(OR(Z13&AE13=Z14&AE14,Z14=""),"",Z14&AE14) -> VBLTLF4001BKOMM | EE14: =IF($ED14="",0,IF(COUNTIF(ED$12:ED13,ED14)=0,0,COUNTIF(ED$12:ED13,ED14))) -> 0 | EF14: =IF(OR($AJ14="B",$ED14="",MID($U14,8,1)=$EF$9,MID($U14,8,1)=$EF$10),0,1) -> 0 | EG14: =IF(EE14+EF14=0,"","R"&(EE14+EF14)) | EI14: =IF($ED14="","",IF($EE14=0,U14,"")) -> VBLTLF4001 | EJ14: =IF($ED14="","",IF($EE14=0,Z14,"")) -> VBLTLF4001BK
A15: =IF(OR($I15="TTL",$I15=""),"",IF(ISERROR(VLOOKUP($B15,CODE!$D:$G,CODE!$F$1-2,FALSE))=TRUE,"전략",VLOOKUP($B15,CODE!$D:$G,CODE!$F$1-2,FALSE))) -> 전략 | B15: =IF(OR($I15="TTL",$I15=""),"",IF(VLOOKUP($P15,CODE!$K:$O,CODE!$O$1,FALSE)="",$I15,$I15&"-"&VLOOKUP($P15,CODE!$K:$O,CODE!$O$1,FALSE))) -> VBL-의류 | C15: =IF($I15="TTL","",I15&"-"&$AG15&"-"&$AI15) -> VBL-아트인드림-01 | D15: =$C15&$Z15 -> VBL-아트인드림-01VBLTLF4001BK | E15: =IF($I15="TTL",0,IF(ISERROR(IF($Z14=$Z15,$E14,$E14+1))=TRUE,1,IF($Z14=$Z15,$E14,$E14+1))) -> 1 | F15: =$C15&$E15 -> VBL-아트인드림-011 | G15: =$F15&"-"&$U15&$Y15&$AE15 -> VBL-아트인드림-011-VBLTLF4001BLACKOLL | H15: =IF(ISERROR(I15&VLOOKUP(P15,CODE!$K:$N,CODE!$N$1,FALSE)&S15)=TRUE,0,I15&VLOOKUP(P15,CODE!$K:$N,CODE!$N$1,FALSE)&S15) -> VBL의류1 | I15: =IF(ISERROR(SEARCH("TTL",$K15))=TRUE,IF($L15="","",VLOOKUP($L15,CODE!$B:$G,CODE!$D$1,FALSE)),"TTL") -> VBL | J15: =MID(W15,1,6) -> 14FW V | L15: VBL | M15: =IF(OR($I15="TTL",$L15=""),"",VLOOKUP($L15,CODE!$B:$D,CODE!$C$1,FALSE)) -> VITAL BLUE | N15: =IF(OR($I15="TTL",$L15=""),"",VLOOKUP($K$2,CODE!$S:$T,CODE!$T$1-1,FALSE)) -> F | O15: 4 | P15: TL | Q15: =IF(OR($I15="TTL",$P15=""),"",VLOOKUP($P15,CODE!$K:$M,CODE!$L$1,FALSE)) -> LONG SLEEVES | R15: U | S15: 1 | T15: =IF(OR($I15="TTL",$S15=""),"",IF($S15<10,"00"&$S15,IF($S15<100,"0"&$S15,$S15))) -> 001 | U15: =IF($I15="TTL","",$L15&$P15&$N15&$O15&$T15) -> VBLTLF4001 | V15: =IF($I15="TTL",SUMIF($C:$C,MID($K15,1,SEARCH("TTL",$K15)-2),$V:$V),IF($EI15="",0,1/COUNTIF($EI:$EI,$EI15))) -> 0.25 | W15: 14FW VB_MTM_01_BK | X15: =IF($Y15="","",VLOOKUP($Y15,CODE!$AE:$AF,CODE!$AF$1-1,FALSE)) -> BK | Y15: BLACK | Z15: =$U15&$X15 -> VBLTLF4001BK | AA15: =VLOOKUP($Z15&$AX15,$EC:$EG,5,FALSE) | AB15: =IF($I15="TTL",SUMIF($C:$C,MID($K15,1,SEARCH("TTL",$K15)-2),$AB:$AB),IF($EJ15="",0,1/COUNTIF($EJ:$EJ,$EJ15))) -> 0.25 | AC15: 0 | AD15: 1 | AE15: OLL | AF15: 350 | AG15: 아트인드림 | AH15: 1 | AI15: =IF($AH15=0,"",IF($AH15<10,"0"&$AH15,$AH15)) -> 01 | AJ15: M | AK15: KR | AL15: =IF($AK15=0,"",IF($AK15="KR",2,1)) -> 2 | AM15: =IF(ISERROR(VLOOKUP($F15,[1]기획현황취합!$A$1:$E$65440,[1]기획현황취합!$B$1,FALSE))=TRUE,0,VLOOKUP($F15,[1]기획현황취합!$A$1:$E$65440,[1]기획현황취합!$B$1,FALSE)) -> 79000 | AN15: =IF(ISERROR(VLOOKUP($F15,[1]기획현황취합!$A$1:$E$65440,[1]기획현황취합!$C$1,FALSE))=TRUE,0,VLOOKUP($F15,[1]기획현황취합!$A$1:$E$65440,[1]기획현황취합!$C$1,FALSE)) -> 41803 | AO15: =IF(ISERROR(($AM15/1.1)/VLOOKUP($AG15,'TARGET MU'!$A:$D,'TARGET MU'!$D$1,FALSE))=TRUE,0,($AM15/1.1)/VLOOKUP($AG15,'TARGET MU'!$A:$D,'TARGET MU'!$D$1,FALSE)) -> 19949.495 | AP15: =IF(OR(AF15=0,AND(AV15=0,AW15=0)),0,IF(AG15="캡보이2",AV15*$AQ$5+AU15,IF(OR(AK15="IN",AK15="BG",AK15="VT",AK15="CB"),$AU15+(($AV15*(1+$AW$4))*(HLOOKUP(VLOOKUP(AG15,'TARGET MU'!$A:$P,'TARGET MU'!$J$1,FALSE),$AO$4:$AR$5,2,FALSE)))+$AW15,$AU15+((($AV15*(1+$AW$4))*(1+HLOOKUP(VLOOKUP($P15,CODE!$K:$P,CODE!$P$1,FALSE),$AS$4:$AV$5,2,FALSE)))*(HLOOKUP(VLOOKUP(AG15,'TARGET MU'!$A:$P,'TARGET MU'!$J$1,FALSE),$AO$4:$AR$5,2,FALSE)))+$AW15))) -> 16500 | AQ15: =AP15-AO15 -> -3449.4949 | AR15: 0 | AS15: 20 | AU15: =SUM(AR15:AT15) -> 20 | AV15: 0 | AW15: 16480 | AX15: =IF(ISERROR(VLOOKUP($F15,[1]기획현황취합!$A$1:$E$65440,[1]기획현황취합!$D$1,FALSE))=TRUE,0,VLOOKUP($F15,[1]기획현황취합!$A$1:$E$65440,[1]기획현황취합!$D$1,FALSE)) -> 41737 | AY15: 0 | AZ15: =IF(ISERROR(VLOOKUP($F15,[1]기획현황취합!$A$1:$E$65440,[1]기획현황취합!$E$1,FALSE))=TRUE,0,VLOOKUP($F15,[1]기획현황취합!$A$1:$E$65440,[1]기획현황취합!$E$1,FALSE)) -> 41823 | BA15: 41864 | BB15: 41885 | BC15: 41901 | BD15: 0 | BE15: 0 | BF15: 0 | BG15: 확정 | BH15: 0 | BI15: =IF($I15="TTL",SUMIF($C:$C,MID($K15,1,SEARCH("TTL",$K15)-2),$BI:$BI),SUMIF(실입고현황!$A:$A,BB15&VLOOKUP($AG15,'TARGET MU'!$A:$D,'TARGET MU'!$B$1,FALSE)&$Z15&" "&$AE15,실입고현황!$C:$C)) -> 322 | BJ15: =IF($I15="TTL",SUMIF($C:$C,MID($K15,1,SEARCH("TTL",$K15)-2),$BJ:$BJ),SUMIF(실입고현황!$A:$A,BC15&VLOOKUP($AG15,'TARGET MU'!$A:$D,'TARGET MU'!$B$1,FALSE)&$Z15&" "&$AE15,실입고현황!$C:$C)) -> 46 | BK15: =IF($I15="TTL",SUMIF($C:$C,MID($K15,1,SEARCH("TTL",$K15)-2),$BK:$BK),SUMIF(실입고현황!$A:$A,BD15&VLOOKUP($AG15,'TARGET MU'!$A:$D,'TARGET MU'!$B$1,FALSE)&$Z15&" "&$AE15,실입고현황!$C:$C)) -> 0 | BL15: =IF($I15="TTL",SUMIF($C:$C,MID($K15,1,SEARCH("TTL",$K15)-2),$BL:$BL),SUMIF(실입고현황!$A:$A,BE15&VLOOKUP($AG15,'TARGET MU'!$A:$D,'TARGET MU'!$B$1,FALSE)&$Z15&" "&$AE15,실입고현황!$C:$C)) -> 0 | BM15: =IF($I15="TTL",SUMIF($C:$C,MID($K15,1,SEARCH("TTL",$K15)-2),$BM:$BM),SUMIF(실입고현황!$A:$A,BF15&VLOOKUP($AG15,'TARGET MU'!$A:$D,'TARGET MU'!$B$1,FALSE)&$Z15&" "&$AE15,실입고현황!$C:$C)) -> 0 | BN15: =IF($I15="TTL",SUMIF($C:$C,MID($K15,1,SEARCH("TTL",$K15)-2),$BN:$BN),IF(($BO15-SUM($BI15,$BJ15,$BK15,BL15,BM15))<$BO15*$BN$6,0,$BO15-SUM($BI15,$BJ15,$BK15,BL15,BM15))) -> 0 | BO15: =IF($I15="TTL",SUMIF($C:$C,MID($K15,1,SEARCH("TTL",$K15)-2),$BO:$BO),$AF15) -> 350 | BP15: =IF($I15="TTL",SUMIF($C:$C,MID($K15,1,SEARCH("TTL",$K15)-2),$BP:$BP),IF($AP15=0,$AO15*$AF15,$AP15*$AF15)) -> 5775000 | BQ15: =IF($I15="TTL",SUMIF($C:$C,MID($K15,1,SEARCH("TTL",$K15)-2),$BQ:$BQ),$AM15*$AF15) -> 27650000 | BR15: =IF(ISERROR($BQ15/($BP15*1.1))=TRUE,0,$BQ15/($BP15*1.1)) -> 4.3526171 | BT15: =IF(ISERROR(Z15&VLOOKUP($AG15,'TARGET MU'!$A:$D,'TARGET MU'!$B$1,FALSE))=TRUE,"",Z15&VLOOKUP($AG15,'TARGET MU'!$A:$D,'TARGET MU'!$B$1,FALSE)) -> VBLTLF4001BK아트인드림 | BU15: =AP15 -> 16500 | BV15: =Z15&AE15&AF15&AM15&AG15&AI15&AK15 -> VBLTLF4001BKOLL35079000아트인드림01KR | BX15: =IF($I15="TTL","",$L15) -> VBL | BY15: =$O15 -> 4 | BZ15: =$AJ15 -> M | CA15: =$P15 -> TL | CB15: =$R15 -> U | CC15: =$AK15 -> KR | CD15: =$W15 -> 14FW VB_MTM_01_BK | CE15: =$U15 -> VBLTLF4001 | CF15: =$T15 -> 001 | CG15: =$W15 -> 14FW VB_MTM_01_BK | CH15: =$X15 -> BK | CI15: =$AD15 -> 1 | CJ15: =$AE15 -> OLL | CK15: =IF($I15="TTL",SUMIF($C:$C,MID($K15,1,SEARCH("TTL",$K15)-2),$BO:$BO),$AF15) -> 350 | CL15: =$AV15 -> 0 | CM15: =$AM15 -> 79000 | CN15: =$AP15-$AU15 -> 16480 | CO15: =$AU15 -> 20 | CP15: =$AL15 -> 2 | CT15: =IF($I15="TTL",$K15,$Z15&$AE15) -> VBLTLF4001BKOLL | CU15: =$M15 -> VITAL BLUE | CV15: =IF($I15="TTL","",IF($CT15="","",$Q15&"_"&$T15&IF(R15="K","_KIDS",""))) -> LONG SLEEVES_001 | CW15: =IF($I15="TTL","",IF($CT15="","",$Y15&"_"&$AE15)) -> BLACK_OLL | CX15: =$L15 -> VBL | CY15: =$T15 -> 001 | CZ15: =IF($I15="TTL",SUMIF($C:$C,MID($K15,1,SEARCH("TTL",$K15)-2),$CZ:$CZ),$AF15) -> 350 | DA15: =$AM15 -> 79000 | DB15: =$Y15 -> BLACK | DC15: =$AE15 -> OLL | DG15: 41778 | DH15: =IF(OR($I15="TTL",$I15=""),"",AZ15-$DH$11) -> 41733 | DI15: 41737 | DJ15: 41737 | DK15: 41829 | DP15: =IF(OR($DN15="없음",$I15="TTL",$I15=""),"",AZ15-$DP$11) -> 41763 | DV15: 41838 | EC15: =IF(OR($Z14&$AX14=$Z15&$AX14,$Z15&$AX15=""),"",$Z15&$AX15) | ED15: =IF(OR(Z14&AE14=Z15&AE15,Z15=""),"",Z15&AE15) -> VBLTLF4001BKOLL | EE15: =IF($ED15="",0,IF(COUNTIF(ED$12:ED14,ED15)=0,0,COUNTIF(ED$12:ED14,ED15))) -> 0 | EF15: =IF(OR($AJ15="B",$ED15="",MID($U15,8,1)=$EF$9,MID($U15,8,1)=$EF$10),0,1) -> 0 | EG15: =IF(EE15+EF15=0,"","R"&(EE15+EF15)) | EI15: =IF($ED15="","",IF($EE15=0,U15,"")) -> VBLTLF4001 | EJ15: =IF($ED15="","",IF($EE15=0,Z15,"")) -> VBLTLF4001BK
A16: =IF(OR($I16="TTL",$I16=""),"",IF(ISERROR(VLOOKUP($B16,CODE!$D:$G,CODE!$F$1-2,FALSE))=TRUE,"전략",VLOOKUP($B16,CODE!$D:$G,CODE!$F$1-2,FALSE))) -> 전략 | B16: =IF(OR($I16="TTL",$I16=""),"",IF(VLOOKUP($P16,CODE!$K:$O,CODE!$O$1,FALSE)="",$I16,$I16&"-"&VLOOKUP($P16,CODE!$K:$O,CODE!$O$1,FALSE))) -> VBL-의류 | C16: =IF($I16="TTL","",I16&"-"&$AG16&"-"&$AI16) -> VBL-아트인드림-01 | D16: =$C16&$Z16 -> VBL-아트인드림-01VBLTLF4001BK | E16: =IF($I16="TTL",0,IF(ISERROR(IF($Z15=$Z16,$E15,$E15+1))=TRUE,1,IF($Z15=$Z16,$E15,$E15+1))) -> 1 | F16: =$C16&$E16 -> VBL-아트인드림-011 | G16: =$F16&"-"&$U16&$Y16&$AE16 -> VBL-아트인드림-011-VBLTLF4001BLACKOXL | H16: =IF(ISERROR(I16&VLOOKUP(P16,CODE!$K:$N,CODE!$N$1,FALSE)&S16)=TRUE,0,I16&VLOOKUP(P16,CODE!$K:$N,CODE!$N$1,FALSE)&S16) -> VBL의류1 | I16: =IF(ISERROR(SEARCH("TTL",$K16))=TRUE,IF($L16="","",VLOOKUP($L16,CODE!$B:$G,CODE!$D$1,FALSE)),"TTL") -> VBL | J16: =MID(W16,1,6) -> 14FW V | L16: VBL | M16: =IF(OR($I16="TTL",$L16=""),"",VLOOKUP($L16,CODE!$B:$D,CODE!$C$1,FALSE)) -> VITAL BLUE | N16: =IF(OR($I16="TTL",$L16=""),"",VLOOKUP($K$2,CODE!$S:$T,CODE!$T$1-1,FALSE)) -> F | O16: 4 | P16: TL | Q16: =IF(OR($I16="TTL",$P16=""),"",VLOOKUP($P16,CODE!$K:$M,CODE!$L$1,FALSE)) -> LONG SLEEVES | R16: U | S16: 1 | T16: =IF(OR($I16="TTL",$S16=""),"",IF($S16<10,"00"&$S16,IF($S16<100,"0"&$S16,$S16))) -> 001 | U16: =IF($I16="TTL","",$L16&$P16&$N16&$O16&$T16) -> VBLTLF4001 | V16: =IF($I16="TTL",SUMIF($C:$C,MID($K16,1,SEARCH("TTL",$K16)-2),$V:$V),IF($EI16="",0,1/COUNTIF($EI:$EI,$EI16))) -> 0.25 | W16: 14FW VB_MTM_01_BK | X16: =IF($Y16="","",VLOOKUP($Y16,CODE!$AE:$AF,CODE!$AF$1-1,FALSE)) -> BK | Y16: BLACK | Z16: =$U16&$X16 -> VBLTLF4001BK | AA16: =VLOOKUP($Z16&$AX16,$EC:$EG,5,FALSE) | AB16: =IF($I16="TTL",SUMIF($C:$C,MID($K16,1,SEARCH("TTL",$K16)-2),$AB:$AB),IF($EJ16="",0,1/COUNTIF($EJ:$EJ,$EJ16))) -> 0.25 | AC16: 0 | AD16: 1 | AE16: OXL | AF16: 250 | AG16: 아트인드림 | AH16: 1 | AI16: =IF($AH16=0,"",IF($AH16<10,"0"&$AH16,$AH16)) -> 01 | AJ16: M | AK16: KR | AL16: =IF($AK16=0,"",IF($AK16="KR",2,1)) -> 2 | AM16: =IF(ISERROR(VLOOKUP($F16,[1]기획현황취합!$A$1:$E$65440,[1]기획현황취합!$B$1,FALSE))=TRUE,0,VLOOKUP($F16,[1]기획현황취합!$A$1:$E$65440,[1]기획현황취합!$B$1,FALSE)) -> 79000 | AN16: =IF(ISERROR(VLOOKUP($F16,[1]기획현황취합!$A$1:$E$65440,[1]기획현황취합!$C$1,FALSE))=TRUE,0,VLOOKUP($F16,[1]기획현황취합!$A$1:$E$65440,[1]기획현황취합!$C$1,FALSE)) -> 41803 | AO16: =IF(ISERROR(($AM16/1.1)/VLOOKUP($AG16,'TARGET MU'!$A:$D,'TARGET MU'!$D$1,FALSE))=TRUE,0,($AM16/1.1)/VLOOKUP($AG16,'TARGET MU'!$A:$D,'TARGET MU'!$D$1,FALSE)) -> 19949.495 | AP16: =IF(OR(AF16=0,AND(AV16=0,AW16=0)),0,IF(AG16="캡보이2",AV16*$AQ$5+AU16,IF(OR(AK16="IN",AK16="BG",AK16="VT",AK16="CB"),$AU16+(($AV16*(1+$AW$4))*(HLOOKUP(VLOOKUP(AG16,'TARGET MU'!$A:$P,'TARGET MU'!$J$1,FALSE),$AO$4:$AR$5,2,FALSE)))+$AW16,$AU16+((($AV16*(1+$AW$4))*(1+HLOOKUP(VLOOKUP($P16,CODE!$K:$P,CODE!$P$1,FALSE),$AS$4:$AV$5,2,FALSE)))*(HLOOKUP(VLOOKUP(AG16,'TARGET MU'!$A:$P,'TARGET MU'!$J$1,FALSE),$AO$4:$AR$5,2,FALSE)))+$AW16))) -> 16500 | AQ16: =AP16-AO16 -> -3449.4949 | AR16: 0 | AS16: 20 | AU16: =SUM(AR16:AT16) -> 20 | AV16: 0 | AW16: 16480 | AX16: =IF(ISERROR(VLOOKUP($F16,[1]기획현황취합!$A$1:$E$65440,[1]기획현황취합!$D$1,FALSE))=TRUE,0,VLOOKUP($F16,[1]기획현황취합!$A$1:$E$65440,[1]기획현황취합!$D$1,FALSE)) -> 41737 | AY16: 0 | AZ16: =IF(ISERROR(VLOOKUP($F16,[1]기획현황취합!$A$1:$E$65440,[1]기획현황취합!$E$1,FALSE))=TRUE,0,VLOOKUP($F16,[1]기획현황취합!$A$1:$E$65440,[1]기획현황취합!$E$1,FALSE)) -> 41823 | BA16: 41864 | BB16: 41885 | BC16: 41901 | BD16: 0 | BE16: 0 | BF16: 0 | BG16: 확정 | BH16: 0 | BI16: =IF($I16="TTL",SUMIF($C:$C,MID($K16,1,SEARCH("TTL",$K16)-2),$BI:$BI),SUMIF(실입고현황!$A:$A,BB16&VLOOKUP($AG16,'TARGET MU'!$A:$D,'TARGET MU'!$B$1,FALSE)&$Z16&" "&$AE16,실입고현황!$C:$C)) -> 234 | BJ16: =IF($I16="TTL",SUMIF($C:$C,MID($K16,1,SEARCH("TTL",$K16)-2),$BJ:$BJ),SUMIF(실입고현황!$A:$A,BC16&VLOOKUP($AG16,'TARGET MU'!$A:$D,'TARGET MU'!$B$1,FALSE)&$Z16&" "&$AE16,실입고현황!$C:$C)) -> 24 | BK16: =IF($I16="TTL",SUMIF($C:$C,MID($K16,1,SEARCH("TTL",$K16)-2),$BK:$BK),SUMIF(실입고현황!$A:$A,BD16&VLOOKUP($AG16,'TARGET MU'!$A:$D,'TARGET MU'!$B$1,FALSE)&$Z16&" "&$AE16,실입고현황!$C:$C)) -> 0 | BL16: =IF($I16="TTL",SUMIF($C:$C,MID($K16,1,SEARCH("TTL",$K16)-2),$BL:$BL),SUMIF(실입고현황!$A:$A,BE16&VLOOKUP($AG16,'TARGET MU'!$A:$D,'TARGET MU'!$B$1,FALSE)&$Z16&" "&$AE16,실입고현황!$C:$C)) -> 0 | BM16: =IF($I16="TTL",SUMIF($C:$C,MID($K16,1,SEARCH("TTL",$K16)-2),$BM:$BM),SUMIF(실입고현황!$A:$A,BF16&VLOOKUP($AG16,'TARGET MU'!$A:$D,'TARGET MU'!$B$1,FALSE)&$Z16&" "&$AE16,실입고현황!$C:$C)) -> 0 | BN16: =IF($I16="TTL",SUMIF($C:$C,MID($K16,1,SEARCH("TTL",$K16)-2),$BN:$BN),IF(($BO16-SUM($BI16,$BJ16,$BK16,BL16,BM16))<$BO16*$BN$6,0,$BO16-SUM($BI16,$BJ16,$BK16,BL16,BM16))) -> 0 | BO16: =IF($I16="TTL",SUMIF($C:$C,MID($K16,1,SEARCH("TTL",$K16)-2),$BO:$BO),$AF16) -> 250 | BP16: =IF($I16="TTL",SUMIF($C:$C,MID($K16,1,SEARCH("TTL",$K16)-2),$BP:$BP),IF($AP16=0,$AO16*$AF16,$AP16*$AF16)) -> 4125000 | BQ16: =IF($I16="TTL",SUMIF($C:$C,MID($K16,1,SEARCH("TTL",$K16)-2),$BQ:$BQ),$AM16*$AF16) -> 19750000 | BR16: =IF(ISERROR($BQ16/($BP16*1.1))=TRUE,0,$BQ16/($BP16*1.1)) -> 4.3526171 | BT16: =IF(ISERROR(Z16&VLOOKUP($AG16,'TARGET MU'!$A:$D,'TARGET MU'!$B$1,FALSE))=TRUE,"",Z16&VLOOKUP($AG16,'TARGET MU'!$A:$D,'TARGET MU'!$B$1,FALSE)) -> VBLTLF4001BK아트인드림 | BU16: =AP16 -> 16500 | BV16: =Z16&AE16&AF16&AM16&AG16&AI16&AK16 -> VBLTLF4001BKOXL25079000아트인드림01KR | BX16: =IF($I16="TTL","",$L16) -> VBL | BY16: =$O16 -> 4 | BZ16: =$AJ16 -> M | CA16: =$P16 -> TL | CB16: =$R16 -> U | CC16: =$AK16 -> KR | CD16: =$W16 -> 14FW VB_MTM_01_BK | CE16: =$U16 -> VBLTLF4001 | CF16: =$T16 -> 001 | CG16: =$W16 -> 14FW VB_MTM_01_BK | CH16: =$X16 -> BK | CI16: =$AD16 -> 1 | CJ16: =$AE16 -> OXL | CK16: =IF($I16="TTL",SUMIF($C:$C,MID($K16,1,SEARCH("TTL",$K16)-2),$BO:$BO),$AF16) -> 250 | CL16: =$AV16 -> 0 | CM16: =$AM16 -> 79000 | CN16: =$AP16-$AU16 -> 16480 | CO16: =$AU16 -> 20 | CP16: =$AL16 -> 2 | CT16: =IF($I16="TTL",$K16,$Z16&$AE16) -> VBLTLF4001BKOXL | CU16: =$M16 -> VITAL BLUE | CV16: =IF($I16="TTL","",IF($CT16="","",$Q16&"_"&$T16&IF(R16="K","_KIDS",""))) -> LONG SLEEVES_001 | CW16: =IF($I16="TTL","",IF($CT16="","",$Y16&"_"&$AE16)) -> BLACK_OXL | CX16: =$L16 -> VBL | CY16: =$T16 -> 001 | CZ16: =IF($I16="TTL",SUMIF($C:$C,MID($K16,1,SEARCH("TTL",$K16)-2),$CZ:$CZ),$AF16) -> 250 | DA16: =$AM16 -> 79000 | DB16: =$Y16 -> BLACK | DC16: =$AE16 -> OXL | DG16: 41778 | DH16: =IF(OR($I16="TTL",$I16=""),"",AZ16-$DH$11) -> 41733 | DI16: 41737 | DJ16: 41737 | DK16: 41829 | DP16: =IF(OR($DN16="없음",$I16="TTL",$I16=""),"",AZ16-$DP$11) -> 41763 | DV16: 41838 | EC16: =IF(OR($Z15&$AX15=$Z16&$AX15,$Z16&$AX16=""),"",$Z16&$AX16) | ED16: =IF(OR(Z15&AE15=Z16&AE16,Z16=""),"",Z16&AE16) -> VBLTLF4001BKOXL | EE16: =IF($ED16="",0,IF(COUNTIF(ED$12:ED15,ED16)=0,0,COUNTIF(ED$12:ED15,ED16))) -> 0 | EF16: =IF(OR($AJ16="B",$ED16="",MID($U16,8,1)=$EF$9,MID($U16,8,1)=$EF$10),0,1) -> 0 | EG16: =IF(EE16+EF16=0,"","R"&(EE16+EF16)) | EI16: =IF($ED16="","",IF($EE16=0,U16,"")) -> VBLTLF4001 | EJ16: =IF($ED16="","",IF($EE16=0,Z16,"")) -> VBLTLF4001BK
A17: =IF(OR($I17="TTL",$I17=""),"",IF(ISERROR(VLOOKUP($B17,CODE!$D:$G,CODE!$F$1-2,FALSE))=TRUE,"전략",VLOOKUP($B17,CODE!$D:$G,CODE!$F$1-2,FALSE))) -> 전략 | B17: =IF(OR($I17="TTL",$I17=""),"",IF(VLOOKUP($P17,CODE!$K:$O,CODE!$O$1,FALSE)="",$I17,$I17&"-"&VLOOKUP($P17,CODE!$K:$O,CODE!$O$1,FALSE))) -> VBL-의류 | C17: =IF($I17="TTL","",I17&"-"&$AG17&"-"&$AI17) -> VBL-아트인드림-01 | D17: =$C17&$Z17 -> VBL-아트인드림-01VBLTLF4002GY | E17: =IF($I17="TTL",0,IF(ISERROR(IF($Z16=$Z17,$E16,$E16+1))=TRUE,1,IF($Z16=$Z17,$E16,$E16+1))) -> 2 | F17: =$C17&$E17 -> VBL-아트인드림-012 | G17: =$F17&"-"&$U17&$Y17&$AE17 -> VBL-아트인드림-012-VBLTLF4002GREYOSS | H17: =IF(ISERROR(I17&VLOOKUP(P17,CODE!$K:$N,CODE!$N$1,FALSE)&S17)=TRUE,0,I17&VLOOKUP(P17,CODE!$K:$N,CODE!$N$1,FALSE)&S17) -> VBL의류2 | I17: =IF(ISERROR(SEARCH("TTL",$K17))=TRUE,IF($L17="","",VLOOKUP($L17,CODE!$B:$G,CODE!$D$1,FALSE)),"TTL") -> VBL | J17: =MID(W17,1,6) -> 14FW V | L17: VBL | M17: =IF(OR($I17="TTL",$L17=""),"",VLOOKUP($L17,CODE!$B:$D,CODE!$C$1,FALSE)) -> VITAL BLUE | N17: =IF(OR($I17="TTL",$L17=""),"",VLOOKUP($K$2,CODE!$S:$T,CODE!$T$1-1,FALSE)) -> F | O17: 4 | P17: TL | Q17: =IF(OR($I17="TTL",$P17=""),"",VLOOKUP($P17,CODE!$K:$M,CODE!$L$1,FALSE)) -> LONG SLEEVES | R17: U | S17: 2 | T17: =IF(OR($I17="TTL",$S17=""),"",IF($S17<10,"00"&$S17,IF($S17<100,"0"&$S17,$S17))) -> 002 | U17: =IF($I17="TTL","",$L17&$P17&$N17&$O17&$T17) -> VBLTLF4002 | V17: =IF($I17="TTL",SUMIF($C:$C,MID($K17,1,SEARCH("TTL",$K17)-2),$V:$V),IF($EI17="",0,1/COUNTIF($EI:$EI,$EI17))) -> 0.25 | W17: 14FW VB_MTM_02_GY | X17: =IF($Y17="","",VLOOKUP($Y17,CODE!$AE:$AF,CODE!$AF$1-1,FALSE)) -> GY | Y17: GREY | Z17: =$U17&$X17 -> VBLTLF4002GY | AA17: =VLOOKUP($Z17&$AX17,$EC:$EG,5,FALSE) | AB17: =IF($I17="TTL",SUMIF($C:$C,MID($K17,1,SEARCH("TTL",$K17)-2),$AB:$AB),IF($EJ17="",0,1/COUNTIF($EJ:$EJ,$EJ17))) -> 0.25 | AC17: 0 | AD17: 1 | AE17: OSS | AF17: 250 | AG17: 아트인드림 | AH17: 1 | AI17: =IF($AH17=0,"",IF($AH17<10,"0"&$AH17,$AH17)) -> 01 | AJ17: M | AK17: KR | AL17: =IF($AK17=0,"",IF($AK17="KR",2,1)) -> 2 | AM17: =IF(ISERROR(VLOOKUP($F17,[1]기획현황취합!$A$1:$E$65440,[1]기획현황취합!$B$1,FALSE))=TRUE,0,VLOOKUP($F17,[1]기획현황취합!$A$1:$E$65440,[1]기획현황취합!$B$1,FALSE)) -> 79000 | AN17: =IF(ISERROR(VLOOKUP($F17,[1]기획현황취합!$A$1:$E$65440,[1]기획현황취합!$C$1,FALSE))=TRUE,0,VLOOKUP($F17,[1]기획현황취합!$A$1:$E$65440,[1]기획현황취합!$C$1,FALSE)) -> 41803 | AO17: =IF(ISERROR(($AM17/1.1)/VLOOKUP($AG17,'TARGET MU'!$A:$D,'TARGET MU'!$D$1,FALSE))=TRUE,0,($AM17/1.1)/VLOOKUP($AG17,'TARGET MU'!$A:$D,'TARGET MU'!$D$1,FALSE)) -> 19949.495 | AP17: =IF(OR(AF17=0,AND(AV17=0,AW17=0)),0,IF(AG17="캡보이2",AV17*$AQ$5+AU17,IF(OR(AK17="IN",AK17="BG",AK17="VT",AK17="CB"),$AU17+(($AV17*(1+$AW$4))*(HLOOKUP(VLOOKUP(AG17,'TARGET MU'!$A:$P,'TARGET MU'!$J$1,FALSE),$AO$4:$AR$5,2,FALSE)))+$AW17,$AU17+((($AV17*(1+$AW$4))*(1+HLOOKUP(VLOOKUP($P17,CODE!$K:$P,CODE!$P$1,FALSE),$AS$4:$AV$5,2,FALSE)))*(HLOOKUP(VLOOKUP(AG17,'TARGET MU'!$A:$P,'TARGET MU'!$J$1,FALSE),$AO$4:$AR$5,2,FALSE)))+$AW17))) -> 16950 | AQ17: =AP17-AO17 -> -2999.4949 | AR17: 0 | AS17: 20 | AU17: =SUM(AR17:AT17) -> 20 | AV17: 0 | AW17: 16930 | AX17: =IF(ISERROR(VLOOKUP($F17,[1]기획현황취합!$A$1:$E$65440,[1]기획현황취합!$D$1,FALSE))=TRUE,0,VLOOKUP($F17,[1]기획현황취합!$A$1:$E$65440,[1]기획현황취합!$D$1,FALSE)) -> 41737 | AY17: 0 | AZ17: =IF(ISERROR(VLOOKUP($F17,[1]기획현황취합!$A$1:$E$65440,[1]기획현황취합!$E$1,FALSE))=TRUE,0,VLOOKUP($F17,[1]기획현황취합!$A$1:$E$65440,[1]기획현황취합!$E$1,FALSE)) -> 41823 | BA17: 41864 | BB17: 41885 | BC17: 41901 | BD17: 0 | BE17: 0 | BF17: 0 | BG17: 확정 | BH17: 0 | BI17: =IF($I17="TTL",SUMIF($C:$C,MID($K17,1,SEARCH("TTL",$K17)-2),$BI:$BI),SUMIF(실입고현황!$A:$A,BB17&VLOOKUP($AG17,'TARGET MU'!$A:$D,'TARGET MU'!$B$1,FALSE)&$Z17&" "&$AE17,실입고현황!$C:$C)) -> 243 | BJ17: =IF($I17="TTL",SUMIF($C:$C,MID($K17,1,SEARCH("TTL",$K17)-2),$BJ:$BJ),SUMIF(실입고현황!$A:$A,BC17&VLOOKUP($AG17,'TARGET MU'!$A:$D,'TARGET MU'!$B$1,FALSE)&$Z17&" "&$AE17,실입고현황!$C:$C)) -> 0 | BK17: =IF($I17="TTL",SUMIF($C:$C,MID($K17,1,SEARCH("TTL",$K17)-2),$BK:$BK),SUMIF(실입고현황!$A:$A,BD17&VLOOKUP($AG17,'TARGET MU'!$A:$D,'TARGET MU'!$B$1,FALSE)&$Z17&" "&$AE17,실입고현황!$C:$C)) -> 0 | BL17: =IF($I17="TTL",SUMIF($C:$C,MID($K17,1,SEARCH("TTL",$K17)-2),$BL:$BL),SUMIF(실입고현황!$A:$A,BE17&VLOOKUP($AG17,'TARGET MU'!$A:$D,'TARGET MU'!$B$1,FALSE)&$Z17&" "&$AE17,실입고현황!$C:$C)) -> 0 | BM17: =IF($I17="TTL",SUMIF($C:$C,MID($K17,1,SEARCH("TTL",$K17)-2),$BM:$BM),SUMIF(실입고현황!$A:$A,BF17&VLOOKUP($AG17,'TARGET MU'!$A:$D,'TARGET MU'!$B$1,FALSE)&$Z17&" "&$AE17,실입고현황!$C:$C)) -> 0 | BN17: =IF($I17="TTL",SUMIF($C:$C,MID($K17,1,SEARCH("TTL",$K17)-2),$BN:$BN),IF(($BO17-SUM($BI17,$BJ17,$BK17,BL17,BM17))<$BO17*$BN$6,0,$BO17-SUM($BI17,$BJ17,$BK17,BL17,BM17))) -> 0 | BO17: =IF($I17="TTL",SUMIF($C:$C,MID($K17,1,SEARCH("TTL",$K17)-2),$BO:$BO),$AF17) -> 250 | BP17: =IF($I17="TTL",SUMIF($C:$C,MID($K17,1,SEARCH("TTL",$K17)-2),$BP:$BP),IF($AP17=0,$AO17*$AF17,$AP17*$AF17)) -> 4237500 | BQ17: =IF($I17="TTL",SUMIF($C:$C,MID($K17,1,SEARCH("TTL",$K17)-2),$BQ:$BQ),$AM17*$AF17) -> 19750000 | BR17: =IF(ISERROR($BQ17/($BP17*1.1))=TRUE,0,$BQ17/($BP17*1.1)) -> 4.2370609 | BT17: =IF(ISERROR(Z17&VLOOKUP($AG17,'TARGET MU'!$A:$D,'TARGET MU'!$B$1,FALSE))=TRUE,"",Z17&VLOOKUP($AG17,'TARGET MU'!$A:$D,'TARGET MU'!$B$1,FALSE)) -> VBLTLF4002GY아트인드림 | BU17: =AP17 -> 16950 | BV17: =Z17&AE17&AF17&AM17&AG17&AI17&AK17 -> VBLTLF4002GYOSS25079000아트인드림01KR | BX17: =IF($I17="TTL","",$L17) -> VBL | BY17: =$O17 -> 4 | BZ17: =$AJ17 -> M | CA17: =$P17 -> TL | CB17: =$R17 -> U | CC17: =$AK17 -> KR | CD17: =$W17 -> 14FW VB_MTM_02_GY | CE17: =$U17 -> VBLTLF4002 | CF17: =$T17 -> 002 | CG17: =$W17 -> 14FW VB_MTM_02_GY | CH17: =$X17 -> GY | CI17: =$AD17 -> 1 | CJ17: =$AE17 -> OSS | CK17: =IF($I17="TTL",SUMIF($C:$C,MID($K17,1,SEARCH("TTL",$K17)-2),$BO:$BO),$AF17) -> 250 | CL17: =$AV17 -> 0 | CM17: =$AM17 -> 79000 | CN17: =$AP17-$AU17 -> 16930 | CO17: =$AU17 -> 20 | CP17: =$AL17 -> 2 | CT17: =IF($I17="TTL",$K17,$Z17&$AE17) -> VBLTLF4002GYOSS | CU17: =$M17 -> VITAL BLUE | CV17: =IF($I17="TTL","",IF($CT17="","",$Q17&"_"&$T17&IF(R17="K","_KIDS",""))) -> LONG SLEEVES_002 | CW17: =IF($I17="TTL","",IF($CT17="","",$Y17&"_"&$AE17)) -> GREY_OSS | CX17: =$L17 -> VBL | CY17: =$T17 -> 002 | CZ17: =IF($I17="TTL",SUMIF($C:$C,MID($K17,1,SEARCH("TTL",$K17)-2),$CZ:$CZ),$AF17) -> 250 | DA17: =$AM17 -> 79000 | DB17: =$Y17 -> GREY | DC17: =$AE17 -> OSS | DG17: 41778 | DH17: =IF(OR($I17="TTL",$I17=""),"",AZ17-$DH$11) -> 41733 | DI17: 41737 | DJ17: 41737 | DK17: 41829 | DP17: =IF(OR($DN17="없음",$I17="TTL",$I17=""),"",AZ17-$DP$11) -> 41763 | DV17: 41838 | EC17: =IF(OR($Z16&$AX16=$Z17&$AX16,$Z17&$AX17=""),"",$Z17&$AX17) -> VBLTLF4002GY41737 | ED17: =IF(OR(Z16&AE16=Z17&AE17,Z17=""),"",Z17&AE17) -> VBLTLF4002GYOSS | EE17: =IF($ED17="",0,IF(COUNTIF(ED$12:ED16,ED17)=0,0,COUNTIF(ED$12:ED16,ED17))) -> 0 | EF17: =IF(OR($AJ17="B",$ED17="",MID($U17,8,1)=$EF$9,MID($U17,8,1)=$EF$10),0,1) -> 0 | EG17: =IF(EE17+EF17=0,"","R"&(EE17+EF17)) | EI17: =IF($ED17="","",IF($EE17=0,U17,"")) -> VBLTLF4002 | EJ17: =IF($ED17="","",IF($EE17=0,Z17,"")) -> VBLTLF4002GY
A18: =IF(OR($I18="TTL",$I18=""),"",IF(ISERROR(VLOOKUP($B18,CODE!$D:$G,CODE!$F$1-2,FALSE))=TRUE,"전략",VLOOKUP($B18,CODE!$D:$G,CODE!$F$1-2,FALSE))) -> 전략 | B18: =IF(OR($I18="TTL",$I18=""),"",IF(VLOOKUP($P18,CODE!$K:$O,CODE!$O$1,FALSE)="",$I18,$I18&"-"&VLOOKUP($P18,CODE!$K:$O,CODE!$O$1,FALSE))) -> VBL-의류 | C18: =IF($I18="TTL","",I18&"-"&$AG18&"-"&$AI18) -> VBL-아트인드림-01 | D18: =$C18&$Z18 -> VBL-아트인드림-01VBLTLF4002GY | E18: =IF($I18="TTL",0,IF(ISERROR(IF($Z17=$Z18,$E17,$E17+1))=TRUE,1,IF($Z17=$Z18,$E17,$E17+1))) -> 2 | F18: =$C18&$E18 -> VBL-아트인드림-012 | G18: =$F18&"-"&$U18&$Y18&$AE18 -> VBL-아트인드림-012-VBLTLF4002GREYOMM | H18: =IF(ISERROR(I18&VLOOKUP(P18,CODE!$K:$N,CODE!$N$1,FALSE)&S18)=TRUE,0,I18&VLOOKUP(P18,CODE!$K:$N,CODE!$N$1,FALSE)&S18) -> VBL의류2 | I18: =IF(ISERROR(SEARCH("TTL",$K18))=TRUE,IF($L18="","",VLOOKUP($L18,CODE!$B:$G,CODE!$D$1,FALSE)),"TTL") -> VBL | J18: =MID(W18,1,6) -> 14FW V | L18: VBL | M18: =IF(OR($I18="TTL",$L18=""),"",VLOOKUP($L18,CODE!$B:$D,CODE!$C$1,FALSE)) -> VITAL BLUE | N18: =IF(OR($I18="TTL",$L18=""),"",VLOOKUP($K$2,CODE!$S:$T,CODE!$T$1-1,FALSE)) -> F | O18: 4 | P18: TL | Q18: =IF(OR($I18="TTL",$P18=""),"",VLOOKUP($P18,CODE!$K:$M,CODE!$L$1,FALSE)) -> LONG SLEEVES | R18: U | S18: 2 | T18: =IF(OR($I18="TTL",$S18=""),"",IF($S18<10,"00"&$S18,IF($S18<100,"0"&$S18,$S18))) -> 002 | U18: =IF($I18="TTL","",$L18&$P18&$N18&$O18&$T18) -> VBLTLF4002 | V18: =IF($I18="TTL",SUMIF($C:$C,MID($K18,1,SEARCH("TTL",$K18)-2),$V:$V),IF($EI18="",0,1/COUNTIF($EI:$EI,$EI18))) -> 0.25 | W18: 14FW VB_MTM_02_GY | X18: =IF($Y18="","",VLOOKUP($Y18,CODE!$AE:$AF,CODE!$AF$1-1,FALSE)) -> GY | Y18: GREY | Z18: =$U18&$X18 -> VBLTLF4002GY | AA18: =VLOOKUP($Z18&$AX18,$EC:$EG,5,FALSE) | AB18: =IF($I18="TTL",SUMIF($C:$C,MID($K18,1,SEARCH("TTL",$K18)-2),$AB:$AB),IF($EJ18="",0,1/COUNTIF($EJ:$EJ,$EJ18))) -> 0.25 | AC18: 0 | AD18: 1 | AE18: OMM | AF18: 350 | AG18: 아트인드림 | AH18: 1 | AI18: =IF($AH18=0,"",IF($AH18<10,"0"&$AH18,$AH18)) -> 01 | AJ18: M | AK18: KR | AL18: =IF($AK18=0,"",IF($AK18="KR",2,1)) -> 2 | AM18: =IF(ISERROR(VLOOKUP($F18,[1]기획현황취합!$A$1:$E$65440,[1]기획현황취합!$B$1,FALSE))=TRUE,0,VLOOKUP($F18,[1]기획현황취합!$A$1:$E$65440,[1]기획현황취합!$B$1,FALSE)) -> 79000 | AN18: =IF(ISERROR(VLOOKUP($F18,[1]기획현황취합!$A$1:$E$65440,[1]기획현황취합!$C$1,FALSE))=TRUE,0,VLOOKUP($F18,[1]기획현황취합!$A$1:$E$65440,[1]기획현황취합!$C$1,FALSE)) -> 41803 | AO18: =IF(ISERROR(($AM18/1.1)/VLOOKUP($AG18,'TARGET MU'!$A:$D,'TARGET MU'!$D$1,FALSE))=TRUE,0,($AM18/1.1)/VLOOKUP($AG18,'TARGET MU'!$A:$D,'TARGET MU'!$D$1,FALSE)) -> 19949.495 | AP18: =IF(OR(AF18=0,AND(AV18=0,AW18=0)),0,IF(AG18="캡보이2",AV18*$AQ$5+AU18,IF(OR(AK18="IN",AK18="BG",AK18="VT",AK18="CB"),$AU18+(($AV18*(1+$AW$4))*(HLOOKUP(VLOOKUP(AG18,'TARGET MU'!$A:$P,'TARGET MU'!$J$1,FALSE),$AO$4:$AR$5,2,FALSE)))+$AW18,$AU18+((($AV18*(1+$AW$4))*(1+HLOOKUP(VLOOKUP($P18,CODE!$K:$P,CODE!$P$1,FALSE),$AS$4:$AV$5,2,FALSE)))*(HLOOKUP(VLOOKUP(AG18,'TARGET MU'!$A:$P,'TARGET MU'!$J$1,FALSE),$AO$4:$AR$5,2,FALSE)))+$AW18))) -> 16950 | AQ18: =AP18-AO18 -> -2999.4949 | AR18: 0 | AS18: 20 | AU18: =SUM(AR18:AT18) -> 20 | AV18: 0 | AW18: 16930 | AX18: =IF(ISERROR(VLOOKUP($F18,[1]기획현황취합!$A$1:$E$65440,[1]기획현황취합!$D$1,FALSE))=TRUE,0,VLOOKUP($F18,[1]기획현황취합!$A$1:$E$65440,[1]기획현황취합!$D$1,FALSE)) -> 41737 | AY18: 0 | AZ18: =IF(ISERROR(VLOOKUP($F18,[1]기획현황취합!$A$1:$E$65440,[1]기획현황취합!$E$1,FALSE))=TRUE,0,VLOOKUP($F18,[1]기획현황취합!$A$1:$E$65440,[1]기획현황취합!$E$1,FALSE)) -> 41823 | BA18: 41864 | BB18: 41885 | BC18: 41901 | BD18: 0 | BE18: 0 | BF18: 0 | BG18: 확정 | BH18: 0 | BI18: =IF($I18="TTL",SUMIF($C:$C,MID($K18,1,SEARCH("TTL",$K18)-2),$BI:$BI),SUMIF(실입고현황!$A:$A,BB18&VLOOKUP($AG18,'TARGET MU'!$A:$D,'TARGET MU'!$B$1,FALSE)&$Z18&" "&$AE18,실입고현황!$C:$C)) -> 346 | BJ18: =IF($I18="TTL",SUMIF($C:$C,MID($K18,1,SEARCH("TTL",$K18)-2),$BJ:$BJ),SUMIF(실입고현황!$A:$A,BC18&VLOOKUP($AG18,'TARGET MU'!$A:$D,'TARGET MU'!$B$1,FALSE)&$Z18&" "&$AE18,실입고현황!$C:$C)) -> 26 | BK18: =IF($I18="TTL",SUMIF($C:$C,MID($K18,1,SEARCH("TTL",$K18)-2),$BK:$BK),SUMIF(실입고현황!$A:$A,BD18&VLOOKUP($AG18,'TARGET MU'!$A:$D,'TARGET MU'!$B$1,FALSE)&$Z18&" "&$AE18,실입고현황!$C:$C)) -> 0 | BL18: =IF($I18="TTL",SUMIF($C:$C,MID($K18,1,SEARCH("TTL",$K18)-2),$BL:$BL),SUMIF(실입고현황!$A:$A,BE18&VLOOKUP($AG18,'TARGET MU'!$A:$D,'TARGET MU'!$B$1,FALSE)&$Z18&" "&$AE18,실입고현황!$C:$C)) -> 0 | BM18: =IF($I18="TTL",SUMIF($C:$C,MID($K18,1,SEARCH("TTL",$K18)-2),$BM:$BM),SUMIF(실입고현황!$A:$A,BF18&VLOOKUP($AG18,'TARGET MU'!$A:$D,'TARGET MU'!$B$1,FALSE)&$Z18&" "&$AE18,실입고현황!$C:$C)) -> 0 | BN18: =IF($I18="TTL",SUMIF($C:$C,MID($K18,1,SEARCH("TTL",$K18)-2),$BN:$BN),IF(($BO18-SUM($BI18,$BJ18,$BK18,BL18,BM18))<$BO18*$BN$6,0,$BO18-SUM($BI18,$BJ18,$BK18,BL18,BM18))) -> 0 | BO18: =IF($I18="TTL",SUMIF($C:$C,MID($K18,1,SEARCH("TTL",$K18)-2),$BO:$BO),$AF18) -> 350 | BP18: =IF($I18="TTL",SUMIF($C:$C,MID($K18,1,SEARCH("TTL",$K18)-2),$BP:$BP),IF($AP18=0,$AO18*$AF18,$AP18*$AF18)) -> 5932500 | BQ18: =IF($I18="TTL",SUMIF($C:$C,MID($K18,1,SEARCH("TTL",$K18)-2),$BQ:$BQ),$AM18*$AF18) -> 27650000 | BR18: =IF(ISERROR($BQ18/($BP18*1.1))=TRUE,0,$BQ18/($BP18*1.1)) -> 4.2370609 | BT18: =IF(ISERROR(Z18&VLOOKUP($AG18,'TARGET MU'!$A:$D,'TARGET MU'!$B$1,FALSE))=TRUE,"",Z18&VLOOKUP($AG18,'TARGET MU'!$A:$D,'TARGET MU'!$B$1,FALSE)) -> VBLTLF4002GY아트인드림 | BU18: =AP18 -> 16950 | BV18: =Z18&AE18&AF18&AM18&AG18&AI18&AK18 -> VBLTLF4002GYOMM35079000아트인드림01KR | BX18: =IF($I18="TTL","",$L18) -> VBL | BY18: =$O18 -> 4 | BZ18: =$AJ18 -> M | CA18: =$P18 -> TL | CB18: =$R18 -> U | CC18: =$AK18 -> KR | CD18: =$W18 -> 14FW VB_MTM_02_GY | CE18: =$U18 -> VBLTLF4002 | CF18: =$T18 -> 002 | CG18: =$W18 -> 14FW VB_MTM_02_GY | CH18: =$X18 -> GY | CI18: =$AD18 -> 1 | CJ18: =$AE18 -> OMM | CK18: =IF($I18="TTL",SUMIF($C:$C,MID($K18,1,SEARCH("TTL",$K18)-2),$BO:$BO),$AF18) -> 350 | CL18: =$AV18 -> 0 | CM18: =$AM18 -> 79000 | CN18: =$AP18-$AU18 -> 16930 | CO18: =$AU18 -> 20 | CP18: =$AL18 -> 2 | CT18: =IF($I18="TTL",$K18,$Z18&$AE18) -> VBLTLF4002GYOMM | CU18: =$M18 -> VITAL BLUE | CV18: =IF($I18="TTL","",IF($CT18="","",$Q18&"_"&$T18&IF(R18="K","_KIDS",""))) -> LONG SLEEVES_002 | CW18: =IF($I18="TTL","",IF($CT18="","",$Y18&"_"&$AE18)) -> GREY_OMM | CX18: =$L18 -> VBL | CY18: =$T18 -> 002 | CZ18: =IF($I18="TTL",SUMIF($C:$C,MID($K18,1,SEARCH("TTL",$K18)-2),$CZ:$CZ),$AF18) -> 350 | DA18: =$AM18 -> 79000 | DB18: =$Y18 -> GREY | DC18: =$AE18 -> OMM | DG18: 41778 | DH18: =IF(OR($I18="TTL",$I18=""),"",AZ18-$DH$11) -> 41733 | DI18: 41737 | DJ18: 41737 | DK18: 41829 | DP18: =IF(OR($DN18="없음",$I18="TTL",$I18=""),"",AZ18-$DP$11) -> 41763 | DV18: 41838 | EC18: =IF(OR($Z17&$AX17=$Z18&$AX17,$Z18&$AX18=""),"",$Z18&$AX18) | ED18: =IF(OR(Z17&AE17=Z18&AE18,Z18=""),"",Z18&AE18) -> VBLTLF4002GYOMM | EE18: =IF($ED18="",0,IF(COUNTIF(ED$12:ED17,ED18)=0,0,COUNTIF(ED$12:ED17,ED18))) -> 0 | EF18: =IF(OR($AJ18="B",$ED18="",MID($U18,8,1)=$EF$9,MID($U18,8,1)=$EF$10),0,1) -> 0 | EG18: =IF(EE18+EF18=0,"","R"&(EE18+EF18)) | EI18: =IF($ED18="","",IF($EE18=0,U18,"")) -> VBLTLF4002 | EJ18: =IF($ED18="","",IF($EE18=0,Z18,"")) -> VBLTLF4002GY
