Workbook

Sheet 브랜드품목별
B1: 14FW SAMPLE LIST (HATS ON) | J1: 14FW SAMPLE LIST (HATS ON KIDS)
AA2: 러닝(R)/신규(N) | AB2: N
E3: ADULT | M3: CHILD | O3: INFANT | R3: 41663 | AA3: *실발주샘플수=중복 발주 및 입고 스타일은 1ST로 계산
AD4: 데이터
B5: 브랜드/품목 | C5: 계획 | E5: 발주 | F5: 입고 | G5: 발주계 | H5: 입고계 | J5: 브랜드/품목 | K5: 계획 | M5: 발주 | N5: 입고 | O5: 발주 | P5: 입고 | Q5: 발주계 | R5: 입고계 | AA5: 연령구분 | AB5: 브랜드/품목2 | AC5: 품목 | AD5: 실발주샘플수 | AE5: 실입고샘플수 | AF5: 미입고샘플수
C6: 품번수 | D6: 색상수 | E6: 품번수 | F6: 품번수 | G6: 품번수 | H6: 품번수 | K6: 품번수 | L6: 색상수 | M6: 품번수 | N6: 품번수 | O6: 품번수 | P6: 품번수 | Q6: 품번수 | R6: 품번수 | X6: =Y6&Z6 -> ADULTELS-의류 | Y6: =IF(AA6="",Y5,AA6) -> ADULT | Z6: =IF(AB6="",Z5,AB6) -> ELS-의류 | AA6: ADULT | AB6: ELS-의류 | AC6: HP | AD6: 3 | AE6: 3 | AF6: 0
B7: ELS | C7: =IF(ISERROR(VLOOKUP(B7,[1]기획현황요약!$B$6:$T$36,19,FALSE))=TRUE,0,VLOOKUP(B7,[1]기획현황요약!$B$6:$T$36,19,FALSE)) -> 69.634333 | E7: =SUMIF($X:$X,E$3&B7,$AD:$AD) -> 64 | F7: =SUMIF($X:$X,E$3&B7,$AE:$AE) -> 54 | G7: =E7 -> 64 | H7: =F7 -> 54 | I7: =MID(J7,1,2)&"K"&MID(J7,4,10) -> ELK | J7: ELS | K7: =IF(ISERROR(VLOOKUP(I7,[2]기획현황요약!$B$6:$T$30,19,FALSE))=TRUE,0,VLOOKUP(I7,[2]기획현황요약!$B$6:$T$30,19,FALSE)) -> 75.49716 | M7: =SUMIF($X:$X,M$3&J7,$AD:$AD) -> 16 | N7: =SUMIF($X:$X,M$3&J7,$AE:$AE) -> 8 | O7: =SUMIF($X:$X,O$3&J7,$AD:$AD) -> 0 | P7: =SUMIF($X:$X,O$3&J7,$AE:$AE) -> 0 | Q7: =M7+O7 -> 16 | R7: =N7+P7 -> 8 | T7: =C7+K7 -> 145.13149 | U7: =G7+Q7 -> 80 | V7: =IF(ISERROR(U7/T7)=TRUE,0,U7/T7) -> 0.55122426 | X7: =Y7&Z7 -> ADULTELS-의류 | Y7: =IF(AA7="",Y6,AA7) -> ADULT | Z7: =IF(AB7="",Z6,AB7) -> ELS-의류 | AC7: JP | AD7: 4 | AE7: 4 | AF7: 0
B8: ELS-의류 | C8: =IF(ISERROR(VLOOKUP(B8,[1]기획현황요약!$B$6:$T$36,19,FALSE))=TRUE,0,VLOOKUP(B8,[1]기획현황요약!$B$6:$T$36,19,FALSE)) -> 35.965649 | E8: =SUMIF($X:$X,E$3&B8,$AD:$AD) -> 28 | F8: =SUMIF($X:$X,E$3&B8,$AE:$AE) -> 25 | G8: =E8 -> 28 | H8: =F8 -> 25 | I8: =MID(J8,1,2)&"K"&MID(J8,4,10) -> ELK-의류 | J8: ELS-의류 | K8: =IF(ISERROR(VLOOKUP(I8,[2]기획현황요약!$B$6:$T$30,19,FALSE))=TRUE,0,VLOOKUP(I8,[2]기획현황요약!$B$6:$T$30,19,FALSE)) -> 47.966794 | M8: =SUMIF($X:$X,M$3&J8,$AD:$AD) -> 45 | N8: =SUMIF($X:$X,M$3&J8,$AE:$AE) -> 42 | O8: =SUMIF($X:$X,O$3&J8,$AD:$AD) -> 0 | P8: =SUMIF($X:$X,O$3&J8,$AE:$AE) -> 0 | Q8: =M8+O8 -> 45 | R8: =N8+P8 -> 42 | T8: =C8+K8 -> 83.932443 | U8: =G8+Q8 -> 73 | V8: =IF(ISERROR(U8/T8)=TRUE,0,U8/T8) -> 0.86974711 | X8: =Y8&Z8 -> ADULTELS-의류 | Y8: =IF(AA8="",Y7,AA8) -> ADULT | Z8: =IF(AB8="",Z7,AB8) -> ELS-의류 | AC8: TH | AD8: 5 | AE8: 5 | AF8: 0
B9: ELS-가방 | C9: =IF(ISERROR(VLOOKUP(B9,[1]기획현황요약!$B$6:$T$36,19,FALSE))=TRUE,0,VLOOKUP(B9,[1]기획현황요약!$B$6:$T$36,19,FALSE)) -> 20.160675 | E9: =SUMIF($X:$X,E$3&B9,$AD:$AD) -> 6 | F9: =SUMIF($X:$X,E$3&B9,$AE:$AE) -> 6 | G9: =E9 -> 6 | H9: =F9 -> 6 | I9: =MID(J9,1,2)&"K"&MID(J9,4,10) -> ELK-가방 | J9: ELS-가방 | K9: =IF(ISERROR(VLOOKUP(I9,[2]기획현황요약!$B$6:$T$30,19,FALSE))=TRUE,0,VLOOKUP(I9,[2]기획현황요약!$B$6:$T$30,19,FALSE)) -> 7.4873217 | M9: =SUMIF($X:$X,M$3&J9,$AD:$AD) -> 2 | N9: =SUMIF($X:$X,M$3&J9,$AE:$AE) -> 2 | O9: =SUMIF($X:$X,O$3&J9,$AD:$AD) -> 0 | P9: =SUMIF($X:$X,O$3&J9,$AE:$AE) -> 0 | Q9: =M9+O9 -> 2 | R9: =N9+P9 -> 2 | T9: =C9+K9 -> 27.647997 | U9: =G9+Q9 -> 8 | V9: =IF(ISERROR(U9/T9)=TRUE,0,U9/T9) -> 0.28935188 | X9: =Y9&Z9 -> ADULTELS-의류 | Y9: =IF(AA9="",Y8,AA9) -> ADULT | Z9: =IF(AB9="",Z8,AB9) -> ELS-의류 | AC9: TL | AD9: 13 | AE9: 10 | AF9: 3
B10: ELS-ACC | C10: =IF(ISERROR(VLOOKUP(B10,[1]기획현황요약!$B$6:$T$36,19,FALSE))=TRUE,0,VLOOKUP(B10,[1]기획현황요약!$B$6:$T$36,19,FALSE)) -> 4.4121754 | E10: =SUMIF($X:$X,E$3&B10,$AD:$AD) -> 2 | F10: =SUMIF($X:$X,E$3&B10,$AE:$AE) -> 2 | G10: =E10 -> 2 | H10: =F10 -> 2 | I10: =MID(J10,1,2)&"K"&MID(J10,4,10) -> ELK-ACC | J10: ELS-ACC | K10: =IF(ISERROR(VLOOKUP(I10,[2]기획현황요약!$B$6:$T$30,19,FALSE))=TRUE,0,VLOOKUP(I10,[2]기획현황요약!$B$6:$T$30,19,FALSE)) -> 5.2267265 | M10: =SUMIF($X:$X,M$3&J10,$AD:$AD) -> 2 | N10: =SUMIF($X:$X,M$3&J10,$AE:$AE) -> 2 | O10: =SUMIF($X:$X,O$3&J10,$AD:$AD) -> 0 | P10: =SUMIF($X:$X,O$3&J10,$AE:$AE) -> 0 | Q10: =M10+O10 -> 2 | R10: =N10+P10 -> 2 | T10: =C10+K10 -> 9.6389019 | U10: =G10+Q10 -> 4 | V10: =IF(ISERROR(U10/T10)=TRUE,0,U10/T10) -> 0.41498503 | X10: =Y10&Z10 -> ADULTELS-의류 | Y10: =IF(AA10="",Y9,AA10) -> ADULT | Z10: =IF(AB10="",Z9,AB10) -> ELS-의류 | AC10: PT | AD10: 3 | AE10: 3 | AF10: 0
B11: SMB | C11: =IF(ISERROR(VLOOKUP(B11,[1]기획현황요약!$B$6:$T$36,19,FALSE))=TRUE,0,VLOOKUP(B11,[1]기획현황요약!$B$6:$T$36,19,FALSE)) -> 45.567338 | E11: =SUMIF($X:$X,E$3&B11,$AD:$AD) -> 0 | F11: =SUMIF($X:$X,E$3&B11,$AE:$AE) -> 0 | G11: =E11 -> 0 | H11: =F11 -> 0 | I11: =MID(J11,1,2)&"K"&MID(J11,4,10) -> SMK | J11: SMB | K11: =IF(ISERROR(VLOOKUP(I11,[2]기획현황요약!$B$6:$T$30,19,FALSE))=TRUE,0,VLOOKUP(I11,[2]기획현황요약!$B$6:$T$30,19,FALSE)) -> 64.34207 | M11: =SUMIF($X:$X,M$3&J11,$AD:$AD) -> 0 | N11: =SUMIF($X:$X,M$3&J11,$AE:$AE) -> 0 | O11: =SUMIF($X:$X,O$3&J11,$AD:$AD) -> 0 | P11: =SUMIF($X:$X,O$3&J11,$AE:$AE) -> 0 | Q11: =M11+O11 -> 0 | R11: =N11+P11 -> 0 | T11: =C11+K11 -> 109.90941 | U11: =G11+Q11 -> 0 | V11: =IF(ISERROR(U11/T11)=TRUE,0,U11/T11) -> 0 | X11: =Y11&Z11 -> ADULTELS-의류 요약 | Y11: =IF(AA11="",Y10,AA11) -> ADULT | Z11: =IF(AB11="",Z10,AB11) -> ELS-의류 요약 | AB11: ELS-의류 요약 | AD11: 28 | AE11: 25 | AF11: 3
B12: SMB-의류 | C12: =IF(ISERROR(VLOOKUP(B12,[1]기획현황요약!$B$6:$T$36,19,FALSE))=TRUE,0,VLOOKUP(B12,[1]기획현황요약!$B$6:$T$36,19,FALSE)) -> 0 | E12: =SUMIF($X:$X,E$3&B12,$AD:$AD) -> 0 | F12: =SUMIF($X:$X,E$3&B12,$AE:$AE) -> 0 | G12: =E12 -> 0 | H12: =F12 -> 0 | I12: =MID(J12,1,2)&"K"&MID(J12,4,10) -> SMK-의류 | J12: SMB-의류 | K12: =IF(ISERROR(VLOOKUP(I12,[2]기획현황요약!$B$6:$T$30,19,FALSE))=TRUE,0,VLOOKUP(I12,[2]기획현황요약!$B$6:$T$30,19,FALSE)) -> 16.472108 | M12: =SUMIF($X:$X,M$3&J12,$AD:$AD) -> 0 | N12: =SUMIF($X:$X,M$3&J12,$AE:$AE) -> 0 | O12: =SUMIF($X:$X,O$3&J12,$AD:$AD) -> 0 | P12: =SUMIF($X:$X,O$3&J12,$AE:$AE) -> 0 | Q12: =M12+O12 -> 0 | R12: =N12+P12 -> 0 | T12: =C12+K12 -> 16.472108 | U12: =G12+Q12 -> 0 | V12: =IF(ISERROR(U12/T12)=TRUE,0,U12/T12) -> 0 | X12: =Y12&Z12 -> ADULTELS-가방 | Y12: =IF(AA12="",Y11,AA12) -> ADULT | Z12: =IF(AB12="",Z11,AB12) -> ELS-가방 | AB12: ELS-가방 | AC12: BP | AD12: 4 | AE12: 4 | AF12: 0
B13: SMB-가방 | C13: =IF(ISERROR(VLOOKUP(B13,[1]기획현황요약!$B$6:$T$36,19,FALSE))=TRUE,0,VLOOKUP(B13,[1]기획현황요약!$B$6:$T$36,19,FALSE)) -> 0 | E13: =SUMIF($X:$X,E$3&B13,$AD:$AD) -> 0 | F13: =SUMIF($X:$X,E$3&B13,$AE:$AE) -> 0 | G13: =E13 -> 0 | H13: =F13 -> 0 | I13: =MID(J13,1,2)&"K"&MID(J13,4,10) -> SMK-가방 | J13: SMB-가방 | K13: =IF(ISERROR(VLOOKUP(I13,[2]기획현황요약!$B$6:$T$30,19,FALSE))=TRUE,0,VLOOKUP(I13,[2]기획현황요약!$B$6:$T$30,19,FALSE)) -> 0 | M13: =SUMIF($X:$X,M$3&J13,$AD:$AD) -> 0 | N13: =SUMIF($X:$X,M$3&J13,$AE:$AE) -> 0 | O13: =SUMIF($X:$X,O$3&J13,$AD:$AD) -> 0 | P13: =SUMIF($X:$X,O$3&J13,$AE:$AE) -> 0 | Q13: =M13+O13 -> 0 | R13: =N13+P13 -> 0 | T13: =C13+K13 -> 0 | U13: =G13+Q13 -> 0 | V13: =IF(ISERROR(U13/T13)=TRUE,0,U13/T13) -> 0 | X13: =Y13&Z13 -> ADULTELS-가방 | Y13: =IF(AA13="",Y12,AA13) -> ADULT | Z13: =IF(AB13="",Z12,AB13) -> ELS-가방 | AC13: SB | AD13: 2 | AE13: 2 | AF13: 0
B14: NAA | C14: =IF(ISERROR(VLOOKUP(B14,[1]기획현황요약!$B$6:$T$36,19,FALSE))=TRUE,0,VLOOKUP(B14,[1]기획현황요약!$B$6:$T$36,19,FALSE)) -> 15.23251 | E14: =SUMIF($X:$X,E$3&B14,$AD:$AD) -> 15 | F14: =SUMIF($X:$X,E$3&B14,$AE:$AE) -> 14 | G14: =E14 -> 15 | H14: =F14 -> 14 | I14: =MID(J14,1,2)&"K"&MID(J14,4,10) -> NAK | J14: NAA | K14: =IF(ISERROR(VLOOKUP(I14,[2]기획현황요약!$B$6:$T$30,19,FALSE))=TRUE,0,VLOOKUP(I14,[2]기획현황요약!$B$6:$T$30,19,FALSE)) -> 5.4357956 | M14: =SUMIF($X:$X,M$3&J14,$AD:$AD) -> 0 | N14: =SUMIF($X:$X,M$3&J14,$AE:$AE) -> 0 | O14: =SUMIF($X:$X,O$3&J14,$AD:$AD) -> 0 | P14: =SUMIF($X:$X,O$3&J14,$AE:$AE) -> 0 | Q14: =M14+O14 -> 0 | R14: =N14+P14 -> 0 | T14: =C14+K14 -> 20.668306 | U14: =G14+Q14 -> 15 | V14: =IF(ISERROR(U14/T14)=TRUE,0,U14/T14) -> 0.72574889 | X14: =Y14&Z14 -> ADULTELS-가방 요약 | Y14: =IF(AA14="",Y13,AA14) -> ADULT | Z14: =IF(AB14="",Z13,AB14) -> ELS-가방 요약 | AB14: ELS-가방 요약 | AD14: 6 | AE14: 6 | AF14: 0
B15: NOV | C15: =IF(ISERROR(VLOOKUP(B15,[1]기획현황요약!$B$6:$T$36,19,FALSE))=TRUE,0,VLOOKUP(B15,[1]기획현황요약!$B$6:$T$36,19,FALSE)) -> 11.373608 | E15: =SUMIF($X:$X,E$3&B15,$AD:$AD) -> 11 | F15: =SUMIF($X:$X,E$3&B15,$AE:$AE) -> 11 | G15: =E15 -> 11 | H15: =F15 -> 11 | I15: =MID(J15,1,2)&"K"&MID(J15,4,10) -> NOK | J15: NOV | K15: =IF(ISERROR(VLOOKUP(I15,[2]기획현황요약!$B$6:$T$30,19,FALSE))=TRUE,0,VLOOKUP(I15,[2]기획현황요약!$B$6:$T$30,19,FALSE)) -> 8.8489695 | M15: =SUMIF($X:$X,M$3&J15,$AD:$AD) -> 0 | N15: =SUMIF($X:$X,M$3&J15,$AE:$AE) -> 0 | O15: =SUMIF($X:$X,O$3&J15,$AD:$AD) -> 0 | P15: =SUMIF($X:$X,O$3&J15,$AE:$AE) -> 0 | Q15: =M15+O15 -> 0 | R15: =N15+P15 -> 0 | T15: =C15+K15 -> 20.222577 | U15: =G15+Q15 -> 11 | V15: =IF(ISERROR(U15/T15)=TRUE,0,U15/T15) -> 0.5439465 | X15: =Y15&Z15 -> ADULTELS-ACC | Y15: =IF(AA15="",Y14,AA15) -> ADULT | Z15: =IF(AB15="",Z14,AB15) -> ELS-ACC | AB15: ELS-ACC | AC15: ED | AD15: 2 | AE15: 2 | AF15: 0
B16: NOV-가방 | C16: =IF(ISERROR(VLOOKUP(B16,[1]기획현황요약!$B$6:$T$36,19,FALSE))=TRUE,0,VLOOKUP(B16,[1]기획현황요약!$B$6:$T$36,19,FALSE)) -> 2.5849108 | E16: =SUMIF($X:$X,E$3&B16,$AD:$AD) -> 0 | F16: =SUMIF($X:$X,E$3&B16,$AE:$AE) -> 0 | G16: =E16 -> 0 | H16: =F16 -> 0 | I16: =MID(J16,1,2)&"K"&MID(J16,4,10) -> NOK-가방 | J16: NOV-가방 | M16: =SUMIF($X:$X,M$3&J16,$AD:$AD) -> 0 | N16: =SUMIF($X:$X,M$3&J16,$AE:$AE) -> 0 | O16: =SUMIF($X:$X,O$3&J16,$AD:$AD) -> 0 | P16: =SUMIF($X:$X,O$3&J16,$AE:$AE) -> 0 | Q16: =M16+O16 -> 0 | R16: =N16+P16 -> 0 | T16: =C17+K17 -> 96.186753 | U16: =G17+Q17 -> 42 | V16: =IF(ISERROR(U16/T16)=TRUE,0,U16/T16) -> 0.43665057 | X16: =Y16&Z16 -> ADULTELS-ACC 요약 | Y16: =IF(AA16="",Y15,AA16) -> ADULT | Z16: =IF(AB16="",Z15,AB16) -> ELS-ACC 요약 | AB16: ELS-ACC 요약 | AD16: 2 | AE16: 2 | AF16: 0
B17: URB | C17: =IF(ISERROR(VLOOKUP(B17,[1]기획현황요약!$B$6:$T$36,19,FALSE))=TRUE,0,VLOOKUP(B17,[1]기획현황요약!$B$6:$T$36,19,FALSE)) -> 49.59422 | E17: =SUMIF($X:$X,E$3&B17,$AD:$AD) -> 42 | F17: =SUMIF($X:$X,E$3&B17,$AE:$AE) -> 29 | G17: =E17 -> 42 | H17: =F17 -> 29 | I17: =MID(J17,1,2)&"K"&MID(J17,4,10) -> URK | J17: URB | K17: =IF(ISERROR(VLOOKUP(I17,[2]기획현황요약!$B$6:$T$30,19,FALSE))=TRUE,0,VLOOKUP(I17,[2]기획현황요약!$B$6:$T$30,19,FALSE)) -> 46.592533 | M17: =SUMIF($X:$X,M$3&J17,$AD:$AD) -> 0 | N17: =SUMIF($X:$X,M$3&J17,$AE:$AE) -> 0 | O17: =SUMIF($X:$X,O$3&J17,$AD:$AD) -> 0 | P17: =SUMIF($X:$X,O$3&J17,$AE:$AE) -> 0 | Q17: =M17+O17 -> 0 | R17: =N17+P17 -> 0 | T17: =C30+K30 -> 17.105864 | U17: =G30+Q30 -> 19 | V17: =IF(ISERROR(U17/T17)=TRUE,0,U17/T17) -> 1.1107302 | X17: =Y17&Z17 -> ADULTPLA-의류 | Y17: =IF(AA17="",Y16,AA17) -> ADULT | Z17: =IF(AB17="",Z16,AB17) -> PLA-의류 | AB17: PLA-의류 | AC17: HP | AD17: 4 | AE17: 4 | AF17: 0
B18: VBL | C18: =IF(ISERROR(VLOOKUP(B18,[1]기획현황요약!$B$6:$T$36,19,FALSE))=TRUE,0,VLOOKUP(B18,[1]기획현황요약!$B$6:$T$36,19,FALSE)) -> 26.246787 | E18: =SUMIF($X:$X,E$3&B18,$AD:$AD) -> 13 | F18: =SUMIF($X:$X,E$3&B18,$AE:$AE) -> 13 | G18: =E18 -> 13 | H18: =F18 -> 13 | I18: =MID(J18,1,2)&"K"&MID(J18,4,10) -> VBK | J18: VBL | K18: =IF(ISERROR(VLOOKUP(I18,[2]기획현황요약!$B$6:$T$30,19,FALSE))=TRUE,0,VLOOKUP(I18,[2]기획현황요약!$B$6:$T$30,19,FALSE)) -> 31.603463 | M18: =SUMIF($X:$X,M$3&J18,$AD:$AD) -> 0 | N18: =SUMIF($X:$X,M$3&J18,$AE:$AE) -> 0 | O18: =SUMIF($X:$X,O$3&J18,$AD:$AD) -> 0 | P18: =SUMIF($X:$X,O$3&J18,$AE:$AE) -> 0 | Q18: =M18+O18 -> 0 | R18: =N18+P18 -> 0 | T18: =C32+K32 -> 23.758611 | U18: =G32+Q32 -> 12 | V18: =IF(ISERROR(U18/T18)=TRUE,0,U18/T18) -> 0.50508003 | X18: =Y18&Z18 -> ADULTPLA-의류 | Y18: =IF(AA18="",Y17,AA18) -> ADULT | Z18: =IF(AB18="",Z17,AB18) -> PLA-의류 | AC18: JP | AD18: 5 | AE18: 5 | AF18: 0
B19: VBL-의류 | C19: =IF(ISERROR(VLOOKUP(B19,[1]기획현황요약!$B$6:$T$36,19,FALSE))=TRUE,0,VLOOKUP(B19,[1]기획현황요약!$B$6:$T$36,19,FALSE)) -> 1.795077 | E19: =SUMIF($X:$X,E$3&B19,$AD:$AD) -> 4 | F19: =SUMIF($X:$X,E$3&B19,$AE:$AE) -> 4 | G19: =E19 -> 4 | H19: =F19 -> 4 | I19: =MID(J19,1,2)&"K"&MID(J19,4,10) -> VBK-의류 | J19: VBL-의류 | K19: =IF(ISERROR(VLOOKUP(I19,[2]기획현황요약!$B$6:$T$30,19,FALSE))=TRUE,0,VLOOKUP(I19,[2]기획현황요약!$B$6:$T$30,19,FALSE)) -> 0 | M19: =SUMIF($X:$X,M$3&J19,$AD:$AD) -> 0 | N19: =SUMIF($X:$X,M$3&J19,$AE:$AE) -> 0 | O19: =SUMIF($X:$X,O$3&J19,$AD:$AD) -> 0 | P19: =SUMIF($X:$X,O$3&J19,$AE:$AE) -> 0 | Q19: =M19+O19 -> 0 | R19: =N19+P19 -> 0 | T19: =C20+K20 -> 29.209489 | U19: =G20+Q20 -> 16 | V19: =IF(ISERROR(U19/T19)=TRUE,0,U19/T19) -> 0.54776721 | X19: =Y19&Z19 -> ADULTPLA-의류 | Y19: =IF(AA19="",Y18,AA19) -> ADULT | Z19: =IF(AB19="",Z18,AB19) -> PLA-의류 | AC19: TH | AD19: 4 | AE19: 4 | AF19: 0
B20: PLA | C20: =IF(ISERROR(VLOOKUP(B20,[1]기획현황요약!$B$6:$T$36,19,FALSE))=TRUE,0,VLOOKUP(B20,[1]기획현황요약!$B$6:$T$36,19,FALSE)) -> 17.349571 | E20: =SUMIF($X:$X,E$3&B20,$AD:$AD) -> 16 | F20: =SUMIF($X:$X,E$3&B20,$AE:$AE) -> 11 | G20: =E20 -> 16 | H20: =F20 -> 11 | I20: =MID(J20,1,2)&"K"&MID(J20,4,10) -> PLK | J20: PLA | K20: =IF(ISERROR(VLOOKUP(I20,[2]기획현황요약!$B$6:$T$30,19,FALSE))=TRUE,0,VLOOKUP(I20,[2]기획현황요약!$B$6:$T$30,19,FALSE)) -> 11.859918 | M20: =SUMIF($X:$X,M$3&J20,$AD:$AD) -> 0 | N20: =SUMIF($X:$X,M$3&J20,$AE:$AE) -> 0 | O20: =SUMIF($X:$X,O$3&J20,$AD:$AD) -> 0 | P20: =SUMIF($X:$X,O$3&J20,$AE:$AE) -> 0 | Q20: =M20+O20 -> 0 | R20: =N20+P20 -> 0 | T20: =C21+K21 -> 31.489631 | U20: =G21+Q21 -> 26 | V20: =IF(ISERROR(U20/T20)=TRUE,0,U20/T20) -> 0.82566862 | X20: =Y20&Z20 -> ADULTPLA-의류 | Y20: =IF(AA20="",Y19,AA20) -> ADULT | Z20: =IF(AB20="",Z19,AB20) -> PLA-의류 | AC20: TL | AD20: 7 | AE20: 7 | AF20: 0
B21: PLA-의류 | C21: =IF(ISERROR(VLOOKUP(B21,[1]기획현황요약!$B$6:$T$36,19,FALSE))=TRUE,0,VLOOKUP(B21,[1]기획현황요약!$B$6:$T$36,19,FALSE)) -> 5.6868038 | E21: =SUMIF($X:$X,E$3&B21,$AD:$AD) -> 26 | F21: =SUMIF($X:$X,E$3&B21,$AE:$AE) -> 25 | G21: =E21 -> 26 | H21: =F21 -> 25 | I21: =MID(J21,1,2)&"K"&MID(J21,4,10) -> PLK-의류 | J21: PLA-의류 | K21: =IF(ISERROR(VLOOKUP(I21,[2]기획현황요약!$B$6:$T$30,19,FALSE))=TRUE,0,VLOOKUP(I21,[2]기획현황요약!$B$6:$T$30,19,FALSE)) -> 25.802827 | M21: =SUMIF($X:$X,M$3&J21,$AD:$AD) -> 0 | N21: =SUMIF($X:$X,M$3&J21,$AE:$AE) -> 0 | O21: =SUMIF($X:$X,O$3&J21,$AD:$AD) -> 0 | P21: =SUMIF($X:$X,O$3&J21,$AE:$AE) -> 0 | Q21: =M21+O21 -> 0 | R21: =N21+P21 -> 0 | T21: =C22+K22 -> 2.5590617 | U21: =G22+Q22 -> 0 | V21: =IF(ISERROR(U21/T21)=TRUE,0,U21/T21) -> 0 | X21: =Y21&Z21 -> ADULTPLA-의류 | Y21: =IF(AA21="",Y20,AA21) -> ADULT | Z21: =IF(AB21="",Z20,AB21) -> PLA-의류 | AC21: PT | AD21: 6 | AE21: 5 | AF21: 1
B22: PLA-가방 | C22: =IF(ISERROR(VLOOKUP(B22,[1]기획현황요약!$B$6:$T$36,19,FALSE))=TRUE,0,VLOOKUP(B22,[1]기획현황요약!$B$6:$T$36,19,FALSE)) -> 2.5590617 | E22: =SUMIF($X:$X,E$3&B22,$AD:$AD) -> 0 | F22: =SUMIF($X:$X,E$3&B22,$AE:$AE) -> 0 | G22: =E22 -> 0 | H22: =F22 -> 0 | I22: =MID(J22,1,2)&"K"&MID(J22,4,10) -> PLK-가방 | J22: PLA-가방 | K22: =IF(ISERROR(VLOOKUP(I22,[2]기획현황요약!$B$6:$T$30,19,FALSE))=TRUE,0,VLOOKUP(I22,[2]기획현황요약!$B$6:$T$30,19,FALSE)) -> 0 | M22: =SUMIF($X:$X,M$3&J22,$AD:$AD) -> 0 | N22: =SUMIF($X:$X,M$3&J22,$AE:$AE) -> 0 | O22: =SUMIF($X:$X,O$3&J22,$AD:$AD) -> 0 | P22: =SUMIF($X:$X,O$3&J22,$AE:$AE) -> 0 | Q22: =M22+O22 -> 0 | R22: =N22+P22 -> 0 | T22: =C23+K23 -> 39.176905 | U22: =G23+Q23 -> 160 | V22: =IF(ISERROR(U22/T22)=TRUE,0,U22/T22) -> 4.0840388 | X22: =Y22&Z22 -> ADULTPLA-의류 요약 | Y22: =IF(AA22="",Y21,AA22) -> ADULT | Z22: =IF(AB22="",Z21,AB22) -> PLA-의류 요약 | AB22: PLA-의류 요약 | AD22: 26 | AE22: 25 | AF22: 1
B23: JIL | C23: =IF(ISERROR(VLOOKUP(B23,[1]기획현황요약!$B$6:$T$36,19,FALSE))=TRUE,0,VLOOKUP(B23,[1]기획현황요약!$B$6:$T$36,19,FALSE)) -> 0 | E23: =SUMIF($X:$X,E$3&B23,$AD:$AD) -> 160 | F23: =SUMIF($X:$X,E$3&B23,$AE:$AE) -> 149 | G23: =E23 -> 160 | H23: =F23 -> 149 | I23: =MID(J23,1,2)&"K"&MID(J23,4,10) -> JIK | J23: JIL | K23: =IF(ISERROR(VLOOKUP(I23,[2]기획현황요약!$B$6:$T$30,19,FALSE))=TRUE,0,VLOOKUP(I23,[2]기획현황요약!$B$6:$T$30,19,FALSE)) -> 39.176905 | M23: =SUMIF($X:$X,M$3&J23,$AD:$AD) -> 0 | N23: =SUMIF($X:$X,M$3&J23,$AE:$AE) -> 0 | O23: =SUMIF($X:$X,O$3&J23,$AD:$AD) -> 0 | P23: =SUMIF($X:$X,O$3&J23,$AE:$AE) -> 0 | Q23: =M23+O23 -> 0 | R23: =N23+P23 -> 0 | T23: =C24+K24 -> 4.1813812 | U23: =G24+Q24 -> 4 | V23: =IF(ISERROR(U23/T23)=TRUE,0,U23/T23) -> 0.9566217 | X23: =Y23&Z23 -> ADULTJIL-ACC | Y23: =IF(AA23="",Y22,AA23) -> ADULT | Z23: =IF(AB23="",Z22,AB23) -> JIL-ACC | AB23: JIL-ACC | AC23: ED | AD23: 1 | AE23: 1 | AF23: 0
B24: JIL-ACC | C24: =IF(ISERROR(VLOOKUP(B24,[1]기획현황요약!$B$6:$T$36,19,FALSE))=TRUE,0,VLOOKUP(B24,[1]기획현황요약!$B$6:$T$36,19,FALSE)) -> 0 | E24: =SUMIF($X:$X,E$3&B24,$AD:$AD) -> 4 | F24: =SUMIF($X:$X,E$3&B24,$AE:$AE) -> 1 | G24: =E24 -> 4 | H24: =F24 -> 1 | I24: =MID(J24,1,2)&"K"&MID(J24,4,10) -> JIK-ACC | J24: JIL-ACC | K24: =IF(ISERROR(VLOOKUP(I24,[2]기획현황요약!$B$6:$T$30,19,FALSE))=TRUE,0,VLOOKUP(I24,[2]기획현황요약!$B$6:$T$30,19,FALSE)) -> 4.1813812 | M24: =SUMIF($X:$X,M$3&J24,$AD:$AD) -> 0 | N24: =SUMIF($X:$X,M$3&J24,$AE:$AE) -> 0 | O24: =SUMIF($X:$X,O$3&J24,$AD:$AD) -> 0 | P24: =SUMIF($X:$X,O$3&J24,$AE:$AE) -> 0 | Q24: =M24+O24 -> 0 | R24: =N24+P24 -> 0 | T24: =C25+K25 -> 0 | U24: =G25+Q25 -> 0 | V24: =IF(ISERROR(U24/T24)=TRUE,0,U24/T24) -> 0 | X24: =Y24&Z24 -> ADULTJIL-ACC | Y24: =IF(AA24="",Y23,AA24) -> ADULT | Z24: =IF(AB24="",Z23,AB24) -> JIL-ACC | AC24: WA | AD24: 3 | AE24: 0 | AF24: 3
B25: JIT | C25: =IF(ISERROR(VLOOKUP(B25,[1]기획현황요약!$B$6:$T$36,19,FALSE))=TRUE,0,VLOOKUP(B25,[1]기획현황요약!$B$6:$T$36,19,FALSE)) -> 0 | E25: =SUMIF($X:$X,E$3&B25,$AD:$AD) -> 0 | F25: =SUMIF($X:$X,E$3&B25,$AE:$AE) -> 0 | G25: =E25 -> 0 | H25: =F25 -> 0 | J25: JIT | K25: =IF(ISERROR(VLOOKUP(I25,[2]기획현황요약!$B$6:$T$30,19,FALSE))=TRUE,0,VLOOKUP(I25,[2]기획현황요약!$B$6:$T$30,19,FALSE)) -> 0 | M25: =SUMIF($X:$X,M$3&J25,$AD:$AD) -> 0 | N25: =SUMIF($X:$X,M$3&J25,$AE:$AE) -> 0 | O25: =SUMIF($X:$X,O$3&J25,$AD:$AD) -> 0 | P25: =SUMIF($X:$X,O$3&J25,$AE:$AE) -> 0 | Q25: =M25+O25 -> 0 | R25: =N25+P25 -> 0 | T25: =C26+K26 -> 38.495344 | U25: =G26+Q26 -> 13 | V25: =IF(ISERROR(U25/T25)=TRUE,0,U25/T25) -> 0.33770318 | X25: =Y25&Z25 -> ADULTJIL-ACC 요약 | Y25: =IF(AA25="",Y24,AA25) -> ADULT | Z25: =IF(AB25="",Z24,AB25) -> JIL-ACC 요약 | AB25: JIL-ACC 요약 | AD25: 4 | AE25: 1 | AF25: 3
B26: HCU | C26: =IF(ISERROR(VLOOKUP(B26,[1]기획현황요약!$B$6:$T$36,19,FALSE))=TRUE,0,VLOOKUP(B26,[1]기획현황요약!$B$6:$T$36,19,FALSE)) -> 29.014305 | E26: =SUMIF($X:$X,E$3&B26,$AD:$AD) -> 13 | F26: =SUMIF($X:$X,E$3&B26,$AE:$AE) -> 13 | G26: =E26 -> 13 | H26: =F26 -> 13 | I26: =MID(J26,1,2)&"K"&MID(J26,4,10) -> HCK | J26: HCU | K26: =IF(ISERROR(VLOOKUP(I26,[2]기획현황요약!$B$6:$T$30,19,FALSE))=TRUE,0,VLOOKUP(I26,[2]기획현황요약!$B$6:$T$30,19,FALSE)) -> 9.4810388 | M26: =SUMIF($X:$X,M$3&J26,$AD:$AD) -> 0 | N26: =SUMIF($X:$X,M$3&J26,$AE:$AE) -> 0 | O26: =SUMIF($X:$X,O$3&J26,$AD:$AD) -> 0 | P26: =SUMIF($X:$X,O$3&J26,$AE:$AE) -> 0 | Q26: =M26+O26 -> 0 | R26: =N26+P26 -> 0 | T26: =C27+K27 -> 18.283164 | U26: =G27+Q27 -> 11 | V26: =IF(ISERROR(U26/T26)=TRUE,0,U26/T26) -> 0.60164641 | X26: =Y26&Z26 -> ADULTJOI-ACC | Y26: =IF(AA26="",Y25,AA26) -> ADULT | Z26: =IF(AB26="",Z25,AB26) -> JOI-ACC | AB26: JOI-ACC | AC26: AC | AD26: 3 | AE26: 3 | AF26: 0
B27: BRO | C27: =IF(ISERROR(VLOOKUP(B27,[1]기획현황요약!$B$6:$T$36,19,FALSE))=TRUE,0,VLOOKUP(B27,[1]기획현황요약!$B$6:$T$36,19,FALSE)) -> 13.056437 | E27: =SUMIF($X:$X,E$3&B27,$AD:$AD) -> 11 | F27: =SUMIF($X:$X,E$3&B27,$AE:$AE) -> 11 | G27: =E27 -> 11 | H27: =F27 -> 11 | I27: =MID(J27,1,2)&"K"&MID(J27,4,10) -> BRK | J27: BRO | K27: =IF(ISERROR(VLOOKUP(I27,[2]기획현황요약!$B$6:$T$30,19,FALSE))=TRUE,0,VLOOKUP(I27,[2]기획현황요약!$B$6:$T$30,19,FALSE)) -> 5.2267265 | M27: =SUMIF($X:$X,M$3&J27,$AD:$AD) -> 0 | N27: =SUMIF($X:$X,M$3&J27,$AE:$AE) -> 0 | O27: =SUMIF($X:$X,O$3&J27,$AD:$AD) -> 0 | P27: =SUMIF($X:$X,O$3&J27,$AE:$AE) -> 0 | Q27: =M27+O27 -> 0 | R27: =N27+P27 -> 0 | T27: =C28+K28 -> 18.681204 | U27: =G28+Q28 -> 10 | V27: =IF(ISERROR(U27/T27)=TRUE,0,U27/T27) -> 0.53529741 | X27: =Y27&Z27 -> ADULTJOI-ACC 요약 | Y27: =IF(AA27="",Y26,AA27) -> ADULT | Z27: =IF(AB27="",Z26,AB27) -> JOI-ACC 요약 | AB27: JOI-ACC 요약 | AD27: 3 | AE27: 3 | AF27: 0
B28: BMD | C28: =IF(ISERROR(VLOOKUP(B28,[1]기획현황요약!$B$6:$T$36,19,FALSE))=TRUE,0,VLOOKUP(B28,[1]기획현황요약!$B$6:$T$36,19,FALSE)) -> 10.44515 | E28: =SUMIF($X:$X,E$3&B28,$AD:$AD) -> 10 | F28: =SUMIF($X:$X,E$3&B28,$AE:$AE) -> 6 | G28: =E28 -> 10 | H28: =F28 -> 6 | I28: =MID(J28,1,2)&"K"&MID(J28,4,10) -> BMK | J28: BMD | K28: =IF(ISERROR(VLOOKUP(I28,[2]기획현황요약!$B$6:$T$30,19,FALSE))=TRUE,0,VLOOKUP(I28,[2]기획현황요약!$B$6:$T$30,19,FALSE)) -> 8.2360539 | M28: =SUMIF($X:$X,M$3&J28,$AD:$AD) -> 0 | N28: =SUMIF($X:$X,M$3&J28,$AE:$AE) -> 0 | O28: =SUMIF($X:$X,O$3&J28,$AD:$AD) -> 0 | P28: =SUMIF($X:$X,O$3&J28,$AE:$AE) -> 0 | Q28: =M28+O28 -> 0 | R28: =N28+P28 -> 0 | T28: =C29+K29 -> 25.66514 | U28: =G29+Q29 -> 0 | V28: =IF(ISERROR(U28/T28)=TRUE,0,U28/T28) -> 0 | X28: =Y28&Z28 -> ADULTJIL | Y28: =IF(AA28="",Y27,AA28) -> ADULT | Z28: =IF(AB28="",Z27,AB28) -> JIL | AB28: JIL | AC28: BA | AD28: 16 | AE28: 16 | AF28: 0
B29: WTR | C29: =IF(ISERROR(VLOOKUP(B29,[1]기획현황요약!$B$6:$T$36,19,FALSE))=TRUE,0,VLOOKUP(B29,[1]기획현황요약!$B$6:$T$36,19,FALSE)) -> 20.11841 | E29: =SUMIF($X:$X,E$3&B29,$AD:$AD) -> 0 | F29: =SUMIF($X:$X,E$3&B29,$AE:$AE) -> 0 | G29: =E29 -> 0 | H29: =F29 -> 0 | I29: =MID(J29,1,2)&"K"&MID(J29,4,10) -> WTK | J29: WTR | K29: =IF(ISERROR(VLOOKUP(I29,[2]기획현황요약!$B$6:$T$30,19,FALSE))=TRUE,0,VLOOKUP(I29,[2]기획현황요약!$B$6:$T$30,19,FALSE)) -> 5.5467302 | M29: =SUMIF($X:$X,M$3&J29,$AD:$AD) -> 0 | N29: =SUMIF($X:$X,M$3&J29,$AE:$AE) -> 0 | O29: =SUMIF($X:$X,O$3&J29,$AD:$AD) -> 0 | P29: =SUMIF($X:$X,O$3&J29,$AE:$AE) -> 0 | Q29: =M29+O29 -> 0 | R29: =N29+P29 -> 0 | T29: =C31+K31 -> 6.9792593 | U29: =G31+Q31 -> 0 | V29: =IF(ISERROR(U29/T29)=TRUE,0,U29/T29) -> 0 | X29: =Y29&Z29 -> ADULTJIL | Y29: =IF(AA29="",Y28,AA29) -> ADULT | Z29: =IF(AB29="",Z28,AB29) -> JIL | AC29: MI | AD29: 9 | AE29: 9 | AF29: 0
B30: YGF | C30: =IF(ISERROR(VLOOKUP(B30,[1]기획현황요약!$B$6:$T$36,19,FALSE))=TRUE,0,VLOOKUP(B30,[1]기획현황요약!$B$6:$T$36,19,FALSE)) -> 9.6934156 | E30: =SUMIF($X:$X,E$3&B30,$AD:$AD) -> 19 | F30: =SUMIF($X:$X,E$3&B30,$AE:$AE) -> 19 | G30: =E30 -> 19 | H30: =F30 -> 19 | I30: =MID(J30,1,2)&"K"&MID(J30,4,10) -> YGK | J30: YGF | K30: =IF(ISERROR(VLOOKUP(I30,[2]기획현황요약!$B$6:$T$30,19,FALSE))=TRUE,0,VLOOKUP(I30,[2]기획현황요약!$B$6:$T$30,19,FALSE)) -> 7.4124485 | M30: =SUMIF($X:$X,M$3&J30,$AD:$AD) -> 0 | N30: =SUMIF($X:$X,M$3&J30,$AE:$AE) -> 0 | O30: =SUMIF($X:$X,O$3&J30,$AD:$AD) -> 0 | P30: =SUMIF($X:$X,O$3&J30,$AE:$AE) -> 0 | Q30: =M30+O30 -> 0 | R30: =N30+P30 -> 0 | T30: =C36+K36 -> 29.911446 | U30: =G36+Q36 -> 24 | V30: =IF(ISERROR(U30/T30)=TRUE,0,U30/T30) -> 0.80236842 | X30: =Y30&Z30 -> ADULTJIL | Y30: =IF(AA30="",Y29,AA30) -> ADULT | Z30: =IF(AB30="",Z29,AB30) -> JIL | AC30: ER | AD30: 63 | AE30: 61 | AF30: 2
B31: B1A | C31: =IF(ISERROR(VLOOKUP(B31,[1]기획현황요약!$B$6:$T$36,19,FALSE))=TRUE,0,VLOOKUP(B31,[1]기획현황요약!$B$6:$T$36,19,FALSE)) -> 6.9792593 | E31: =SUMIF($X:$X,E$3&B31,$AD:$AD) -> 0 | F31: =SUMIF($X:$X,E$3&B31,$AE:$AE) -> 0 | G31: =E31 -> 0 | H31: =F31 -> 0 | I31: =MID(J31,1,2)&"K"&MID(J31,4,10) -> B1K | J31: B1A | K31: =IF(ISERROR(VLOOKUP(I31,[2]기획현황요약!$B$6:$T$30,19,FALSE))=TRUE,0,VLOOKUP(I31,[2]기획현황요약!$B$6:$T$30,19,FALSE)) -> 0 | M31: =SUMIF($X:$X,M$3&J31,$AD:$AD) -> 0 | N31: =SUMIF($X:$X,M$3&J31,$AE:$AE) -> 0 | O31: =SUMIF($X:$X,O$3&J31,$AD:$AD) -> 0 | P31: =SUMIF($X:$X,O$3&J31,$AE:$AE) -> 0 | Q31: =M31+O31 -> 0 | R31: =N31+P31 -> 0 | T31: =C37+K37 -> 0 | U31: =G37+Q37 -> 3 | V31: =IF(ISERROR(U31/T31)=TRUE,0,U31/T31) -> 0 | X31: =Y31&Z31 -> ADULTJIL | Y31: =IF(AA31="",Y30,AA31) -> ADULT | Z31: =IF(AB31="",Z30,AB31) -> JIL | AC31: FE | AD31: 1 | AE31: 1 | AF31: 0
B32: POL | C32: =IF(ISERROR(VLOOKUP(B32,[1]기획현황요약!$B$6:$T$36,19,FALSE))=TRUE,0,VLOOKUP(B32,[1]기획현황요약!$B$6:$T$36,19,FALSE)) -> 9.4955908 | E32: =SUMIF($X:$X,E$3&B32,$AD:$AD) -> 0 | F32: =SUMIF($X:$X,E$3&B32,$AE:$AE) -> 0 | G32: =E32 -> 0 | H32: =F32 -> 0 | I32: =MID(J32,1,2)&"K"&MID(J32,4,10) -> POK | J32: POL | K32: =IF(ISERROR(VLOOKUP(I32,[2]기획현황요약!$B$6:$T$30,19,FALSE))=TRUE,0,VLOOKUP(I32,[2]기획현황요약!$B$6:$T$30,19,FALSE)) -> 14.26302 | M32: =SUMIF($X:$X,M$3&J32,$AD:$AD) -> 12 | N32: =SUMIF($X:$X,M$3&J32,$AE:$AE) -> 12 | O32: =SUMIF($X:$X,O$3&J32,$AD:$AD) -> 0 | P32: =SUMIF($X:$X,O$3&J32,$AE:$AE) -> 0 | Q32: =M32+O32 -> 12 | R32: =N32+P32 -> 12 | T32: =C38+K38 -> 0 | U32: =G38+Q38 -> 19 | V32: =IF(ISERROR(U32/T32)=TRUE,0,U32/T32) -> 0 | X32: =Y32&Z32 -> ADULTJIL | Y32: =IF(AA32="",Y31,AA32) -> ADULT | Z32: =IF(AB32="",Z31,AB32) -> JIL | AC32: HU | AD32: 2 | AE32: 2 | AF32: 0
B33: DPS | C33: =IF(ISERROR(VLOOKUP(B33,[1]기획현황요약!$B$6:$T$36,19,FALSE))=TRUE,0,VLOOKUP(B33,[1]기획현황요약!$B$6:$T$36,19,FALSE)) -> 13.293827 | E33: =SUMIF($X:$X,E$3&B33,$AD:$AD) -> 5 | F33: =SUMIF($X:$X,E$3&B33,$AE:$AE) -> 4 | G33: =E33 -> 5 | H33: =F33 -> 4 | I33: =MID(J33,1,2)&"K"&MID(J33,4,10) -> DPK | J33: DPS | K33: =IF(ISERROR(VLOOKUP(I33,[2]기획현황요약!$B$6:$T$30,19,FALSE))=TRUE,0,VLOOKUP(I33,[2]기획현황요약!$B$6:$T$30,19,FALSE)) -> 0 | M33: =SUMIF($X:$X,M$3&J33,$AD:$AD) -> 0 | N33: =SUMIF($X:$X,M$3&J33,$AE:$AE) -> 0 | O33: =SUMIF($X:$X,O$3&J33,$AD:$AD) -> 0 | P33: =SUMIF($X:$X,O$3&J33,$AE:$AE) -> 0 | Q33: =M33+O33 -> 0 | R33: =N33+P33 -> 0 | T33: =C39+K39 -> 945.37745 | U33: =G39+Q39 -> 572 | V33: =IF(ISERROR(U33/T33)=TRUE,0,U33/T33) -> 0.60504934 | X33: =Y33&Z33 -> ADULTJIL | Y33: =IF(AA33="",Y32,AA33) -> ADULT | Z33: =IF(AB33="",Z32,AB33) -> JIL | AC33: TP | AD33: 17 | AE33: 9 | AF33: 8
B34: MGM | C34: =IF(ISERROR(VLOOKUP(B34,[1]기획현황요약!$B$6:$T$36,19,FALSE))=TRUE,0,VLOOKUP(B34,[1]기획현황요약!$B$6:$T$36,19,FALSE)) -> 26.112875 | E34: =SUMIF($X:$X,E$3&B34,$AD:$AD) -> 0 | F34: =SUMIF($X:$X,E$3&B34,$AE:$AE) -> 0 | G34: =E34 -> 0 | H34: =F34 -> 0 | I34: =MID(J34,1,2)&"K"&MID(J34,4,10) -> MGK | J34: MGM | K34: =IF(ISERROR(VLOOKUP(I34,[2]기획현황요약!$B$6:$T$30,19,FALSE))=TRUE,0,VLOOKUP(I34,[2]기획현황요약!$B$6:$T$30,19,FALSE)) -> 0 | M34: =SUMIF($X:$X,M$3&J34,$AD:$AD) -> 0 | N34: =SUMIF($X:$X,M$3&J34,$AE:$AE) -> 0 | O34: =SUMIF($X:$X,O$3&J34,$AD:$AD) -> 0 | P34: =SUMIF($X:$X,O$3&J34,$AE:$AE) -> 0 | Q34: =M34+O34 -> 0 | R34: =N34+P34 -> 0 | X34: =Y34&Z34 -> ADULTJIL | Y34: =IF(AA34="",Y33,AA34) -> ADULT | Z34: =IF(AB34="",Z33,AB34) -> JIL | AC34: BE | AD34: 52 | AE34: 51 | AF34: 1
B35: ZZZ | C35: =IF(ISERROR(VLOOKUP(B35,[1]기획현황요약!$B$6:$T$36,19,FALSE))=TRUE,0,VLOOKUP(B35,[1]기획현황요약!$B$6:$T$36,19,FALSE)) -> 28.434019 | E35: =SUMIF($X:$X,E$3&B35,$AD:$AD) -> 0 | F35: =SUMIF($X:$X,E$3&B35,$AE:$AE) -> 0 | G35: =E35 -> 0 | H35: =F35 -> 0 | I35: =MID(J35,1,2)&"K"&MID(J35,4,10) -> ZZK | J35: ZZZ | K35: =IF(ISERROR(VLOOKUP(I35,[2]기획현황요약!$B$6:$T$30,19,FALSE))=TRUE,0,VLOOKUP(I35,[2]기획현황요약!$B$6:$T$30,19,FALSE)) -> 0 | M35: =SUMIF($X:$X,M$3&J35,$AD:$AD) -> 0 | N35: =SUMIF($X:$X,M$3&J35,$AE:$AE) -> 0 | O35: =SUMIF($X:$X,O$3&J35,$AD:$AD) -> 0 | P35: =SUMIF($X:$X,O$3&J35,$AE:$AE) -> 0 | Q35: =M35+O35 -> 0 | R35: =N35+P35 -> 0 | X35: =Y35&Z35 -> ADULTJIL 요약 | Y35: =IF(AA35="",Y34,AA35) -> ADULT | Z35: =IF(AB35="",Z34,AB35) -> JIL 요약 | AB35: JIL 요약 | AD35: 160 | AE35: 149 | AF35: 11
B36: JOI | C36: =IF(ISERROR(VLOOKUP(B36,[1]기획현황요약!$B$6:$T$36,19,FALSE))=TRUE,0,VLOOKUP(B36,[1]기획현황요약!$B$6:$T$36,19,FALSE)) -> 11.191232 | E36: =SUMIF($X:$X,E$3&B36,$AD:$AD) -> 5 | F36: =SUMIF($X:$X,E$3&B36,$AE:$AE) -> 5 | G36: =E36 -> 5 | H36: =F36 -> 5 | I36: =MID(J36,1,2)&"K"&MID(J36,4,10) -> JOK | J36: JOI | K36: =IF(ISERROR(VLOOKUP(I36,[2]기획현황요약!$B$6:$T$30,19,FALSE))=TRUE,0,VLOOKUP(I36,[2]기획현황요약!$B$6:$T$30,19,FALSE)) -> 18.720214 | M36: =SUMIF($X:$X,M$3&J36,$AD:$AD) -> 19 | N36: =SUMIF($X:$X,M$3&J36,$AE:$AE) -> 14 | O36: =SUMIF($X:$X,O$3&J36,$AD:$AD) -> 0 | P36: =SUMIF($X:$X,O$3&J36,$AE:$AE) -> 0 | Q36: =M36+O36 -> 19 | R36: =N36+P36 -> 14 | X36: =Y36&Z36 -> ADULTJOI | Y36: =IF(AA36="",Y35,AA36) -> ADULT | Z36: =IF(AB36="",Z35,AB36) -> JOI | AB36: JOI | AC36: FA | AD36: 1 | AE36: 1 | AF36: 0
B37: JOI-가방 | C37: =IF(ISERROR(VLOOKUP(B37,[1]기획현황요약!$B$6:$T$36,19,FALSE))=TRUE,0,VLOOKUP(B37,[1]기획현황요약!$B$6:$T$36,19,FALSE)) -> 0 | E37: =SUMIF($X:$X,E$3&B37,$AD:$AD) -> 0 | F37: =SUMIF($X:$X,E$3&B37,$AE:$AE) -> 0 | G37: =E37 -> 0 | H37: =F37 -> 0 | I37: =MID(J37,1,2)&"K"&MID(J37,4,10) -> JOK-가방 | J37: JOI-가방 | K37: =IF(ISERROR(VLOOKUP(I37,[2]기획현황요약!$B$6:$T$30,19,FALSE))=TRUE,0,VLOOKUP(I37,[2]기획현황요약!$B$6:$T$30,19,FALSE)) -> 0 | M37: =SUMIF($X:$X,M$3&J37,$AD:$AD) -> 3 | N37: =SUMIF($X:$X,M$3&J37,$AE:$AE) -> 0 | O37: =SUMIF($X:$X,O$3&J37,$AD:$AD) -> 0 | P37: =SUMIF($X:$X,O$3&J37,$AE:$AE) -> 0 | Q37: =M37+O37 -> 3 | R37: =N37+P37 -> 0 | X37: =Y37&Z37 -> ADULTJOI | Y37: =IF(AA37="",Y36,AA37) -> ADULT | Z37: =IF(AB37="",Z36,AB37) -> JOI | AC37: BE | AD37: 4 | AE37: 4 | AF37: 0
B38: JOI-ACC | C38: =IF(ISERROR(VLOOKUP(B38,[1]기획현황요약!$B$6:$T$36,19,FALSE))=TRUE,0,VLOOKUP(B38,[1]기획현황요약!$B$6:$T$36,19,FALSE)) -> 0 | E38: =SUMIF($X:$X,E$3&B38,$AD:$AD) -> 3 | F38: =SUMIF($X:$X,E$3&B38,$AE:$AE) -> 3 | G38: =E38 -> 3 | H38: =F38 -> 3 | I38: =MID(J38,1,2)&"K"&MID(J38,4,10) -> JOK-ACC | J38: JOI-ACC | K38: =IF(ISERROR(VLOOKUP(I38,[2]기획현황요약!$B$6:$T$30,19,FALSE))=TRUE,0,VLOOKUP(I38,[2]기획현황요약!$B$6:$T$30,19,FALSE)) -> 0 | M38: =SUMIF($X:$X,M$3&J38,$AD:$AD) -> 16 | N38: =SUMIF($X:$X,M$3&J38,$AE:$AE) -> 7 | O38: =SUMIF($X:$X,O$3&J38,$AD:$AD) -> 0 | P38: =SUMIF($X:$X,O$3&J38,$AE:$AE) -> 0 | Q38: =M38+O38 -> 16 | R38: =N38+P38 -> 7 | X38: =Y38&Z38 -> ADULTJOI 요약 | Y38: =IF(AA38="",Y37,AA38) -> ADULT | Z38: =IF(AB38="",Z37,AB38) -> JOI 요약 | AB38: JOI 요약 | AD38: 5 | AE38: 5 | AF38: 0
B39: 합계 | C39: =SUM(C7:C38) -> 485.99724 | D39: =SUM(D7:D38) -> 0 | E39: =SUM(E7:E38) -> 457 | F39: =SUM(F7:F38) -> 405 | G39: =SUM(G7:G38) -> 457 | H39: =SUM(H7:H38) -> 405 | J39: =B39 -> 합계 | K39: =SUM(K7:K38) -> 459.3802 | L39: =SUM(L7:L38) -> 0 | M39: =SUM(M7:M38) -> 115 | N39: =SUM(N7:N38) -> 87 | O39: =SUM(O7:O38) -> 0 | P39: =SUM(P7:P38) -> 0 | Q39: =SUM(Q7:Q38) -> 115 | R39: =SUM(R7:R38) -> 87 | X39: =Y39&Z39 -> ADULTELS | Y39: =IF(AA39="",Y38,AA39) -> ADULT | Z39: =IF(AB39="",Z38,AB39) -> ELS | AB39: ELS | AC39: FI | AD39: 18 | AE39: 15 | AF39: 3
X40: =Y40&Z40 -> ADULTELS | Y40: =IF(AA40="",Y39,AA40) -> ADULT | Z40: =IF(AB40="",Z39,AB40) -> ELS | AC40: FA | AD40: 2 | AE40: 2 | AF40: 0
...

Sheet 발주입고월
A1: 14FW SAMPLE LIST (HATS ON) | S1: 14FW SAMPLE LIST (HATS ON) | AK1: 14FW SAMPLE LIST (HATS ON) | BO1: 14FW SAMPLE LIST (HATS ON KIDS) | CS1: 14FW SAMPLE LIST (HATS ON) | DP1: 14SS SAMPLE LIST (HATS ON KIDS)
AK2: *실발주샘플수=중복 발주 및 입고 스타일은 1ST로 계산 | BO2: *실발주샘플수=중복 발주 및 입고 스타일은 1ST로 계산 | CS2: *실발주샘플수=중복 발주 및 입고 스타일은 1ST로 계산 | DP2: *실발주샘플수=중복 발주 및 입고 스타일은 1ST로 계산
A3: *실발주샘플수=중복 발주 및 입고 스타일은 1ST로 계산 | S3: *실발주샘플수=중복 발주 및 입고 스타일은 1ST로 계산 | AK3: 러닝(R)/신규(N) | AL3: N | BO3: 러닝(R)/신규(N) | BP3: N | CS3: 러닝(R)/신규(N) | CT3: N | DP3: 러닝(R)/신규(N) | DQ3: N
A4: 샘플수 | D4: 입고월 | S4: 샘플수 | V4: 입고월 | AK4: 연령구분 | AL4: (다중 항목) | BO4: 연령구분 | BP4: (다중 항목) | CS4: 연령구분 | CT4: (다중 항목) | DP4: 연령구분 | DQ4: (다중 항목)
A5: 브랜드/품목2 | B5: 품목 | C5: 실발주월 | D5: 190001 | E5: #VALUE! | F5: 201402 | G5: 201401 | H5: 201403 | I5: 201404 | J5: 201405 | K5: 200405 | L5: 201406 | M5: 총합계 | S5: 업체 | T5: 브랜드/품목2 | U5: 실발주월 | V5: 190001 | W5: #VALUE! | X5: 201402 | Y5: 201401 | Z5: 201403 | AA5: 201404 | AB5: 201405 | AC5: 200405 | AD5: 201406 | AE5: 총합계
A6: ELS-의류 | B6: JP | C6: 201401 | F6: 5 | M6: 5 | S6: 동일모자 | T6: JIL | U6: 201401 | Y6: 1 | AE6: 1 | AK6: 실발주샘플수 | AN6: 입고주 | BO6: 실발주샘플수 | BR6: 입고주 | CS6: 실발주샘플수 | CT6: 입고주 | DP6: 실발주샘플수 | DQ6: 입고주
C7: 201402 | H7: 2 | M7: 2 | T7: JIL 요약 | Y7: 1 | AE7: 1 | AK7: 브랜드/품목 | AL7: 해외/국내 | AM7: 발주주 | AN7: 3월 2주 | AO7: 3월 1주 | AP7: 2월 4주 | AQ7: 2월 3주 | AR7: 2월 2주 | AS7: 1월 5주 | AT7: #N/A | AU7: 총합계 | BO7: 브랜드/품목 | BP7: 해외/국내 | BQ7: 발주주 | BR7: 3월 2주 | BS7: 3월 1주 | BT7: 2월 4주 | BU7: 2월 3주 | BV7: 2월 2주 | BW7: #N/A | BX7: 총합계 | CS7: 브랜드/품목 | CT7: 3월 2주 | CU7: 3월 1주 | CV7: 2월 4주 | CW7: 2월 3주 | CX7: 2월 2주 | CY7: 1월 5주 | CZ7: #N/A | DA7: 총합계 | DP7: 브랜드/품목 | DQ7: 3월 2주 | DR7: 3월 1주 | DS7: 2월 4주 | DT7: 2월 3주 | DU7: 2월 2주 | DV7: #N/A | DW7: 총합계
C8: 201403 | H8: 1 | M8: 1 | T8: JOI | U8: 201401 | Z8: 1 | AA8: 2 | AE8: 3 | AK8: NOV | AL8: 해외 | AM8: 1월 5주 | AN8: 6 | AU8: 6 | BO8: DPS | BP8: 국내 | BQ8: 3월 2주 | BR8: 2 | BX8: 2 | CS8: NOV | CT8: 11 | DA8: 11 | DP8: DPS | DQ8: 7 | DW8: 7
B9: JP 요약 | F9: 5 | H9: 3 | M9: 8 | U9: 201404 | AB9: 4 | AE9: 4 | AK9: NOV 요약 | AN9: 6 | AU9: 6 | BP9: 해외 | BQ9: 3월 2주 | BR9: 5 | BX9: 5 | CS9: BMD | CT9: 7 | CX9: 3 | DA9: 10 | DP9: DPS-가방 | DQ9: 4 | DW9: 4
B10: HP | C10: 201402 | H10: 5 | M10: 5 | T10: JOI 요약 | Z10: 1 | AA10: 2 | AB10: 4 | AE10: 7 | AK10: BMD | AL10: 해외 | AM10: 1월 3주 | AR10: 3 | AU10: 3 | BO10: DPS 요약 | BR10: 7 | BX10: 7 | CS10: BRO | CT10: 11 | DA10: 11 | DP10: DPS-의류 | DQ10: 4 | DW10: 4
C11: 201404 | I11: 2 | M11: 2 | T11: ELS | U11: 201401 | Z11: 10 | AE11: 10 | AK11: BMD 요약 | AR11: 3 | AU11: 3 | BO11: DPS-가방 | BP11: 해외 | BQ11: 3월 2주 | BR11: 4 | BX11: 4 | CS11: DPS | CT11: 12 | DA11: 12 | DP11: ELS | DQ11: 15 | DR11: 1 | DW11: 16
B12: HP 요약 | H12: 5 | I12: 2 | M12: 7 | U12: 201403 | AA12: 8 | AE12: 8 | AK12: BRO | AL12: 해외 | AM12: 1월 4주 | AN12: 8 | AU12: 8 | BO12: DPS-가방 요약 | BR12: 4 | BX12: 4 | CS12: DPS-가방 | CT12: 5 | DA12: 5 | DP12: ELS-ACC | DQ12: 2 | DW12: 2
B13: TH | C13: 201402 | H13: 8 | M13: 8 | U13: 201404 | AA13: 9 | AE13: 9 | AK13: BRO 요약 | AN13: 8 | AU13: 8 | BO13: DPS-의류 | BP13: 해외 | BQ13: 3월 2주 | BR13: 4 | BX13: 4 | CS13: DPS-의류 | CT13: 14 | DA13: 14 | DP13: ELS-가방 | DQ13: 4 | DW13: 4
C14: 201403 | H14: 6 | M14: 6 | T14: ELS 요약 | Z14: 10 | AA14: 17 | AE14: 27 | AK14: ELS | AL14: 해외 | AM14: 1월 4주 | AN14: 17 | AO14: 12 | AU14: 29 | BO14: DPS-의류 요약 | BR14: 4 | BX14: 4 | CS14: ELS | CT14: 53 | CU14: 11 | DA14: 64 | DP14: ELS-의류 | DQ14: 44 | DT14: 1 | DW14: 45
B15: TH 요약 | H15: 14 | M15: 14 | T15: SMB | U15: 201401 | Z15: 6 | AE15: 6 | AK15: ELS 요약 | AN15: 17 | AO15: 12 | AU15: 29 | BO15: ELS | BP15: 해외 | BQ15: 1월 4주 | BS15: 1 | BX15: 1 | CS15: ELS-ACC | CU15: 2 | DA15: 2 | DP15: JAY.PARK | DU15: 5 | DW15: 5
B16: TL | C16: 201402 | H16: 12 | M16: 12 | U16: 201403 | V16: 1 | AA16: 17.5 | AE16: 18.5 | AK16: ELS-ACC | AL16: 해외 | AM16: 1월 4주 | AN16: 2 | AO16: 2 | AU16: 4 | BQ16: 3월 1주 | BR16: 7 | BX16: 7 | CS16: ELS-가방 | CT16: 6 | DA16: 6 | DP16: JIL | DQ16: 13.5 | DW16: 13.5
C17: 201403 | H17: 14 | I17: 5 | M17: 19 | T17: SMB 요약 | V17: 1 | Z17: 6 | AA17: 17.5 | AE17: 24.5 | AK17: ELS-ACC 요약 | AN17: 2 | AO17: 2 | AU17: 4 | BQ17: 3월 2주 | BR17: 8 | BX17: 8 | CS17: ELS-의류 | CT17: 24 | CW17: 4 | DA17: 28 | DP17: JIL-ACC | DQ17: 1 | DW17: 1
B18: TL 요약 | H18: 26 | I18: 5 | M18: 31 | T18: BRO | U18: 201401 | Z18: 8 | AE18: 8 | AK18: ELS-의류 | AL18: 해외 | AM18: 1월 1주 | AQ18: 1 | AU18: 1 | BO18: ELS 요약 | BR18: 15 | BS18: 1 | BX18: 16 | CS18: HCU | CT18: 13 | DA18: 13 | DP18: JOI | DQ18: 18.333333 | DV18: 0.66666667 | DW18: 19
B19: PT | C19: 201403 | H19: 4 | I19: 2 | M19: 6 | U19: 201402 | Z19: 3 | AE19: 3 | AM19: 1월 3주 | AQ19: 4 | AU19: 4 | BO19: ELS-ACC | BP19: 해외 | BQ19: 1월 4주 | BR19: 2 | BX19: 2 | CS19: JAY.PARK | CX19: 5 | DA19: 5 | DP19: JOI-ACC | DQ19: 16 | DW19: 16
B20: PT 요약 | H20: 4 | I20: 2 | M20: 6 | T20: BRO 요약 | Z20: 11 | AE20: 11 | AK20: ELS-의류 요약 | AQ20: 5 | AU20: 5 | BO20: ELS-ACC 요약 | BR20: 2 | BX20: 2 | CS20: JIL | CT20: 170.5 | CU20: 2 | CY20: 1 | DA20: 173.5 | DP20: JOI-가방 | DQ20: 3 | DW20: 3
B21: OP | C21: 201403 | H21: 1 | M21: 1 | T21: BMD | U21: 201401 | X21: 3 | AE21: 3 | AK21: JIL | AL21: 해외 | AM21: 1월 3주 | AN21: 14 | AS21: 1 | AU21: 15 | BO21: ELS-가방 | BP21: 해외 | BQ21: 3월 2주 | BR21: 4 | BX21: 4 | CS21: JIL-ACC | CT21: 5 | DA21: 5 | DP21: KONGHYOJIN | DR21: 6 | DW21: 6
B22: OP 요약 | H22: 1 | M22: 1 | U22: 201402 | AB22: 1 | AE22: 1 | AK22: JIL 요약 | AN22: 14 | AS22: 1 | AU22: 15 | BO22: ELS-가방 요약 | BR22: 4 | BX22: 4 | CS22: JOI | CT22: 5 | DA22: 5 | DP22: POL | DQ22: 13.333333 | DV22: 2.6666667 | DW22: 16
B23: SP | C23: 201403 | I23: 5 | M23: 5 | U23: 201403 | AA23: 1.5 | AE23: 1.5 | AK23: JOI | AL23: 해외 | AM23: 1월 3주 | AN23: 3 | AU23: 3 | BO23: ELS-의류 | BP23: 국내 | BQ23: 2월 3주 | BR23: 3 | BX23: 3 | CS23: JOI-ACC | CT23: 3 | DA23: 3 | DP23: SMB | DQ23: 65 | DR23: 1 | DS23: 1 | DV23: 4 | DW23: 71
B24: SP 요약 | I24: 5 | M24: 5 | T24: BMD 요약 | X24: 3 | AA24: 1.5 | AB24: 1 | AE24: 5.5 | AM24: 1월 4주 | AN24: 10 | AU24: 10 | BQ24: 3월 2주 | BR24: 13 | BX24: 13 | CS24: KONGHYOJIN | CU24: 6 | DA24: 6 | DP24: WTR | DQ24: 12 | DW24: 12
B25: VE | C25: 201403 | I25: 1 | M25: 1 | T25: WTR | U25: 201402 | Z25: 6 | AE25: 6 | AK25: JOI 요약 | AN25: 13 | AU25: 13 | BP25: 해외 | BQ25: 1월 3주 | BU25: 1 | BX25: 1 | CS25: MR.REAL GOODMAN | CT25: 3.5 | CV25: 9.5 | CW25: 5 | DA25: 18 | DP25: (비어 있음) | DV25: 0.5 | DW25: 0.5
B26: VE 요약 | I26: 1 | M26: 1 | U26: 201403 | AA26: 3 | AE26: 3 | AK26: JOI-ACC | AL26: 해외 | AM26: 1월 4주 | AN26: 7 | AU26: 7 | BQ26: 2월 3주 | BR26: 4 | BX26: 4 | CS26: NAA | CT26: 15 | DA26: 15 | DP26: 총합계 | DQ26: 222.16667 | DR26: 8 | DS26: 1 | DT26: 1 | DU26: 5 | DV26: 7.8333333 | DW26: 245
A27: ELS-의류 요약 | F27: 5 | H27: 53 | I27: 15 | M27: 73 | T27: WTR 요약 | Z27: 6 | AA27: 3 | AE27: 9 | AK27: JOI-ACC 요약 | AN27: 7 | AU27: 7 | BQ27: 2월 4주 | BR27: 3 | BX27: 3 | CS27: NOV-ACC | CT27: 4 | DA27: 4
A28: ELS-가방 | B28: BP | C28: 201403 | H28: 1 | I28: 5 | M28: 6 | T28: HCU | U28: 201402 | Z28: 7 | AA28: 6 | AE28: 13 | AK28: MR.REAL GOODMAN | AL28: 국내 | AM28: 1월 3주 | AP28: 6.5 | AU28: 6.5 | BQ28: 3월 1주 | BR28: 1 | BX28: 1 | CS28: PLA | CT28: 12 | CU28: 4 | DA28: 16
C29: 201405 | J29: 2 | M29: 2 | T29: HCU 요약 | Z29: 7 | AA29: 6 | AE29: 13 | AK29: MR.REAL GOODMAN 요약 | AP29: 6.5 | AU29: 6.5 | BQ29: 3월 2주 | BR29: 20 | BX29: 20 | CS29: PLA-의류 | CT29: 25 | CU29: 1 | DA29: 26
B30: BP 요약 | H30: 1 | I30: 5 | J30: 2 | M30: 8 | T30: MR.REAL GOODMAN | U30: 201402 | X30: 5 | Z30: 2 | AE30: 7 | AK30: PLA | AL30: 해외 | AM30: 1월 3주 | AN30: 6 | AO30: 4 | AU30: 10 | BO30: ELS-의류 요약 | BR30: 44 | BU30: 1 | BX30: 45 | CS30: SMB | CT30: 65 | CU30: 1 | CV30: 1 | CZ30: 4 | DA30: 71
B31: SB | C31: 201403 | H31: 2 | M31: 2 | T31: MR.REAL GOODMAN 요약 | X31: 5 | Z31: 2 | AE31: 7 | AK31: PLA 요약 | AN31: 6 | AO31: 4 | AU31: 10 | BO31: JAY.PARK | BP31: 국내 | BQ31: 2월 1주 | BV31: 5 | BX31: 5 | CS31: URB | CT31: 42 | DA31: 42
B32: SB 요약 | H32: 2 | M32: 2 | T32: POL | U32: 201403 | AA32: 6 | AE32: 6 | AK32: SMB | AL32: 해외 | AM32: 1월 4주 | AN32: 19.5 | AO32: 1 | AP32: 1 | AT32: 1 | AU32: 22.5 | BO32: JAY.PARK 요약 | BV32: 5 | BX32: 5 | CS32: URB-가방 | CT32: 4 | DA32: 4
A33: ELS-가방 요약 | H33: 3 | I33: 5 | J33: 2 | M33: 10 | U33: 201404 | AA33: 2 | AE33: 2 | AK33: SMB 요약 | AN33: 19.5 | AO33: 1 | AP33: 1 | AT33: 1 | AU33: 22.5 | BO33: JIL | BP33: 해외 | BQ33: 2월 4주 | BR33: 3 | BX33: 3 | CS33: URB-의류 | CT33: 8 | DA33: 8
A34: ELS-ACC | B34: ED | C34: 201401 | H34: 2 | I34: 2 | M34: 4 | T34: POL 요약 | AA34: 8 | AE34: 8 | AK34: VBL | AL34: 해외 | AM34: 1월 4주 | AN34: 13 | AU34: 13 | BQ34: 3월 1주 | BR34: 2 | BX34: 2 | CS34: VBL | CT34: 13 | DA34: 13
B35: ED 요약 | H35: 2 | I35: 2 | M35: 4 | S35: 동일모자 요약 | V35: 1 | X35: 8 | Y35: 1 | Z35: 43 | AA35: 55 | AB35: 5 | AE35: 113 | AK35: VBL 요약 | AN35: 13 | AU35: 13 | BQ35: 3월 2주 | BR35: 8.5 | BX35: 8.5 | CS35: VBL-의류 | CT35: 1.5 | CU35: 2.5 | DA35: 4
A36: ELS-ACC 요약 | H36: 2 | I36: 2 | M36: 4 | S36: 성진 | T36: ELS | U36: 201401 | Z36: 9 | AE36: 9 | AK36: 총합계 | AN36: 105.5 | AO36: 19 | AP36: 7.5 | AQ36: 5 | AR36: 3 | AS36: 1 | AT36: 1 | AU36: 142 | BO36: JIL 요약 | BR36: 13.5 | BX36: 13.5 | CS36: WTR | CT36: 12 | DA36: 12
A37: PLA-의류 | B37: JP | C37: 201403 | H37: 2 | I37: 3 | M37: 5 | U37: 201403 | AA37: 3 | AE37: 3 | BO37: JIL-ACC | BP37: 해외 | BQ37: 3월 2주 | BR37: 1 | BX37: 1 | CS37: YGF | CT37: 19 | DA37: 19
B38: JP 요약 | H38: 2 | I38: 3 | M38: 5 | U38: 201404 | AB38: 3 | AE38: 3 | BO38: JIL-ACC 요약 | BR38: 1 | BX38: 1 | CS38: (비어 있음) | CZ38: 0.5 | DA38: 0.5
B39: HP | C39: 201403 | H39: 1 | I39: 2 | M39: 3 | T39: ELS 요약 | Z39: 9 | AA39: 3 | AB39: 3 | AE39: 15 | BO39: JOI | BP39: 해외 | BQ39: 1월 3주 | BR39: 3 | BX39: 3 | CS39: 총합계 | CT39: 563.5 | CU39: 29.5 | CV39: 10.5 | CW39: 9 | CX39: 8 | CY39: 1 | CZ39: 4.5 | DA39: 626
C40: 201404 | I40: 1 | M40: 1 | T40: SMB | U40: 190001 | V40: 1 | AE40: 1 | BQ40: 1월 4주 | BR40: 5 | BX40: 5
...

Sheet 샘플별업체 아이템별
A1: 14FW SAMPLE LIST (HATS ON) | G1: 1/2월 | H1: 356 | I1: 310 | K1: 14FW SAMPLE LIST (HATS ON) 품목별 | W1: 14FW SAMPLE LIST (HATS ON) 업체별 | AE1: 14FW SAMPLE LIST (HATS ON) 중국원단 사용 | AL1: 1/2월 | AM1: 356 | AN1: 356
G2: 3월 | H2: 263 | I2: 91 | K2: 러닝(R)/신규(N) | L2: (모두) | P2: 41752 | W2: 러닝(R)/신규(N) | X2: (모두) | AE2: 러닝(R)/신규(N) | AF2: (모두) | AK2: 41780 | AL2: 3/4월 | AM2: 373 | AN2: 302
A3: *실발주샘플수=중복 발주 및 입고 스타일은 1ST로 계산 | G3: 4월 | H3: 11 | I3: 0 | K3: *실발주샘플수=중복 발주 및 입고 스타일은 1ST로 계산 | N3: HP:후드점퍼, JP:점퍼, TH:후드, TL: 맨투맨,롱슬리브, PT:바지 | W3: *실발주샘플수=중복 발주 및 입고 스타일은 1ST로 계산 | AE3: *실발주샘플수=중복 발주 및 입고 스타일은 1ST로 계산 | AK3: =GETPIVOTDATA(" 중국원단사용수",$AE$4)/GETPIVOTDATA(" 원단총수",$AE$4) -> 0.685623 | AL3: 5월 | AM3: 31 | AN3: 2
H4: 데이터 | N4: 데이터 | X4: 데이터 | AH4: 데이터
A5: 브랜드/품목2 | B5: 품목 | C5: 샘플번호 | D5: 업체 | E5: 발주일 | F5: 입고일 | G5: 총입고샘플건수 | H5: 실발주샘플수 | I5: 실입고샘플수 | K5: 품목 | L5: 브랜드 | M5: 업체 | N5: 실발주샘플수 | O5: 실입고샘플수 | P5: 총입고샘플건수 | Q5: 미입고샘플수 | R5: 총미입고샘플건수 | W5: 업체 | X5: 실발주샘플수 | Y5: 총발주샘플건수 | Z5: 실입고샘플수 | AA5: 총입고샘플건수 | AB5: 미입고샘플수 | AC5: 총미입고샘플건수 | AE5: 브랜드/품목 | AF5: 업체 | AG5: 품목 | AH5: 실발주샘플건수 | AI5: 총발주샘플건수 | AJ5: 원단총수 | AK5: 중국원단사용수 | AL5: 총입고샘플건수 | AM5: 미입고샘플수 | AN5: 총미입고샘플건수
A6: ELS-의류 | B6: HP | C6: 14FW - ELSTINKO - HZ04- WH -KIDS | D6: EVERGREEN | E6: 41730 | F6: 41739 | G6: 1 | H6: 1 | I6: 1 | J6: =K6&L6&M6 -> BANOVFOREMOST | K6: BA | L6: NOV | M6: FOREMOST | N6: 5 | O6: 5 | P6: 5 | Q6: 0 | R6: 0 | W6: 동일모자 | X6: 112.5 | Y6: 116 | Z6: 113 | AA6: 116 | AB6: -0.5 | AC6: 0 | AE6: NOV | AF6: FOREMOST | AG6: BA | AH6: 5 | AI6: 5 | AJ6: 19 | AK6: 14 | AL6: 5 | AM6: 0 | AN6: 0
C7: 14FW - ELSTINKO - HZ05- P4.N9 -KIDS | D7: EVERGREEN | E7: 41730 | F7: 41739 | G7: 0.5 | H7: 1 | I7: 1 | J7: =K7&L7&M7 -> BRO동일모자 | L7: BRO | M7: 동일모자 | N7: 1 | O7: 1 | P7: 1 | Q7: 0 | R7: 0 | W7: 성진 | X7: 58.5 | Y7: 60 | Z7: 50.5 | AA7: 52 | AB7: 8 | AC7: 8 | AG7: TP | AH7: 5 | AI7: 5 | AJ7: 18 | AK7: 11 | AL7: 5 | AM7: 0 | AN7: 0
B8: HP 요약 | H8: 2 | I8: 2 | J8: =K8&L8&M8 -> ELS동일모자 | L8: ELS | M8: 동일모자 | N8: 1 | O8: 1 | P8: 1 | Q8: 0 | R8: 0 | W8: FOREMOST | X8: 224 | Y8: 244 | Z8: 198.5 | AA8: 212 | AB8: 25.5 | AC8: 32 | AG8: FA | AH8: 1 | AI8: 1 | AJ8: 3 | AK8: 2 | AL8: 1 | AM8: 0 | AN8: 0
B9: JP | C9: 14FW_ELSTINKO_DOWN_JUMPER_05_RD_KIDS | D9: 대경 | E9: 41701 | F9: 41719 | G9: 1 | H9: 1 | I9: 1 | J9: =K9&L9&M9 -> JILFOREMOST | L9: JIL | M9: FOREMOST | N9: 16 | O9: 16 | P9: 16 | Q9: 0 | R9: 0 | W9: QF | X9: 89 | Y9: 98 | Z9: 61 | AA9: 70 | AB9: 28 | AC9: 28 | AF9: FOREMOST 요약 | AH9: 11 | AI9: 11 | AJ9: 40 | AK9: 27 | AL9: 11 | AM9: 0 | AN9: 0
B10: JP 요약 | H10: 1 | I10: 1 | J10: =K10&L10&M10 -> SMB동일모자 | L10: SMB | M10: 동일모자 | N10: 7 | O10: 7 | P10: 7 | Q10: 0 | R10: 0 | W10: (비어 있음) | AB10: 0 | AC10: 0 | AE10: BMD | AF10: 동일모자 | AG10: BA | AH10: 1.5 | AI10: 2 | AJ10: 6 | AK10: 6 | AL10: 2 | AM10: -0.5 | AN10: 0
B11: TH | C11: 14FW ELSTINKO_HOOD_15_PK_KIDS | D11: 아트인드림 | E11: 41709 | F11: 41722 | G11: 1 | H11: 1 | I11: 1 | J11: =K11&L11&M11 -> 성진 | M11: 성진 | N11: 8.5 | O11: 8.5 | P11: 9 | Q11: 0 | R11: 0 | W11: KIDS FIRST TOYS | X11: 25.833333 | Y11: 35 | Z11: 9.5 | AA11: 13 | AB11: 16.333333 | AC11: 22 | AG11: ER | AH11: 2 | AI11: 2 | AJ11: 6 | AK11: 6 | AL11: 2 | AM11: 0 | AN11: 0
C12: 14FW - ELSTINKO - HD16- MI - KIDS | D12: piafield | E12: 41715 | F12: 41722 | G12: 1 | H12: 1 | I12: 1 | J12: =K12&L12&M12 -> QF | M12: QF | N12: 5 | O12: 5 | P12: 5 | Q12: 0 | R12: 0 | W12: 캡보이2 | X12: 5 | Y12: 6 | Z12: 5 | AA12: 6 | AB12: 0 | AC12: 0 | AG12: FI | AH12: 2 | AI12: 2 | AJ12: 3 | AK12: 3 | AL12: 2 | AM12: 0 | AN12: 0
C13: 14FW - ELSTINKO - HD17- Y6 - KIDS | D13: piafield | E13: 41715 | F13: 41722 | G13: 1 | H13: 1 | I13: 1 | J13: =K13&L13&M13 -> 캡보이2 | M13: 캡보이2 | N13: 1.5 | O13: 1.5 | P13: 2 | Q13: 0 | R13: 0 | W13: 캡보이 | X13: 40.5 | Y13: 42 | Z13: 34.5 | AA13: 36 | AB13: 6 | AC13: 6 | AF13: 동일모자 요약 | AH13: 5.5 | AI13: 6 | AJ13: 15 | AK13: 15 | AL13: 6 | AM13: -0.5 | AN13: 0
C14: 14FW - ELSTINKO - HD18- GR - KIDS | D14: piafield | E14: 41715 | F14: 41722 | G14: 1 | H14: 1 | I14: 1 | J14: =K14&L14&M14 -> VBLFOREMOST | L14: VBL | M14: FOREMOST | N14: 6 | O14: 6 | P14: 6 | Q14: 0 | R14: 0 | W14: J&F | X14: 15 | Y14: 23 | Z14: 15 | AA14: 23 | AB14: 0 | AC14: 0 | AF14: FOREMOST | AG14: BA | AH14: 3 | AI14: 3 | AL14: 3 | AM14: 3 | AN14: 3
C15: 14FW - ELSTINKO - HD19- Pi - KIDS | D15: piafield | E15: 41715 | F15: 41723 | G15: 1 | H15: 1 | I15: 1 | J15: =K15&L15&M15 -> WTR동일모자 | L15: WTR | M15: 동일모자 | N15: 3 | O15: 3 | P15: 3 | Q15: 0 | R15: 0 | W15: 대경 | X15: 32 | Y15: 32 | Z15: 32 | AA15: 32 | AB15: 0 | AC15: 0 | AG15: MI | AH15: 1.5 | AI15: 2 | AL15: 2 | AM15: 1.5 | AN15: 2
C16: 14FW - ELSTINKO - HD20- CA - KIDS | D16: piafield | E16: 41715 | F16: 41722 | G16: 1 | H16: 1 | I16: 1 | J16: =K16&L16&M16 -> FOREMOST | M16: FOREMOST | N16: 2 | O16: 2 | P16: 2 | Q16: 0 | R16: 0 | W16: 아트인드림 | X16: 37 | Y16: 37 | Z16: 31 | AA16: 31 | AB16: 6 | AC16: 6 | AF16: FOREMOST 요약 | AH16: 4.5 | AI16: 5 | AL16: 5 | AM16: 4.5 | AN16: 5
B17: TH 요약 | H17: 6 | I17: 6 | J17: =K17&L17&M17 -> JOI동일모자 | L17: JOI | M17: 동일모자 | N17: 7 | O17: 7 | P17: 7 | Q17: 0 | R17: 0 | W17: Y&Y | X17: 60 | Y17: 65 | Z17: 49 | AA17: 52 | AB17: 11 | AC17: 13 | AE17: BRO | AF17: 동일모자 | AG17: BA | AH17: 1 | AI17: 1 | AJ17: 2 | AK17: 2 | AL17: 1 | AM17: 0 | AN17: 0
B18: TL | C18: 14FW ELSTINKO_MTM_12_PK_KIDS | D18: 대경 | E18: 41709 | F18: 41719 | G18: 1 | H18: 1 | I18: 1 | J18: =K18&L18&M18 -> BMD동일모자 | L18: BMD | M18: 동일모자 | N18: 1.5 | O18: 2 | P18: 2 | Q18: -0.5 | R18: 0 | W18: NT SENHONG | X18: 4 | Y18: 9 | Z18: 5 | AA18: 9 | AB18: -1 | AC18: 0 | AG18: ER | AH18: 9 | AI18: 9 | AJ18: 33 | AK18: 24 | AL18: 9 | AM18: 0 | AN18: 0
C19: 14FW ELSTINKO_MTM_13_RE_KIDS | D19: EVERGREEN | E19: 41709 | F19: 41719 | G19: 1 | H19: 1 | I19: 1 | J19: =K19&L19&M19 -> FOREMOST | M19: FOREMOST | N19: 3 | O19: 0 | P19: 0 | Q19: 3 | R19: 3 | W19: ORIENT | X19: 3 | Y19: 6 | Z19: 3 | AA19: 6 | AB19: 0 | AC19: 0 | AG19: MI | AH19: 1 | AI19: 1 | AJ19: 4 | AK19: 3 | AL19: 1 | AM19: 0 | AN19: 0
C20: 14FW ELSTINKO_MTM_14_NY_KIDS | D20: EVERGREEN | E20: 41709 | F20: 41725 | G20: 1 | H20: 1 | I20: 1 | J20: =K20&L20&M20 -> POL동일모자 | L20: POL | M20: 동일모자 | N20: 6 | O20: 6 | P20: 6 | Q20: 0 | R20: 0 | W20: EVERGREEN | X20: 18 | Y20: 18 | Z20: 18 | AA20: 18 | AB20: 0 | AC20: 0 | AF20: 동일모자 요약 | AH20: 11 | AI20: 11 | AJ20: 39 | AK20: 29 | AL20: 11 | AM20: 0 | AN20: 0
C21: 14FW - ELSTINKO - MTM15- BL - KIDS | D21: piafield | E21: 41715 | F21: 41722 | G21: 1 | H21: 1 | I21: 1 | J21: =K21&L21&M21 -> BA 요약 | K21: BA 요약 | N21: 73.5 | O21: 71 | P21: 72 | Q21: 2.5 | R21: 3 | W21: piafield | X21: 22 | Y21: 22 | Z21: 21 | AA21: 21 | AB21: 1 | AC21: 1 | AE21: ELS | AF21: 동일모자 | AG21: BA | AH21: 1 | AI21: 1 | AJ21: 4 | AK21: 0 | AL21: 1 | AM21: 0 | AN21: 0
C22: 14FW - ELSTINKO - MTM15- RE - KIDS | D22: piafield | E22: 41715 | F22: 41722 | G22: 1 | H22: 1 | I22: 1 | J22: =K22&L22&M22 -> BPELS바이칼 | K22: BP | L22: ELS | M22: 바이칼 | N22: 8 | O22: 8 | P22: 8 | Q22: 0 | R22: 0 | W22: FILL 21 | X22: 2 | Y22: 4 | Z22: 2 | AA22: 4 | AB22: 0 | AC22: 0 | AG22: ER | AH22: 11 | AI22: 11 | AJ22: 50 | AK22: 31 | AL22: 11 | AM22: 0 | AN22: 0
C23: 14FW - ELSTINKO - MTM16- GR - KIDS | D23: piafield | E23: 41715 | F23: 41722 | G23: 1 | H23: 1 | I23: 1 | J23: =K23&L23&M23 -> JOIKIDS FIRST TOYS | L23: JOI | M23: KIDS FIRST TOYS | N23: 3 | O23: 0 | P23: 0 | Q23: 3 | R23: 3 | W23: 바이칼 | X23: 23 | Y23: 23 | Z23: 10 | AA23: 10 | AB23: 13 | AC23: 13 | AG23: TP | AH23: 3 | AI23: 3 | AJ23: 15 | AK23: 9 | AL23: 3 | AM23: 0 | AN23: 0
C24: 14FW - ELSTINKO - MTM17- YO - KIDS | D24: piafield | E24: 41715 | F24: 41723 | G24: 1 | H24: 1 | I24: 1 | J24: =K24&L24&M24 -> URB바이칼 | L24: URB | M24: 바이칼 | N24: 4 | O24: 0 | P24: 0 | Q24: 4 | R24: 4 | W24: 유건 | X24: 2 | Y24: 2 | Z24: 2 | AA24: 2 | AB24: 0 | AC24: 0 | AG24: FI | AH24: 4 | AI24: 4 | AJ24: 10 | AK24: 6 | AL24: 4 | AM24: 0 | AN24: 0
C25: 14FW - ELSTINKO - MTM18- PI - KIDS | D25: piafield | E25: 41715 | F25: 41722 | G25: 1 | H25: 1 | I25: 1 | J25: =K25&L25&M25 -> DPS바이칼 | L25: DPS | M25: 바이칼 | N25: 9 | O25: 0 | P25: 0 | Q25: 9 | R25: 9 | W25: HADSOCK | X25: 2 | Y25: 4 | Z25: 2 | AA25: 4 | AB25: 0 | AC25: 0 | AG25: SN | AH25: 8 | AI25: 8 | AJ25: 16 | AK25: 12 | AL25: 8 | AM25: 0 | AN25: 0
C26: 14FW - ELSTINKO - MTM19- GR - KIDS | D26: piafield | E26: 41715 | F26: 41723 | G26: 1 | H26: 1 | I26: 1 | J26: =K26&L26&M26 -> BP 요약 | K26: BP 요약 | N26: 24 | O26: 8 | P26: 8 | Q26: 16 | R26: 16 | W26: EVERRICH TEXTILE | X26: 0.66666667 | Y26: 2 | Z26: 0 | AA26: 0 | AB26: 0.66666667 | AC26: 2 | AF26: 동일모자 요약 | AH26: 27 | AI26: 27 | AJ26: 95 | AK26: 58 | AL26: 27 | AM26: 0 | AN26: 0
C27: 14FW - ELSTINKO - MTM20- BK - KIDS | D27: piafield | E27: 41715 | F27: 41722 | G27: 1 | H27: 1 | I27: 1 | J27: =K27&L27&M27 -> ERBRO동일모자 | K27: ER | L27: BRO | M27: 동일모자 | N27: 9 | O27: 9 | P27: 9 | Q27: 0 | R27: 0 | W27: 총합계 | X27: 776 | Y27: 848 | Z27: 662 | AA27: 717 | AB27: 114 | AC27: 131 | AF27: 성진 | AG27: ER | AH27: 3 | AI27: 3 | AJ27: 9 | AK27: 6 | AL27: 3 | AM27: 0 | AN27: 0
C28: 14FW - ELSTINKO - MTM21- WH - KIDS | D28: 아트인드림 | E28: 41715 | F28: 41740 | G28: 0 | H28: 1 | I28: 0 | J28: =K28&L28&M28 -> ELS동일모자 | L28: ELS | M28: 동일모자 | N28: 11 | O28: 11 | P28: 11 | Q28: 0 | R28: 0 | AG28: FI | AH28: 9 | AI28: 9 | AJ28: 24 | AK28: 13 | AL28: 9 | AM28: 0 | AN28: 0
C29: 14FW - ELSTINKO - MTM21- OR - KIDS | D29: 아트인드림 | E29: 41715 | F29: 41723 | G29: 1 | H29: 1 | I29: 1 | J29: =K29&L29&M29 -> 성진 | M29: 성진 | N29: 3 | O29: 3 | P29: 3 | Q29: 0 | R29: 0 | AG29: SN | AH29: 3 | AI29: 3 | AJ29: 7 | AK29: 4 | AL29: 3 | AM29: 3 | AN29: 3
C30: 14FW - ELSTINKO - MTM21- BL - KIDS | D30: 아트인드림 | E30: 41715 | F30: 41740 | G30: 0 | H30: 1 | I30: 0 | J30: =K30&L30&M30 -> FOREMOST | M30: FOREMOST | N30: 1 | O30: 1 | P30: 1 | Q30: 0 | R30: 0 | AF30: 성진 요약 | AH30: 15 | AI30: 15 | AJ30: 40 | AK30: 23 | AL30: 15 | AM30: 3 | AN30: 3
C31: 14FW - ELSTINKO - MTM22-WH | D31: 아트인드림 | E31: 41715 | F31: 41726 | G31: 0 | H31: 1 | I31: 0 | J31: =K31&L31&M31 -> QF | M31: QF | N31: 2 | O31: 2 | P31: 2 | Q31: 0 | R31: 0 | AF31: FOREMOST | AG31: ER | AH31: 1 | AI31: 1 | AJ31: 3 | AK31: 1 | AL31: 1 | AM31: 0 | AN31: 0
C32: 14FW - ELSTINKO - MTM22-OR | D32: 아트인드림 | E32: 41715 | F32: 41740 | G32: 0 | H32: 1 | I32: 0 | J32: =K32&L32&M32 -> JILFOREMOST | L32: JIL | M32: FOREMOST | N32: 50.5 | O32: 49.5 | P32: 52 | Q32: 1 | R32: 1 | AG32: TP | AH32: 13 | AI32: 13 | AJ32: 38 | AK32: 33 | AL32: 13 | AM32: 6 | AN32: 6
C33: 14FW - ELSTINKO - MTM22-BL | D33: 아트인드림 | E33: 41715 | F33: 41740 | G33: 0 | H33: 1 | I33: 0 | J33: =K33&L33&M33 -> KIDS FIRST TOYS | M33: KIDS FIRST TOYS | N33: 1 | O33: 1 | P33: 1 | Q33: 0 | R33: 0 | AG33: BE | AH33: 9 | AI33: 9 | AJ33: 20 | AK33: 20 | AL33: 9 | AM33: 0 | AN33: 0
C34: 14FW - ELSTINKO -MTM23- BK - KIDS | D34: 아트인드림 | E34: 41715 | F34: 41723 | G34: 1 | H34: 1 | I34: 1 | J34: =K34&L34&M34 -> Y&Y | M34: Y&Y | N34: 15 | O34: 14 | P34: 14 | Q34: 1 | R34: 1 | AG34: FA | AH34: 2 | AI34: 2 | AJ34: 5 | AK34: 4 | AL34: 2 | AM34: 0 | AN34: 0
C35: 14FW - ELSTINKO -MTM23- BK | D35: 아트인드림 | E35: 41715 | F35: 41723 | G35: 1 | H35: 1 | I35: 1 | J35: =K35&L35&M35 -> ORIENT | M35: ORIENT | N35: 2.5 | O35: 2.5 | P35: 5 | Q35: 0 | R35: 0 | AF35: FOREMOST 요약 | AH35: 25 | AI35: 25 | AJ35: 66 | AK35: 58 | AL35: 25 | AM35: 6 | AN35: 6
C36: 14FW - ELSTINKO - MTM25- BK -KIDS | D36: 아트인드림 | E36: 41715 | F36: 41740 | G36: 0 | H36: 1 | I36: 0 | J36: =K36&L36&M36 -> SMB동일모자 | L36: SMB | M36: 동일모자 | N36: 12.5 | O36: 12.5 | P36: 13 | Q36: 0 | R36: 0 | AF36: QF | AG36: ER | AH36: 2 | AI36: 2 | AJ36: 9 | AK36: 7 | AL36: 2 | AM36: 0 | AN36: 0
B37: TL 요약 | H37: 19 | I37: 13 | J37: =K37&L37&M37 -> 성진 | M37: 성진 | N37: 5 | O37: 5 | P37: 5 | Q37: 0 | R37: 0 | AG37: FI | AH37: 5 | AI37: 5 | AJ37: 10 | AK37: 7 | AL37: 5 | AM37: 3 | AN37: 3
B38: PT | C38: 14FW ELSTINKO_PANTS_01_BK | D38: 아트인드림 | E38: 41709 | F38: 41722 | G38: 1 | H38: 1 | I38: 1 | J38: =K38&L38&M38 -> FOREMOST | M38: FOREMOST | N38: 2 | O38: 2 | P38: 2 | Q38: 0 | R38: 0 | AG38: SN | AH38: 1 | AI38: 1 | AJ38: 2 | AK38: 2 | AL38: 1 | AM38: 1 | AN38: 1
C39: 14FW ELSTINKO_PANTS_02_BK | D39: 아트인드림 | E39: 41709 | F39: 41722 | G39: 1 | H39: 1 | I39: 1 | J39: =K39&L39&M39 -> QF | M39: QF | N39: 9 | O39: 9 | P39: 9 | Q39: 0 | R39: 0 | AF39: QF 요약 | AH39: 8 | AI39: 8 | AJ39: 21 | AK39: 16 | AL39: 8 | AM39: 4 | AN39: 4
C40: 14FW ELSTINKO_PANTS_03_BK | D40: EVERGREEN | E40: 41709 | F40: 41725 | G40: 1 | H40: 1 | I40: 1 | J40: =K40&L40&M40 -> 캡보이2 | M40: 캡보이2 | N40: 2.5 | O40: 2.5 | P40: 3 | Q40: 0 | R40: 0 | AF40: Y&Y | AG40: BE | AH40: 5 | AI40: 5 | AJ40: 12 | AK40: 11 | AL40: 5 | AM40: 5 | AN40: 5
...

Sheet 샘플현황취합
A1: 실발주샘플수 | B1: 실발주샘플번호 | C1: 총발주샘플건수 | D1: 총발주샘플업체/번호 | E1: 실발주월 | F1: 발주주 | G1: 실입고샘플수 | H1: 실입고샘플번호 | I1: 총입고샘플건수 | J1: 총입고샘플업체/번호 | K1: 입고일 | L1: 입고월 | M1: 입고주 | N1: 해외/국내 | O1: 브랜드/품목2 | P1: 브랜드/품목 | Q1: 공란 | R1: 순번 | S1: 이미지 | T1: 브랜드 | U1: 품목 | V1: 러닝(R)/신규(N) | W1: 샘플번호 | X1: 연령구분 | Y1: 샘플수 | Z1: 업체 | AA1: 발주일 | AB1: 목표입고일 | AC1: 입고예정일 | AD1: 실입고일 | AE1: 해외 (FOB, USD, JPY) | AF1: 국내 (-V, KRW) | AG1: 참조샘플 발송여부 | AH1: 원단총수 | AI1: 중국원단사용수 | AJ1: 기타
A2: =IF(B2="",0,1/COUNTIF(B:B,B2)) -> 1 | B2: =IF(AA2="","",W2) -> 14FW SMB_01_FLAT_GR_N | C2: =IF(D2="",0,1/COUNTIF(D:D,D2)) -> 1 | D2: =IF(AA2="","",Z2&W2) -> QF14FW SMB_01_FLAT_GR_N | E2: =IF(YEAR(AA2)<10,0&YEAR(AA2),YEAR(AA2))&IF(MONTH(AA2)<10,0&MONTH(AA2),MONTH(AA2)) -> 201401 | F2: =VLOOKUP($AA2,[3]주!$A:$F,6,FALSE) -> 1월 4주 | G2: =IF(H2="",0,1/COUNTIF(H:H,H2)) -> 1 | H2: =IF(AD2="","",W2) -> 14FW SMB_01_FLAT_GR_N | I2: =IF(J2="",0,1/COUNTIF(J:J,J2)) -> 1 | J2: =IF(AD2="","",Z2&W2) -> QF14FW SMB_01_FLAT_GR_N | K2: =IF(AD2="",AC2,AD2) -> 41711 | L2: =IF(YEAR(K2)<10,0&YEAR(K2),YEAR(K2))&IF(MONTH(K2)<10,0&MONTH(K2),MONTH(K2)) -> 201403 | M2: =VLOOKUP($K2,[3]주!$A:$F,6,FALSE) -> 3월 2주 | N2: =IF(VLOOKUP($Z2,생산업체!$A:$C,2,FALSE)=1,"해외","국내") -> 해외 | O2: =IF(VLOOKUP($U2,CODE!$K:$P,CODE!P$1,FALSE)="모자",T2,T2&"-"&VLOOKUP($U2,CODE!$K:$P,CODE!P$1,FALSE)) -> SMB | P2: SMB | R2: 1 | T2: SMB | U2: FI | V2: N | W2: 14FW SMB_01_FLAT_GR_N | X2: U | Y2: 1 | Z2: QF | AA2: 41662 | AB2: 41690 | AC2: 41719 | AD2: 41711 | AE2: 2.7 | AH2: 2 | AI2: 2 | AK2: 모든 자재 캡보이 공급 기준으로 받기
A3: =IF(B3="",0,1/COUNTIF(B:B,B3)) -> 1 | B3: =IF(AA3="","",W3) -> 14FW SMB_01_FLAT_NY_N | C3: =IF(D3="",0,1/COUNTIF(D:D,D3)) -> 1 | D3: =IF(AA3="","",Z3&W3) -> 동일모자14FW SMB_01_FLAT_NY_N | E3: =IF(YEAR(AA3)<10,0&YEAR(AA3),YEAR(AA3))&IF(MONTH(AA3)<10,0&MONTH(AA3),MONTH(AA3)) -> 201401 | F3: =VLOOKUP($AA3,[3]주!$A:$F,6,FALSE) -> 1월 4주 | G3: =IF(H3="",0,1/COUNTIF(H:H,H3)) -> 1 | H3: =IF(AD3="","",W3) -> 14FW SMB_01_FLAT_NY_N | I3: =IF(J3="",0,1/COUNTIF(J:J,J3)) -> 1 | J3: =IF(AD3="","",Z3&W3) -> 동일모자14FW SMB_01_FLAT_NY_N | K3: =IF(AD3="",AC3,AD3) -> 41716 | L3: =IF(YEAR(K3)<10,0&YEAR(K3),YEAR(K3))&IF(MONTH(K3)<10,0&MONTH(K3),MONTH(K3)) -> 201403 | M3: =VLOOKUP($K3,[3]주!$A:$F,6,FALSE) -> 3월 2주 | N3: =IF(VLOOKUP($Z3,생산업체!$A:$C,2,FALSE)=1,"해외","국내") -> 해외 | O3: =IF(VLOOKUP($U3,CODE!$K:$P,CODE!P$1,FALSE)="모자",T3,T3&"-"&VLOOKUP($U3,CODE!$K:$P,CODE!P$1,FALSE)) -> SMB | P3: SMB | R3: 2 | T3: SMB | U3: FI | V3: N | W3: 14FW SMB_01_FLAT_NY_N | X3: U | Y3: 1 | Z3: 동일모자 | AA3: 41663 | AB3: 41691 | AC3: 41716 | AD3: 41716 | AE3: 3.85 | AH3: 3 | AI3: 3 | AK3: 모든 자재 캡보이 공급 기준으로 받기
A4: =IF(B4="",0,1/COUNTIF(B:B,B4)) -> 1 | B4: =IF(AA4="","",W4) -> 14FW SMB_02_FLAT_BL_N | C4: =IF(D4="",0,1/COUNTIF(D:D,D4)) -> 1 | D4: =IF(AA4="","",Z4&W4) -> QF14FW SMB_02_FLAT_BL_N | E4: =IF(YEAR(AA4)<10,0&YEAR(AA4),YEAR(AA4))&IF(MONTH(AA4)<10,0&MONTH(AA4),MONTH(AA4)) -> 201401 | F4: =VLOOKUP($AA4,[3]주!$A:$F,6,FALSE) -> 1월 4주 | G4: =IF(H4="",0,1/COUNTIF(H:H,H4)) -> 1 | H4: =IF(AD4="","",W4) -> 14FW SMB_02_FLAT_BL_N | I4: =IF(J4="",0,1/COUNTIF(J:J,J4)) -> 1 | J4: =IF(AD4="","",Z4&W4) -> QF14FW SMB_02_FLAT_BL_N | K4: =IF(AD4="",AC4,AD4) -> 41717 | L4: =IF(YEAR(K4)<10,0&YEAR(K4),YEAR(K4))&IF(MONTH(K4)<10,0&MONTH(K4),MONTH(K4)) -> 201403 | M4: =VLOOKUP($K4,[3]주!$A:$F,6,FALSE) -> 3월 2주 | N4: =IF(VLOOKUP($Z4,생산업체!$A:$C,2,FALSE)=1,"해외","국내") -> 해외 | O4: =IF(VLOOKUP($U4,CODE!$K:$P,CODE!P$1,FALSE)="모자",T4,T4&"-"&VLOOKUP($U4,CODE!$K:$P,CODE!P$1,FALSE)) -> SMB | P4: SMB | R4: 3 | T4: SMB | U4: FI | V4: N | W4: 14FW SMB_02_FLAT_BL_N | X4: U | Y4: 1 | Z4: QF | AA4: 41662 | AB4: 41690 | AC4: 41719 | AD4: 41717 | AE4: 3.4 | AH4: 3 | AI4: 2 | AJ4: 크라운 및 챙 원단 국내제공시 가격 | AK4: 모든 자재 캡보이 공급 기준으로 받기
A5: =IF(B5="",0,1/COUNTIF(B:B,B5)) -> 1 | B5: =IF(AA5="","",W5) -> 14FW SMB_03_FLAT_BK_N | C5: =IF(D5="",0,1/COUNTIF(D:D,D5)) -> 1 | D5: =IF(AA5="","",Z5&W5) -> QF14FW SMB_03_FLAT_BK_N | E5: =IF(YEAR(AA5)<10,0&YEAR(AA5),YEAR(AA5))&IF(MONTH(AA5)<10,0&MONTH(AA5),MONTH(AA5)) -> 201401 | F5: =VLOOKUP($AA5,[3]주!$A:$F,6,FALSE) -> 1월 4주 | G5: =IF(H5="",0,1/COUNTIF(H:H,H5)) -> 1 | H5: =IF(AD5="","",W5) -> 14FW SMB_03_FLAT_BK_N | I5: =IF(J5="",0,1/COUNTIF(J:J,J5)) -> 1 | J5: =IF(AD5="","",Z5&W5) -> QF14FW SMB_03_FLAT_BK_N | K5: =IF(AD5="",AC5,AD5) -> 41717 | L5: =IF(YEAR(K5)<10,0&YEAR(K5),YEAR(K5))&IF(MONTH(K5)<10,0&MONTH(K5),MONTH(K5)) -> 201403 | M5: =VLOOKUP($K5,[3]주!$A:$F,6,FALSE) -> 3월 2주 | N5: =IF(VLOOKUP($Z5,생산업체!$A:$C,2,FALSE)=1,"해외","국내") -> 해외 | O5: =IF(VLOOKUP($U5,CODE!$K:$P,CODE!P$1,FALSE)="모자",T5,T5&"-"&VLOOKUP($U5,CODE!$K:$P,CODE!P$1,FALSE)) -> SMB | P5: SMB | R5: 4 | T5: SMB | U5: FI | V5: N | W5: 14FW SMB_03_FLAT_BK_N | X5: U | Y5: 1 | Z5: QF | AA5: 41662 | AB5: 41690 | AC5: 41719 | AD5: 41717 | AE5: 3.4 | AH5: 3 | AI5: 2 | AJ5: 크라운 및 챙 원단 국내제공시 가격 | AK5: 모든 자재 캡보이 공급 기준으로 받기
A6: =IF(B6="",0,1/COUNTIF(B:B,B6)) -> 1 | B6: =IF(AA6="","",W6) -> 14FW SMB_05_FLAT_KH_N | C6: =IF(D6="",0,1/COUNTIF(D:D,D6)) -> 1 | D6: =IF(AA6="","",Z6&W6) -> QF14FW SMB_05_FLAT_KH_N | E6: =IF(YEAR(AA6)<10,0&YEAR(AA6),YEAR(AA6))&IF(MONTH(AA6)<10,0&MONTH(AA6),MONTH(AA6)) -> 201401 | F6: =VLOOKUP($AA6,[3]주!$A:$F,6,FALSE) -> 1월 4주 | G6: =IF(H6="",0,1/COUNTIF(H:H,H6)) -> 1 | H6: =IF(AD6="","",W6) -> 14FW SMB_05_FLAT_KH_N | I6: =IF(J6="",0,1/COUNTIF(J:J,J6)) -> 1 | J6: =IF(AD6="","",Z6&W6) -> QF14FW SMB_05_FLAT_KH_N | K6: =IF(AD6="",AC6,AD6) -> 41709 | L6: =IF(YEAR(K6)<10,0&YEAR(K6),YEAR(K6))&IF(MONTH(K6)<10,0&MONTH(K6),MONTH(K6)) -> 201403 | M6: =VLOOKUP($K6,[3]주!$A:$F,6,FALSE) -> 3월 2주 | N6: =IF(VLOOKUP($Z6,생산업체!$A:$C,2,FALSE)=1,"해외","국내") -> 해외 | O6: =IF(VLOOKUP($U6,CODE!$K:$P,CODE!P$1,FALSE)="모자",T6,T6&"-"&VLOOKUP($U6,CODE!$K:$P,CODE!P$1,FALSE)) -> SMB | P6: SMB | R6: 5 | T6: SMB | U6: FI | V6: N | W6: 14FW SMB_05_FLAT_KH_N | X6: U | Y6: 1 | Z6: QF | AA6: 41662 | AB6: 41690 | AC6: 41719 | AD6: 41709 | AE6: 3.3 | AH6: 2 | AI6: 2 | AK6: 모든 자재 캡보이 공급 기준으로 받기
A7: =IF(B7="",0,1/COUNTIF(B:B,B7)) -> 1 | B7: =IF(AA7="","",W7) -> 14FW SMB_05_FLAT_PP_N | C7: =IF(D7="",0,1/COUNTIF(D:D,D7)) -> 1 | D7: =IF(AA7="","",Z7&W7) -> QF14FW SMB_05_FLAT_PP_N | E7: =IF(YEAR(AA7)<10,0&YEAR(AA7),YEAR(AA7))&IF(MONTH(AA7)<10,0&MONTH(AA7),MONTH(AA7)) -> 201401 | F7: =VLOOKUP($AA7,[3]주!$A:$F,6,FALSE) -> 1월 4주 | G7: =IF(H7="",0,1/COUNTIF(H:H,H7)) -> 1 | H7: =IF(AD7="","",W7) -> 14FW SMB_05_FLAT_PP_N | I7: =IF(J7="",0,1/COUNTIF(J:J,J7)) -> 1 | J7: =IF(AD7="","",Z7&W7) -> QF14FW SMB_05_FLAT_PP_N | K7: =IF(AD7="",AC7,AD7) -> 41711 | L7: =IF(YEAR(K7)<10,0&YEAR(K7),YEAR(K7))&IF(MONTH(K7)<10,0&MONTH(K7),MONTH(K7)) -> 201403 | M7: =VLOOKUP($K7,[3]주!$A:$F,6,FALSE) -> 3월 2주 | N7: =IF(VLOOKUP($Z7,생산업체!$A:$C,2,FALSE)=1,"해외","국내") -> 해외 | O7: =IF(VLOOKUP($U7,CODE!$K:$P,CODE!P$1,FALSE)="모자",T7,T7&"-"&VLOOKUP($U7,CODE!$K:$P,CODE!P$1,FALSE)) -> SMB | P7: SMB | R7: 6 | T7: SMB | U7: FI | V7: N | W7: 14FW SMB_05_FLAT_PP_N | X7: U | Y7: 1 | Z7: QF | AA7: 41662 | AB7: 41690 | AC7: 41719 | AD7: 41711 | AE7: 3.2 | AH7: 2 | AI7: 2 | AK7: 모든 자재 캡보이 공급 기준으로 받기
