Workbook

Sheet 브랜드품목별
A1: 14FW SAMPLE LIST (LUI MARCHE)
A3: *실발주샘플수=중복 발주 및 입고 스타일은 1ST로 계산 | E3: 41572
C4: 데이터
A5: 브랜드/품목2 | B5: 품목 | C5: 실발주샘플수 | D5: 실입고샘플수 | E5: 미입고샘플수
A6: (비어 있음) | B6: (비어 있음) | E6: 0
A7: (비어 있음) 요약 | E7: 0
A8: JST | B8: FA | C8: 58 | D8: 40 | E8: 18
A9: JST 요약 | C9: 58 | D9: 40 | E9: 18
A10: 총합계 | C10: 58 | D10: 40 | E10: 18

Sheet 발주입고월
A1: 14FW SAMPLE LIST (LUI MARCHE)
A3: *중복 발주 및 입고 스타일은 1ST로 계산
A4: 샘플수 | D4: 입고월
A5: 브랜드/품목2 | B5: 품목 | C5: 실발주월 | D5: 201401 | E5: 201402 | F5: 201403 | G5: 201404 | H5: 총합계
A6: JST | B6: FA | C6: 201312 | D6: 11.333333 | E6: 2.5 | H6: 13.833333
C7: 201401 | E7: 6.5 | F7: 3.3333333 | G7: 1 | H7: 10.833333
C8: 201402 | F8: 26.833333 | G8: 2 | H8: 28.833333
C9: 201403 | F9: 1 | G9: 3.5 | H9: 4.5
B10: FA 요약 | D10: 11.333333 | E10: 9 | F10: 31.166667 | G10: 6.5 | H10: 58
A11: JST 요약 | D11: 11.333333 | E11: 9 | F11: 31.166667 | G11: 6.5 | H11: 58
A12: 총합계 | D12: 11.333333 | E12: 9 | F12: 31.166667 | G12: 6.5 | H12: 58

Sheet 샘플별업체별
A1: 14FW SAMPLE LIST (LUI MARCHE) | H1: 14FW SAMPLE LIST (HATS ON)
E2: 41722 | H2: 러닝(R)/신규(N) | I2: (모두) | N2: 41736
A3: *중복 발주 및 입고 스타일은 1ST로 계산 | H3: *실발주샘플수=중복 발주 및 입고 스타일은 1ST로 계산
E4: 데이터 | K4: 데이터
A5: 생산업체 | B5: 브랜드/품목2 | C5: 품목 | D5: 발주일 | E5: 실발주샘플수 | F5: 실입고샘플수 | H5: 브랜드 | I5: 생산업체 | J5: 품목 | K5: 실발주샘플수 | L5: 총발주샘플건수 | M5: 원단사용총수 | N5: 중국원단사용수 | O5: 총입고샘플건수 | P5: 미입고샘플수 | Q5: 총미입고샘플건수
A6: 우진모자 | B6: JST | C6: FA | D6: 41635 | E6: 2.8333333 | F6: 2.8333333 | H6: (비어 있음) | I6: (비어 있음) | J6: (비어 있음) | P6: 0 | Q6: 0
D7: 41653 | E7: 1 | F7: 0 | H7: JST | I7: 우진모자 | J7: FA | K7: 3.8333333 | L7: 6 | M7: 6 | N7: 6 | O7: 5 | P7: 1 | Q7: 1
A8: 우진모자 요약 | E8: 3.8333333 | F8: 2.8333333 | I8: BS | J8: FA | K8: 8.8333333 | L8: 15 | M8: 14 | N8: 14 | O8: 15 | P8: -1 | Q8: 0
A9: BS | B9: JST | C9: FA | D9: 41635 | E9: 2.5 | F9: 2.5 | I9: FOREMOST | J9: FA | K9: 39.333333 | L9: 48 | M9: 45 | N9: 45 | O9: 34 | P9: 14 | Q9: 14
D10: 41653 | E10: 3 | F10: 3 | I10: TS | J10: FA | K10: 3.5 | L10: 4 | M10: 4 | N10: 4 | O10: 0 | P10: 3.5 | Q10: 4
D11: 41682 | E11: 2.3333333 | F11: 3.3333333 | I11: 5 works room | J11: FA | K11: 2.5 | L11: 5 | M11: 4 | N11: 4 | O11: 4 | P11: 0.5 | Q11: 1
D12: 41698 | E12: 1 | F12: 1 | H12: 총합계 | K12: 58 | L12: 78 | M12: 73 | N12: 73 | O12: 58 | P12: 18 | Q12: 20
A13: BS 요약 | E13: 8.8333333 | F13: 9.8333333
A14: FOREMOST | B14: JST | C14: FA | D14: 41635 | E14: 6.5 | F14: 6.5
D15: 41653 | E15: 3 | F15: 3
D16: 41661 | E16: 2.3333333 | F16: 1.3333333
D17: 41676 | E17: 2 | F17: 1
D18: 41680 | E18: 3 | F18: 2
D19: 41682 | E19: 0.5 | F19: 0.5
D20: 41684 | E20: 2 | F20: 2
D21: 41689 | E21: 8 | F21: 4
D22: 41698 | E22: 8 | F22: 4
D23: 41701 | E23: 1 | F23: 1
D24: 41717 | E24: 3 | F24: 0
A25: FOREMOST 요약 | E25: 39.333333 | F25: 25.333333
A26: TS | B26: JST | C26: FA | D26: 41635 | E26: 2 | F26: 0
D27: 41653 | E27: 1.5 | F27: 0
A28: TS 요약 | E28: 3.5 | F28: 0
A29: 5 works room | B29: JST | C29: FA | D29: 41691 | E29: 2 | F29: 2
D30: 41724 | E30: 0.5 | F30: 0
A31: 5 works room 요약 | E31: 2.5 | F31: 2
A32: 총합계 | E32: 58 | F32: 40

Sheet 샘플현황취합
A1: 실발주샘플수 | B1: 실발주샘플번호 | C1: 총발주샘플건수 | D1: 총발주샘플업체/번호 | E1: 실발주월 | F1: 발주주 | G1: 실입고샘플수 | H1: 실입고샘플번호 | I1: 총입고샘플건수 | J1: 총입고샘플업체/번호 | K1: 입고일 | L1: 입고월 | M1: 입고주 | N1: 해외/국내 | O1: 브랜드/품목2 | P1: 브랜드 품목 | Q1: 공란 | R1: 순번 | S1: 이미지 | T1: 브랜드 | U1: 품목 | V1: 러닝(R)/신규(N) | W1: SAMPLE NO. | X1: 연령구분 | Y1: 샘플수 | Z1: 생산업체 | AA1: 발주일 | AB1: 목표입고일 | AC1: 입고예정일 | AD1: 실입고일 | AE1: 해외원가 | AF1: 국내원가 | AG1: 참조샘플 발송여부 | AH1: 중국원단사용총수 | AI1: 중국원단사용수 | AJ1: 기타
A2: =IF(B2="",0,1/COUNTIF(B:B,B2)) -> 0.5 | B2: =IF(AA2="","",W2) -> 14-FW-SP-06 | C2: =IF(D2="",0,1/COUNTIF(D:D,D2)) -> 1 | D2: =IF(AA2="","",Z2&W2) -> FOREMOST14-FW-SP-06 | E2: =IF(YEAR(AA2)<10,0&YEAR(AA2),YEAR(AA2))&IF(MONTH(AA2)<10,0&MONTH(AA2),MONTH(AA2)) -> 201312 | F2: =VLOOKUP($AA2,주!$A:$F,6,FALSE) -> 12월 4주 | G2: =IF(H2="",0,1/COUNTIF(H:H,H2)) -> 0.5 | H2: =IF(AD2="","",W2) -> 14-FW-SP-06 | I2: =IF(J2="",0,1/COUNTIF(J:J,J2)) -> 1 | J2: =IF(AD2="","",Z2&W2) -> FOREMOST14-FW-SP-06 | K2: =IF(AD2="",AC2,AD2) -> 41656 | L2: =IF(YEAR(K2)<10,0&YEAR(K2),YEAR(K2))&IF(MONTH(K2)<10,0&MONTH(K2),MONTH(K2)) -> 201401 | M2: =VLOOKUP($K2,주!$A:$F,6,FALSE) -> 1월 3주 | N2: =IF(VLOOKUP($Z2,[1]생산업체!$A:$C,2,FALSE)=1,"해외","국내") -> 해외 | O2: =IF(VLOOKUP($U2,[1]CODE!$K:$P,[1]CODE!P$1,FALSE)="모자",T2,T2&"-"&VLOOKUP($U2,[1]CODE!$K:$P,[1]CODE!P$1,FALSE)) -> JST | P2: JST | R2: 1 | T2: JST | U2: FA | V2: N | W2: 14-FW-SP-06 | X2: ADULT | Y2: 0.5 | Z2: FOREMOST | AA2: 41635 | AB2: 41663 | AC2: 41663 | AD2: 41656 | AE2: 6.5 | AG2: ORIGINAL SAMPLE | AH2: 4 | AI2: 1
A3: =IF(B3="",0,1/COUNTIF(B:B,B3)) -> 0.5 | B3: =IF(AA3="","",W3) -> 14-FW-SP-06 | C3: =IF(D3="",0,1/COUNTIF(D:D,D3)) -> 1 | D3: =IF(AA3="","",Z3&W3) -> BS14-FW-SP-06 | E3: =IF(YEAR(AA3)<10,0&YEAR(AA3),YEAR(AA3))&IF(MONTH(AA3)<10,0&MONTH(AA3),MONTH(AA3)) -> 201312 | F3: =VLOOKUP($AA3,주!$A:$F,6,FALSE) -> 12월 4주 | G3: =IF(H3="",0,1/COUNTIF(H:H,H3)) -> 0.5 | H3: =IF(AD3="","",W3) -> 14-FW-SP-06 | I3: =IF(J3="",0,1/COUNTIF(J:J,J3)) -> 1 | J3: =IF(AD3="","",Z3&W3) -> BS14-FW-SP-06 | K3: =IF(AD3="",AC3,AD3) -> 41694 | L3: =IF(YEAR(K3)<10,0&YEAR(K3),YEAR(K3))&IF(MONTH(K3)<10,0&MONTH(K3),MONTH(K3)) -> 201402 | M3: =VLOOKUP($K3,주!$A:$F,6,FALSE) -> 2월 4주 | N3: =IF(VLOOKUP($Z3,[1]생산업체!$A:$C,2,FALSE)=1,"해외","국내") -> 해외 | O3: =IF(VLOOKUP($U3,[1]CODE!$K:$P,[1]CODE!P$1,FALSE)="모자",T3,T3&"-"&VLOOKUP($U3,[1]CODE!$K:$P,[1]CODE!P$1,FALSE)) -> JST | P3: JST | R3: 2 | T3: JST | U3: FA | V3: N | W3: 14-FW-SP-06 | X3: ADULT | Y3: 0.5 | Z3: BS | AA3: 41635 | AB3: 41663 | AC3: 41663 | AD3: 41694 | AE3: 3.8 | AH3: 4 | AI3: 1
A4: =IF(B4="",0,1/COUNTIF(B:B,B4)) -> 0.5 | B4: =IF(AA4="","",W4) -> 14-FW-SP-07 | C4: =IF(D4="",0,1/COUNTIF(D:D,D4)) -> 1 | D4: =IF(AA4="","",Z4&W4) -> FOREMOST14-FW-SP-07 | E4: =IF(YEAR(AA4)<10,0&YEAR(AA4),YEAR(AA4))&IF(MONTH(AA4)<10,0&MONTH(AA4),MONTH(AA4)) -> 201312 | F4: =VLOOKUP($AA4,주!$A:$F,6,FALSE) -> 12월 4주 | G4: =IF(H4="",0,1/COUNTIF(H:H,H4)) -> 0.5 | H4: =IF(AD4="","",W4) -> 14-FW-SP-07 | I4: =IF(J4="",0,1/COUNTIF(J:J,J4)) -> 1 | J4: =IF(AD4="","",Z4&W4) -> FOREMOST14-FW-SP-07 | K4: =IF(AD4="",AC4,AD4) -> 41652 | L4: =IF(YEAR(K4)<10,0&YEAR(K4),YEAR(K4))&IF(MONTH(K4)<10,0&MONTH(K4),MONTH(K4)) -> 201401 | M4: =VLOOKUP($K4,주!$A:$F,6,FALSE) -> 1월 3주 | N4: =IF(VLOOKUP($Z4,[1]생산업체!$A:$C,2,FALSE)=1,"해외","국내") -> 해외 | O4: =IF(VLOOKUP($U4,[1]CODE!$K:$P,[1]CODE!P$1,FALSE)="모자",T4,T4&"-"&VLOOKUP($U4,[1]CODE!$K:$P,[1]CODE!P$1,FALSE)) -> JST | P4: JST | R4: 3 | T4: JST | U4: FA | V4: N | W4: 14-FW-SP-07 | X4: ADULT | Y4: 0.5 | Z4: FOREMOST | AA4: 41635 | AB4: 41663 | AC4: 41663 | AD4: 41652 | AE4: 5.7 | AH4: 4 | AI4: 1
A5: =IF(B5="",0,1/COUNTIF(B:B,B5)) -> 0.5 | B5: =IF(AA5="","",W5) -> 14-FW-SP-07 | C5: =IF(D5="",0,1/COUNTIF(D:D,D5)) -> 1 | D5: =IF(AA5="","",Z5&W5) -> BS14-FW-SP-07 | E5: =IF(YEAR(AA5)<10,0&YEAR(AA5),YEAR(AA5))&IF(MONTH(AA5)<10,0&MONTH(AA5),MONTH(AA5)) -> 201312 | F5: =VLOOKUP($AA5,주!$A:$F,6,FALSE) -> 12월 4주 | G5: =IF(H5="",0,1/COUNTIF(H:H,H5)) -> 0.5 | H5: =IF(AD5="","",W5) -> 14-FW-SP-07 | I5: =IF(J5="",0,1/COUNTIF(J:J,J5)) -> 1 | J5: =IF(AD5="","",Z5&W5) -> BS14-FW-SP-07 | K5: =IF(AD5="",AC5,AD5) -> 41694 | L5: =IF(YEAR(K5)<10,0&YEAR(K5),YEAR(K5))&IF(MONTH(K5)<10,0&MONTH(K5),MONTH(K5)) -> 201402 | M5: =VLOOKUP($K5,주!$A:$F,6,FALSE) -> 2월 4주 | N5: =IF(VLOOKUP($Z5,[1]생산업체!$A:$C,2,FALSE)=1,"해외","국내") -> 해외 | O5: =IF(VLOOKUP($U5,[1]CODE!$K:$P,[1]CODE!P$1,FALSE)="모자",T5,T5&"-"&VLOOKUP($U5,[1]CODE!$K:$P,[1]CODE!P$1,FALSE)) -> JST | P5: JST | R5: 4 | T5: JST | U5: FA | V5: N | W5: 14-FW-SP-07 | X5: ADULT | Y5: 0.5 | Z5: BS | AA5: 41635 | AB5: 41663 | AC5: 41663 | AD5: 41694 | AE5: 3.2 | AG5: ORIGINAL SAMPLE | AH5: 4 | AI5: 1 | AJ5: 오리지널샘플받아야함
A6: =IF(B6="",0,1/COUNTIF(B:B,B6)) -> 1 | B6: =IF(AA6="","",W6) -> 14-FW-SP-08 | C6: =IF(D6="",0,1/COUNTIF(D:D,D6)) -> 1 | D6: =IF(AA6="","",Z6&W6) -> FOREMOST14-FW-SP-08 | E6: =IF(YEAR(AA6)<10,0&YEAR(AA6),YEAR(AA6))&IF(MONTH(AA6)<10,0&MONTH(AA6),MONTH(AA6)) -> 201312 | F6: =VLOOKUP($AA6,주!$A:$F,6,FALSE) -> 12월 4주 | G6: =IF(H6="",0,1/COUNTIF(H:H,H6)) -> 1 | H6: =IF(AD6="","",W6) -> 14-FW-SP-08 | I6: =IF(J6="",0,1/COUNTIF(J:J,J6)) -> 1 | J6: =IF(AD6="","",Z6&W6) -> FOREMOST14-FW-SP-08 | K6: =IF(AD6="",AC6,AD6) -> 41656 | L6: =IF(YEAR(K6)<10,0&YEAR(K6),YEAR(K6))&IF(MONTH(K6)<10,0&MONTH(K6),MONTH(K6)) -> 201401 | M6: =VLOOKUP($K6,주!$A:$F,6,FALSE) -> 1월 3주 | N6: =IF(VLOOKUP($Z6,[1]생산업체!$A:$C,2,FALSE)=1,"해외","국내") -> 해외 | O6: =IF(VLOOKUP($U6,[1]CODE!$K:$P,[1]CODE!P$1,FALSE)="모자",T6,T6&"-"&VLOOKUP($U6,[1]CODE!$K:$P,[1]CODE!P$1,FALSE)) -> JST | P6: JST | R6: 5 | T6: JST | U6: FA | V6: N | W6: 14-FW-SP-08 | X6: ADULT | Y6: 1 | Z6: FOREMOST | AA6: 41635 | AB6: 41663 | AC6: 41663 | AD6: 41656 | AE6: 6.7 | AH6: 4 | AI6: 1
A7: =IF(B7="",0,1/COUNTIF(B:B,B7)) -> 0.5 | B7: =IF(AA7="","",W7) -> 14-FW-SP-09 | C7: =IF(D7="",0,1/COUNTIF(D:D,D7)) -> 1 | D7: =IF(AA7="","",Z7&W7) -> FOREMOST14-FW-SP-09 | E7: =IF(YEAR(AA7)<10,0&YEAR(AA7),YEAR(AA7))&IF(MONTH(AA7)<10,0&MONTH(AA7),MONTH(AA7)) -> 201312 | F7: =VLOOKUP($AA7,주!$A:$F,6,FALSE) -> 12월 4주 | G7: =IF(H7="",0,1/COUNTIF(H:H,H7)) -> 0.5 | H7: =IF(AD7="","",W7) -> 14-FW-SP-09 | I7: =IF(J7="",0,1/COUNTIF(J:J,J7)) -> 1 | J7: =IF(AD7="","",Z7&W7) -> FOREMOST14-FW-SP-09 | K7: =IF(AD7="",AC7,AD7) -> 41661 | L7: =IF(YEAR(K7)<10,0&YEAR(K7),YEAR(K7))&IF(MONTH(K7)<10,0&MONTH(K7),MONTH(K7)) -> 201401 | M7: =VLOOKUP($K7,주!$A:$F,6,FALSE) -> 1월 4주 | N7: =IF(VLOOKUP($Z7,[1]생산업체!$A:$C,2,FALSE)=1,"해외","국내") -> 해외 | O7: =IF(VLOOKUP($U7,[1]CODE!$K:$P,[1]CODE!P$1,FALSE)="모자",T7,T7&"-"&VLOOKUP($U7,[1]CODE!$K:$P,[1]CODE!P$1,FALSE)) -> JST | P7: JST | R7: 6 | T7: JST | U7: FA | V7: N | W7: 14-FW-SP-09 | X7: ADULT | Y7: 0.5 | Z7: FOREMOST | AA7: 41635 | AB7: 41663 | AC7: 41663 | AD7: 41661 | AE7: 7 | AH7: 5 | AI7: 1
A8: =IF(B8="",0,1/COUNTIF(B:B,B8)) -> 0.5 | B8: =IF(AA8="","",W8) -> 14-FW-SP-09 | C8: =IF(D8="",0,1/COUNTIF(D:D,D8)) -> 1 | D8: =IF(AA8="","",Z8&W8) -> BS14-FW-SP-09 | E8: =IF(YEAR(AA8)<10,0&YEAR(AA8),YEAR(AA8))&IF(MONTH(AA8)<10,0&MONTH(AA8),MONTH(AA8)) -> 201312 | F8: =VLOOKUP($AA8,주!$A:$F,6,FALSE) -> 12월 4주 | G8: =IF(H8="",0,1/COUNTIF(H:H,H8)) -> 0.5 | H8: =IF(AD8="","",W8) -> 14-FW-SP-09 | I8: =IF(J8="",0,1/COUNTIF(J:J,J8)) -> 1 | J8: =IF(AD8="","",Z8&W8) -> BS14-FW-SP-09 | K8: =IF(AD8="",AC8,AD8) -> 41694 | L8: =IF(YEAR(K8)<10,0&YEAR(K8),YEAR(K8))&IF(MONTH(K8)<10,0&MONTH(K8),MONTH(K8)) -> 201402 | M8: =VLOOKUP($K8,주!$A:$F,6,FALSE) -> 2월 4주 | N8: =IF(VLOOKUP($Z8,[1]생산업체!$A:$C,2,FALSE)=1,"해외","국내") -> 해외 | O8: =IF(VLOOKUP($U8,[1]CODE!$K:$P,[1]CODE!P$1,FALSE)="모자",T8,T8&"-"&VLOOKUP($U8,[1]CODE!$K:$P,[1]CODE!P$1,FALSE)) -> JST | P8: JST | R8: 7 | T8: JST | U8: FA | V8: N | W8: 14-FW-SP-09 | X8: ADULT | Y8: 0.5 | Z8: BS | AA8: 41635 | AB8: 41663 | AC8: 41663 | AD8: 41694 | AE8: 3.8 | AG8: ORIGINAL SAMPLE | AH8: 5 | AI8: 1
A9: =IF(B9="",0,1/COUNTIF(B:B,B9)) -> 0.5 | B9: =IF(AA9="","",W9) -> 14-FW-SP-10 | C9: =IF(D9="",0,1/COUNTIF(D:D,D9)) -> 1 | D9: =IF(AA9="","",Z9&W9) -> FOREMOST14-FW-SP-10 | E9: =IF(YEAR(AA9)<10,0&YEAR(AA9),YEAR(AA9))&IF(MONTH(AA9)<10,0&MONTH(AA9),MONTH(AA9)) -> 201312 | F9: =VLOOKUP($AA9,주!$A:$F,6,FALSE) -> 12월 4주 | G9: =IF(H9="",0,1/COUNTIF(H:H,H9)) -> 0.5 | H9: =IF(AD9="","",W9) -> 14-FW-SP-10 | I9: =IF(J9="",0,1/COUNTIF(J:J,J9)) -> 1 | J9: =IF(AD9="","",Z9&W9) -> FOREMOST14-FW-SP-10 | K9: =IF(AD9="",AC9,AD9) -> 41652 | L9: =IF(YEAR(K9)<10,0&YEAR(K9),YEAR(K9))&IF(MONTH(K9)<10,0&MONTH(K9),MONTH(K9)) -> 201401 | M9: =VLOOKUP($K9,주!$A:$F,6,FALSE) -> 1월 3주 | N9: =IF(VLOOKUP($Z9,[1]생산업체!$A:$C,2,FALSE)=1,"해외","국내") -> 해외 | O9: =IF(VLOOKUP($U9,[1]CODE!$K:$P,[1]CODE!P$1,FALSE)="모자",T9,T9&"-"&VLOOKUP($U9,[1]CODE!$K:$P,[1]CODE!P$1,FALSE)) -> JST | P9: JST | R9: 8 | T9: JST | U9: FA | V9: N | W9: 14-FW-SP-10 | X9: ADULT | Y9: 0.5 | Z9: FOREMOST | AA9: 41635 | AB9: 41663 | AC9: 41663 | AD9: 41652 | AE9: 5.4 | AH9: 3 | AI9: 1
A10: =IF(B10="",0,1/COUNTIF(B:B,B10)) -> 0.5 | B10: =IF(AA10="","",W10) -> 14-FW-SP-10 | C10: =IF(D10="",0,1/COUNTIF(D:D,D10)) -> 1 | D10: =IF(AA10="","",Z10&W10) -> BS14-FW-SP-10 | E10: =IF(YEAR(AA10)<10,0&YEAR(AA10),YEAR(AA10))&IF(MONTH(AA10)<10,0&MONTH(AA10),MONTH(AA10)) -> 201312 | F10: =VLOOKUP($AA10,주!$A:$F,6,FALSE) -> 12월 4주 | G10: =IF(H10="",0,1/COUNTIF(H:H,H10)) -> 0.5 | H10: =IF(AD10="","",W10) -> 14-FW-SP-10 | I10: =IF(J10="",0,1/COUNTIF(J:J,J10)) -> 1 | J10: =IF(AD10="","",Z10&W10) -> BS14-FW-SP-10 | K10: =IF(AD10="",AC10,AD10) -> 41694 | L10: =IF(YEAR(K10)<10,0&YEAR(K10),YEAR(K10))&IF(MONTH(K10)<10,0&MONTH(K10),MONTH(K10)) -> 201402 | M10: =VLOOKUP($K10,주!$A:$F,6,FALSE) -> 2월 4주 | N10: =IF(VLOOKUP($Z10,[1]생산업체!$A:$C,2,FALSE)=1,"해외","국내") -> 해외 | O10: =IF(VLOOKUP($U10,[1]CODE!$K:$P,[1]CODE!P$1,FALSE)="모자",T10,T10&"-"&VLOOKUP($U10,[1]CODE!$K:$P,[1]CODE!P$1,FALSE)) -> JST | P10: JST | R10: 9 | T10: JST | U10: FA | V10: N | W10: 14-FW-SP-10 | X10: ADULT | Y10: 0.5 | Z10: BS | AA10: 41635 | AB10: 41663 | AC10: 41663 | AD10: 41694 | AE10: 3.2 | AH10: 3 | AI10: 1
A11: =IF(B11="",0,1/COUNTIF(B:B,B11)) -> 0.5 | B11: =IF(AA11="","",W11) -> 14-FW-SP-11 | C11: =IF(D11="",0,1/COUNTIF(D:D,D11)) -> 1 | D11: =IF(AA11="","",Z11&W11) -> FOREMOST14-FW-SP-11 | E11: =IF(YEAR(AA11)<10,0&YEAR(AA11),YEAR(AA11))&IF(MONTH(AA11)<10,0&MONTH(AA11),MONTH(AA11)) -> 201312 | F11: =VLOOKUP($AA11,주!$A:$F,6,FALSE) -> 12월 4주 | G11: =IF(H11="",0,1/COUNTIF(H:H,H11)) -> 0.5 | H11: =IF(AD11="","",W11) -> 14-FW-SP-11 | I11: =IF(J11="",0,1/COUNTIF(J:J,J11)) -> 1 | J11: =IF(AD11="","",Z11&W11) -> FOREMOST14-FW-SP-11 | K11: =IF(AD11="",AC11,AD11) -> 41656 | L11: =IF(YEAR(K11)<10,0&YEAR(K11),YEAR(K11))&IF(MONTH(K11)<10,0&MONTH(K11),MONTH(K11)) -> 201401 | M11: =VLOOKUP($K11,주!$A:$F,6,FALSE) -> 1월 3주 | N11: =IF(VLOOKUP($Z11,[1]생산업체!$A:$C,2,FALSE)=1,"해외","국내") -> 해외 | O11: =IF(VLOOKUP($U11,[1]CODE!$K:$P,[1]CODE!P$1,FALSE)="모자",T11,T11&"-"&VLOOKUP($U11,[1]CODE!$K:$P,[1]CODE!P$1,FALSE)) -> JST | P11: JST | R11: 10 | T11: JST | U11: FA | V11: N | W11: 14-FW-SP-11 | X11: ADULT | Y11: 0.5 | Z11: FOREMOST | AA11: 41635 | AB11: 41663 | AC11: 41663 | AD11: 41656 | AE11: 4.2 | AH11: 4 | AI11: 1
A12: =IF(B12="",0,1/COUNTIF(B:B,B12)) -> 0.5 | B12: =IF(AA12="","",W12) -> 14-FW-SP-11 | C12: =IF(D12="",0,1/COUNTIF(D:D,D12)) -> 1 | D12: =IF(AA12="","",Z12&W12) -> 5 works room14-FW-SP-11 | E12: =IF(YEAR(AA12)<10,0&YEAR(AA12),YEAR(AA12))&IF(MONTH(AA12)<10,0&MONTH(AA12),MONTH(AA12)) -> 201402 | F12: =VLOOKUP($AA12,주!$A:$F,6,FALSE) -> 2월 3주 | G12: =IF(H12="",0,1/COUNTIF(H:H,H12)) -> 0.5 | H12: =IF(AD12="","",W12) -> 14-FW-SP-11 | I12: =IF(J12="",0,1/COUNTIF(J:J,J12)) -> 1 | J12: =IF(AD12="","",Z12&W12) -> 5 works room14-FW-SP-11 | K12: =IF(AD12="",AC12,AD12) -> 41715 | L12: =IF(YEAR(K12)<10,0&YEAR(K12),YEAR(K12))&IF(MONTH(K12)<10,0&MONTH(K12),MONTH(K12)) -> 201403 | M12: =VLOOKUP($K12,주!$A:$F,6,FALSE) -> 3월 4주 | N12: =IF(VLOOKUP($Z12,[1]생산업체!$A:$C,2,FALSE)=1,"해외","국내") -> #N/A | O12: =IF(VLOOKUP($U12,[1]CODE!$K:$P,[1]CODE!P$1,FALSE)="모자",T12,T12&"-"&VLOOKUP($U12,[1]CODE!$K:$P,[1]CODE!P$1,FALSE)) -> JST | P12: JST | R12: 11 | T12: JST | U12: FA | V12: N | W12: 14-FW-SP-11 | X12: ADULT | Y12: 0.5 | Z12: 5 works room | AA12: 41691 | AB12: 41719 | AC12: 41719 | AD12: 41715 | AE12: 4 | AH12: 4 | AI12: 1
A13: =IF(B13="",0,1/COUNTIF(B:B,B13)) -> 0.5 | B13: =IF(AA13="","",W13) -> 14-FW-SP-12 | C13: =IF(D13="",0,1/COUNTIF(D:D,D13)) -> 1 | D13: =IF(AA13="","",Z13&W13) -> 우진모자14-FW-SP-12 | E13: =IF(YEAR(AA13)<10,0&YEAR(AA13),YEAR(AA13))&IF(MONTH(AA13)<10,0&MONTH(AA13),MONTH(AA13)) -> 201312 | F13: =VLOOKUP($AA13,주!$A:$F,6,FALSE) -> 12월 4주 | G13: =IF(H13="",0,1/COUNTIF(H:H,H13)) -> 0.5 | H13: =IF(AD13="","",W13) -> 14-FW-SP-12 | I13: =IF(J13="",0,1/COUNTIF(J:J,J13)) -> 1 | J13: =IF(AD13="","",Z13&W13) -> 우진모자14-FW-SP-12 | K13: =IF(AD13="",AC13,AD13) -> 41656 | L13: =IF(YEAR(K13)<10,0&YEAR(K13),YEAR(K13))&IF(MONTH(K13)<10,0&MONTH(K13),MONTH(K13)) -> 201401 | M13: =VLOOKUP($K13,주!$A:$F,6,FALSE) -> 1월 3주 | N13: =IF(VLOOKUP($Z13,[1]생산업체!$A:$C,2,FALSE)=1,"해외","국내") -> 국내 | O13: =IF(VLOOKUP($U13,[1]CODE!$K:$P,[1]CODE!P$1,FALSE)="모자",T13,T13&"-"&VLOOKUP($U13,[1]CODE!$K:$P,[1]CODE!P$1,FALSE)) -> JST | P13: JST | R13: 12 | T13: JST | U13: FA | V13: N | W13: 14-FW-SP-12 | X13: ADULT | Y13: 0.5 | Z13: 우진모자 | AA13: 41635 | AB13: 41656 | AC13: 41656 | AD13: 41656 | AH13: 3 | AI13: 1
A14: =IF(B14="",0,1/COUNTIF(B:B,B14)) -> 0.5 | B14: =IF(AA14="","",W14) -> 14-FW-SP-12 | C14: =IF(D14="",0,1/COUNTIF(D:D,D14)) -> 1 | D14: =IF(AA14="","",Z14&W14) -> FOREMOST14-FW-SP-12 | E14: =IF(YEAR(AA14)<10,0&YEAR(AA14),YEAR(AA14))&IF(MONTH(AA14)<10,0&MONTH(AA14),MONTH(AA14)) -> 201312 | F14: =VLOOKUP($AA14,주!$A:$F,6,FALSE) -> 12월 4주 | G14: =IF(H14="",0,1/COUNTIF(H:H,H14)) -> 0.5 | H14: =IF(AD14="","",W14) -> 14-FW-SP-12 | I14: =IF(J14="",0,1/COUNTIF(J:J,J14)) -> 1 | J14: =IF(AD14="","",Z14&W14) -> FOREMOST14-FW-SP-12 | K14: =IF(AD14="",AC14,AD14) -> 41652 | L14: =IF(YEAR(K14)<10,0&YEAR(K14),YEAR(K14))&IF(MONTH(K14)<10,0&MONTH(K14),MONTH(K14)) -> 201401 | M14: =VLOOKUP($K14,주!$A:$F,6,FALSE) -> 1월 3주 | N14: =IF(VLOOKUP($Z14,[1]생산업체!$A:$C,2,FALSE)=1,"해외","국내") -> 해외 | O14: =IF(VLOOKUP($U14,[1]CODE!$K:$P,[1]CODE!P$1,FALSE)="모자",T14,T14&"-"&VLOOKUP($U14,[1]CODE!$K:$P,[1]CODE!P$1,FALSE)) -> JST | P14: JST | R14: 13 | T14: JST | U14: FA | V14: N | W14: 14-FW-SP-12 | X14: ADULT | Y14: 0.5 | Z14: FOREMOST | AA14: 41635 | AB14: 41663 | AC14: 41663 | AD14: 41652 | AE14: 6.7 | AH14: 3 | AI14: 1
A15: =IF(B15="",0,1/COUNTIF(B:B,B15)) -> 0.5 | B15: =IF(AA15="","",W15) -> 14-FW-SP-13 | C15: =IF(D15="",0,1/COUNTIF(D:D,D15)) -> 1 | D15: =IF(AA15="","",Z15&W15) -> 우진모자14-FW-SP-13 | E15: =IF(YEAR(AA15)<10,0&YEAR(AA15),YEAR(AA15))&IF(MONTH(AA15)<10,0&MONTH(AA15),MONTH(AA15)) -> 201312 | F15: =VLOOKUP($AA15,주!$A:$F,6,FALSE) -> 12월 4주 | G15: =IF(H15="",0,1/COUNTIF(H:H,H15)) -> 0.5 | H15: =IF(AD15="","",W15) -> 14-FW-SP-13 | I15: =IF(J15="",0,1/COUNTIF(J:J,J15)) -> 1 | J15: =IF(AD15="","",Z15&W15) -> 우진모자14-FW-SP-13 | K15: =IF(AD15="",AC15,AD15) -> 41656 | L15: =IF(YEAR(K15)<10,0&YEAR(K15),YEAR(K15))&IF(MONTH(K15)<10,0&MONTH(K15),MONTH(K15)) -> 201401 | M15: =VLOOKUP($K15,주!$A:$F,6,FALSE) -> 1월 3주 | N15: =IF(VLOOKUP($Z15,[1]생산업체!$A:$C,2,FALSE)=1,"해외","국내") -> 국내 | O15: =IF(VLOOKUP($U15,[1]CODE!$K:$P,[1]CODE!P$1,FALSE)="모자",T15,T15&"-"&VLOOKUP($U15,[1]CODE!$K:$P,[1]CODE!P$1,FALSE)) -> JST | P15: JST | R15: 14 | T15: JST | U15: FA | V15: N | W15: 14-FW-SP-13 | X15: ADULT | Y15: 0.5 | Z15: 우진모자 | AA15: 41635 | AB15: 41656 | AC15: 41656 | AD15: 41656 | AH15: 3 | AI15: 1
A16: =IF(B16="",0,1/COUNTIF(B:B,B16)) -> 0.5 | B16: =IF(AA16="","",W16) -> 14-FW-SP-13 | C16: =IF(D16="",0,1/COUNTIF(D:D,D16)) -> 1 | D16: =IF(AA16="","",Z16&W16) -> FOREMOST14-FW-SP-13 | E16: =IF(YEAR(AA16)<10,0&YEAR(AA16),YEAR(AA16))&IF(MONTH(AA16)<10,0&MONTH(AA16),MONTH(AA16)) -> 201312 | F16: =VLOOKUP($AA16,주!$A:$F,6,FALSE) -> 12월 4주 | G16: =IF(H16="",0,1/COUNTIF(H:H,H16)) -> 0.5 | H16: =IF(AD16="","",W16) -> 14-FW-SP-13 | I16: =IF(J16="",0,1/COUNTIF(J:J,J16)) -> 1 | J16: =IF(AD16="","",Z16&W16) -> FOREMOST14-FW-SP-13 | K16: =IF(AD16="",AC16,AD16) -> 41652 | L16: =IF(YEAR(K16)<10,0&YEAR(K16),YEAR(K16))&IF(MONTH(K16)<10,0&MONTH(K16),MONTH(K16)) -> 201401 | M16: =VLOOKUP($K16,주!$A:$F,6,FALSE) -> 1월 3주 | N16: =IF(VLOOKUP($Z16,[1]생산업체!$A:$C,2,FALSE)=1,"해외","국내") -> 해외 | O16: =IF(VLOOKUP($U16,[1]CODE!$K:$P,[1]CODE!P$1,FALSE)="모자",T16,T16&"-"&VLOOKUP($U16,[1]CODE!$K:$P,[1]CODE!P$1,FALSE)) -> JST | P16: JST | R16: 15 | T16: JST | U16: FA | V16: N | W16: 14-FW-SP-13 | X16: ADULT | Y16: 0.5 | Z16: FOREMOST | AA16: 41635 | AB16: 41663 | AC16: 41663 | AD16: 41652 | AE16: 6.5 | AH16: 3 | AI16: 1
A17: =IF(B17="",0,1/COUNTIF(B:B,B17)) -> 1 | B17: =IF(AA17="","",W17) -> 14-FW-SP-14 | C17: =IF(D17="",0,1/COUNTIF(D:D,D17)) -> 1 | D17: =IF(AA17="","",Z17&W17) -> 우진모자14-FW-SP-14 | E17: =IF(YEAR(AA17)<10,0&YEAR(AA17),YEAR(AA17))&IF(MONTH(AA17)<10,0&MONTH(AA17),MONTH(AA17)) -> 201312 | F17: =VLOOKUP($AA17,주!$A:$F,6,FALSE) -> 12월 4주 | G17: =IF(H17="",0,1/COUNTIF(H:H,H17)) -> 1 | H17: =IF(AD17="","",W17) -> 14-FW-SP-14 | I17: =IF(J17="",0,1/COUNTIF(J:J,J17)) -> 1 | J17: =IF(AD17="","",Z17&W17) -> 우진모자14-FW-SP-14 | K17: =IF(AD17="",AC17,AD17) -> 41656 | L17: =IF(YEAR(K17)<10,0&YEAR(K17),YEAR(K17))&IF(MONTH(K17)<10,0&MONTH(K17),MONTH(K17)) -> 201401 | M17: =VLOOKUP($K17,주!$A:$F,6,FALSE) -> 1월 3주 | N17: =IF(VLOOKUP($Z17,[1]생산업체!$A:$C,2,FALSE)=1,"해외","국내") -> 국내 | O17: =IF(VLOOKUP($U17,[1]CODE!$K:$P,[1]CODE!P$1,FALSE)="모자",T17,T17&"-"&VLOOKUP($U17,[1]CODE!$K:$P,[1]CODE!P$1,FALSE)) -> JST | P17: JST | R17: 16 | T17: JST | U17: FA | V17: N | W17: 14-FW-SP-14 | X17: ADULT | Y17: 1 | Z17: 우진모자 | AA17: 41635 | AB17: 41656 | AC17: 41656 | AD17: 41656 | AH17: 3 | AI17: 1
A18: =IF(B18="",0,1/COUNTIF(B:B,B18)) -> 0.5 | B18: =IF(AA18="","",W18) -> 14-FW-SP-15 | C18: =IF(D18="",0,1/COUNTIF(D:D,D18)) -> 1 | D18: =IF(AA18="","",Z18&W18) -> 우진모자14-FW-SP-15 | E18: =IF(YEAR(AA18)<10,0&YEAR(AA18),YEAR(AA18))&IF(MONTH(AA18)<10,0&MONTH(AA18),MONTH(AA18)) -> 201312 | F18: =VLOOKUP($AA18,주!$A:$F,6,FALSE) -> 12월 4주 | G18: =IF(H18="",0,1/COUNTIF(H:H,H18)) -> 0.5 | H18: =IF(AD18="","",W18) -> 14-FW-SP-15 | I18: =IF(J18="",0,1/COUNTIF(J:J,J18)) -> 1 | J18: =IF(AD18="","",Z18&W18) -> 우진모자14-FW-SP-15 | K18: =IF(AD18="",AC18,AD18) -> 41656 | L18: =IF(YEAR(K18)<10,0&YEAR(K18),YEAR(K18))&IF(MONTH(K18)<10,0&MONTH(K18),MONTH(K18)) -> 201401 | M18: =VLOOKUP($K18,주!$A:$F,6,FALSE) -> 1월 3주 | N18: =IF(VLOOKUP($Z18,[1]생산업체!$A:$C,2,FALSE)=1,"해외","국내") -> 국내 | O18: =IF(VLOOKUP($U18,[1]CODE!$K:$P,[1]CODE!P$1,FALSE)="모자",T18,T18&"-"&VLOOKUP($U18,[1]CODE!$K:$P,[1]CODE!P$1,FALSE)) -> JST | P18: JST | R18: 17 | T18: JST | U18: FA | V18: N | W18: 14-FW-SP-15 | X18: ADULT | Y18: 0.5 | Z18: 우진모자 | AA18: 41635 | AB18: 41656 | AC18: 41656 | AD18: 41656 | AH18: 4 | AI18: 1
A19: =IF(B19="",0,1/COUNTIF(B:B,B19)) -> 0.5 | B19: =IF(AA19="","",W19) -> 14-FW-SP-15 | C19: =IF(D19="",0,1/COUNTIF(D:D,D19)) -> 1 | D19: =IF(AA19="","",Z19&W19) -> FOREMOST14-FW-SP-15 | E19: =IF(YEAR(AA19)<10,0&YEAR(AA19),YEAR(AA19))&IF(MONTH(AA19)<10,0&MONTH(AA19),MONTH(AA19)) -> 201312 | F19: =VLOOKUP($AA19,주!$A:$F,6,FALSE) -> 12월 4주 | G19: =IF(H19="",0,1/COUNTIF(H:H,H19)) -> 0.5 | H19: =IF(AD19="","",W19) -> 14-FW-SP-15 | I19: =IF(J19="",0,1/COUNTIF(J:J,J19)) -> 1 | J19: =IF(AD19="","",Z19&W19) -> FOREMOST14-FW-SP-15 | K19: =IF(AD19="",AC19,AD19) -> 41656 | L19: =IF(YEAR(K19)<10,0&YEAR(K19),YEAR(K19))&IF(MONTH(K19)<10,0&MONTH(K19),MONTH(K19)) -> 201401 | M19: =VLOOKUP($K19,주!$A:$F,6,FALSE) -> 1월 3주 | N19: =IF(VLOOKUP($Z19,[1]생산업체!$A:$C,2,FALSE)=1,"해외","국내") -> 해외 | O19: =IF(VLOOKUP($U19,[1]CODE!$K:$P,[1]CODE!P$1,FALSE)="모자",T19,T19&"-"&VLOOKUP($U19,[1]CODE!$K:$P,[1]CODE!P$1,FALSE)) -> JST | P19: JST | R19: 18 | T19: JST | U19: FA | V19: N | W19: 14-FW-SP-15 | X19: ADULT | Y19: 0.5 | Z19: FOREMOST | AA19: 41635 | AB19: 41663 | AC19: 41663 | AD19: 41656 | AE19: 6.7 | AH19: 4 | AI19: 1
A20: =IF(B20="",0,1/COUNTIF(B:B,B20)) -> 1 | B20: =IF(AA20="","",W20) -> 14-FW-SP-16 | C20: =IF(D20="",0,1/COUNTIF(D:D,D20)) -> 1 | D20: =IF(AA20="","",Z20&W20) -> TS14-FW-SP-16 | E20: =IF(YEAR(AA20)<10,0&YEAR(AA20),YEAR(AA20))&IF(MONTH(AA20)<10,0&MONTH(AA20),MONTH(AA20)) -> 201312 | F20: =VLOOKUP($AA20,주!$A:$F,6,FALSE) -> 12월 4주 | G20: =IF(H20="",0,1/COUNTIF(H:H,H20)) -> 0 | H20: =IF(AD20="","",W20) | I20: =IF(J20="",0,1/COUNTIF(J:J,J20)) -> 0 | J20: =IF(AD20="","",Z20&W20) | K20: =IF(AD20="",AC20,AD20) -> 41656 | L20: =IF(YEAR(K20)<10,0&YEAR(K20),YEAR(K20))&IF(MONTH(K20)<10,0&MONTH(K20),MONTH(K20)) -> 201401 | M20: =VLOOKUP($K20,주!$A:$F,6,FALSE) -> 1월 3주 | N20: =IF(VLOOKUP($Z20,[1]생산업체!$A:$C,2,FALSE)=1,"해외","국내") -> 국내 | O20: =IF(VLOOKUP($U20,[1]CODE!$K:$P,[1]CODE!P$1,FALSE)="모자",T20,T20&"-"&VLOOKUP($U20,[1]CODE!$K:$P,[1]CODE!P$1,FALSE)) -> JST | P20: JST | R20: 19 | T20: JST | U20: FA | V20: N | W20: 14-FW-SP-16 | X20: ADULT | Y20: 1 | Z20: TS | AA20: 41635 | AB20: 41656 | AC20: 41656 | AH20: 5 | AI20: 1 | AJ20: 안한다함(2/10)
A21: =IF(B21="",0,1/COUNTIF(B:B,B21)) -> 1 | B21: =IF(AA21="","",W21) -> 14-FW-SP-17 | C21: =IF(D21="",0,1/COUNTIF(D:D,D21)) -> 1 | D21: =IF(AA21="","",Z21&W21) -> TS14-FW-SP-17 | E21: =IF(YEAR(AA21)<10,0&YEAR(AA21),YEAR(AA21))&IF(MONTH(AA21)<10,0&MONTH(AA21),MONTH(AA21)) -> 201312 | F21: =VLOOKUP($AA21,주!$A:$F,6,FALSE) -> 12월 4주 | G21: =IF(H21="",0,1/COUNTIF(H:H,H21)) -> 0 | H21: =IF(AD21="","",W21) | I21: =IF(J21="",0,1/COUNTIF(J:J,J21)) -> 0 | J21: =IF(AD21="","",Z21&W21) | K21: =IF(AD21="",AC21,AD21) -> 41656 | L21: =IF(YEAR(K21)<10,0&YEAR(K21),YEAR(K21))&IF(MONTH(K21)<10,0&MONTH(K21),MONTH(K21)) -> 201401 | M21: =VLOOKUP($K21,주!$A:$F,6,FALSE) -> 1월 3주 | N21: =IF(VLOOKUP($Z21,[1]생산업체!$A:$C,2,FALSE)=1,"해외","국내") -> 국내 | O21: =IF(VLOOKUP($U21,[1]CODE!$K:$P,[1]CODE!P$1,FALSE)="모자",T21,T21&"-"&VLOOKUP($U21,[1]CODE!$K:$P,[1]CODE!P$1,FALSE)) -> JST | P21: JST | R21: 20 | T21: JST | U21: FA | V21: N | W21: 14-FW-SP-17 | X21: ADULT | Y21: 1 | Z21: TS | AA21: 41635 | AB21: 41656 | AC21: 41656 | AH21: 5 | AI21: 1 | AJ21: 안한다함(2/10)
A22: =IF(B22="",0,1/COUNTIF(B:B,B22)) -> 0.5 | B22: =IF(AA22="","",W22) -> 14-FW-SP-18 | C22: =IF(D22="",0,1/COUNTIF(D:D,D22)) -> 1 | D22: =IF(AA22="","",Z22&W22) -> FOREMOST14-FW-SP-18 | E22: =IF(YEAR(AA22)<10,0&YEAR(AA22),YEAR(AA22))&IF(MONTH(AA22)<10,0&MONTH(AA22),MONTH(AA22)) -> 201312 | F22: =VLOOKUP($AA22,주!$A:$F,6,FALSE) -> 12월 4주 | G22: =IF(H22="",0,1/COUNTIF(H:H,H22)) -> 0.5 | H22: =IF(AD22="","",W22) -> 14-FW-SP-18 | I22: =IF(J22="",0,1/COUNTIF(J:J,J22)) -> 1 | J22: =IF(AD22="","",Z22&W22) -> FOREMOST14-FW-SP-18 | K22: =IF(AD22="",AC22,AD22) -> 41652 | L22: =IF(YEAR(K22)<10,0&YEAR(K22),YEAR(K22))&IF(MONTH(K22)<10,0&MONTH(K22),MONTH(K22)) -> 201401 | M22: =VLOOKUP($K22,주!$A:$F,6,FALSE) -> 1월 3주 | N22: =IF(VLOOKUP($Z22,[1]생산업체!$A:$C,2,FALSE)=1,"해외","국내") -> 해외 | O22: =IF(VLOOKUP($U22,[1]CODE!$K:$P,[1]CODE!P$1,FALSE)="모자",T22,T22&"-"&VLOOKUP($U22,[1]CODE!$K:$P,[1]CODE!P$1,FALSE)) -> JST | P22: JST | R22: 21 | T22: JST | U22: FA | V22: N | W22: 14-FW-SP-18 | X22: ADULT | Y22: 0.5 | Z22: FOREMOST | AA22: 41635 | AB22: 41663 | AC22: 41663 | AD22: 41652 | AE22: 6.15 | AH22: 4 | AI22: 1
A23: =IF(B23="",0,1/COUNTIF(B:B,B23)) -> 0.5 | B23: =IF(AA23="","",W23) -> 14-FW-SP-18 | C23: =IF(D23="",0,1/COUNTIF(D:D,D23)) -> 1 | D23: =IF(AA23="","",Z23&W23) -> 5 works room14-FW-SP-18 | E23: =IF(YEAR(AA23)<10,0&YEAR(AA23),YEAR(AA23))&IF(MONTH(AA23)<10,0&MONTH(AA23),MONTH(AA23)) -> 201402 | F23: =VLOOKUP($AA23,주!$A:$F,6,FALSE) -> 2월 3주 | G23: =IF(H23="",0,1/COUNTIF(H:H,H23)) -> 0.5 | H23: =IF(AD23="","",W23) -> 14-FW-SP-18 | I23: =IF(J23="",0,1/COUNTIF(J:J,J23)) -> 1 | J23: =IF(AD23="","",Z23&W23) -> 5 works room14-FW-SP-18 | K23: =IF(AD23="",AC23,AD23) -> 41715 | L23: =IF(YEAR(K23)<10,0&YEAR(K23),YEAR(K23))&IF(MONTH(K23)<10,0&MONTH(K23),MONTH(K23)) -> 201403 | M23: =VLOOKUP($K23,주!$A:$F,6,FALSE) -> 3월 4주 | N23: =IF(VLOOKUP($Z23,[1]생산업체!$A:$C,2,FALSE)=1,"해외","국내") -> #N/A | O23: =IF(VLOOKUP($U23,[1]CODE!$K:$P,[1]CODE!P$1,FALSE)="모자",T23,T23&"-"&VLOOKUP($U23,[1]CODE!$K:$P,[1]CODE!P$1,FALSE)) -> JST | P23: JST | R23: 22 | T23: JST | U23: FA | V23: N | W23: 14-FW-SP-18 | X23: ADULT | Y23: 0.5 | Z23: 5 works room | AA23: 41691 | AB23: 41719 | AC23: 41719 | AD23: 41715 | AE23: 4.8 | AH23: 4 | AI23: 1
A24: =IF(B24="",0,1/COUNTIF(B:B,B24)) -> 0.5 | B24: =IF(AA24="","",W24) -> 14-FW-SP-19 | C24: =IF(D24="",0,1/COUNTIF(D:D,D24)) -> 1 | D24: =IF(AA24="","",Z24&W24) -> FOREMOST14-FW-SP-19 | E24: =IF(YEAR(AA24)<10,0&YEAR(AA24),YEAR(AA24))&IF(MONTH(AA24)<10,0&MONTH(AA24),MONTH(AA24)) -> 201312 | F24: =VLOOKUP($AA24,주!$A:$F,6,FALSE) -> 12월 4주 | G24: =IF(H24="",0,1/COUNTIF(H:H,H24)) -> 0.5 | H24: =IF(AD24="","",W24) -> 14-FW-SP-19 | I24: =IF(J24="",0,1/COUNTIF(J:J,J24)) -> 1 | J24: =IF(AD24="","",Z24&W24) -> FOREMOST14-FW-SP-19 | K24: =IF(AD24="",AC24,AD24) -> 41661 | L24: =IF(YEAR(K24)<10,0&YEAR(K24),YEAR(K24))&IF(MONTH(K24)<10,0&MONTH(K24),MONTH(K24)) -> 201401 | M24: =VLOOKUP($K24,주!$A:$F,6,FALSE) -> 1월 4주 | N24: =IF(VLOOKUP($Z24,[1]생산업체!$A:$C,2,FALSE)=1,"해외","국내") -> 해외 | O24: =IF(VLOOKUP($U24,[1]CODE!$K:$P,[1]CODE!P$1,FALSE)="모자",T24,T24&"-"&VLOOKUP($U24,[1]CODE!$K:$P,[1]CODE!P$1,FALSE)) -> JST | P24: JST | R24: 23 | T24: JST | U24: FA | V24: N | W24: 14-FW-SP-19 | X24: ADULT | Y24: 0.5 | Z24: FOREMOST | AA24: 41635 | AB24: 41663 | AC24: 41663 | AD24: 41661 | AE24: 5 | AH24: 3 | AI24: 1
A25: =IF(B25="",0,1/COUNTIF(B:B,B25)) -> 0.5 | B25: =IF(AA25="","",W25) -> 14-FW-SP-19 | C25: =IF(D25="",0,1/COUNTIF(D:D,D25)) -> 1 | D25: =IF(AA25="","",Z25&W25) -> 5 works room14-FW-SP-19 | E25: =IF(YEAR(AA25)<10,0&YEAR(AA25),YEAR(AA25))&IF(MONTH(AA25)<10,0&MONTH(AA25),MONTH(AA25)) -> 201402 | F25: =VLOOKUP($AA25,주!$A:$F,6,FALSE) -> 2월 3주 | G25: =IF(H25="",0,1/COUNTIF(H:H,H25)) -> 0.5 | H25: =IF(AD25="","",W25) -> 14-FW-SP-19 | I25: =IF(J25="",0,1/COUNTIF(J:J,J25)) -> 1 | J25: =IF(AD25="","",Z25&W25) -> 5 works room14-FW-SP-19 | K25: =IF(AD25="",AC25,AD25) -> 41715 | L25: =IF(YEAR(K25)<10,0&YEAR(K25),YEAR(K25))&IF(MONTH(K25)<10,0&MONTH(K25),MONTH(K25)) -> 201403 | M25: =VLOOKUP($K25,주!$A:$F,6,FALSE) -> 3월 4주 | N25: =IF(VLOOKUP($Z25,[1]생산업체!$A:$C,2,FALSE)=1,"해외","국내") -> #N/A | O25: =IF(VLOOKUP($U25,[1]CODE!$K:$P,[1]CODE!P$1,FALSE)="모자",T25,T25&"-"&VLOOKUP($U25,[1]CODE!$K:$P,[1]CODE!P$1,FALSE)) -> JST | P25: JST | R25: 24 | T25: JST | U25: FA | V25: N | W25: 14-FW-SP-19 | X25: ADULT | Y25: 0.5 | Z25: 5 works room | AA25: 41691 | AB25: 41719 | AC25: 41719 | AD25: 41715 | AE25: 4.2 | AH25: 3 | AI25: 1
A26: =IF(B26="",0,1/COUNTIF(B:B,B26)) -> 0.5 | B26: =IF(AA26="","",W26) -> 14-FW-SP-20 | C26: =IF(D26="",0,1/COUNTIF(D:D,D26)) -> 1 | D26: =IF(AA26="","",Z26&W26) -> FOREMOST14-FW-SP-20 | E26: =IF(YEAR(AA26)<10,0&YEAR(AA26),YEAR(AA26))&IF(MONTH(AA26)<10,0&MONTH(AA26),MONTH(AA26)) -> 201312 | F26: =VLOOKUP($AA26,주!$A:$F,6,FALSE) -> 12월 4주 | G26: =IF(H26="",0,1/COUNTIF(H:H,H26)) -> 0.5 | H26: =IF(AD26="","",W26) -> 14-FW-SP-20 | I26: =IF(J26="",0,1/COUNTIF(J:J,J26)) -> 1 | J26: =IF(AD26="","",Z26&W26) -> FOREMOST14-FW-SP-20 | K26: =IF(AD26="",AC26,AD26) -> 41667 | L26: =IF(YEAR(K26)<10,0&YEAR(K26),YEAR(K26))&IF(MONTH(K26)<10,0&MONTH(K26),MONTH(K26)) -> 201401 | M26: =VLOOKUP($K26,주!$A:$F,6,FALSE) -> 1월 5주 | N26: =IF(VLOOKUP($Z26,[1]생산업체!$A:$C,2,FALSE)=1,"해외","국내") -> 해외 | O26: =IF(VLOOKUP($U26,[1]CODE!$K:$P,[1]CODE!P$1,FALSE)="모자",T26,T26&"-"&VLOOKUP($U26,[1]CODE!$K:$P,[1]CODE!P$1,FALSE)) -> JST | P26: JST | R26: 25 | T26: JST | U26: FA | V26: N | W26: 14-FW-SP-20 | X26: ADULT | Y26: 0.5 | Z26: FOREMOST | AA26: 41635 | AB26: 41663 | AC26: 41663 | AD26: 41667 | AE26: 6.7 | AH26: 4 | AI26: 2
A27: =IF(B27="",0,1/COUNTIF(B:B,B27)) -> 0.5 | B27: =IF(AA27="","",W27) -> 14-FW-SP-20 | C27: =IF(D27="",0,1/COUNTIF(D:D,D27)) -> 1 | D27: =IF(AA27="","",Z27&W27) -> BS14-FW-SP-20 | E27: =IF(YEAR(AA27)<10,0&YEAR(AA27),YEAR(AA27))&IF(MONTH(AA27)<10,0&MONTH(AA27),MONTH(AA27)) -> 201312 | F27: =VLOOKUP($AA27,주!$A:$F,6,FALSE) -> 12월 4주 | G27: =IF(H27="",0,1/COUNTIF(H:H,H27)) -> 0.5 | H27: =IF(AD27="","",W27) -> 14-FW-SP-20 | I27: =IF(J27="",0,1/COUNTIF(J:J,J27)) -> 1 | J27: =IF(AD27="","",Z27&W27) -> BS14-FW-SP-20 | K27: =IF(AD27="",AC27,AD27) -> 41694 | L27: =IF(YEAR(K27)<10,0&YEAR(K27),YEAR(K27))&IF(MONTH(K27)<10,0&MONTH(K27),MONTH(K27)) -> 201402 | M27: =VLOOKUP($K27,주!$A:$F,6,FALSE) -> 2월 4주 | N27: =IF(VLOOKUP($Z27,[1]생산업체!$A:$C,2,FALSE)=1,"해외","국내") -> 해외 | O27: =IF(VLOOKUP($U27,[1]CODE!$K:$P,[1]CODE!P$1,FALSE)="모자",T27,T27&"-"&VLOOKUP($U27,[1]CODE!$K:$P,[1]CODE!P$1,FALSE)) -> JST | P27: JST | R27: 26 | T27: JST | U27: FA | V27: N | W27: 14-FW-SP-20 | X27: ADULT | Y27: 0.5 | Z27: BS | AA27: 41635 | AB27: 41663 | AC27: 41663 | AD27: 41694 | AE27: 3.6 | AH27: 4 | AI27: 2
A28: =IF(B28="",0,1/COUNTIF(B:B,B28)) -> 0.33333333 | B28: =IF(AA28="","",W28) -> 14-FW-SP-21 | C28: =IF(D28="",0,1/COUNTIF(D:D,D28)) -> 1 | D28: =IF(AA28="","",Z28&W28) -> 우진모자14-FW-SP-21 | E28: =IF(YEAR(AA28)<10,0&YEAR(AA28),YEAR(AA28))&IF(MONTH(AA28)<10,0&MONTH(AA28),MONTH(AA28)) -> 201312 | F28: =VLOOKUP($AA28,주!$A:$F,6,FALSE) -> 12월 4주 | G28: =IF(H28="",0,1/COUNTIF(H:H,H28)) -> 0.33333333 | H28: =IF(AD28="","",W28) -> 14-FW-SP-21 | I28: =IF(J28="",0,1/COUNTIF(J:J,J28)) -> 1 | J28: =IF(AD28="","",Z28&W28) -> 우진모자14-FW-SP-21 | K28: =IF(AD28="",AC28,AD28) -> 41656 | L28: =IF(YEAR(K28)<10,0&YEAR(K28),YEAR(K28))&IF(MONTH(K28)<10,0&MONTH(K28),MONTH(K28)) -> 201401 | M28: =VLOOKUP($K28,주!$A:$F,6,FALSE) -> 1월 3주 | N28: =IF(VLOOKUP($Z28,[1]생산업체!$A:$C,2,FALSE)=1,"해외","국내") -> 국내 | O28: =IF(VLOOKUP($U28,[1]CODE!$K:$P,[1]CODE!P$1,FALSE)="모자",T28,T28&"-"&VLOOKUP($U28,[1]CODE!$K:$P,[1]CODE!P$1,FALSE)) -> JST | P28: JST | R28: 27 | T28: JST | U28: FA | V28: N | W28: 14-FW-SP-21 | X28: ADULT | Y28: 0.33333333 | Z28: 우진모자 | AA28: 41635 | AB28: 41656 | AC28: 41656 | AD28: 41656 | AH28: 3 | AI28: 1
A29: =IF(B29="",0,1/COUNTIF(B:B,B29)) -> 0.5 | B29: =IF(AA29="","",W29) -> 14-FW-SP-22 | C29: =IF(D29="",0,1/COUNTIF(D:D,D29)) -> 1 | D29: =IF(AA29="","",Z29&W29) -> FOREMOST14-FW-SP-22 | E29: =IF(YEAR(AA29)<10,0&YEAR(AA29),YEAR(AA29))&IF(MONTH(AA29)<10,0&MONTH(AA29),MONTH(AA29)) -> 201401 | F29: =VLOOKUP($AA29,주!$A:$F,6,FALSE) -> 1월 3주 | G29: =IF(H29="",0,1/COUNTIF(H:H,H29)) -> 0.5 | H29: =IF(AD29="","",W29) -> 14-FW-SP-22 | I29: =IF(J29="",0,1/COUNTIF(J:J,J29)) -> 1 | J29: =IF(AD29="","",Z29&W29) -> FOREMOST14-FW-SP-22 | K29: =IF(AD29="",AC29,AD29) -> 41673 | L29: =IF(YEAR(K29)<10,0&YEAR(K29),YEAR(K29))&IF(MONTH(K29)<10,0&MONTH(K29),MONTH(K29)) -> 201402 | M29: =VLOOKUP($K29,주!$A:$F,6,FALSE) -> 2월 1주 | N29: =IF(VLOOKUP($Z29,[1]생산업체!$A:$C,2,FALSE)=1,"해외","국내") -> 해외 | O29: =IF(VLOOKUP($U29,[1]CODE!$K:$P,[1]CODE!P$1,FALSE)="모자",T29,T29&"-"&VLOOKUP($U29,[1]CODE!$K:$P,[1]CODE!P$1,FALSE)) -> JST | P29: JST | R29: 28 | T29: JST | U29: FA | V29: N | W29: 14-FW-SP-22 | X29: ADULT | Y29: 0.5 | Z29: FOREMOST | AA29: 41653 | AB29: 41681 | AC29: 41681 | AD29: 41673 | AE29: 5.7 | AH29: 3 | AI29: 1
A30: =IF(B30="",0,1/COUNTIF(B:B,B30)) -> 0.5 | B30: =IF(AA30="","",W30) -> 14-FW-SP-22 | C30: =IF(D30="",0,1/COUNTIF(D:D,D30)) -> 1 | D30: =IF(AA30="","",Z30&W30) -> BS14-FW-SP-22 | E30: =IF(YEAR(AA30)<10,0&YEAR(AA30),YEAR(AA30))&IF(MONTH(AA30)<10,0&MONTH(AA30),MONTH(AA30)) -> 201401 | F30: =VLOOKUP($AA30,주!$A:$F,6,FALSE) -> 1월 3주 | G30: =IF(H30="",0,1/COUNTIF(H:H,H30)) -> 0.5 | H30: =IF(AD30="","",W30) -> 14-FW-SP-22 | I30: =IF(J30="",0,1/COUNTIF(J:J,J30)) -> 1 | J30: =IF(AD30="","",Z30&W30) -> BS14-FW-SP-22 | K30: =IF(AD30="",AC30,AD30) -> 41705 | L30: =IF(YEAR(K30)<10,0&YEAR(K30),YEAR(K30))&IF(MONTH(K30)<10,0&MONTH(K30),MONTH(K30)) -> 201403 | M30: =VLOOKUP($K30,주!$A:$F,6,FALSE) -> 3월 2주 | N30: =IF(VLOOKUP($Z30,[1]생산업체!$A:$C,2,FALSE)=1,"해외","국내") -> 해외 | O30: =IF(VLOOKUP($U30,[1]CODE!$K:$P,[1]CODE!P$1,FALSE)="모자",T30,T30&"-"&VLOOKUP($U30,[1]CODE!$K:$P,[1]CODE!P$1,FALSE)) -> JST | P30: JST | R30: 29 | T30: JST | U30: FA | V30: N | W30: 14-FW-SP-22 | X30: ADULT | Y30: 0.5 | Z30: BS | AA30: 41653 | AB30: 41681 | AC30: 41681 | AD30: 41705 | AE30: 3.5 | AG30: ORIGINAL SAMPLE | AH30: 3 | AI30: 1
A31: =IF(B31="",0,1/COUNTIF(B:B,B31)) -> 0.5 | B31: =IF(AA31="","",W31) -> 14-FW-SP-25 | C31: =IF(D31="",0,1/COUNTIF(D:D,D31)) -> 1 | D31: =IF(AA31="","",Z31&W31) -> FOREMOST14-FW-SP-25 | E31: =IF(YEAR(AA31)<10,0&YEAR(AA31),YEAR(AA31))&IF(MONTH(AA31)<10,0&MONTH(AA31),MONTH(AA31)) -> 201401 | F31: =VLOOKUP($AA31,주!$A:$F,6,FALSE) -> 1월 3주 | G31: =IF(H31="",0,1/COUNTIF(H:H,H31)) -> 0.5 | H31: =IF(AD31="","",W31) -> 14-FW-SP-25 | I31: =IF(J31="",0,1/COUNTIF(J:J,J31)) -> 1 | J31: =IF(AD31="","",Z31&W31) -> FOREMOST14-FW-SP-25 | K31: =IF(AD31="",AC31,AD31) -> 41687 | L31: =IF(YEAR(K31)<10,0&YEAR(K31),YEAR(K31))&IF(MONTH(K31)<10,0&MONTH(K31),MONTH(K31)) -> 201402 | M31: =VLOOKUP($K31,주!$A:$F,6,FALSE) -> 2월 3주 | N31: =IF(VLOOKUP($Z31,[1]생산업체!$A:$C,2,FALSE)=1,"해외","국내") -> 해외 | O31: =IF(VLOOKUP($U31,[1]CODE!$K:$P,[1]CODE!P$1,FALSE)="모자",T31,T31&"-"&VLOOKUP($U31,[1]CODE!$K:$P,[1]CODE!P$1,FALSE)) -> JST | P31: JST | R31: 30 | T31: JST | U31: FA | V31: N | W31: 14-FW-SP-25 | X31: ADULT | Y31: 0.5 | Z31: FOREMOST | AA31: 41653 | AB31: 41681 | AC31: 41681 | AD31: 41687 | AE31: 6.7 | AG31: ORIGINAL SAMPLE | AH31: 4 | AI31: 1
A32: =IF(B32="",0,1/COUNTIF(B:B,B32)) -> 0.5 | B32: =IF(AA32="","",W32) -> 14-FW-SP-25 | C32: =IF(D32="",0,1/COUNTIF(D:D,D32)) -> 1 | D32: =IF(AA32="","",Z32&W32) -> BS14-FW-SP-25 | E32: =IF(YEAR(AA32)<10,0&YEAR(AA32),YEAR(AA32))&IF(MONTH(AA32)<10,0&MONTH(AA32),MONTH(AA32)) -> 201401 | F32: =VLOOKUP($AA32,주!$A:$F,6,FALSE) -> 1월 3주 | G32: =IF(H32="",0,1/COUNTIF(H:H,H32)) -> 0.5 | H32: =IF(AD32="","",W32) -> 14-FW-SP-25 | I32: =IF(J32="",0,1/COUNTIF(J:J,J32)) -> 1 | J32: =IF(AD32="","",Z32&W32) -> BS14-FW-SP-25 | K32: =IF(AD32="",AC32,AD32) -> 41705 | L32: =IF(YEAR(K32)<10,0&YEAR(K32),YEAR(K32))&IF(MONTH(K32)<10,0&MONTH(K32),MONTH(K32)) -> 201403 | M32: =VLOOKUP($K32,주!$A:$F,6,FALSE) -> 3월 2주 | N32: =IF(VLOOKUP($Z32,[1]생산업체!$A:$C,2,FALSE)=1,"해외","국내") -> 해외 | O32: =IF(VLOOKUP($U32,[1]CODE!$K:$P,[1]CODE!P$1,FALSE)="모자",T32,T32&"-"&VLOOKUP($U32,[1]CODE!$K:$P,[1]CODE!P$1,FALSE)) -> JST | P32: JST | R32: 31 | T32: JST | U32: FA | V32: N | W32: 14-FW-SP-25 | X32: ADULT | Y32: 0.5 | Z32: BS | AA32: 41653 | AB32: 41681 | AC32: 41681 | AD32: 41705 | AE32: 3.2 | AH32: 4 | AI32: 1
A33: =IF(B33="",0,1/COUNTIF(B:B,B33)) -> 0.5 | B33: =IF(AA33="","",W33) -> 14-FW-SP-24 | C33: =IF(D33="",0,1/COUNTIF(D:D,D33)) -> 1 | D33: =IF(AA33="","",Z33&W33) -> FOREMOST14-FW-SP-24 | E33: =IF(YEAR(AA33)<10,0&YEAR(AA33),YEAR(AA33))&IF(MONTH(AA33)<10,0&MONTH(AA33),MONTH(AA33)) -> 201401 | F33: =VLOOKUP($AA33,주!$A:$F,6,FALSE) -> 1월 3주 | G33: =IF(H33="",0,1/COUNTIF(H:H,H33)) -> 0.5 | H33: =IF(AD33="","",W33) -> 14-FW-SP-24 | I33: =IF(J33="",0,1/COUNTIF(J:J,J33)) -> 1 | J33: =IF(AD33="","",Z33&W33) -> FOREMOST14-FW-SP-24 | K33: =IF(AD33="",AC33,AD33) -> 41687 | L33: =IF(YEAR(K33)<10,0&YEAR(K33),YEAR(K33))&IF(MONTH(K33)<10,0&MONTH(K33),MONTH(K33)) -> 201402 | M33: =VLOOKUP($K33,주!$A:$F,6,FALSE) -> 2월 3주 | N33: =IF(VLOOKUP($Z33,[1]생산업체!$A:$C,2,FALSE)=1,"해외","국내") -> 해외 | O33: =IF(VLOOKUP($U33,[1]CODE!$K:$P,[1]CODE!P$1,FALSE)="모자",T33,T33&"-"&VLOOKUP($U33,[1]CODE!$K:$P,[1]CODE!P$1,FALSE)) -> JST | P33: JST | R33: 32 | T33: JST | U33: FA | V33: N | W33: 14-FW-SP-24 | X33: ADULT | Y33: 0.5 | Z33: FOREMOST | AA33: 41653 | AB33: 41681 | AC33: 41681 | AD33: 41687 | AE33: 6.15 | AH33: 3 | AI33: 1
A34: =IF(B34="",0,1/COUNTIF(B:B,B34)) -> 0.5 | B34: =IF(AA34="","",W34) -> 14-FW-SP-24 | C34: =IF(D34="",0,1/COUNTIF(D:D,D34)) -> 1 | D34: =IF(AA34="","",Z34&W34) -> BS14-FW-SP-24 | E34: =IF(YEAR(AA34)<10,0&YEAR(AA34),YEAR(AA34))&IF(MONTH(AA34)<10,0&MONTH(AA34),MONTH(AA34)) -> 201401 | F34: =VLOOKUP($AA34,주!$A:$F,6,FALSE) -> 1월 3주 | G34: =IF(H34="",0,1/COUNTIF(H:H,H34)) -> 0.5 | H34: =IF(AD34="","",W34) -> 14-FW-SP-24 | I34: =IF(J34="",0,1/COUNTIF(J:J,J34)) -> 1 | J34: =IF(AD34="","",Z34&W34) -> BS14-FW-SP-24 | K34: =IF(AD34="",AC34,AD34) -> 41705 | L34: =IF(YEAR(K34)<10,0&YEAR(K34),YEAR(K34))&IF(MONTH(K34)<10,0&MONTH(K34),MONTH(K34)) -> 201403 | M34: =VLOOKUP($K34,주!$A:$F,6,FALSE) -> 3월 2주 | N34: =IF(VLOOKUP($Z34,[1]생산업체!$A:$C,2,FALSE)=1,"해외","국내") -> 해외 | O34: =IF(VLOOKUP($U34,[1]CODE!$K:$P,[1]CODE!P$1,FALSE)="모자",T34,T34&"-"&VLOOKUP($U34,[1]CODE!$K:$P,[1]CODE!P$1,FALSE)) -> JST | P34: JST | R34: 33 | T34: JST | U34: FA | V34: N | W34: 14-FW-SP-24 | X34: ADULT | Y34: 0.5 | Z34: BS | AA34: 41653 | AB34: 41681 | AC34: 41681 | AD34: 41705 | AE34: 3.5 | AG34: ORIGINAL SAMPLE | AH34: 3 | AI34: 1
A35: =IF(B35="",0,1/COUNTIF(B:B,B35)) -> 1 | B35: =IF(AA35="","",W35) -> 14-FW-SP-29 | C35: =IF(D35="",0,1/COUNTIF(D:D,D35)) -> 1 | D35: =IF(AA35="","",Z35&W35) -> 우진모자14-FW-SP-29 | E35: =IF(YEAR(AA35)<10,0&YEAR(AA35),YEAR(AA35))&IF(MONTH(AA35)<10,0&MONTH(AA35),MONTH(AA35)) -> 201401 | F35: =VLOOKUP($AA35,주!$A:$F,6,FALSE) -> 1월 3주 | G35: =IF(H35="",0,1/COUNTIF(H:H,H35)) -> 0 | H35: =IF(AD35="","",W35) | I35: =IF(J35="",0,1/COUNTIF(J:J,J35)) -> 0 | J35: =IF(AD35="","",Z35&W35) | K35: =IF(AD35="",AC35,AD35) -> 41674 | L35: =IF(YEAR(K35)<10,0&YEAR(K35),YEAR(K35))&IF(MONTH(K35)<10,0&MONTH(K35),MONTH(K35)) -> 201402 | M35: =VLOOKUP($K35,주!$A:$F,6,FALSE) -> 2월 1주 | N35: =IF(VLOOKUP($Z35,[1]생산업체!$A:$C,2,FALSE)=1,"해외","국내") -> 국내 | O35: =IF(VLOOKUP($U35,[1]CODE!$K:$P,[1]CODE!P$1,FALSE)="모자",T35,T35&"-"&VLOOKUP($U35,[1]CODE!$K:$P,[1]CODE!P$1,FALSE)) -> JST | P35: JST | R35: 34 | T35: JST | U35: FA | V35: N | W35: 14-FW-SP-29 | X35: ADULT | Y35: 1 | Z35: 우진모자 | AA35: 41653 | AB35: 41674 | AC35: 41674 | AH35: 3 | AI35: 1 | AJ35: 안한다함(2/10)
A36: =IF(B36="",0,1/COUNTIF(B:B,B36)) -> 0.5 | B36: =IF(AA36="","",W36) -> 14-FW-SP-30 | C36: =IF(D36="",0,1/COUNTIF(D:D,D36)) -> 1 | D36: =IF(AA36="","",Z36&W36) -> FOREMOST14-FW-SP-30 | E36: =IF(YEAR(AA36)<10,0&YEAR(AA36),YEAR(AA36))&IF(MONTH(AA36)<10,0&MONTH(AA36),MONTH(AA36)) -> 201401 | F36: =VLOOKUP($AA36,주!$A:$F,6,FALSE) -> 1월 3주 | G36: =IF(H36="",0,1/COUNTIF(H:H,H36)) -> 0.5 | H36: =IF(AD36="","",W36) -> 14-FW-SP-30 | I36: =IF(J36="",0,1/COUNTIF(J:J,J36)) -> 1 | J36: =IF(AD36="","",Z36&W36) -> FOREMOST14-FW-SP-30 | K36: =IF(AD36="",AC36,AD36) -> 41673 | L36: =IF(YEAR(K36)<10,0&YEAR(K36),YEAR(K36))&IF(MONTH(K36)<10,0&MONTH(K36),MONTH(K36)) -> 201402 | M36: =VLOOKUP($K36,주!$A:$F,6,FALSE) -> 2월 1주 | N36: =IF(VLOOKUP($Z36,[1]생산업체!$A:$C,2,FALSE)=1,"해외","국내") -> 해외 | O36: =IF(VLOOKUP($U36,[1]CODE!$K:$P,[1]CODE!P$1,FALSE)="모자",T36,T36&"-"&VLOOKUP($U36,[1]CODE!$K:$P,[1]CODE!P$1,FALSE)) -> JST | P36: JST | R36: 35 | T36: JST | U36: FA | V36: N | W36: 14-FW-SP-30 | X36: ADULT | Y36: 0.5 | Z36: FOREMOST | AA36: 41653 | AB36: 41681 | AC36: 41681 | AD36: 41673 | AE36: 5.7 | AH36: 5 | AI36: 1
A37: =IF(B37="",0,1/COUNTIF(B:B,B37)) -> 0.5 | B37: =IF(AA37="","",W37) -> 14-FW-SP-30 | C37: =IF(D37="",0,1/COUNTIF(D:D,D37)) -> 1 | D37: =IF(AA37="","",Z37&W37) -> BS14-FW-SP-30 | E37: =IF(YEAR(AA37)<10,0&YEAR(AA37),YEAR(AA37))&IF(MONTH(AA37)<10,0&MONTH(AA37),MONTH(AA37)) -> 201401 | F37: =VLOOKUP($AA37,주!$A:$F,6,FALSE) -> 1월 3주 | G37: =IF(H37="",0,1/COUNTIF(H:H,H37)) -> 0.5 | H37: =IF(AD37="","",W37) -> 14-FW-SP-30 | I37: =IF(J37="",0,1/COUNTIF(J:J,J37)) -> 1 | J37: =IF(AD37="","",Z37&W37) -> BS14-FW-SP-30 | K37: =IF(AD37="",AC37,AD37) -> 41705 | L37: =IF(YEAR(K37)<10,0&YEAR(K37),YEAR(K37))&IF(MONTH(K37)<10,0&MONTH(K37),MONTH(K37)) -> 201403 | M37: =VLOOKUP($K37,주!$A:$F,6,FALSE) -> 3월 2주 | N37: =IF(VLOOKUP($Z37,[1]생산업체!$A:$C,2,FALSE)=1,"해외","국내") -> 해외 | O37: =IF(VLOOKUP($U37,[1]CODE!$K:$P,[1]CODE!P$1,FALSE)="모자",T37,T37&"-"&VLOOKUP($U37,[1]CODE!$K:$P,[1]CODE!P$1,FALSE)) -> JST | P37: JST | R37: 36 | T37: JST | U37: FA | V37: N | W37: 14-FW-SP-30 | X37: ADULT | Y37: 0.5 | Z37: BS | AA37: 41653 | AB37: 41681 | AC37: 41681 | AD37: 41705 | AE37: 3.2 | AH37: 5 | AI37: 1
A38: =IF(B38="",0,1/COUNTIF(B:B,B38)) -> 1 | B38: =IF(AA38="","",W38) -> 14-FW-SP-37 | C38: =IF(D38="",0,1/COUNTIF(D:D,D38)) -> 1 | D38: =IF(AA38="","",Z38&W38) -> BS14-FW-SP-37 | E38: =IF(YEAR(AA38)<10,0&YEAR(AA38),YEAR(AA38))&IF(MONTH(AA38)<10,0&MONTH(AA38),MONTH(AA38)) -> 201401 | F38: =VLOOKUP($AA38,주!$A:$F,6,FALSE) -> 1월 3주 | G38: =IF(H38="",0,1/COUNTIF(H:H,H38)) -> 1 | H38: =IF(AD38="","",W38) -> 14-FW-SP-37 | I38: =IF(J38="",0,1/COUNTIF(J:J,J38)) -> 1 | J38: =IF(AD38="","",Z38&W38) -> BS14-FW-SP-37 | K38: =IF(AD38="",AC38,AD38) -> 41705 | L38: =IF(YEAR(K38)<10,0&YEAR(K38),YEAR(K38))&IF(MONTH(K38)<10,0&MONTH(K38),MONTH(K38)) -> 201403 | M38: =VLOOKUP($K38,주!$A:$F,6,FALSE) -> 3월 2주 | N38: =IF(VLOOKUP($Z38,[1]생산업체!$A:$C,2,FALSE)=1,"해외","국내") -> 해외 | O38: =IF(VLOOKUP($U38,[1]CODE!$K:$P,[1]CODE!P$1,FALSE)="모자",T38,T38&"-"&VLOOKUP($U38,[1]CODE!$K:$P,[1]CODE!P$1,FALSE)) -> JST | P38: JST | R38: 37 | T38: JST | U38: FA | V38: N | W38: 14-FW-SP-37 | X38: ADULT | Y38: 1 | Z38: BS | AA38: 41653 | AB38: 41681 | AC38: 41681 | AD38: 41705 | AE38: 3.5 | AG38: ORIGINAL SAMPLE | AH38: 3 | AI38: 1
A39: =IF(B39="",0,1/COUNTIF(B:B,B39)) -> 1 | B39: =IF(AA39="","",W39) -> 14-FW-SP-38 | C39: =IF(D39="",0,1/COUNTIF(D:D,D39)) -> 1 | D39: =IF(AA39="","",Z39&W39) -> FOREMOST14-FW-SP-38 | E39: =IF(YEAR(AA39)<10,0&YEAR(AA39),YEAR(AA39))&IF(MONTH(AA39)<10,0&MONTH(AA39),MONTH(AA39)) -> 201401 | F39: =VLOOKUP($AA39,주!$A:$F,6,FALSE) -> 1월 3주 | G39: =IF(H39="",0,1/COUNTIF(H:H,H39)) -> 1 | H39: =IF(AD39="","",W39) -> 14-FW-SP-38 | I39: =IF(J39="",0,1/COUNTIF(J:J,J39)) -> 1 | J39: =IF(AD39="","",Z39&W39) -> FOREMOST14-FW-SP-38 | K39: =IF(AD39="",AC39,AD39) -> 41690 | L39: =IF(YEAR(K39)<10,0&YEAR(K39),YEAR(K39))&IF(MONTH(K39)<10,0&MONTH(K39),MONTH(K39)) -> 201402 | M39: =VLOOKUP($K39,주!$A:$F,6,FALSE) -> 2월 3주 | N39: =IF(VLOOKUP($Z39,[1]생산업체!$A:$C,2,FALSE)=1,"해외","국내") -> 해외 | O39: =IF(VLOOKUP($U39,[1]CODE!$K:$P,[1]CODE!P$1,FALSE)="모자",T39,T39&"-"&VLOOKUP($U39,[1]CODE!$K:$P,[1]CODE!P$1,FALSE)) -> JST | P39: JST | R39: 38 | T39: JST | U39: FA | V39: N | W39: 14-FW-SP-38 | X39: ADULT | Y39: 1 | Z39: FOREMOST | AA39: 41653 | AB39: 41681 | AC39: 41681 | AD39: 41690 | AE39: 9.5 | AG39: ORIGINAL SAMPLE | AH39: 1 | AI39: 1
A40: =IF(B40="",0,1/COUNTIF(B:B,B40)) -> 1 | B40: =IF(AA40="","",W40) -> 14-FW-SP-23 | C40: =IF(D40="",0,1/COUNTIF(D:D,D40)) -> 1 | D40: =IF(AA40="","",Z40&W40) -> TS14-FW-SP-23 | E40: =IF(YEAR(AA40)<10,0&YEAR(AA40),YEAR(AA40))&IF(MONTH(AA40)<10,0&MONTH(AA40),MONTH(AA40)) -> 201401 | F40: =VLOOKUP($AA40,주!$A:$F,6,FALSE) -> 1월 3주 | G40: =IF(H40="",0,1/COUNTIF(H:H,H40)) -> 0 | H40: =IF(AD40="","",W40) | I40: =IF(J40="",0,1/COUNTIF(J:J,J40)) -> 0 | J40: =IF(AD40="","",Z40&W40) | K40: =IF(AD40="",AC40,AD40) -> 41674 | L40: =IF(YEAR(K40)<10,0&YEAR(K40),YEAR(K40))&IF(MONTH(K40)<10,0&MONTH(K40),MONTH(K40)) -> 201402 | M40: =VLOOKUP($K40,주!$A:$F,6,FALSE) -> 2월 1주 | N40: =IF(VLOOKUP($Z40,[1]생산업체!$A:$C,2,FALSE)=1,"해외","국내") -> 국내 | O40: =IF(VLOOKUP($U40,[1]CODE!$K:$P,[1]CODE!P$1,FALSE)="모자",T40,T40&"-"&VLOOKUP($U40,[1]CODE!$K:$P,[1]CODE!P$1,FALSE)) -> JST | P40: JST | R40: 39 | T40: JST | U40: FA | V40: N | W40: 14-FW-SP-23 | X40: ADULT | Y40: 1 | Z40: TS | AA40: 41653 | AB40: 41674 | AC40: 41674 | AH40: 5 | AI40: 1 | AJ40: 안한다함(2/10)
...

Sheet 兰
A1: 13SS BROWN SQUARE SAMPLE STATUS
A2: 1ST PROTO TYPE | S2: 41221
A3: SAMPLE # | B3: COLOR | C3: SKETCH | D3: PRODUCTION FIRM | E3: DESIGNER | F3: PROTO SAMPLE | I3: U/PRICE | J3: RXK MATERIAL | K3: ACC. MATERIAL | O3: ACC. MATERIAL | S3: REMARK | T3: PROTO SAMPLE COMMENTS
F4: D. ATRWORK | G4: REQUEST | H4: RCVD | K4: METAL | L4: COLOR | M4: U/PIRICE | N4: MOQ & LEADTIME | O4: LEATHER | P4: CFM NO. | Q4: U/PIRICE | R4: MOQ & LEADTIME
A5: CAP-01 | B5: BLUE | D5: CNG | E5: sinclair | F5: 41180 | G5: OK | H5: at earliest 11/9 | S5: 굵은실, 6쪽 바이오워싱 BIO washing (生物洗涤）
B6: PINK | D6: DONGRI | E6: sinclair | F6: 41192 | G6: 41197 | H6: 41219 | I6: US $ 5.35 | J6: #1,#2, leather fabric metal | L6: antique silver | M6: 0.067 | N6: 7~10 DAYS Mounld fee US$80.00 | P6: NB-02 | Q6: US$ 2.38/FEET | R6: CHINA STOCKS
P7: SB-03 | Q7: US$ 4.76/FEET | R7: CHINA STOCKS
A8: CAP-02 | B8: LM | D8: CNG | E8: sinclair | F8: 41180 | G8: OK | H8: at earliest 11/9 | S8: 6쪽 BIO washing
B9: RED | D9: DONGRI | E9: sinclair | F9: 41192 | G9: 41197 | H9: 41219 | I9: US $ 4.60 | J9: #1,#2,#3, leather fabric metal | L9: antique silver | M9: 0.076 | N9: 7~10 DAYS | P9: NB-02 | Q9: US$ 2.38/FEET | R9: CHINA STOCKS
P10: SB-03 | Q10: US$ 4.76/FEET | R10: CHINA STOCKS
A11: CAP-03 | B11: BEIGE | D11: CNG | E11: sinclair | F11: 41180 | G11: OK | H11: at earliest 11/9 | S11: 6쪽 BIO washing
B12: NAVY | D12: DONGRI | E12: sinclair | F12: 41192 | G12: 41197 | H12: 41219 | I12: US $ 5.35 | J12: #1,#2,#3,#4 leather fabric metal | L12: antique silver | M12: 0.076 | N12: 7~10 DAYS | P12: NB-02 | Q12: US$ 2.38/FEET | R12: CHINA STOCKS
P13: SB-03 | Q13: US$ 4.76/FEET | R13: CHINA STOCKS
A14: CAP-04 | B14: BLUE | D14: CNG | E14: sinclair | F14: 41180 | G14: OK | H14: at earliest 11/9 | S14: 굵은실, 6쪽 hard BIO washing
A15: CAP-05 | B15: WHITE | D15: CNG | E15: mathew | F15: 41180 | G15: OK | H15: at earliest 11/9 | S15: 굵은실, 6쪽 hard BIO washing
A16: CAP-06 | B16: PINK | D16: CNG | E16: mathew | F16: 41180 | G16: OK | H16: at earliest 11/9 | S16: 굵은실, 6쪽 hard BIO washing
A17: CAP-07 | B17: RED | D17: CNG | E17: mathew | F17: 41180 | G17: OK | H17: at earliest 11/9 | S17: 6쪽 soft BIO washing
B18: YELLOW | D18: DONGRI | E18: mathew | F18: 41192 | G18: 41197 | H18: 41219 | I18: US $ 4.70 | J18: #1,#2,#3,#4,#5, leather fabric metal | K18: N/A | L18: x | M18: x | N18: x | P18: SB-03 | Q18: US$ 4.76/FEET | R18: CHINA STOCKS
A19: CAP-08 | B19: MINT | D19: CNG | E19: mathew | F19: 41180 | G19: OK | H19: at earliest 11/9 | S19: 6쪽 soft BIO washing
B20: BLUE | D20: DONGRI | E20: mathew | F20: 41192 | G20: 41197 | H20: 41219 | I20: US $ 5.55 | J20: #1,#2,#3,#4 leather fabric metal | L20: antique silver | M20: 0.067 | N20: 7~10 DAYS | P20: NB-02 | Q20: US$ 2.38/FEET | R20: CHINA STOCKS | S20: (셔닐자수) 6쪽 chenille embroidery 雪尼尔花线 刺绣 soft BIO washing
P21: SB-03 | Q21: US$ 4.76/FEET | R21: CHINA STOCKS
A22: CAP-09 | B22: BLACK | D22: CNG | E22: sinclair | F22: 41180 | G22: OK | H22: at earliest 11/9 | S22: 6쪽 soft BIO washing
B23: PINK | D23: DONGRI | E23: sinclair | F23: 41192 | G23: 41197 | H23: 41219 | I23: US $ 4.40 | J23: #1,#2,#3,#4 leather fabric metal | L23: antique silver | M23: 0.076 | N23: 7~10 DAYS | P23: NB-02 | Q23: US$ 2.38/FEET | R23: CHINA STOCKS
P24: SB-03 | Q24: US$ 4.76/FEET | R24: CHINA STOCKS
A25: CAP-10 | B25: KHAKI | D25: CNG | E25: sinclair | F25: 41180 | G25: OK | H25: at earliest 11/9 | S25: (굵은실) 6쪽 soft BIO washing
B26: BEIGE | D26: DONGRI | E26: sinclair | F26: 41192 | G26: 41197 | H26: 41219 | I26: US $5.48 | J26: #1,#2,#3,#4,#5 leather fabric | K26: N/A | P26: SB-03 | Q26: US$ 4.76/FEET | R26: CHINA STOCKS
A27: CAP-11 | B27: LM | D27: CNG | E27: sinclair | F27: 41180 | G27: OK | H27: at earliest 11/9 | S27: (굵은실) 6쪽 no washing
B28: PINK
B29: BLACK | D29: DONGRI | E29: sinclair | F29: 41192 | G29: 41197 | H29: 41219 | I29: US $5.20 | J29: #1,#2,#3 leather fabric metal | L29: antique silver | M29: 0.067 | N29: 7~10 DAYS | P29: SB-03 | Q29: US$ 4.76/FEET | R29: CHINA STOCKS
A30: CAP-12 | B30: BLUE | D30: CNG | E30: mathew | F30: 41180 | G30: OK | H30: at earliest 11/9 | S30: 6쪽 no washing
B31: RED | D31: DONGRI | E31: mathew | F31: 41192 | G31: 41197 | H31: 41219 | I31: US $5.65 | J31: #1,#2, leather fabric metal | L31: antique silver | M31: 0.076 | N31: 7~10 DAYS | P31: NB-02 | Q31: US$ 2.38/FEET | R31: CHINA STOCKS
P32: SB-03 | Q32: US$ 4.76/FEET | R32: CHINA STOCKS
A33: CAP-13 | B33: YELLOW | D33: CNG | E33: mathew | F33: 41180 | G33: OK | H33: at earliest 11/9 | S33: 6쪽 no washing
B34: NAVY | D34: DONGRI | E34: mathew | F34: 41192 | G34: 41197 | H34: 41219 | I34: US $5.65 | J34: #1,#2,#3,#4,#5 leather fabric metal | L34: antique silver | M34: 0.076 | N34: 7~10 DAYS | P34: SB-03 | Q34: US$ 4.76/FEET | R34: CHINA STOCKS
A35: CAP-14 | B35: NAVY | D35: CNG | E35: mathew | F35: 41180 | G35: OK | H35: at earliest 11/9 | S35: 숏바이저 6쪽 short visor (短帽檐） no washing
B36: MINT | D36: DONGRI | E36: mathew | F36: 41192 | G36: 10/24 Leather Delayed | H36: 41219 | I36: US $4.60 | J36: #1,#2, leather fabric metal | L36: antique silver | M36: 0.076 | N36: 7~10 DAYS | P36: NB-02 | Q36: US$ 2.38/FEET | R36: CHINA STOCKS
K37: thick leather | L37: BROWN | M37: ￦..? | N37: 한국업체 | P37: SB-03 | Q37: US$ 4.76/FEET | R37: CHINA STOCKS
A38: CAP-15 | B38: BU | D38: CNG | E38: sinclair | F38: 41180 | G38: OK | H38: at earliest 11/9 | S38: 숏바이저 6쪽 평챙 short visor (短平帽檐） no washing
B39: MINT | D39: DONGRI | E39: sinclair | F39: 41192 | G39: 10/17 Fabric Delayed | H39: 41219 | I39: US $4.60 | J39: #1,#2,#3,#4 leather fabric | K39: N/A | L39: x | M39: x | N39: x | P39: NB-02 | Q39: US$ 2.38/FEET | R39: CHINA STOCKS
P40: SB-03 | Q40: US$ 4.76/FEET | R40: CHINA STOCKS
...

Sheet LAN NOVENT
A1: 13SS NOVENT SAMPLE STATUS
A2: 1ST PROTO TYPE
R3: 41221
A4: SAMPLE # | B4: COLOR | C4: SKETCH | D4: PRODUCTION FIRM | E4: DESIGNER | F4: PROTO SAMPLE | J4: PRICING INFO | L4: ACC. MATERIAL | R4: REMARK | S4: PROTO SAMPLE COMMENTS
F5: D. ATRWORK | G5: REQUEST | H5: RCVD | I5: REF SMPL | J5: U/PRICE | K5: INCLUDING MEMO | L5: LEATHER PATCH | M5: DIAMOND LABEL | N5: MAIN LABEL | O5: RUBBER LABEL | P5: BUCKLE | Q5: OTHERS
A6: NV 01_WIRE | B6: MINT | D6: FOREMOST | E6: Camilo | F6: OK | G6: 41193 | H6: 41213 | I6: X | J6: US $ 3.70 | K6: fabric diamond label | L6: X | Q6: X | R6: 11/12 D실-> all style China fabric swatch & 13ss samples. Design team CFMing
A7: NV 02_WIRE | B7: BLUE | D7: FOREMOST | E7: Camilo | F7: OK | G7: 41193 | H7: 41213 | I7: X | J7: US $ 3.70 | K7: fabric diamond label | L7: X | Q7: X
A8: NV 03_WIRE | B8: RED | D8: FOREMOST | E8: Camilo | F8: OK | G8: 41193 | H8: 41213 | I8: X | J8: US $ 4.15 | K8: fabric woven label leather patch | O8: X | Q8: X
A9: NV 04_CAMP | B9: DENIM | D9: FOREMOST | E9: Benny | F9: OK | G9: 41193 | H9: 41220 | I9: X | J9: US $ 3.00 | K9: fabric woven label leather patch | M9: X
A10: NV 05_CAMP | B10: BLACK | D10: FOREMOST | E10: Camilo | F10: OK | G10: 41193 | H10: 41219 | I10: X | J10: US $ 3.10 | K10: fabric woven label leather patch | M10: X
A11: NV 06_TULIP HAT | B11: BLUE | D11: FOREMOST | E11: Camilo | F11: OK | G11: 41193 | H11: 41225 | I11: X | J11: RCVD 11/12 | L11: X | M11: X | N11: X | P11: X
A12: NV 07_WIRE | B12: NAVY | D12: FOREMOST | E12: Benny | F12: OK | G12: 41193 | H12: 41213 | I12: X | J12: US $ 2.95 | M12: X | Q12: X
A13: NV 08_WIRE | B13: CAMAL | D13: FOREMOST | E13: Benny | F13: OK | G13: 41193 | H13: 41213 | I13: X | J13: US $ 2.90 | M13: X | N13: X | P13: X | Q13: X
A14: NV 09_WIRE | B14: NAVY | D14: FOREMOST | E14: Benny | F14: OK | G14: 41193 | H14: 41213 | I14: X | J14: US $ 3.85 | Q14: X
A15: NV10_WIRE | B15: PP | D15: FOREMOST | E15: Benny | F15: OK | G15: 41193 | H15: 41213 | I15: X | J15: US $ 3.50
A16: NV11_HAT | B16: PP | D16: FOREMOST | E16: Benny | F16: OK | G16: 41193 | H16: 41213 | I16: X | J16: US $ 4.45 | Q16: X
A17: 13SS NOVENT KIDS
A19: SAMPLE # | B19: COLOR | C19: SKETCH | D19: PRODUCTION FIRM | E19: DESIGNER | F19: PROTO SAMPLE | J19: PRICING INFO | L19: ACC. MATERIAL | R19: REMARK | S19: PROTO SAMPLE COMMENTS
F20: D. ATRWORK | G20: REQUEST | H20: RCVD | I20: REF SMPL | J20: U/PRICE | K20: INCLUDING MEMO | L20: LEATHER PATCH | M20: DIAMOND LABEL | N20: MAIN LABEL | O20: RUBBER LABEL | P20: BUCKLE | Q20: OTHERS
A21: NV 12_WIRE (KIDS) | B21: PP | D21: FOREMOST | E21: Benny | F21: 41220 | G21: 41220 | H21: 11/16 FOR.SEND | I21: NOVBAD3107YE (CAPBOY작업건) 1 PCS | M21: X | Q21: X | R21: FOR. 중국원단 수배1week후 샘플제작, 작업시간 : 샘플발송부터 1주일로 제한 SIZE : ROUND 52CM
B22: RED | D22: FOREMOST | E22: Benny | F22: 41220 | G22: 41220 | H22: 11/16 FOR.SEND | M22: X | Q22: X

Sheet 노민석 (JST,BEL)
C1: 14FW SAMPLE LIST
I2: 표기예 | M2: LEAD TIME | N2: 임의일자이니 확인되면 수정하고 색 지우기 | O2: 실입고일은 실제 샘플수령한 일자, 미입고시에는 공란 | S2: 총수=원자재 가지수 사용수=원자재 중 중국원자재 사용가지수 숫자로 표기
C3: * SAMPLE NO. = ARTWORK의 SAMPLE NO.와 동일해야 함 | I3: ADULT | M3: 국내제조
C4: * 발주일 = 작지+공급자재(+참조샘플) 최종 발송일 기준 | I4: CHILD | M4: 21
C5: * 목표입고일 = 발주시 생산업체와 협의 후 반드시 기록 | I5: INFANT | M5: 해외제조
C6: * 원가 = 입고시 반드시 기록 | M6: 28
J7: =SUM(J11:J1048576) -> 58
C8: 순번 | D8: 이미지 | E8: 브랜드 | F8: 품목 | G8: 러닝(R)/신규(N) | H8: SAMPLE NO. | I8: 연령구분 | J8: 샘플수 | K8: 생산업체 | L8: 일정 | P8: 원가 | R8: 참조샘플 발송여부 | S8: 중국원단사용수 | U8: 기타
A9: 브랜드/품목 | L9: 발주일 | M9: 목표입고일 | N9: 입고예정일 | O9: 실입고일 | P9: 해외 (FOB, USD, JPY) | Q9: 국내 (-V, KRW) | S9: 총수 | T9: 사용수
C10: 순번 | D10: 이미지 | E10: 브랜드 | F10: 품목 | G10: 러닝(R)/신규(N) | H10: SAMPLE NO. | I10: 연령구분 | J10: 샘플수 | K10: 생산업체 | L10: 발주일 | M10: 목표입고일 | N10: 입고예정일 | O10: 실입고일 | P10: 해외원가 | Q10: 국내원가 | R10: 참조샘플 발송여부 | S10: 중국원단사용총수 | T10: 중국원단사용수 | U10: 기타
A11: =IF(E11="","",IF(VLOOKUP($F11,CODE!$K:$O,CODE!$O$1,FALSE)="",$E11,$E11&"-"&VLOOKUP($F11,CODE!$K:$O,CODE!$O$1,FALSE))) -> JST | C11: 1 | E11: JST | F11: FA | G11: N | H11: 14-FW-SP-06 | I11: ADULT | J11: =IF(ISERROR(1/COUNTIF(H:H,H11))=TRUE,0,1/COUNTIF(H:H,H11)) -> 0.5 | K11: FOREMOST | L11: 41635 | M11: =IF(ISERROR(VLOOKUP($K11,생산업체!$A:$C,생산업체!$A$1,FALSE))=TRUE,"업체리스트 참조 후 업체명 변경",IF(VLOOKUP($K11,생산업체!$A:$C,생산업체!$B$1,FALSE)=1,$L11+$M$6,$L11+$M$4)) -> 41663 | N11: =M11 -> 41663 | O11: 41656 | P11: 6.5 | R11: ORIGINAL SAMPLE | S11: 4 | T11: 1 | U11: x
A12: =IF(E12="","",IF(VLOOKUP($F12,CODE!$K:$O,CODE!$O$1,FALSE)="",$E12,$E12&"-"&VLOOKUP($F12,CODE!$K:$O,CODE!$O$1,FALSE))) -> JST | C12: =C11+1 -> 2 | E12: JST | F12: FA | G12: N | H12: 14-FW-SP-06 | I12: ADULT | J12: =IF(ISERROR(1/COUNTIF(H:H,H12))=TRUE,0,1/COUNTIF(H:H,H12)) -> 0.5 | K12: BS | L12: 41635 | M12: =IF(ISERROR(VLOOKUP($K12,생산업체!$A:$C,생산업체!$A$1,FALSE))=TRUE,"업체리스트 참조 후 업체명 변경",IF(VLOOKUP($K12,생산업체!$A:$C,생산업체!$B$1,FALSE)=1,$L12+$M$6,$L12+$M$4)) -> 41663 | N12: =M12 -> 41663 | O12: 41694 | P12: 3.8 | S12: 4 | T12: 1
A13: =IF(E13="","",IF(VLOOKUP($F13,CODE!$K:$O,CODE!$O$1,FALSE)="",$E13,$E13&"-"&VLOOKUP($F13,CODE!$K:$O,CODE!$O$1,FALSE))) -> JST | C13: =C12+1 -> 3 | E13: JST | F13: FA | G13: N | H13: 14-FW-SP-07 | I13: ADULT | J13: =IF(ISERROR(1/COUNTIF(H:H,H13))=TRUE,0,1/COUNTIF(H:H,H13)) -> 0.5 | K13: FOREMOST | L13: 41635 | M13: =IF(ISERROR(VLOOKUP($K13,생산업체!$A:$C,생산업체!$A$1,FALSE))=TRUE,"업체리스트 참조 후 업체명 변경",IF(VLOOKUP($K13,생산업체!$A:$C,생산업체!$B$1,FALSE)=1,$L13+$M$6,$L13+$M$4)) -> 41663 | N13: =M13 -> 41663 | O13: 41652 | P13: 5.7 | S13: 4 | T13: 1 | U13: x
A14: =IF(E14="","",IF(VLOOKUP($F14,CODE!$K:$O,CODE!$O$1,FALSE)="",$E14,$E14&"-"&VLOOKUP($F14,CODE!$K:$O,CODE!$O$1,FALSE))) -> JST | C14: =C13+1 -> 4 | E14: JST | F14: FA | G14: N | H14: 14-FW-SP-07 | I14: ADULT | J14: =IF(ISERROR(1/COUNTIF(H:H,H14))=TRUE,0,1/COUNTIF(H:H,H14)) -> 0.5 | K14: BS | L14: 41635 | M14: =IF(ISERROR(VLOOKUP($K14,생산업체!$A:$C,생산업체!$A$1,FALSE))=TRUE,"업체리스트 참조 후 업체명 변경",IF(VLOOKUP($K14,생산업체!$A:$C,생산업체!$B$1,FALSE)=1,$L14+$M$6,$L14+$M$4)) -> 41663 | N14: =M14 -> 41663 | O14: 41694 | P14: 3.2 | R14: ORIGINAL SAMPLE | S14: 4 | T14: 1 | U14: 오리지널샘플받아야함
A15: =IF(E15="","",IF(VLOOKUP($F15,CODE!$K:$O,CODE!$O$1,FALSE)="",$E15,$E15&"-"&VLOOKUP($F15,CODE!$K:$O,CODE!$O$1,FALSE))) -> JST | C15: =C14+1 -> 5 | E15: JST | F15: FA | G15: N | H15: 14-FW-SP-08 | I15: ADULT | J15: =IF(ISERROR(1/COUNTIF(H:H,H15))=TRUE,0,1/COUNTIF(H:H,H15)) -> 1 | K15: FOREMOST | L15: 41635 | M15: =IF(ISERROR(VLOOKUP($K15,생산업체!$A:$C,생산업체!$A$1,FALSE))=TRUE,"업체리스트 참조 후 업체명 변경",IF(VLOOKUP($K15,생산업체!$A:$C,생산업체!$B$1,FALSE)=1,$L15+$M$6,$L15+$M$4)) -> 41663 | N15: =M15 -> 41663 | O15: 41656 | P15: 6.7 | S15: 4 | T15: 1 | U15: x
A16: =IF(E16="","",IF(VLOOKUP($F16,CODE!$K:$O,CODE!$O$1,FALSE)="",$E16,$E16&"-"&VLOOKUP($F16,CODE!$K:$O,CODE!$O$1,FALSE))) -> JST | C16: =C15+1 -> 6 | E16: JST | F16: FA | G16: N | H16: 14-FW-SP-09 | I16: ADULT | J16: =IF(ISERROR(1/COUNTIF(H:H,H16))=TRUE,0,1/COUNTIF(H:H,H16)) -> 0.5 | K16: FOREMOST | L16: 41635 | M16: =IF(ISERROR(VLOOKUP($K16,생산업체!$A:$C,생산업체!$A$1,FALSE))=TRUE,"업체리스트 참조 후 업체명 변경",IF(VLOOKUP($K16,생산업체!$A:$C,생산업체!$B$1,FALSE)=1,$L16+$M$6,$L16+$M$4)) -> 41663 | N16: =M16 -> 41663 | O16: 41661 | P16: 7 | S16: 5 | T16: 1 | U16: x
A17: =IF(E17="","",IF(VLOOKUP($F17,CODE!$K:$O,CODE!$O$1,FALSE)="",$E17,$E17&"-"&VLOOKUP($F17,CODE!$K:$O,CODE!$O$1,FALSE))) -> JST | C17: =C16+1 -> 7 | E17: JST | F17: FA | G17: N | H17: 14-FW-SP-09 | I17: ADULT | J17: =IF(ISERROR(1/COUNTIF(H:H,H17))=TRUE,0,1/COUNTIF(H:H,H17)) -> 0.5 | K17: BS | L17: 41635 | M17: =IF(ISERROR(VLOOKUP($K17,생산업체!$A:$C,생산업체!$A$1,FALSE))=TRUE,"업체리스트 참조 후 업체명 변경",IF(VLOOKUP($K17,생산업체!$A:$C,생산업체!$B$1,FALSE)=1,$L17+$M$6,$L17+$M$4)) -> 41663 | N17: =M17 -> 41663 | O17: 41694 | P17: 3.8 | R17: ORIGINAL SAMPLE | S17: 5 | T17: 1
A18: =IF(E18="","",IF(VLOOKUP($F18,CODE!$K:$O,CODE!$O$1,FALSE)="",$E18,$E18&"-"&VLOOKUP($F18,CODE!$K:$O,CODE!$O$1,FALSE))) -> JST | C18: =C17+1 -> 8 | E18: JST | F18: FA | G18: N | H18: 14-FW-SP-10 | I18: ADULT | J18: =IF(ISERROR(1/COUNTIF(H:H,H18))=TRUE,0,1/COUNTIF(H:H,H18)) -> 0.5 | K18: FOREMOST | L18: 41635 | M18: =IF(ISERROR(VLOOKUP($K18,생산업체!$A:$C,생산업체!$A$1,FALSE))=TRUE,"업체리스트 참조 후 업체명 변경",IF(VLOOKUP($K18,생산업체!$A:$C,생산업체!$B$1,FALSE)=1,$L18+$M$6,$L18+$M$4)) -> 41663 | N18: =M18 -> 41663 | O18: 41652 | P18: 5.4 | S18: 3 | T18: 1 | U18: x
