Workbook

Sheet 정리
B1: 13FW 샘플 진행 현황
B2: 생산업체별 샘플수 | J2: 총샘플수
B3: 개수 : 샘플수 | E3: 생산업체 | J3: 합계 : 샘플수
B4: 브랜드 | C4: 품목 | D4: SAMPLE NO. | E4: FOREMOST | F4: 성진 | G4: 캡보이 | J4: 브랜드 | K4: 품목 | L4: SAMPLE NO. | M4: 요약
B5: SMB | C5: FI | D5: 12FW SMB_02_FLAT_RD | F5: 2 | J5: SMB | K5: FI | L5: 12FW SMB_02_FLAT_RD | M5: 1
D6: 12FW SMB_03_FLAT_BK | F6: 2 | L6: 12FW SMB_03_FLAT_BK | M6: 1
C7: FI 요약 | F7: 4 | K7: FI 요약 | M7: 2
B8: SMB 요약 | F8: 4 | J8: SMB 요약 | M8: 2
B9: VBL | C9: BA | D9: 12FW VB 04_CAMP_BK | E9: 1 | J9: VBL | K9: BA | L9: 12FW VB 04_CAMP_BK | M9: 1
D10: 13FW VB 01_CURVED_GY | E10: 1 | F10: 1 | L10: 13FW VB 01_CURVED_GY | M10: 1
D11: 13FW VB 02_CURVED_GR | E11: 1 | F11: 1 | L11: 13FW VB 02_CURVED_GR | M11: 1
D12: 13FW VB 11_CURVED_BL | E12: 1 | F12: 1 | L12: 13FW VB 11_CURVED_BL | M12: 1
D13: 13FW VB 03_WIRE_OR | G13: 1 | L13: 13FW VB 03_WIRE_OR | M13: 1
D14: 13FW VB 04_CAMP_NV | E14: 1 | F14: 1 | L14: 13FW VB 04_CAMP_NV | M14: 1
D15: 13FW VB 05_CAMP_OR | E15: 1 | F15: 1 | L15: 13FW VB 05_CAMP_OR | M15: 1
D16: 13FW VB 06_CAMP_D.G | E16: 1 | F16: 1 | L16: 13FW VB 06_CAMP_D.G | M16: 1
D17: 13FW VB 07_CAMP_BK | E17: 1 | L17: 13FW VB 07_CAMP_BK | M17: 1
D18: 13FW VB 08_CAMP_RD | E18: 1 | L18: 13FW VB 08_CAMP_RD | M18: 1
D19: 13FW VB 09_CAMP_S.BL | E19: 1 | L19: 13FW VB 09_CAMP_S.BL | M19: 1
D20: 13FW VB 10_CAMP_BK | E20: 1 | F20: 1 | L20: 13FW VB 10_CAMP_BK | M20: 1
D21: 13FW VB 12_CAMP_GR | E21: 1 | L21: 13FW VB 12_CAMP_GR | M21: 1
D22: 13FW VB 13_CAMP_RD | E22: 1 | L22: 13FW VB 13_CAMP_RD | M22: 1
D23: 13FW VB 14_CAMP_NV | E23: 1 | L23: 13FW VB 14_CAMP_NV | M23: 1
D24: 13FW VB 15_CAMP_LEO | E24: 1 | L24: 13FW VB 15_CAMP_LEO | M24: 1
D25: 13FW VB 16_CAMP_BL | E25: 1 | L25: 13FW VB 16_CAMP_BL | M25: 1
D26: 13FW VB 17_CAMP_BK | E26: 1 | L26: 13FW VB 17_CAMP_BK | M26: 1
D27: 13FW VB 18_WIRE_MUS | E27: 1 | L27: 13FW VB 18_WIRE_MUS | M27: 1
D28: 13FW VB 19_WIRE_BK | E28: 1 | L28: 13FW VB 19_WIRE_BK | M28: 1
D29: 13FW VB 22_CURVED_CHECK | E29: 1 | L29: 13FW VB 22_CURVED_CHECK | M29: 1
D30: 13FW VB 23_8PANNEL_D.GREY | G30: 1 | L30: 13FW VB 23_8PANNEL_D.GREY | M30: 1
D31: 13FW VB 21_CURVED_GREY | G31: 1 | L31: 13FW VB 21_CURVED_GREY | M31: 1
D32: 13FW VB 20_CURVED_L.GREY | G32: 1 | L32: 13FW VB 20_CURVED_L.GREY | M32: 1
D33: 13SS VB 21_8PANNEL_BK | E33: 1 | L33: 13SS VB 21_8PANNEL_BK | M33: 1
C34: BA 요약 | E34: 21 | F34: 7 | G34: 4 | K34: BA 요약 | M34: 25
B35: VBL 요약 | E35: 21 | F35: 7 | G35: 4 | J35: VBL 요약 | M35: 25
B36: WTR | C36: BA | D36: 13FW WITAILOR CAP-01-OG | G36: 1 | J36: WTR | K36: BA | L36: 13FW WITAILOR CAP-01-OG | M36: 1
D37: 13FW WITAILOR CAP-02-BL | E37: 1 | G37: 1 | L37: 13FW WITAILOR CAP-02-BL | M37: 1
D38: 13FW WITAILOR CAP-03-GR | G38: 1 | L38: 13FW WITAILOR CAP-03-GR | M38: 1
C39: BA 요약 | E39: 1 | G39: 3 | K39: BA 요약 | M39: 3
C40: ER | D40: 13FW WITAILOR CAP-04-BL | G40: 1 | K40: ER | L40: 13FW WITAILOR CAP-04-BL | M40: 1
...

Sheet Sheet1
A3: 개수 : SAMPLE NO. | B3: 열 레이블
A4: 행 레이블 | B4: 브랜드 | C4: JAY.PARK | D4: KONGHYOJIN | E4: SMB | F4: WTR | G4: (비어 있음) | H4: 총합계
A5: 동일모자 | E5: 25 | F5: 10 | H5: 35
A6: 생산업체 | B6: 1 | H6: 1
A7: 성진 | E7: 19 | H7: 19
A8: 캡보이 | C8: 5 | D8: 6 | H8: 11
A9: 캡보이2 | E9: 6 | H9: 6
A10: FOREMOST | E10: 7 | F10: 7 | H10: 14
A11: KIDS FIRST TOYS | E11: 2 | H11: 2
A12: QF | E12: 29 | H12: 29
A13: Y&Y | E13: 9 | H13: 9
A14: (비어 있음)
A15: 총합계 | B15: 1 | C15: 5 | D15: 6 | E15: 97 | F15: 17 | H15: 126

Sheet 리스트
C1: 14FW SAMPLE LIST
I2: 표기예 | M2: LEAD TIME | N2: 임의일자이니 확인되면 수정하고 색 지우기 | O2: 실입고일은 실제 샘플수령한 일자, 미입고시에는 공란 | S2: 총수=원자재 가지수 사용수=원자재 중 중국원자재 사용가지수 숫자로 표기
C3: * SAMPLE NO. = ARTWORK의 SAMPLE NO.와 동일해야 함 | I3: ADULT | M3: 국내제조
C4: * 발주일 = 작지+공급자재(+참조샘플) 최종 발송일 기준 | I4: CHILD | M4: 21
C5: * 목표입고일 = 발주시 생산업체와 협의 후 반드시 기록 | I5: INFANT | M5: 해외제조
C6: * 원가 = 입고시 반드시 기록 | M6: 28
J7: =SUM(J11:J1048576) -> 120.5
C8: 순번 | D8: 이미지 | E8: 브랜드 | F8: 품목 | G8: 러닝(R)/신규(N) | H8: SAMPLE NO. | I8: 연령구분 | J8: 샘플수 | K8: 생산업체 | L8: 일정 | P8: 원가 | R8: 참조샘플 발송여부 | S8: 중국원단사용수 | U8: 기타
A9: 브랜드/품목 | L9: 발주일 | M9: 목표입고일 | N9: 입고예정일 | O9: 실입고일 | P9: 해외 (FOB, USD, JPY) | Q9: 국내 (-V, KRW) | S9: 총수 | T9: 사용수
A10: 브랜드/품목 | B10: 공란 | C10: 순번 | D10: 이미지 | E10: 브랜드 | F10: 품목 | G10: 러닝(R)/신규(N) | H10: SAMPLE NO. | I10: 연령구분 | J10: 샘플수 | K10: 생산업체 | L10: 발주일 | M10: 목표입고일 | N10: 입고예정일 | O10: 실입고일 | P10: 해외원가 | Q10: 국내원가 | R10: 참조샘플 발송여부 | U10: 기타
A11: =IF(E11="","",IF(VLOOKUP($F11,CODE!$K:$O,CODE!$O$1,FALSE)="",$E11,$E11&"-"&VLOOKUP($F11,CODE!$K:$O,CODE!$O$1,FALSE))) -> SMB | C11: 1 | E11: SMB | F11: FI | G11: N | H11: 14FW SMB_01_FLAT_GR_N | I11: U | J11: =IF(ISERROR(1/COUNTIF(H:H,H11))=TRUE,0,1/COUNTIF(H:H,H11)) -> 1 | K11: QF | L11: 41662 | M11: =IF(ISERROR(VLOOKUP($K11,생산업체!$A:$C,생산업체!$A$1,FALSE))=TRUE,"업체리스트 참조 후 업체명 변경",IF(VLOOKUP($K11,생산업체!$A:$C,생산업체!$B$1,FALSE)=1,$L11+$M$6,$L11+$M$4)) -> 41690 | N11: 41719 | O11: 41711 | P11: 2.7 | S11: 2 | T11: 2
A12: =IF(E12="","",IF(VLOOKUP($F12,CODE!$K:$O,CODE!$O$1,FALSE)="",$E12,$E12&"-"&VLOOKUP($F12,CODE!$K:$O,CODE!$O$1,FALSE))) -> SMB | C12: =C11+1 -> 2 | E12: SMB | F12: FI | G12: N | H12: 14FW SMB_01_FLAT_NY_N | I12: U | J12: =IF(ISERROR(1/COUNTIF(H:H,H12))=TRUE,0,1/COUNTIF(H:H,H12)) -> 1 | K12: 동일모자 | L12: 41663 | M12: =IF(ISERROR(VLOOKUP($K12,생산업체!$A:$C,생산업체!$A$1,FALSE))=TRUE,"업체리스트 참조 후 업체명 변경",IF(VLOOKUP($K12,생산업체!$A:$C,생산업체!$B$1,FALSE)=1,$L12+$M$6,$L12+$M$4)) -> 41691 | N12: 41716 | O12: 41716 | P12: 3.85 | S12: 3 | T12: 3
A13: =IF(E13="","",IF(VLOOKUP($F13,CODE!$K:$O,CODE!$O$1,FALSE)="",$E13,$E13&"-"&VLOOKUP($F13,CODE!$K:$O,CODE!$O$1,FALSE))) -> SMB | C13: =C12+1 -> 3 | E13: SMB | F13: FI | G13: N | H13: 14FW SMB_02_FLAT_BL_N | I13: U | J13: =IF(ISERROR(1/COUNTIF(H:H,H13))=TRUE,0,1/COUNTIF(H:H,H13)) -> 1 | K13: QF | L13: 41662 | M13: =IF(ISERROR(VLOOKUP($K13,생산업체!$A:$C,생산업체!$A$1,FALSE))=TRUE,"업체리스트 참조 후 업체명 변경",IF(VLOOKUP($K13,생산업체!$A:$C,생산업체!$B$1,FALSE)=1,$L13+$M$6,$L13+$M$4)) -> 41690 | N13: 41719 | O13: 41717 | P13: 3.4 | S13: 3 | T13: 2 | U13: 크라운 및 챙 원단 국내제공시 가격
A14: =IF(E14="","",IF(VLOOKUP($F14,CODE!$K:$O,CODE!$O$1,FALSE)="",$E14,$E14&"-"&VLOOKUP($F14,CODE!$K:$O,CODE!$O$1,FALSE))) -> SMB | C14: =C13+1 -> 4 | E14: SMB | F14: FI | G14: N | H14: 14FW SMB_03_FLAT_BK_N | I14: U | J14: =IF(ISERROR(1/COUNTIF(H:H,H14))=TRUE,0,1/COUNTIF(H:H,H14)) -> 1 | K14: QF | L14: 41662 | M14: =IF(ISERROR(VLOOKUP($K14,생산업체!$A:$C,생산업체!$A$1,FALSE))=TRUE,"업체리스트 참조 후 업체명 변경",IF(VLOOKUP($K14,생산업체!$A:$C,생산업체!$B$1,FALSE)=1,$L14+$M$6,$L14+$M$4)) -> 41690 | N14: 41719 | O14: 41717 | P14: 3.4 | S14: 3 | T14: 2 | U14: 크라운 및 챙 원단 국내제공시 가격
A15: =IF(E15="","",IF(VLOOKUP($F15,CODE!$K:$O,CODE!$O$1,FALSE)="",$E15,$E15&"-"&VLOOKUP($F15,CODE!$K:$O,CODE!$O$1,FALSE))) -> SMB | C15: =C14+1 -> 5 | E15: SMB | F15: FI | G15: N | H15: 14FW SMB_05_FLAT_KH_N | I15: U | J15: =IF(ISERROR(1/COUNTIF(H:H,H15))=TRUE,0,1/COUNTIF(H:H,H15)) -> 1 | K15: QF | L15: 41662 | M15: =IF(ISERROR(VLOOKUP($K15,생산업체!$A:$C,생산업체!$A$1,FALSE))=TRUE,"업체리스트 참조 후 업체명 변경",IF(VLOOKUP($K15,생산업체!$A:$C,생산업체!$B$1,FALSE)=1,$L15+$M$6,$L15+$M$4)) -> 41690 | N15: 41719 | O15: 41709 | P15: 3.3 | S15: 2 | T15: 2
A16: =IF(E16="","",IF(VLOOKUP($F16,CODE!$K:$O,CODE!$O$1,FALSE)="",$E16,$E16&"-"&VLOOKUP($F16,CODE!$K:$O,CODE!$O$1,FALSE))) -> SMB | C16: =C15+1 -> 6 | E16: SMB | F16: FI | G16: N | H16: 14FW SMB_05_FLAT_PP_N | I16: U | J16: =IF(ISERROR(1/COUNTIF(H:H,H16))=TRUE,0,1/COUNTIF(H:H,H16)) -> 1 | K16: QF | L16: 41662 | M16: =IF(ISERROR(VLOOKUP($K16,생산업체!$A:$C,생산업체!$A$1,FALSE))=TRUE,"업체리스트 참조 후 업체명 변경",IF(VLOOKUP($K16,생산업체!$A:$C,생산업체!$B$1,FALSE)=1,$L16+$M$6,$L16+$M$4)) -> 41690 | N16: 41719 | O16: 41711 | P16: 3.2 | S16: 2 | T16: 2
A17: =IF(E17="","",IF(VLOOKUP($F17,CODE!$K:$O,CODE!$O$1,FALSE)="",$E17,$E17&"-"&VLOOKUP($F17,CODE!$K:$O,CODE!$O$1,FALSE))) -> SMB | C17: =C16+1 -> 7 | E17: SMB | F17: FI | G17: N | H17: 14FW SMB_05_FLAT_RE_N | I17: U | J17: =IF(ISERROR(1/COUNTIF(H:H,H17))=TRUE,0,1/COUNTIF(H:H,H17)) -> 1 | K17: QF | L17: 41662 | M17: =IF(ISERROR(VLOOKUP($K17,생산업체!$A:$C,생산업체!$A$1,FALSE))=TRUE,"업체리스트 참조 후 업체명 변경",IF(VLOOKUP($K17,생산업체!$A:$C,생산업체!$B$1,FALSE)=1,$L17+$M$6,$L17+$M$4)) -> 41690 | N17: 41719 | O17: 41709 | P17: 3.2 | S17: 2 | T17: 2
A18: =IF(E18="","",IF(VLOOKUP($F18,CODE!$K:$O,CODE!$O$1,FALSE)="",$E18,$E18&"-"&VLOOKUP($F18,CODE!$K:$O,CODE!$O$1,FALSE))) -> SMB | C18: =C17+1 -> 8 | E18: SMB | F18: FI | G18: N | H18: 14FW SMB_06_FLAT_BK_N | I18: U | J18: =IF(ISERROR(1/COUNTIF(H:H,H18))=TRUE,0,1/COUNTIF(H:H,H18)) -> 1 | K18: QF | L18: 41663 | M18: =IF(ISERROR(VLOOKUP($K18,생산업체!$A:$C,생산업체!$A$1,FALSE))=TRUE,"업체리스트 참조 후 업체명 변경",IF(VLOOKUP($K18,생산업체!$A:$C,생산업체!$B$1,FALSE)=1,$L18+$M$6,$L18+$M$4)) -> 41691 | N18: 41719 | O18: 41709 | P18: 4.5 | S18: 3 | T18: 3
A19: =IF(E19="","",IF(VLOOKUP($F19,CODE!$K:$O,CODE!$O$1,FALSE)="",$E19,$E19&"-"&VLOOKUP($F19,CODE!$K:$O,CODE!$O$1,FALSE))) -> SMB | C19: =C18+1 -> 9 | E19: SMB | F19: BA | G19: N | H19: 14FW SMB_01_CURVED_BK_N | I19: U | J19: =IF(ISERROR(1/COUNTIF(H:H,H19))=TRUE,0,1/COUNTIF(H:H,H19)) -> 1 | K19: 캡보이2 | L19: 41663 | M19: =IF(ISERROR(VLOOKUP($K19,생산업체!$A:$C,생산업체!$A$1,FALSE))=TRUE,"업체리스트 참조 후 업체명 변경",IF(VLOOKUP($K19,생산업체!$A:$C,생산업체!$B$1,FALSE)=1,$L19+$M$6,$L19+$M$4)) -> 41691 | N19: 41717 | O19: 41726 | S19: 3 | T19: 3
A20: =IF(E20="","",IF(VLOOKUP($F20,CODE!$K:$O,CODE!$O$1,FALSE)="",$E20,$E20&"-"&VLOOKUP($F20,CODE!$K:$O,CODE!$O$1,FALSE))) -> SMB | C20: =C19+1 -> 10 | E20: SMB | F20: BA | G20: N | H20: 14FW SMB_02_CURVED_NV_N | I20: U | J20: =IF(ISERROR(1/COUNTIF(H:H,H20))=TRUE,0,1/COUNTIF(H:H,H20)) -> 1 | K20: 성진 | L20: 41663 | M20: =IF(ISERROR(VLOOKUP($K20,생산업체!$A:$C,생산업체!$A$1,FALSE))=TRUE,"업체리스트 참조 후 업체명 변경",IF(VLOOKUP($K20,생산업체!$A:$C,생산업체!$B$1,FALSE)=1,$L20+$M$6,$L20+$M$4)) -> 41691 | N20: 41719 | O20: 41709 | P20: 5.4 | S20: 2 | T20: 2
A21: =IF(E21="","",IF(VLOOKUP($F21,CODE!$K:$O,CODE!$O$1,FALSE)="",$E21,$E21&"-"&VLOOKUP($F21,CODE!$K:$O,CODE!$O$1,FALSE))) -> SMB | C21: =C20+1 -> 11 | E21: SMB | F21: BA | G21: N | H21: 14FW SMB_03_CURVED_BK_N | I21: U | J21: =IF(ISERROR(1/COUNTIF(H:H,H21))=TRUE,0,1/COUNTIF(H:H,H21)) -> 1 | K21: 성진 | L21: 41663 | M21: =IF(ISERROR(VLOOKUP($K21,생산업체!$A:$C,생산업체!$A$1,FALSE))=TRUE,"업체리스트 참조 후 업체명 변경",IF(VLOOKUP($K21,생산업체!$A:$C,생산업체!$B$1,FALSE)=1,$L21+$M$6,$L21+$M$4)) -> 41691 | N21: 41719 | O21: 41709 | P21: 5.4 | S21: 2 | T21: 2
A22: =IF(E22="","",IF(VLOOKUP($F22,CODE!$K:$O,CODE!$O$1,FALSE)="",$E22,$E22&"-"&VLOOKUP($F22,CODE!$K:$O,CODE!$O$1,FALSE))) -> SMB | C22: =C21+1 -> 12 | E22: SMB | F22: BA | G22: N | H22: 14FW SMB_03_CURVED_RD_N | I22: U | J22: =IF(ISERROR(1/COUNTIF(H:H,H22))=TRUE,0,1/COUNTIF(H:H,H22)) -> 0.5 | K22: 성진 | L22: 41663 | M22: =IF(ISERROR(VLOOKUP($K22,생산업체!$A:$C,생산업체!$A$1,FALSE))=TRUE,"업체리스트 참조 후 업체명 변경",IF(VLOOKUP($K22,생산업체!$A:$C,생산업체!$B$1,FALSE)=1,$L22+$M$6,$L22+$M$4)) -> 41691 | N22: 41719 | O22: 41709 | P22: 5.95 | S22: 3 | T22: 3
A23: =IF(E23="","",IF(VLOOKUP($F23,CODE!$K:$O,CODE!$O$1,FALSE)="",$E23,$E23&"-"&VLOOKUP($F23,CODE!$K:$O,CODE!$O$1,FALSE))) -> SMB | C23: =C22+1 -> 13 | E23: SMB | F23: BA | G23: N | H23: 14FW SMB_04_CURVED_YL_N | I23: U | J23: =IF(ISERROR(1/COUNTIF(H:H,H23))=TRUE,0,1/COUNTIF(H:H,H23)) -> 1 | K23: 성진 | L23: 41663 | M23: =IF(ISERROR(VLOOKUP($K23,생산업체!$A:$C,생산업체!$A$1,FALSE))=TRUE,"업체리스트 참조 후 업체명 변경",IF(VLOOKUP($K23,생산업체!$A:$C,생산업체!$B$1,FALSE)=1,$L23+$M$6,$L23+$M$4)) -> 41691 | N23: 41719 | O23: 41719 | P23: 5.4 | S23: 2 | T23: 2
A24: =IF(E24="","",IF(VLOOKUP($F24,CODE!$K:$O,CODE!$O$1,FALSE)="",$E24,$E24&"-"&VLOOKUP($F24,CODE!$K:$O,CODE!$O$1,FALSE))) -> SMB | C24: =C23+1 -> 14 | E24: SMB | F24: BA | G24: N | H24: 14FW SMB_05_CURVED_BD_N | I24: U | J24: =IF(ISERROR(1/COUNTIF(H:H,H24))=TRUE,0,1/COUNTIF(H:H,H24)) -> 1 | K24: 동일모자 | L24: 41663 | M24: =IF(ISERROR(VLOOKUP($K24,생산업체!$A:$C,생산업체!$A$1,FALSE))=TRUE,"업체리스트 참조 후 업체명 변경",IF(VLOOKUP($K24,생산업체!$A:$C,생산업체!$B$1,FALSE)=1,$L24+$M$6,$L24+$M$4)) -> 41691 | N24: 41719 | O24: 41716 | P24: 4.2 | S24: 3 | T24: 3
A25: =IF(E25="","",IF(VLOOKUP($F25,CODE!$K:$O,CODE!$O$1,FALSE)="",$E25,$E25&"-"&VLOOKUP($F25,CODE!$K:$O,CODE!$O$1,FALSE))) -> SMB | C25: =C24+1 -> 15 | E25: SMB | F25: BA | G25: N | H25: 14FW SMB_05_CURVED_BL_N | I25: U | J25: =IF(ISERROR(1/COUNTIF(H:H,H25))=TRUE,0,1/COUNTIF(H:H,H25)) -> 1 | K25: 동일모자 | L25: 41663 | M25: =IF(ISERROR(VLOOKUP($K25,생산업체!$A:$C,생산업체!$A$1,FALSE))=TRUE,"업체리스트 참조 후 업체명 변경",IF(VLOOKUP($K25,생산업체!$A:$C,생산업체!$B$1,FALSE)=1,$L25+$M$6,$L25+$M$4)) -> 41691 | N25: 41719 | O25: 41719 | P25: 4.2 | S25: 3 | T25: 3 | U25: 앞 노말자수 네이비컬러 (그라만 뺀 컬러로 진행)
A26: =IF(E26="","",IF(VLOOKUP($F26,CODE!$K:$O,CODE!$O$1,FALSE)="",$E26,$E26&"-"&VLOOKUP($F26,CODE!$K:$O,CODE!$O$1,FALSE))) -> SMB | C26: =C25+1 -> 16 | E26: SMB | F26: BA | G26: N | H26: 14FW SMB_06_CURVED_BK_N | I26: U | J26: =IF(ISERROR(1/COUNTIF(H:H,H26))=TRUE,0,1/COUNTIF(H:H,H26)) -> 1 | K26: 성진 | L26: 41663 | M26: =IF(ISERROR(VLOOKUP($K26,생산업체!$A:$C,생산업체!$A$1,FALSE))=TRUE,"업체리스트 참조 후 업체명 변경",IF(VLOOKUP($K26,생산업체!$A:$C,생산업체!$B$1,FALSE)=1,$L26+$M$6,$L26+$M$4)) -> 41691 | N26: 41719 | O26: 41702 | P26: 5.15 | S26: 2 | T26: 2
A27: =IF(E27="","",IF(VLOOKUP($F27,CODE!$K:$O,CODE!$O$1,FALSE)="",$E27,$E27&"-"&VLOOKUP($F27,CODE!$K:$O,CODE!$O$1,FALSE))) -> SMB | C27: =C26+1 -> 17 | E27: SMB | F27: BA | G27: N | H27: 14FW SMB_06_CURVED_NY_N | I27: U | J27: =IF(ISERROR(1/COUNTIF(H:H,H27))=TRUE,0,1/COUNTIF(H:H,H27)) -> 1 | K27: 성진 | L27: 41663 | M27: =IF(ISERROR(VLOOKUP($K27,생산업체!$A:$C,생산업체!$A$1,FALSE))=TRUE,"업체리스트 참조 후 업체명 변경",IF(VLOOKUP($K27,생산업체!$A:$C,생산업체!$B$1,FALSE)=1,$L27+$M$6,$L27+$M$4)) -> 41691 | N27: 41698 | O27: 41698 | P27: 5.1 | S27: 2 | T27: 2
A28: =IF(E28="","",IF(VLOOKUP($F28,CODE!$K:$O,CODE!$O$1,FALSE)="",$E28,$E28&"-"&VLOOKUP($F28,CODE!$K:$O,CODE!$O$1,FALSE))) -> SMB | C28: =C27+1 -> 18 | E28: SMB | F28: BA | G28: N | H28: 14FW SMB_07_CURVED_BK_N | I28: U | J28: =IF(ISERROR(1/COUNTIF(H:H,H28))=TRUE,0,1/COUNTIF(H:H,H28)) -> 1 | K28: 동일모자 | L28: 41663 | M28: =IF(ISERROR(VLOOKUP($K28,생산업체!$A:$C,생산업체!$A$1,FALSE))=TRUE,"업체리스트 참조 후 업체명 변경",IF(VLOOKUP($K28,생산업체!$A:$C,생산업체!$B$1,FALSE)=1,$L28+$M$6,$L28+$M$4)) -> 41691 | N28: 41719 | O28: 41716 | P28: 4.45 | S28: 3 | T28: 3
A29: =IF(E29="","",IF(VLOOKUP($F29,CODE!$K:$O,CODE!$O$1,FALSE)="",$E29,$E29&"-"&VLOOKUP($F29,CODE!$K:$O,CODE!$O$1,FALSE))) -> SMB | C29: =C28+1 -> 19 | E29: SMB | F29: BA | G29: N | H29: 14FW SMB_07_CURVED_GR_N | I29: U | J29: =IF(ISERROR(1/COUNTIF(H:H,H29))=TRUE,0,1/COUNTIF(H:H,H29)) -> 1 | K29: 동일모자 | L29: 41663 | M29: =IF(ISERROR(VLOOKUP($K29,생산업체!$A:$C,생산업체!$A$1,FALSE))=TRUE,"업체리스트 참조 후 업체명 변경",IF(VLOOKUP($K29,생산업체!$A:$C,생산업체!$B$1,FALSE)=1,$L29+$M$6,$L29+$M$4)) -> 41691 | N29: 41719 | O29: 41716 | P29: 4.2 | S29: 3 | T29: 3
A30: =IF(E30="","",IF(VLOOKUP($F30,CODE!$K:$O,CODE!$O$1,FALSE)="",$E30,$E30&"-"&VLOOKUP($F30,CODE!$K:$O,CODE!$O$1,FALSE))) -> SMB | C30: =C29+1 -> 20 | E30: SMB | F30: BA | G30: N | H30: 14FW SMB_07_CURVED_OR | I30: U | J30: =IF(ISERROR(1/COUNTIF(H:H,H30))=TRUE,0,1/COUNTIF(H:H,H30)) -> 1 | K30: 동일모자 | L30: 41663 | M30: =IF(ISERROR(VLOOKUP($K30,생산업체!$A:$C,생산업체!$A$1,FALSE))=TRUE,"업체리스트 참조 후 업체명 변경",IF(VLOOKUP($K30,생산업체!$A:$C,생산업체!$B$1,FALSE)=1,$L30+$M$6,$L30+$M$4)) -> 41691 | N30: 41719 | O30: 41716 | P30: 4.45 | S30: 3 | T30: 3
A31: =IF(E31="","",IF(VLOOKUP($F31,CODE!$K:$O,CODE!$O$1,FALSE)="",$E31,$E31&"-"&VLOOKUP($F31,CODE!$K:$O,CODE!$O$1,FALSE))) -> SMB | C31: =C30+1 -> 21 | E31: SMB | F31: ER | G31: N | H31: 14FW SMB_08_CURVED_NY_N | I31: U | J31: =IF(ISERROR(1/COUNTIF(H:H,H31))=TRUE,0,1/COUNTIF(H:H,H31)) -> 0.5 | K31: 캡보이2 | L31: 41663 | M31: =IF(ISERROR(VLOOKUP($K31,생산업체!$A:$C,생산업체!$A$1,FALSE))=TRUE,"업체리스트 참조 후 업체명 변경",IF(VLOOKUP($K31,생산업체!$A:$C,생산업체!$B$1,FALSE)=1,$L31+$M$6,$L31+$M$4)) -> 41691 | N31: 캔슬 | O31: 캔슬 | S31: 3 | T31: 3
A32: =IF(E32="","",IF(VLOOKUP($F32,CODE!$K:$O,CODE!$O$1,FALSE)="",$E32,$E32&"-"&VLOOKUP($F32,CODE!$K:$O,CODE!$O$1,FALSE))) -> SMB | C32: =C31+1 -> 22 | E32: SMB | F32: ER | G32: N | H32: 14FW SMB_09_CURVED_PK_N | I32: U | J32: =IF(ISERROR(1/COUNTIF(H:H,H32))=TRUE,0,1/COUNTIF(H:H,H32)) -> 1 | K32: 캡보이2 | L32: 41663 | M32: =IF(ISERROR(VLOOKUP($K32,생산업체!$A:$C,생산업체!$A$1,FALSE))=TRUE,"업체리스트 참조 후 업체명 변경",IF(VLOOKUP($K32,생산업체!$A:$C,생산업체!$B$1,FALSE)=1,$L32+$M$6,$L32+$M$4)) -> 41691 | N32: 41717 | O32: 41726 | S32: 3 | T32: 3
A33: =IF(E33="","",IF(VLOOKUP($F33,CODE!$K:$O,CODE!$O$1,FALSE)="",$E33,$E33&"-"&VLOOKUP($F33,CODE!$K:$O,CODE!$O$1,FALSE))) -> SMB | C33: =C32+1 -> 23 | E33: SMB | F33: ER | G33: N | H33: 14FW SMB_01_CURVED_NY_N | I33: U | J33: =IF(ISERROR(1/COUNTIF(H:H,H33))=TRUE,0,1/COUNTIF(H:H,H33)) -> 1 | K33: 캡보이2 | L33: 41663 | M33: =IF(ISERROR(VLOOKUP($K33,생산업체!$A:$C,생산업체!$A$1,FALSE))=TRUE,"업체리스트 참조 후 업체명 변경",IF(VLOOKUP($K33,생산업체!$A:$C,생산업체!$B$1,FALSE)=1,$L33+$M$6,$L33+$M$4)) -> 41691 | N33: 41717 | O33: 41722 | S33: 3 | T33: 3
A34: =IF(E34="","",IF(VLOOKUP($F34,CODE!$K:$O,CODE!$O$1,FALSE)="",$E34,$E34&"-"&VLOOKUP($F34,CODE!$K:$O,CODE!$O$1,FALSE))) -> SMB | C34: =C33+1 -> 24 | E34: SMB | F34: BA | G34: N | H34: 14FW SMB_03_CURVED_RD_N | I34: U | J34: =IF(ISERROR(1/COUNTIF(H:H,H34))=TRUE,0,1/COUNTIF(H:H,H34)) -> 0.5 | K34: 캡보이2 | L34: 41663 | M34: =IF(ISERROR(VLOOKUP($K34,생산업체!$A:$C,생산업체!$A$1,FALSE))=TRUE,"업체리스트 참조 후 업체명 변경",IF(VLOOKUP($K34,생산업체!$A:$C,생산업체!$B$1,FALSE)=1,$L34+$M$6,$L34+$M$4)) -> 41691 | N34: 캔슬 | O34: 캔슬 | S34: 2 | T34: 2 | U34: 캔슬
A35: =IF(E35="","",IF(VLOOKUP($F35,CODE!$K:$O,CODE!$O$1,FALSE)="",$E35,$E35&"-"&VLOOKUP($F35,CODE!$K:$O,CODE!$O$1,FALSE))) -> WTR | C35: =C34+1 -> 25 | E35: WTR | F35: TP | G35: N | H35: 14FW WITAILOR CAP-01-WN | I35: U | J35: =IF(ISERROR(1/COUNTIF(H:H,H35))=TRUE,0,1/COUNTIF(H:H,H35)) -> 1 | K35: FOREMOST | L35: 41675 | M35: =IF(ISERROR(VLOOKUP($K35,생산업체!$A:$C,생산업체!$A$1,FALSE))=TRUE,"업체리스트 참조 후 업체명 변경",IF(VLOOKUP($K35,생산업체!$A:$C,생산업체!$B$1,FALSE)=1,$L35+$M$6,$L35+$M$4)) -> 41703 | N35: 41719 | O35: 41719 | S35: 7 | T35: 5 | U35: 13FW BROWN SQURE 1 샘플배송 (20140210) -> 받음 20140228
A36: =IF(E36="","",IF(VLOOKUP($F36,CODE!$K:$O,CODE!$O$1,FALSE)="",$E36,$E36&"-"&VLOOKUP($F36,CODE!$K:$O,CODE!$O$1,FALSE))) -> WTR | C36: =C35+1 -> 26 | E36: WTR | F36: TP | G36: N | H36: 14FW WITAILOR CAP-02-BK | I36: U | J36: =IF(ISERROR(1/COUNTIF(H:H,H36))=TRUE,0,1/COUNTIF(H:H,H36)) -> 1 | K36: FOREMOST | L36: 41675 | M36: =IF(ISERROR(VLOOKUP($K36,생산업체!$A:$C,생산업체!$A$1,FALSE))=TRUE,"업체리스트 참조 후 업체명 변경",IF(VLOOKUP($K36,생산업체!$A:$C,생산업체!$B$1,FALSE)=1,$L36+$M$6,$L36+$M$4)) -> 41703 | N36: 41729 | O36: 41725 | S36: 5 | T36: 4
A37: =IF(E37="","",IF(VLOOKUP($F37,CODE!$K:$O,CODE!$O$1,FALSE)="",$E37,$E37&"-"&VLOOKUP($F37,CODE!$K:$O,CODE!$O$1,FALSE))) -> WTR | C37: =C36+1 -> 27 | E37: WTR | F37: BA | G37: N | H37: 14FW WITAILOR CAP-03-NY | I37: U | J37: =IF(ISERROR(1/COUNTIF(H:H,H37))=TRUE,0,1/COUNTIF(H:H,H37)) -> 1 | K37: 동일모자 | L37: 41675 | M37: =IF(ISERROR(VLOOKUP($K37,생산업체!$A:$C,생산업체!$A$1,FALSE))=TRUE,"업체리스트 참조 후 업체명 변경",IF(VLOOKUP($K37,생산업체!$A:$C,생산업체!$B$1,FALSE)=1,$L37+$M$6,$L37+$M$4)) -> 41703 | N37: 41719 | O37: 41709 | P37: 4.85 | S37: 5 | T37: 3
A38: =IF(E38="","",IF(VLOOKUP($F38,CODE!$K:$O,CODE!$O$1,FALSE)="",$E38,$E38&"-"&VLOOKUP($F38,CODE!$K:$O,CODE!$O$1,FALSE))) -> WTR | C38: =C37+1 -> 28 | E38: WTR | F38: BA | G38: N | H38: 14FW WITAILOR CAP-04-GY | I38: U | J38: =IF(ISERROR(1/COUNTIF(H:H,H38))=TRUE,0,1/COUNTIF(H:H,H38)) -> 1 | K38: 동일모자 | L38: 41675 | M38: =IF(ISERROR(VLOOKUP($K38,생산업체!$A:$C,생산업체!$A$1,FALSE))=TRUE,"업체리스트 참조 후 업체명 변경",IF(VLOOKUP($K38,생산업체!$A:$C,생산업체!$B$1,FALSE)=1,$L38+$M$6,$L38+$M$4)) -> 41703 | N38: 41719 | O38: 41719 | P38: 4.85 | S38: 5 | T38: 3
A39: =IF(E39="","",IF(VLOOKUP($F39,CODE!$K:$O,CODE!$O$1,FALSE)="",$E39,$E39&"-"&VLOOKUP($F39,CODE!$K:$O,CODE!$O$1,FALSE))) -> WTR | C39: =C38+1 -> 29 | E39: WTR | F39: BA | G39: N | H39: 14FW WITAILOR CAP-05-RE | I39: U | J39: =IF(ISERROR(1/COUNTIF(H:H,H39))=TRUE,0,1/COUNTIF(H:H,H39)) -> 1 | K39: FOREMOST | L39: 41675 | M39: =IF(ISERROR(VLOOKUP($K39,생산업체!$A:$C,생산업체!$A$1,FALSE))=TRUE,"업체리스트 참조 후 업체명 변경",IF(VLOOKUP($K39,생산업체!$A:$C,생산업체!$B$1,FALSE)=1,$L39+$M$6,$L39+$M$4)) -> 41703 | N39: 41729 | O39: 41722 | S39: 5 | T39: 3
A40: =IF(E40="","",IF(VLOOKUP($F40,CODE!$K:$O,CODE!$O$1,FALSE)="",$E40,$E40&"-"&VLOOKUP($F40,CODE!$K:$O,CODE!$O$1,FALSE))) -> WTR | C40: =C39+1 -> 30 | E40: WTR | F40: BA | G40: N | H40: 14FW WITAILOR CAP-06-BR | I40: U | J40: =IF(ISERROR(1/COUNTIF(H:H,H40))=TRUE,0,1/COUNTIF(H:H,H40)) -> 1 | K40: FOREMOST | L40: 41675 | M40: =IF(ISERROR(VLOOKUP($K40,생산업체!$A:$C,생산업체!$A$1,FALSE))=TRUE,"업체리스트 참조 후 업체명 변경",IF(VLOOKUP($K40,생산업체!$A:$C,생산업체!$B$1,FALSE)=1,$L40+$M$6,$L40+$M$4)) -> 41703 | N40: 41729 | O40: 41722 | S40: 5 | T40: 2
...

Sheet 생산업체
A1: 1 | B1: 2 | C1: 3
A2: 약칭(기획현황) | B2: 수입1, 내수2 | C2: 통화
A3: 스포팅21 | B3: 2
A4: 아디다스 | B4: 2
A5: 홈런 | B5: 2 | C5: KRW
A6: AI | B6: 2
A7: GSM | B7: 2 | C7: KRW
A8: 닉슨코리아 | B8: 2 | C8: KRW
A9: FLAT FITTY | B9: 2 | C9: KRW
A10: JOYRICH | B10: 2 | C10: KRW
A11: KANGOL | B11: 2
A12: LG패션 | B12: 2
A13: NEWERA | B13: 2 | C13: KRW
A14: 고성 | B14: 2 | C14: KRW
A15: 림스스포츠 | B15: 2 | C15: KRW
A16: 아트인드림 | B16: 2 | C16: KRW
A17: 캡보이 | B17: 2 | C17: KRW
A18: 현주실업 | B18: 2 | C18: KRW
A19: CNG | B19: 2 | C19: KRW
A20: POWER JK | B20: 2
A21: 신성모자 | B21: 2 | C21: KRW
A22: TS | B22: 2 | C22: KRW
A23: 최강모자 | B23: 2 | C23: KRW
A24: 아우리에프엔 | B24: 2 | C24: KRW
A25: 현대제모 | B25: 2 | C25: KRW
A26: ING | B26: 2
A27: 우진모자 | B27: 2 | C27: KRW
A28: 47 Brand | B28: 1 | C28: USD
A29: ED HARDY | B29: 1
A30: TRUE RELIGION | B30: 1 | C30: USD
A31: TWINS | B31: 1 | C31: USD
A32: GOORIN BROTHERS | B32: 1 | C32: USD
A33: GRACE HAT | B33: 1 | C33: JPY
A34: BRONER HATS | B34: 1
A35: CODELLO | B35: 1 | C35: USD
A36: 해외소매구매 | B36: 1 | C36: USD
A37: 해외소매구매2 | B37: 1 | C37: EUR
A38: SEEBERGER | B38: 1 | C38: USD
A39: EUGENIA KIM | B39: 1 | C39: USD
A40: GREVI | B40: 1 | C40: EUR
...

Sheet CODE
C1: 2 | D1: 3 | E1: 4 | F1: 5 | G1: 6 | L1: 2 | M1: 3 | N1: 4 | O1: 5 | P1: 6 | S1: 2 | T1: 3 | X1: 2 | Y1: 3 | AE1: 2 | AF1: 3 | AJ1: 2 | AK1: 3 | AL1: 4 | AO1: 2 | AP1: 3 | AS1: 2 | AT1: 3 | AW1: 2 | AX1: 3
A2: BRAND (3자리) | I2: ITEM (2자리) | R2: YEAR (2자리) | V2: SEASON (1자리) | AA2: STNO (3자리) | AC2: COLOR (2자리) | AH2: SIZE (3자리) | AN2: 분류 | AR2: 성별 | AV2: 원산지
A3: 구코드 | B3: 코드 | C3: 코드명 | D3: 그룹 | E3: 코드 | F3: 구분 | G3: B/M/C | I3: 구코드 | J3: 구코드명 | K3: 코드 | L3: 코드명 | M3: 코드 | N3: 구분 | O3: 구분 | P3: 구분 | R3: 코드 | S3: 코드명 | T3: 코드 | V3: 구코드 | W3: 코드 | X3: 코드명 | Y3: 코드 | AA3: 코드 | AC3: 구코드 | AD3: 코드 | AE3: 코드명 | AF3: 코드 | AH3: 구코드 | AI3: 코드 | AJ3: 코드명 | AK3: TYPE | AL3: 코드 | AN3: 코드 | AO3: 코드명 | AP3: 코드 | AR3: 코드 | AS3: 코드명 | AT3: 코드 | AV3: 코드 | AW3: 코드명 | AX3: 코드
A4: BZ | C4: COP CARDINALS | D4: =B4 -> 0 | E4: =B4 -> 0 | F4: SPORTS | G4: B | I4: CA | J4: BASIC CAP (핀치히터) | K4: BA | L4: BASIC CAP | M4: =K4 -> BA | N4: 의류외 | P4: 모자 | R4: A | S4: 2009 | T4: =R4 -> A | V4: 0 | W4: 0 | X4: SS | Y4: =W4 -> 0 | AA4: 001 | AC4: B0 | AD4: BK | AE4: Black | AF4: =AD4 -> BK | AH4: A | AI4: FRE | AJ4: OSFA(ADJUST CAP) | AK4: 1 | AL4: =AI4 -> FRE | AN4: B | AO4: 사입 | AP4: =AN4 -> B | AR4: M | AS4: 남자 | AT4: =AR4 -> M | AV4: CN | AW4: 중국 | AX4: =AV4 -> CN
A5: BH | C5: COP INDIANS | D5: =B5 -> 0 | E5: =B5 -> 0 | F5: SPORTS | G5: B | I5: CS | J5: VISOR CAP | K5: BA | L5: BASIC CAP | M5: =K5 -> BA | N5: 의류외 | P5: 모자 | R5: B | S5: 2010 | T5: =R5 -> B | V5: 1 | W5: 0 | X5: SS | Y5: =W5 -> 0 | AA5: 002 | AC5: B1 | AE5: Black Camo | AF5: =AD5 -> 0 | AH5: N | AI5: OXS | AJ5: XS | AK5: 1 | AL5: =AI5 -> OXS | AN5: C | AO5: 위탁 | AP5: =AN5 -> C | AR5: W | AS5: 여자 | AT5: =AR5 -> W | AV5: JP | AW5: 일본 | AX5: =AV5 -> JP
A6: BR | C6: COP METS | D6: =B6 -> 0 | E6: =B6 -> 0 | F6: SPORTS | G6: B | I6: CC | J6: FLEX CAP (3930) | K6: FL | L6: FLEX CAP | M6: =K6 -> FL | N6: 의류외 | P6: 모자 | R6: C | S6: 2011 | T6: =R6 -> C | V6: 2 | W6: 0 | X6: SS | Y6: =W6 -> 0 | AA6: 003 | AC6: B2 | AE6: Black Leopard | AF6: =AD6 -> 0 | AI6: OSS | AJ6: S | AK6: 1 | AL6: =AI6 -> OSS | AN6: M | AO6: 제조 | AP6: =AN6 -> M | AR6: U | AS6: UNISEX | AT6: =AR6 -> U | AV6: KR | AW6: 한국 | AX6: =AV6 -> KR
A7: BC | C7: COP ORIOLES | D7: =B7 -> 0 | E7: =B7 -> 0 | F7: SPORTS | G7: B | I7: CD | J7: NORMAL FITTED CAP (커브) | K7: FL | L7: FLEX CAP | M7: =K7 -> FL | N7: 의류외 | P7: 모자 | R7: D | S7: 2012 | T7: =R7 -> D | V7: 3 | W7: 0 | X7: SS | Y7: =W7 -> 0 | AA7: 004 | AC7: B3 | AE7: Black/White | AF7: =AD7 -> 0 | AI7: OMM | AJ7: M | AK7: 1 | AL7: =AI7 -> OMM | AR7: K | AS7: KIDS | AT7: =AR7 -> K | AV7: US | AW7: 미국 | AX7: =AV7 -> US
A8: BJ | C8: COP TIGERS | D8: =B8 -> 0 | E8: =B8 -> 0 | F8: SPORTS | G8: B | I8: CE | J8: FLAT BILL FITTED CAP(5950) | K8: FI | L8: FITTED CAP | M8: =K8 -> FI | N8: 의류외 | P8: 모자 | R8: E | S8: 2013 | T8: =R8 -> E | V8: 4 | W8: 0 | X8: SS | Y8: =W8 -> 0 | AA8: 005 | AC8: B4 | AE8: Black/Flann | AF8: =AD8 -> 0 | AI8: OLL | AJ8: L | AK8: 1 | AL8: =AI8 -> OLL | AR8: N | AS8: NEWERA | AT8: =AR8 -> N | AV8: IN | AW8: 인도네시아 | AX8: =AV8 -> IN
A9: KC | B9: KDO | C9: DOOSAN BEARS | D9: KBO | E9: =B9 -> KDO | F9: SPORTS | G9: B | I9: CU | J9: FLAT BILL FLEX CAP(일자) | K9: FI | L9: FITTED CAP | M9: =K9 -> FI | N9: 의류외 | P9: 모자 | R9: F | S9: 2014 | T9: =R9 -> F | V9: 5 | W9: 3 | X9: FW | Y9: =W9 -> 3 | AA9: 006 | AC9: B5 | AE9: Dark Flann | AF9: =AD9 -> 0 | AI9: OXL | AJ9: XL | AK9: 1 | AL9: =AI9 -> OXL | AR9: A | AS9: AUTHENTIC | AT9: =AR9 -> A | AV9: BG | AW9: 방글라데시 | AX9: =AV9 -> BG
A10: CD | B10: ZCD | C10: EUR BARCELONA | D10: =B10 -> ZCD | E10: =B10 -> ZCD | F10: SPORTS | G10: B | I10: DA | J10: FLAT BILL FITTED BASIC (BLANK 5950) | K10: FI | L10: FITTED CAP | M10: =K10 -> FI | N10: 의류외 | P10: 모자 | R10: G | S10: 2015 | T10: =R10 -> G | V10: 6 | W10: 3 | X10: FW | Y10: =W10 -> 3 | AA10: 007 | AC10: B6 | AE10: Loden | AF10: =AD10 -> 0 | AH10: O | AI10: OSM | AJ10: S~M | AK10: 1 | AL10: =AI10 -> OSM | AV10: DE | AW10: 독일 | AX10: =AV10 -> DE
A11: CA | B11: ZCA | C11: EUR MUCHESTER | D11: =B11 -> ZCA | E11: =B11 -> ZCA | F11: SPORTS | G11: B | I11: CB | J11: WASHED CAP (워싱캡) | K11: WC | L11: WASHED CAP | M11: =K11 -> WC | N11: 의류외 | P11: 모자 | R11: H | S11: 2016 | T11: =R11 -> H | V11: 7 | W11: 3 | X11: FW | Y11: =W11 -> 3 | AA11: 008 | AC11: B7 | AE11: Pine X | AF11: =AD11 -> 0 | AH11: P | AI11: OML | AJ11: M~L | AK11: 1 | AL11: =AI11 -> OML | AV11: AT | AW11: 오스트리아 | AX11: =AV11 -> AT
A12: KH | B12: KHA | C12: HANWHA EAGLES | D12: KBO | E12: =B12 -> KHA | F12: SPORTS | G12: B | I12: CF | J12: TRUCKER CAP | K12: TR | L12: TRUCKER CAP | M12: =K12 -> TR | N12: 의류외 | P12: 모자 | R12: I | S12: 2017 | T12: =R12 -> I | V12: 8 | W12: 3 | X12: FW | Y12: =W12 -> 3 | AA12: 009 | AC12: B8 | AE12: Block | AF12: =AD12 -> 0 | AH12: Q | AI12: LXL | AJ12: L~XL | AK12: 1 | AL12: =AI12 -> LXL | AV12: BE | AW12: 벨기에 | AX12: =AV12 -> BE
A13: KA | B13: KKI | C13: KIA TIGERS | D13: KBO | E13: =B13 -> KKI | F13: SPORTS | G13: B | I13: CV | J13: MESH CAP(커브) | K13: TR | L13: TRUCKER CAP | M13: =K13 -> TR | N13: 의류외 | P13: 모자 | R13: J | S13: 2018 | T13: =R13 -> J | V13: 9 | W13: 3 | X13: FW | Y13: =W13 -> 3 | AA13: 010 | AC13: B9 | AD13: BU | AE13: Burgundy | AF13: =AD13 -> BU | AV13: CH | AW13: 스위스 | AX13: =AV13 -> CH
A14: KG | B14: KLG | C14: LG TWINS | D14: KBO | E14: =B14 -> KLG | F14: SPORTS | G14: B | I14: CW | J14: FLAT BILL MESH CAP(일자) | K14: TR | L14: TRUCKER CAP | M14: =K14 -> TR | N14: 의류외 | P14: 모자 | AC14: BA | AE14: PLAID BLACK | AF14: =AD14 -> 0 | AH14: E | AI14: 700 | AJ14: 7(56CM) | AK14: 2 | AL14: =AI14 -> 700 | AV14: ES | AW14: 스페인 | AX14: =AV14 -> ES
A15: KD | B15: KLO | C15: LOTTE GIANTS | D15: KBO | E15: =B15 -> KLO | F15: SPORTS | G15: B | I15: DB | J15: FLAT BILL TRUCKER CAP | K15: TR | L15: TRUCKER CAP | M15: =K15 -> TR | N15: 의류외 | P15: 모자 | AC15: BB | AE15: Black/Red | AF15: =AD15 -> 0 | AH15: F | AI15: 718 | AJ15: 71/8(57CM) | AK15: 2 | AL15: =AI15 -> 718 | AV15: FR | AW15: 프랑스 | AX15: =AV15 -> FR
A16: AO | B16: NAN | C16: MLB ANGELS | D16: MLB | E16: =B16 -> NAN | F16: SPORTS | G16: B | I16: CZ | J16: UMPIRE | K16: UM | L16: UMPIRE | M16: =K16 -> UM | N16: 의류외 | P16: 모자 | AC16: C1 | AD16: BG | AE16: Beige | AF16: =AD16 -> BG | AH16: G | AI16: 714 | AJ16: 71/4(58CM) | AK16: 2 | AL16: =AI16 -> 714 | AV16: GR | AW16: 영국 | AX16: =AV16 -> GR
A17: AU | B17: NAS | C17: MLB A'S | D17: MLB | E17: =B17 -> NAS | F17: SPORTS | G17: B | I17: CG | J17: PERFORMANCE CAP(기능성) | K17: PE | L17: PERFORMANCE CAP | M17: =K17 -> PE | N17: 의류외 | P17: 모자 | AC17: C2 | AE17: Putty | AF17: =AD17 -> 0 | AH17: H | AI17: 738 | AJ17: 73/8(59CM) | AK17: 2 | AL17: =AI17 -> 738 | AV17: IT | AW17: 이탈리아 | AX17: =AV17 -> IT
A18: AM | B18: NAT | C18: MLB ASTROS | D18: MLB | E18: =B18 -> NAT | F18: SPORTS | G18: B | I18: CI | J18: MILITARY CAP | K18: MI | L18: MILITARY CAP | M18: =K18 -> MI | N18: 의류외 | P18: 모자 | AC18: C3 | AE18: Sand | AF18: =AD18 -> 0 | AH18: I | AI18: 712 | AJ18: 71/2(60CM) | AK18: 2 | AL18: =AI18 -> 712 | AV18: PI | AW18: 필리핀 | AX18: =AV18 -> PI
A19: A4 | B19: NBL | C19: MLB BLUEJAYS | D19: MLB | E19: =B19 -> NBL | F19: SPORTS | G19: B | I19: CK | J19: FEDORA | K19: FE | L19: FEDORA | M19: =K19 -> FE | N19: 의류외 | P19: 모자 | AC19: C4 | AD19: KH | AE19: Khaki | AF19: =AD19 -> KH | AH19: J | AI19: 758 | AJ19: 75/8(61CM) | AK19: 2 | AL19: =AI19 -> 758 | AV19: PT | AW19: 포르투갈 | AX19: =AV19 -> PT
A20: AC | B20: NBR | C20: MLB BRAVES | D20: MLB | E20: =B20 -> NBR | F20: SPORTS | G20: B | I20: CL | J20: HUNTING CAP | K20: HU | L20: HUNTING CAP | M20: =K20 -> HU | N20: 의류외 | P20: 모자 | AC20: C5 | AE20: Café | AF20: =AD20 -> 0 | AH20: K | AI20: 734 | AJ20: 73/4(62CM) | AK20: 2 | AL20: =AI20 -> 734 | AV20: TW | AW20: 대만 | AX20: =AV20 -> TW
A21: AQ | B21: NBE | C21: MLB BREWERS | D21: MLB | E21: =B21 -> NBE | F21: SPORTS | G21: B | I21: CT | J21: CASQUETTE | K21: CT | L21: CASQUETTE | M21: =K21 -> CT | N21: 의류외 | P21: 모자 | AC21: C6 | AD21: BW | AE21: Brown | AF21: =AD21 -> BW | AH21: L | AI21: 778 | AJ21: 77/8(63CM) | AK21: 2 | AL21: =AI21 -> 778
A22: A1 | B22: NCA | C22: MLB CARDINALS | D22: MLB | E22: =B22 -> NCA | F22: SPORTS | G22: B | I22: CM | J22: BERET | K22: CM | L22: BERET | M22: =K22 -> CM | N22: 의류외 | P22: 모자 | AC22: C7 | AE22: Dk.Brown | AF22: =AD22 -> 0 | AH22: M | AI22: 800 | AJ22: 8(64CM) | AK22: 2 | AL22: =AI22 -> 800
A23: AF | B23: NCU | C23: MLB CUBS | D23: MLB | E23: =B23 -> NCU | F23: SPORTS | G23: B | I23: CJ | J23: FASHION HAT | K23: FA | L23: FASHION HAT | M23: =K23 -> FA | N23: 의류외 | P23: 모자 | AC23: C8 | AE23: Light.Brown | AF23: =AD23 -> 0
A24: AB | B24: NDB | C24: MLB D'BACKS | D24: MLB | E24: =B24 -> NDB | F24: SPORTS | G24: B | I24: CX | J24: PAPER 소재로 된 것. | K24: FA | L24: FASHION HAT | M24: =K24 -> FA | N24: 의류외 | P24: 모자 | AC24: C9 | AD24: BR | AE24: Metalic Bronze | AF24: =AD24 -> BR | AI24: 600 | AJ24: 6(48CM) | AK24: 3 | AL24: =AI24 -> 600
A25: A2 | B25: NDE | C25: MLB DEVILSRAYS | D25: MLB | E25: =B25 -> NDE | F25: SPORTS | G25: B | I25: CY | J25: Trim이 길고 펄럭임 | K25: FA | L25: FASHION HAT | M25: =K25 -> FA | N25: 의류외 | P25: 모자 | AC25: CA | AE25: Brown Leopard | AF25: =AD25 -> 0 | AI25: 618 | AJ25: 61/8(49CM) | AK25: 3 | AL25: =AI25 -> 618
A26: AP | B26: NDO | C26: MLB DODGERS | D26: MLB | E26: =B26 -> NDO | F26: SPORTS | G26: B | I26: CH | J26: BUCKET | K26: FA | L26: FASHION HAT | M26: =K26 -> FA | N26: 의류외 | P26: 모자 | AC26: CB | AE26: Dk.Khaki | AF26: =AD26 -> 0 | AI26: 614 | AJ26: 61/4(50CM) | AK26: 3 | AL26: =AI26 -> 614
A27: AY | B27: NGI | C27: MLB GIANTS | D27: MLB | E27: =B27 -> NGI | F27: SPORTS | G27: B | I27: CN | J27: NORMAL BEANIE | K27: BE | L27: BEANIE | M27: =K27 -> BE | N27: 의류외 | P27: 모자 | AC27: CC | AD27: CH | AE27: Chocolate | AF27: =AD27 -> CH | AH27: H | AI27: 638 | AJ27: 63/8(51CM) | AK27: 3 | AL27: =AI27 -> 638
A28: AI | B28: NIN | C28: MLB INDIANS | D28: MLB | E28: =B28 -> NIN | F28: SPORTS | G28: B | I28: CO | J28: REVERSABLE BEANIE | K28: BE | L28: BEANIE | M28: =K28 -> BE | N28: 의류외 | P28: 모자 | AC28: CD | AE28: Walnut | AF28: =AD28 -> 0 | AH28: I | AI28: 612 | AJ28: 61/2(52CM) | AK28: 3 | AL28: =AI28 -> 612
A29: AZ | B29: NMR | C29: MLB MARINERS | D29: MLB | E29: =B29 -> NMR | F29: SPORTS | G29: B | I29: CR | J29: CUFF KNIT BEANIE | K29: BE | L29: BEANIE | M29: =K29 -> BE | N29: 의류외 | P29: 모자 | AC29: CE | AD29: CL | AE29: CAMEL | AF29: =AD29 -> CL | AH29: J | AI29: 658 | AJ29: 65/8(53CM) | AK29: 3 | AL29: =AI29 -> 658
A30: AL | B30: NMA | C30: MLB MARLINS | D30: MLB | E30: =B30 -> NMA | F30: SPORTS | G30: B | I30: CP | J30: VISOR BEANIE (챙비니) | K30: VB | L30: VISOR BEANIE | M30: =K30 -> VB | N30: 의류외 | P30: 모자 | AC30: CF | AE30: PLAID BROWN | AF30: =AD30 -> 0 | AH30: K | AI30: 634 | AJ30: 63/4(54CM) | AK30: 3 | AL30: =AI30 -> 634
A31: AS | B31: NME | C31: MLB METS | D31: MLB | E31: =B31 -> NME | F31: SPORTS | G31: B | I31: CQ | J31: EARFLAP BEANIE | K31: EB | L31: EARFLAP BEANIE | M31: =K31 -> EB | N31: 의류외 | P31: 모자 | AC31: E0 | AD31: GY | AE31: Grey | AF31: =AD31 -> GY | AH31: D | AI31: 678 | AJ31: 67/8(55CM) | AK31: 3 | AL31: =AI31 -> 678
A32: A5 | B32: NNA | C32: MLB NATIONALS | D32: MLB | E32: =B32 -> NNA | F32: SPORTS | G32: B | J32: EARCAP | K32: ER | L32: EARCAP | M32: =K32 -> ER | N32: 의류외 | P32: 모자 | AC32: E1 | AE32: Light Grey | AF32: =AD32 -> 0
A33: AD | B33: NOR | C33: MLB ORIOLES | D33: MLB | E33: =B33 -> NOR | F33: SPORTS | G33: B | J33: TROOPER | K33: TP | L33: TROOPER | M33: =K33 -> TP | N33: 의류외 | P33: 모자 | AC33: E2 | AE33: Dk.Grey | AF33: =AD33 -> 0 | AH33: 4 | AI33: 240 | AJ33: 240 | AK33: 4 | AL33: =AI33 -> 240
A34: AX | B34: NPA | C34: MLB PADRES | D34: MLB | E34: =B34 -> NPA | F34: SPORTS | G34: B | I34: EA | J34: KNIT MUFFLER | K34: MU | L34: MUFFLER | M34: =K34 -> MU | N34: 의류외 | O34: ACC | P34: ACC | AC34: E3 | AE34: C.Coal Grey | AF34: =AD34 -> 0 | AH34: 5 | AI34: 250 | AJ34: 250 | AK34: 4 | AL34: =AI34 -> 250
A35: AV | B35: NPH | C35: MLB PHILLIES | D35: MLB | E35: =B35 -> NPH | F35: SPORTS | G35: B | I35: EB | J35: HOOD MUFFLER | K35: MU | L35: MUFFLER | N35: 의류외 | O35: ACC | P35: ACC | AC35: E4 | AE35: Gunmetal | AF35: =AD35 -> 0 | AH35: 7 | AI35: 270 | AJ35: 270 | AK35: 4 | AL35: =AI35 -> 270
A36: AW | B36: NPI | C36: MLB PIRATES | D36: MLB | E36: =B36 -> NPI | F36: SPORTS | G36: B | I36: EC | J36: SCARF | K36: MU | L36: MUFFLER | N36: 의류외 | O36: ACC | P36: ACC | AC36: E5 | AE36: PLAID GREY | AF36: =AD36 -> 0 | AH36: 8 | AI36: 280 | AJ36: 280 | AK36: 4 | AL36: =AI36 -> 280
A37: A3 | B37: NRA | C37: MLB RANGERS | D37: MLB | E37: =B37 -> NRA | F37: SPORTS | G37: B | J37: WARMER | K37: WA | L37: WARMER | M37: =K37 -> WA | N37: 의류외 | O37: ACC | P37: ACC | AC37: E6 | AE37: Light Beige | AF37: =AD37 -> 0
A38: AH | B38: NRD | C38: MLB REDS | D38: MLB | E38: =B38 -> NRD | F38: SPORTS | G38: B | I38: ED | J38: MITTEN(장갑) | K38: ED | L38: MITTEN | M38: =K38 -> ED | N38: 의류외 | O38: ACC | P38: ACC | AC38: G0 | AD38: MT | AE38: Mint | AF38: =AD38 -> MT
A39: AE | B39: NRE | C39: MLB REDSOX | D39: MLB | E39: =B39 -> NRE | F39: SPORTS | G39: B | I39: FA | J39: CAP CARRIER(모자 휴대가방) | K39: CC | L39: CAP CARRIER | M39: =K39 -> CC | N39: 의류외 | O39: ACC | P39: ACC | AC39: G1 | AD39: GR | AE39: Green | AF39: =AD39 -> GR
A40: AJ | B40: NRO | C40: MLB ROCKIES | D40: MLB | E40: =B40 -> NRO | F40: SPORTS | G40: B | I40: FB | J40: CAP SPRAY(모자 세정액) | K40: CS | L40: CAP SPRAY | M40: =K40 -> CS | N40: 의류외 | O40: ACC | P40: ACC | AC40: G2 | AE40: Olive | AF40: =AD40 -> 0
...
